Workbook

Sheet TOC
A1: PISA 2018 Results (Volume III) - © OECD 2019
A2: Annex B1 | B2: Annex B1.6 Results (tables): Teachers' support and teaching practices
A3: Version 2 - Last updated: 02-Dec-2019
A4: Disclaimer: http://oe.cd/disclaimer
A6: TOC | B6: PISA 2018 Results - Volume III
A8: Chapter 6 | B8: Teacher support
A9: Tables
A11: ='Table III.B1.6.1'!A6 -> Table III.B1.6.1 | B11: ='Table III.B1.6.1'!$A$7 -> Teacher support
A12: ='Table III.B1.6.2'!A6 -> Table III.B1.6.2 | B12: ='Table III.B1.6.2'!$A$7 -> Teacher emotional support
A13: ='Table III.B1.6.3'!A6 -> Table III.B1.6.3 | B13: ='Table III.B1.6.3'!$A$7 -> Teacher feedback
A14: ='Table III.B1.6.4'!A6 -> Table III.B1.6.4 | B14: ='Table III.B1.6.4'!$A$7 -> Prevalence of teacher support in schools
A15: ='Table III.B1.6.5'!A6 -> Table III.B1.6.5 | B15: ='Table III.B1.6.5'!$A$7 -> Teacher support, by student characteristics
A16: ='Table III.B1.6.6'!A6 -> Table III.B1.6.6 | B16: ='Table III.B1.6.6'!$A$7 -> Teacher support, by school characteristics
A17: ='Table III.B1.6.7'!A6 -> Table III.B1.6.7 | B17: ='Table III.B1.6.7'!$A$7 -> Teacher support and reading performance
A18: ='Table III.B1.6.8'!A6 -> Table III.B1.6.8 | B18: ='Table III.B1.6.8'!$A$7 -> School-level teacher support and reading performance
A19: ='Table III.B1.6.9'!A6 -> Table III.B1.6.9 | B19: ='Table III.B1.6.9'!$A$7 -> Correlations between teaching practices in language-of-instruction lessons
A20: ='Table III.B1.6.10'!A6 -> Table III.B1.6.10 | B20: ='Table III.B1.6.10'!$A$7 -> Enjoyment of reading and teaching practices in language-of-instruction lessons
A21: ='Table III.B1.6.11'!A6 -> Table III.B1.6.11 | B21: ='Table III.B1.6.11'!$A$7 -> Principals' concern about education staff and teaching practices in language-of-instruction lessons
A24: Symbols for missing data
A25: c: There were too few observations to provide reliable estimates (i.e. there were fewer than 30 students or fewer than 5 schools with valid data).
A26: m: Data are not available. There are no observations in the sample; these data were not collected by the country; or these data were collected but subsequently removed from the publication for technical reasons.
A27: w: Results were withdrawn at the request of the country concerned.

Sheet INFORMATION ON SCALED INDICES
A1: PISA 2018 Results (Volume III) - © OECD 2019
A2: Annex B1 | B2: Annex B1.6 Results (tables): Teachers' support and teaching practices
A3: Version 2 - Last updated: 02-Dec-2019
A4: Disclaimer: http://oe.cd/disclaimer
A6: Information on scaled indices used in PISA 2015 Results (Volume III): What School Life Means for Students’ Lives
A11: Full name of the index | B11: Name in dataset | C11: Questionnaire | D11: Item 1 | E11: Item 2 | F11: Item 3 | G11: Item 4 | H11: Item 5 | I11: Item 6 | J11: Item 7
A12: Adaptive instruction | B12: adaptivity | C12: Student | D12: ST212Q01HA | E12: ST212Q02HA | F12: ST212Q03HA
A13: Attitudes towards competition | B13: compete | C13: Student | D13: ST181Q02HA | E13: ST181Q03HA | F13: ST181Q04HA
A14: Enjoyment of reading | B14: joyread | C14: Student | D14: ST160Q01IR | E14: ST160Q02IA | F14: ST160Q03IA | G14: ST160Q04IR | H14: ST160Q05IR
A15: Exposure to bullying | B15: beingbullied | C15: Student | D15: ST038Q03NA | E15: ST038Q04NA | F15: ST038Q05NA
A16: Fear of failure | B16: gfofail | C16: Student | D16: ST183Q01HA | E16: ST183Q02HA | F16: ST183Q03HA
A17: Disciplinary climate | B17: disclima | C17: Student | D17: ST097Q01TA | E17: ST097Q02TA | F17: ST097Q03TA | G17: ST097Q04TA | H17: ST097Q05TA
A18: Learning goals | B18: mastgoal | C18: Student | D18: ST208Q01HA | E18: ST208Q02HA | F18: ST208Q04HA
A19: Meaning in life | B19: eudmo | C19: Student | D19: ST185Q01HA | E19: ST185Q02HA | F19: ST185Q03HA
A20: Motivation to master tasks | B20: workmast | C20: Student | D20: ST182Q03HA | E20: ST182Q04HA | F20: ST182Q05HA
A21: Parents’ emotional support | B21: emosups | C21: Student | D21: ST123Q02NA | E21: ST123Q03NA | F21: ST123Q04NA
A22: Parents’ perceived school quality | B22: pqschool | C22: Parent | D22: PA007Q01TR | E22: PA007Q02TR | F22: PA007Q03TR | G22: PA007Q04TR | H22: PA007Q05TR | I22: PA007Q06TR | J22: PA007Q07TR
A23: Positive feelings | B23: swbp | C23: Student | D23: ST186Q01HA | E23: ST186Q03HA | F23: ST186Q05HA
A24: School policies for parental involvement | B24: paschpol | C24: Parent | D24: PA007Q09NR | E24: PA007Q11NR | F24: PA007Q12NR | G24: PA007Q13NR | H24: PA007Q14NR | I24: PA007Q15NR
A25: Self-efficacy | B25: resilience | C25: Student | D25: ST188Q01HA | E25: ST188Q02HA | F25: ST188Q03HA | G25: ST188Q06HA | H25: ST188Q07HA
A26: Sense of belonging | B26: belong | C26: Student | D26: ST034Q01TA | E26: ST034Q02TR | F26: ST034Q03TR | G26: ST034Q04TA | H26: ST034Q05TR | I26: ST034Q06TA
A27: Shortage of educational staff | B27: staffshort | C27: School | D27: SC017Q01NA | E27: SC017Q02NA | F27: SC017Q03NA | G27: SC017Q04NA
A28: Student competition | B28: percomp | C28: Student | D28: ST205Q01HA | E28: ST205Q02HA | F28: ST205Q03HA
A29: Student co-operation | B29: percoop | C29: Student | D29: ST206Q01HA | E29: ST206Q02HA | F29: ST206Q03HA
A30: Teacher behaviour hindering learning | B30: teachbeha | C30: School | D30: SC061Q06TA | E30: SC061Q07TA | F30: SC061Q08TA | G30: SC061Q09TA | H30: SC061Q10TA
A31: Teacher enthusiasm | B31: teachint | C31: Student | D31: ST213Q01HA | E31: ST213Q02HA | F31: ST213Q03HA | G31: ST213Q04HA
A32: Teacher feedback | B32: perfeed | C32: Student | D32: ST104Q02NA | E32: ST104Q03NA | F32: ST104Q04NA
A33: Teacher support | B33: teachsup | C33: Student | D33: ST100Q01TR | E33: ST100Q02TR | F33: ST100Q03TR | G33: ST100Q04TR
A34: Teacher-directed instruction | B34: dirins | C34: Student | D34: ST102Q01TR | E34: ST102Q02TR | F34: ST102Q03TR | G34: ST102Q04TR
A35: Teachers' stimulation of reading engagement | B35: stimread | C35: Student | D35: ST152Q05IA | E35: ST152Q06IA | F35: ST152Q07IA | G35: ST152Q08IA
A36: Value of school | B36: attlnact | C36: Student | D36: ST036Q05TR | E36: ST036Q06TR | F36: ST036Q08TR

Sheet Table III.B1.6.1
A1: PISA 2018 Results (Volume III) - © OECD 2019
A2: Annex B1 | B2: Annex B1.6 Results (tables): Teachers' support and teaching practices
A3: Version 2 - Last updated: 02-Dec-2019
A4: Disclaimer: http://oe.cd/disclaimer
A6: Table III.B1.6.1
A7: Teacher support
A8: Based on students' reports
B11: Index of teacher support | H11: Percentage of students who reported the following things happen in their language-of-instruction lessons:
H12: The teacher shows an interest in every student's learning | T12: The teacher gives extra help when students need it | AF12: The teacher helps students with their learning | AR12: The teacher continues teaching until students understand
B13: Average | E13: Variability | H13: Never or hardly ever | K13: Some lessons | N13: Most lessons | Q13: Every lesson | T13: Never or hardly ever | W13: Some lessons | Z13: Most lessons | AC13: Every lesson | AF13: Never or hardly ever | AI13: Some lessons | AL13: Most lessons | AO13: Every lesson | AR13: Never or hardly ever | AU13: Some lessons | AX13: Most lessons | BA13: Every lesson
B14: Mean index | C14: S.E. | E14: S.D. | F14: S.E. | H14: % | I14: S.E. | K14: % | L14: S.E. | N14: % | O14: S.E. | Q14: % | R14: S.E. | T14: % | U14: S.E. | W14: % | X14: S.E. | Z14: % | AA14: S.E. | AC14: % | AD14: S.E. | AF14: % | AG14: S.E. | AI14: % | AJ14: S.E. | AL14: % | AM14: S.E. | AO14: % | AP14: S.E. | AR14: % | AS14: S.E. | AU14: % | AV14: S.E. | AX14: % | AY14: S.E. | BA14: % | BB14: S.E.
A15: OECD
A16: Australia | B16: 0.25204698 | C16: 0.012513802 | E16: 0.96888009 | F16: 0.0064771467 | H16: 4.9887234 | I16: 0.21177018 | K16: 16.325936 | L16: 0.43161694 | N16: 32.366502 | O16: 0.49556182 | Q16: 46.318839 | R16: 0.62089527 | T16: 4.4489042 | U16: 0.22949546 | W16: 14.461362 | X16: 0.36244774 | Z16: 29.93441 | AA16: 0.48524526 | AC16: 51.155324 | AD16: 0.57139162 | AF16: 3.0038122 | AG16: 0.15476831 | AI16: 11.660789 | AJ16: 0.34702628 | AL16: 28.366144 | AM16: 0.46115729 | AO16: 56.969255 | AP16: 0.57025587 | AR16: 6.5738963 | AS16: 0.2677026 | AU16: 17.890152 | AV16: 0.39708055 | AX16: 31.319418 | AY16: 0.44091994 | BA16: 44.216533 | BB16: 0.61047781
A17: Austria | B17: -0.44658974 | C17: 0.02087212 | E17: 1.0787151 | F17: 0.01001399 | H17: 14.501659 | I17: 0.55216026 | K17: 22.428281 | L17: 0.60533451 | N17: 34.021866 | O17: 0.71723514 | Q17: 29.048194 | R17: 0.7585122 | T17: 13.979788 | U17: 0.61516959 | W17: 21.342207 | X17: 0.61534459 | Z17: 27.789936 | AA17: 0.62826537 | AC17: 36.88807 | AD17: 0.79062905 | AF17: 23.302785 | AG17: 0.71424369 | AI17: 24.95221 | AJ17: 0.7113187 | AL17: 26.570754 | AM17: 0.7297039 | AO17: 25.174251 | AP17: 0.69536658 | AR17: 16.647224 | AS17: 0.64774692 | AU17: 24.911365 | AV17: 0.5971391 | AX17: 28.739577 | AY17: 0.61531351 | BA17: 29.701835 | BB17: 0.77732233
A18: Belgium | B18: -0.16720602 | C18: 0.016838532 | E18: 0.99240922 | F18: 0.0083217236 | H18: 11.941734 | I18: 0.45460128 | K18: 23.463177 | L18: 0.5625821 | N18: 33.018936 | O18: 0.619286 | Q18: 31.576153 | R18: 0.65601838 | T18: 7.6581974 | U18: 0.32175173 | W18: 19.583479 | X18: 0.54711464 | Z18: 30.972062 | AA18: 0.56189607 | AC18: 41.786262 | AD18: 0.75379478 | AF18: 13.081026 | AG18: 0.47831908 | AI18: 22.970502 | AJ18: 0.57843231 | AL18: 28.765701 | AM18: 0.56943524 | AO18: 35.18277 | AP18: 0.639933 | AR18: 8.4076678 | AS18: 0.37724403 | AU18: 21.40382 | AV18: 0.56262687 | AX18: 31.689961 | AY18: 0.55573917 | BA18: 38.498551 | BB18: 0.72268658
A19: Canada | B19: m | C19: m | E19: m | F19: m | H19: m | I19: m | K19: m | L19: m | N19: m | O19: m | Q19: m | R19: m | T19: m | U19: m | W19: m | X19: m | Z19: m | AA19: m | AC19: m | AD19: m | AF19: m | AG19: m | AI19: m | AJ19: m | AL19: m | AM19: m | AO19: m | AP19: m | AR19: m | AS19: m | AU19: m | AV19: m | AX19: m | AY19: m | BA19: m | BB19: m
A20: Chile | B20: 0.43688606 | C20: 0.020886064 | E20: 0.90201753 | F20: 0.010163966 | H20: 2.7464531 | I20: 0.23110569 | K20: 10.533227 | L20: 0.55181777 | N20: 25.090348 | O20: 0.668211 | Q20: 61.629971 | R20: 1.0423427 | T20: 4.6257009 | U20: 0.31538866 | W20: 14.522848 | X20: 0.60339071 | Z20: 26.915487 | AA20: 0.56113883 | AC20: 53.935964 | AD20: 0.97547832 | AF20: 1.9028701 | AG20: 0.21734223 | AI20: 9.1760002 | AJ20: 0.4637454 | AL20: 24.329588 | AM20: 0.67013063 | AO20: 64.591542 | AP20: 0.97679932 | AR20: 3.9531071 | AS20: 0.27018478 | AU20: 13.524714 | AV20: 0.59511466 | AX20: 25.800635 | AY20: 0.60116798 | BA20: 56.721544 | BB20: 0.98313298
A21: Colombia | B21: 0.34053714 | C21: 0.01858889 | E21: 0.88623384 | F21: 0.0083620249 | H21: 2.9343543 | I21: 0.21916127 | K21: 8.944241 | L21: 0.41699596 | N21: 23.986329 | O21: 0.66412262 | Q21: 64.135076 | R21: 0.87955989 | T21: 5.6650489 | U21: 0.31811598 | W21: 18.473518 | X21: 0.7203658 | Z21: 27.415734 | AA21: 0.72489908 | AC21: 48.445699 | AD21: 1.033744 | AF21: 1.9421478 | AG21: 0.16903887 | AI21: 11.2891 | AJ21: 0.62849362 | AL21: 25.635488 | AM21: 0.60111543 | AO21: 61.133264 | AP21: 0.9488068 | AR21: 4.39075 | AS21: 0.31854836 | AU21: 17.225141 | AV21: 0.60783086 | AX21: 27.246591 | AY21: 0.62555162 | BA21: 51.137518 | BB21: 0.99693352
A22: Czech Republic | B22: -0.2183739 | C22: 0.022201743 | E22: 0.97465584 | F22: 0.012101992 | H22: 8.6704825 | I22: 0.49435258 | K22: 21.320889 | L22: 0.60217506 | N22: 32.021699 | O22: 0.69052995 | Q22: 37.98693 | R22: 1.0118736 | T22: 5.7149972 | U22: 0.44181537 | W22: 15.839428 | X22: 0.65808479 | Z22: 28.717303 | AA22: 0.6967987 | AC22: 49.728272 | AD22: 0.97640057 | AF22: 13.971997 | AG22: 0.62900128 | AI22: 25.241312 | AJ22: 0.51715221 | AL22: 29.676093 | AM22: 0.6245998 | AO22: 31.110597 | AP22: 0.9397896 | AR22: 14.756119 | AS22: 0.76793835 | AU22: 29.075304 | AV22: 0.82410178 | AX22: 30.228902 | AY22: 0.65454234 | BA22: 25.939675 | BB22: 0.9121384
A23: Denmark | B23: 0.14056715 | C23: 0.018387875 | E23: 0.84847164 | F23: 0.0087736416 | H23: 5.3128354 | I23: 0.37137494 | K23: 18.082663 | L23: 0.65629151 | N23: 40.197918 | O23: 0.61449953 | Q23: 36.406583 | R23: 0.9288197 | T23: 4.8495667 | U23: 0.35289194 | W23: 16.958382 | X23: 0.59245377 | Z23: 37.678927 | AA23: 0.80207453 | AC23: 40.513125 | AD23: 1.0028462 | AF23: 2.0751632 | AG23: 0.22300743 | AI23: 10.852399 | AJ23: 0.5033756 | AL23: 35.841456 | AM23: 0.79624788 | AO23: 51.230981 | AP23: 0.89333224 | AR23: 4.3918094 | AS23: 0.29567566 | AU23: 16.165453 | AV23: 0.58843836 | AX23: 37.392779 | AY23: 0.66287229 | BA23: 42.049959 | BB23: 0.89599103
A24: Estonia | B24: -0.11259174 | C24: 0.015780928 | E24: 0.92799225 | F24: 0.0098941271 | H24: 11.492165 | I24: 0.58485075 | K24: 28.272446 | L24: 0.65365114 | N24: 34.755067 | O24: 0.66788035 | Q24: 25.480322 | R24: 0.73157246 | T24: 5.7768929 | U24: 0.35281462 | W24: 20.663981 | X24: 0.64680128 | Z24: 33.278507 | AA24: 0.72469756 | AC24: 40.280619 | AD24: 0.77450658 | AF24: 5.6397132 | AG24: 0.36436805 | AI24: 18.431151 | AJ24: 0.57864809 | AL24: 34.205951 | AM24: 0.76814619 | AO24: 41.723185 | AP24: 0.76040068 | AR24: 9.7658799 | AS24: 0.44311215 | AU24: 22.731322 | AV24: 0.62665095 | AX24: 35.199664 | AY24: 0.81470474 | BA24: 32.303135 | BB24: 0.79617507
A25: Finland | B25: 0.21104799 | C25: 0.017334122 | E25: 0.90805888 | F25: 0.011312796 | H25: 6.2099972 | I25: 0.36702831 | K25: 20.235402 | L25: 0.71579571 | N25: 38.557182 | O25: 0.79130295 | Q25: 34.997419 | R25: 0.8701138 | T25: 3.0313774 | U25: 0.28290124 | W25: 11.659757 | X25: 0.4393068 | Z25: 30.380619 | AA25: 0.72244322 | AC25: 54.928247 | AD25: 0.84025188 | AF25: 2.7442046 | AG25: 0.25131166 | AI25: 10.105591 | AJ25: 0.43465397 | AL25: 29.486271 | AM25: 0.74590511 | AO25: 57.663933 | AP25: 0.9020439 | AR25: 5.8510715 | AS25: 0.37581788 | AU25: 19.350754 | AV25: 0.59210846 | AX25: 36.025112 | AY25: 0.63598785 | BA25: 38.773063 | BB25: 0.84157778
A26: France | B26: -0.22013677 | C26: 0.019198829 | E26: 1.0494388 | F26: 0.0094005293 | H26: 16.572503 | I26: 0.65605317 | K26: 26.117412 | L26: 0.72199174 | N26: 30.009444 | O26: 0.71701306 | Q26: 27.300641 | R26: 0.66594802 | T26: 11.674305 | U26: 0.47279022 | W26: 23.139985 | X26: 0.62226518 | Z26: 27.353439 | AA26: 0.6078868 | AC26: 37.832271 | AD26: 0.81172697 | AF26: 10.368145 | AG26: 0.48277037 | AI26: 20.874656 | AJ26: 0.61142231 | AL26: 28.898358 | AM26: 0.68917771 | AO26: 39.858841 | AP26: 0.78577681 | AR26: 13.492029 | AS26: 0.58686513 | AU26: 20.690816 | AV26: 0.56326143 | AX26: 28.076057 | AY26: 0.58655901 | BA26: 37.741098 | BB26: 0.78280175
A27: Germany | B27: -0.23656022 | C27: 0.01875665 | E27: 1.0017877 | F27: 0.011913009 | H27: 13.598094 | I27: 0.59211505 | K27: 25.259536 | L27: 0.73908142 | N27: 32.106789 | O27: 0.6491452 | Q27: 29.035581 | R27: 0.73374696 | T27: 8.0426044 | U27: 0.49511548 | W27: 19.410846 | X27: 0.61518619 | Z27: 29.482134 | AA27: 0.66670005 | AC27: 43.064415 | AD27: 0.76139385 | AF27: 13.401933 | AG27: 0.66109397 | AI27: 23.455096 | AJ27: 0.60995063 | AL27: 30.007291 | AM27: 0.70891709 | AO27: 33.13568 | AP27: 0.6630109 | AR27: 11.311046 | AS27: 0.64934909 | AU27: 25.19449 | AV27: 0.63768382 | AX27: 30.765926 | AY27: 0.71818471 | BA27: 32.728539 | BB27: 0.74570863
A28: Greece | B28: -0.17064699 | C28: 0.020642879 | E28: 0.98566933 | F28: 0.010654999 | H28: 17.603986 | I28: 0.60383289 | K28: 26.347373 | L28: 0.55998984 | N28: 27.271988 | O28: 0.64796854 | Q28: 28.776654 | R28: 0.70584606 | T28: 9.8371724 | U28: 0.52734305 | W28: 23.200264 | X28: 0.5985807 | Z28: 29.596254 | AA28: 0.61150257 | AC28: 37.366309 | AD28: 0.81901918 | AF28: 6.2905942 | AG28: 0.40094905 | AI28: 18.791931 | AJ28: 0.5448517 | AL28: 29.193162 | AM28: 0.60903573 | AO28: 45.724313 | AP28: 0.88137389 | AR28: 13.164614 | AS28: 0.5416681 | AU28: 25.2524 | AV28: 0.63437041 | AX28: 28.624343 | AY28: 0.57851573 | BA28: 32.958643 | BB28: 0.8092845
A29: Hungary | B29: -0.15823919 | C29: 0.02157314 | E29: 0.99251865 | F29: 0.010233097 | H29: 7.7838015 | I29: 0.44667735 | K29: 19.632145 | L29: 0.64897603 | N29: 35.323429 | O29: 0.75197778 | Q29: 37.260625 | R29: 0.82749522 | T29: 8.270737 | U29: 0.45074925 | W29: 19.18545 | X29: 0.75220879 | Z29: 31.341665 | AA29: 0.78022908 | AC29: 41.202148 | AD29: 0.94119653 | AF29: 11.114304 | AG29: 0.51200181 | AI29: 21.23055 | AJ29: 0.67912551 | AL29: 30.622282 | AM29: 0.72279205 | AO29: 37.032863 | AP29: 0.86653557 | AR29: 13.779521 | AS29: 0.68818517 | AU29: 22.59308 | AV29: 0.63675238 | AX29: 31.930843 | AY29: 0.68809001 | BA29: 31.696556 | BB29: 0.93437811
A30: Iceland | B30: 0.21067868 | C30: 0.016453937 | E30: 0.9602258 | F30: 0.01267101 | H30: 5.203002 | I30: 0.34183925 | K30: 17.921339 | L30: 0.65633893 | N30: 37.486315 | O30: 0.84886851 | Q30: 39.389345 | R30: 0.89057384 | T30: 5.3636477 | U30: 0.43813283 | W30: 17.402571 | X30: 0.69317938 | Z30: 33.044683 | AA30: 0.81836982 | AC30: 44.189099 | AD30: 0.74928214 | AF30: 2.7878697 | AG30: 0.30857801 | AI30: 11.679766 | AJ30: 0.58875223 | AL30: 31.111629 | AM30: 0.76809051 | AO30: 54.420736 | AP30: 0.75999348 | AR30: 4.3661312 | AS30: 0.35376173 | AU30: 15.991705 | AV30: 0.71766495 | AX30: 32.478516 | AY30: 0.85121708 | BA30: 47.163647 | BB30: 0.92623735
A31: Ireland | B31: 0.1576429 | C31: 0.020628086 | E31: 0.98611623 | F31: 0.010548558 | H31: 5.736326 | I31: 0.35169665 | K31: 17.834258 | L31: 0.57946177 | N31: 30.326197 | O31: 0.6742573 | Q31: 46.103219 | R31: 0.98793073 | T31: 6.4738234 | U31: 0.40678461 | W31: 18.678337 | X31: 0.60697493 | Z31: 28.583259 | AA31: 0.62752558 | AC31: 46.26458 | AD31: 0.90111688 | AF31: 4.2002849 | AG31: 0.32676376 | AI31: 14.665146 | AJ31: 0.51208322 | AL31: 27.099714 | AM31: 0.6802295 | AO31: 54.034855 | AP31: 0.95805365 | AR31: 8.0427538 | AS31: 0.4338623 | AU31: 18.244158 | AV31: 0.60200855 | AX31: 29.954814 | AY31: 0.64364358 | BA31: 43.758273 | BB31: 0.88375892
... A53: OECD average | B53: 0.010582953 | C53: 0.00313966 | E53: 0.96388562 | F53: 0.0017099103 | H53: 8.6403885 | I53: 0.07407856 | K53: 20.403009 | L53: 0.10256933 | N53: 32.797431 | O53: 0.11289869 | Q53: 38.159172 | R53: 0.13844876 | T53: 6.7819059 | U53: 0.06660657 | W53: 18.519357 | X53: 0.10267759 | Z53: 30.752324 | AA53: 0.11025815 | AC53: 43.946413 | AD53: 0.14189125 | AF53: 7.3464012 | AG53: 0.069079522 | AI53: 17.07345 | AJ53: 0.096422033 | AL53: 29.524559 | AM53: 0.11174093 | AO53: 46.055589 | AP53: 0.13924971 | AR53: 8.711501 | AS53: 0.078025899 | AU53: 20.803448 | AV53: 0.10485239 | AX53: 31.106334 | AY53: 0.10997891 | BA53: 39.378717 | BB53: 0.1389305
A54: Partners
A55: Albania | B55: 0.71671868 | C55: 0.01431473 | E55: 0.79997299 | F55: 0.013816265 | H55: 7.3665518 | I55: 0.34997312 | K55: 5.4707545 | L55: 0.37659067 | N55: 11.215768 | O55: 0.44583148 | Q55: 75.946926 | R55: 0.74480342 | T55: 2.8898738 | U55: 0.22965677 | W55: 9.7561648 | X55: 0.48661746 | Z55: 20.004381 | AA55: 0.59850926 | AC55: 67.34958 | AD55: 0.7988527 | AF55: 1.9617218 | AG55: 0.21473032 | AI55: 4.804093 | AJ55: 0.31333363 | AL55: 11.36706 | AM55: 0.49772926 | AO55: 81.867125 | AP55: 0.61547823 | AR55: 2.4664152 | AS55: 0.25144576 | AU55: 5.8282388 | AV55: 0.34743587 | AX55: 13.181924 | AY55: 0.50599601 | BA55: 78.523422 | BB55: 0.70105548
A56: Argentina | B56: 0.39044525 | C56: 0.022342185 | E56: 0.91394159 | F56: 0.016310198 | H56: 3.3455983 | I56: 0.42950004 | K56: 10.942026 | L56: 0.51675156 | N56: 17.768576 | O56: 0.51090865 | Q56: 67.943799 | R56: 0.93426342 | T56: 5.8876769 | U56: 0.43771746 | W56: 15.378866 | X56: 0.54337318 | Z56: 23.532159 | AA56: 0.63984464 | AC56: 55.201299 | AD56: 0.91067165 | AF56: 2.946818 | AG56: 0.29241298 | AI56: 10.931117 | AJ56: 0.46996809 | AL56: 21.477461 | AM56: 0.60810009 | AO56: 64.644604 | AP56: 0.93556741 | AR56: 5.8236457 | AS56: 0.51465957 | AU56: 16.735734 | AV56: 0.55252698 | AX56: 21.690627 | AY56: 0.55754984 | BA56: 55.749993 | BB56: 1.012659
A57: Baku (Azerbaijan) | B57: 0.50224932 | C57: 0.013873095 | E57: 0.92935902 | F57: 0.011278421 | H57: 4.3790453 | I57: 0.29116224 | K57: 9.4386518 | L57: 0.39724344 | N57: 20.166812 | O57: 0.52015197 | Q57: 66.015491 | R57: 0.67102038 | T57: 4.4980764 | U57: 0.27834292 | W57: 15.518771 | X57: 0.46278405 | Z57: 21.710401 | AA57: 0.64737188 | AC57: 58.272752 | AD57: 0.69653769 | AF57: 2.7134328 | AG57: 0.22476447 | AI57: 8.2153841 | AJ57: 0.37057213 | AL57: 19.062396 | AM57: 0.46695028 | AO57: 70.008787 | AP57: 0.62617824 | AR57: 4.5677642 | AS57: 0.275976 | AU57: 12.30044 | AV57: 0.47599601 | AX57: 18.839967 | AY57: 0.63280712 | BA57: 64.291829 | BB57: 0.70700991
A58: Belarus | B58: 0.37401833 | C58: 0.019127049 | E58: 0.88350353 | F58: 0.011102206 | H58: 3.4725661 | I58: 0.28064126 | K58: 10.603279 | L58: 0.52191719 | N58: 24.768119 | O58: 0.61966076 | Q58: 61.156036 | R58: 0.88570496 | T58: 3.6808443 | U58: 0.29728137 | W58: 14.024483 | X58: 0.52735444 | Z58: 28.277091 | AA58: 0.66995922 | AC58: 54.017582 | AD58: 0.93501004 | AF58: 2.2693742 | AG58: 0.24069648 | AI58: 9.0022455 | AJ58: 0.46057367 | AL58: 21.81357 | AM58: 0.58113563 | AO58: 66.91481 | AP58: 0.84396128 | AR58: 6.3193019 | AS58: 0.42262914 | AU58: 18.033663 | AV58: 0.63762532 | AX58: 29.522781 | AY58: 0.61807049 | BA58: 46.124253 | BB58: 0.95445886
A59: Bosnia and Herzegovina | B59: -0.029273797 | C59: 0.023946923 | E59: 1.0659756 | F59: 0.011906736 | H59: 8.4819118 | I59: 0.5364314 | K59: 16.042331 | L59: 0.65433831 | N59: 25.54715 | O59: 0.68059824 | Q59: 49.928607 | R59: 0.95799758 | T59: 6.7023145 | U59: 0.42512515 | W59: 16.823872 | X59: 0.72459188 | Z59: 26.024505 | AA59: 0.62567116 | AC59: 50.449308 | AD59: 0.91729865 | AF59: 13.800823 | AG59: 0.63812681 | AI59: 23.529415 | AJ59: 0.55833923 | AL59: 24.049811 | AM59: 0.57820884 | AO59: 38.619951 | AP59: 0.88149221 | AR59: 10.759883 | AS59: 0.60149944 | AU59: 20.720662 | AV59: 0.62837347 | AX59: 24.707279 | AY59: 0.53509721 | BA59: 43.812175 | BB59: 0.88715657
A60: Brazil | B60: 0.43221611 | C60: 0.012472201 | E60: 0.90650333 | F60: 0.011167661 | H60: 3.4806466 | I60: 0.27512386 | K60: 10.510788 | L60: 0.38010062 | N60: 19.634052 | O60: 0.47258675 | Q60: 66.374514 | R60: 0.63855539 | T60: 5.93962 | U60: 0.31652933 | W60: 16.298449 | X60: 0.45081539 | Z60: 25.048972 | AA60: 0.57938187 | AC60: 52.712959 | AD60: 0.60128415 | AF60: 2.2071964 | AG60: 0.22038456 | AI60: 10.024412 | AJ60: 0.35774534 | AL60: 20.383825 | AM60: 0.4634356 | AO60: 67.384567 | AP60: 0.53995434 | AR60: 4.9194892 | AS60: 0.29924744 | AU60: 13.476767 | AV60: 0.35221545 | AX60: 21.047636 | AY60: 0.47215319 | BA60: 60.556108 | BB60: 0.59395916
A61: Brunei Darussalam | B61: 0.22696088 | C61: 0.0094355212 | E61: 0.78181568 | F61: 0.0071810026 | H61: 3.7182571 | I61: 0.2576299 | K61: 25.348927 | L61: 0.52463795 | N61: 36.679491 | O61: 0.63391316 | Q61: 34.253325 | R61: 0.61237624 | T61: 2.4146037 | U61: 0.18900357 | W61: 16.371782 | X61: 0.44576264 | Z61: 32.575088 | AA61: 0.59749486 | AC61: 48.638526 | AD61: 0.6618477 | AF61: 1.3209703 | AG61: 0.13797518 | AI61: 11.128922 | AJ61: 0.41601153 | AL61: 29.756884 | AM61: 0.58337699 | AO61: 57.793224 | AP61: 0.64845857 | AR61: 2.8478481 | AS61: 0.18549199 | AU61: 14.771904 | AV61: 0.40835039 | AX61: 31.234423 | AY61: 0.69506568 | BA61: 51.145825 | BB61: 0.64738485
A62: B-S-J-Z (China) | B62: 0.36280115 | C62: 0.017596311 | E62: 0.89018791 | F62: 0.0089417828 | H62: 3.537626 | I62: 0.24544802 | K62: 13.312223 | L62: 0.65082653 | N62: 29.070445 | O62: 0.67447234 | Q62: 54.079706 | R62: 1.0695745 | T62: 3.1067306 | U62: 0.26536985 | W62: 11.354276 | X62: 0.44519946 | Z62: 23.073351 | AA62: 0.53138748 | AC62: 62.465642 | AD62: 0.8065754 | AF62: 3.439499 | AG62: 0.29203407 | AI62: 10.81966 | AJ62: 0.42323433 | AL62: 21.993394 | AM62: 0.67149851 | AO62: 63.747448 | AP62: 0.90616333 | AR62: 5.0195807 | AS62: 0.32168388 | AU62: 18.763136 | AV62: 0.57037294 | AX62: 30.761682 | AY62: 0.58161311 | BA62: 45.455602 | BB62: 0.86003091
A63: Bulgaria | B63: 0.099598215 | C63: 0.022695726 | E63: 1.0852635 | F63: 0.012507329 | H63: 8.6938998 | I63: 0.44228803 | K63: 14.813956 | L63: 0.54122745 | N63: 25.95296 | O63: 0.78790834 | Q63: 50.539184 | R63: 0.86704421 | T63: 11.074094 | U63: 0.64833416 | W63: 19.019614 | X63: 0.64660778 | Z63: 24.279669 | AA63: 0.61544463 | AC63: 45.626623 | AD63: 1.0524188 | AF63: 10.772765 | AG63: 0.56424697 | AI63: 15.488547 | AJ63: 0.57983789 | AL63: 21.573334 | AM63: 0.75921241 | AO63: 52.165354 | AP63: 1.0408834 | AR63: 9.5613136 | AS63: 0.54296146 | AU63: 15.242845 | AV63: 0.57505064 | AX63: 21.558491 | AY63: 0.66310851 | BA63: 53.637351 | BB63: 0.97429387
A64: Costa Rica | B64: 0.47093266 | C64: 0.016576158 | E64: 0.90278339 | F64: 0.0090494679 | H64: 2.9292443 | I64: 0.21810136 | K64: 8.1754789 | L64: 0.42652515 | N64: 18.030735 | O64: 0.57624267 | Q64: 70.864541 | R64: 0.76756304 | T64: 5.1050374 | U64: 0.269622 | W64: 13.399151 | X64: 0.49183162 | Z64: 23.288022 | AA64: 0.63424968 | AC64: 58.20779 | AD64: 0.74112124 | AF64: 2.5565613 | AG64: 0.19963114 | AI64: 9.2212092 | AJ64: 0.48869962 | AL64: 20.768042 | AM64: 0.5670788 | AO64: 67.454188 | AP64: 0.81628975 | AR64: 4.8755503 | AS64: 0.29011323 | AU64: 15.268793 | AV64: 0.60846375 | AX64: 23.826209 | AY64: 0.49200356 | BA64: 56.029448 | BB64: 0.90825741
...

Sheet Table III.B1.6.2
A1: PISA 2018 Results (Volume III) - © OECD 2019
A2: Annex B1 | B2: Annex B1.6 Results (tables): Teachers' support and teaching practices
A3: Version 2 - Last updated: 02-Dec-2019
A4: Disclaimer: http://oe.cd/disclaimer
A6: Table III.B1.6.2
A7: Teacher emotional support
A8: Based on students' reports
B11: Percentage of students who reported the following occurred during the previous two language-of-instruction lessons:
B12: The teacher made me feel confident in my ability to do well in the course | N12: The teacher listened to my view on how to do things | Z12: I felt that my teacher understood me
B13: Strongly disagree | E13: Disagree | H13: Agree | K13: Strongly agree | N13: Strongly disagree | Q13: Disagree | T13: Agree | W13: Strongly agree | Z13: Strongly disagree | AC13: Disagree | AF13: Agree | AI13: Strongly agree
B14: % | C14: S.E. | E14: % | F14: S.E. | H14: % | I14: S.E. | K14: % | L14: S.E. | N14: % | O14: S.E. | Q14: % | R14: S.E. | T14: % | U14: S.E. | W14: % | X14: S.E. | Z14: % | AA14: S.E. | AC14: % | AD14: S.E. | AF14: % | AG14: S.E. | AI14: % | AJ14: S.E.
A15: OECD
A16: Australia | B16: 7.9490173 | C16: 0.29530581 | E16: 13.858209 | F16: 0.4306808 | H16: 56.034651 | I16: 0.61223091 | K16: 22.158123 | L16: 0.47906727 | N16: 8.6935336 | O16: 0.3072587 | Q16: 17.718176 | R16: 0.40443125 | T16: 55.054477 | U16: 0.45969876 | W16: 18.533813 | X16: 0.41753108 | Z16: 9.2021406 | AA16: 0.29179697 | AC16: 16.625312 | AD16: 0.38530206 | AF16: 53.436741 | AG16: 0.4568648 | AI16: 20.735807 | AJ16: 0.38155899
A17: Austria | B17: 18.020323 | C17: 0.65120538 | E17: 23.013685 | F17: 0.6141384 | H17: 39.334213 | I17: 0.60632499 | K17: 19.631779 | L17: 0.64712814 | N17: 15.741359 | O17: 0.54513549 | Q17: 24.314698 | R17: 0.67609057 | T17: 39.288991 | U17: 0.63666916 | W17: 20.654952 | X17: 0.62961029 | Z17: 13.7216 | AA17: 0.49358894 | AC17: 19.160831 | AD17: 0.53013948 | AF17: 39.765408 | AG17: 0.63182576 | AI17: 27.352161 | AJ17: 0.82069463
A18: Belgium | B18: 7.8791336 | C18: 0.40266393 | E18: 16.94053 | F18: 0.65958723 | H18: 57.479469 | I18: 0.74080878 | K18: 17.700868 | L18: 0.47171251 | N18: 8.986872 | O18: 0.44328617 | Q18: 20.271822 | R18: 0.59029548 | T18: 56.211995 | U18: 0.78340486 | W18: 14.529311 | X18: 0.48800573 | Z18: 10.045746 | AA18: 0.4092764 | AC18: 20.51357 | AD18: 0.59373028 | AF18: 54.050093 | AG18: 0.72557269 | AI18: 15.390591 | AJ18: 0.4804346
A19: Canada | B19: m | C19: m | E19: m | F19: m | H19: m | I19: m | K19: m | L19: m | N19: m | O19: m | Q19: m | R19: m | T19: m | U19: m | W19: m | X19: m | Z19: m | AA19: m | AC19: m | AD19: m | AF19: m | AG19: m | AI19: m | AJ19: m
A20: Chile | B20: 13.067515 | C20: 0.44232808 | E20: 10.664871 | F20: 0.46092562 | H20: 50.064031 | I20: 0.77840085 | K20: 26.203583 | L20: 0.79784416 | N20: 13.30357 | O20: 0.4552515 | Q20: 14.048009 | R20: 0.49269932 | T20: 48.131974 | U20: 0.78545966 | W20: 24.516447 | X20: 0.83433954 | Z20: 13.571155 | AA20: 0.43525498 | AC20: 15.054216 | AD20: 0.56438244 | AF20: 46.301216 | AG20: 0.71344897 | AI20: 25.073413 | AJ20: 0.81234156
A21: Colombia | B21: 9.432072 | C21: 0.44801536 | E21: 8.7365529 | F21: 0.40884127 | H21: 56.145002 | I21: 0.81096113 | K21: 25.686373 | L21: 0.67270828 | N21: 9.3130288 | O21: 0.40864376 | Q21: 13.959252 | R21: 0.54315052 | T21: 55.0094 | U21: 0.71133708 | W21: 21.718319 | X21: 0.68316959 | Z21: 9.5948022 | AA21: 0.43220391 | AC21: 13.785807 | AD21: 0.5816737 | AF21: 55.008627 | AG21: 0.76351985 | AI21: 21.610764 | AJ21: 0.63370814
A22: Czech Republic | B22: 13.564983 | C22: 0.56679429 | E22: 31.276202 | F22: 0.72154646 | H22: 46.392168 | I22: 0.90193668 | K22: 8.7666481 | L22: 0.39556571 | N22: 14.147234 | O22: 0.59505754 | Q22: 32.904236 | R22: 0.71375487 | T22: 45.053613 | U22: 0.85431359 | W22: 7.8949172 | X22: 0.447199 | Z22: 13.464768 | AA22: 0.6121181 | AC22: 26.638451 | AD22: 0.71040149 | AF22: 49.411797 | AG22: 0.80910289 | AI22: 10.484984 | AJ22: 0.49460356
A23: Denmark | B23: 5.266748 | C23: 0.36807431 | E23: 12.348843 | F23: 0.49624127 | H23: 59.952417 | I23: 0.62754273 | K23: 22.431992 | L23: 0.73542207 | N23: 7.1265575 | O23: 0.40485222 | Q23: 19.739072 | R23: 0.84132548 | T23: 57.229986 | U23: 0.82981574 | W23: 15.904385 | X23: 0.62704839 | Z23: 6.0643006 | AA23: 0.38892049 | AC23: 13.857782 | AD23: 0.6778221 | AF23: 57.736704 | AG23: 0.74415813 | AI23: 22.341213 | AJ23: 0.72291807
A24: Estonia | B24: 11.715212 | C24: 0.47537543 | E24: 24.807016 | F24: 0.72034654 | H24: 50.982898 | I24: 0.78085864 | K24: 12.494874 | L24: 0.56291266 | N24: 12.505727 | O24: 0.53642111 | Q24: 24.684919 | R24: 0.64272404 | T24: 49.975537 | U24: 0.80431025 | W24: 12.833817 | X24: 0.48775117 | Z24: 10.603296 | AA24: 0.46327054 | AC24: 18.970735 | AD24: 0.53898155 | AF24: 55.008272 | AG24: 0.62870513 | AI24: 15.417697 | AJ24: 0.56926532
A25: Finland | B25: 8.2784404 | C25: 0.43586621 | E25: 19.505064 | F25: 0.63753369 | H25: 55.796175 | I25: 0.84370709 | K25: 16.420321 | L25: 0.66179165 | N25: 9.4962209 | O25: 0.46716874 | Q25: 21.869881 | R25: 0.61545871 | T25: 55.749007 | U25: 0.83627448 | W25: 12.884891 | X25: 0.50020317 | Z25: 8.9696979 | AA25: 0.46297463 | AC25: 18.271558 | AD25: 0.57759782 | AF25: 55.947372 | AG25: 0.86657451 | AI25: 16.811373 | AJ25: 0.67965956
A26: France | B26: 15.312705 | C26: 0.64164748 | E26: 23.554678 | F26: 0.59089157 | H26: 46.618338 | I26: 0.80047977 | K26: 14.514278 | L26: 0.55476665 | N26: 16.381146 | O26: 0.5440312 | Q26: 24.608984 | R26: 0.59486759 | T26: 45.965045 | U26: 0.76161683 | W26: 13.044824 | X26: 0.47930673 | Z26: 17.28751 | AA26: 0.59663956 | AC26: 23.150074 | AD26: 0.55521726 | AF26: 45.243804 | AG26: 0.70649635 | AI26: 14.318611 | AJ26: 0.44780044
A27: Germany | B27: 14.176829 | C27: 0.5682203 | E27: 25.448635 | F27: 0.67615279 | H27: 43.069077 | I27: 0.87166222 | K27: 17.305459 | L27: 0.63273845 | N27: 13.622234 | O27: 0.54706084 | Q27: 26.188418 | R27: 0.66874267 | T27: 42.41136 | U27: 0.89599418 | W27: 17.777987 | X27: 0.64617945 | Z27: 10.574607 | AA27: 0.46594978 | AC27: 20.215271 | AD27: 0.60089387 | AF27: 45.666043 | AG27: 0.77261614 | AI27: 23.54408 | AJ27: 0.64892634
A28: Greece | B28: 7.5975722 | C28: 0.45561571 | E28: 17.321597 | F28: 0.47023347 | H28: 56.70622 | I28: 0.70066658 | K28: 18.374611 | L28: 0.56908876 | N28: 8.7960957 | O28: 0.43503994 | Q28: 20.902501 | R28: 0.54057862 | T28: 52.972342 | U28: 0.61206325 | W28: 17.329061 | X28: 0.56659697 | Z28: 10.482929 | AA28: 0.45147301 | AC28: 21.296591 | AD28: 0.52433526 | AF28: 50.360669 | AG28: 0.63245535 | AI28: 17.859811 | AJ28: 0.56832316
A29: Hungary | B29: 8.5830813 | C29: 0.45737003 | E29: 16.766412 | F29: 0.63351688 | H29: 56.155204 | I29: 0.79748618 | K29: 18.495303 | L29: 0.58141569 | N29: 12.652906 | O29: 0.53111826 | Q29: 23.735465 | R29: 0.67084532 | T29: 49.767663 | U29: 0.80945399 | W29: 13.843965 | X29: 0.51627868 | Z29: 10.980676 | AA29: 0.4915565 | AC29: 19.524212 | AD29: 0.58952776 | AF29: 52.070625 | AG29: 0.74363713 | AI29: 17.424486 | AJ29: 0.55472941
A30: Iceland | B30: 15.178546 | C30: 0.69322763 | E30: 16.458792 | F30: 0.64856771 | H30: 47.070843 | I30: 1.0465634 | K30: 21.291818 | L30: 0.78989193 | N30: 11.874395 | O30: 0.52318742 | Q30: 16.440197 | R30: 0.61660582 | T30: 51.497875 | U30: 0.77355634 | W30: 20.187534 | X30: 0.7418243 | Z30: 12.064536 | AA30: 0.56561206 | AC30: 15.457721 | AD30: 0.68647841 | AF30: 49.281021 | AG30: 0.83385073 | AI30: 23.196722 | AJ30: 0.68575603
A31: Ireland | B31: 6.1360926 | C31: 0.3488394 | E31: 15.741701 | F31: 0.59260362 | H31: 55.753458 | I31: 0.70295075 | K31: 22.368749 | L31: 0.68520132 | N31: 6.9915879 | O31: 0.35976725 | Q31: 21.499635 | R31: 0.69018659 | T31: 55.833153 | U31: 0.77914073 | W31: 15.675625 | X31: 0.62236811 | Z31: 6.1574049 | AA31: 0.3374964 | AC31: 18.207415 | AD31: 0.57650252 | AF31: 56.932524 | AG31: 0.71432438 | AI31: 18.702657 | AJ31: 0.64413158
... A53: OECD average | B53: 10.534268 | C53: 0.079953145 | E53: 18.477846 | F53: 0.10073232 | H53: 52.097405 | I53: 0.12677628 | K53: 18.89048 | L53: 0.10676146 | N53: 11.260402 | O53: 0.07910854 | Q53: 21.668409 | R53: 0.1051871 | T53: 50.672967 | U53: 0.12391743 | W53: 16.398223 | X53: 0.098362122 | Z53: 10.790857 | AA53: 0.078244673 | AC53: 19.048353 | AD53: 0.098904143 | AF53: 51.03561 | AG53: 0.12088138 | AI53: 19.125181 | AJ53: 0.10589904
A54: Partners
A55: Albania | B55: 4.8546879 | C55: 0.30844992 | E55: 3.9162401 | F55: 0.27519194 | H55: 45.390854 | I55: 0.82158641 | K55: 45.838218 | L55: 0.74410411 | N55: 6.0653565 | O55: 0.36347129 | Q55: 10.142038 | R55: 0.40898443 | T55: 48.557537 | U55: 0.69831916 | W55: 35.235069 | X55: 0.73881501 | Z55: 5.9221797 | AA55: 0.35225642 | AC55: 7.5046132 | AD55: 0.35279095 | AF55: 46.054446 | AG55: 0.83732175 | AI55: 40.518762 | AJ55: 0.8428573
A56: Argentina | B56: 9.4713713 | C56: 0.51216054 | E56: 13.912603 | F56: 0.55477513 | H56: 55.92144 | I56: 0.67125666 | K56: 20.694586 | L56: 0.5841655 | N56: 9.2137449 | O56: 0.42213855 | Q56: 20.369341 | R56: 0.62798316 | T56: 53.487062 | U56: 0.5977423 | W56: 16.929852 | X56: 0.59938343 | Z56: 9.4817219 | AA56: 0.54795291 | AC56: 16.203148 | AD56: 0.52646273 | AF56: 52.531918 | AG56: 0.6860113 | AI56: 21.783212 | AJ56: 0.57164162
A57: Baku (Azerbaijan) | B57: 18.627691 | C57: 0.57689549 | E57: 9.7097953 | F57: 0.44680559 | H57: 42.176869 | I57: 0.63320912 | K57: 29.485645 | L57: 0.69538519 | N57: 16.969421 | O57: 0.53143369 | Q57: 10.973719 | R57: 0.56274277 | T57: 47.063513 | U57: 0.72198903 | W57: 24.993346 | X57: 0.68457209 | Z57: 17.246679 | AA57: 0.57286151 | AC57: 9.039576 | AD57: 0.39720019 | AF57: 45.946707 | AG57: 0.76788734 | AI57: 27.767038 | AJ57: 0.71270165
A58: Belarus | B58: 6.9356124 | C58: 0.40314385 | E58: 16.54965 | F58: 0.58323913 | H58: 59.231089 | I58: 0.71635717 | K58: 17.283648 | L58: 0.59383509 | N58: 7.4770886 | O58: 0.36492432 | Q58: 20.583708 | R58: 0.62837027 | T58: 57.432603 | U58: 0.72346122 | W58: 14.506601 | X58: 0.52057693 | Z58: 7.0246651 | AA58: 0.35766502 | AC58: 17.684593 | AD58: 0.64562721 | AF58: 56.556854 | AG58: 0.78355055 | AI58: 18.733888 | AJ58: 0.67234222
A59: Bosnia and Herzegovina | B59: 12.422886 | C59: 0.57963568 | E59: 14.274914 | F59: 0.55141898 | H59: 54.928998 | I59: 0.77835624 | K59: 18.373201 | L59: 0.6149263 | N59: 13.208039 | O59: 0.60620809 | Q59: 21.672925 | R59: 0.5737641 | T59: 51.361218 | U59: 0.73346283 | W59: 13.757818 | X59: 0.54258658 | Z59: 13.130719 | AA59: 0.56389955 | AC59: 17.891419 | AD59: 0.61153108 | AF59: 51.017706 | AG59: 0.76057448 | AI59: 17.960156 | AJ59: 0.51487617
A60: Brazil | B60: 9.9418913 | C60: 0.37784844 | E60: 18.66421 | F60: 0.44640562 | H60: 54.975864 | I60: 0.55999543 | K60: 16.418035 | L60: 0.44989351 | N60: 9.6357892 | O60: 0.36522487 | Q60: 23.004536 | R60: 0.59945748 | T60: 53.969777 | U60: 0.63966444 | W60: 13.389898 | X60: 0.40641082 | Z60: 10.182254 | AA60: 0.37477031 | AC60: 21.486148 | AD60: 0.49807992 | AF60: 51.538898 | AG60: 0.58332812 | AI60: 16.7927 | AJ60: 0.45021728
A61: Brunei Darussalam | B61: 3.3727316 | C61: 0.20183367 | E61: 9.8059959 | F61: 0.34030587 | H61: 66.740203 | I61: 0.5077821 | K61: 20.08107 | L61: 0.4581021 | N61: 3.9800445 | O61: 0.23481609 | Q61: 18.534573 | R61: 0.41487664 | T61: 66.15443 | U61: 0.49716757 | W61: 11.330952 | X61: 0.36417448 | Z61: 6.0575201 | AA61: 0.26850706 | AC61: 20.487862 | AD61: 0.46882516 | AF61: 59.35947 | AG61: 0.6101901 | AI61: 14.095147 | AJ61: 0.36543407
A62: B-S-J-Z (China) | B62: 4.9042276 | C62: 0.32534728 | E62: 12.712591 | F62: 0.4339595 | H62: 56.465753 | I62: 0.67030462 | K62: 25.917429 | L62: 0.80031852 | N62: 5.4500947 | O62: 0.3674358 | Q62: 13.548508 | R62: 0.5433017 | T62: 55.331498 | U62: 0.66255646 | W62: 25.669899 | X62: 0.85099698 | Z62: 6.4571998 | AA62: 0.33459473 | AC62: 16.379557 | AD62: 0.53320851 | AF62: 52.580674 | AG62: 0.61716157 | AI62: 24.582569 | AJ62: 0.71654335
A63: Bulgaria | B63: 16.669543 | C63: 0.71852004 | E63: 15.006543 | F63: 0.65269711 | H63: 46.291608 | I63: 0.81964912 | K63: 22.032306 | L63: 0.80534103 | N63: 12.212958 | O63: 0.53177724 | Q63: 14.49637 | R63: 0.65373624 | T63: 49.715933 | U63: 0.65883099 | W63: 23.574738 | X63: 0.77977122 | Z63: 14.335586 | AA63: 0.63359823 | AC63: 15.333957 | AD63: 0.58006509 | AF63: 47.964696 | AG63: 0.87004571 | AI63: 22.365761 | AJ63: 0.83043763
A64: Costa Rica | B64: 10.184473 | C64: 0.40418983 | E64: 9.8011841 | F64: 0.49687352 | H64: 49.370352 | I64: 0.70574956 | K64: 30.643991 | L64: 0.81719128 | N64: 10.585164 | O64: 0.47558125 | Q64: 15.33914 | R64: 0.49829069 | T64: 50.91904 | U64: 0.73755707 | W64: 23.156656 | X64: 0.72164425 | Z64: 10.657449 | AA64: 0.48684606 | AC64: 12.574257 | AD64: 0.57717234 | AF64: 51.099548 | AG64: 0.64271365 | AI64: 25.668746 | AJ64: 0.71746193
...

Sheet Table III.B1.6.3
A1: PISA 2018 Results (Volume III) - © OECD 2019
A2: Annex B1 | B2: Annex B1.6 Results (tables): Teachers' support and teaching practices
A3: Version 2 - Last updated: 02-Dec-2019
A4: Disclaimer: http://oe.cd/disclaimer
A6: Table III.B1.6.3
A7: Teacher feedback
A8: Based on students' reports
B11: Index of perceived feedback | H11: Percentage of students who reported the following things occur in their language-of-instruction lessons:
H12: The teacher gives me feedback on my strengths in this subject | T12: The teacher tells me in which areas I can still improve | AF12: The teacher tells me how I can improve my performance
B13: Average | E13: Variability | H13: Never or almost never | K13: Some lessons | N13: Many lessons | Q13: Every lesson or almost every lesson | T13: Never or almost never | W13: Some lessons | Z13: Many lessons | AC13: Every lesson or almost every lesson | AF13: Never or almost never | AI13: Some lessons | AL13: Many lessons | AO13: Every lesson or almost every lesson
B14: Mean index | C14: S.E. | E14: S.D. | F14: S.E. | H14: % | I14: S.E. | K14: % | L14: S.E. | N14: % | O14: S.E. | Q14: % | R14: S.E. | T14: % | U14: S.E. | W14: % | X14: S.E. | Z14: % | AA14: S.E. | AC14: % | AD14: S.E. | AF14: % | AG14: S.E. | AI14: % | AJ14: S.E. | AL14: % | AM14: S.E. | AO14: % | AP14: S.E.
A15: OECD
A16: Australia | B16: 0.35463609 | C16: 0.010455967 | E16: 0.99371515 | F16: 0.0068582693 | H16: 13.259421 | I16: 0.40162185 | K16: 35.169224 | L16: 0.42661278 | N16: 35.251788 | O16: 0.49640896 | Q16: 16.319567 | R16: 0.34014452 | T16: 10.563766 | U16: 0.33116319 | W16: 32.178812 | X16: 0.44667135 | Z16: 38.763398 | AA16: 0.51424233 | AC16: 18.494025 | AD16: 0.39716617 | AF16: 11.4211 | AG16: 0.32684691 | AI16: 32.632585 | AJ16: 0.44604811 | AL16: 37.220075 | AM16: 0.46220304 | AO16: 18.72624 | AP16: 0.43747402
A17: Austria | B17: -0.036971933 | C17: 0.016905921 | E17: 0.98072592 | F17: 0.0081894221 | H17: 37.825831 | I17: 0.7898843 | K17: 32.549092 | L17: 0.73791778 | N17: 21.014045 | O17: 0.5635719 | Q17: 8.611031 | R17: 0.4459316 | T17: 17.65071 | U17: 0.54472864 | W17: 38.759689 | X17: 0.7967246 | Z17: 30.684073 | AA17: 0.69282567 | AC17: 12.905527 | AD17: 0.46351687 | AF17: 20.698364 | AG17: 0.57368166 | AI17: 36.636971 | AJ17: 0.82424966 | AL17: 29.445296 | AM17: 0.72187822 | AO17: 13.219369 | AP17: 0.54003804
A18: Belgium | B18: -0.32354612 | C18: 0.013635331 | E18: 0.89123504 | F18: 0.006931611 | H18: 41.155709 | I18: 0.79914503 | K18: 37.567855 | L18: 0.63832105 | N18: 16.726868 | O18: 0.43930282 | Q18: 4.5495675 | R18: 0.27687069 | T18: 28.109487 | U18: 0.75411565 | W18: 42.479036 | X18: 0.62004246 | Z18: 23.233347 | AA18: 0.52790634 | AC18: 6.1781308 | AD18: 0.25375095 | AF18: 25.589431 | AG18: 0.61702333 | AI18: 42.611941 | AJ18: 0.54012153 | AL18: 23.896527 | AM18: 0.54211533 | AO18: 7.9021015 | AP18: 0.32908852
A19: Canada | B19: m | C19: m | E19: m | F19: m | H19: m | I19: m | K19: m | L19: m | N19: m | O19: m | Q19: m | R19: m | T19: m | U19: m | W19: m | X19: m | Z19: m | AA19: m | AC19: m | AD19: m | AF19: m | AG19: m | AI19: m | AJ19: m | AL19: m | AM19: m | AO19: m | AP19: m
A20: Chile | B20: 0.18262016 | C20: 0.025644321 | E20: 1.0915676 | F20: 0.00846061 | H20: 22.931311 | I20: 0.72961084 | K20: 34.564735 | L20: 0.65441908 | N20: 27.261839 | O20: 0.7569098 | Q20: 15.242115 | R20: 0.68893791 | T20: 22.380701 | U20: 0.73689665 | W20: 28.582945 | X20: 0.62686445 | Z20: 29.419409 | AA20: 0.67243829 | AC20: 19.616945 | AD20: 0.77281015 | AF20: 17.958692 | AG20: 0.63678995 | AI20: 28.217348 | AJ20: 0.67739807 | AL20: 29.570336 | AM20: 0.63026256 | AO20: 24.253624 | AP20: 0.81864253
A21: Colombia | B21: 0.25201457 | C21: 0.020616317 | E21: 0.97311678 | F21: 0.0079514341 | H21: 22.89786 | I21: 0.77547652 | K21: 40.577193 | L21: 0.71610936 | N21: 23.802374 | O21: 0.69994942 | Q21: 12.722572 | R21: 0.56688918 | T21: 12.411129 | U21: 0.53526101 | W21: 35.630814 | X21: 0.7853591 | Z21: 33.242247 | AA21: 0.68322779 | AC21: 18.715811 | AD21: 0.66659833 | AF21: 11.456398 | AG21: 0.51928868 | AI21: 32.90786 | AJ21: 0.7745393 | AL21: 33.48312 | AM21: 0.79645571 | AO21: 22.152623 | AP21: 0.66760801
A22: Czech Republic | B22: -0.2366054 | C22: 0.020943702 | E22: 0.92107913 | F22: 0.009327212 | H22: 33.722557 | I22: 0.88758538 | K22: 41.981565 | L22: 0.75818039 | N22: 17.623745 | O22: 0.68366956 | Q22: 6.6721323 | R22: 0.4018025 | T22: 26.623298 | U22: 0.94920679 | W22: 41.742544 | X22: 0.75634238 | Z22: 23.676953 | AA22: 0.69232497 | AC22: 7.957205 | AD22: 0.44161596 | AF22: 23.459994 | AG22: 0.81227308 | AI22: 42.632743 | AJ22: 0.62674917 | AL22: 24.421894 | AM22: 0.67940725 | AO22: 9.4853694 | AP22: 0.52372439
A23: Denmark | B23: 0.11099286 | C23: 0.01857458 | E23: 0.89803739 | F23: 0.0093342941 | H23: 14.994929 | I23: 0.65113237 | K23: 40.545415 | L23: 0.72423717 | N23: 34.248424 | O23: 0.81748031 | Q23: 10.211233 | R23: 0.51261606 | T23: 12.680329 | U23: 0.59696438 | W23: 41.425826 | X23: 0.71490771 | Z23: 35.037625 | AA23: 0.75400987 | AC23: 10.85622 | AD23: 0.54062883 | AF23: 15.311863 | AG23: 0.63463029 | AI23: 41.892025 | AJ23: 0.69117603 | AL23: 32.407915 | AM23: 0.7372865 | AO23: 10.388196 | AP23: 0.57198447
A24: Estonia | B24: -0.12940233 | C24: 0.016046084 | E24: 0.91707792 | F24: 0.0088610778 | H24: 20.805546 | I24: 0.61971039 | K24: 44.543975 | L24: 0.68819262 | N24: 26.793323 | O24: 0.76477196 | Q24: 7.8571557 | R24: 0.435096 | T24: 27.836436 | U24: 0.80458025 | W24: 39.845465 | X24: 0.70494937 | Z24: 25.15108 | AA24: 0.64816115 | AC24: 7.1670199 | AD24: 0.40377484 | AF24: 18.680195 | AG24: 0.61374713 | AI24: 40.939068 | AJ24: 0.80427709 | AL24: 29.949192 | AM24: 0.78719063 | AO24: 10.431545 | AP24: 0.48191802
A25: Finland | B25: -0.15868092 | C25: 0.016217651 | E25: 0.92758172 | F25: 0.0088334273 | H25: 22.922185 | I25: 0.76348281 | K25: 45.114911 | L25: 0.80299669 | N25: 25.00106 | O25: 0.7936507 | Q25: 6.9618441 | R25: 0.32224584 | T25: 21.433988 | U25: 0.72168835 | W25: 45.3616 | X25: 0.77021589 | Z25: 25.6504 | AA25: 0.66381482 | AC25: 7.5540125 | AD25: 0.31668003 | AF25: 22.558918 | AG25: 0.75664101 | AI25: 44.460808 | AJ25: 0.83205382 | AL25: 25.399194 | AM25: 0.65527499 | AO25: 7.5810794 | AP25: 0.35665928
A26: France | B26: -0.21141598 | C26: 0.0153061 | E26: 0.98671611 | F26: 0.0082139379 | H26: 46.843912 | I26: 0.75242353 | K26: 30.836085 | L26: 0.66725742 | N26: 15.069398 | O26: 0.54647973 | Q26: 7.2506041 | R26: 0.39139481 | T26: 26.777782 | U26: 0.68310992 | W26: 37.140113 | X26: 0.63934327 | Z26: 25.351249 | AA26: 0.55461611 | AC26: 10.730856 | AD26: 0.43981634 | AF26: 23.125428 | AG26: 0.58318238 | AI26: 38.402096 | AJ26: 0.71647172 | AL26: 25.662829 | AM26: 0.63625354 | AO26: 12.809647 | AP26: 0.44972524
A27: Germany | B27: -0.074504193 | C27: 0.015503937 | E27: 0.92041958 | F27: 0.0086879297 | H27: 38.348288 | I27: 0.75336317 | K27: 35.595551 | L27: 0.66991923 | N27: 19.839957 | O27: 0.63871891 | Q27: 6.2162036 | R27: 0.41620767 | T27: 16.141354 | U27: 0.49726232 | W27: 41.269087 | X27: 0.88299809 | Z27: 30.808663 | AA27: 0.7136173 | AC27: 11.780896 | AD27: 0.54685706 | AF27: 20.621021 | AG27: 0.64510831 | AI27: 39.121989 | AJ27: 0.80564398 | AL27: 30.012442 | AM27: 0.81306485 | AO27: 10.244547 | AP27: 0.5671807
A28: Greece | B28: -0.10314606 | C28: 0.016366976 | E28: 0.95253974 | F28: 0.0084601142 | H28: 39.3911 | I28: 0.77347859 | K28: 35.749598 | L28: 0.66327963 | N28: 17.509818 | O28: 0.62082301 | Q28: 7.3494841 | R28: 0.35972944 | T28: 19.560664 | U28: 0.67885283 | W28: 39.389425 | X28: 0.70186003 | Z28: 29.762533 | AA28: 0.73371585 | AC28: 11.287378 | AD28: 0.43290235 | AF28: 21.566028 | AG28: 0.65883962 | AI28: 38.577547 | AJ28: 0.58492409 | AL28: 26.919196 | AM28: 0.53046553 | AO28: 12.937229 | AP28: 0.58583954
A29: Hungary | B29: -0.054489792 | C29: 0.019474522 | E29: 0.92399134 | F29: 0.0074147575 | H29: 26.812394 | I29: 0.78132996 | K29: 40.636871 | L29: 0.78264217 | N29: 24.893313 | O29: 0.72276254 | Q29: 7.6574213 | R29: 0.40394192 | T29: 21.606336 | U29: 0.81667119 | W29: 40.203358 | X29: 0.71989795 | Z29: 29.823545 | AA29: 0.79019642 | AC29: 8.366761 | AD29: 0.3994804 | AF29: 16.121184 | AG29: 0.69178948 | AI29: 38.844057 | AJ29: 0.71107668 | AL29: 34.155226 | AM29: 0.83609628 | AO29: 10.879533 | AP29: 0.48160492
A30: Iceland | B30: -0.20146569 | C30: 0.016602341 | E30: 1.0591679 | F30: 0.011197583 | H30: 36.881166 | I30: 0.87141824 | K30: 33.959884 | L30: 0.8086415 | N30: 20.625129 | O30: 0.70331873 | Q30: 8.5338204 | R30: 0.45109561 | T30: 26.40703 | U30: 0.75525941 | W30: 38.007482 | X30: 0.8921082 | Z30: 25.405871 | AA30: 0.80488976 | AC30: 10.179616 | AD30: 0.46606518 | AF30: 27.199082 | AG30: 0.78754478 | AI30: 36.565 | AJ30: 0.81977577 | AL30: 25.297335 | AM30: 0.80560063 | AO30: 10.938583 | AP30: 0.51296563
A31: Ireland | B31: 0.3033601 | C31: 0.018977434 | E31: 0.96592175 | F31: 0.0088331931 | H31: 15.426024 | I31: 0.64342046 | K31: 37.478454 | L31: 0.67644171 | N31: 32.339127 | O31: 0.61538866 | Q31: 14.756395 | R31: 0.57500742 | T31: 10.074183 | U31: 0.54542115 | W31: 35.119021 | X31: 0.757118 | Z31: 37.10452 | AA31: 0.63630114 | AC31: 17.702275 | AD31: 0.63793584 | AF31: 11.647807 | AG31: 0.50786973 | AI31: 34.885352 | AJ31: 0.77352717 | AL31: 36.164861 | AM31: 0.73041099 | AO31: 17.301979 | AP31: 0.60412386
... A53: OECD average | B53: 0.0061975257 | C53: 0.0030479949 | E53: 0.97390158 | F53: 0.0014319884 | H53: 29.472161 | I53: 0.1265125 | K53: 36.912844 | L53: 0.11773357 | N53: 23.653548 | O53: 0.1082344 | Q53: 9.9614474 | R53: 0.078895812 | T53: 19.796009 | U53: 0.11166781 | W53: 37.166725 | X53: 0.12077608 | Z53: 30.02558 | AA53: 0.11440523 | AC53: 13.011686 | AD53: 0.088408026 | AF53: 18.646187 | AG53: 0.10307769 | AI53: 36.784203 | AJ53: 0.11887767 | AL53: 30.226978 | AM53: 0.11581498 | AO53: 14.342632 | AP53: 0.092763623
A54: Partners
A55: Albania | B55: 0.77015 | C55: 0.017521636 | E55: 0.95495616 | F55: 0.009806737 | H55: 9.7230205 | I55: 0.47034025 | K55: 28.279753 | L55: 0.79371272 | N55: 30.129732 | O55: 0.73152209 | Q55: 31.867494 | R55: 0.71955755 | T55: 7.6130041 | U55: 0.39981634 | W55: 25.3427 | X55: 0.73831881 | Z55: 34.216305 | AA55: 0.7280888 | AC55: 32.827991 | AD55: 0.79664708 | AF55: 4.4159756 | AG55: 0.3167789 | AI55: 19.397083 | AJ55: 0.58209977 | AL55: 33.019553 | AM55: 0.67891123 | AO55: 43.167388 | AP55: 0.80054148
A56: Argentina | B56: -0.16464535 | C56: 0.018920459 | E56: 0.96019262 | F56: 0.0074588972 | H56: 32.480684 | I56: 0.7567683 | K56: 43.200351 | L56: 0.67655487 | N56: 17.432213 | O56: 0.47320731 | Q56: 6.8867523 | R56: 0.41795416 | T56: 30.005051 | U56: 0.78167998 | W56: 36.483479 | X56: 0.60266593 | Z56: 22.858313 | AA56: 0.56589477 | AC56: 10.653157 | AD56: 0.51768185 | AF56: 22.063567 | AG56: 0.68619653 | AI56: 34.877811 | AJ56: 0.6059316 | AL56: 27.115104 | AM56: 0.62198965 | AO56: 15.943518 | AP56: 0.57422051
A57: Baku (Azerbaijan) | B57: 0.42259218 | C57: 0.014215375 | E57: 0.99379084 | F57: 0.0096068284 | H57: 11.498059 | I57: 0.43480097 | K57: 34.881529 | L57: 0.6670315 | N57: 33.150527 | O57: 0.57542364 | Q57: 20.469885 | R57: 0.53893691 | T57: 11.113529 | U57: 0.46626863 | W57: 33.199443 | X57: 0.76744133 | Z57: 35.071037 | AA57: 0.7605381 | AC57: 20.615991 | AD57: 0.53535385 | AF57: 10.406688 | AG57: 0.44066508 | AI57: 29.721663 | AJ57: 0.69427072 | AL57: 35.648869 | AM57: 0.69289365 | AO57: 24.22278 | AP57: 0.57806563
A58: Belarus | B58: 0.16806205 | C58: 0.018501568 | E58: 0.98612042 | F58: 0.0095762169 | H58: 18.556303 | I58: 0.61746456 | K58: 37.886272 | L58: 0.72497719 | N58: 32.401672 | O58: 0.68438672 | Q58: 11.155753 | R58: 0.52544272 | T58: 17.302047 | U58: 0.67532098 | W58: 34.020781 | X58: 0.69972032 | Z58: 35.021314 | AA58: 0.6589492 | AC58: 13.655858 | AD58: 0.53960467 | AF58: 13.870136 | AG58: 0.58059512 | AI58: 33.418405 | AJ58: 0.65173224 | AL58: 36.431876 | AM58: 0.60212393 | AO58: 16.279583 | AP58: 0.66650072
A59: Bosnia and Herzegovina | B59: -0.15035087 | C59: 0.018439422 | E59: 0.9917106 | F59: 0.009646165 | H59: 26.687646 | I59: 0.78662603 | K59: 41.955359 | L59: 0.68474034 | N59: 22.210613 | O59: 0.62552297 | Q59: 9.1463829 | R59: 0.38049252 | T59: 28.583822 | U59: 0.83353362 | W59: 38.27886 | X59: 0.67506502 | Z59: 23.495099 | AA59: 0.67150225 | AC59: 9.6422192 | AD59: 0.43254486 | AF59: 22.070677 | AG59: 0.76041633 | AI59: 38.173335 | AJ59: 0.68284639 | AL59: 27.699226 | AM59: 0.57284119 | AO59: 12.056763 | AP59: 0.49982746
A60: Brazil | B60: -0.15662909 | C60: 0.014421706 | E60: 0.95858958 | F60: 0.0064708094 | H60: 46.698686 | I60: 0.67591502 | K60: 35.230734 | L60: 0.53722686 | N60: 12.331925 | O60: 0.3900767 | Q60: 5.7386555 | R60: 0.2780886 | T60: 25.270779 | U60: 0.60209023 | W60: 37.654854 | X60: 0.48385741 | Z60: 25.022015 | AA60: 0.4900235 | AC60: 12.052352 | AD60: 0.42711959 | AF60: 19.658474 | AG60: 0.47253709 | AI60: 35.503387 | AJ60: 0.60146599 | AL60: 28.300796 | AM60: 0.53421826 | AO60: 16.537343 | AP60: 0.44592055
A61: Brunei Darussalam | B61: 0.3289389 | C61: 0.0090413147 | E61: 0.854307 | F61: 0.0074300606 | H61: 11.610164 | I61: 0.40414047 | K61: 50.622019 | L61: 0.5356883 | N61: 25.463192 | O61: 0.56383445 | Q61: 12.304625 | R61: 0.3916532 | T61: 8.4015236 | U61: 0.32633266 | W61: 38.540484 | X61: 0.63625188 | Z61: 35.623205 | AA61: 0.60864375 | AC61: 17.434788 | AD61: 0.45285633 | AF61: 6.8593149 | AG61: 0.26699588 | AI61: 36.456699 | AJ61: 0.57953596 | AL61: 35.396051 | AM61: 0.5857601 | AO61: 21.287935 | AP61: 0.49464306
A62: B-S-J-Z (China) | B62: 0.27751943 | C62: 0.019664528 | E62: 1.0337583 | F62: 0.0084560806 | H62: 23.841133 | I62: 0.70143278 | K62: 35.626605 | L62: 0.53282633 | N62: 23.489444 | O62: 0.58688031 | Q62: 17.042818 | R62: 0.63597266 | T62: 10.163943 | U62: 0.39963825 | W62: 34.866816 | X62: 0.76094569 | Z62: 33.534575 | AA62: 0.57954881 | AC62: 21.434667 | AD62: 0.72214115 | AF62: 13.974241 | AG62: 0.50253144 | AI62: 36.871292 | AJ62: 0.65721751 | AL62: 29.244063 | AM62: 0.52215616 | AO62: 19.910405 | AP62: 0.68595984
A63: Bulgaria | B63: 0.11133775 | C63: 0.024451076 | E63: 1.1021107 | F63: 0.0089760458 | H63: 28.999507 | I63: 0.9041529 | K63: 31.324432 | L63: 0.7326538 | N63: 23.241824 | O63: 0.7727664 | Q63: 16.434237 | R63: 0.64656289 | T63: 28.421999 | U63: 0.80177999 | W63: 28.526818 | X63: 0.68801111 | Z63: 25.863864 | AA63: 0.77989485 | AC63: 17.18732 | AD63: 0.60169639 | AF63: 16.199629 | AG63: 0.72515475 | AI63: 27.682861 | AJ63: 0.75044705 | AL63: 31.47872 | AM63: 0.76821051 | AO63: 24.638791 | AP63: 0.76970683
A64: Costa Rica | B64: -0.2468784 | C64: 0.02166979 | E64: 1.0482195 | F64: 0.0084372944 | H64: 48.151886 | I64: 0.89944745 | K64: 30.471176 | L64: 0.63571082 | N64: 13.713928 | O64: 0.54460697 | Q64: 7.6630098 | R64: 0.39153523 | T64: 30.864057 | U64: 0.86812745 | W64: 34.751478 | X64: 0.63573325 | Z64: 22.552601 | AA64: 0.57146923 | AC64: 11.831865 | AD64: 0.4525569 | AF64: 26.506897 | AG64: 0.93342605 | AI64: 33.954231 | AJ64: 0.58160198 | AL64: 24.352242 | AM64: 0.62200341 | AO64: 15.18663 | AP64: 0.58516631
...

Sheet Table III.B1.6.4
A1: PISA 2018 Results (Volume III) - © OECD 2019
A2: Annex B1 | B2: Annex B1.6 Results (tables): Teachers' support and teaching practices
A3: Version 2 - Last updated: 02-Dec-2019
A4: Disclaimer: http://oe.cd/disclaimer
A6: Table III.B1.6.4
A7: Prevalence of teacher support in schools
A8: Based on students' reports
B11: Percentage of students who reported the teacher gives extra help when students need it in most or every language-of-instruction lesson | E11: Percentage of students who are in schools where…
E12: Over 90% of students reported the teacher gives extra help when students need it in most or every language-of-instruction lesson | H12: Between 75% and 90% of students reported the teacher gives extra help when students need it in most or every language-of-instruction lesson | K12: Between 25% and 75% of students reported the teacher gives extra help when students need it in most or every language-of-instruction lesson | N12: Between 10% and 25% of students reported the teacher gives extra help when students need it in most or every language-of-instruction lesson | Q12: 10% of students or less reported the teacher gives extra help when students need it in most or every language-of-instruction lesson
B14: % | C14: S.E. | E14: % | F14: S.E. | H14: % | I14: S.E. | K14: % | L14: S.E. | N14: % | O14: S.E. | Q14: % | R14: S.E.
A15: OECD
A16: Australia | B16: 81.089734 | C16: 0.45865061 | E16: 22.016999 | F16: 1.791154 | H16: 50.212531 | I16: 2.1810329 | K16: 27.513345 | L16: 1.9404819 | N16: 0.02283251 | O16: 0.02365631 | Q16: 0.23429251 | R16: 0.13063514
A17: Austria | B17: 64.678006 | C17: 0.84980098 | E17: 3.9477094 | F17: 1.0038768 | H17: 22.903454 | I17: 2.7072429 | K17: 72.635418 | L17: 2.8987316 | N17: 0.41281847 | O17: 0.25244855 | Q17: 0.10059983 | R17: 0.081473236
A18: Belgium | B18: 72.758323 | C18: 0.65858406 | E18: 7.551613 | F18: 1.4839812 | H18: 34.584192 | I18: 2.9549499 | K18: 57.864195 | L18: 2.9551241 | N18: 0 | O18: c | Q18: 0 | R18: c
A19: Canada | B19: m | C19: m | E19: m | F19: m | H19: m | I19: m | K19: m | L19: m | N19: m | O19: m | Q19: m | R19: m
A20: Chile | B20: 80.851451 | C20: 0.74901443 | E20: 20.12661 | F20: 2.7966465 | H20: 54.029159 | I20: 3.7759286 | K20: 25.713761 | L20: 3.1202396 | N20: 0 | O20: c | Q20: 0.13047018 | R20: 0.0924848
A21: Colombia | B21: 75.861433 | C21: 0.83929796 | E21: 8.1659146 | F21: 1.8020666 | H21: 45.547109 | I21: 3.8840973 | K21: 46.225916 | L21: 3.9538683 | N21: 0 | O21: c | Q21: 0.061060022 | R21: 0.061177222
A22: Czech Republic | B22: 78.445575 | C22: 0.86690621 | E22: 24.306469 | F22: 2.549197 | H22: 39.987322 | I22: 2.7035272 | K22: 35.319936 | L22: 2.7913999 | N22: 0.38627293 | O22: 0.29026473 | Q22: 0 | R22: c
A23: Denmark | B23: 78.192051 | C23: 0.70194461 | E23: 15.191018 | F23: 2.4957689 | H23: 46.76314 | I23: 3.130332 | K23: 38.045841 | L23: 2.9579911 | N23: 0 | O23: c | Q23: 0 | R23: c
A24: Estonia | B24: 73.559126 | C24: 0.77063473 | E24: 10.410657 | F24: 1.2030127 | H24: 37.040168 | I24: 2.1752771 | K24: 52.493381 | L24: 2.2057457 | N24: 0 | O24: c | Q24: 0.055794283 | R24: 0.055714091
A25: Finland | B25: 85.308866 | C25: 0.53049583 | E25: 33.883436 | F25: 3.4414748 | H25: 51.971646 | I25: 4.0136995 | K25: 14.082066 | L25: 2.2468396 | N25: 0 | O25: c | Q25: 0.062851812 | R25: 0.063144913
A26: France | B26: 65.18571 | C26: 0.84635973 | E26: 2.3644146 | F26: 0.94313807 | H26: 22.454349 | I26: 2.5526808 | K26: 75.109922 | L26: 2.6921552 | N26: 0 | O26: c | Q26: 0.07131507 | R26: 0.10333758
A27: Germany | B27: 72.54655 | C27: 0.79655911 | E27: 8.4553452 | F27: 1.8736941 | H27: 36.939171 | I27: 3.5744711 | K27: 54.605484 | L27: 3.3086843 | N27: 0 | O27: c | Q27: 0 | R27: c
A28: Greece | B28: 66.962563 | C28: 0.81622343 | E28: 3.7928272 | F28: 1.1023511 | H28: 25.233466 | I28: 2.6047008 | K28: 70.863059 | L28: 2.5864881 | N28: 0 | O28: c | Q28: 0.11064836 | R28: 0.080158132
A29: Hungary | B29: 72.543813 | C29: 0.92908328 | E29: 6.5426644 | F29: 1.505395 | H29: 38.189975 | I29: 3.6750567 | K29: 54.729236 | L29: 3.8035917 | N29: 0.48582821 | O29: 0.28296287 | Q29: 0.052296657 | R29: 0.052506635
A30: Iceland | B30: 77.233781 | C30: 0.74121254 | E30: 7.7915732 | F30: 0.14800835 | H30: 57.074868 | I30: 0.2356966 | K30: 34.743676 | L30: 0.22553513 | N30: 0.22051121 | O30: 0.02077548 | Q30: 0.16937158 | R30: 0.059265328
A31: Ireland | B31: 74.847839 | C31: 0.80387066 | E31: 6.011604 | F31: 1.8995759 | H31: 45.168867 | I31: 4.1786477 | K31: 48.819529 | L31: 4.1784208 | N31: 0 | O31: c | Q31: 0 | R31: c
A32: Israel | B32: 65.510898 | C32: 1.1266821 | E32: 5.3180067 | F32: 1.7690105 | H32: 24.232852 | I32: 3.5801238 | K32: 70.449141 | L32: 3.2853648 | N32: 0 | O32: c | Q32: 0 | R32: c
A33: Italy | B33: 72.406808 | C33: 0.75001919 | E33: 7.3178636 | F33: 1.5408315 | H33: 40.509839 | I33: 2.9225091 | K33: 52.152539 | L33: 2.9181756 | N33: 0 | O33: c | Q33: 0.019758185 | R33: 0.016339458
A34: Japan | B34: 81.048675 | C34: 0.73308939 | E34: 18.712458 | F34: 3.0265333 | H34: 55.841886 | I34: 4.1496034 | K34: 25.445656 | L34: 3.4986259 | N34: 0 | O34: c | Q34: 0 | R34: c
A35: Korea | B35: 79.618484 | C35: 0.80873948 | E35: 13.371725 | F35: 2.6984941 | H35: 54.993183 | I35: 3.9457546 | K35: 31.635092 | L35: 3.4946484 | N35: 0 | O35: c | Q35: 0 | R35: c
A36: Latvia | B36: 79.387912 | C36: 0.70395399 | E36: 17.765117 | F36: 1.7743561 | H36: 48.615198 | I36: 1.9671783 | K36: 33.619685 | L36: 1.8126633 | N36: 0 | O36: c | Q36: 0 | R36: c
A37: Lithuania | B37: 76.899828 | C37: 0.6623341 | E37: 13.869441 | F37: 1.2042173 | H37: 45.194084 | I37: 1.9719195 | K37: 40.781339 | L37: 1.92848 | N37: 0.072096603 | O37: 0.072878615 | Q37: 0.083039101 | R37: 0.061647279
A38: Luxembourg | B38: 71.43933 | C38: 0.62703176 | E38: 0 | F38: c | H38: 32.612882 | I38: 0.10113772 | K38: 67.387118 | L38: 0.10113772 | N38: 0 | O38: c | Q38: 0 | R38: c
A39: Mexico | B39: 82.64012 | C39: 0.6261497 | E39: 27.316927 | F39: 3.0407159 | H39: 50.05908 | I39: 2.9751749 | K39: 22.280289 | L39: 2.5294776 | N39: 0.27057105 | O39: 0.27590416 | Q39: 0.073133352 | R39: 0.074446932
A40: Netherlands* | B40: 68.969164 | C40: 1.0087823 | E40: 3.075941 | F40: 1.402252 | H40: 32.041795 | I40: 3.8870166 | K40: 64.882264 | L40: 3.9473556 | N40: 0 | O40: c | Q40: 0 | R40: c
A41: New Zealand | B41: 82.102805 | C41: 0.54653365 | E41: 17.034469 | F41: 2.3804677 | H41: 64.754553 | I41: 3.0148862 | K41: 18.210978 | L41: 2.4761168 | N41: 0 | O41: c | Q41: 0 | R41: c
A42: Norway | B42: 71.044108 | C42: 0.81859729 | E42: 4.4714041 | F42: 1.222823 | H42: 39.767644 | I42: 3.4223116 | K42: 55.465233 | L42: 3.3430667 | N42: 0.19929684 | O42: 0.20826783 | Q42: 0.096422338 | R42: 0.099226783
