Workbook

Sheet TOC
A1: PISA 2018 Results (Volume III) - © OECD 2019
A2: Annex B1 | B2: Annex B1.12 Results (tables): Students' feelings
A3: Version 2 - Last updated: 02-Dec-2019
A4: Disclaimer: http://oe.cd/disclaimer
A6: TOC | B6: PISA 2018 Results - Volume III
A8: Chapter 12 | B8: Student feelings
A9: Tables
A11: ='Table III.B1.12.1'!A6 -> Table III.B1.12.1 | B11: ='Table III.B1.12.1'!$A$7 -> Students' positive feelings
A12: ='Table III.B1.12.2'!A6 -> Table III.B1.12.2 | B12: ='Table III.B1.12.2'!$A$7 -> Students' negative feelings
A13: ='Table III.B1.12.3'!A6 -> Table III.B1.12.3 | B13: ='Table III.B1.12.3'!$A$7 -> Prevalence of happiness in schools
A14: ='Table III.B1.12.4'!A6 -> Table III.B1.12.4 | B14: ='Table III.B1.12.4'!$A$7 -> Prevalence of sadness in schools
A15: ='Table III.B1.12.5'!A6 -> Table III.B1.12.5 | B15: ='Table III.B1.12.5'!$A$7 -> Index of positive feelings, by student characteristics
A16: ='Table III.B1.12.6'!A6 -> Table III.B1.12.6 | B16: ='Table III.B1.12.6'!$A$7 -> Feeling sad, by student characteristics
A17: ='Table III.B1.12.7'!A6 -> Table III.B1.12.7 | B17: ='Table III.B1.12.7'!$A$7 -> Index of positive feelings, by school characteristics
A18: ='Table III.B1.12.8'!A6 -> Table III.B1.12.8 | B18: ='Table III.B1.12.8'!$A$7 -> Feeling sad, by school characteristics
A19: ='Table III.B1.12.9'!A6 -> Table III.B1.12.9 | B19: ='Table III.B1.12.9'!$A$7 -> Positive feelings and reading performance
A20: ='Table III.B1.12.10'!A6 -> Table III.B1.12.10 | B20: ='Table III.B1.12.10'!$A$7 -> Intensity of positive feelings and reading performance
A21: ='Table III.B1.12.11'!A6 -> Table III.B1.12.11 | B21: ='Table III.B1.12.11'!$A$7 -> Negative feelings and reading performance
A22: ='Table III.B1.12.12'!A6 -> Table III.B1.12.12 | B22: ='Table III.B1.12.12'!$A$7 -> Intensity of negative feelings and reading performance
A23: ='Table III.B1.12.13'!A6 -> Table III.B1.12.13 | B23: ='Table III.B1.12.13'!$A$7 -> School-level positive feelings and reading performance
A24: ='Table III.B1.12.14'!A6 -> Table III.B1.12.14 | B24: ='Table III.B1.12.14'!$A$7 -> School-level negative feelings and reading performance
A25: ='Table III.B1.12.15'!A6 -> Table III.B1.12.15 | B25: ='Table III.B1.12.15'!$A$7 -> Internet use outside of school and positive feelings
A26: ='Table III.B1.12.16'!A6 -> Table III.B1.12.16 | B26: ='Table III.B1.12.16'!$A$7 -> Internet use outside of school and negative feelings
A27: ='Table III.B1.12.17'!A6 -> Table III.B1.12.17 | B27: ='Table III.B1.12.17'!$A$7 -> Internet use outside of school and feeling lively
A28: ='Table III.B1.12.18'!A6 -> Table III.B1.12.18 | B28: ='Table III.B1.12.18'!$A$7 -> Internet use outside of school and feeling miserable
A29: ='Table III.B1.12.19'!A6 -> Table III.B1.12.19 | B29: ='Table III.B1.12.19'!$A$7 -> Predictors of the index of positive feelings
A30: ='Table III.B1.12.20'!A6 -> Table III.B1.12.20 | B30: ='Table III.B1.12.20'!$A$7 -> Predictors of sadness
A31: ='Table III.B1.12.21'!A6 -> Table III.B1.12.21 | B31: ='Table III.B1.12.21'!$A$7 -> Association between students' satisfaction with different aspects of life and the index of positive feelings
A32: ='Table III.B1.12.22'!A6 -> Table III.B1.12.22 | B32: ='Table III.B1.12.22'!$A$7 -> Association between students' satisfaction with different aspects of life and feelings of sadness
A35: Symbols for missing data
A36: c: There were too few observations to provide reliable estimates (i.e. there were fewer than 30 students or fewer than 5 schools with valid data).
A37: m: Data are not available. There are no observations in the sample; these data were not collected by the country; or these data were collected but subsequently removed from the publication for technical reasons.
A38: w: Results were withdrawn at the request of the country concerned.

Sheet INFORMATION ON SCALED INDICES
A1: PISA 2018 Results (Volume III) - © OECD 2019
A2: Annex B1 | B2: Annex B1.12 Results (tables): Students' feelings
A3: Version 2 - Last updated: 02-Dec-2019
A4: Disclaimer: http://oe.cd/disclaimer
A6: Information on scaled indices used in PISA 2015 Results (Volume III): What School Life Means for Students’ Lives
A11: Full name of the index | B11: Name in dataset | C11: Questionnaire | D11: Item 1 | E11: Item 2 | F11: Item 3 | G11: Item 4 | H11: Item 5 | I11: Item 6 | J11: Item 7
A12: Adaptive instruction | B12: adaptivity | C12: Student | D12: ST212Q01HA | E12: ST212Q02HA | F12: ST212Q03HA
A13: Attitudes towards competition | B13: compete | C13: Student | D13: ST181Q02HA | E13: ST181Q03HA | F13: ST181Q04HA
A14: Enjoyment of reading | B14: joyread | C14: Student | D14: ST160Q01IR | E14: ST160Q02IA | F14: ST160Q03IA | G14: ST160Q04IR | H14: ST160Q05IR
A15: Exposure to bullying | B15: beingbullied | C15: Student | D15: ST038Q03NA | E15: ST038Q04NA | F15: ST038Q05NA
A16: Fear of failure | B16: gfofail | C16: Student | D16: ST183Q01HA | E16: ST183Q02HA | F16: ST183Q03HA
A17: Disciplinary climate | B17: disclima | C17: Student | D17: ST097Q01TA | E17: ST097Q02TA | F17: ST097Q03TA | G17: ST097Q04TA | H17: ST097Q05TA
A18: Learning goals | B18: mastgoal | C18: Student | D18: ST208Q01HA | E18: ST208Q02HA | F18: ST208Q04HA
A19: Meaning in life | B19: eudmo | C19: Student | D19: ST185Q01HA | E19: ST185Q02HA | F19: ST185Q03HA
A20: Motivation to master tasks | B20: workmast | C20: Student | D20: ST182Q03HA | E20: ST182Q04HA | F20: ST182Q05HA
A21: Parents’ emotional support | B21: emosups | C21: Student | D21: ST123Q02NA | E21: ST123Q03NA | F21: ST123Q04NA
A22: Parents’ perceived school quality | B22: pqschool | C22: Parent | D22: PA007Q01TR | E22: PA007Q02TR | F22: PA007Q03TR | G22: PA007Q04TR | H22: PA007Q05TR | I22: PA007Q06TR | J22: PA007Q07TR
A23: Positive feelings | B23: swbp | C23: Student | D23: ST186Q01HA | E23: ST186Q03HA | F23: ST186Q05HA
A24: School policies for parental involvement | B24: paschpol | C24: Parent | D24: PA007Q09NR | E24: PA007Q11NR | F24: PA007Q12NR | G24: PA007Q13NR | H24: PA007Q14NR | I24: PA007Q15NR
A25: Self-efficacy | B25: resilience | C25: Student | D25: ST188Q01HA | E25: ST188Q02HA | F25: ST188Q03HA | G25: ST188Q06HA | H25: ST188Q07HA
A26: Sense of belonging | B26: belong | C26: Student | D26: ST034Q01TA | E26: ST034Q02TR | F26: ST034Q03TR | G26: ST034Q04TA | H26: ST034Q05TR | I26: ST034Q06TA
A27: Shortage of educational staff | B27: staffshort | C27: School | D27: SC017Q01NA | E27: SC017Q02NA | F27: SC017Q03NA | G27: SC017Q04NA
A28: Student competition | B28: percomp | C28: Student | D28: ST205Q01HA | E28: ST205Q02HA | F28: ST205Q03HA
A29: Student co-operation | B29: percoop | C29: Student | D29: ST206Q01HA | E29: ST206Q02HA | F29: ST206Q03HA
A30: Teacher behaviour hindering learning | B30: teachbeha | C30: School | D30: SC061Q06TA | E30: SC061Q07TA | F30: SC061Q08TA | G30: SC061Q09TA | H30: SC061Q10TA
A31: Teacher enthusiasm | B31: teachint | C31: Student | D31: ST213Q01HA | E31: ST213Q02HA | F31: ST213Q03HA | G31: ST213Q04HA
A32: Teacher feedback | B32: perfeed | C32: Student | D32: ST104Q02NA | E32: ST104Q03NA | F32: ST104Q04NA
A33: Teacher support | B33: teachsup | C33: Student | D33: ST100Q01TR | E33: ST100Q02TR | F33: ST100Q03TR | G33: ST100Q04TR
A34: Teacher-directed instruction | B34: dirins | C34: Student | D34: ST102Q01TR | E34: ST102Q02TR | F34: ST102Q03TR | G34: ST102Q04TR
A35: Teachers' stimulation of reading engagement | B35: stimread | C35: Student | D35: ST152Q05IA | E35: ST152Q06IA | F35: ST152Q07IA | G35: ST152Q08IA
A36: Value of school | B36: attlnact | C36: Student | D36: ST036Q05TR | E36: ST036Q06TR | F36: ST036Q08TR

Sheet Table III.B1.12.1
A1: PISA 2018 Results (Volume III) - © OECD 2019
A2: Annex B1 | B2: Annex B1.12 Results (tables): Students' feelings
A3: Version 2 - Last updated: 02-Dec-2019
A4: Disclaimer: http://oe.cd/disclaimer
A6: Table III.B1.12.1
A7: Students' positive feelings
A8: Based on students' reports
B11: Index of positive feelings1 | H11: Percentage of students who reported feeling the following:
H12: Happy | T12: Lively | AF12: Proud | AR12: Joyful | BD12: Cheerful
B13: Average | E13: Variability | H13: Never | K13: Rarely | N13: Sometimes | Q13: Always | T13: Never | W13: Rarely | Z13: Sometimes | AC13: Always | AF13: Never | AI13: Rarely | AL13: Sometimes | AO13: Always | AR13: Never | AU13: Rarely | AX13: Sometimes | BA13: Always | BD13: Never | BG13: Rarely | BJ13: Sometimes | BM13: Always
B14: Mean index | C14: S.E. | E14: S.D. | F14: S.E. | H14: % | I14: S.E. | K14: % | L14: S.E. | N14: % | O14: S.E. | Q14: % | R14: S.E. | T14: % | U14: S.E. | W14: % | X14: S.E. | Z14: % | AA14: S.E. | AC14: % | AD14: S.E. | AF14: % | AG14: S.E. | AI14: % | AJ14: S.E. | AL14: % | AM14: S.E. | AO14: % | AP14: S.E. | AR14: % | AS14: S.E. | AU14: % | AV14: S.E. | AX14: % | AY14: S.E. | BA14: % | BB14: S.E. | BD14: % | BE14: S.E. | BG14: % | BH14: S.E. | BJ14: % | BK14: S.E. | BM14: % | BN14: S.E.
A15: OECD
A16: Australia | B16: m | C16: m | E16: m | F16: m | H16: m | I16: m | K16: m | L16: m | N16: m | O16: m | Q16: m | R16: m | T16: m | U16: m | W16: m | X16: m | Z16: m | AA16: m | AC16: m | AD16: m | AF16: m | AG16: m | AI16: m | AJ16: m | AL16: m | AM16: m | AO16: m | AP16: m | AR16: m | AS16: m | AU16: m | AV16: m | AX16: m | AY16: m | BA16: m | BB16: m | BD16: m | BE16: m | BG16: m | BH16: m | BJ16: m | BK16: m | BM16: m | BN16: m
A17: Austria | B17: 0.10998022 | C17: 0.016162497 | E17: 0.99519072 | F17: 0.0085857561 | H17: 1.5184281 | I17: 0.17307567 | K17: 7.0470975 | L17: 0.43669262 | N17: 48.845503 | O17: 0.72953565 | Q17: 42.588971 | R17: 0.75057362 | T17: 3.2360715 | U17: 0.26508649 | W17: 12.803585 | X17: 0.49376544 | Z17: 43.771056 | AA17: 0.64487884 | AC17: 40.189287 | AD17: 0.72917885 | AF17: 4.4085212 | AG17: 0.33781621 | AI17: 21.541107 | AJ17: 0.62968156 | AL17: 55.773728 | AM17: 0.60220194 | AO17: 18.276644 | AP17: 0.52112167 | AR17: 1.5127581 | AS17: 0.1658147 | AU17: 7.7005877 | AV17: 0.41478072 | AX17: 46.346103 | AY17: 0.69193585 | BA17: 44.440552 | BB17: 0.71937711 | BD17: 1.3923377 | BE17: 0.15882628 | BG17: 6.9853261 | BH17: 0.3983167 | BJ17: 43.666587 | BK17: 0.69301374 | BM17: 47.955749 | BN17: 0.75024218
A18: Belgium | B18: m | C18: m | E18: m | F18: m | H18: m | I18: m | K18: m | L18: m | N18: m | O18: m | Q18: m | R18: m | T18: m | U18: m | W18: m | X18: m | Z18: m | AA18: m | AC18: m | AD18: m | AF18: m | AG18: m | AI18: m | AJ18: m | AL18: m | AM18: m | AO18: m | AP18: m | AR18: m | AS18: m | AU18: m | AV18: m | AX18: m | AY18: m | BA18: m | BB18: m | BD18: m | BE18: m | BG18: m | BH18: m | BJ18: m | BK18: m | BM18: m | BN18: m
A19: Canada | B19: -0.05731641 | C19: 0.012519068 | E19: 1.0188123 | F19: 0.0048899 | H19: 1.2920782 | I19: 0.12648086 | K19: 5.5123626 | L19: 0.21104866 | N19: 46.040084 | O19: 0.54265025 | Q19: 47.155475 | R19: 0.6067559 | T19: 3.859242 | U19: 0.17793299 | W19: 15.943623 | X19: 0.37235593 | Z19: 50.711566 | AA19: 0.47634676 | AC19: 29.485569 | AD19: 0.48396721 | AF19: 3.8833962 | AG19: 0.20371059 | AI19: 19.9456 | AJ19: 0.38363971 | AL19: 55.559318 | AM19: 0.44607756 | AO19: 20.611686 | AP19: 0.36184766 | AR19: 2.1851429 | AS19: 0.16069141 | AU19: 11.610338 | AV19: 0.34824826 | AX19: 52.067465 | AY19: 0.42521159 | BA19: 34.137054 | BB19: 0.48973886 | BD19: 2.579584 | BE19: 0.16684182 | BG19: 12.557345 | BH19: 0.30854511 | BJ19: 49.846371 | BK19: 0.42491081 | BM19: 35.0167 | BN19: 0.53083641
A20: Chile | B20: 0.17035172 | C20: 0.016492328 | E20: 0.98247434 | F20: 0.008631556 | H20: 1.0750231 | I20: 0.17977764 | K20: 5.2269849 | L20: 0.30915876 | N20: 46.410737 | O20: 0.65619165 | Q20: 47.287255 | R20: 0.73232137 | T20: 2.129696 | U20: 0.2371001 | W20: 11.093556 | X20: 0.48090493 | Z20: 47.822649 | AA20: 0.83514882 | AC20: 38.954099 | AD20: 0.83367425 | AF20: 7.398106 | AG20: 0.41489338 | AI20: 22.224473 | AJ20: 0.53523242 | AL20: 46.932797 | AM20: 0.76131956 | AO20: 23.444624 | AP20: 0.63724512 | AR20: 1.3235405 | AS20: 0.2013171 | AU20: 6.3407445 | AV20: 0.33390092 | AX20: 41.147769 | AY20: 0.69382575 | BA20: 51.187946 | BB20: 0.81418497 | BD20: 2.0153187 | BE20: 0.23113828 | BG20: 9.3051465 | BH20: 0.39604758 | BJ20: 44.880191 | BK20: 0.69610992 | BM20: 43.799344 | BN20: 0.73448682
A21: Colombia | B21: 0.24820992 | C21: 0.013916018 | E21: 0.97863966 | F21: 0.0079145129 | H21: 0.75203979 | I21: 0.11032712 | K21: 6.4941897 | L21: 0.31476841 | N21: 43.725265 | O21: 0.59891724 | Q21: 49.028506 | R21: 0.58998324 | T21: 1.1566059 | U21: 0.16017051 | W21: 8.2571883 | X21: 0.46413034 | Z21: 44.502022 | AA21: 0.68718184 | AC21: 46.084184 | AD21: 0.83890942 | AF21: 8.3517817 | AG21: 0.43827251 | AI21: 19.275599 | AJ21: 0.62526482 | AL21: 42.217358 | AM21: 0.77786324 | AO21: 30.15526 | AP21: 0.95344668 | AR21: 0.81744835 | AS21: 0.10723634 | AU21: 7.0489838 | AV21: 0.35535295 | AX21: 37.533012 | AY21: 0.74863425 | BA21: 54.600556 | BB21: 0.753163 | BD21: 0.89233576 | BE21: 0.12987433 | BG21: 7.3223669 | BH21: 0.40999014 | BJ21: 42.508592 | BK21: 0.76694621 | BM21: 49.276705 | BN21: 0.73778516
A22: Czech Republic | B22: -0.13170145 | C22: 0.015790722 | E22: 1.0035375 | F22: 0.0099174109 | H22: 2.2253255 | I22: 0.23563974 | K22: 11.334449 | L22: 0.53621761 | N22: 53.669745 | O22: 0.83212695 | Q22: 32.77048 | R22: 0.73205785 | T22: 4.0950888 | U22: 0.30468455 | W22: 18.483473 | X22: 0.60676073 | Z22: 47.342075 | AA22: 0.75353016 | AC22: 30.079363 | AD22: 0.74231121 | AF22: 7.039004 | AG22: 0.35558353 | AI22: 29.229217 | AJ22: 0.65187186 | AL22: 47.098909 | AM22: 0.86373178 | AO22: 16.63287 | AP22: 0.64461179 | AR22: 1.6843604 | AS22: 0.18083198 | AU22: 9.7362726 | AV22: 0.47901793 | AX22: 54.721699 | AY22: 0.884476 | BA22: 33.857667 | BB22: 0.82146021 | BD22: 2.0431964 | BE22: 0.19478059 | BG22: 9.6755821 | BH22: 0.43525491 | BJ22: 50.677671 | BK22: 0.87334357 | BM22: 37.603551 | BN22: 0.75073922
A23: Denmark | B23: 0.24137527 | C23: 0.014970291 | E23: 0.88388108 | F23: 0.009953387 | H23: 1.4407393 | I23: 0.16202588 | K23: 7.4229927 | L23: 0.37843673 | N23: 56.543837 | O23: 0.75778999 | Q23: 34.592431 | R23: 0.68320075 | T23: 1.5523799 | U23: 0.18091208 | W23: 8.1731203 | X23: 0.42101022 | Z23: 56.293513 | AA23: 0.71207807 | AC23: 33.980987 | AD23: 0.68940298 | AF23: 2.2230235 | AG23: 0.22126156 | AI23: 13.89561 | AJ23: 0.57653385 | AL23: 66.936972 | AM23: 0.76621241 | AO23: 16.944395 | AP23: 0.63075983 | AR23: 0.70592317 | AS23: 0.12256168 | AU23: 2.2917979 | AV23: 0.22096615 | AX23: 42.40332 | AY23: 0.85810813 | BA23: 54.598959 | BB23: 0.87508934 | BD23: 0.69026873 | BE23: 0.11949491 | BG23: 2.5917239 | BH23: 0.2660499 | BJ23: 39.182351 | BK23: 0.75227768 | BM23: 57.535656 | BN23: 0.82916478
A24: Estonia | B24: -0.18499502 | C24: 0.016567314 | E24: 1.0180642 | F24: 0.0077548621 | H24: 1.5173377 | I24: 0.17265406 | K24: 9.3478151 | L24: 0.48222806 | N24: 50.655523 | O24: 0.75383504 | Q24: 38.479324 | R24: 0.81283665 | T24: 2.4904567 | U24: 0.21602701 | W24: 18.071714 | X24: 0.62489843 | Z24: 50.764808 | AA24: 0.73322339 | AC24: 28.673021 | AD24: 0.81897276 | AF24: 6.8645373 | AG24: 0.41807692 | AI24: 32.51381 | AJ24: 0.7877321 | AL24: 50.367958 | AM24: 0.84918095 | AO24: 10.253695 | AP24: 0.48577666 | AR24: 4.2142416 | AS24: 0.31958281 | AU24: 17.835062 | AV24: 0.59679198 | AX24: 48.733974 | AY24: 0.65949516 | BA24: 29.216722 | BB24: 0.69167924 | BD24: 1.7706972 | BE24: 0.18365277 | BG24: 9.2686744 | BH24: 0.4651331 | BJ24: 46.259134 | BK24: 0.75568106 | BM24: 42.701495 | BN24: 0.78475644
A25: Finland | B25: -0.11714228 | C25: 0.012884542 | E25: 0.93118338 | F25: 0.007439717 | H25: 1.5197836 | I25: 0.15245634 | K25: 7.659276 | L25: 0.37525638 | N25: 59.344936 | O25: 0.63794152 | Q25: 31.476004 | R25: 0.59463468 | T25: 2.7185594 | U25: 0.23687978 | W25: 17.118727 | X25: 0.53801163 | Z25: 63.082529 | AA25: 0.66261077 | AC25: 17.080185 | AD25: 0.48697956 | AF25: 4.222737 | AG25: 0.2653755 | AI25: 25.678176 | AJ25: 0.56332725 | AL25: 60.909544 | AM25: 0.67666724 | AO25: 9.189543 | AP25: 0.44309749 | AR25: 1.198934 | AS25: 0.11817648 | AU25: 6.7077343 | AV25: 0.34430752 | AX25: 60.178873 | AY25: 0.63450624 | BA25: 31.914459 | BB25: 0.67418504 | BD25: 1.3558666 | BE25: 0.13616052 | BG25: 8.0809819 | BH25: 0.4127235 | BJ25: 56.869167 | BK25: 0.64321363 | BM25: 33.693984 | BN25: 0.54073467
A26: France | B26: 0.27122914 | C26: 0.014566728 | E26: 0.95222799 | F26: 0.010178697 | H26: 1.2325801 | I26: 0.12896726 | K26: 5.234609 | L26: 0.3045711 | N26: 43.599212 | O26: 0.74077991 | Q26: 49.933599 | R26: 0.72902811 | T26: 9.5521301 | U26: 0.44069304 | W26: 21.532151 | X26: 0.67250537 | Z26: 46.226983 | AA26: 0.78116363 | AC26: 22.688736 | AD26: 0.67712163 | AF26: 5.2777181 | AG26: 0.32620565 | AI26: 21.619268 | AJ26: 0.49861728 | AL26: 50.546675 | AM26: 0.68793679 | AO26: 22.556339 | AP26: 0.58593372 | AR26: 1.3708777 | AS26: 0.18808149 | AU26: 6.1758454 | AV26: 0.3574891 | AX26: 40.967254 | AY26: 0.6039546 | BA26: 51.486023 | BB26: 0.69098893 | BD26: 1.1833394 | BE26: 0.15232689 | BG26: 5.2623672 | BH26: 0.29948631 | BJ26: 38.172995 | BK26: 0.69765934 | BM26: 55.381298 | BN26: 0.71476344
A27: Germany | B27: 0.074550392 | C27: 0.015887463 | D27: † | E27: 0.96070645 | F27: 0.010299789 | G27: † | H27: 0.90379257 | I27: 0.17477457 | K27: 7.3066479 | L27: 0.47773621 | N27: 52.652526 | O27: 0.93787164 | Q27: 39.137033 | R27: 0.83819866 | T27: 2.6158647 | U27: 0.30439803 | V27: † | W27: 14.126535 | X27: 0.59226296 | Y27: † | Z27: 45.46849 | AA27: 1.0155281 | AB27: † | AC27: 37.78911 | AD27: 0.83457104 | AE27: † | AF27: 3.8698436 | AG27: 0.26274124 | AH27: † | AI27: 23.906232 | AJ27: 0.69259568 | AK27: † | AL27: 56.112781 | AM27: 0.78288349 | AN27: † | AO27: 16.111143 | AP27: 0.6889377 | AQ27: † | AR27: 1.2455624 | AS27: 0.18694891 | AT27: † | AU27: 7.6933304 | AV27: 0.42060518 | AW27: † | AX27: 49.505227 | AY27: 0.71492969 | AZ27: † | BA27: 41.55588 | BB27: 0.67609824 | BC27: † | BD27: 1.0139415 | BE27: 0.18002308 | BF27: † | BG27: 6.6957811 | BH27: 0.38652498 | BI27: † | BJ27: 44.776176 | BK27: 0.93611569 | BL27: † | BM27: 47.514101 | BN27: 0.96939792 | BO27: †
A28: Greece | B28: -0.045323368 | C28: 0.013344683 | E28: 0.93335128 | F28: 0.0080915061 | H28: 2.3031315 | I28: 0.24970334 | K28: 8.3321457 | L28: 0.41488137 | N28: 54.7274 | O28: 0.73296014 | Q28: 34.637323 | R28: 0.68223741 | T28: 2.0792349 | U28: 0.20606336 | W28: 12.159273 | X28: 0.43328949 | Z28: 45.097218 | AA28: 0.73704755 | AC28: 40.664274 | AD28: 0.71511082 | AF28: 3.4273806 | AG28: 0.23452564 | AI28: 17.525075 | AJ28: 0.58595999 | AL28: 52.419327 | AM28: 0.74938358 | AO28: 26.628217 | AP28: 0.71712295 | AR28: 1.4226196 | AS28: 0.15922105 | AU28: 5.8143981 | AV28: 0.33725251 | AX28: 47.776158 | AY28: 0.7681447 | BA28: 44.986824 | BB28: 0.72351653 | BD28: 3.4677981 | BE28: 0.26535429 | BG28: 13.791137 | BH28: 0.49271709 | BJ28: 48.8004 | BK28: 0.68716748 | BM28: 33.940665 | BN28: 0.60543501
A29: Hungary | B29: 0.18779638 | C29: 0.017551106 | E29: 1.034142 | F29: 0.01073817 | H29: 1.6410307 | I29: 0.2243826 | K29: 6.3200261 | L29: 0.39546895 | N29: 40.29158 | O29: 0.78703585 | Q29: 51.747363 | R29: 0.83230517 | T29: 3.224608 | U29: 0.27764172 | W29: 14.504026 | X29: 0.50039581 | Z29: 42.283981 | AA29: 0.63154373 | AC29: 39.987385 | AD29: 0.74253079 | AF29: 5.8845318 | AG29: 0.37237902 | AI29: 21.772592 | AJ29: 0.68787882 | AL29: 50.875732 | AM29: 0.86331214 | AO29: 21.467144 | AP29: 0.66299315 | AR29: 1.2366565 | AS29: 0.18169719 | AU29: 6.8503046 | AV29: 0.41210737 | AX29: 36.431362 | AY29: 0.70181195 | BA29: 55.481677 | BB29: 0.7874408 | BD29: 3.496137 | BE29: 0.29922835 | BG29: 13.402193 | BH29: 0.44900661 | BJ29: 39.491141 | BK29: 0.82372635 | BM29: 43.610529 | BN29: 0.75092898
A30: Iceland | B30: -0.088781789 | C30: 0.016180255 | E30: 0.99989134 | F30: 0.011485077 | H30: 2.0155346 | I30: 0.23630514 | K30: 7.0442294 | L30: 0.50432687 | N30: 52.149449 | O30: 0.90107326 | Q30: 38.790787 | R30: 0.89984793 | T30: 1.8981217 | U30: 0.24209891 | W30: 8.1715007 | X30: 0.48696357 | Z30: 54.126079 | AA30: 0.92481488 | AC30: 35.804298 | AD30: 0.90711984 | AF30: 3.5726665 | AG30: 0.32684287 | AI30: 18.499597 | AJ30: 0.65212437 | AL30: 57.527759 | AM30: 0.8827107 | AO30: 20.399978 | AP30: 0.80746479 | AR30: 1.9193593 | AS30: 0.23752391 | AU30: 10.283983 | AV30: 0.51379005 | AX30: 57.136668 | AY30: 0.86398227 | BA30: 30.65999 | BB30: 0.81251196 | BD30: 1.7118126 | BE30: 0.23254474 | BG30: 6.4576076 | BH30: 0.43221564 | BJ30: 53.173625 | BK30: 0.90573798 | BM30: 38.656955 | BN30: 0.81150407
A31: Ireland | B31: -0.089399801 | C31: 0.014982076 | E31: 0.91334048 | F31: 0.0071215589 | H31: 0.43658489 | I31: 0.10041401 | K31: 3.8001539 | L31: 0.31124584 | N31: 50.496455 | O31: 0.71215796 | Q31: 45.266806 | R31: 0.78484426 | T31: 1.1159006 | U31: 0.17689203 | W31: 10.00361 | X31: 0.42044327 | Z31: 53.084375 | AA31: 0.69705429 | AC31: 35.796114 | AD31: 0.72004709 | AF31: 3.6620558 | AG31: 0.28024978 | AI31: 22.739058 | AJ31: 0.60900906 | AL31: 58.412213 | AM31: 0.67355046 | AO31: 15.186673 | AP31: 0.4511191 | AR31: 1.3486302 | AS31: 0.15938044 | AU31: 11.64278 | AV31: 0.47864816 | AX31: 59.752886 | AY31: 0.70526573 | BA31: 27.255703 | BB31: 0.66566251 | BD31: 1.0601737 | BE31: 0.16708707 | BG31: 10.144031 | BH31: 0.41435839 | BJ31: 56.835123 | BK31: 0.77900821 | BM31: 31.960672 | BN31: 0.76388899
A32: Israel | B32: m | C32: m | E32: m | F32: m | H32: m | I32: m | K32: m | L32: m | N32: m | O32: m | Q32: m | R32: m | T32: m | U32: m | W32: m | X32: m | Z32: m | AA32: m | AC32: m | AD32: m | AF32: m | AG32: m | AI32: m | AJ32: m | AL32: m | AM32: m | AO32: m | AP32: m | AR32: m | AS32: m | AU32: m | AV32: m | AX32: m | AY32: m | BA32: m | BB32: m | BD32: m | BE32: m | BG32: m | BH32: m | BJ32: m | BK32: m | BM32: m | BN32: m
A33: Italy | B33: m | C33: m | E33: m | F33: m | H33: 1.7457943 | I33: 0.19537482 | K33: 7.0164015 | L33: 0.36790563 | N33: 51.995566 | O33: 0.73646893 | Q33: 39.242238 | R33: 0.77048811 | T33: 14.518206 | U33: 0.53371253 | W33: 33.396687 | X33: 0.60297142 | Z33: 38.2174 | AA33: 0.67616041 | AC33: 13.867707 | AD33: 0.56131483 | AF33: 5.4635398 | AG33: 0.30621237 | AI33: 21.271319 | AJ33: 0.45325342 | AL33: 49.639704 | AM33: 0.80357672 | AO33: 23.625437 | AP33: 0.70360625 | AR33: 1.6644208 | AS33: 0.17887975 | AU33: 7.3769566 | AV33: 0.43243556 | AX33: 46.749069 | AY33: 0.74147315 | BA33: 44.209554 | BB33: 0.75154152 | BD33: 10.349194 | BE33: 0.46090545 | BG33: 23.574596 | BH33: 0.63745865 | BJ33: 43.238648 | BK33: 0.72257228 | BM33: 22.837563 | BN33: 0.51677587
A34: Japan | B34: -0.12914626 | C34: 0.01645362 | E34: 0.95512962 | F34: 0.0093713423 | H34: 2.2253905 | I34: 0.22533872 | K34: 6.6072802 | L34: 0.34236964 | N34: 56.073176 | O34: 0.70507214 | Q34: 35.094154 | R34: 0.76889013 | T34: 2.4280245 | U34: 0.22907114 | W34: 7.5163259 | X34: 0.36155425 | Z34: 45.795483 | AA34: 0.72670792 | AC34: 44.260166 | AD34: 0.80002074 | AF34: 10.849282 | AG34: 0.43397332 | AI34: 37.424601 | AJ34: 0.81304204 | AL34: 43.990137 | AM34: 0.7683539 | AO34: 7.7359806 | AP34: 0.35380114 | AR34: 1.6506436 | AS34: 0.18732726 | AU34: 4.1108702 | AV34: 0.243013 | AX34: 56.419652 | AY34: 0.67397695 | BA34: 37.818834 | BB34: 0.72078806 | BD34: 5.5219316 | BE34: 0.34771975 | BG34: 15.612431 | BH34: 0.44160877 | BJ34: 49.008307 | BK34: 0.70003527 | BM34: 29.85733 | BN34: 0.68596342
A35: Korea | B35: 0.032102615 | C35: 0.013760811 | E35: 1.0542859 | F35: 0.0073389898 | H35: 1.6191799 | I35: 0.15755056 | K35: 11.640475 | L35: 0.44367861 | N35: 42.838331 | O35: 0.58725954 | Q35: 43.902014 | R35: 0.60499885 | T35: 2.8746348 | U35: 0.23803202 | W35: 15.028172 | X35: 0.40829003 | Z35: 40.769007 | AA35: 0.62267688 | AC35: 41.328186 | AD35: 0.63768407 | AF35: 7.32241 | AG35: 0.37851751 | AI35: 26.681292 | AJ35: 0.58964561 | AL35: 43.454942 | AM35: 0.63967432 | AO35: 22.541356 | AP35: 0.53922355 | AR35: 1.3440085 | AS35: 0.15209907 | AU35: 8.3616056 | AV35: 0.3668514 | AX35: 45.394375 | AY35: 0.54888892 | BA35: 44.900011 | BB35: 0.58990726 | BD35: 1.850779 | BE35: 0.1672706 | BG35: 11.465707 | BH35: 0.49164922 | BJ35: 46.076332 | BK35: 0.49583893 | BM35: 40.607183 | BN35: 0.52135711
A36: Latvia | B36: 0.03295703 | C36: 0.016066855 | E36: 0.99676123 | F36: 0.0091800065 | H36: 1.7150338 | I36: 0.20640425 | K36: 11.152712 | L36: 0.47456553 | N36: 50.447027 | O36: 0.70606218 | Q36: 36.685228 | R36: 0.72539522 | T36: 3.2374617 | U36: 0.23840433 | W36: 19.403103 | X36: 0.68385514 | Z36: 48.221293 | AA36: 0.85734906 | AC36: 29.138142 | AD36: 0.60599485 | AF36: 8.8634388 | AG36: 0.39228096 | AI36: 35.014382 | AJ36: 0.72421622 | AL36: 45.571502 | AM36: 0.75121044 | AO36: 10.550677 | AP36: 0.50500238 | AR36: 1.4410306 | AS36: 0.1723192 | AU36: 7.7167021 | AV36: 0.41951988 | AX36: 48.08834 | AY36: 0.84542684 | BA36: 42.753927 | BB36: 0.78660405 | BD36: 1.8243028 | BE36: 0.2007108 | BG36: 8.8968071 | BH36: 0.43106943 | BJ36: 40.588583 | BK36: 0.8052893 | BM36: 48.690307 | BN36: 0.83979436
A37: Lithuania | B37: 0.079815047 | C37: 0.013829578 | E37: 1.0059563 | F37: 0.0079554648 | H37: 1.8330559 | I37: 0.19547498 | K37: 7.8662828 | L37: 0.38969922 | N37: 46.588772 | O37: 0.67040732 | Q37: 43.711889 | R37: 0.68673717 | T37: 2.7253042 | U37: 0.2599223 | W37: 15.146648 | X37: 0.43589609 | Z37: 49.148562 | AA37: 0.63034654 | AC37: 32.979486 | AD37: 0.6171591 | AF37: 4.4149242 | AG37: 0.29270647 | AI37: 22.699334 | AJ37: 0.54469285 | AL37: 53.683012 | AM37: 0.72474692 | AO37: 19.202729 | AP37: 0.58330858 | AR37: 1.6409763 | AS37: 0.16312938 | AU37: 8.1473535 | AV37: 0.38733265 | AX37: 48.467652 | AY37: 0.6069188 | BA37: 41.744018 | BB37: 0.65490841 | BD37: 1.4334023 | BE37: 0.1502386 | BG37: 7.5927271 | BH37: 0.39427191 | BJ37: 44.308699 | BK37: 0.59327669 | BM37: 46.665172 | BN37: 0.6514093
A38: Luxembourg | B38: 0.073416402 | C38: 0.013105162 | E38: 1.0060561 | F38: 0.0088230418 | H38: 1.7304701 | I38: 0.17764303 | K38: 6.9983033 | L38: 0.3476563 | N38: 48.389425 | O38: 0.74085832 | Q38: 42.881802 | R38: 0.66447982 | T38: 3.5984312 | U38: 0.28677703 | W38: 12.864638 | X38: 0.50342924 | Z38: 41.862516 | AA38: 0.78316578 | AC38: 41.674415 | AD38: 0.70618725 | AF38: 3.8163075 | AG38: 0.30922051 | AI38: 21.126012 | AJ38: 0.60131929 | AL38: 54.675508 | AM38: 0.70668894 | AO38: 20.382173 | AP38: 0.58603459 | AR38: 1.8834681 | AS38: 0.18739837 | AU38: 8.0111103 | AV38: 0.38863819 | AX38: 48.328621 | AY38: 0.71731982 | BA38: 41.7768 | BB38: 0.64751117 | BD38: 1.6953349 | BE38: 0.18496619 | BG38: 7.5366224 | BH38: 0.3904418 | BJ38: 44.292643 | BK38: 0.76798722 | BM38: 46.4754 | BN38: 0.73743777
A39: Mexico | B39: 0.35851249 | C39: 0.014895203 | D39: † | E39: 0.92253078 | F39: 0.014441702 | G39: † | H39: 0.7883207 | I39: 0.16826911 | K39: 3.5919201 | L39: 0.24176088 | N39: 39.645878 | O39: 0.60437802 | Q39: 55.973881 | R39: 0.65228762 | T39: 1.4226904 | U39: 0.18470787 | W39: 6.4188347 | X39: 0.4169876 | Z39: 46.9887 | AA39: 0.75694168 | AC39: 45.169775 | AD39: 0.74344999 | AF39: 4.85255 | AG39: 0.31898063 | AI39: 15.730282 | AJ39: 0.49870066 | AL39: 47.10543 | AM39: 0.66522357 | AO39: 32.311738 | AP39: 0.66891236 | AR39: 0.88191738 | AS39: 0.24350798 | AT39: † | AU39: 4.9471133 | AV39: 0.33519631 | AW39: † | AX39: 34.097977 | AY39: 0.66124121 | AZ39: † | BA39: 60.072992 | BB39: 0.70268996 | BC39: † | BD39: 1.3622812 | BE39: 0.21482641 | BF39: † | BG39: 6.1571693 | BH39: 0.36744141 | BI39: † | BJ39: 42.448798 | BK39: 0.74050115 | BL39: † | BM39: 50.031751 | BN39: 0.72323108 | BO39: †
A40: Netherlands* | B40: 0.082553189 | C40: 0.018435867 | E40: 0.86610676 | F40: 0.0085127921 | H40: 0.46033622 | I40: 0.12964275 | K40: 2.695352 | L40: 0.27205348 | N40: 46.829938 | O40: 1.0605666 | Q40: 50.014374 | R40: 1.0544857 | T40: 1.6308971 | U40: 0.26516782 | W40: 7.7620526 | X40: 0.4735583 | Z40: 54.3095 | AA40: 0.7810656 | AC40: 36.29755 | AD40: 0.94715639 | AF40: 1.9371002 | AG40: 0.21456969 | AI40: 14.658647 | AJ40: 0.50198208 | AL40: 64.431621 | AM40: 0.76062507 | AO40: 18.972631 | AP40: 0.74858025 | AR40: 0.59284955 | AS40: 0.14598039 | AU40: 3.2825285 | AV40: 0.31971697 | AX40: 44.840262 | AY40: 0.89202458 | BA40: 51.28436 | BB40: 0.88374665 | BD40: 3.4567676 | BE40: 0.31372075 | BG40: 15.509589 | BH40: 0.76929988 | BJ40: 58.662343 | BK40: 0.80219347 | BM40: 22.371301 | BN40: 0.92578307
A41: New Zealand | B41: m | C41: m | E41: m | F41: m | H41: m | I41: m | K41: m | L41: m | N41: m | O41: m | Q41: m | R41: m | T41: m | U41: m | W41: m | X41: m | Z41: m | AA41: m | AC41: m | AD41: m | AF41: m | AG41: m | AI41: m | AJ41: m | AL41: m | AM41: m | AO41: m | AP41: m | AR41: m | AS41: m | AU41: m | AV41: m | AX41: m | AY41: m | BA41: m | BB41: m | BD41: m | BE41: m | BG41: m | BH41: m | BJ41: m | BK41: m | BM41: m | BN41: m
A42: Norway | B42: m | C42: m | E42: m | F42: m | H42: m | I42: m | K42: m | L42: m | N42: m | O42: m | Q42: m | R42: m | T42: m | U42: m | W42: m | X42: m | Z42: m | AA42: m | AC42: m | AD42: m | AF42: m | AG42: m | AI42: m | AJ42: m | AL42: m | AM42: m | AO42: m | AP42: m | AR42: m | AS42: m | AU42: m | AV42: m | AX42: m | AY42: m | BA42: m | BB42: m | BD42: m | BE42: m | BG42: m | BH42: m | BJ42: m | BK42: m | BM42: m | BN42: m
A43: Poland | B43: -0.076022968 | C43: 0.01772141 | E43: 1.036487 | F43: 0.0087993701 | H43: 1.8725211 | I43: 0.22795388 | K43: 11.208843 | L43: 0.53229813 | N43: 52.42325 | O43: 0.80011317 | Q43: 34.495386 | R43: 0.73064148 | T43: 2.7985954 | U43: 0.21403091 | W43: 16.67241 | X43: 0.5476076 | Z43: 48.006529 | AA43: 0.60616953 | AC43: 32.522466 | AD43: 0.71789392 | AF43: 4.5844085 | AG43: 0.27907811 | AI43: 28.110991 | AJ43: 0.64306238 | AL43: 55.445356 | AM43: 0.77714769 | AO43: 11.859244 | AP43: 0.52135531 | AR43: 1.967391 | AS43: 0.17994696 | AU43: 10.781774 | AV43: 0.439009 | AX43: 49.118647 | AY43: 0.78171074 | BA43: 38.132188 | BB43: 0.82296423 | BD43: 1.593231 | BE43: 0.19870539 | BG43: 9.6793742 | BH43: 0.42322657 | BJ43: 47.714169 | BK43: 0.85206831 | BM43: 41.013226 | BN43: 0.87389909
...

Sheet Table III.B1.12.2
A1: PISA 2018 Results (Volume III) - © OECD 2019
A2: Annex B1 | B2: Annex B1.12 Results (tables): Students' feelings
A3: Version 2 - Last updated: 02-Dec-2019
A4: Disclaimer: http://oe.cd/disclaimer
A6: Table III.B1.12.2
A7: Students' negative feelings
A8: Based on students' reports
B11: Percentage of students who reported feeling the following:
B12: Scared | N12: Miserable | Z12: Afraid | AL12: Sad
B13: Never | E13: Rarely | H13: Sometimes | K13: Always | N13: Never | Q13: Rarely | T13: Sometimes | W13: Always | Z13: Never | AC13: Rarely | AF13: Sometimes | AI13: Always | AL13: Never | AO13: Rarely | AR13: Sometimes | AU13: Always
B14: % | C14: S.E. | E14: % | F14: S.E. | H14: % | I14: S.E. | K14: % | L14: S.E. | N14: % | O14: S.E. | Q14: % | R14: S.E. | T14: % | U14: S.E. | W14: % | X14: S.E. | Z14: % | AA14: S.E. | AC14: % | AD14: S.E. | AF14: % | AG14: S.E. | AI14: % | AJ14: S.E. | AL14: % | AM14: S.E. | AO14: % | AP14: S.E. | AR14: % | AS14: S.E. | AU14: % | AV14: S.E.
A15: OECD
A16: Australia | B16: m | C16: m | E16: m | F16: m | H16: m | I16: m | K16: m | L16: m | N16: m | O16: m | Q16: m | R16: m | T16: m | U16: m | W16: m | X16: m | Z16: m | AA16: m | AC16: m | AD16: m | AF16: m | AG16: m | AI16: m | AJ16: m | AL16: m | AM16: m | AO16: m | AP16: m | AR16: m | AS16: m | AU16: m | AV16: m
A17: Austria | B17: 18.326901 | C17: 0.63620979 | E17: 49.385697 | F17: 0.86899202 | H17: 28.503796 | I17: 0.78649893 | K17: 3.7836062 | L17: 0.34246389 | N17: 11.466557 | O17: 0.45964381 | Q17: 48.272017 | R17: 0.77050185 | T17: 35.073468 | U17: 0.76374829 | W17: 5.1879582 | X17: 0.31083758 | Z17: 7.9873433 | AA17: 0.41386611 | AC17: 35.978954 | AD17: 0.76753261 | AF17: 45.369357 | AG17: 0.70516071 | AI17: 10.664346 | AJ17: 0.50002067 | AL17: 9.8265863 | AM17: 0.45829687 | AO17: 46.316903 | AP17: 0.81167841 | AR17: 38.436892 | AS17: 0.85606572 | AU17: 5.4196185 | AV17: 0.30309998
A18: Belgium | B18: m | C18: m | E18: m | F18: m | H18: m | I18: m | K18: m | L18: m | N18: m | O18: m | Q18: m | R18: m | T18: m | U18: m | W18: m | X18: m | Z18: m | AA18: m | AC18: m | AD18: m | AF18: m | AG18: m | AI18: m | AJ18: m | AL18: m | AM18: m | AO18: m | AP18: m | AR18: m | AS18: m | AU18: m | AV18: m
A19: Canada | B19: 15.127492 | C19: 0.37385417 | E19: 46.475588 | F19: 0.51829927 | H19: 33.005461 | I19: 0.54469038 | K19: 5.3914599 | L19: 0.2262172 | N19: 16.831583 | O19: 0.40244774 | Q19: 42.130551 | R19: 0.50494856 | T19: 34.913629 | U19: 0.47978269 | W19: 6.124237 | X19: 0.267035 | Z19: 16.442779 | AA19: 0.37901986 | AC19: 42.096135 | AD19: 0.49074051 | AF19: 34.028096 | AG19: 0.45311964 | AI19: 7.4329904 | AJ19: 0.20395318 | AL19: 8.1834052 | AM19: 0.27128923 | AO19: 35.395753 | AP19: 0.44129223 | AR19: 47.449758 | AS19: 0.50325073 | AU19: 8.9710832 | AV19: 0.3207138
A20: Chile | B20: 28.747107 | C20: 0.69680563 | E20: 46.715193 | F20: 0.85390307 | H20: 21.235684 | I20: 0.55928139 | K20: 3.3020157 | L20: 0.26475431 | N20: 16.104436 | O20: 0.53219485 | Q20: 33.31023 | R20: 0.61358215 | T20: 41.586106 | U20: 0.7484145 | W20: 8.9992284 | X20: 0.40414623 | Z20: 27.481362 | AA20: 0.75647819 | AC20: 46.298224 | AD20: 0.79445472 | AF20: 22.742587 | AG20: 0.60493436 | AI20: 3.4778268 | AJ20: 0.26394896 | AL20: 9.6317203 | AM20: 0.4047122 | AO20: 36.122426 | AP20: 0.60699929 | AR20: 46.35533 | AS20: 0.69514267 | AU20: 7.890524 | AV20: 0.40587915
A21: Colombia | B21: 11.573053 | C21: 0.50864148 | E21: 50.573809 | F21: 0.71188327 | H21: 33.917078 | I21: 0.67198521 | K21: 3.9360592 | L21: 0.31670759 | N21: 34.133089 | O21: 0.81521745 | Q21: 40.684376 | R21: 0.68365682 | T21: 21.75138 | U21: 0.58639159 | W21: 3.4311558 | X21: 0.25155383 | Z21: 5.179996 | AA21: 0.35496907 | AC21: 35.835758 | AD21: 0.80416 | AF21: 48.362988 | AG21: 0.71042399 | AI21: 10.621259 | AJ21: 0.55455744 | AL21: 7.3302806 | AM21: 0.41180265 | AO21: 42.721647 | AP21: 0.7832225 | AR21: 44.212254 | AS21: 0.74630499 | AU21: 5.7358178 | AV21: 0.29239589
A22: Czech Republic | B22: 8.2031991 | C22: 0.39997173 | E22: 37.169952 | F22: 0.71700932 | H22: 45.977967 | I22: 0.72661309 | K22: 8.6488813 | L22: 0.51396234 | N22: 10.380837 | O22: 0.46804984 | Q22: 45.966828 | R22: 0.59582249 | T22: 38.025985 | U22: 0.69487499 | W22: 5.6263506 | X22: 0.3730577 | Z22: 7.2004212 | AA22: 0.36272035 | AC22: 34.116034 | AD22: 0.76695493 | AF22: 46.214839 | AG22: 0.72332456 | AI22: 12.468706 | AJ22: 0.59621809 | AL22: 6.8291859 | AM22: 0.42494711 | AO22: 41.342281 | AP22: 0.71593597 | AR22: 45.263429 | AS22: 0.73250948 | AU22: 6.5651038 | AV22: 0.42580965
A23: Denmark | B23: 13.545513 | C23: 0.48079987 | E23: 51.997616 | F23: 0.85749564 | H23: 32.162474 | I23: 0.68980911 | K23: 2.2943975 | L23: 0.23838389 | N23: 20.754162 | O23: 0.52920678 | Q23: 50.560287 | R23: 0.72230813 | T23: 26.522243 | U23: 0.71039608 | W23: 2.1633075 | X23: 0.1953961 | Z23: 44.441774 | AA23: 0.6593541 | AC23: 32.487986 | AD23: 0.60440637 | AF23: 18.867598 | AG23: 0.50591213 | AI23: 4.2026414 | AJ23: 0.28553111 | AL23: 9.1017305 | AM23: 0.44393118 | AO23: 43.289754 | AP23: 0.69351928 | AR23: 44.424318 | AS23: 0.71206704 | AU23: 3.1841978 | AV23: 0.23547471
A24: Estonia | B24: 11.448359 | C24: 0.47936248 | E24: 54.996341 | F24: 0.77423608 | H24: 30.360034 | I24: 0.76249564 | K24: 3.195266 | L24: 0.28234781 | N24: 16.112746 | O24: 0.58330333 | Q24: 40.805111 | R24: 0.73329882 | T24: 35.900337 | U24: 0.72345161 | W24: 7.1818064 | X24: 0.44870028 | Z24: 7.0490131 | AA24: 0.37479592 | AC24: 40.141303 | AD24: 0.72245512 | AF24: 42.722685 | AG24: 0.80144749 | AI24: 10.086999 | AJ24: 0.5297027 | AL24: 5.5066916 | AM24: 0.35990477 | AO24: 43.169072 | AP24: 0.71042523 | AR24: 42.210107 | AS24: 0.75864811 | AU24: 9.1141299 | AV24: 0.44943366
A25: Finland | B25: 14.847719 | C25: 0.43424509 | E25: 59.147419 | F25: 0.6008791 | H25: 23.748747 | I25: 0.47661906 | K25: 2.2561155 | L25: 0.2304637 | N25: 16.500898 | O25: 0.53882062 | Q25: 51.668217 | R25: 0.65679223 | T25: 29.154974 | U25: 0.55995931 | W25: 2.6759112 | X25: 0.23774051 | Z25: 6.0068492 | AA25: 0.3305564 | AC25: 43.109663 | AD25: 0.5987248 | AF25: 43.494545 | AG25: 0.64147197 | AI25: 7.3889429 | AJ25: 0.35559977 | AL25: 6.7901452 | AM25: 0.37092554 | AO25: 47.451506 | AP25: 0.55706413 | AR25: 42.033067 | AS25: 0.53938949 | AU25: 3.7252827 | AV25: 0.25427983
A26: France | B26: 20.729229 | C26: 0.54135218 | E26: 50.921892 | F26: 0.81929537 | H26: 25.123204 | I26: 0.66405381 | K26: 3.2256748 | L26: 0.23371972 | N26: 16.807647 | O26: 0.5468403 | Q26: 46.259979 | R26: 0.72431266 | T26: 33.107281 | U26: 0.59568838 | W26: 3.8250932 | X26: 0.26286562 | Z26: 8.4519816 | AA26: 0.39042369 | AC26: 33.886892 | AD26: 0.61351551 | AF26: 42.830971 | AG26: 0.59105639 | AI26: 14.830156 | AJ26: 0.49121929 | AL26: 10.128164 | AM26: 0.3814828 | AO26: 44.051709 | AP26: 0.66915463 | AR26: 41.037079 | AS26: 0.68155591 | AU26: 4.7830479 | AV26: 0.25861588
A27: Germany | B27: 18.501087 | C27: 0.67676896 | D27: † | E27: 53.282833 | F27: 0.77201945 | G27: † | H27: 25.360367 | I27: 0.71418313 | J27: † | K27: 2.8557138 | L27: 0.27328554 | M27: † | N27: 9.6793477 | O27: 0.50848488 | P27: † | Q27: 49.300717 | R27: 0.7924181 | S27: † | T27: 36.755852 | U27: 0.85996116 | V27: † | W27: 4.2640829 | X27: 0.32505161 | Y27: † | Z27: 7.1664345 | AA27: 0.4777871 | AB27: † | AC27: 38.251871 | AD27: 0.78206924 | AE27: † | AF27: 44.628367 | AG27: 0.84473901 | AH27: † | AI27: 9.9533271 | AJ27: 0.53263055 | AK27: † | AL27: 8.557015 | AM27: 0.49129112 | AN27: † | AO27: 48.289495 | AP27: 0.84216782 | AQ27: † | AR27: 39.31585 | AS27: 0.85095072 | AT27: † | AU27: 3.8376403 | AV27: 0.368397 | AW27: †
A28: Greece | B28: 13.749462 | C28: 0.45792436 | E28: 47.963501 | F28: 0.75487539 | H28: 33.049034 | I28: 0.6253435 | K28: 5.2380024 | L28: 0.27456535 | N28: 17.32555 | O28: 0.49364835 | Q28: 46.586178 | R28: 0.65835715 | T28: 30.846526 | U28: 0.61914065 | W28: 5.2417456 | X28: 0.29755705 | Z28: 6.8879061 | AA28: 0.36835697 | AC28: 32.779505 | AD28: 0.6310674 | AF28: 45.564821 | AG28: 0.6942849 | AI28: 14.767767 | AJ28: 0.44193669 | AL28: 7.0242402 | AM28: 0.3445434 | AO28: 41.931126 | AP28: 0.66664648 | AR28: 45.534713 | AS28: 0.7273278 | AU28: 5.5099215 | AV28: 0.30715832
A29: Hungary | B29: 20.892561 | C29: 0.66564073 | E29: 49.540298 | F29: 0.82032444 | H29: 26.175988 | I29: 0.7137706 | K29: 3.3911523 | L29: 0.2919893 | N29: 13.5473 | O29: 0.51155031 | Q29: 45.039746 | R29: 0.84719471 | T29: 34.732333 | U29: 0.80958589 | W29: 6.6806213 | X29: 0.39122296 | Z29: 17.123065 | AA29: 0.65805964 | AC29: 41.933729 | AD29: 0.77694627 | AF29: 30.3802 | AG29: 0.70175279 | AI29: 10.563005 | AJ29: 0.55018365 | AL29: 10.240478 | AM29: 0.44645 | AO29: 44.897436 | AP29: 0.93168679 | AR29: 39.517343 | AS29: 0.86157697 | AU29: 5.3447437 | AV29: 0.38107354
A30: Iceland | B30: 24.244992 | C30: 0.78571375 | E30: 49.444279 | F30: 1.0068376 | H30: 23.4006 | I30: 0.77728127 | K30: 2.9101297 | L30: 0.34812649 | N30: 17.663475 | O30: 0.61527878 | Q30: 43.071724 | R30: 0.87729629 | T30: 33.160789 | U30: 0.7748697 | W30: 6.104011 | X30: 0.41227519 | Z30: 23.563578 | AA30: 0.83294621 | AC30: 48.182517 | AD30: 0.83343612 | AF30: 24.156158 | AG30: 0.69537061 | AI30: 4.0977474 | AJ30: 0.34175807 | AL30: 13.037307 | AM30: 0.53113155 | AO30: 42.65765 | AP30: 1.0188 | AR30: 38.535843 | AS30: 0.96637399 | AU30: 5.7691999 | AV30: 0.38859662
A31: Ireland | B31: 12.105211 | C31: 0.39574314 | E31: 51.696792 | F31: 0.69354154 | H31: 33.754629 | I31: 0.73645069 | K31: 2.4433685 | L31: 0.19806375 | N31: 16.186743 | O31: 0.55592204 | Q31: 47.65256 | R31: 0.68498693 | T31: 33.275554 | U31: 0.80103122 | W31: 2.885143 | X31: 0.24543758 | Z31: 14.330508 | AA31: 0.45254878 | AC31: 51.737857 | AD31: 0.69118434 | AF31: 31.016934 | AG31: 0.73187634 | AI31: 2.9147008 | AJ31: 0.2202136 | AL31: 4.4472876 | AM31: 0.24327871 | AO31: 37.523746 | AP31: 0.78094231 | AR31: 53.056025 | AS31: 0.73516452 | AU31: 4.9729417 | AV31: 0.29212985
A32: Israel | B32: m | C32: m | E32: m | F32: m | H32: m | I32: m | K32: m | L32: m | N32: m | O32: m | Q32: m | R32: m | T32: m | U32: m | W32: m | X32: m | Z32: m | AA32: m | AC32: m | AD32: m | AF32: m | AG32: m | AI32: m | AJ32: m | AL32: m | AM32: m | AO32: m | AP32: m | AR32: m | AS32: m | AU32: m | AV32: m
A33: Italy | B33: 12.738935 | C33: 0.45081645 | E33: 46.667779 | F33: 0.74930643 | H33: 36.29144 | I33: 0.62985991 | K33: 4.3018452 | L33: 0.31677434 | N33: 11.44823 | O33: 0.40871648 | Q33: 42.443545 | R33: 0.62418312 | T33: 39.70858 | U33: 0.65940684 | W33: 6.399645 | X33: 0.39894786 | Z33: 19.920193 | AA33: 0.55449582 | AC33: 49.027627 | AD33: 0.72918564 | AF33: 27.388867 | AG33: 0.70946843 | AI33: 3.6633133 | AJ33: 0.27213607 | AL33: 6.856278 | AM33: 0.35260236 | AO33: 37.888006 | AP33: 0.70563571 | AR33: 49.084406 | AS33: 0.762299 | AU33: 6.17131 | AV33: 0.37758502
A34: Japan | B34: 9.2318562 | C34: 0.41960074 | E34: 30.10525 | F34: 0.67926575 | H34: 50.725838 | I34: 0.78653486 | K34: 9.9370553 | L34: 0.41939548 | N34: 16.202347 | O34: 0.52558151 | Q34: 38.254687 | R34: 0.65265553 | T34: 37.449275 | U34: 0.63726401 | W34: 8.0936914 | X34: 0.39706809 | Z34: 4.1987839 | AA34: 0.29665004 | AC34: 12.608044 | AD34: 0.45906664 | AF34: 54.82643 | AG34: 0.62138441 | AI34: 28.366742 | AJ34: 0.62254814 | AL34: 6.6733032 | AM34: 0.36471349 | AO34: 27.727528 | AP34: 0.6008473 | AR34: 54.275049 | AS34: 0.74004733 | AU34: 11.324119 | AV34: 0.4806425
A35: Korea | B35: 15.735533 | C35: 0.5016564 | E35: 36.412794 | F35: 0.6553399 | H35: 38.304713 | I35: 0.67060176 | K35: 9.5469599 | L35: 0.39884646 | N35: 34.9915 | O35: 0.64395107 | Q35: 35.268279 | R35: 0.53212717 | T35: 24.325407 | U35: 0.55663288 | W35: 5.4148139 | X35: 0.32149105 | Z35: 7.8488954 | AA35: 0.39743495 | AC35: 23.375504 | AD35: 0.55445598 | AF35: 44.707738 | AG35: 0.57169937 | AI35: 24.067862 | AJ35: 0.65569225 | AL35: 11.817867 | AM35: 0.48105836 | AO35: 35.830267 | AP35: 0.62779369 | AR35: 42.504677 | AS35: 0.58211275 | AU35: 9.8471892 | AV35: 0.47887935
A36: Latvia | B36: 9.9088445 | C36: 0.46972537 | E36: 53.492613 | F36: 0.77855203 | H36: 32.298433 | I36: 0.77206987 | K36: 4.3001098 | L36: 0.31985614 | N36: 17.948021 | O36: 0.65939104 | Q36: 44.077877 | R36: 0.82332596 | T36: 31.27688 | U36: 0.71560206 | W36: 6.6972225 | X36: 0.386375 | Z36: 9.1415106 | AA36: 0.42630398 | AC36: 46.107386 | AD36: 0.7693368 | AF36: 36.612624 | AG36: 0.79386205 | AI36: 8.1384794 | AJ36: 0.43884609 | AL36: 6.2445903 | AM36: 0.35618966 | AO36: 43.392724 | AP36: 0.77145493 | AR36: 42.45507 | AS36: 0.77297644 | AU36: 7.9076152 | AV36: 0.45432578
A37: Lithuania | B37: 17.219221 | C37: 0.56068314 | E37: 52.059597 | F37: 0.72147107 | H37: 27.700967 | I37: 0.60297847 | K37: 3.0202162 | L37: 0.24461157 | N37: 31.890558 | O37: 0.64165606 | Q37: 38.573645 | R37: 0.69447951 | T37: 24.095424 | U37: 0.6423852 | W37: 5.4403729 | X37: 0.31089802 | Z37: 22.072914 | AA37: 0.56810714 | AC37: 46.538809 | AD37: 0.6617357 | AF37: 26.632748 | AG37: 0.56539344 | AI37: 4.7555284 | AJ37: 0.28636924 | AL37: 12.848346 | AM37: 0.52835015 | AO37: 42.537896 | AP37: 0.7779275 | AR37: 38.625623 | AS37: 0.72292345 | AU37: 5.9881349 | AV37: 0.34323387
A38: Luxembourg | B38: 16.799929 | C38: 0.53921584 | E38: 47.893205 | F38: 0.716319 | H38: 30.513351 | I38: 0.5948178 | K38: 4.7935156 | L38: 0.34327399 | N38: 11.048541 | O38: 0.44081687 | Q38: 45.029995 | R38: 0.69394949 | T38: 38.041455 | U38: 0.71568998 | W38: 5.8800096 | X38: 0.39240664 | Z38: 7.6436969 | AA38: 0.37381579 | AC38: 32.921342 | AD38: 0.61525763 | AF38: 46.864068 | AG38: 0.73973437 | AI38: 12.570892 | AJ38: 0.53689856 | AL38: 8.5846409 | AM38: 0.38957536 | AO38: 42.41652 | AP38: 0.70564838 | AR38: 42.678966 | AS38: 0.67135999 | AU38: 6.319873 | AV38: 0.36276092
A39: Mexico | B39: 22.967563 | C39: 0.66302708 | D39: † | E39: 47.913336 | F39: 0.58103092 | G39: † | H39: 26.427101 | I39: 0.69141041 | J39: † | K39: 2.6919998 | L39: 0.25360189 | M39: † | N39: 19.430103 | O39: 0.54105275 | Q39: 37.163982 | R39: 0.77938557 | T39: 37.021998 | U39: 0.76228827 | W39: 6.3839167 | X39: 0.35218456 | Z39: 22.300501 | AA39: 0.69662123 | AB39: † | AC39: 48.375798 | AD39: 0.7986451 | AE39: † | AF39: 26.379818 | AG39: 0.78425794 | AH39: † | AI39: 2.9438822 | AJ39: 0.23399958 | AK39: † | AL39: 11.72529 | AM39: 0.43380262 | AN39: † | AO39: 38.316052 | AP39: 0.72627961 | AQ39: † | AR39: 43.784832 | AS39: 0.77420372 | AT39: † | AU39: 6.1738253 | AV39: 0.34814768 | AW39: †
A40: Netherlands* | B40: 20.403573 | C40: 0.71238471 | E40: 50.940173 | F40: 0.83522318 | H40: 26.573048 | I40: 0.76711693 | K40: 2.0832053 | L40: 0.24600201 | N40: 22.099542 | O40: 0.81805903 | Q40: 47.12223 | R40: 0.92595123 | T40: 28.426881 | U40: 0.79066421 | W40: 2.3513466 | X40: 0.2686139 | Z40: 7.7523944 | AA40: 0.45690377 | AC40: 34.378499 | AD40: 0.80271681 | AF40: 50.145924 | AG40: 0.869853 | AI40: 7.7231825 | AJ40: 0.52125853 | AL40: 9.7067744 | AM40: 0.56748286 | AO40: 45.20026 | AP40: 0.80965651 | AR40: 42.463515 | AS40: 0.84969786 | AU40: 2.6294505 | AV40: 0.29122469
A41: New Zealand | B41: m | C41: m | E41: m | F41: m | H41: m | I41: m | K41: m | L41: m | N41: m | O41: m | Q41: m | R41: m | T41: m | U41: m | W41: m | X41: m | Z41: m | AA41: m | AC41: m | AD41: m | AF41: m | AG41: m | AI41: m | AJ41: m | AL41: m | AM41: m | AO41: m | AP41: m | AR41: m | AS41: m | AU41: m | AV41: m
A42: Norway | B42: m | C42: m | E42: m | F42: m | H42: m | I42: m | K42: m | L42: m | N42: m | O42: m | Q42: m | R42: m | T42: m | U42: m | W42: m | X42: m | Z42: m | AA42: m | AC42: m | AD42: m | AF42: m | AG42: m | AI42: m | AJ42: m | AL42: m | AM42: m | AO42: m | AP42: m | AR42: m | AS42: m | AU42: m | AV42: m
A43: Poland | B43: 14.720232 | C43: 0.54823994 | E43: 54.552356 | F43: 0.66567445 | H43: 26.960516 | I43: 0.58947858 | K43: 3.7668964 | L43: 0.31693202 | N43: 9.0238666 | O43: 0.3654307 | Q43: 46.565258 | R43: 0.74265859 | T43: 37.219906 | U43: 0.66547396 | W43: 7.1909695 | X43: 0.42462287 | Z43: 17.960772 | AA43: 0.50415426 | AC43: 56.821032 | AD43: 0.71721287 | AF43: 21.38372 | AG43: 0.57487866 | AI43: 3.8344751 | AJ43: 0.33117855 | AL43: 6.3085298 | AM43: 0.33156907 | AO43: 43.315193 | AP43: 0.70535315 | AR43: 42.597811 | AS43: 0.75795011 | AU43: 7.7784662 | AV43: 0.43599398
...

Sheet Table III.B1.12.3
A1: PISA 2018 Results (Volume III) - © OECD 2019
A2: Annex B1 | B2: Annex B1.12 Results (tables): Students' feelings
A3: Version 2 - Last updated: 02-Dec-2019
A4: Disclaimer: http://oe.cd/disclaimer
A6: Table III.B1.12.3
A7: Prevalence of happiness in schools
A8: Based on students' reports
B11: Percentage of students who feel happy sometimes or always | E11: Percentage of students who are in schools where…
E12: Over 90% of students feel happy sometimes or always | H12: Between 75% and 90% of students feel happy sometimes or always | K12: Between 25% and 75% of students feel happy sometimes or always | N12: Between 10% and 25% of students feel happy sometimes or always | Q12: 10% of students or less feel happy sometimes or always
B14: % | C14: S.E. | E14: % | F14: S.E. | H14: % | I14: S.E. | K14: % | L14: S.E. | N14: % | O14: S.E. | Q14: % | R14: S.E.
A15: OECD
A16: Australia | B16: m | C16: m | E16: m | F16: m | H16: m | I16: m | K16: m | L16: m | N16: m | O16: m | Q16: m | R16: m
A17: Austria | B17: 91.434474 | C17: 0.46713294 | E17: 67.839586 | F17: 3.0328402 | H17: 28.297854 | I17: 2.938277 | K17: 3.8625606 | L17: 1.183681 | N17: 0 | O17: c | Q17: 0 | R17: c
A18: Belgium | B18: m | C18: m | E18: m | F18: m | H18: m | I18: m | K18: m | L18: m | N18: m | O18: m | Q18: m | R18: m
A19: Canada | B19: 93.195559 | C19: 0.21534035 | E19: 76.019739 | F19: 1.9629649 | H19: 23.197079 | I19: 1.9227315 | K19: 0.31742133 | L19: 0.13427188 | N19: 0 | O19: c | Q19: 0.46576087 | R19: 0.45916424
A20: Chile | B20: 93.697992 | C20: 0.35851601 | E20: 80.342035 | F20: 2.7803762 | H20: 18.315293 | I20: 2.7519826 | K20: 1.3109873 | L20: 0.522297 | N20: 0 | O20: c | Q20: 0.031684749 | R20: 0.031599494
A21: Colombia | B21: 92.753771 | C21: 0.37176031 | E21: 70.81681 | F21: 3.3578227 | H21: 28.592878 | I21: 3.3566126 | K21: 0.59031204 | L21: 0.36338721 | N21: 0 | O21: c | Q21: 0 | R21: c
A22: Czech Republic | B22: 86.440225 | C22: 0.5819767 | E22: 43.89565 | F22: 2.834436 | H22: 43.066113 | I22: 2.8904675 | K22: 13.038237 | L22: 1.9313118 | N22: 0 | O22: c | Q22: 0 | R22: c
A23: Denmark | B23: 91.136268 | C23: 0.41554989 | E23: 64.547836 | F23: 2.9308074 | H23: 32.431913 | I23: 2.81221 | K23: 3.0202501 | L23: 1.0428909 | N23: 0 | O23: c | Q23: 0 | R23: c
A24: Estonia | B24: 89.134847 | C24: 0.53414207 | E24: 50.580089 | F24: 2.2336476 | H24: 44.430694 | I24: 2.1399435 | K24: 4.7461658 | L24: 0.97983481 | N24: 0.18725783 | O24: 0.18739217 | Q24: 0.055794283 | R24: 0.055714091
A25: Finland | B25: 90.82094 | C25: 0.38994079 | E25: 57.48236 | F25: 3.120246 | H25: 40.820137 | I25: 3.1427829 | K25: 1.6295363 | L25: 0.46308198 | N25: 0 | O25: c | Q25: 0.067967289 | R25: 0.067211315
A26: France | B26: 93.532811 | C26: 0.34364362 | E26: 76.233998 | F26: 2.8079947 | H26: 22.428421 | I26: 2.8234679 | K26: 1.337581 | L26: 0.58646741 | N26: 0 | O26: c | Q26: 0 | R26: c
A27: Germany | B27: 91.78956 | C27: 0.52507164 | E27: 67.316879 | F27: 3.5803586 | H27: 29.755683 | I27: 3.4677763 | K27: 2.9274377 | L27: 1.3667869 | N27: 0 | O27: c | Q27: 0 | R27: c
A28: Greece | B28: 89.364723 | C28: 0.4691103 | E28: 56.649491 | F28: 3.0695286 | H28: 37.987695 | I28: 2.9478313 | K28: 5.2881897 | L28: 1.3705088 | N28: 0 | O28: c | Q28: 0.074623971 | R28: 0.055530429
A29: Hungary | B29: 92.038943 | C29: 0.46487575 | E29: 70.844739 | F29: 2.9447006 | H29: 25.536171 | I29: 2.8165818 | K29: 3.5649684 | L29: 0.87724546 | N29: 0 | O29: c | Q29: 0.05412106 | R29: 0.054303521
A30: Iceland | B30: 90.940236 | C30: 0.51934868 | E30: 64.661233 | F30: 0.22490465 | H30: 32.896089 | I30: 0.20637131 | K30: 2.353223 | L30: 0.094732607 | N30: 0 | O30: c | Q30: 0.089455122 | R30: 0.05150868
A31: Ireland | B31: 95.763261 | C31: 0.32245798 | E31: 92.750551 | F31: 2.1694812 | H31: 6.2414647 | I31: 2.0031162 | K31: 1.0079839 | L31: 0.80804322 | N31: 0 | O31: c | Q31: 0 | R31: c
A32: Israel | B32: m | C32: m | E32: m | F32: m | H32: m | I32: m | K32: m | L32: m | N32: m | O32: m | Q32: m | R32: m
A33: Italy | B33: 91.237804 | C33: 0.41154414 | E33: 62.884601 | F33: 2.9131534 | H33: 33.453579 | I33: 2.8949324 | K33: 3.6594468 | L33: 0.91458238 | N33: 0 | O33: c | Q33: 0.0023724043 | R33: 0.0023729845
A34: Japan | B34: 91.167329 | C34: 0.41127383 | E34: 64.845853 | F34: 3.2819797 | H34: 32.09837 | I34: 3.1393649 | K34: 3.055777 | L34: 1.2176864 | N34: 0 | O34: c | Q34: 0 | R34: c
A35: Korea | B35: 86.740345 | C35: 0.48511272 | E35: 31.577822 | F35: 3.5680498 | H35: 61.82933 | I35: 3.6349531 | K35: 6.592848 | L35: 1.9513447 | N35: 0 | O35: c | Q35: 0 | R35: c
A36: Latvia | B36: 87.132254 | C36: 0.54547485 | E36: 39.689149 | F36: 1.9818306 | H36: 49.204988 | I36: 1.9524492 | K36: 11.105863 | L36: 1.2271038 | N36: 0 | O36: c | Q36: 0 | R36: c
A37: Lithuania | B37: 90.300661 | C37: 0.45078578 | E37: 61.555058 | F37: 1.7792175 | H37: 32.9893 | I37: 1.7633083 | K37: 5.3302602 | L37: 0.8399074 | N37: 0 | O37: c | Q37: 0.12538196 | R37: 0.10705859
A38: Luxembourg | B38: 91.271227 | C38: 0.39101044 | E38: 65.635529 | F38: 0.098863478 | H38: 34.364471 | I38: 0.098863478 | K38: 0 | L38: c | N38: 0 | O38: c | Q38: 0 | R38: c
A39: Mexico | B39: 95.619759 | C39: 0.32207924 | E39: 90.230431 | F39: 1.9783487 | H39: 8.8930014 | I39: 1.8716334 | K39: 0.65238097 | L39: 0.41967276 | N39: 0 | O39: c | Q39: 0.22418653 | R39: 0.22215179
A40: Netherlands* | B40: 96.844312 | C40: 0.30715351 | E40: 90.078256 | F40: 2.1691914 | H40: 9.8798066 | I40: 2.1690799 | K40: 0.041937733 | L40: 0.041751329 | N40: 0 | O40: c | Q40: 0 | R40: c
A41: New Zealand | B41: m | C41: m | E41: m | F41: m | H41: m | I41: m | K41: m | L41: m | N41: m | O41: m | Q41: m | R41: m
A42: Norway | B42: m | C42: m | E42: m | F42: m | H42: m | I42: m | K42: m | L42: m | N42: m | O42: m | Q42: m | R42: m
A43: Poland | B43: 86.918636 | C43: 0.59056067 | E43: 42.729419 | F43: 3.6072339 | H43: 50.508725 | I43: 3.4408162 | K43: 6.5497881 | L43: 1.5835966 | N43: 0 | O43: c | Q43: 0.2120679 | R43: 0.15194722
A44: Portugal* | B44: 95.818281 | C44: 0.30127681 | E44: 87.034308 | F44: 2.0541446 | H44: 12.725512 | I44: 2.0709252 | K44: 0.24018022 | L44: 0.18072375 | N44: 0 | O44: c | Q44: 0 | R44: c
...

Sheet Table III.B1.12.4
A1: PISA 2018 Results (Volume III) - © OECD 2019
A2: Annex B1 | B2: Annex B1.12 Results (tables): Students' feelings
A3: Version 2 - Last updated: 02-Dec-2019
A4: Disclaimer: http://oe.cd/disclaimer
A6: Table III.B1.12.4
A7: Prevalence of sadness in schools
A8: Based on students' reports
B11: Percentage of students who feel sad sometimes or always | E11: Percentage of students who are in schools where…
E12: Over 90% of students feel sad sometimes or always | H12: Between 75% and 90% of students feel sad sometimes or always | K12: Between 25% and 75% of students feel sad sometimes or always | N12: Between 10% and 25% of students feel sad sometimes or always | Q12: 10% of students or less feel sad sometimes or always
B14: % | C14: S.E. | E14: % | F14: S.E. | H14: % | I14: S.E. | K14: % | L14: S.E. | N14: % | O14: S.E. | Q14: % | R14: S.E.
A15: OECD
A16: Australia | B16: m | C16: m | E16: m | F16: m | H16: m | I16: m | K16: m | L16: m | N16: m | O16: m | Q16: m | R16: m
A17: Austria | B17: 43.85651 | C17: 0.89608556 | E17: 1.0254652 | F17: 0.43557133 | H17: 0.84291001 | I17: 0.42070138 | K17: 89.234065 | L17: 1.6890142 | N17: 7.1797347 | O17: 1.5782683 | Q17: 1.7178249 | R17: 0.57867253
A18: Belgium | B18: m | C18: m | E18: m | F18: m | H18: m | I18: m | K18: m | L18: m | N18: m | O18: m | Q18: m | R18: m
A19: Canada | B19: 56.420842 | C19: 0.50147203 | E19: 0.58579836 | F19: 0.45934981 | H19: 5.9408278 | I19: 1.1968085 | K19: 92.892059 | L19: 1.4293543 | N19: 0.47692217 | O19: 0.40982943 | Q19: 0.10439242 | R19: 0.039640505
A20: Chile | B20: 54.245854 | C20: 0.72905026 | E20: 0.7951946 | F20: 0.33522928 | H20: 3.2066585 | I20: 1.1985064 | K20: 94.160716 | L20: 1.4045742 | N20: 0.37624361 | O20: 0.214555 | Q20: 1.461187 | R20: 0.82212293
A21: Colombia | B21: 49.948072 | C21: 0.71789826 | E21: 0.3433124 | F21: 0.20160137 | H21: 4.3681311 | I21: 1.4730108 | K21: 93.061656 | L21: 1.4753472 | N21: 2.1541342 | O21: 0.48765088 | Q21: 0.072766714 | R21: 0.072091906
A22: Czech Republic | B22: 51.828533 | C22: 0.81893696 | E22: 1.1695513 | F22: 0.62089272 | H22: 4.3278245 | I22: 1.1299608 | K22: 91.223322 | L22: 1.5633329 | N22: 2.317295 | O22: 0.63291662 | Q22: 0.96200726 | R22: 0.47731897
A23: Denmark | B23: 47.608516 | C23: 0.71207924 | E23: 0.19180008 | F23: 0.13868006 | H23: 3.4700019 | I23: 1.1663115 | K23: 92.596337 | L23: 1.6320573 | N23: 3.4773897 | O23: 1.1418044 | Q23: 0.26447119 | R23: 0.18643765
A24: Estonia | B24: 51.324237 | C24: 0.76427708 | E24: 0.64534576 | F24: 0.31303247 | H24: 1.9275159 | I24: 0.77130019 | K24: 94.345091 | L24: 1.1487844 | N24: 2.462587 | O24: 0.88020194 | Q24: 0.61945992 | R24: 0.25235254
A25: Finland | B25: 45.758349 | C25: 0.62556667 | E25: 0.20077465 | F25: 0.11589741 | H25: 0 | I25: c | K25: 98.190897 | L25: 0.89348011 | N25: 1.5384055 | O25: 0.88254764 | Q25: 0.069922596 | R25: 0.072802514
A26: France | B26: 45.820127 | C26: 0.68194854 | E26: 0.0043797383 | F26: 0.0044274281 | H26: 0.36456934 | I26: 0.28611611 | K26: 96.665168 | L26: 1.0895862 | N26: 2.9220079 | O26: 1.0563377 | Q26: 0.043874654 | R26: 0.04383866
A27: Germany | B27: 43.15349 | C27: 0.90652982 | D27: † | E27: 0.20307271 | F27: 0.24880574 | H27: 1.3141113 | I27: 0.73360943 | K27: 89.300721 | L27: 2.0249171 | N27: 8.3790462 | O27: 1.9334833 | Q27: 0.80304915 | R27: 0.51074106
A28: Greece | B28: 51.044634 | C28: 0.70805134 | E28: 0.62421527 | F28: 0.21956492 | H28: 1.3007414 | I28: 0.59161027 | K28: 97.145745 | L28: 0.72230184 | N28: 0.51326728 | O28: 0.31829293 | Q28: 0.41603155 | R28: 0.17914826
A29: Hungary | B29: 44.862086 | C29: 0.97336054 | E29: 0.92483693 | F29: 0.34667404 | H29: 1.532952 | I29: 0.85704968 | K29: 88.880136 | L29: 1.8581824 | N29: 6.7310218 | O29: 1.8041748 | Q29: 1.9310535 | R29: 0.40222524
A30: Iceland | B30: 44.305043 | C30: 1.0009317 | E30: 0.54926218 | F30: 0.086034002 | H30: 0 | I30: c | K30: 95.634797 | L30: 0.14221709 | N30: 3.1827472 | O30: 0.098475541 | Q30: 0.63319367 | R30: 0.091196392
A31: Ireland | B31: 58.028967 | C31: 0.80424405 | E31: 0 | F31: c | H31: 9.220385 | I31: 2.0884484 | K31: 90.779615 | L31: 2.0884484 | N31: 0 | O31: c | Q31: 0 | R31: c
A32: Israel | B32: m | C32: m | E32: m | F32: m | H32: m | I32: m | K32: m | L32: m | N32: m | O32: m | Q32: m | R32: m
A33: Italy | B33: 55.255716 | C33: 0.74712086 | E33: 0.21633248 | F33: 0.11774774 | H33: 5.5924038 | I33: 1.433275 | K33: 92.455802 | L33: 1.7166577 | N33: 1.5752891 | O33: 0.83398641 | Q33: 0.16017241 | R33: 0.074650017
A34: Japan | B34: 65.599169 | C34: 0.72839422 | E34: 1.1428843 | F34: 0.65809275 | H34: 16.451514 | I34: 2.61022 | K34: 82.405601 | L34: 2.6973446 | N34: 0 | O34: c | Q34: 0 | R34: c
A35: Korea | B35: 52.351866 | C35: 0.69670922 | E35: 0.10328629 | F35: 0.070140004 | H35: 2.6786403 | I35: 1.1579252 | K35: 96.545492 | L35: 1.3116001 | N35: 0.60779015 | O35: 0.6073229 | Q35: 0.06479165 | R35: 0.06541077
A36: Latvia | B36: 50.362685 | C36: 0.80258905 | E36: 0.51452526 | F36: 0.27750782 | H36: 2.9552371 | I36: 0.92848435 | K36: 92.011755 | L36: 1.3682633 | N36: 3.5171088 | O36: 1.0071618 | Q36: 1.0013736 | R36: 0.3814836
A37: Lithuania | B37: 44.613758 | C37: 0.73042153 | E37: 0.74876204 | F37: 0.34301387 | H37: 1.6119191 | I37: 0.33958463 | K37: 91.578393 | L37: 1.0784869 | N37: 4.9039557 | O37: 0.95083899 | Q37: 1.1569701 | R37: 0.35367111
A38: Luxembourg | B38: 48.998839 | C38: 0.67008642 | E38: 0 | F38: c | H38: 0 | I38: c | K38: 100 | L38: c | N38: 0 | O38: c | Q38: 0 | R38: c
A39: Mexico | B39: 49.958658 | C39: 0.7578555 | D39: † | E39: 0.8981553 | F39: 0.48232056 | H39: 2.1620215 | I39: 0.93069421 | K39: 91.999163 | L39: 1.2520314 | N39: 2.162151 | O39: 1.0034745 | Q39: 2.7785091 | R39: 0.88140903
A40: Netherlands* | B40: 45.092966 | C40: 0.84038124 | E40: 0 | F40: c | H40: 0.041937733 | I40: 0.041751329 | K40: 94.916347 | L40: 0.94072815 | N40: 5.0417154 | O40: 0.93898861 | Q40: 0 | R40: c
A41: New Zealand | B41: m | C41: m | E41: m | F41: m | H41: m | I41: m | K41: m | L41: m | N41: m | O41: m | Q41: m | R41: m
A42: Norway | B42: m | C42: m | E42: m | F42: m | H42: m | I42: m | K42: m | L42: m | N42: m | O42: m | Q42: m | R42: m
A43: Poland | B43: 50.376278 | C43: 0.75557164 | E43: 1.0110557 | F43: 0.38850137 | H43: 1.0258826 | I43: 0.56528427 | K43: 95.578153 | L43: 1.0906531 | N43: 1.8653143 | O43: 0.842353 | Q43: 0.51959477 | R43: 0.17603635
A44: Portugal* | B44: 48.357846 | C44: 0.80182436 | E44: 0.026176415 | F44: 0.024805822 | H44: 1.6118153 | I44: 0.77582641 | K44: 94.037142 | L44: 1.6814149 | N44: 4.1011809 | O44: 1.3266044 | Q44: 0.22368579 | R44: 0.16612469
...

Sheet Table III.B1.12.5
A1: PISA 2018 Results (Volume III) - © OECD 2019
A2: Annex B1 | B2: Annex B1.12 Results (tables): Students' feelings
A3: Version 2 - Last updated: 02-Dec-2019
A4: Disclaimer: http://oe.cd/disclaimer
A6: Table III.B1.12.5
A7: Index of positive feelings, by student characteristics
A8: Based on students' reports
B11: Index of positive feelings,1 by the following student characteristics:
B12: Gender | K12: Socio-economic status2 | T12: Education level | AC12: Immigrant background
B13: Boys | E13: Girls | H13: Girls - boys | K13: Disadvantaged students | N13: Advantaged students | Q13: Advantaged -disadvantaged | T13: Lower secondary (ISCED 2) | W13: Upper secondary (ISCED 3) | Z13: ISCED 3 - ISCED 2 | AC13: Non-immigrant students | AF13: Immigrant students | AI13: Immigrant - non-immigrant
