Workbook

Sheet TOC
A1: PISA 2018 Results (Volume I) - © OECD 2019
A2: Annex A2 | B2: Annex A2 The PISA target population, the PISA samples, and the definition of schools
A3: Version 4 - Last updated: 13-Oct-2020
A4: Disclaimer: http://oe.cd/disclaimer
A6: TOC | B6: PISA 2018 Results - Volume I
A8: Annex A2 | B8: The PISA target population, the PISA samples, and the definition of schools
A9: Tables
A12: Table I.A2.1 | B12: ='Table I.A2.1'!$A$7 -> PISA target populations and samples, 2018
A13: Table I.A2.2 | B13: ='Table I.A2.2'!$A$7 -> Change in the enrolment of 15-year-olds in grade 7 and above (PISA 2003 through PISA 2018)
A14: Table I.A2.3 | B14: ='Table I.A2.3'!$A$7 -> PISA target populations and samples in adjudicated regions
A15: Table I.A2.4 | B15: ='Table I.A2.4'!$A$7 -> Exclusions, PISA 2018
A16: Table I.A2.5 | B16: ='Table I.A2.5'!$A$7 -> Exclusions in adjudicated regions
A17: Table I.A2.6 | B17: ='Table I.A2.6'!$A$7 -> Response rates, PISA 2018
A18: Table I.A2.7 | B18: ='Table I.A2.7'!$A$7 -> Response rates in adjudicated regions
A19: Table I.A2.8 | B19: ='Table I.A2.8'!$A$7 -> Percentage of students, including those with missing information, at each grade level, PISA 2018
A20: Table I.A2.9 | B20: ='Table I.A2.9'!$A$7 -> Percentage of students at each grade level, PISA 2018
A21: Table I.A2.10 | B21: ='Table I.A2.10'!$A$7 -> Percentage of students, including those with missing information, at each grade level in adjudicated regions
A22: Table I.A2.11 | B22: ='Table I.A2.11'!$A$7 -> Percentage of students at each grade level in adjudicated regions
A23: Table I.A2.12 | B23: ='Table I.A2.12'!$A$7 -> Percentage of students, including those with missing information, at each grade level, by gender
A24: Table I.A2.13 | B24: ='Table I.A2.13'!$A$7 -> Percentage of students at each grade level, by gender
A25: Table I.A2.14 | B25: ='Table I.A2.14'!$A$7 -> Percentage of students, including those with missing information, at each grade level in adjudicated regions, by gender
A26: Table I.A2.15 | B26: ='Table I.A2.15'!$A$7 -> Percentage of students at each grade level in adjudicated regions, by gender
A29: Symbols for missing data
A30: c: There are too few observations or no observation to provide reliable estimates (i.e. there are fewer than 30 students or fewer than 5 schools with valid data).
A31: m: Data are not available. These data were not submitted by the country or were collected but subsequently removed from the publication for technical reasons.

Sheet Table I.A2.1
A1: PISA 2018 Results (Volume I) - © OECD 2019
A2: Annex A2 | B2: Annex A2 The PISA target population, the PISA samples, and the definition of schools
A3: Version 4 - Last updated: 13-Oct-2020
A4: Disclaimer: http://oe.cd/disclaimer
A6: Table I.A2.1
A7: PISA target populations and samples, 2018
B12: Population and sample information | N12: Coverage indices
B13: Total population of 15-year-olds | C13: Total enrolled population of 15-year-olds at grade 7 or above | D13: Total in national desired target population | E13: Total school-level exclusions | F13: Total in national desired target population after all school exclusions and before within-school exclusions | G13: School-level exclusion rate (%) | H13: Number of participating students | I13: Weighted number of participating students | J13: Number of excluded students | K13: Weighted number of excluded students | L13: Within-school exclusion rate (%) | M13: Overall exclusion rate (%) | N13: Coverage Index 1: Coverage of national desired population | O13: Coverage Index 2: Coverage of national enrolled population | P13: Coverage Index 3: Coverage of 15-year-old population
B14: (1) | C14: (2) | D14: (3) | E14: (4) | F14: (5) | G14: (6) | H14: (7) | I14: (8) | J14: (9) | K14: (10) | L14: (11) | M14: (12) | N14: (13) | O14: (14) | P14: (15)
A15: OECD
A16: Australia | B16: 288195 | C16: 284687 | D16: 284687 | E16: 5609.6881 | F16: 279077.31 | G16: 1.9704757 | H16: 14273 | I16: 257778.72 | J16: 716 | K16: 10248.66 | L16: 3.8237358 | M16: 5.7188657 | N16: 0.94281123 | O16: 0.94281123 | P16: 0.89445938
A17: Austria | B17: 84473 | C17: 80108 | D17: 80108 | E17: 603.27929 | F17: 79504.721 | G17: 0.75308245 | H17: 6802 | I17: 75077.25 | J17: 117 | K17: 1378.83 | L17: 1.8034275 | M17: 2.5429287 | N17: 0.97457071 | O17: 0.97457071 | P17: 0.88877215
A18: Belgium | B18: 126031 | C18: 122808 | D18: 122808 | E18: 1877.4538 | F18: 120930.55 | G18: 1.5287716 | H18: 8475 | I18: 118024.8 | J18: 45 | K18: 493.62 | L18: 0.41649222 | M18: 1.9388966 | N18: 0.98061103 | O18: 0.98061103 | P18: 0.93647436
A19: Canada | B19: 388205 | C19: 400139 | D19: 395448 | E19: 7950.446 | F19: 387497.55 | G19: 2.0104909 | H19: 22653 | I19: 335196.99 | J19: 1481 | K19: 17496.3 | L19: 4.9607692 | M19: 6.8715242 | N19: 0.93128476 | O19: 0.92036691 | P19: 0.86345356
A20: Chile | B20: 239492 | C20: 215580 | D20: 215470 | E20: 2151 | F20: 213319 | G20: 0.99828282 | H20: 7621 | I20: 213832.11 | J20: 68 | K20: 2028.78 | L20: 0.93985529 | M20: 1.9287557 | N20: 0.98071244 | O20: 0.98021203 | P20: 0.89285701
A21: Colombia | B21: 856081 | C21: 645339 | D21: 645339 | E21: 950 | F21: 644389 | G21: 0.14720945 | H21: 7522 | I21: 529976.04 | J21: 28 | K21: 1812.21 | L21: 0.34077662 | M21: 0.48748441 | N21: 0.99512516 | O21: 0.99512516 | P21: 0.61907231
A22: Czech Republic | B22: 92013 | C22: 90835 | D22: 90835 | E22: 1509.7044 | F22: 89325.296 | G22: 1.6620293 | H22: 7019 | I22: 87807.57 | J22: 1 | K22: 10.95 | L22: 0.012468896 | M22: 1.674291 | N22: 0.98325709 | O22: 0.98325709 | P22: 0.95429526
A23: Denmark | B23: 68313 | C23: 67414 | D23: 67414 | E23: 652.71477 | F23: 66761.285 | G23: 0.96821843 | H23: 7657 | I23: 59966.97 | J23: 444 | K23: 3009.21 | L23: 4.7783327 | M23: 5.7002865 | N23: 0.94299761 | O23: 0.94299761 | P23: 0.87782662
A24: Estonia | B24: 12257 | C24: 12120 | D24: 12120 | E24: 413.16666 | F24: 11706.833 | G24: 3.4089659 | H24: 5316 | I24: 11414.49 | J24: 96 | K24: 194.73 | L24: 1.6773693 | M24: 5.0291542 | N24: 0.94970596 | O24: 0.94970596 | P24: 0.93126295
A25: Finland | B25: 58325 | C25: 57552 | D25: 57552 | E25: 495.97954 | F25: 57056.02 | G25: 0.86179376 | H25: 5649 | I25: 56172.39 | J25: 157 | K25: 1490.64 | L25: 2.5850879 | M25: 3.4246035 | N25: 0.96575396 | O25: 0.96575396 | P25: 0.96309284
A26: France | B26: 828196 | C26: 798480 | D26: 798480 | E26: 13732 | F26: 784748 | G26: 1.7197676 | H26: 6308 | I26: 756477.36 | J26: 56 | K26: 6644.22 | L26: 0.8706634 | M26: 2.5754576 | N26: 0.97424546 | O26: 0.97424546 | P26: 0.91340378
A27: Germany | B27: 739792 | C27: 739792 | D27: 739792 | E27: 15447.626 | F27: 724344.37 | G27: 2.088104 | H27: 5451 | I27: 734915.28 | J27: 42 | K27: 4846.83 | L27: 0.65518765 | M27: 2.7296106 | N27: 0.97270389 | O27: 0.97270389 | P27: 0.99340798
... A52: United States | B52: 4133719 | C52: 4058637 | D52: 4058637 | E52: 24756.591 | F52: 4033880.4 | G52: 0.60997303 | H52: 4838 | I52: 3559044.6 | J52: 194 | K52: 119057.1 | L52: 3.2369171 | M52: 3.8271458 | N52: 0.96172855 | O52: 0.96172855 | P52: 0.86097884
A53: Partners
A54: Albania | B54: 36955 | C54: 30160 | D54: 30160 | E54: 0 | F54: 30160 | G54: 0 | H54: 6359 | I54: 27962.73 | J54: 0 | K54: 0 | L54: 0 | M54: 0 | N54: 1 | O54: 1 | P54: 0.75666973
A55: Argentina | B55: 702788 | C55: 678151 | D55: 678151 | E55: 5597 | F55: 672554 | G55: 0.82533241 | H55: 11975 | I55: 566485.56 | J55: 118 | K55: 4083.3 | L55: 0.7156542 | M55: 1.5350801 | N55: 0.9846492 | O55: 0.9846492 | P55: 0.80605469
A56: Baku (Azerbaijan) | B56: 43798 | C56: 22672 | D56: 22672 | E56: 454 | F56: 22218 | G56: 2.00247 | H56: 6827 | I56: 20271.21 | J56: 0 | K56: 0 | L56: 0 | M56: 2.00247 | N56: 0.9799753 | O56: 0.9799753 | P56: 0.46283415
A57: Belarus | B57: 89440 | C57: 82580 | D57: 82580 | E57: 1439.5232 | F57: 81140.477 | G57: 1.7431862 | H57: 5803 | I57: 78333.03 | J57: 31 | K57: 462.48 | L57: 0.586937 | M57: 2.3198918 | N57: 0.97680108 | O57: 0.97680108 | P57: 0.87581653
A58: Bosnia and Herzegovina | B58: 35056 | C58: 32313 | D58: 32313 | E58: 242.55904 | F58: 32070.441 | G58: 0.75065466 | H58: 6480 | I58: 28842.75 | J58: 24 | K58: 105.66 | L58: 0.36499414 | M58: 1.112909 | N58: 0.98887091 | O58: 0.98887091 | P58: 0.82276215
A59: Brazil | B59: 3132463 | C59: 2980084 | D59: 2980084 | E59: 74772 | F59: 2905312 | G59: 2.5090568 | H59: 10691 | I59: 2036860.6 | J59: 41 | K59: 8179.71 | L59: 0.39997793 | M59: 2.898999 | N59: 0.97101001 | O59: 0.97101001 | P59: 0.65024252
A60: Brunei Darussalam | B60: 7081 | C60: 7384 | D60: 7384 | E60: 0 | F60: 7384 | G60: 0 | H60: 6828 | I60: 6899.01 | J60: 53 | K60: 53.01 | L60: 0.76251548 | M60: 0.76251548 | N60: 0.99237916 | O60: 0.99237916 | P60: 0.97429883
A61: B-S-J-Z (China) | B61: 1221746 | C61: 1097296 | D61: 1097296 | E61: 33279 | F61: 1064017 | G61: 3.0328189 | H61: 12058 | I61: 992301.63 | J61: 34 | K61: 1452.24 | L61: 0.14613678 | M61: 3.1745236 | N61: 0.96825473 | O61: 0.96825473 | P61: 0.81219961
A62: Bulgaria | B62: 66499 | C62: 51674 | D62: 51674 | E62: 388 | F62: 51286 | G62: 0.75086117 | H62: 5294 | I62: 47851.47 | J62: 80 | K62: 684.87 | L62: 1.4110458 | M62: 2.151312 | N62: 0.97848688 | O62: 0.97848688 | P62: 0.7195818
A63: Costa Rica | B63: 72444 | C63: 58789 | D63: 58789 | E63: 0 | F63: 58789 | G63: 0 | H63: 7221 | I63: 45474.66 | J63: 39 | K63: 248.61 | L63: 0.54372752 | M63: 0.54372752 | N63: 0.99456272 | O63: 0.99456272 | P63: 0.62772155
A64: Croatia | B64: 39812 | C64: 30534 | D64: 30534 | E64: 408.65623 | F64: 30125.344 | G64: 1.3383645 | H64: 6609 | I64: 35461.65 | J64: 135 | K64: 636.57 | L64: 1.7634388 | M64: 3.0782021 | N64: 0.96921798 | O64: 0.96921798 | P64: 0.89072767
A65: Cyprus | B65: 8285 | C65: 8285 | D65: 8277 | E65: 138.28125 | F65: 8138.7187 | G65: 1.6706688 | H65: 5503 | I65: 7638.87 | J65: 201 | K65: 351.24 | L65: 4.3959345 | M65: 5.9931617 | N65: 0.94006838 | O65: 0.93916065 | P65: 0.92201207
... A95: Viet Nam | B95: 1332000 | C95: 1251842 | D95: 1251842 | E95: 6169.124 | F95: 1245672.9 | G95: 0.49280373 | H95: 5377 | I95: 926259.69 | J95: 0 | K95: 0 | L95: 0 | M95: 0.49280373 | N95: 0.99507196 | O95: 0.99507196 | P95: 0.69539016
A103: Information on data for Cyprus: https://oe.cd/cyprus-disclaimer
A104: Notes: For a full explanation of the details in this table please refer to the PISA 2018 Technical Report (OECD, forthcoming).
A105: The figure for total national population of 15-year-olds enrolled in Column 2 may occasionally be larger than the total number of 15-year-olds in Column 1 due to differing data sources.

Sheet Table I.A2.2
A1: PISA 2018 Results (Volume I) - © OECD 2019
A2: Annex A2 | B2: Annex A2 The PISA target population, the PISA samples, and the definition of schools
A3: Version 4 - Last updated: 13-Oct-2020
A4: Disclaimer: http://oe.cd/disclaimer
A6: Table I.A2.2
A7: Change in the enrolment of 15-year-olds in grade 7 and above (PISA 2003 through PISA 2018)
B11: PISA 2018 | F11: PISA 2015 | J11: PISA 2012 | N11: PISA 2009 | R11: PISA 2006 | V11: PISA 2003
B12: Total population of 15-year-olds | C12: Total population of 15-year-olds enrolled in grade 7 or above | D12: Weighted number of participating students | E12: Coverage index 3. Coverage of the national 15-year-old population | F12: Total population of 15-year-olds | G12: Total population of 15-year-olds enrolled in grade 7 or above | H12: Weighted number of participating students | I12: Coverage index 3. Coverage of the national 15-year-old population | J12: Total population of 15-year-olds | K12: Total population of 15-year-olds enrolled in grade 7 or above | L12: Weighted number of participating students | M12: Coverage index 3. Coverage of the national 15-year-old population | N12: Total population of 15-year-olds | O12: Total population of 15-year-olds enrolled in grade 7 or above | P12: Weighted number of participating students | Q12: Coverage index 3. Coverage of the national 15-year-old population | R12: Total population of 15-year-olds | S12: Total population of 15-year-olds enrolled in grade 7 or above | T12: Weighted number of participating students | U12: Coverage index 3. Coverage of the national 15-year-old population | V12: Total population of 15-year-olds | W12: Total population of 15-year-olds enrolled in grade 7 or above | X12: Weighted number of participating students | Y12: Coverage index 3. Coverage of the national 15-year-old population
A15: OECD
A16: Australia | B16: 288195 | C16: 284687 | D16: 257778.72 | E16: =IFERROR(D16/B16,"m") -> 0.89445938 | F16: 282888 | G16: 282547 | H16: 256329.12 | I16: =IFERROR(H16/F16,"m") -> 0.90611521 | J16: 291967 | K16: 288159 | L16: 250778.7 | M16: 0.85892824 | N16: 286334 | O16: 269669 | P16: 240851.46 | Q16: =IFERROR(P16/N16,"m") -> 0.84115564 | R16: 270115 | S16: 256754 | T16: 234939.52 | U16: =IFERROR(T16/R16,"m") -> 0.86977591 | V16: 268164 | W16: 250635 | X16: 235591.18 | Y16: =IFERROR(X16/V16,"m") -> 0.87853396
A17: Austria | B17: 84473 | C17: 80108 | D17: 75077.25 | E17: =IFERROR(D17/B17,"m") -> 0.88877215 | F17: 88013 | G17: 82683 | H17: 73378.77 | I17: =IFERROR(H17/F17,"m") -> 0.83372649 | J17: 93537 | K17: 89073 | L17: 82242.06 | M17: 0.87924629 | N17: 99818 | O17: 94192 | P17: 87326.21 | Q17: =IFERROR(P17/N17,"m") -> 0.87485433 | R17: 97337 | S17: 92149 | T17: 89925.11 | U17: =IFERROR(T17/R17,"m") -> 0.92385331 | V17: 94515 | W17: 89049 | X17: 85931.03 | Y17: =IFERROR(X17/V17,"m") -> 0.90917875
A18: Belgium | B18: 126031 | C18: 122808 | D18: 118024.8 | E18: =IFERROR(D18/B18,"m") -> 0.93647436 | F18: 123630 | G18: 121954 | H18: 114901.86 | I18: =IFERROR(H18/F18,"m") -> 0.92940112 | J18: 123469 | K18: 121493 | L18: 117912.45 | M18: 0.9549964 | N18: 126377 | O18: 126335 | P18: 119140.46 | Q18: =IFERROR(P18/N18,"m") -> 0.94273847 | R18: 124943 | S18: 124557 | T18: 123161.45 | U18: =IFERROR(T18/R18,"m") -> 0.9857411 | V18: 120802 | W18: 118185 | X18: 111830.64 | Y18: =IFERROR(X18/V18,"m") -> 0.92573502
A19: Canada | B19: 388205 | C19: 400139 | D19: 335196.99 | E19: =IFERROR(D19/B19,"m") -> 0.86345356 | F19: 396966 | G19: 381660 | H19: 331545.69 | I19: =IFERROR(H19/F19,"m") -> 0.83519921 | J19: 417873 | K19: 409453 | L19: 348069.93 | M19: 0.83295626 | N19: 430791 | O19: 426590 | P19: 360286.41 | Q19: =IFERROR(P19/N19,"m") -> 0.8363369 | R19: 426967 | S19: 428876 | T19: 370879.36 | U19: =IFERROR(T19/R19,"m") -> 0.86863706 | V19: 398865 | W19: 399265 | X19: 330436.39 | Y19: =IFERROR(X19/V19,"m") -> 0.82844168
A20: Chile | B20: 239492 | C20: 215580 | D20: 213832.11 | E20: =IFERROR(D20/B20,"m") -> 0.89285701 | F20: 255440 | G20: 245947 | H20: 203781.75 | I20: =IFERROR(H20/F20,"m") -> 0.79776758 | J20: 274803 | K20: 252733 | L20: 229198.53 | M20: 0.83404668 | N20: 290056 | O20: 265542 | P20: 247269.72 | Q20: =IFERROR(P20/N20,"m") -> 0.85248959 | R20: 297085 | S20: 255459 | T20: 233526.11 | U20: =IFERROR(T20/R20,"m") -> 0.78605823 | V20: m | W20: m | X20: m | Y20: =IFERROR(X20/V20,"m") -> m
A21: Colombia | B21: 856081 | C21: 645339 | D21: 529976.04 | E21: =IFERROR(D21/B21,"m") -> 0.61907231 | F21: 760919 | G21: 674079 | H21: 567847.83 | I21: =IFERROR(H21/F21,"m") -> 0.7462658 | J21: 889729 | K21: 620422 | L21: 560805.39 | M21: 0.63031034 | N21: 893057 | O21: 582640 | P21: 522388.27 | Q21: =IFERROR(P21/N21,"m") -> 0.58494393 | R21: 897477 | S21: 543630 | T21: 537262.21 | U21: =IFERROR(T21/R21,"m") -> 0.59863619 | V21: m | W21: m | X21: m | Y21: =IFERROR(X21/V21,"m") -> m
A22: Czech Republic | B22: 92013 | C22: 90835 | D22: 87807.57 | E22: =IFERROR(D22/B22,"m") -> 0.95429526 | F22: 90391 | G22: 90076 | H22: 84518.52 | I22: =IFERROR(H22/F22,"m") -> 0.93503247 | J22: 96946 | K22: 93214 | L22: 82100.55 | M22: 0.84686888 | N22: 122027 | O22: 116153 | P22: 113951.07 | Q22: =IFERROR(P22/N22,"m") -> 0.9338185 | R22: 127748 | S22: 124764 | T22: 128827.19 | U22: =IFERROR(T22/R22,"m") -> 1.0084478 | V22: 130679 | W22: 126348 | X22: 121183.06 | Y22: =IFERROR(X22/V22,"m") -> 0.92733385
A23: Denmark | B23: 68313 | C23: 67414 | D23: 59966.97 | E23: =IFERROR(D23/B23,"m") -> 0.87782662 | F23: 68174 | G23: 67466 | H23: 60654.54 | I23: =IFERROR(H23/F23,"m") -> 0.88970194 | J23: 72310 | K23: 70854 | L23: 65641.98 | M23: 0.90778565 | N23: 70522 | O23: 68897 | P23: 60854.5 | Q23: =IFERROR(P23/N23,"m") -> 0.86291512 | R23: 66989 | S23: 65984 | T23: 57012.63 | U23: =IFERROR(T23/R23,"m") -> 0.8510745 | V23: 59156 | W23: 58188 | X23: 51740.79 | Y23: =IFERROR(X23/V23,"m") -> 0.87464991
A24: Estonia | B24: 12257 | C24: 12120 | D24: 11414.49 | E24: =IFERROR(D24/B24,"m") -> 0.93126295 | F24: 11676 | G24: 11491 | H24: 10834.08 | I24: =IFERROR(H24/F24,"m") -> 0.92789311 | J24: 12649 | K24: 12438 | L24: 11633.88 | M24: 0.91974702 | N24: 14248 | O24: 14106 | P24: 12977.98 | Q24: =IFERROR(P24/N24,"m") -> 0.91086328 | R24: 19871 | S24: 19623 | T24: 18662.26 | U24: =IFERROR(T24/R24,"m") -> 0.93917065 | V24: m | W24: m | X24: m | Y24: =IFERROR(X24/V24,"m") -> m
A25: Finland | B25: 58325 | C25: 57552 | D25: 56172.39 | E25: =IFERROR(D25/B25,"m") -> 0.96309284 | F25: 58526 | G25: 58955 | H25: 56934.27 | I25: =IFERROR(H25/F25,"m") -> 0.97280303 | J25: 62523 | K25: 62195 | L25: 60047.25 | M25: 0.96040257 | N25: 66198 | O25: 66198 | P25: 61463 | Q25: =IFERROR(P25/N25,"m") -> 0.92847216 | R25: 66232 | S25: 66232 | T25: 61386.99 | U25: =IFERROR(T25/R25,"m") -> 0.9268479 | V25: 61107 | W25: 61107 | X25: 57883.49 | Y25: =IFERROR(X25/V25,"m") -> 0.94724811
A26: France | B26: 828196 | C26: 798480 | D26: 756477.36 | E26: =IFERROR(D26/B26,"m") -> 0.91340378 | F26: 807867 | G26: 778679 | H26: 734943.84 | I26: =IFERROR(H26/F26,"m") -> 0.90973371 | J26: 792983 | K26: 755447 | L26: 701398.89 | M26: 0.88450684 | N26: 749808 | O26: 732825 | P26: 677620.22 | Q26: =IFERROR(P26/N26,"m") -> 0.90372498 | R26: 809375 | S26: 809375 | T26: 739428.06 | U26: =IFERROR(T26/R26,"m") -> 0.91357907 | V26: 809053 | W26: 808276 | X26: 734579.09 | Y26: =IFERROR(X26/V26,"m") -> 0.90794928
A27: Germany | B27: 739792 | C27: 739792 | D27: 734915.28 | E27: =IFERROR(D27/B27,"m") -> 0.99340798 | F27: 774149 | G27: 774149 | H27: 743969.4 | I27: =IFERROR(H27/F27,"m") -> 0.96101577 | J27: 798136 | K27: 798136 | L27: 756906.81 | M27: 0.94834315 | N27: 852044 | O27: 852044 | P27: 766992.57 | Q27: =IFERROR(P27/N27,"m") -> 0.90017953 | R27: 951535 | S27: 1062920 | T27: 903512.45 | U27: =IFERROR(T27/R27,"m") -> 0.94953149 | V27: 951800 | W27: 916869 | X27: 884357.67 | Y27: =IFERROR(X27/V27,"m") -> 0.92914233
A28: Greece | B28: 102868 | C28: 100203 | D28: 95369.97 | E28: =IFERROR(D28/B28,"m") -> 0.92711018 | F28: 105530 | G28: 105253 | H28: 96156.75 | I28: =IFERROR(H28/F28,"m") -> 0.91117929 | J28: 110521 | K28: 105096 | L28: 96639.84 | M28: 0.87440251 | N28: 102229 | O28: 105664 | P28: 93088.22 | Q28: =IFERROR(P28/N28,"m") -> 0.91058525 | R28: 107505 | S28: 110663 | T28: 96411.69 | U28: =IFERROR(T28/R28,"m") -> 0.89681122 | V28: 111286 | W28: 108314 | X28: 105130.79 | Y28: =IFERROR(X28/V28,"m") -> 0.94469017
A29: Hungary | B29: 96838 | C29: 91297 | D29: 86753.76 | E29: =IFERROR(D29/B29,"m") -> 0.89586485 | F29: 94515 | G29: 90065 | H29: 84644.16 | I29: =IFERROR(H29/F29,"m") -> 0.89556324 | J29: 111761 | K29: 108816 | L29: 91178.64 | M29: 0.81583594 | N29: 121155 | O29: 118387 | P29: 105610.83 | Q29: =IFERROR(P29/N29,"m") -> 0.87170014 | R29: 124444 | S29: 120061 | T29: 106010.05 | U29: =IFERROR(T29/R29,"m") -> 0.85186952 | V29: 129138 | W29: 123762 | X29: 107043.9 | Y29: =IFERROR(X29/V29,"m") -> 0.82891093
A30: Iceland | B30: 4232 | C30: 4177 | D30: 3875.01 | E30: =IFERROR(D30/B30,"m") -> 0.91564509 | F30: 4250 | G30: 4195 | H30: 3966.24 | I30: =IFERROR(H30/F30,"m") -> 0.93323294 | J30: 4505 | K30: 4491 | L30: 4168.65 | M30: 0.92533851 | N30: 4738 | O30: 4738 | P30: 4409.87 | Q30: =IFERROR(P30/N30,"m") -> 0.93074504 | R30: 4820 | S30: 4777 | T30: 4624.4 | U30: =IFERROR(T30/R30,"m") -> 0.95941909 | V30: 4168 | W30: 4112 | X30: 3927.76 | Y30: =IFERROR(X30/V30,"m") -> 0.94236084
A31: Ireland | B31: 61999 | C31: 61188 | D31: 59638.95 | E31: =IFERROR(D31/B31,"m") -> 0.96193406 | F31: 61234 | G31: 59811 | H31: 59082.39 | I31: =IFERROR(H31/F31,"m") -> 0.96486249 | J31: 59296 | K31: 57979 | L31: 54010.32 | M31: 0.91085942 | N31: 56635 | O31: 55464 | P31: 52794.26 | Q31: =IFERROR(P31/N31,"m") -> 0.93218434 | R31: 58667 | S31: 57648 | T31: 55114.26 | U31: =IFERROR(T31/R31,"m") -> 0.93944228 | V31: 61535 | W31: 58997 | X31: 54849.87 | Y31: =IFERROR(X31/V31,"m") -> 0.89136053
A32: Israel | B32: 136848 | C32: 128419 | D32: 110644.59 | E32: =IFERROR(D32/B32,"m") -> 0.80852179 | F32: 124852 | G32: 118997 | H32: 117030.72 | I32: =IFERROR(H32/F32,"m") -> 0.93735559 | J32: 118953 | K32: 113278 | L32: 107745.27 | M32: 0.90578018 | N32: 122701 | O32: 112254 | P32: 103184.06 | Q32: =IFERROR(P32/N32,"m") -> 0.84093903 | R32: 122626 | S32: 109370 | T32: 93346.84 | U32: =IFERROR(T32/R32,"m") -> 0.76123204 | V32: m | W32: m | X32: m | Y32: =IFERROR(X32/V32,"m") -> m
A33: Italy | B33: 616185 | C33: 544279 | D33: 521222.55 | E33: =IFERROR(D33/B33,"m") -> 0.84588646 | F33: 616761 | G33: 567268 | H33: 495093.3 | I33: =IFERROR(H33/F33,"m") -> 0.8027312 | J33: 605490 | K33: 566973 | L33: 521287.62 | M33: 0.86093514 | N33: 586904 | O33: 573542 | P33: 506732.9 | Q33: =IFERROR(P33/N33,"m") -> 0.86339998 | R33: 578131 | S33: 639971 | T33: 520055.2 | U33: =IFERROR(T33/R33,"m") -> 0.8995456 | V33: 561304 | W33: 574611 | X33: 481520.75 | Y33: =IFERROR(X33/V33,"m") -> 0.85786089
A34: Japan | B34: 1186849 | C34: 1159226 | D34: 1078921.3 | E34: =IFERROR(D34/B34,"m") -> 0.90906368 | F34: 1201615 | G34: 1175907 | H34: 1138348.6 | I34: =IFERROR(H34/F34,"m") -> 0.94734885 | J34: 1241786 | K34: 1214756 | L34: 1128178.9 | M34: 0.90851311 | N34: 1211642 | O34: 1189263 | P34: 1113402.7 | Q34: =IFERROR(P34/N34,"m") -> 0.91892051 | R34: 1246207 | S34: 1222171 | T34: 1113700.9 | U34: =IFERROR(T34/R34,"m") -> 0.8936725 | V34: 1365471 | W34: 1328498 | X34: 1240053.6 | Y34: =IFERROR(X34/V34,"m") -> 0.90815085
A35: Korea | B35: 517040 | C35: 517040 | D35: 455544.03 | E35: =IFERROR(D35/B35,"m") -> 0.88106148 | F35: 620687 | G35: 619950 | H35: 569106.18 | I35: =IFERROR(H35/F35,"m") -> 0.91689721 | J35: 687104 | K35: 672101 | L35: 603631.68 | M35: 0.87851574 | N35: 717164 | O35: 700226 | P35: 630030.35 | Q35: =IFERROR(P35/N35,"m") -> 0.87850248 | R35: 660812 | S35: 627868 | T35: 576669.37 | U35: =IFERROR(T35/R35,"m") -> 0.87266782 | V35: 606722 | W35: 606370 | X35: 533504.2 | Y35: =IFERROR(X35/V35,"m") -> 0.87932233
A36: Latvia | B36: 17977 | C36: 17677 | D36: 15932.49 | E36: =IFERROR(D36/B36,"m") -> 0.88627079 | F36: 17255 | G36: 16955 | H36: 15319.74 | I36: =IFERROR(H36/F36,"m") -> 0.88784352 | J36: 18789 | K36: 18389 | L36: 16054.41 | M36: 0.85445793 | N36: 28749 | O36: 28149 | P36: 23362.38 | Q36: =IFERROR(P36/N36,"m") -> 0.81263279 | R36: 34277 | S36: 33659 | T36: 29231.86 | U36: =IFERROR(T36/R36,"m") -> 0.85281267 | V36: 37544 | W36: 37138 | X36: 33643.32 | Y36: =IFERROR(X36/V36,"m") -> 0.89610377
A37: Lithuania | B37: 27075 | C37: 25998 | D37: 24453.27 | E37: =IFERROR(D37/B37,"m") -> 0.90316787 | F37: 33163 | G37: 32097 | H37: 29914.59 | I37: =IFERROR(H37/F37,"m") -> 0.90204716 | J37: 38524 | K37: 35567 | L37: 33041.97 | M37: 0.85769832 | N37: 51822 | O37: 43967 | P37: 40530.17 | Q37: =IFERROR(P37/N37,"m") -> 0.78210355 | R37: 53931 | S37: 51808 | T37: 50329.08 | U37: =IFERROR(T37/R37,"m") -> 0.93321244 | V37: m | W37: m | X37: m | Y37: =IFERROR(X37/V37,"m") -> m
A38: Luxembourg | B38: 6291 | C38: 5952 | D38: 5478 | E38: =IFERROR(D38/B38,"m") -> 0.87076776 | F38: 6327 | G38: 6053 | H38: 5540.01 | I38: =IFERROR(H38/F38,"m") -> 0.87561404 | J38: 6187 | K38: 6082 | L38: 5523 | M38: 0.85016971 | N38: 5864 | O38: 5623 | P38: 5124 | Q38: =IFERROR(P38/N38,"m") -> 0.87380628 | R38: 4595 | S38: 4595 | T38: 4733 | U38: =IFERROR(T38/R38,"m") -> 1.0300326 | V38: 4204 | W38: 4204 | X38: 4080 | Y38: =IFERROR(X38/V38,"m") -> 0.97050428
A39: Mexico | B39: 2231751 | C39: 1697100 | D39: 1480904.4 | E39: =IFERROR(D39/B39,"m") -> 0.66356166 | F39: 2257399 | G39: 1401247 | H39: 1392995.4 | I39: =IFERROR(H39/F39,"m") -> 0.61707983 | J39: 2114745 | K39: 1472875 | L39: 1326024.8 | M39: 0.62703769 | N39: 2151771 | O39: 1425397 | P39: 1305460.8 | Q39: =IFERROR(P39/N39,"m") -> 0.60669131 | R39: 2200916 | S39: 1383364 | T39: 1190420 | U39: =IFERROR(T39/R39,"m") -> 0.54087482 | V39: 2192452 | W39: 1273163 | X39: 1071650.1 | Y39: =IFERROR(X39/V39,"m") -> 0.48879066
A40: Netherlands | B40: 208704 | C40: 204753 | D40: 190280.52 | E40: =IFERROR(D40/B40,"m") -> 0.91172436 | F40: 203234 | G40: 200976 | H40: 191816.61 | I40: =IFERROR(H40/F40,"m") -> 0.94382146 | J40: 194000 | K40: 193190 | L40: 196261.62 | M40: 1.0116578 | N40: 199000 | O40: 198334 | P40: 183546.23 | Q40: =IFERROR(P40/N40,"m") -> 0.92234286 | R40: 197046 | S40: 193769 | T40: 189575.82 | U40: =IFERROR(T40/R40,"m") -> 0.96208916 | V40: 194216 | W40: 194216 | X40: 184942.82 | Y40: =IFERROR(X40/V40,"m") -> 0.95225326
A41: New Zealand | B41: 59700 | C41: 58131 | D41: 52999.62 | E41: =IFERROR(D41/B41,"m") -> 0.88776583 | F41: 60162 | G41: 57448 | H41: 54274.44 | I41: =IFERROR(H41/F41,"m") -> 0.90213823 | J41: 60940 | K41: 59118 | L41: 53413.62 | M41: 0.87649524 | N41: 63460 | O41: 60083 | P41: 55128.8 | Q41: =IFERROR(P41/N41,"m") -> 0.8687173 | R41: 63800 | S41: 59341 | T41: 53397.58 | U41: =IFERROR(T41/R41,"m") -> 0.83695266 | V41: 55440 | W41: 53293 | X41: 48637.56 | Y41: =IFERROR(X41/V41,"m") -> 0.87730087
A42: Norway | B42: 60968 | C42: 60794 | D42: 55566.06 | E42: =IFERROR(D42/B42,"m") -> 0.91139713 | F42: 63642 | G42: 63491 | H42: 58082.58 | I42: =IFERROR(H42/F42,"m") -> 0.91264542 | J42: 64917 | K42: 64777 | L42: 59431.62 | M42: 0.91550164 | N42: 63352 | O42: 62948 | P42: 57366.74 | Q42: =IFERROR(P42/N42,"m") -> 0.90552374 | R42: 61708 | S42: 61449 | T42: 59884.49 | U42: =IFERROR(T42/R42,"m") -> 0.97044937 | V42: 56060 | W42: 55648 | X42: 52816.3 | Y42: =IFERROR(X42/V42,"m") -> 0.94213878
A43: Poland | B43: 354020 | C43: 331850 | D43: 318723.75 | E43: =IFERROR(D43/B43,"m") -> 0.90029871 | F43: 380366 | G43: 361600 | H43: 345709.14 | I43: =IFERROR(H43/F43,"m") -> 0.90888549 | J43: 425597 | K43: 410700 | L43: 379275.21 | M43: 0.89116044 | N43: 482500 | O43: 473700 | P43: 448866.15 | Q43: =IFERROR(P43/N43,"m") -> 0.93029254 | R43: 549000 | S43: 546000 | T43: 515992.95 | U43: =IFERROR(T43/R43,"m") -> 0.93987787 | V43: 589506 | W43: 569294 | X43: 534900.03 | Y43: =IFERROR(X43/V43,"m") -> 0.90736995
A44: Portugal | B44: 112977 | C44: 110732 | D44: 98627.58 | E44: =IFERROR(D44/B44,"m") -> 0.87298813 | F44: 110939 | G44: 101107 | H44: 97213.65 | I44: =IFERROR(H44/F44,"m") -> 0.87628021 | J44: 108728 | K44: 127537 | L44: 96034.23 | M44: 0.88325206 | N44: 115669 | O44: 107583 | P44: 96820.39 | Q44: =IFERROR(P44/N44,"m") -> 0.837047 | R44: 115426 | S44: 100816 | T44: 90078.87 | U44: =IFERROR(T44/R44,"m") -> 0.78040364 | V44: 109149 | W44: 99216 | X44: 96856.99 | Y44: =IFERROR(X44/V44,"m") -> 0.88738321
A45: Slovak Republic | B45: 51526 | C45: 50100 | D45: 44418.06 | E45: =IFERROR(D45/B45,"m") -> 0.86205139 | F45: 55674 | G45: 55203 | H45: 49653.57 | I45: =IFERROR(H45/F45,"m") -> 0.89186281 | J45: 59723 | K45: 59367 | L45: 54486.15 | M45: 0.91231435 | N45: 72826 | O45: 72454 | P45: 69274.05 | Q45: =IFERROR(P45/N45,"m") -> 0.9512269 | R45: 79989 | S45: 78427 | T45: 76200.83 | U45: =IFERROR(T45/R45,"m") -> 0.95264136 | V45: 84242 | W45: 81945 | X45: 77066.7 | Y45: =IFERROR(X45/V45,"m") -> 0.91482515
A46: Slovenia | B46: 17501 | C46: 18236 | D46: 17138.34 | E46: =IFERROR(D46/B46,"m") -> 0.97927776 | F46: 18078 | G46: 17689 | H46: 16772.88 | I46: =IFERROR(H46/F46,"m") -> 0.92780617 | J46: 19471 | K46: 18935 | L46: 18303.39 | M46: 0.94003338 | N46: 20314 | O46: 19571 | P46: 18773.01 | Q46: =IFERROR(P46/N46,"m") -> 0.92414148 | R46: 23431 | S46: 23018 | T46: 20595.17 | U46: =IFERROR(T46/R46,"m") -> 0.87897102 | V46: m | W46: m | X46: m | Y46: =IFERROR(X46/V46,"m") -> m
...

Sheet Table I.A2.3
A1: PISA 2018 Results (Volume I) - © OECD 2019
A2: Annex A2 | B2: Annex A2 The PISA target population, the PISA samples, and the definition of schools
A3: Version 4 - Last updated: 13-Oct-2020
A4: Disclaimer: http://oe.cd/disclaimer
A6: Table I.A2.3
A7: PISA target populations and samples in adjudicated regions
B12: Population and sample information | N12: Coverage indices
B13: Total population of 15-year-olds | C13: Total enrolled population of 15-year-olds at grade 7 or above | D13: Total in national desired target population | E13: Total school-level exclusions | F13: Total in national desired target population after all school exclusions and before within-school exclusions | G13: School-level exclusion rate (%) | H13: Number of participating students | I13: Weighted number of participating students | J13: Number of excluded students | K13: Weighted number of excluded students | L13: Within-school exclusion rate (%) | M13: Overall exclusion rate (%) | N13: Coverage Index 1: Coverage of national desired population | O13: Coverage Index 2: Coverage of national enrolled population | P13: Coverage Index 3: Coverage of 15-year-old population
B14: (1) | C14: (2) | D14: (3) | E14: (4) | F14: (5) | G14: (6) | H14: (7) | I14: (8) | J14: (9) | K14: (10) | L14: (11) | M14: (12) | N14: (13) | O14: (14) | P14: (15)
A15: OECD
A16: Belgium
A17: Flemish community* | B17: 69245 | C17: 67326 | D17: 67326 | E17: 1270.454 | F17: 66055.546 | G17: 1.8870184 | H17: 4882 | I17: 66685.44 | J17: 24 | K17: 293.19 | L17: 0.43773663 | M17: 2.3164949 | N17: 0.97683505 | O17: 0.97683505 | P17: 0.96303618
A18: United Kingdom
A19: Excluding Scotland* | B19: 650593 | C19: 644332 | D19: 644332 | E19: 14425 | F19: 629907 | G19: 2.2387527 | H19: 10820 | I19: 552087.87 | J19: 544 | K19: 18798.66 | L19: 3.292889 | M19: 5.4579221 | N19: 0.94542078 | O19: 0.94542078 | P19: 0.84859178
A20: Scotland* | B20: 53398 | C20: 53271 | D20: 53271 | E20: 902 | F20: 52369 | G20: 1.693229 | H20: 2998 | I20: 45151.71 | J20: 144 | K20: 1763.58 | L20: 3.759073 | M20: 5.3886523 | N20: 0.94611348 | O20: 0.94611348 | P20: 0.84556931
A21: Partners
A22: Argentina
A23: Ciudad Autónoma de Buenos Aires* | B23: 36923 | C23: 37793 | D23: 37793 | E23: 222 | F23: 37571 | G23: 0.58741037 | H23: 2330 | I23: 34625.13 | J23: 6 | K23: 71.61 | L23: 0.20638827 | M23: 0.79258629 | N23: 0.99207414 | O23: 0.99207414 | P23: 0.93776589
A24: Córdoba* | B24: 55682 | C24: 53654 | D24: 53654 | E24: 617 | F24: 53037 | G24: 1.1499609 | H24: 2391 | I24: 46205.16 | J24: 63 | K24: 1230.93 | L24: 2.594923 | M24: 3.7150432 | N24: 0.96284957 | O24: 0.96284957 | P24: 0.82980425
A25: Provincia de Buenos Aires* | B25: 258548 | C25: 256779 | D25: 256779 | E25: 2960 | F25: 253819 | G25: 1.1527422 | H25: 2073 | I25: 210617.52 | J25: 18 | K25: 1392.21 | L25: 0.6566726 | M25: 1.8018451 | N25: 0.98198141 | O25: 0.98198141 | P25: 0.81461671
A26: Tucumán* | B26: 28534 | C26: 27010 | D26: 27010 | E26: 257 | F26: 26753 | G26: 0.95149944 | H26: 2279 | I26: 21434.13 | J26: 13 | K26: 120.78 | L26: 0.56033559 | M26: 1.5065034 | N26: 0.98493359 | O26: 0.98493359 | P26: 0.75117859
A27: Russia
A28: Moscow City* | H28: 5768 | I28: 79378.38 | J28: 80 | K28: 1037.16 | L28: 1.2897507 | M28: 1.2897507
A29: Moscow Region* | H29: 2016 | I29: 65735.73 | J29: 4 | K29: 127.32 | L29: 0.19331021 | M29: 0.19331021
A30: Tatarstan* | H30: 5816 | I30: 35048.1 | J30: 17 | K30: 122.25 | L30: 0.34759392 | M30: 0.34759392
A31: United Arab Emirates
A32: Abu Dhabi* | B32: 22207 | C32: 22194 | D32: 22176 | E32: 190.48907 | F32: 21985.511 | G32: 0.85898753 | H32: 6450 | I32: 20630.79 | J32: 27 | K32: 61.95 | L32: 0.2993808 | M32: 1.1557967 | N32: 0.98844347 | O32: 0.98764181 | P32: 0.92902193
A33: Dubai* | B33: 16464 | C33: 16455 | D33: 16453 | E33: 584 | F33: 15869 | G33: 3.5495046 | H33: 6133 | I33: 14580.57 | J33: 75 | K33: 167.37 | L33: 1.1348704 | M33: 4.6440927 | N33: 0.95355907 | O33: 0.95344317 | P33: 0.88560313
A35: *PISA adjudicated region
A36: Notes: For a full explanation of the details in this table please refer to the PISA 2018 Technical Report (OECD, forthcoming).
A37: The figure for total national population of 15-year-olds enrolled in Column 2 may occasionally be larger than the total number of 15-year-olds in Column 1 due to differing data sources.

Sheet Table I.A2.4
A1: PISA 2018 Results (Volume I) - © OECD 2019
A2: Annex A2 | B2: Annex A2 The PISA target population, the PISA samples, and the definition of schools
A3: Version 4 - Last updated: 13-Oct-2020
A4: Disclaimer: http://oe.cd/disclaimer
A6: Table I.A2.4
A7: Exclusions, PISA 2018
B12: Student exclusions (unweighted) | H12: Student exclusions (weighted)
B13: Number of excluded students with functional disability (Code 1) | C13: Number of excluded students with intellectual disability (Code 2) | D13: Number of excluded students because of language (Code 3) | E13: Number of excluded students for other reasons (Code 4) | F13: Number of excluded students because of no materials available in the language of instruction (Code 5) | G13: Total number of excluded students | H13: Weighted number of excluded students with functional disability (Code 1) | I13: Weighted number of excluded students with intellectual disability (Code 2) | J13: Weighted number of excluded students because of language (Code 3) | K13: Weighted number of excluded students for other reasons (Code 4) | L13: Weighted number of excluded students because of no materials available in the language of instruction (Code 5) | M13: Total weighted number of excluded students
B14: (1) | C14: (2) | D14: (3) | E14: (4) | F14: (5) | G14: (6) | H14: (7) | I14: (8) | J14: (9) | K14: (10) | L14: (11) | M14: (12)
A15: OECD
A16: Australia | B16: 69 | C16: 555 | D16: 92 | E16: 0 | F16: 0 | G16: 716 | H16: 1053.51 | I16: 7894.98 | J16: 1300.17 | K16: 0 | L16: 0 | M16: 10248.66
A17: Austria | B17: 7 | C17: 49 | D17: 61 | E17: 0 | F17: 0 | G17: 117 | H17: 77.46 | I17: 530.73 | J17: 770.61 | K17: 0 | L17: 0 | M17: 1378.83
A18: Belgium | B18: 8 | C18: 19 | D18: 18 | E18: 0 | F18: 0 | G18: 45 | H18: 86.85 | I18: 210.96 | J18: 195.81 | K18: 0 | L18: 0 | M18: 493.62
A19: Canada | B19: 125 | C19: 1040 | D19: 316 | E19: 0 | F19: 0 | G19: 1481 | H19: 1611.18 | I19: 11744.07 | J19: 4141.05 | K19: 0 | L19: 0 | M19: 17496.3
A20: Chile | B20: 6 | C20: 58 | D20: 4 | E20: 0 | F20: 0 | G20: 68 | H20: 173.22 | I20: 1726.83 | J20: 128.73 | K20: 0 | L20: 0 | M20: 2028.78
A21: Colombia | B21: 4 | C21: 24 | D21: 0 | E21: 0 | F21: 0 | G21: 28 | H21: 345.81 | I21: 1466.4 | J21: 0 | K21: 0 | L21: 0 | M21: 1812.21
A22: Czech Republic | B22: 1 | C22: 0 | D22: 0 | E22: 0 | F22: 0 | G22: 1 | H22: 10.95 | I22: 0 | J22: 0 | K22: 0 | L22: 0 | M22: 10.95
A23: Denmark | B23: 15 | C23: 179 | D23: 88 | E23: 162 | F23: 0 | G23: 444 | H23: 97.62 | I23: 1453.2 | J23: 426.51 | K23: 1031.88 | L23: 0 | M23: 3009.21
A24: Estonia | B24: 3 | C24: 85 | D24: 8 | E24: 0 | F24: 0 | G24: 96 | H24: 7.86 | I24: 173.85 | J24: 13.05 | K24: 0 | L24: 0 | M24: 194.73
A25: Finland | B25: 6 | C25: 100 | D25: 22 | E25: 17 | F25: 12 | G25: 157 | H25: 54.72 | I25: 965.82 | J25: 204.33 | K25: 154.86 | L25: 110.91 | M25: 1490.64
A26: France | B26: 8 | C26: 28 | D26: 20 | E26: 0 | F26: 0 | G26: 56 | H26: 776.25 | I26: 3397.08 | J26: 2470.89 | K26: 0 | L26: 0 | M26: 6644.22
A27: Germany | B27: 2 | C27: 18 | D27: 22 | E27: 0 | F27: 0 | G27: 42 | H27: 198.75 | I27: 1858.8 | J27: 2789.28 | K27: 0 | L27: 0 | M27: 4846.83
... A52: United States | B52: 38 | C52: 106 | D52: 39 | E52: 11 | F52: 0 | G52: 194 | H52: 25164.18 | I52: 62554.8 | J52: 24971.58 | K52: 6366.54 | L52: 0 | M52: 119057.1
A53: Partners
A54: Albania | B54: 0 | C54: 0 | D54: 0 | E54: 0 | F54: 0 | G54: 0 | H54: 0 | I54: 0 | J54: 0 | K54: 0 | L54: 0 | M54: 0
A55: Argentina | B55: 21 | C55: 96 | D55: 1 | E55: 0 | F55: 0 | G55: 118 | H55: 870.81 | I55: 3199.11 | J55: 13.41 | K55: 0 | L55: 0 | M55: 4083.3
A56: Baku (Azerbaijan) | B56: 0 | C56: 0 | D56: 0 | E56: 0 | F56: 0 | G56: 0 | H56: 0 | I56: 0 | J56: 0 | K56: 0 | L56: 0 | M56: 0
A57: Belarus | B57: 30 | C57: 1 | D57: 0 | E57: 0 | F57: 0 | G57: 31 | H57: 449.46 | I57: 13.02 | J57: 0 | K57: 0 | L57: 0 | M57: 462.48
A58: Bosnia and Herzegovina | B58: 8 | C58: 16 | D58: 0 | E58: 0 | F58: 0 | G58: 24 | H58: 28.65 | I58: 77.01 | J58: 0 | K58: 0 | L58: 0 | M58: 105.66
A59: Brazil | B59: 4 | C59: 36 | D59: 1 | E59: 0 | F59: 0 | G59: 41 | H59: 693.45 | I59: 7100.01 | J59: 386.25 | K59: 0 | L59: 0 | M59: 8179.71
A60: Brunei Darussalam | B60: 9 | C60: 44 | D60: 0 | E60: 0 | F60: 0 | G60: 53 | H60: 9 | I60: 44.01 | J60: 0 | K60: 0 | L60: 0 | M60: 53.01
A61: B-S-J-Z (China) | B61: 2 | C61: 24 | D61: 8 | E61: 0 | F61: 0 | G61: 34 | H61: 49.02 | I61: 1194.06 | J61: 209.19 | K61: 0 | L61: 0 | M61: 1452.24
A62: Bulgaria | B62: 4 | C62: 76 | D62: 0 | E62: 0 | F62: 0 | G62: 80 | H62: 31.41 | I62: 653.46 | J62: 0 | K62: 0 | L62: 0 | M62: 684.87
A63: Costa Rica | B63: 22 | C63: 12 | D63: 5 | E63: 0 | F63: 0 | G63: 39 | H63: 138.96 | I63: 78.33 | J63: 31.32 | K63: 0 | L63: 0 | M63: 248.61
A64: Croatia | B64: 7 | C64: 84 | D64: 4 | E64: 0 | F64: 40 | G64: 135 | H64: 33.33 | I64: 397.2 | J64: 23.55 | K64: 0 | L64: 182.46 | M64: 636.57
A65: Cyprus | B65: 17 | C65: 143 | D65: 41 | E65: 0 | F65: 0 | G65: 201 | H65: 24.57 | I65: 249.69 | J65: 76.98 | K65: 0 | L65: 0 | M65: 351.24
... A95: Viet Nam | B95: 0 | C95: 0 | D95: 0 | E95: 0 | F95: 0 | G95: 0 | H95: 0 | I95: 0 | J95: 0 | K95: 0 | L95: 0 | M95: 0
A103: Information on data for Cyprus: https://oe.cd/cyprus-disclaimer
A104: Note: For a full explanation of other details in this table please refer to the PISA 2018 Technical Report (OECD, forthcoming).
A106: Exclusion codes:
...

Sheet Table I.A2.5
A1: PISA 2018 Results (Volume I) - © OECD 2019
A2: Annex A2 | B2: Annex A2 The PISA target population, the PISA samples, and the definition of schools
A3: Version 4 - Last updated: 13-Oct-2020
A4: Disclaimer: http://oe.cd/disclaimer
A6: Table I.A2.5
A7: Exclusions in adjudicated regions
B12: Student exclusions (unweighted) | H12: Student exclusion (weighted)
B13: Number of excluded students with functional disability (Code 1) | C13: Number of excluded students with intellectual disability (Code 2) | D13: Number of excluded students because of language (Code 3) | E13: Number of excluded students for other reasons (Code 4) | F13: Number of excluded students because of no materials available in the language of instruction (Code 5) | G13: Total number of excluded students | H13: Weighted number of excluded students with functional disability (Code 1) | I13: Weighted number of excluded students with intellectual disability (Code 2) | J13: Weighted number of excluded students because of language (Code 3) | K13: Weighted number of excluded students for other reasons (Code 4) | L13: Weighted number of excluded students because of no materials available in the language of instruction (Code 5) | M13: Total weighted number of excluded students
B14: (1) | C14: (2) | D14: (3) | E14: (4) | F14: (5) | G14: (6) | H14: (7) | I14: (8) | J14: (9) | K14: (10) | L14: (11) | M14: (12)
A15: OECD
A16: Belgium
A17: Flemish community* | B17: 5 | C17: 17 | D17: 2 | E17: 0 | F17: 0 | G17: 24 | H17: 56.55 | I17: 198.81 | J17: 37.83 | K17: 0 | L17: 0 | M17: 293.19
A18: United Kingdom
A19: Excluding Scotland* | B19: 55 | C19: 459 | D19: 30 | E19: 0 | F19: 0 | G19: 544 | H19: 2210.19 | I19: 15189.36 | J19: 1399.11 | K19: 0 | L19: 0 | M19: 18798.66
A20: Scotland* | B20: 20 | C20: 114 | D20: 10 | E20: 0 | F20: 0 | G20: 144 | H20: 238.2 | I20: 1402.74 | J20: 122.64 | K20: 0 | L20: 0 | M20: 1763.58
A21: Partners
A22: Argentina
A23: Ciudad Autónoma de Buenos Aires* | B23: 0 | C23: 5 | D23: 1 | E23: 0 | F23: 0 | G23: 6 | H23: 0 | I23: 58.23 | J23: 13.41 | K23: 0 | L23: 0 | M23: 71.61
A24: Córdoba* | B24: 10 | C24: 53 | D24: 0 | E24: 0 | F24: 0 | G24: 63 | H24: 138.06 | I24: 1092.87 | J24: 0 | K24: 0 | L24: 0 | M24: 1230.93
A25: Provincia de Buenos Aires* | B25: 7 | C25: 11 | D25: 0 | E25: 0 | F25: 0 | G25: 18 | H25: 516.45 | I25: 875.76 | J25: 0 | K25: 0 | L25: 0 | M25: 1392.21
A26: Tucumán* | B26: 1 | C26: 12 | D26: 0 | E26: 0 | F26: 0 | G26: 13 | H26: 6.45 | I26: 114.36 | J26: 0 | K26: 0 | L26: 0 | M26: 120.78
A27: Russia
A28: Moscow City* | B28: 36 | C28: 42 | D28: 2 | E28: 0 | F28: 0 | G28: 80 | H28: 465 | I28: 546.6 | J28: 25.56 | K28: 0 | L28: 0 | M28: 1037.16
A29: Moscow Region* | B29: 3 | C29: 0 | D29: 1 | E29: 0 | F29: 0 | G29: 4 | H29: 97.71 | I29: 0 | J29: 29.61 | K29: 0 | L29: 0 | M29: 127.32
A30: Tatarstan* | B30: 8 | C30: 5 | D30: 4 | E30: 0 | F30: 0 | G30: 17 | H30: 47.46 | I30: 47.22 | J30: 27.6 | K30: 0 | L30: 0 | M30: 122.25
A31: United Arab Emirates
A32: Abu Dhabi* | B32: 1 | C32: 24 | D32: 2 | E32: 0 | F32: 0 | G32: 27 | H32: 0.99 | I32: 57.06 | J32: 3.87 | K32: 0 | L32: 0 | M32: 61.95
A33: Dubai* | B33: 6 | C33: 51 | D33: 18 | E33: 0 | F33: 0 | G33: 75 | H33: 7.23 | I33: 125.19 | J33: 34.95 | K33: 0 | L33: 0 | M33: 167.37
A35: *PISA adjudicated region
A36: Exclusion codes:
A37: Code 1 | B37: Functional disability – student has a moderate to severe permanent physical disability.
A38: Code 2 | B38: Intellectual disability – student has a mental or emotional disability and has either been tested as cognitively delayed or is considered in the professional opinion of qualified staff to be cognitively delayed.
A39: Code 3 | B39: Limited assessment language proficiency – student is not a native speaker of any of the languages of the assessment in the country; he/she has limited proficiency in the assessment language, and he/she has received less than one year of instruction in the assessment language.
A40: Code 4 | B40: Other reasons defined by the national centres and approved by the international centre.
A41: Code 5 | B41: No materials available in the language of instruction.
A42: Notes: For a full explanation of other details in this table please refer to the PISA 2018 Technical Report (OECD, forthcoming).

Sheet Table I.A2.6
A1: PISA 2018 Results (Volume I) - © OECD 2019
A2: Annex A2 | B2: Annex A2 The PISA target population, the PISA samples, and the definition of schools
A3: Version 4 - Last updated: 13-Oct-2020
A4: Disclaimer: http://oe.cd/disclaimer
A6: Table I.A2.6
A7: Response rates, PISA 2018
B12: Initial sample - before school replacement | G12: Final sample - after school replacement | L12: Final sample - students within schools after school replacement
B13: Weighted school participation rate before replacement (%) | C13: Weighted number of responding schools (weighted also by enrolment) | D13: Weighted number of schools sampled (responding and non-responding) (weighted also by enrolment) | E13: Number of responding schools (unweighted) | F13: Number of responding and non-responding schools (unweighted) | G13: Weighted school participation rate after replacement (%) | H13: Weighted number of responding schools (weighted also by enrolment) | I13: Weighted number of schools sampled (responding and non-responding) (weighted also by enrolment) | J13: Number of responding schools (unweighted) | K13: Number of responding and non-responding schools (unweighted) | L13: Weighted student participation rate after replacement (%) | M13: Number of students assessed (weighted) | N13: Number of students sampled (assessed and absent) (weighted) | O13: Number of students assessed (unweighted) | P13: Number of students sampled (assessed and absent) (unweighted)
B14: (1) | C14: (2) | D14: (3) | E14: (4) | F14: (5) | G14: (6) | H14: (7) | I14: (8) | J14: (9) | K14: (10) | L14: (11) | M14: (12) | N14: (13) | O14: (14) | P14: (15)
A15: OECD
A16: Australia | B16: 94.812302 | C16: 264303.78 | D16: 278765.28 | E16: 734 | F16: 779 | G16: 95.807638 | H16: 267078.43 | I16: 278765.28 | J16: 740 | K16: 779 | L16: 85.140134 | M16: 210664.66 | N16: 247432.85 | O16: 14081 | P16: 16756
A17: Austria | B17: 99.906015 | C17: 78872.014 | D17: 78946.211 | E17: 291 | F17: 293 | G17: 99.906015 | H17: 78872.014 | I17: 78946.211 | J17: 291 | K17: 293 | L17: 92.544467 | M17: 69425.931 | N17: 75018.997 | O17: 6802 | P17: 7555
A18: Belgium | B18: 86.544264 | C18: 103631.37 | D18: 119743.78 | E18: 256 | F18: 308 | G18: 94.604608 | H18: 113259.4 | I18: 119718.69 | J18: 285 | K18: 308 | L18: 91.099378 | M18: 101503.87 | N18: 111421.03 | O18: 8431 | P18: 9271
A19: Canada | B19: 85.727358 | C19: 328934.66 | D19: 383698.58 | E19: 782 | F19: 914 | G19: 88.57498 | H19: 339896.26 | I19: 383738.45 | J19: 804 | K19: 914 | L19: 84.028909 | M19: 251025.04 | N19: 298736.52 | O19: 22440 | P19: 26252
A20: Chile | B20: 90.217054 | C20: 190059.7 | D20: 210669.37 | E20: 224 | F20: 258 | G20: 99.66134 | H20: 209952.74 | I20: 210666.18 | J20: 255 | K20: 258 | L20: 93.093646 | M20: 197940.24 | N20: 212624.87 | O20: 7601 | P20: 8156
A21: Colombia | B21: 94.708348 | C21: 596406.25 | D21: 629729.33 | E21: 238 | F21: 250 | G21: 96.999278 | H21: 610210.96 | I21: 629088.14 | J21: 244 | K21: 250 | L21: 92.822217 | M21: 475819.89 | N21: 512614.22 | O21: 7480 | P21: 8036
A22: Czech Republic | B22: 98.815348 | C22: 86649.728 | D22: 87688.533 | E22: 330 | F22: 334 | G22: 98.815348 | H22: 86649.728 | I22: 87688.533 | J22: 330 | K22: 334 | L22: 91.902917 | M22: 79903.479 | N22: 86943.354 | O22: 6996 | P22: 7628
A23: Denmark | B23: 88.114664 | C23: 52391.672 | D23: 59458.517 | E23: 328 | F23: 371 | G23: 93.335298 | H23: 55169.539 | I23: 59108.976 | J23: 344 | K23: 371 | L23: 86.437764 | M23: 48473 | N23: 56078.498 | O23: 7607 | P23: 8891
A24: Estonia | B24: 100 | C24: 11684.163 | D24: 11684.163 | E24: 231 | F24: 231 | G24: 100 | H24: 11684.163 | I24: 11684.163 | J24: 231 | K24: 231 | L24: 92.096821 | M24: 10532.157 | N24: 11435.962 | O24: 5316 | P24: 5786
A25: Finland | B25: 99.496475 | C25: 57419.596 | D25: 57710.181 | E25: 213 | F25: 214 | G25: 100 | H25: 57710.181 | I25: 57710.181 | J25: 214 | K25: 214 | L25: 92.833263 | M25: 52101.957 | N25: 56124.233 | O25: 5649 | P25: 6084
A26: France | B26: 98.010673 | C26: 769117.14 | D26: 784727.94 | E26: 244 | F26: 252 | G26: 99.786043 | H26: 783048.96 | I26: 784727.94 | J26: 250 | K26: 252 | L26: 92.565209 | M26: 698720.67 | N26: 754841.56 | O26: 6295 | P26: 6817
A27: Germany | B27: 95.6776 | C27: 739666.09 | D27: 773082.01 | E27: 215 | F27: 226 | G27: 98.196 | H27: 759094.47 | I27: 773040.22 | J27: 221 | K27: 226 | L27: 90.401039 | M27: 652025.02 | N27: 721258.32 | O27: 5431 | P27: 6036
... A52: United States | B52: 64.95708 | C52: 2516630.5 | D52: 3874297.5 | E52: 136 | F52: 215 | G52: 76.412206 | H52: 2960088.5 | I52: 3873842.5 | J52: 162 | K52: 215 | L52: 84.798053 | M52: 2301006.4 | N52: 2713513.2 | O52: 4811 | P52: 5686
A53: Partners
A54: Albania | B54: 96.920426 | C54: 29234.249 | D54: 30163.145 | E54: 322 | F54: 336 | G54: 97.006689 | H54: 29260.268 | I54: 30163.145 | J54: 323 | K54: 336 | L54: 98.265902 | M54: 26611.09 | N54: 27080.696 | O54: 6333 | P54: 6438
A55: Argentina | B55: 95.228564 | C55: 626740.22 | D55: 658143.09 | E55: 439 | F55: 458 | G55: 95.670764 | H55: 629650.52 | I55: 658143.09 | J55: 445 | K55: 458 | L55: 86.278379 | M55: 467612.53 | N55: 541981.13 | O55: 11836 | P55: 13532
A56: Baku (Azerbaijan) | B56: 93.465696 | C56: 18730.316 | D56: 20039.776 | E56: 181 | F56: 197 | G56: 100 | H56: 20248.539 | I56: 20248.539 | J56: 197 | K56: 197 | L56: 88.860889 | M56: 18049.389 | N56: 20311.96 | O56: 6827 | P56: 7607
A57: Belarus | B57: 100 | C57: 79623.287 | D57: 79623.287 | E57: 234 | F57: 234 | G57: 100 | H57: 79623.287 | I57: 79623.287 | J57: 234 | K57: 234 | L57: 97.431204 | M57: 76320.813 | N57: 78333.028 | O57: 5803 | P57: 5963
A58: Bosnia and Herzegovina | B58: 99.892942 | C58: 31024.545 | D58: 31057.795 | E58: 212 | F58: 213 | G58: 100 | H58: 31051.145 | I58: 31051.145 | J58: 213 | K58: 213 | L58: 95.558762 | M58: 27561.769 | N58: 28842.744 | O58: 6480 | P58: 6781
A59: Brazil | B59: 86.76155 | C59: 2483765.8 | D59: 2862749.5 | E59: 547 | F59: 638 | G59: 92.692699 | H59: 2649165.4 | I59: 2858008.7 | J59: 586 | K59: 638 | L59: 88.845141 | M59: 1683080.4 | N59: 1894397.8 | O59: 10606 | P59: 11956
A60: Brunei Darussalam | B60: 100 | C60: 6681 | D60: 6681 | E60: 55 | F60: 55 | G60: 100 | H60: 6681 | I60: 6681 | J60: 55 | K60: 55 | L60: 98.970865 | M60: 6828 | N60: 6899 | O60: 6828 | P60: 6899
A61: B-S-J-Z (China) | B61: 96.440185 | C61: 1030427.3 | D61: 1068462.6 | E61: 355 | F61: 362 | G61: 99.393066 | H61: 1062001 | I61: 1068486 | J61: 361 | K61: 362 | L61: 99.214132 | M61: 978802.84 | N61: 986555.87 | O61: 12058 | P61: 12156
A62: Bulgaria | B62: 95.875245 | C62: 48095.058 | D62: 50164.209 | E62: 191 | F62: 199 | G62: 98.850431 | H62: 49568.222 | I62: 50144.669 | J62: 197 | K62: 199 | L62: 93.078858 | M62: 44002.735 | N62: 47274.683 | O62: 5294 | P62: 5673
A63: Costa Rica | B63: 100 | C63: 58842.794 | D63: 58842.794 | E63: 205 | F63: 205 | G63: 100 | H63: 58842.794 | I63: 58842.794 | J63: 205 | K63: 205 | L63: 97.050841 | M63: 44179.008 | N63: 45521.51 | O63: 7221 | P63: 7433
A64: Croatia | B64: 97.237496 | C64: 28382.067 | D64: 29188.398 | E64: 178 | F64: 183 | G64: 100 | H64: 29177.059 | I64: 29177.059 | J64: 183 | K64: 183 | L64: 92.019344 | M64: 32631.568 | N64: 35461.64 | O64: 6609 | P64: 7190
A65: Cyprus | B65: 97.826212 | C65: 7945.7814 | D65: 8122.3439 | E65: 90 | F65: 99 | G65: 97.826212 | H65: 7945.7814 | I65: 8122.3439 | J65: 90 | K65: 99 | L65: 93.353315 | M65: 6975.4478 | N65: 7472.0944 | O65: 5503 | P65: 5890
... A95: Viet Nam | B95: 100 | C95: 1116404 | D95: 1116404 | E95: 151 | F95: 151 | G95: 100 | H95: 1116404 | I95: 1116404 | J95: 151 | K95: 151 | L95: 98.770771 | M95: 914873.84 | N95: 926259.69 | O95: 5377 | P95: 5445
A103: Information on data for Cyprus: https://oe.cd/cyprus-disclaimer

Sheet Table I.A2.7
A1: PISA 2018 Results (Volume I) - © OECD 2019
A2: Annex A2 | B2: Annex A2 The PISA target population, the PISA samples, and the definition of schools
A3: Version 4 - Last updated: 13-Oct-2020
A4: Disclaimer: http://oe.cd/disclaimer
A6: Table I.A2.7
A7: Response rates in adjudicated regions
B12: Initial sample - before school replacement | G12: Final sample - after school replacement | L12: Final sample - students within schools after school replacement
B13: Weighted school participation rate before replacement (%) | C13: Weighted number of responding schools (weighted also by enrolment) | D13: Weighted number of schools sampled (responding and non-responding) (weighted also by enrolment) | E13: Number of responding schools (unweighted) | F13: Number of responding and non-responding schools (unweighted) | G13: Weighted school participation rate after replacement (%) | H13: Weighted number of responding schools (weighted also by enrolment) | I13: Weighted number of schools sampled (responding and non-responding) (weighted also by enrolment) | J13: Number of responding schools (unweighted) | K13: Number of responding and non-responding schools (unweighted) | L13: Weighted student participation rate after replacement (%) | M13: Number of students assessed (weighted) | N13: Number of students sampled (assessed and absent) (weighted) | O13: Number of students assessed (unweighted) | P13: Number of students sampled (assessed and absent) (unweighted)
B14: (1) | C14: (2) | D14: (3) | E14: (4) | F14: (5) | G14: (6) | H14: (7) | I14: (8) | J14: (9) | K14: (10) | L14: (11) | M14: (12) | N14: (13) | O14: (14) | P14: (15)
A15: OECD
A16: Belgium
A17: Flemish community* | B17: 78.981891 | C17: 50947.433 | D17: 64505.208 | E17: 144 | F17: 190 | G17: 91.106224 | H17: 58745.402 | I17: 64480.12 | J17: 169 | K17: 190 | L17: 90.4048 | M17: 55105.677 | N17: 60954.358 | O17: 4855 | P17: 5360
A18: United Kingdom
A19: Excluding Scotland* | B19: 71.770047 | C19: 451975.58 | D19: 629755.17 | E19: 298 | F19: 421 | G19: 86.106853 | H19: 542901.49 | I19: 630497.43 | J19: 353 | K19: 421 | L19: 83.327382 | M19: 394434 | N19: 473354.6 | O19: 10699 | P19: 12756
A20: Scotland* | B20: 86.496579 | C20: 44766.406 | D20: 51755.117 | E20: 101 | F20: 117 | G20: 92.154403 | H20: 47656.974 | I20: 51714.267 | J20: 108 | K20: 117 | L20: 80.512597 | M20: 33509.888 | N20: 41620.677 | O20: 2969 | P20: 3687
A21: Partners
A22: Argentina
A23: Ciudad Autónoma de Buenos Aires* | B23: 91.228291 | C23: 33148.836 | D23: 36336.136 | E23: 74 | F23: 81 | G23: 97.462105 | H23: 35413.963 | I23: 36336.136 | J23: 79 | K23: 81 | L23: 87.2371 | M23: 29322.493 | N23: 33612.393 | O23: 2303 | P23: 2655
A24: Córdoba* | B24: 98.711525 | C24: 49427.807 | D24: 50072.985 | E24: 82 | F24: 83 | G24: 100 | H24: 50072.985 | I24: 50072.985 | J24: 83 | K24: 83 | L24: 94.3466 | M24: 43592.988 | N24: 46205.154 | O24: 2391 | P24: 2543
A25: Provincia de Buenos Aires* | B25: 95.158062 | C25: 240701.89 | D25: 252949.56 | E25: 84 | F25: 88 | G25: 95.158062 | H25: 240701.89 | I25: 252949.56 | J25: 84 | K25: 88 | L25: 83.7333 | M25: 168541.18 | N25: 201283.36 | O25: 2026 | P25: 2451
A26: Tucumán* | B26: 98.677889 | C26: 24749.042 | D26: 25080.636 | E26: 84 | F26: 85 | G26: 98.677889 | H26: 24749.042 | I26: 25080.636 | J26: 84 | K26: 85 | L26: 88.1264 | M26: 18609.437 | N26: 21116.755 | O26: 2268 | P26: 2585
A27: Russia
A28: Moscow City* | B28: 100 | C28: 78840.172 | D28: 78840.172 | E28: 151 | F28: 151 | G28: 100 | H28: 78840.172 | I28: 78840.172 | J28: 151 | K28: 151 | L28: 95.4506 | M28: 75678.256 | N28: 79285.273 | O28: 5768 | P28: 6044
A29: Moscow Region* | B29: 100 | C29: 66209.192 | D29: 66209.192 | E29: 61 | F29: 61 | G29: 100 | H29: 66209.192 | I29: 66209.192 | J29: 61 | K29: 61 | L29: 98.0496 | M29: 64439.239 | N29: 65721.033 | O29: 2016 | P29: 2059
A30: Tatarstan* | B30: 100 | C30: 35865.544 | D30: 35865.544 | E30: 239 | F30: 239 | G30: 100 | H30: 35865.544 | I30: 35865.544 | J30: 239 | K30: 239 | L30: 97.8585 | M30: 34308.431 | N30: 35059.215 | O30: 5816 | P30: 5954
A31: United Arab Emirates
A32: Abu Dhabi* | B32: 99.986399 | C32: 22053.884 | D32: 22056.884 | E32: 244 | F32: 246 | G32: 99.986399 | H32: 22053.884 | I32: 22056.884 | J32: 244 | K32: 246 | L32: 94.8463 | M32: 19566.775 | N32: 20629.993 | O32: 6450 | P32: 6792
A33: Dubai* | B33: 99.804527 | C33: 15828 | D33: 15859 | E33: 234 | F33: 235 | G33: 99.804527 | H33: 15828 | I33: 15859 | J33: 234 | K33: 235 | L33: 94.9807 | M33: 13856.086 | N33: 14588.314 | O33: 6121 | P33: 6461
A35: *PISA adjudicated region

Sheet Table I.A2.8
A1: PISA 2018 Results (Volume I) - © OECD 2019
A2: Annex A2 | B2: Annex A2 The PISA target population, the PISA samples, and the definition of schools
A3: Version 4 - Last updated: 13-Oct-2020
A4: Disclaimer: http://oe.cd/disclaimer
A6: Table I.A2.8
A7: Percentage of students, including those with missing information, at each grade level, PISA 2018
B12: All students
B13: 7th grade | D13: 8th grade | F13: 9th grade | H13: 10th grade | J13: 11th grade | L13: 12th grade and above | N13: Information unavailable
B14: % | C14: S.E. | D14: % | E14: S.E. | F14: % | G14: S.E. | H14: % | I14: S.E. | J14: % | K14: S.E. | L14: % | M14: S.E. | N14: % | O14: SE
A15: OECD
A16: Australia | B16: 0 | C16: c | D16: 0.087350266 | E16: 0.033663397 | F16: 11.491462 | G16: 0.36250726 | H16: 81.002697 | I16: 0.54268543 | J16: 7.3895484 | K16: 0.40437766 | L16: 0.028942407 | M16: 0.015990907 | N16: 0 | O16: c
A17: Austria | B17: 0.43179546 | C17: 0.11389359 | D17: 6.8199103 | E17: 0.4334443 | F17: 44.526559 | G17: 0.73790128 | H17: 48.056344 | I17: 0.81610204 | J17: 0.16539097 | K17: 0.052447744 | L17: 0 | M17: c | N17: 0 | O17: c
A18: Belgium | B18: 0.34734711 | C18: 0.10552091 | D18: 6.1214958 | E18: 0.38301087 | F18: 26.658644 | G18: 0.67340997 | H18: 63.333287 | I18: 0.76407521 | J18: 1.2652469 | K18: 0.136221 | L18: 0 | M18: c | N18: 2.2739794 | O18: 0.31999113
A19: Canada | B19: 0.33703709 | C19: 0.088397267 | D19: 1.0476709 | E19: 0.17062457 | F19: 9.7424394 | G19: 0.3110233 | H19: 87.688202 | I19: 0.30396376 | J19: 1.1282997 | K19: 0.080947594 | L19: 0.056351352 | M19: 0.028114458 | N19: 0 | O19: c
A20: Chile | B20: 0.96666087 | C20: 0.1982964 | D20: 4.3607198 | E20: 0.453877 | F20: 20.557346 | G20: 0.70918429 | H20: 68.527888 | I20: 0.92484296 | J20: 5.5873848 | K20: 0.33168119 | L20: 0 | M20: c | N20: 0 | O20: c
A21: Colombia | B21: 4.4392426 | C21: 0.41384962 | D21: 11.277525 | E21: 0.52640651 | F21: 22.821737 | G21: 0.64998351 | H21: 42.963735 | I21: 0.75284507 | J21: 18.49776 | K21: 0.71144404 | L21: 0 | M21: c | N21: 0 | O21: c
A22: Czech Republic | B22: 0.6201213 | C22: 0.17961522 | D22: 3.3469904 | E22: 0.4265869 | F22: 48.486902 | G22: 1.2127481 | H22: 47.545987 | I22: 1.2571427 | J22: 0 | K22: c | L22: 0 | M22: c | N22: 0 | O22: c
A23: Denmark | B23: 0.12000257 | C23: 0.041972636 | D23: 16.302405 | E23: 0.50800133 | F23: 81.738068 | G23: 0.54400418 | H23: 1.7443991 | I23: 0.26448956 | J23: 0 | K23: c | L23: 0.095125402 | M23: 0.097776204 | N23: 0 | O23: c
A24: Estonia | B24: 0.41034963 | C24: 0.09830147 | D24: 21.842922 | E24: 0.57186498 | F24: 76.357839 | G24: 0.56385552 | H24: 1.3471281 | I24: 0.16723201 | J24: 0.041761959 | K24: 0.045237871 | L24: 0 | M24: c | N24: 0 | O24: c
A25: Finland | B25: 0.33734727 | C25: 0.095433338 | D25: 13.887889 | E25: 0.40304574 | F25: 85.558413 | G25: 0.45135213 | H25: 0.21635084 | I25: 0.11628163 | J25: 0 | K25: c | L25: 0 | M25: c | N25: 0 | O25: c
A26: France | B26: 0.016235689 | C26: 0.009567623 | D26: 0.51728393 | E26: 0.10617312 | F26: 16.91535 | G26: 0.5575355 | H26: 79.240849 | I26: 0.5874574 | J26: 3.206763 | K26: 0.16160798 | L26: 0.10351885 | M26: 0.034072486 | N26: 0 | O26: c
A27: Germany | B27: 0.43145454 | C27: 0.10509514 | D27: 8.0898971 | E27: 0.44595116 | F27: 46.360338 | G27: 1.0214936 | H27: 43.990888 | I27: 1.125573 | J27: 1.0964885 | K27: 0.30919574 | L27: 0.03093391 | M27: 0.022137772 | N27: 0 | O27: c
A28: Greece | B28: 0.080343475 | C28: 0.043188707 | D28: 0.70434462 | E28: 0.17976737 | F28: 3.6885865 | G28: 0.54893163 | H28: 95.526725 | I28: 0.59943095 | J28: 0 | K28: c | L28: 0 | M28: c | N28: 0 | O28: c
A29: Hungary | B29: 1.6726281 | C29: 0.25618579 | D29: 8.2893155 | E29: 0.52523536 | F29: 71.064459 | G29: 0.73795551 | H29: 18.937371 | I29: 0.64178301 | J29: 0.036225547 | K29: 0.026025583 | L29: 0 | M29: c | N29: 0 | O29: c
A30: Iceland | B30: 0 | C30: c | D30: 0 | E30: c | F30: 0 | G30: c | H30: 99.216408 | I30: 0.08240121 | J30: 0.78359153 | K30: 0.08240121 | L30: 0 | M30: c | N30: 0 | O30: c
A31: Ireland | B31: 0.016885759 | C31: 0.016275421 | D31: 2.0181134 | E31: 0.22460215 | F31: 61.568136 | G31: 0.67735112 | H31: 27.914427 | I31: 0.90704475 | J31: 8.4824375 | K31: 0.73040073 | L31: 0 | M31: c | N31: 0 | O31: c
A32: Israel | B32: 0.015167647 | C32: 0.014581302 | D32: 0.11434016 | E32: 0.052800349 | F32: 16.730808 | G32: 0.85525575 | H32: 82.408562 | I32: 0.86469987 | J32: 0.7009414 | K32: 0.21780254 | L32: 0.030181052 | M32: 0.03136623 | N32: 0 | O32: c
A33: Italy | B33: 0 | C33: c | D33: 0.96303395 | E33: 0.17873953 | F33: 13.495185 | G33: 0.46521666 | H33: 77.849247 | I33: 0.5208668 | J33: 7.6925341 | K33: 0.32736694 | L33: 0 | M33: c | N33: 0 | O33: c
A34: Japan | B34: 0 | C34: c | D34: 0 | E34: c | F34: 0 | G34: c | H34: 100 | I34: c | J34: 0 | K34: c | L34: 0 | M34: c | N34: 0 | O34: c
A35: Korea | B35: 0 | C35: c | D35: 0 | E35: c | F35: 16.07867 | G35: 0.71626635 | H35: 83.842565 | I35: 0.71541742 | J35: 0.078765291 | K35: 0.035303451 | L35: 0 | M35: c | N35: 0 | O35: c
A36: Latvia | B36: 0.65828165 | C36: 0.14688892 | D36: 9.7888695 | E36: 0.49162254 | F36: 85.973652 | G36: 0.53812516 | H36: 2.4990885 | I36: 0.18336589 | J36: 0.029582021 | K36: 0.021038351 | L36: 0 | M36: c | N36: 1.0505263 | O36: 0.24566477
A37: Lithuania | B37: 0.052639667 | C37: 0.051705912 | D37: 2.4278561 | E37: 0.21406574 | F37: 90.241569 | G37: 0.45667923 | H37: 7.2779348 | I37: 0.36418403 | J37: 0 | K37: c | L37: 0 | M37: c | N37: 0 | O37: c
