Workbook
Name _: [1]EAT12_1!#REF!,[1]EAT12_1!#REF!,[1]EAT12_1!#REF!,[1]EAT12_1!#REF!,[1]EAT12_1!#REF!,[1]EAT12_1!#REF!,[1]EAT12_1!#REF!,[1]EAT12_1!#REF!,[1]EAT12_1!#REF!,[1]EAT12_1!#REF!
Name _: [1]EAT12_1!#REF!,[1]EAT12_1!#REF!,[1]EAT12_1!#REF!,[1]EAT12_1!#REF!,[1]EAT12_1!#REF!,[1]EAT12_1!#REF!,[1]EAT12_1!#REF!,[1]EAT12_1!#REF!,[1]EAT12_1!#REF!,[1]EAT12_1!#REF!
Name _______ISC3: [2]ISC01!$B:$B+[3]Q_ISC3!$1:$23
Name ______ISC3: [2]ISC01!$B:$B+[3]Q_ISC3!$1:$23
Name _____ISC3: [2]ISC01!$B:$B+[3]Q_ISC3!$1:$23
Name ____ISC3: [2]ISC01!$B:$B+[3]Q_ISC3!$1:$23
Name ___ISC3: [2]ISC01!$B:$B+[3]Q_ISC3!$1:$23
Name __ISC3: [2]ISC01!$B:$B+[3]Q_ISC3!$1:$23
Name _6Y: [1]EAT12_1!#REF!,[1]EAT12_1!#REF!,[1]EAT12_1!#REF!,[1]EAT12_1!#REF!,[1]EAT12_1!#REF!,[1]EAT12_1!#REF!,[1]EAT12_1!#REF!,[1]EAT12_1!#REF!,[1]EAT12_1!#REF!,[1]EAT12_1!#REF!
Name _6Y: [1]EAT12_1!#REF!,[1]EAT12_1!#REF!,[1]EAT12_1!#REF!,[1]EAT12_1!#REF!,[1]EAT12_1!#REF!,[1]EAT12_1!#REF!,[1]EAT12_1!#REF!,[1]EAT12_1!#REF!,[1]EAT12_1!#REF!,[1]EAT12_1!#REF!
Name _ISC3: [2]ISC01!$B:$B+[3]Q_ISC3!$1:$23
Name calcul: '[6]Calcul_B1.1'!$A$1:$L$37
Name POpula: [8]POpula!$A$1:$I$1559
Name SPSS: [9]Figure5.6!$B$2:$X$30
Name toto: [10]Data5.11a!$B$3:$C$34

Sheet TOC
A1: PISA 2018 Results (Volume II) - © OECD 2019
A2: Annex B1 | B2: Annex B1.5 Results (tables): How do schools compensate for socio-economic disadvantage?
A3: Version 2 - Last updated: 02-Dec-2019
A4: Disclaimer: http://oe.cd/disclaimer
A6: TOC | B6: Volume II
A8: Chapter 5 | B8: How do schools compensate for socio-economic disadvantage?
A9: Tables
A11: ='Table II.B1.5.1'!A6 -> Table II.B1.5.1 | B11: ='Table II.B1.5.1'!$A$7 -> Variation in class size, by school characteristics
A12: ='Table II.B1.5.2'!A6 -> Table II.B1.5.2 | B12: ='Table II.B1.5.2'!$A$7 -> Student-teacher ratio, by school characteristics
A13: ='Table II.B1.5.3'!A6 -> Table II.B1.5.3 | B13: ='Table II.B1.5.3'!$A$7 -> Fully certified teachers, by school characteristics
A14: ='Table II.B1.5.4'!A6 -> Table II.B1.5.4 | B14: ='Table II.B1.5.4'!$A$7 -> Teachers with at least a master's degree, by school characteristics
A15: ='Table II.B1.5.5'!A6 -> Table II.B1.5.5 | B15: ='Table II.B1.5.5'!$A$7 -> Novice teachers, by school characteristics
A16: ='Table II.B1.5.6'!A6 -> Table II.B1.5.6 | B16: ='Table II.B1.5.6'!$A$7 -> Teachers and professional development activities, by school characteristics
A17: ='Table II.B1.5.7'!A6 -> Table II.B1.5.7 | B17: ='Table II.B1.5.7'!$A$7 -> Teacher absenteeism, by school characteristics
A18: ='Table II.B1.5.8'!A6 -> Table II.B1.5.8 | B18: ='Table II.B1.5.8'!$A$7 -> Teachers' satisfaction with their current job environment, by school characteristics
A19: ='Table II.B1.5.9'!A6 -> Table II.B1.5.9 | B19: ='Table II.B1.5.9'!$A$7 -> Teachers' satisfaction with teaching profession, by school characteristics
A20: ='Table II.B1.5.10'!A6 -> Table II.B1.5.10 | B20: ='Table II.B1.5.10'!$A$7 -> Teachers' self-efficacy in maintaining positive relations with students, by school characteristics
A21: ='Table II.B1.5.11'!A6 -> Table II.B1.5.11 | B21: ='Table II.B1.5.11'!$A$7 -> Teachers' self-efficacy in classroom management, by school characteristics
A22: ='Table II.B1.5.12'!A6 -> Table II.B1.5.12 | B22: ='Table II.B1.5.12'!$A$7 -> Teachers' self-efficacy in instructional settings, by school characteristics
A23: ='Table II.B1.5.13'!A6 -> Table II.B1.5.13 | B23: ='Table II.B1.5.13'!$A$7 -> Variation in principals' views on staff shortage, by school characteristics
A24: ='Table II.B1.5.14'!A6 -> Table II.B1.5.14 | B24: ='Table II.B1.5.14'!$A$7 -> Variation in principals' views on material shortage, by school characteristics
A25: ='Table II.B1.5.15'!A6 -> Table II.B1.5.15 | B25: ='Table II.B1.5.15'!$A$7 -> Principals' views on lack of educational material, by school characteristics
A26: ='Table II.B1.5.16'!A6 -> Table II.B1.5.16 | B26: ='Table II.B1.5.16'!$A$7 -> Principals' views on lack of teaching staff, by school characteristics
A27: ='Table II.B1.5.17'!A6 -> Table II.B1.5.17 | B27: ='Table II.B1.5.17'!$A$7 -> Principals' negative views on educational material, by school characteristics
A28: ='Table II.B1.5.18'!A6 -> Table II.B1.5.18 | B28: ='Table II.B1.5.18'!$A$7 -> Principals' views on lack of physical infrastructure, by school characteristics
A29: ='Table II.B1.5.19'!A6 -> Table II.B1.5.19 | B29: ='Table II.B1.5.19'!$A$7 -> Principals' negative views on teaching staff, by school characteristics
A30: ='Table II.B1.5.20'!A6 -> Table II.B1.5.20 | B30: ='Table II.B1.5.20'!$A$7 -> Principals' views on lack of assisting staff, by school characteristics
A31: ='Table II.B1.5.21'!A6 -> Table II.B1.5.21 | B31: ='Table II.B1.5.21'!$A$7 -> Principals' negative views on assisting staff, by school characteristics
A32: ='Table II.B1.5.22'!A6 -> Table II.B1.5.22 | B32: ='Table II.B1.5.22'!$A$7 -> Principals' negative views on physical infrastructure, by school characteristics
A33: ='Table II.B1.5.23'!A6 -> Table II.B1.5.23 | B33: ='Table II.B1.5.23'!$A$7 -> Teachers not being well prepared for classes, by school characteristics
A34: ='Table II.B1.5.24'!A6 -> Table II.B1.5.24 | B34: ='Table II.B1.5.24'!$A$7 -> Teacher training, by school characteristics
A35: ='Table II.B1.5.25'!A6 -> Table II.B1.5.25 | B35: ='Table II.B1.5.25'!$A$7 -> Teachers who participated in selected professional development activities, by school characteristics
A39: Symbols for missing data
A40: c: There were too few observations to provide reliable estimates (i.e. there were fewer than 30 students or fewer than 5 schools with valid data).
A41: m: Data are not available. There was no observation in the sample; these data were not collected by the country; or these data were collected but subsequently removed from the publication for technical reasons.
A42: w: Results were withdrawn at the request of the country concerned.
A44: OECD averages
A45: OECD average | B45: Arithmetic mean across all OECD countries.
A47: Note
A48: Information on data for Cyprus: https://oe.cd/cyprus-disclaimer

Sheet Table II.B1.5.1
A1: PISA 2018 Results (Volume II) - © OECD 2019
A2: Annex B1 | B2: Annex B1.5 Results (tables): How do schools compensate for socio-economic disadvantage?
A3: Version 2 - Last updated: 02-Dec-2019
A4: Disclaimer: http://oe.cd/disclaimer
A6: Table II.B1.5.1
A7: Variation in class size, by school characteristics
A8: Results based on school principals' reports about the average size of language-of-instruction classes in the modal grade for 15-year-olds
B11: All schools1 | N11: Average class size, by schools' socio-economic profile3 | X11: Average class size, by type of school
B12: Sample size | C12: Coverage2 | D12: Average class size | F12: Percentiles of class size | L12: Variability in class size across schools
L13: Inter-decile range | N13: Bottom quarter | P13: Second quarter | R13: Third quarter | T13: Top quarter | V13: Top - bottom quarter | X13: Public | Z13: Private government-dependent | AB13: Private independent | AD13: Private-Public4
B14: Number of schools | C14: % | D14: Mean | E14: S.E. | F14: 10th | G14: S.E. | H14: Median (50th) | I14: S.E. | J14: 90th | K14: S.E. | L14: I.D.R. | M14: S.E. | N14: Mean | O14: S.E. | P14: Mean | Q14: S.E. | R14: Mean | S14: S.E. | T14: Mean | U14: S.E. | V14: Dif. | W14: S.E. | X14: Mean | Y14: S.E. | Z14: Mean | AA14: S.E. | AB14: Mean | AC14: S.E. | AD14: Dif. | AE14: S.E.
A15: OECD
A16: Australia | B16: 682 | C16: 89.932747 | D16: 24.737923 | E16: 0.13100152 | F16: 23 | G16: c | H16: 23 | I16: c | J16: 28 | K16: c | L16: 5 | M16: c | N16: 24.174745 | O16: 0.28862537 | P16: 24.896906 | Q16: 0.29449085 | R16: 25.220017 | S16: 0.27490218 | T16: 24.691323 | U16: 0.34625546 | V16: 0.51657748 | W16: 0.42794395 | X16: 25.006431 | Y16: 0.15371508 | Z16: 24.998941 | AA16: 0.29603445 | AB16: 23.320567 | AC16: 0.35276683 | AD16: -0.65467239 | AE16: 0.29855771
A17: Austria | B17: 291 | C17: m | D17: 22.751294 | E17: 0.2610282 | F17: 18 | G17: c | H17: 23 | I17: c | J17: 28 | K17: c | L17: 10 | M17: c | N17: m | O17: m | P17: m | Q17: m | R17: m | S17: m | T17: m | U17: m | V17: m | W17: m | X17: m | Y17: m | Z17: m | AA17: m | AB17: m | AC17: m | AD17: m | AE17: m
A18: Belgium | B18: 256 | C18: 92.785469 | D18: 19.967083 | E18: 0.17813591 | F18: 13 | G18: 5 | H18: 18 | I18: c | J18: 23 | K18: c | L18: 10 | M18: 5 | N18: 18.475904 | O18: 0.45209576 | P18: 18.536819 | Q18: 0.52940102 | R18: 20.752513 | S18: 0.43961382 | T18: 22.065084 | U18: 0.30591899 | V18: 3.5891799 | W18: 0.53631381 | X18: m | Y18: m | Z18: m | AA18: m | AB18: m | AC18: m | AD18: m | AE18: m
A19: Canada | B19: 768 | C19: 96.37516 | D19: 27.290003 | E19: 0.17613191 | F19: 23 | G19: c | H19: 28 | I19: c | J19: 33 | K19: c | L19: 10 | M19: c | N19: 27.011712 | O19: 0.47013382 | P19: 26.473643 | Q19: 0.39420006 | R19: 27.71432 | S19: 0.41743124 | T19: 28.039091 | U19: 0.35532432 | V19: 1.0273792 | W19: 0.61082676 | X19: 27.30925 | Y19: 0.18958729 | Z19: 27.955852 | AA19: 0.71681133 | AB19: 26.577245 | AC19: 0.92118294 | AD19: -0.193594 | AE19: 0.64574788
A20: Chile | B20: 196 | C20: 83.04335 | D20: 35.011507 | E20: 0.47315179 | F20: 23 | G20: 4.0311289 | H20: 38 | I20: 4.1833001 | J20: 43 | K20: c | L20: 20 | M20: 4.0311289 | N20: 33.113674 | O20: 1.1940445 | P20: 35.026476 | Q20: 1.2002688 | R20: 36.976323 | S20: 1.2438479 | T20: 34.92516 | U20: 0.70937639 | V20: 1.8114857 | W20: 1.3656368 | X20: 33.805494 | Y20: 0.86020631 | Z20: 36.803814 | AA20: 0.71880869 | AB20: 31.152963 | AC20: 1.0129985 | AD20: 1.7856881 | AE20: 1.0779412
A21: Colombia | B21: 244 | C21: 98.509407 | D21: 37.87766 | E21: 0.7730026 | F21: 23 | G21: c | H21: 38 | I21: c | J21: 53 | K21: c | L21: 30 | M21: c | N21: 35.335887 | O21: 1.9789238 | P21: 39.520493 | Q21: 2.1515347 | R21: 39.378064 | S21: 1.7371289 | T21: 37.23668 | U21: 1.5564736 | V21: 1.9007923 | W21: 2.6248757 | X21: 38.609963 | Y21: 0.84933164 | Z21: m | AA21: m | AB21: 34.484517 | AC21: 1.7743172 | AD21: -4.1254455 | AE21: 2.0075249
A22: Czech Republic | B22: 326 | C22: 97.663795 | D22: 24.050527 | E22: 0.26377735 | F22: 18 | G22: c | H22: 23 | I22: c | J22: 28 | K22: c | L22: 10 | M22: c | N22: 21.208101 | O22: 0.61518789 | P22: 23.754017 | Q22: 0.66256788 | R22: 24.906759 | S22: 0.60008503 | T22: 26.340382 | U22: 0.52933658 | V22: 5.1322804 | W22: 0.85166012 | X22: 24.092619 | Y22: 0.25494814 | Z22: 25.120355 | AA22: 1.3203688 | AB22: m | AC22: m | AD22: 1.0277361 | AE22: 1.3610925
A23: Denmark | B23: 254 | C23: 76.070045 | D23: 21.357966 | E23: 0.21395295 | F23: 18 | G23: c | H23: 23 | I23: c | J23: 23 | K23: c | L23: 5 | M23: c | N23: 20.438201 | O23: 0.43815539 | P23: 20.648137 | Q23: 0.51607824 | R23: 22.056864 | S23: 0.50779017 | T23: 22.308698 | U23: 0.40914149 | V23: 1.870497 | W23: 0.58776103 | X23: 21.513979 | Y23: 0.25123892 | Z23: 21.070425 | AA23: 0.53406618 | AB23: 20.351323 | AC23: 1.0976537 | AD23: -0.60189825 | AE23: 0.53015095
A24: Estonia | B24: 224 | C24: 99.549774 | D24: 22.592311 | E24: 0.18591395 | F24: 13 | G24: c | H24: 23 | I24: c | J24: 28 | K24: c | L24: 15 | M24: c | N24: 19.031041 | O24: 0.51476052 | P24: 22.524487 | Q24: 0.74375785 | R24: 24.44244 | S24: 0.50166263 | T24: 24.465158 | U24: 0.47697164 | V24: 5.4341169 | W24: 0.70479179 | X24: 22.605473 | Y24: 0.18401533 | Z24: 24.180913 | AA24: 1.4335611 | AB24: 19.58247 | AC24: 2.250421 | AD24: -0.33272582 | AE24: 1.0921545
A25: Finland | B25: 210 | C25: 99.331734 | D25: 19.599562 | E25: 0.20502562 | F25: 18 | G25: c | H25: 18 | I25: c | J25: 23 | K25: c | L25: 5 | M25: c | N25: 18.00987 | O25: 0.35866684 | P25: 18.777465 | Q25: 0.48041475 | R25: 20.935682 | S25: 0.47566558 | T25: 20.687716 | U25: 0.52338285 | V25: 2.6778461 | W25: 0.65179787 | X25: 19.464773 | Y25: 0.18602767 | Z25: 22.833024 | AA25: 1.7768748 | AB25: m | AC25: m | AD25: 3.3682503 | AE25: 1.7520892
A26: France | B26: 164 | C26: 76.747353 | D26: 30.51477 | E26: 0.31239274 | F26: 23 | G26: c | H26: 33 | I26: c | J26: 33 | K26: c | L26: 10 | M26: c | N26: 27.798291 | O26: 0.68126384 | P26: 29.998474 | Q26: 0.84983066 | R26: 31.328101 | S26: 0.73705842 | T26: 33.01667 | U26: 0.44698174 | V26: 5.2183783 | W26: 0.81362009 | X26: 30.979694 | Y26: 0.30474135 | Z26: 25.355023 | AA26: 1.4914856 | AB26: 33.096163 | AC26: 0.86648886 | AD26: -1.90374 | AE26: 0.93622167
A27: Germany | B27: 185 | C27: 82.236961 | D27: 24.974321 | E27: 0.30156709 | F27: 18 | G27: c | H27: 28 | I27: 2.5 | J27: 28 | K27: c | L27: 10 | M27: c | N27: 22.087327 | O27: 0.82573805 | P27: 24.981336 | Q27: 0.7037513 | R27: 26.131362 | S27: 0.58538701 | T27: 26.882465 | U27: 0.25537966 | V27: 4.7951385 | W27: 0.87868168 | X27: 24.830469 | Y27: 0.27208921 | Z27: 24.72986 | AA27: 1.9153239 | AB27: m | AC27: m | AD27: -0.10060885 | AE27: 1.918829
A28: Greece | B28: 204 | C28: 94.527107 | D28: 23.032886 | E28: 0.24807376 | F28: 18 | G28: c | H28: 23 | I28: c | J28: 28 | K28: c | L28: 10 | M28: c | N28: 21.694229 | O28: 0.59145233 | P28: 22.493167 | Q28: 0.63256916 | R28: 24.395369 | S28: 0.49658407 | T28: 23.566547 | U28: 0.51583318 | V28: 1.8723185 | W28: 0.75961765 | X28: 23.063452 | Y28: 0.24945038 | Z28: m | AA28: m | AB28: 22.904998 | AC28: 1.1345372 | AD28: -0.15845398 | AE28: 1.1651252
A29: Hungary | B29: 161 | C29: 89.597336 | D29: 28.287476 | E29: 0.78097549 | F29: 18 | G29: 2.236068 | H29: 28 | I29: c | J29: 38 | K29: 12.845233 | L29: 20 | M29: 13.601471 | N29: 21.594461 | O29: 0.95439638 | P29: 29.873513 | Q29: 2.0238967 | R29: 30.85121 | S29: 1.7620982 | T29: 30.947984 | U29: 1.423088 | V29: 9.3535227 | W29: 1.7746386 | X29: 28.433993 | Y29: 0.98993448 | Z29: 27.927504 | AA29: 1.0655206 | AB29: m | AC29: m | AD29: -0.50648844 | AE29: 1.5337475
A30: Iceland | B30: 130 | C30: 98.915398 | D30: 18.857234 | E30: 0.018279291 | F30: 13 | G30: c | H30: 18 | I30: c | J30: 23 | K30: c | L30: 10 | M30: c | N30: 16.743475 | O30: 0.044350602 | P30: 18.737904 | Q30: 0.032272177 | R30: 19.103982 | S30: 0.030583872 | T30: 20.8712 | U30: 0.031424868 | V30: 4.127725 | W30: 0.060333552 | X30: 18.895073 | Y30: 0.01882948 | Z30: m | AA30: m | AB30: m | AC30: m | AD30: m | AE30: m
A31: Ireland | B31: 156 | C31: 99.289833 | D31: 24.1139 | E31: 0.2620777 | F31: 18 | G31: c | H31: 23 | I31: c | J31: 28 | K31: c | L31: 10 | M31: c | N31: 21.796399 | O31: 0.74703949 | P31: 25.00046 | Q31: 0.82761177 | R31: 24.643605 | S31: 0.66898236 | T31: 24.951591 | U31: 0.60971246 | V31: 3.1551918 | W31: 1.0451081 | X31: m | Y31: m | Z31: m | AA31: m | AB31: m | AC31: m | AD31: m | AE31: m
A32: Israel | B32: 160 | C32: 93.672966 | D32: 29.806965 | E32: 0.35895856 | F32: 23 | G32: c | H32: 28 | I32: 4.0311289 | J32: 38 | K32: c | L32: 15 | M32: c | N32: 25.799084 | O32: 0.87221043 | P32: 29.682068 | Q32: 1.0597959 | R32: 31.380009 | S32: 0.86045933 | T32: 32.318863 | U32: 0.8551801 | V32: 6.5197798 | W32: 1.2228264 | X32: 29.806965 | Y32: 0.35895856 | Z32: m | AA32: m | AB32: m | AC32: m | AD32: m | AE32: m
A33: Italy | B33: 488 | C33: 94.727379 | D33: 22.915658 | E33: 0.32705112 | F33: 18 | G33: c | H33: 23 | I33: c | J33: 28 | K33: c | L33: 10 | M33: c | N33: 21.513852 | O33: 0.67024781 | P33: 22.813164 | Q33: 0.81349526 | R33: 23.412634 | S33: 0.51600679 | T33: 23.950449 | U33: 0.78105018 | V33: 2.4365972 | W33: 1.0333063 | X33: 22.796209 | Y33: 0.29353799 | Z33: 22.733325 | AA33: 0.41534928 | AB33: 29.910789 | AC33: 7.1318923 | AD33: 4.163521 | AE33: 4.7792806
A34: Japan | B34: 183 | C34: 100 | D34: 35.125266 | E34: 0.45425272 | F34: 23 | G34: 6.0207973 | H34: 38 | I34: c | J34: 43 | K34: 4.0311289 | L34: 20 | M34: 8.2158384 | N34: 31.302484 | O34: 1.2811775 | P34: 35.601621 | Q34: 0.66647081 | R34: 36.450631 | S34: 0.98811036 | T34: 37.042789 | U34: 0.80323075 | V34: 5.7403057 | W34: 1.4271166 | X34: 34.946505 | Y34: 0.5699296 | Z34: 34.543572 | AA34: 2.1312054 | AB34: 35.589308 | AC34: 0.83297215 | AD34: 0.53032392 | AE34: 0.9552243
A35: Korea | B35: 153 | C35: 83.323898 | D35: 25.813315 | E35: 0.34018498 | F35: 18 | G35: 2.9580399 | H35: 28 | I35: 2.7386128 | J35: 33 | K35: 1.118034 | L35: 15 | M35: 3.5355339 | N35: 23.658619 | O35: 0.93640552 | P35: 25.291761 | Q35: 0.88183143 | R35: 27.158179 | S35: 1.1210133 | T35: 27.078249 | U35: 0.85886781 | V35: 3.4196301 | W35: 1.1919512 | X35: 25.86524 | Y35: 0.4767935 | Z35: 25.03282 | AA35: 0.58255416 | AB35: 29.893704 | AC35: 1.8125075 | AD35: -0.12183622 | AE35: 0.83807718
A36: Latvia | B36: 292 | C36: 95.217674 | D36: 22.583775 | E36: 0.2547633 | F36: 13 | G36: c | H36: 23 | I36: c | J36: 33 | K36: 1.118034 | L36: 20 | M36: 1.118034 | N36: 17.517863 | O36: 0.49735782 | P36: 22.2259 | Q36: 0.58769853 | R36: 23.605167 | S36: 0.75505338 | T36: 27.109012 | U36: 0.34964874 | V36: 9.5911488 | W36: 0.57658681 | X36: 22.708048 | Y36: 0.25770605 | Z36: m | AA36: m | AB36: m | AC36: m | AD36: m | AE36: m
A37: Lithuania | B37: 362 | C37: 100 | D37: 23.709073 | E37: 0.18753298 | F37: 13 | G37: c | H37: 23 | I37: c | J37: 28 | K37: c | L37: 15 | M37: c | N37: 19.744458 | O37: 0.54477515 | P37: 22.690606 | Q37: 0.54743701 | R37: 25.784812 | S37: 0.45712265 | T37: 26.576515 | U37: 0.20615759 | V37: 6.8320572 | W37: 0.58436977 | X37: 23.675706 | Y37: 0.19466542 | Z37: 24.475884 | AA37: 0.57099611 | AB37: m | AC37: m | AD37: 0.8001785 | AE37: 0.59696815
A38: Luxembourg | B38: 41 | C38: 90.241196 | D38: 22.333845 | E38: 0.005840203 | F38: 18 | G38: c | H38: 23 | I38: c | J38: 23 | K38: c | L38: 5 | M38: c | N38: 21.737207 | O38: 0.0087004749 | P38: 22.816219 | Q38: 0.011163642 | R38: 22.162009 | S38: 0.013417391 | T38: 22.653753 | U38: 0.010978509 | V38: 0.91654579 | W38: 0.013428481 | X38: 22.373795 | Y38: 0.0053104892 | Z38: 23.641953 | AA38: 0.026672857 | AB38: m | AC38: m | AD38: 1.268158 | AE38: 0.027394536
A39: Mexico | B39: 207 | C39: 77.499275 | D39: 43.864532 | E39: 0.52673257 | F39: 28 | G39: c | H39: 48 | I39: c | J39: 53 | K39: c | L39: 25 | M39: c | N39: 40.51502 | O39: 1.4296585 | P39: 46.418857 | Q39: 1.2890777 | R39: 46.873299 | S39: 1.7190038 | T39: 41.750318 | U39: 1.5983486 | V39: 1.2352981 | W39: 1.9580076 | X39: 44.772797 | Y39: 0.5145556 | Z39: m | AA39: m | AB39: 37.77892 | AC39: 2.4217768 | AD39: -6.9938772 | AE39: 2.4882512
A40: Netherlands* | B40: 145 | C40: 93.512642 | D40: 24.91222 | E40: 0.22571892 | F40: 18 | G40: 2.9580399 | H40: 28 | I40: 1.118034 | J40: 28 | K40: c | L40: 10 | M40: 2.9580399 | N40: 21.113785 | O40: 0.55723251 | P40: 24.667964 | Q40: 0.59670133 | R40: 27.033897 | S40: 0.402342 | T40: 26.793665 | U40: 0.45877174 | V40: 5.6798802 | W40: 0.71666913 | X40: 25.223141 | Y40: 0.44409939 | Z40: 24.995853 | AA40: 0.3209023 | AB40: m | AC40: m | AD40: -0.22728761 | AE40: 0.60317026
A41: New Zealand | B41: 181 | C41: 94.84259 | D41: 25.075563 | E41: 0.31022917 | F41: 18 | G41: c | H41: 23 | I41: 4.0311289 | J41: 28 | K41: c | L41: 10 | M41: c | N41: 23.409789 | O41: 0.53992447 | P41: 25.71051 | Q41: 0.82451721 | R41: 26.380453 | S41: 0.8897537 | T41: 24.77301 | U41: 0.45951646 | V41: 1.3632207 | W41: 0.76006043 | X41: 25.360144 | Y41: 0.31952948 | Z41: m | AA41: m | AB41: 20.705558 | AC41: 0.74264912 | AD41: -4.6545859 | AE41: 0.79413645
A42: Norway | B42: 243 | C42: 97.620384 | D42: 23.800096 | E42: 0.20699119 | F42: 18 | G42: c | H42: 23 | I42: c | J42: 28 | K42: c | L42: 10 | M42: c | N42: 21.631547 | O42: 0.56610248 | P42: 23.659502 | Q42: 0.57895832 | R42: 24.470882 | S42: 0.68213653 | T42: 25.469835 | U42: 0.53660861 | V42: 3.8382882 | W42: 0.88478513 | X42: w | Y42: w | Z42: w | AA42: w | AB42: w | AC42: w | AD42: w | AE42: w
A43: Poland | B43: 229 | C43: 98.568817 | D43: 24.356363 | E43: 0.48311814 | F43: 18 | G43: c | H43: 23 | I43: c | J43: 28 | K43: c | L43: 10 | M43: c | N43: 22.510626 | O43: 0.92131417 | P43: 23.523857 | Q43: 1.249557 | R43: 25.706755 | S43: 1.0963778 | T43: 25.686912 | U43: 0.89106686 | V43: 3.1762857 | W43: 1.2209455 | X43: 24.519978 | Y43: 0.48719092 | Z43: 19.008554 | AA43: 1.2286166 | AB43: m | AC43: m | AD43: -5.5114241 | AE43: 1.3015829
...

Sheet Table II.B1.5.2
A1: PISA 2018 Results (Volume II) - © OECD 2019
A2: Annex B1 | B2: Annex B1.5 Results (tables): How do schools compensate for socio-economic disadvantage?
A3: Version 2 - Last updated: 02-Dec-2019
A4: Disclaimer: http://oe.cd/disclaimer
A6: Table II.B1.5.2
A7: Student-teacher ratio, by school characteristics
A8: Results based on principals' reports
B12: All schools1 | G12: Number of students per teacher, by schools' socio-economic profile4 | Q12: Number of students per teacher, by type of school
B13: Sample size | D13: Coverage2 | E13: Overall number of students per teacher3 | G13: Bottom quarter | I13: Second quarter | K13: Third quarter | M13: Top quarter | O13: Top - bottom quarter | Q13: Public | S13: Private government-dependent | U13: Private independent | W13: Private-Public5
B14: Number of teachers | C14: Number of schools | D14: % | E14: Ratio | F14: S.E. | G14: Ratio | H14: S.E. | I14: Ratio | J14: S.E. | K14: Ratio | L14: S.E. | M14: Ratio | N14: S.E. | O14: Dif. | P14: S.E. | Q14: Ratio | R14: S.E. | S14: Ratio | T14: S.E. | U14: Ratio | V14: S.E. | W14: Dif. | X14: S.E.
A15: OECD
A16: Australia | B16: 46214 | C16: 596 | D16: 78.766449 | E16: 12.808252 | F16: 0.31006516 | G16: 11.861669 | H16: 0.24272689 | I16: 13.116003 | J16: 0.23951434 | K16: 12.569429 | L16: 0.38463119 | M16: 13.56737 | N16: 1.0275278 | O16: 1.705701 | P16: 1.0481935 | Q16: 12.900625 | R16: 0.16877976 | S16: 13.012406 | T16: 0.24943573 | U16: 12.262633 | V16: 1.4179255 | W16: -0.21067788 | X16: 0.64803572
A17: Austria | B17: 13477.5 | C17: 291 | D17: m | E17: m | F17: m | G17: m | H17: m | I17: m | J17: m | K17: m | L17: m | M17: m | N17: m | O17: m | P17: m | Q17: m | R17: m | S17: m | T17: m | U17: m | V17: m | W17: m | X17: m
A18: Belgium | B18: 20661.5 | C18: 224 | D18: 80.128441 | E18: 8.3407494 | F18: 0.23674891 | G18: 7.345378 | H18: 0.26262024 | I18: 7.4413007 | J18: 0.52513094 | K18: 9.1820646 | L18: 0.44742224 | M18: 10.583079 | N18: 0.58925122 | O18: 3.2377015 | P18: 0.64304731 | Q18: m | R18: m | S18: m | T18: m | U18: m | V18: m | W18: m | X18: m
A19: Canada | B19: 30429 | C19: 575 | D19: 74.78508 | E19: 14.616875 | F19: 0.16029603 | G19: 13.617841 | H19: 0.34749081 | I19: 15.25632 | J19: 0.18494256 | K19: 15.757064 | L19: 0.27679826 | M19: 14.379037 | N19: 0.50268951 | O19: 0.76119637 | P19: 0.6836687 | Q19: 14.878266 | R19: 0.15249285 | S19: 15.30122 | T19: 0.90739573 | U19: 11.883426 | V19: 0.75909469 | W19: -2.0626387 | X19: 0.65754765
A20: Chile | B20: 7383 | C20: 135 | D20: 57.024799 | E20: 18.85911 | F20: 0.69259546 | G20: 15.409988 | H20: 1.0508528 | I20: 20.980517 | J20: 2.7555982 | K20: 19.094566 | L20: 1.0243371 | M20: 19.685936 | N20: 1.0792147 | O20: 4.2759481 | P20: 1.4814879 | Q20: 13.928932 | R20: 0.55248721 | S20: 22.454722 | T20: 1.2756944 | U20: 15.563265 | V20: 0.79590124 | W20: 6.4238523 | X20: 0.98648581
A21: Colombia | B21: 13463 | C21: 241 | D21: 96.856422 | E21: 22.744306 | F21: 0.81149516 | G21: 21.963309 | H21: 1.177226 | I21: 23.087401 | J21: 1.1777589 | K21: 27.066381 | L21: 1.2072825 | M21: 18.400689 | N21: 0.87439874 | O21: -3.5626192 | P21: 1.4207308 | Q21: 24.091655 | R21: 0.94635225 | S21: m | T21: m | U21: 16.364215 | V21: 0.73270113 | W21: -7.7274392 | X21: 1.1074493
A22: Czech Republic | B22: 11324.5 | C22: 311 | D22: 92.462929 | E22: 12.323228 | F22: 0.3198545 | G22: 11.619522 | H22: 0.42338806 | I22: 13.866954 | J22: 0.47512462 | K22: 12.982969 | L22: 0.71892983 | M22: 11.339711 | N22: 0.90404565 | O22: -0.27981076 | P22: 1.0037434 | Q22: 12.471461 | R22: 0.33371318 | S22: 11.14841 | T22: 0.81238313 | U22: m | V22: m | W22: -1.3230513 | X22: 0.86829036
A23: Denmark | B23: 8955 | C23: 212 | D23: 65.478149 | E23: 12.377795 | F23: 0.44508289 | G23: 10.652465 | H23: 0.52679472 | I23: 13.134783 | J23: 0.62749343 | K23: 14.055447 | L23: 0.48343825 | M23: 12.295832 | N23: 1.3912356 | O23: 1.6433669 | P23: 1.493565 | Q23: 12.289723 | R23: 0.53880765 | S23: 13.99717 | T23: 0.63466339 | U23: 6.9301633 | V23: 1.0987751 | W23: 0.36289717 | X23: 0.95962835
A24: Estonia | B24: 9219 | C24: 224 | D24: 99.549774 | E24: 11.604146 | F24: 0.13850558 | G24: 9.42376 | H24: 0.28057842 | I24: 10.999646 | J24: 0.3329721 | K24: 13.577988 | L24: 0.24245883 | M24: 12.993747 | N24: 0.31115666 | O24: 3.5699873 | P24: 0.40591321 | Q24: 11.732818 | R24: 0.12460611 | S24: 10.540372 | T24: 1.4406285 | U24: 7.6782845 | V24: 1.0270935 | W24: -2.5947292 | X24: 0.89641041
A25: Finland | B25: 7698.5 | C25: 177 | D25: 85.729897 | E25: 10.668735 | F25: 0.23782507 | G25: 10.433956 | H25: 0.33748092 | I25: 10.609031 | J25: 0.43127722 | K25: 11.345085 | L25: 0.37549032 | M25: 10.432849 | N25: 0.67040237 | O25: -0.0011061346 | P25: 0.75039483 | Q25: 10.616651 | R25: 0.21135942 | S25: 11.441217 | T25: 1.576707 | U25: m | V25: m | W25: 0.82456643 | X25: 1.5586501
A26: France | B26: 15510 | C26: 151 | D26: 70.429939 | E26: 10.557089 | F26: 0.28366946 | G26: 10.083539 | H26: 0.37390192 | I26: 10.035727 | J26: 0.61794848 | K26: 10.666394 | L26: 0.4944366 | M26: 11.716632 | N26: 0.73391809 | O26: 1.6330931 | P26: 0.82392205 | Q26: 10.484848 | R26: 0.29778359 | S26: 10.265355 | T26: 0.84623151 | U26: 10.506756 | V26: 1.4153812 | W26: -0.1271826 | X26: 0.79165023
A27: Germany | B27: 9393 | C27: 177 | D27: 78.697334 | E27: 13.863464 | F27: 0.3160293 | G27: 14.348154 | H27: 0.70986065 | I27: 14.819557 | J27: 0.8530061 | K27: 13.196582 | L27: 0.57996456 | M27: 12.815289 | N27: 0.35360538 | O27: -1.5328651 | P27: 0.82394203 | Q27: 13.900852 | R27: 0.34813749 | S27: 12.345586 | T27: 1.5446747 | U27: m | V27: m | W27: -1.555266 | X27: 1.7068023
A28: Greece | B28: 5672.5 | C28: 180 | D28: 82.492142 | E28: 8.4936013 | F28: 0.2753181 | G28: 7.2925516 | H28: 0.64358849 | I28: 9.2420613 | J28: 0.33387953 | K28: 10.17317 | L28: 0.40730669 | M28: 8.5005952 | N28: 0.46961037 | O28: 1.2080436 | P28: 0.7861803 | Q28: 8.6986939 | R28: 0.29362818 | S28: m | T28: m | U28: 6.5554658 | V28: 0.35568361 | W28: -2.1432281 | X28: 0.45864612
A29: Hungary | B29: 9640 | C29: 147 | D29: 81.9795 | E29: 10.138571 | F29: 0.23190335 | G29: 9.5779893 | H29: 0.66934342 | I29: 9.5429323 | J29: 0.61977064 | K29: 10.429157 | L29: 0.44775492 | M29: 10.893492 | N29: 0.39721343 | O29: 1.3155024 | P29: 0.77791333 | Q29: 10.188001 | R29: 0.3144255 | S29: 10.174565 | T29: 0.41820069 | U29: m | V29: m | W29: -0.013435607 | X29: 0.57037801
A30: Iceland | B30: 3440 | C30: 114 | D30: 84.909386 | E30: 10.010366 | F30: 0.019370494 | G30: 9.0990672 | H30: 0.041198388 | I30: 10.486182 | J30: 0.011050853 | K30: 9.9351235 | L30: 0.038840545 | M30: 11.423874 | N30: c | O30: 2.3248068 | P30: 0.041198388 | Q30: 10.017292 | R30: 0.019448699 | S30: m | T30: m | U30: m | V30: m | W30: m | X30: m
A31: Ireland | B31: 6478.5 | C31: 127 | D31: 81.618851 | E31: 12.404253 | F31: 0.20844359 | G31: 10.433709 | H31: 0.46613143 | I31: 13.186219 | J31: 0.19738104 | K31: 13.726092 | L31: 0.2468113 | M31: 13.211513 | N31: 0.28918801 | O31: 2.777804 | P31: 0.54685832 | Q31: m | R31: m | S31: m | T31: m | U31: m | V31: m | W31: m | X31: m
A32: Israel | B32: 10092.5 | C32: 144 | D32: 84.238327 | E32: 9.8165482 | F32: 0.23231933 | G32: 8.9083708 | H32: 0.48424336 | I32: 9.9402793 | J32: 0.58240827 | K32: 10.881156 | L32: 0.42844719 | M32: 9.6843178 | N32: 0.39254833 | O32: 0.77594693 | P32: 0.60525128 | Q32: 9.8165482 | R32: 0.23231933 | S32: m | T32: m | U32: m | V32: m | W32: m | X32: m
A33: Italy | B33: 43774 | C33: 427 | D33: 82.103226 | E33: 7.9867908 | F33: 0.19617102 | G33: 6.6196107 | H33: 0.22953846 | I33: 7.4377403 | J33: 0.41222235 | K33: 8.9425955 | L33: 0.39358338 | M33: 10.513731 | N33: 0.568744 | O33: 3.8941204 | P33: 0.63588369 | Q33: 7.8553606 | R33: 0.18702764 | S33: 10.64956 | T33: 0.53928129 | U33: 10.893498 | V33: 2.4030999 | W33: 2.9708221 | X33: 1.7058482
A34: Japan | B34: 11435 | C34: 183 | D34: 100 | E34: 8.6251228 | F34: 0.36765057 | G34: 6.6672372 | H34: 0.87485231 | I34: 8.4674598 | J34: 1.2180424 | K34: 10.85957 | L34: 1.3564629 | M34: 9.6416126 | N34: 1.162306 | O34: 2.9743754 | P34: 1.4429427 | Q34: 9.0815269 | R34: 0.31883439 | S34: 11.470067 | T34: 2.6003916 | U34: 7.5223436 | V34: 0.77650149 | W34: -1.2414988 | X34: 0.79628071
A35: Korea | B35: 8736.5 | C35: 126 | D35: 69.099594 | E35: 12.379539 | F35: 0.27764682 | G35: 10.764269 | H35: 0.56548758 | I35: 12.489835 | J35: 0.46451273 | K35: 13.888211 | L35: 0.44318718 | M35: 12.986751 | N35: 0.90127615 | O35: 2.222482 | P35: 1.0638789 | Q35: 11.903808 | R35: 0.4256018 | S35: 12.747518 | T35: 0.46542503 | U35: 15.996121 | V35: 1.2089897 | W35: 1.2023617 | X35: 0.69614601
A36: Latvia | B36: 11985 | C36: 275 | D36: 89.13089 | E36: 9.8176649 | F36: 0.17469947 | G36: 8.1016531 | H36: 0.22600497 | I36: 10.396692 | J36: 0.30398412 | K36: 11.092826 | L36: 0.44971833 | M36: 10.331973 | N36: 0.47931531 | O36: 2.23032 | P36: 0.53061192 | Q36: 10.027977 | R36: 0.13659773 | S36: m | T36: m | U36: m | V36: m | W36: m | X36: m
A37: Lithuania | B37: 14979 | C37: 362 | D37: 100 | E37: 9.8667266 | F37: 0.24798326 | G37: 8.934607 | H37: 0.36691138 | I37: 10.410305 | J37: 0.55510838 | K37: 10.717154 | L37: 0.34910138 | M37: 10.684452 | N37: 0.7338733 | O37: 1.7498448 | P37: 0.75458526 | Q37: 9.8424751 | R37: 0.25321179 | S37: 10.736211 | T37: 1.2764843 | U37: m | V37: m | W37: 0.89373633 | X37: 1.2715116
A38: Luxembourg | B38: 4914 | C38: 39 | D38: 88.64315 | E38: 8.9989566 | F38: c | G38: 9.3031674 | H38: c | I38: 8.661865 | J38: c | K38: 8.4850829 | L38: c | M38: 9.4066023 | N38: c | O38: 0.10343483 | P38: c | Q38: 8.9125676 | R38: c | S38: 9.9623318 | T38: c | U38: m | V38: m | W38: 1.0497642 | X38: c
A39: Mexico | B39: 8688 | C39: 165 | D39: 63.440716 | E39: 25.787449 | F39: 1.5669014 | G39: 24.107633 | H39: 2.3961902 | I39: 31.079748 | J39: 2.2571674 | K39: 26.536647 | L39: 2.8029744 | M39: 22.642663 | N39: 3.4319988 | O39: -1.4649708 | P39: 4.2351404 | Q39: 29.831867 | R39: 2.1468188 | S39: m | T39: m | U39: 14.446542 | V39: 1.1335294 | W39: -15.385324 | X39: 2.427769
A40: Netherlands* | B40: 8355 | C40: 133 | D40: 86.277153 | E40: 16.73023 | F40: 0.53747779 | G40: 14.000941 | H40: 0.55245328 | I40: 15.266046 | J40: 1.0030673 | K40: 18.388237 | L40: 1.4985103 | M40: 19.398419 | N40: 0.52679627 | O40: 5.3974774 | P40: 0.72874473 | Q40: 17.335897 | R40: 0.76516553 | S40: 16.468186 | T40: 0.72828628 | U40: m | V40: m | W40: -0.86771031 | X40: 1.0515748
A41: New Zealand | B41: 11789.5 | C41: 175 | D41: 90.98394 | E41: 13.802468 | F41: 0.22375647 | G41: 13.425227 | H41: 0.51784658 | I41: 13.725687 | J41: 0.41843568 | K41: 14.977755 | L41: 0.22458464 | M41: 13.35845 | N41: 0.52981706 | O41: -0.066776733 | P41: 0.77495152 | Q41: 14.121129 | R41: 0.20200134 | S41: m | T41: m | U41: 11.248006 | V41: 0.90955634 | W41: -2.8731233 | X41: 0.92904448
A42: Norway | B42: 7396 | C42: 230 | D42: 92.369698 | E42: 9.310519 | F42: 0.18576077 | G42: 8.5656577 | H42: 0.28434534 | I42: 9.1945549 | J42: 0.32224138 | K42: 10.048203 | L42: 0.51442952 | M42: 10.085777 | N42: 0.47825645 | O42: 1.5201194 | P42: 0.50472506 | Q42: w | R42: w | S42: w | T42: w | U42: w | V42: w | W42: w | X42: w
A43: Poland | B43: 10178 | C43: 229 | D43: 98.568817 | E43: 7.9385793 | F43: 0.22324525 | G43: 8.9592382 | H43: 0.23808737 | I43: 7.9446382 | J43: 0.43551196 | K43: 7.2847754 | L43: 0.61024459 | M43: 6.8189993 | N43: 0.52980119 | O43: -2.1402389 | P43: 0.55566486 | Q43: 8.0721481 | R43: 0.22921655 | S43: 4.5124518 | T43: 0.5938612 | U43: m | V43: m | W43: -3.5596963 | X43: 0.62784665
A44: Portugal* | B44: 29113.5 | C44: 179 | D44: 67.669884 | E44: 10.010535 | F44: 0.43414476 | G44: 9.4227229 | H44: 0.57606574 | I44: 8.8016494 | J44: 0.67567381 | K44: 9.2557113 | L44: 0.40965646 | M44: 12.776879 | N44: 1.1979383 | O44: 3.3541561 | P44: 1.3324282 | Q44: 9.2608743 | R44: 0.42409057 | S44: 11.387197 | T44: 1.0222198 | U44: 15.339322 | V44: 1.5009254 | W44: 4.2914927 | X44: 1.4242443
...

Sheet Table II.B1.5.3
A1: PISA 2018 Results (Volume II) - © OECD 2019
A2: Annex B1 | B2: Annex B1.5 Results (tables): How do schools compensate for socio-economic disadvantage?
A3: Version 2 - Last updated: 02-Dec-2019
A4: Disclaimer: http://oe.cd/disclaimer
A6: Table II.B1.5.3
A7: Fully certified teachers, by school characteristics
A8: Fully certified by the appropriate authority; results based on principals' reports
B12: All schools1 | G12: Proportion of fully certified teachers, by schools' socio-economic profile4 | Q12: Proportion of fully certified teachers, by type of school
B13: Sample size | D13: Coverage2 | E13: Overall proportion of fully certified teachers3 | G13: Bottom quarter | I13: Second quarter | K13: Third quarter | M13: Top quarter | O13: Top - bottom quarter | Q13: Public | S13: Private government-dependent | U13: Private independent | W13: Private-Public5
B14: Number of teachers | C14: Number of schools | D14: % | E14: % | F14: S.E. | G14: % | H14: S.E. | I14: % | J14: S.E. | K14: % | L14: S.E. | M14: % | N14: S.E. | O14: % dif. | P14: S.E. | Q14: % | R14: S.E. | S14: % | T14: S.E. | U14: % | V14: S.E. | W14: % dif. | X14: S.E.
A15: OECD
A16: Australia | B16: 39792 | C16: 506 | D16: 67.317924 | E16: 97.827087 | F16: 0.55627812 | G16: 97.225673 | H16: 0.93364358 | I16: 96.250189 | J16: 1.8594015 | K16: 97.863081 | L16: 1.1426462 | M16: 99.22096 | N16: 0.57085006 | O16: 1.9952864 | P16: 1.0866174 | Q16: 97.349287 | R16: 0.7640114 | S16: 98.141704 | T16: 1.0675932 | U16: 99.545435 | V16: 0.28416908 | W16: 1.3980633 | X16: 0.97200301
A17: Austria | B17: 10864 | C17: 291 | D17: m | E17: 92.323613 | F17: 2.020128 | G17: m | H17: m | I17: m | J17: m | K17: m | L17: m | M17: m | N17: m | O17: m | P17: m | Q17: m | R17: m | S17: m | T17: m | U17: m | V17: m | W17: m | X17: m
A18: Belgium | B18: 17834.5 | C18: 195 | D18: 69.305092 | E18: 89.66611 | F18: 1.7774072 | G18: 89.264056 | H18: 3.8156615 | I18: 90.07083 | J18: 2.7407102 | K18: 89.452628 | L18: 3.3111795 | M18: 89.886841 | N18: 5.6691286 | O18: 0.62278522 | P18: 7.1436312 | Q18: m | R18: m | S18: m | T18: m | U18: m | V18: m | W18: m | X18: m
A19: Canada | B19: 22452 | C19: 442 | D19: 58.412197 | E19: 96.472542 | F19: 1.1709867 | G19: 95.127047 | H19: 3.1313677 | I19: 97.086994 | J19: 2.0744714 | K19: 97.945433 | L19: 1.2011048 | M19: 96.067332 | N19: 2.114479 | O19: 0.94028483 | P19: 3.8798541 | Q19: 98.447432 | R19: 0.65062793 | S19: 97.188666 | T19: 1.7765509 | U19: 76.450922 | V19: 10.154338 | W19: -15.998051 | X19: 7.6838482
A20: Chile | B20: 5939 | C20: 107 | D20: 47.296906 | E20: 25.766479 | F20: 4.2357893 | G20: 30.175581 | H20: 10.832281 | I20: 16.606084 | J20: 5.8630101 | K20: 16.522924 | L20: 8.5265066 | M20: 36.17702 | N20: 7.8441934 | O20: 6.0014387 | P20: 13.767979 | Q20: 25.410055 | R20: 6.9142317 | S20: 21.283522 | T20: 6.3694636 | U20: 36.777197 | V20: 9.1493695 | W20: 0.47230624 | X20: 8.5639623
A21: Colombia | B21: 5791.5 | C21: 122 | D21: 48.036758 | E21: 72.895224 | F21: 4.327748 | G21: 77.777703 | H21: 8.3545552 | I21: 71.115628 | J21: 12.421494 | K21: 80.493428 | L21: 7.9139083 | M21: 62.440753 | N21: 6.3151597 | O21: -15.336951 | P21: 10.036977 | Q21: 76.925594 | R21: 5.5476295 | S21: m | T21: m | U21: 62.969483 | V21: 6.2027258 | W21: -13.956111 | X21: 8.4282811
A22: Czech Republic | B22: 10337 | C22: 284 | D22: 83.931358 | E22: 94.581319 | F22: 0.88681197 | G22: 91.50123 | H22: 2.0430519 | I22: 97.529123 | J22: 0.49735715 | K22: 96.418122 | L22: 0.76673986 | M22: 94.517318 | N22: 2.1365922 | O22: 3.0160883 | P22: 2.9483002 | Q22: 95.229094 | R22: 0.79433674 | S22: 82.088592 | T22: 8.0213844 | U22: m | V22: m | W22: -13.140501 | X22: 8.0514748
A23: Denmark | B23: m | C23: m | D23: m | E23: m | F23: m | G23: m | H23: m | I23: m | J23: m | K23: m | L23: m | M23: m | N23: m | O23: m | P23: m | Q23: m | R23: m | S23: m | T23: m | U23: m | V23: m | W23: m | X23: m
A24: Estonia | B24: 8230 | C24: 197 | D24: 88.773499 | E24: 89.425154 | F24: 0.90980967 | G24: 88.96299 | H24: 1.7257672 | I24: 90.345613 | J24: 2.0259516 | K24: 87.983237 | L24: 2.198988 | M24: 90.505092 | N24: 0.83264638 | O24: 1.5421022 | P24: 1.8901185 | Q24: 89.081613 | R24: 0.95361885 | S24: 95.455082 | T24: 1.4465836 | U24: 95.085317 | V24: 3.1532853 | W24: 6.1923023 | X24: 1.9013856
A25: Finland | B25: 5636.5 | C25: 133 | D25: 63.926308 | E25: 93.391956 | F25: 1.2209689 | G25: 91.01318 | H25: 3.5136781 | I25: 94.509263 | J25: 1.0373782 | K25: 94.886464 | L25: 1.9326248 | M25: 94.103859 | N25: 1.2841455 | O25: 3.0906787 | P25: 3.5710347 | Q25: 93.332847 | R25: 1.2863344 | S25: 94.098794 | T25: 3.5900386 | U25: m | V25: m | W25: 0.76594679 | X25: 3.8334184
A26: France | B26: 13905.5 | C26: 135 | D26: 63.497051 | E26: 71.794995 | F26: 3.2646268 | G26: 58.138849 | H26: 8.6755793 | I26: 62.548151 | J26: 6.7910106 | K26: 80.78824 | L26: 3.7805972 | M26: 87.257298 | N26: 4.4928823 | O26: 29.11845 | P26: 9.8599738 | Q26: 74.647682 | R26: 3.2195469 | S26: 52.005748 | T26: 13.275254 | U26: 79.053802 | V26: 10.070009 | W26: -12.005998 | X26: 9.4621942
A27: Germany | B27: 8681.5 | C27: 167 | D27: 75.171959 | E27: 90.343303 | F27: 2.199955 | G27: 93.915797 | H27: 2.0732477 | I27: 94.348291 | J27: 3.3964936 | K27: 88.082438 | L27: 4.9302652 | M27: 84.741589 | N27: 5.2382096 | O27: -9.1742078 | P27: 5.277903 | Q27: 90.210222 | R27: 2.2776941 | S27: 94.480513 | T27: 3.3453451 | U27: m | V27: m | W27: 4.2702903 | X27: 3.8887327
A28: Greece | B28: 4299.5 | C28: 143 | D28: 65.612923 | E28: 88.82971 | F28: 2.5706784 | G28: 86.693811 | H28: 5.4166059 | I28: 91.602325 | J28: 3.3424237 | K28: 92.24492 | L28: 4.7523742 | M28: 86.401033 | N28: 6.361564 | O28: -0.29277776 | P28: 8.4079421 | Q28: 89.208089 | R28: 2.5313776 | S28: m | T28: m | U28: 80.812448 | V28: 20.006071 | W28: -8.3956402 | X28: 19.992611
A29: Hungary | B29: m | C29: m | D29: m | E29: m | F29: m | G29: m | H29: m | I29: m | J29: m | K29: m | L29: m | M29: m | N29: m | O29: m | P29: m | Q29: m | R29: m | S29: m | T29: m | U29: m | V29: m | W29: m | X29: m
A30: Iceland | B30: 2481 | C30: 82 | D30: 64.67569 | E30: 89.517254 | F30: 0.043432277 | G30: 86.115474 | H30: 0.12384309 | I30: 87.141002 | J30: 0.030553664 | K30: 97.16503 | L30: c | M30: 93.258899 | N30: c | O30: 7.1434243 | P30: 0.12384309 | Q30: 89.483886 | R30: 0.043537597 | S30: m | T30: m | U30: m | V30: m | W30: m | X30: m
A31: Ireland | B31: 5239.5 | C31: 107 | D31: 68.323097 | E31: 99.778662 | F31: 0.06750194 | G31: 99.800062 | H31: 0.090239477 | I31: 99.847148 | J31: 0.10010367 | K31: 99.887166 | L31: 0.064659233 | M31: 99.550292 | N31: 0.24556769 | O31: -0.24977019 | P31: 0.25697008 | Q31: m | R31: m | S31: m | T31: m | U31: m | V31: m | W31: m | X31: m
A32: Israel | B32: 7508.5 | C32: 112 | D32: 65.445831 | E32: 72.130803 | F32: 3.8389932 | G32: 65.453988 | H32: 7.8144657 | I32: 79.369025 | J32: 6.9911112 | K32: 70.266199 | L32: 8.553857 | M32: 71.163163 | N32: 6.6486109 | O32: 5.7091746 | P32: 10.068717 | Q32: 72.130803 | R32: 3.8389932 | S32: m | T32: m | U32: m | V32: m | W32: m | X32: m
A33: Italy | B33: 34178 | C33: 337 | D33: 64.241783 | E33: 81.264483 | F33: 2.3733622 | G33: 79.819259 | H33: 3.4939898 | I33: 77.042405 | J33: 6.1398166 | K33: 87.347946 | L33: 1.5832555 | M33: 83.790618 | N33: 4.8609848 | O33: 3.9713595 | P33: 5.820398 | Q33: 82.267331 | R33: 2.40356 | S33: 21.256712 | T33: 7.8662714 | U33: 58.681676 | V33: 9.7978119 | W33: -34.513992 | X33: 12.595371
A34: Japan | B34: 11023 | C34: 179 | D34: 97.821442 | E34: 97.188773 | F34: 0.70200541 | G34: 95.044131 | H34: 1.8951419 | I34: 96.859512 | J34: 0.60829673 | K34: 98.592292 | L34: 0.67218581 | M34: 99.461406 | N34: 0.18474781 | O34: 4.4172753 | P34: 1.9078569 | Q34: 97.599827 | R34: 0.53493681 | S34: 99.067062 | T34: 0.50855627 | U34: 96.225324 | V34: 1.7632446 | W34: -1.1381048 | X34: 1.6785621
A35: Korea | B35: 7279 | C35: 105 | D35: 57.079472 | E35: 98.137596 | F35: 1.127945 | G35: 100 | H35: 1.0048592e-14 | I35: 96.568112 | J35: 3.2417023 | K35: 99.749316 | L35: 0.16545513 | M35: 96.646367 | N35: 2.728234 | O35: -3.3536326 | P35: 2.728234 | Q35: 98.43251 | R35: 1.4246255 | S35: 99.785411 | T35: 0.1176661 | U35: 81.13734 | V35: 15.218398 | W35: -0.72277276 | X35: 2.3285354
A36: Latvia | B36: m | C36: m | D36: m | E36: m | F36: m | G36: m | H36: m | I36: m | J36: m | K36: m | L36: m | M36: m | N36: m | O36: m | P36: m | Q36: m | R36: m | S36: m | T36: m | U36: m | V36: m | W36: m | X36: m
A37: Lithuania | B37: 14851 | C37: 360 | D37: 99.522125 | E37: 98.638137 | F37: 0.1728553 | G37: 98.074388 | H37: 0.37344558 | I37: 99.437467 | J37: 0.18955376 | K37: 98.532593 | L37: 0.19814845 | M37: 99.103764 | N37: 0.19330752 | O37: 1.0293758 | P37: 0.40681469 | Q37: 98.655591 | R37: 0.17682596 | S37: 97.403311 | T37: 1.8598342 | U37: m | V37: m | W37: -1.2522796 | X37: 1.8827179
A38: Luxembourg | B38: 3916.5 | C38: 32 | D38: 74.86763 | E38: 70.509383 | F38: c | G38: 57.466063 | H38: c | I38: 78.18854 | J38: c | K38: 62.432916 | L38: c | M38: 84.728805 | N38: c | O38: 27.262741 | P38: c | Q38: 67.983589 | R38: c | S38: 72.95082 | T38: c | U38: m | V38: m | W38: 4.9672306 | X38: c
A39: Mexico | B39: 7507.5 | C39: 135 | D39: 51.550671 | E39: 37.913414 | F39: 4.4203972 | G39: 51.012543 | H39: 12.1095 | I39: 25.563424 | J39: 5.5790613 | K39: 28.753839 | L39: 5.0726323 | M39: 48.306908 | N39: 9.0544222 | O39: -2.7056343 | P39: 14.487773 | Q39: 32.201078 | R39: 4.0159618 | S39: m | T39: m | U39: 56.132488 | V39: 10.577563 | W39: 23.93141 | X39: 11.445531
A40: Netherlands* | B40: 7866.5 | C40: 125 | D40: 81.718971 | E40: 89.448749 | F40: 1.440934 | G40: 87.439245 | H40: 3.1034803 | I40: 85.942738 | J40: 5.714384 | K40: 90.797153 | L40: 1.2268638 | M40: 93.091368 | N40: 0.78941848 | O40: 5.6521232 | P40: 3.2137961 | Q40: 86.097116 | R40: 3.0922803 | S40: 91.439417 | T40: 1.039521 | U40: m | V40: m | W40: 5.342301 | X40: 3.1458885
A41: New Zealand | B41: 10578.5 | C41: 156 | D41: 81.870483 | E41: 90.447288 | F41: 1.9733832 | G41: 90.380377 | H41: 3.8723249 | I41: 87.047977 | J41: 5.1422839 | K41: 93.259839 | L41: 3.0504968 | M41: 91.140461 | N41: 3.4080151 | O41: 0.76008451 | P41: 5.0727166 | Q41: 90.100686 | R41: 2.2364072 | S41: m | T41: m | U41: 92.926305 | V41: 1.117125 | W41: 2.8256191 | X41: 2.493925
A42: Norway | B42: 6270 | C42: 202 | D42: 81.183014 | E42: 90.812105 | F42: 1.9690699 | G42: 90.92377 | H42: 3.2804816 | I42: 92.056755 | J42: 3.6741153 | K42: 88.992597 | L42: 4.9488755 | M42: 90.57473 | N42: 3.5872217 | O42: -0.3490399 | P42: 4.7462836 | Q42: w | R42: w | S42: w | T42: w | U42: w | V42: w | W42: w | X42: w
A43: Poland | B43: 8614.5 | C43: 194 | D43: 84.160278 | E43: 98.601645 | F43: 0.68107639 | G43: 97.211058 | H43: 1.8396514 | I43: 99.746758 | J43: 0.21794046 | K43: 99.640206 | L43: 0.15900043 | M43: 98.617168 | N43: 0.92278654 | O43: 1.4061099 | P43: 2.1017203 | Q43: 98.579829 | R43: 0.7059992 | S43: 100 | T43: 3.3327408e-14 | U43: m | V43: m | W43: 1.4201709 | X43: 0.7059992
A44: Portugal* | B44: 22487 | C44: 143 | D44: 54.206627 | E44: 92.018845 | F44: 1.3067407 | G44: 87.591627 | H44: 3.5834477 | I44: 93.407279 | J44: 2.448134 | K44: 93.490764 | L44: 2.8372416 | M44: 93.611256 | N44: 1.9439458 | O44: 6.0196283 | P44: 4.0423506 | Q44: 95.596729 | R44: 1.1482055 | S44: 60.355961 | T44: 3.7658161 | U44: 88.683027 | V44: 6.0581563 | W44: -22.59733 | X44: 5.7889073
...

Sheet Table II.B1.5.4
A1: PISA 2018 Results (Volume II) - © OECD 2019
A2: Annex B1 | B2: Annex B1.5 Results (tables): How do schools compensate for socio-economic disadvantage?
A3: Version 2 - Last updated: 02-Dec-2019
A4: Disclaimer: http://oe.cd/disclaimer
A6: Table II.B1.5.4
A7: Teachers with at least a master's degree, by school characteristics
A8: Results based on principals' reports
B12: All schools1 | G12: Proportion of teachers with at least a master's degree, by schools' socio-economic profile4 | Q12: Proportion of teachers with at least a master's degree,6 by type of school
B13: Sample size | D13: Coverage2 | E13: Overall proportion of teachers with at least a master's degree3 | G13: Bottom quarter | I13: Second quarter | K13: Third quarter | M13: Top quarter | O13: Top - bottom quarter | Q13: Public | S13: Private government-dependent | U13: Private independent | W13: Private-Public5
B14: Number of teachers | C14: Number of schools | D14: % | E14: % | F14: S.E. | G14: % | H14: S.E. | I14: % | J14: S.E. | K14: % | L14: S.E. | M14: % | N14: S.E. | O14: % dif. | P14: S.E. | Q14: % | R14: S.E. | S14: % | T14: S.E. | U14: % | V14: S.E. | W14: % dif. | X14: S.E.
A15: OECD
A16: Australia | B16: 33035 | C16: 419 | D16: 56.318748 | E16: 18.484224 | F16: 0.62483872 | G16: 12.566391 | H16: 1.0452136 | I16: 14.866972 | J16: 1.4445117 | K16: 20.081 | L16: 1.3660718 | M16: 24.286943 | N16: 1.3531005 | O16: 11.720552 | P16: 1.8451225 | Q16: 14.387637 | R16: 0.87809069 | S16: 19.64533 | T16: 1.0567796 | U16: 25.919508 | V16: 1.6999178 | W16: 7.8763511 | X16: 1.2920567
A17: Austria | B17: 10333 | C17: 291 | D17: m | E17: 53.264576 | F17: 2.8226955 | G17: m | H17: m | I17: m | J17: m | K17: m | L17: m | M17: m | N17: m | O17: m | P17: m | Q17: m | R17: m | S17: m | T17: m | U17: m | V17: m | W17: m | X17: m
A18: Belgium | B18: 16148 | C18: 175 | D18: 63.410633 | E18: 38.21278 | F18: 1.5228567 | G18: 31.59366 | H18: 3.2207953 | I18: 35.437784 | J18: 2.4096071 | K18: 41.879178 | L18: 2.8901071 | M18: 52.11498 | N18: 3.0968692 | O18: 20.521321 | P18: 4.2078387 | Q18: m | R18: m | S18: m | T18: m | U18: m | V18: m | W18: m | X18: m
A19: Canada | B19: 17988 | C19: 373 | D19: 45.636093 | E19: 17.664456 | F19: 0.80190438 | G19: 18.877483 | H19: 2.1008425 | I19: 13.755331 | J19: 1.1078871 | K19: 17.208643 | L19: 1.3363252 | M19: 19.715406 | N19: 1.6095071 | O19: 0.8379234 | P19: 2.6704233 | Q19: 17.279937 | R19: 0.87224583 | S19: 14.714473 | T19: 1.3467451 | U19: 21.804425 | V19: 3.1408032 | W19: 2.2594904 | X19: 2.5521325
A20: Chile | B20: 5810.5 | C20: 107 | D20: 47.113201 | E20: 10.722462 | F20: 0.75942229 | G20: 8.2335414 | H20: 1.4620376 | I20: 6.9877799 | J20: 2.1107827 | K20: 9.7421449 | L20: 1.3131555 | M20: 14.483529 | N20: 1.66619 | O20: 6.2499881 | P20: 2.1374801 | Q20: 11.14902 | R20: 2.0418983 | S20: 7.7582742 | T20: 0.74206041 | U20: 17.426639 | V20: 2.2062651 | W20: -0.54248119 | X20: 2.4053673
A21: Colombia | B21: 13209.5 | C21: 239 | D21: 95.490021 | E21: 12.553873 | F21: 1.2375792 | G21: 9.7633482 | H21: 2.3275515 | I21: 12.232979 | J21: 1.6342308 | K21: 19.311947 | L21: 2.6597928 | M21: 12.474578 | N21: 3.059646 | O21: 2.7112295 | P21: 3.9093503 | Q21: 13.279103 | R21: 1.3241453 | S21: m | T21: m | U21: 9.9429717 | V21: 3.0302579 | W21: -3.3361317 | X21: 3.1963613
A22: Czech Republic | B22: 9743 | C22: 267 | D22: 79.738815 | E22: 88.148298 | F22: 1.3647134 | G22: 80.324867 | H22: 3.0101344 | I22: 90.571408 | J22: 2.1758534 | K22: 90.600592 | L22: 2.2186981 | M22: 93.654598 | N22: 2.1604229 | O22: 13.329732 | P22: 3.7211824 | Q22: 88.523641 | R22: 1.3978036 | S22: 80.918677 | T22: 7.9270931 | U22: m | V22: m | W22: -7.6049637 | X22: 8.0959498
A23: Denmark | B23: 6557 | C23: 152 | D23: 48.139141 | E23: 3.3617808 | F23: 0.55069832 | G23: 2.6748866 | H23: 0.77053231 | I23: 2.2029255 | J23: 0.60372848 | K23: 2.3782865 | L23: 1.1971369 | M23: 5.773876 | N23: 1.5480484 | O23: 3.0989895 | P23: 1.7266474 | Q23: 2.4376663 | R23: 0.49235601 | S23: 5.8669623 | T23: 1.7680978 | U23: 8.6788024 | V23: 3.1472623 | W23: 3.9112255 | X23: 1.6707783
A24: Estonia | B24: 8501.5 | C24: 204 | D24: 91.353706 | E24: 80.920872 | F24: 1.2829461 | G24: 78.076345 | H24: 2.5812694 | I24: 77.111549 | J24: 1.922157 | K24: 84.852866 | L24: 2.2851233 | M24: 83.906649 | N24: 2.8444835 | O24: 5.8303043 | P24: 3.747446 | Q24: 80.439122 | R24: 1.3352169 | S24: m | T24: m | U24: 87.943972 | V24: 6.2751525 | W24: 7.5048502 | X24: 6.3959565
A25: Finland | B25: 4395 | C25: 104 | D25: 49.592617 | E25: 91.034216 | F25: 2.0135442 | G25: 92.289722 | H25: 3.4018021 | I25: 93.050089 | J25: 2.828851 | K25: 96.549839 | L25: 0.66533112 | M25: 84.04553 | N25: 6.0113126 | O25: -8.2441917 | P25: 6.7230489 | Q25: 92.294844 | R25: 1.5179009 | S25: 73.210334 | T25: 17.661868 | U25: m | V25: m | W25: -19.084511 | X25: 17.736076
A26: France | B26: 12829.5 | C26: 129 | D26: 61.443195 | E26: 42.827197 | F26: 3.3439265 | G26: 42.429262 | H26: 7.3060653 | I26: 44.315646 | J26: 6.2740157 | K26: 40.660564 | L26: 5.9123233 | M26: 43.997485 | N26: 6.3052607 | O26: 1.5682231 | P26: 9.6042945 | Q26: 42.372208 | R26: 4.0472001 | S26: 53.547089 | T26: 5.6351524 | U26: 33.327645 | V26: 12.316071 | W26: 3.5492352 | X26: 7.5650969
A27: Germany | B27: 7731.5 | C27: 149 | D27: 66.368408 | E27: 83.216243 | F27: 3.3495018 | G27: 80.474651 | H27: 5.7975904 | I27: 82.059718 | J27: 8.6041353 | K27: 84.92859 | L27: 6.8938515 | M27: 88.986655 | N27: 4.8704802 | O27: 8.5120034 | P27: 7.6055391 | Q27: 83.806549 | R27: 3.3642897 | S27: m | T27: m | U27: m | V27: m | W27: m | X27: m
A28: Greece | B28: 3959 | C28: 130 | D28: 58.626656 | E28: 22.900661 | F28: 2.046553 | G28: 19.100548 | H28: 2.2250268 | I28: 18.557283 | J28: 1.9089152 | K28: 19.790801 | L28: 2.6002946 | M28: 37.751401 | N28: 7.2083836 | O28: 18.650853 | P28: 7.5603062 | Q28: 20.374375 | R28: 1.2985634 | S28: m | T28: m | U28: 51.823658 | V28: 13.238011 | W28: 31.449283 | X28: 13.306786
A29: Hungary | B29: 8401 | C29: 132 | D29: 74.080711 | E29: 73.891266 | F29: 2.0713415 | G29: 58.916084 | H29: 3.6756069 | I29: 72.790765 | J29: 3.7066324 | K29: 78.812373 | L29: 3.424997 | M29: 83.792536 | N29: 5.1260889 | O29: 24.876452 | P29: 6.3055735 | Q29: 74.559745 | R29: 1.9404951 | S29: 70.237119 | T29: 4.7194284 | U29: m | V29: m | W29: -4.3226265 | X29: 5.0648955
A30: Iceland | B30: 2101 | C30: 71 | D30: 55.981873 | E30: 19.061024 | F30: 0.32141816 | G30: 19.437934 | H30: 0.82538852 | I30: 16.609859 | J30: 0.04212616 | K30: 25.750445 | L30: c | M30: 15.461782 | N30: c | O30: -3.9761512 | P30: 0.82538852 | Q30: 19.085641 | R30: 0.3225257 | S30: m | T30: m | U30: m | V30: m | W30: m | X30: m
A31: Ireland | B31: 4299 | C31: 90 | D31: 57.588337 | E31: 28.350067 | F31: 2.2782851 | G31: 29.779029 | H31: 4.1275725 | I31: 27.550856 | J31: 5.0223786 | K31: 25.45769 | L31: 3.7755292 | M31: 31.115588 | N31: 5.6485487 | O31: 1.3365589 | P31: 6.8279174 | Q31: m | R31: m | S31: m | T31: m | U31: m | V31: m | W31: m | X31: m
A32: Israel | B32: 9370 | C32: 132 | D32: 77.495262 | E32: 41.76873 | F32: 1.8224069 | G32: 36.527807 | H32: 4.0579737 | I32: 51.364176 | J32: 4.2347181 | K32: 45.923884 | L32: 2.4885312 | M32: 32.403509 | N32: 3.3417435 | O32: -4.1242977 | P32: 5.2378187 | Q32: 41.76873 | R32: 1.8224069 | S32: m | T32: m | U32: m | V32: m | W32: m | X32: m
A33: Italy | B33: 29930.5 | C33: 293 | D33: 59.897335 | E33: 72.478129 | F33: 3.1588064 | G33: 71.926882 | H33: 5.0917479 | I33: 75.211453 | J33: 4.7945841 | K33: 80.683545 | L33: 5.1276001 | M33: 61.382976 | N33: 9.8219522 | O33: -10.543906 | P33: 11.27816 | Q33: 71.810747 | R33: 3.2683749 | S33: 59.71858 | T33: 3.8599691 | U33: 98.58796 | V33: 2.2670231 | W33: 15.618218 | X33: 8.0204763
A34: Japan | B34: m | C34: m | D34: m | E34: m | F34: m | G34: m | H34: m | I34: m | J34: m | K34: m | L34: m | M34: m | N34: m | O34: m | P34: m | Q34: m | R34: m | S34: m | T34: m | U34: m | V34: m | W34: m | X34: m
A35: Korea | B35: 5863.5 | C35: 80 | D35: 43.213665 | E35: 39.52163 | F35: 2.3913493 | G35: 35.43781 | H35: 3.3242939 | I35: 39.485913 | J35: 2.7941749 | K35: 39.145695 | L35: 4.4876397 | M35: 44.082049 | N35: 5.8614672 | O35: 8.6442389 | P35: 6.8225193 | Q35: 41.863821 | R35: 3.2014511 | S35: 34.78106 | T35: 3.2397799 | U35: 37.898174 | V35: 8.9106234 | W35: -6.5533467 | X35: 4.4214351
A36: Latvia | B36: 10284 | C36: 237 | D36: 76.242699 | E36: 51.812909 | F36: 1.0652525 | G36: 46.566166 | H36: 2.3902696 | I36: 51.458391 | J36: 2.2411117 | K36: 53.998691 | L36: 2.5075664 | M36: 56.283209 | N36: 2.3924245 | O36: 9.7170432 | P36: 3.1026484 | Q36: 52.300684 | R36: 1.1065076 | S36: m | T36: m | U36: m | V36: m | W36: m | X36: m
A37: Lithuania | B37: 14934 | C37: 361 | D37: 99.652031 | E37: 42.214759 | F37: 1.7361528 | G37: 37.409499 | H37: 3.0549367 | I37: 40.61224 | J37: 2.3953273 | K37: 44.135668 | L37: 4.3707036 | M37: 53.795035 | N37: 3.7592841 | O37: 16.385536 | P37: 5.3618856 | Q37: 41.578816 | R37: 1.7697049 | S37: 58.687806 | T37: 7.0909011 | U37: m | V37: m | W37: 17.10899 | X37: 7.2167661
A38: Luxembourg | B38: 2971.5 | C38: 25 | D38: 58.766594 | E38: 83.728757 | F38: c | G38: 74.59893 | H38: c | I38: 82.962963 | J38: c | K38: 92.908263 | L38: c | M38: 84.102564 | N38: c | O38: 9.5036336 | P38: c | Q38: 85.480869 | R38: c | S38: m | T38: m | U38: m | V38: m | W38: m | X38: m
A39: Mexico | B39: 7504.5 | C39: 135 | D39: 52.613537 | E39: 24.524504 | F39: 1.841262 | G39: 21.770218 | H39: 4.5364025 | I39: 21.485857 | J39: 2.123524 | K39: 22.09892 | L39: 3.1758876 | M39: 28.785413 | N39: 4.007169 | O39: 7.0151959 | P39: 5.9843737 | Q39: 23.653464 | R39: 1.8680562 | S39: m | T39: m | U39: 26.92883 | V39: 4.0257191 | W39: 3.2753657 | X39: 4.3453774
A40: Netherlands* | B40: 7652.5 | C40: 124 | D40: 79.725136 | E40: 26.123755 | F40: 2.5380176 | G40: 14.638541 | H40: 3.1458886 | I40: 19.730789 | J40: 6.6915423 | K40: 28.881962 | L40: 4.742907 | M40: 41.930712 | N40: 5.4092782 | O40: 27.29217 | P40: 6.2846293 | Q40: 25.439675 | R40: 3.7819797 | S40: 26.241973 | T40: 3.347326 | U40: m | V40: m | W40: 0.80229816 | X40: 5.0493725
A41: New Zealand | B41: 11179.5 | C41: 163 | D41: 85.358147 | E41: 18.361141 | F41: 1.2427744 | G41: 17.365345 | H41: 2.1127594 | I41: 21.205937 | J41: 3.2223443 | K41: 20.875247 | L41: 2.9566475 | M41: 15.39528 | N41: 0.98937166 | O41: -1.9700644 | P41: 2.4096598 | Q41: 18.524105 | R41: 1.322072 | S41: m | T41: m | U41: 16.908013 | V41: 3.0230127 | W41: -1.6160925 | X41: 3.2333409
A42: Norway | B42: m | C42: m | D42: m | E42: m | F42: m | G42: m | H42: m | I42: m | J42: m | K42: m | L42: m | M42: m | N42: m | O42: m | P42: m | Q42: w | R42: w | S42: w | T42: w | U42: w | V42: w | W42: w | X42: w
A43: Poland | B43: 9029 | C43: 202 | D43: 86.820343 | E43: 96.509259 | F43: 0.73214368 | G43: 95.375321 | H43: 1.6754071 | I43: 96.825807 | J43: 0.55350891 | K43: 96.778001 | L43: 1.4262571 | M43: 98.047815 | N43: 0.35652632 | O43: 2.6724944 | P43: 1.671014 | Q43: 96.442562 | R43: 0.75892708 | S43: 100 | T43: 3.3327408e-14 | U43: m | V43: m | W43: 3.5574383 | X43: 0.75892708
A44: Portugal* | B44: 23351 | C44: 146 | D44: 54.670826 | E44: 18.762764 | F44: 1.9382994 | G44: 16.719688 | H44: 5.7496705 | I44: 20.332927 | J44: 4.1135079 | K44: 18.057961 | L44: 3.6526049 | M44: 19.158113 | N44: 2.6187606 | O44: 2.4384243 | P44: 6.3859849 | Q44: 19.03555 | R44: 2.2435417 | S44: 18.022034 | T44: 4.6352788 | U44: 16.225884 | V44: 4.3886616 | W44: -1.7986024 | X44: 3.8372833
...

Sheet Table II.B1.5.5
A1: PISA 2018 Results (Volume II) - © OECD 2019
A2: Annex B1 | B2: Annex B1.5 Results (tables): How do schools compensate for socio-economic disadvantage?
A3: Version 2 - Last updated: 02-Dec-2019
A4: Disclaimer: http://oe.cd/disclaimer
A6: Table II.B1.5.5
A7: Novice teachers, by school characteristics
A8: Teachers with less than five years of experience; results based on teachers' reports
B12: All schools1 | G12: Proportion of novice teachers, by schools' socio-economic profile4 | Q12: Proportion of novice teachers, by type of school
B13: Sample size | D13: Coverage2 | E13: Average proportion of novice teachers3 | G13: Bottom quarter | I13: Second quarter | K13: Third quarter | M13: Top quarter | O13: Top - bottom quarter | Q13: Public | S13: Private government-dependent | U13: Private independent | W13: Private-Public5
B14: Number of teachers | C14: Number of schools | D14: % | E14: % | F14: S.E. | G14: % | H14: S.E. | I14: % | J14: S.E. | K14: % | L14: S.E. | M14: % | N14: S.E. | O14: % dif | P14: S.E. | Q14: % | R14: S.E. | S14: % | T14: S.E. | U14: % | V14: S.E. | W14: % dif. | X14: S.E.
A15: OECD
A16: Chile | B16: 689 | C16: 223 | D16: 81.300156 | E16: 25.388781 | F16: 1.2648427 | G16: 27.243658 | H16: 2.0093424 | I16: 30.063692 | J16: 3.8831501 | K16: 26.041815 | L16: 2.8086125 | M16: 20.194012 | N16: 1.7947892 | O16: -7.0496458 | P16: 2.7168975 | Q16: 26.222041 | R16: 1.431449 | S16: 26.945496 | T16: 1.9316774 | U16: 18.174902 | V16: 2.1413255 | W16: -1.8203581 | X16: 2.2204248
A17: Germany | B17: 996 | C17: 218 | D17: 70.638672 | E17: 20.806802 | F17: 0.9874455 | G17: 20.571356 | H17: 1.7368129 | I17: 19.756345 | J17: 1.8994906 | K17: 22.975226 | L17: 2.1512171 | M17: 20.774892 | N17: 2.151638 | O17: 0.20353536 | P17: 2.7623101 | Q17: 20.589552 | R17: 1.1250255 | S17: 26.367806 | T17: 9.8508489 | U17: 29.62963 | V17: 5.0242959e-15 | W17: 6.3753541 | X17: 8.2996692
A18: Korea | B18: 635 | C18: 154 | D18: 83.416168 | E18: 16.483421 | F18: 1.1406318 | G18: 19.35312 | H18: 2.7383102 | I18: 15.497485 | J18: 2.2100483 | K18: 14.705834 | L18: 1.2314026 | M18: 14.720825 | N18: 1.5003151 | O18: -4.6322947 | P18: 3.140974 | Q18: 18.295616 | R18: 1.7628095 | S18: 13.432081 | T18: 1.1061223 | U18: 16.350139 | V18: 2.2404781 | W18: -4.5022264 | X18: 2.0781885
A19: Portugal* | B19: 99 | C19: 234 | D19: 81.072624 | E19: 3.6617846 | F19: 0.58624753 | G19: 4.4914165 | H19: 1.4919217 | I19: 3.5896089 | J19: 0.78355614 | K19: 2.5370938 | L19: 0.7539802 | M19: 3.4450015 | N19: 1.2359586 | O19: -1.046415 | P19: 1.9479604 | Q19: 1.5646477 | R19: 0.2683831 | S19: 10.536519 | T19: 3.1744893 | U19: 6.6713116 | V19: 1.6550361 | W19: 7.0546322 | X19: 1.834531
A20: Spain | B20: 2981 | C20: 1079 | D20: 85.49733 | E20: 16.785295 | F20: 0.52810608 | G20: 18.154969 | H20: 0.92512413 | I20: 17.377233 | J20: 1.2611347 | K20: 14.911045 | L20: 0.99813692 | M20: 16.538427 | N20: 1.0623062 | O20: -1.6165419 | P20: 1.3137088 | Q20: 16.636984 | R20: 0.59291476 | S20: 16.086565 | T20: 1.0247798 | U20: 21.697359 | V20: 1.78992 | W20: 0.71373074 | X20: 1.0609373
A21: Scotland (United Kingdom) | B21: 249 | C21: 97 | D21: 35.70681 | E21: 17.195713 | F21: 1.3054135 | G21: 18.633542 | H21: 2.541126 | I21: 21.042795 | J21: 1.8247879 | K21: 14.44734 | L21: 2.7607625 | M21: 12.118682 | N21: 1.9075588 | O21: -6.5148602 | P21: 3.1535189 | Q21: 17.721432 | R21: 1.3368528 | S21: m | T21: m | U21: 12.641321 | V21: 3.8229381 | W21: -5.0801111 | X21: 4.0469558
A22: United States* | B22: 514 | C22: 157 | D22: 78.164978 | E22: 19.346393 | F22: 1.5421026 | G22: 25.561824 | H22: 2.9145716 | I22: 19.967244 | J22: 3.0270835 | K22: 17.45752 | L22: 2.6940118 | M22: 12.262639 | N22: 2.3504934 | O22: -13.299185 | P22: 3.7838149 | Q22: 18.730537 | R22: 1.4738086 | S22: 41.346108 | T22: 2.8780174 | U22: 16.863272 | V22: 7.567979 | W22: 5.4260108 | X22: 7.6721458
A23: OECD average | B23: m | C23: m | D23: m | E23: 17.095456 | F23: 0.41846863 | G23: 19.144269 | H23: 0.81548851 | I23: 18.184914 | J23: 0.88373903 | K23: 16.153696 | L23: 0.78865248 | M23: 14.293497 | N23: 0.66886208 | O23: -4.8507725 | P23: 1.0561764 | Q23: 17.108687 | R23: 0.46958711 | S23: 22.452429 | T23: 1.8363963 | U23: 17.432562 | V23: 1.3358261 | W23: 1.1667189 | X23: 1.7949159
A24: Partners
A25: Albania | B25: 575 | C25: 324 | D25: 95.234802 | E25: 18.917438 | F25: 0.84921836 | G25: 19.00109 | H25: 1.3567279 | I25: 18.400587 | J25: 2.4155334 | K25: 16.189198 | L25: 2.1556416 | M25: 21.225652 | N25: 2.4467494 | O25: 2.2245621 | P25: 2.9064564 | Q25: 17.239531 | R25: 0.88409893 | S25: m | T25: m | U25: 32.392159 | V25: 3.4215421 | W25: 15.152628 | X25: 3.6551373
A26: Baku (Azerbaijan) | B26: 99 | C26: 153 | D26: 49.318989 | E26: 4.9481305 | F26: 0.79568707 | G26: 9.862209 | H26: 2.2050094 | I26: 5.9575037 | J26: 1.9369704 | K26: 0.69987644 | L26: 0.34095378 | M26: 2.7895429 | N26: 0.90323069 | O26: -7.0726661 | P26: 2.2866772 | Q26: 4.8107643 | R26: 0.80670878 | S26: m | T26: m | U26: 13.529412 | V26: 0.36693057 | W26: 8.7186478 | X26: 0.88206599
