Workbook

Sheet TOC
A1: PISA 2018 Results (Volume III) - © OECD 2019
A2: Annex B1 | B2: Annex B1.2 Results (tables): Bullying
A3: Version 2 - Last updated: 02-Dec-2019
A4: Disclaimer: http://oe.cd/disclaimer
A6: TOC | B6: PISA 2018 Results - Volume III
A8: Chapter 2 | B8: Bullying
A9: Tables
A11: ='Table III.B1.2.1'!A6 -> Table III.B1.2.1 | B11: ='Table III.B1.2.1'!$A$7 -> Students' exposure to bullying
A12: ='Table III.B1.2.2'!A6 -> Table III.B1.2.2 | B12: ='Table III.B1.2.2'!$A$7 -> Change between 2015 and 2018 in students' exposure to bullying
A13: ='Table III.B1.2.3'!A6 -> Table III.B1.2.3 | B13: ='Table III.B1.2.3'!$A$7 -> Prevalence of exposure to bullying in schools
A14: ='Table III.B1.2.4'!A6 -> Table III.B1.2.4 | B14: ='Table III.B1.2.4'!$A$7 -> Students' exposure to bullying, by student characteristics
A15: ='Table III.B1.2.5'!A6 -> Table III.B1.2.5 | B15: ='Table III.B1.2.5'!$A$7 -> Students' exposure to bullying, by school characteristics
A16: ='Table III.B1.2.6'!A6 -> Table III.B1.2.6 | B16: ='Table III.B1.2.6'!$A$7 -> Students' exposure to bullying and reading performance
A17: ='Table III.B1.2.7'!A6 -> Table III.B1.2.7 | B17: ='Table III.B1.2.7'!$A$7 -> School-level students' exposure to bullying and reading performance
A18: ='Table III.B1.2.8'!A6 -> Table III.B1.2.8 | B18: ='Table III.B1.2.8'!$A$7 -> Bullying as obstacle to student learning, by prevalence of bullying at school
A19: ='Table III.B1.2.9'!A6 -> Table III.B1.2.9 | B19: ='Table III.B1.2.9'!$A$7 -> Students' exposure to bullying, by gender
A20: ='Table III.B1.2.10'!A6 -> Table III.B1.2.10 | B20: ='Table III.B1.2.10'!$A$7 -> Students' exposure to bullying, by socio-economic status
A21: ='Table III.B1.2.11'!A6 -> Table III.B1.2.11 | B21: ='Table III.B1.2.11'!$A$7 -> Being frequently bullied, by the gender composition at school
A22: ='Table III.B1.2.12'!A6 -> Table III.B1.2.12 | B22: ='Table III.B1.2.12'!$A$7 -> Change between 2015 and 2018 in students' exposure to bullying, by time spent on the Internet
A23: ='Table III.B1.2.13'!A6 -> Table III.B1.2.13 | B23: ='Table III.B1.2.13'!$A$7 -> Being frequently bullied and students' well-being
A24: ='Table III.B1.2.14'!A6 -> Table III.B1.2.14 | B24: ='Table III.B1.2.14'!$A$7 -> School climate, by prevalence of bullying at schools
A25: ='Table III.B1.2.15'!A6 -> Table III.B1.2.15 | B25: ='Table III.B1.2.15'!$A$7 -> Students' attitudes towards bullying
A26: ='Table III.B1.2.16'!A6 -> Table III.B1.2.16 | B26: ='Table III.B1.2.16'!$A$7 -> Students' attitudes towards bullying, by gender
A27: ='Table III.B1.2.17'!A6 -> Table III.B1.2.17 | B27: ='Table III.B1.2.17'!$A$7 -> Students' attitudes towards bullying, by socio-economic status
A28: ='Table III.B1.2.18'!A6 -> Table III.B1.2.18 | B28: ='Table III.B1.2.18'!$A$7 -> Being bullied, by students' attitudes towards bullying
A29: ='Table III.B1.2.19'!A6 -> Table III.B1.2.19 | B29: ='Table III.B1.2.19'!$A$7 -> Exposure to bullying and students' attitudes towards bullying at school
A30: ='Table III.B1.2.20'!A6 -> Table III.B1.2.20 | B30: ='Table III.B1.2.20'!$A$7 -> Rate of victimisation of "frequently bullied students"
A33: Symbols for missing data
A34: c: There were too few observations to provide reliable estimates (i.e. there were fewer than 30 students or fewer than 5 schools with valid data).
A35: m: Data are not available. There are no observations in the sample; these data were not collected by the country; or these data were collected but subsequently removed from the publication for technical reasons.
A36: w: Results were withdrawn at the request of the country concerned.

Sheet INFORMATION ON SCALED INDICES
A1: PISA 2018 Results (Volume III) - © OECD 2019
A2: Annex B1 | B2: Annex B1.2 Results (tables): Bullying
A3: Version 2 - Last updated: 02-Dec-2019
A4: Disclaimer: http://oe.cd/disclaimer
A6: Information on scaled indices used in PISA 2015 Results (Volume III): What School Life Means for Students’ Lives
A11: Full name of the index | B11: Name in dataset | C11: Questionnaire | D11: Item 1 | E11: Item 2 | F11: Item 3 | G11: Item 4 | H11: Item 5 | I11: Item 6 | J11: Item 7
A12: Adaptive instruction | B12: adaptivity | C12: Student | D12: ST212Q01HA | E12: ST212Q02HA | F12: ST212Q03HA
A13: Attitudes towards competition | B13: compete | C13: Student | D13: ST181Q02HA | E13: ST181Q03HA | F13: ST181Q04HA
A14: Enjoyment of reading | B14: joyread | C14: Student | D14: ST160Q01IR | E14: ST160Q02IA | F14: ST160Q03IA | G14: ST160Q04IR | H14: ST160Q05IR
A15: Exposure to bullying | B15: beingbullied | C15: Student | D15: ST038Q03NA | E15: ST038Q04NA | F15: ST038Q05NA
A16: Fear of failure | B16: gfofail | C16: Student | D16: ST183Q01HA | E16: ST183Q02HA | F16: ST183Q03HA
A17: Disciplinary climate | B17: disclima | C17: Student | D17: ST097Q01TA | E17: ST097Q02TA | F17: ST097Q03TA | G17: ST097Q04TA | H17: ST097Q05TA
A18: Learning goals | B18: mastgoal | C18: Student | D18: ST208Q01HA | E18: ST208Q02HA | F18: ST208Q04HA
A19: Meaning in life | B19: eudmo | C19: Student | D19: ST185Q01HA | E19: ST185Q02HA | F19: ST185Q03HA
A20: Motivation to master tasks | B20: workmast | C20: Student | D20: ST182Q03HA | E20: ST182Q04HA | F20: ST182Q05HA
A21: Parents’ emotional support | B21: emosups | C21: Student | D21: ST123Q02NA | E21: ST123Q03NA | F21: ST123Q04NA
A22: Parents’ perceived school quality | B22: pqschool | C22: Parent | D22: PA007Q01TR | E22: PA007Q02TR | F22: PA007Q03TR | G22: PA007Q04TR | H22: PA007Q05TR | I22: PA007Q06TR | J22: PA007Q07TR
A23: Positive feelings | B23: swbp | C23: Student | D23: ST186Q01HA | E23: ST186Q03HA | F23: ST186Q05HA
A24: School policies for parental involvement | B24: paschpol | C24: Parent | D24: PA007Q09NR | E24: PA007Q11NR | F24: PA007Q12NR | G24: PA007Q13NR | H24: PA007Q14NR | I24: PA007Q15NR
A25: Self-efficacy | B25: resilience | C25: Student | D25: ST188Q01HA | E25: ST188Q02HA | F25: ST188Q03HA | G25: ST188Q06HA | H25: ST188Q07HA
A26: Sense of belonging | B26: belong | C26: Student | D26: ST034Q01TA | E26: ST034Q02TR | F26: ST034Q03TR | G26: ST034Q04TA | H26: ST034Q05TR | I26: ST034Q06TA
A27: Shortage of educational staff | B27: staffshort | C27: School | D27: SC017Q01NA | E27: SC017Q02NA | F27: SC017Q03NA | G27: SC017Q04NA
A28: Student competition | B28: percomp | C28: Student | D28: ST205Q01HA | E28: ST205Q02HA | F28: ST205Q03HA
A29: Student co-operation | B29: percoop | C29: Student | D29: ST206Q01HA | E29: ST206Q02HA | F29: ST206Q03HA
A30: Teacher behaviour hindering learning | B30: teachbeha | C30: School | D30: SC061Q06TA | E30: SC061Q07TA | F30: SC061Q08TA | G30: SC061Q09TA | H30: SC061Q10TA
A31: Teacher enthusiasm | B31: teachint | C31: Student | D31: ST213Q01HA | E31: ST213Q02HA | F31: ST213Q03HA | G31: ST213Q04HA
A32: Teacher feedback | B32: perfeed | C32: Student | D32: ST104Q02NA | E32: ST104Q03NA | F32: ST104Q04NA
A33: Teacher support | B33: teachsup | C33: Student | D33: ST100Q01TR | E33: ST100Q02TR | F33: ST100Q03TR | G33: ST100Q04TR
A34: Teacher-directed instruction | B34: dirins | C34: Student | D34: ST102Q01TR | E34: ST102Q02TR | F34: ST102Q03TR | G34: ST102Q04TR
A35: Teachers' stimulation of reading engagement | B35: stimread | C35: Student | D35: ST152Q05IA | E35: ST152Q06IA | F35: ST152Q07IA | G35: ST152Q08IA
A36: Value of school | B36: attlnact | C36: Student | D36: ST036Q05TR | E36: ST036Q06TR | F36: ST036Q08TR

Sheet Table III.B1.2.1
A1: PISA 2018 Results (Volume III) - © OECD 2019
A2: Annex B1 | B2: Annex B1.2 Results (tables): Bullying
A3: Version 2 - Last updated: 02-Dec-2019
A4: Disclaimer: http://oe.cd/disclaimer
A6: Table III.B1.2.1
A7: Students' exposure to bullying
A8: Based on students' reports
B11: Index of exposure to bullying1 | H11: Variation in the index of exposure to bullying | R11: Percentage of frequently bullied students4 | U11: Any type of bullying act | AG11: Percentage of students who reported the following:
AG12: Other students left me out of things on purpose | AS12: Other students made fun of me | BE12: I was threatened by other students | BQ12: Other students took away or destroyed things that belong to me | CC12: I got hit or pushed around by other students | CO12: Other students spread nasty rumours about me
B13: Average | E13: Variability | H13: Total variation2 | K13: Variation between schools3 | N13: Variation within schools | Q13: Proportion of variation that lies between schools | U13: Never or almost never | X13: A few times a year | AA13: A few times a month | AD13: Once a week or more | AG13: Never or almost never | AJ13: A few times a year | AM13: A few times a month | AP13: Once a week or more | AS13: Never or almost never | AV13: A few times a year | AY13: A few times a month | BB13: Once a week or more | BE13: Never or almost never | BH13: A few times a year | BK13: A few times a month | BN13: Once a week or more | BQ13: Never or almost never | BT13: A few times a year | BW13: A few times a month | BZ13: Once a week or more | CC13: Never or almost never | CF13: A few times a year | CI13: A few times a month | CL13: Once a week or more | CO13: Never or almost never | CR13: A few times a year | CU13: A few times a month | CX13: Once a week or more
B14: Mean index | C14: S.E. | E14: S.D. | F14: S.E. | H14: Variance | I14: S.E. | K14: Variance | L14: S.E. | N14: Variance | O14: S.E. | Q14: % | R14: % | S14: S.E. | U14: % | V14: S.E. | X14: % | Y14: S.E. | AA14: % | AB14: S.E. | AD14: % | AE14: S.E. | AG14: % | AH14: S.E. | AJ14: % | AK14: S.E. | AM14: % | AN14: S.E. | AP14: % | AQ14: S.E. | AS14: % | AT14: S.E. | AV14: % | AW14: S.E. | AY14: % | AZ14: S.E. | BB14: % | BC14: S.E. | BE14: % | BF14: S.E. | BH14: % | BI14: S.E. | BK14: % | BL14: S.E. | BN14: % | BO14: S.E. | BQ14: % | BR14: S.E. | BT14: % | BU14: S.E. | BW14: % | BX14: S.E. | BZ14: % | CA14: S.E. | CC14: % | CD14: S.E. | CF14: % | CG14: S.E. | CI14: % | CJ14: S.E. | CL14: % | CM14: S.E. | CO14: % | CP14: S.E. | CR14: % | CS14: S.E. | CU14: % | CV14: S.E. | CX14: % | CY14: S.E.
A15: OECD
A16: Australia | B16: 0.32996933 | C16: 0.012060573 | E16: 1.1198612 | F16: 0.0093711397 | H16: 1.2326816 | I16: 0.027727587 | K16: 0.035849206 | L16: 0.0073729014 | N16: 1.1968324 | O16: 0.020354685 | Q16: 2.9082291 | R16: 13.049248 | S16: 0.39973772 | U16: 36.758097 | V16: 0.5017037 | X16: 33.693312 | Y16: 0.5473852 | AA16: 16.311218 | AB16: 0.39421842 | AD16: 13.237373 | AE16: 0.36778748 | AG16: 58.261641 | AH16: 0.48667484 | AJ16: 28.237576 | AK16: 0.4523816 | AM16: 8.764575 | AN16: 0.30305283 | AP16: 4.7362072 | AQ16: 0.22211672 | AS16: 50.082607 | AT16: 0.52351064 | AV16: 28.948818 | AW16: 0.5776165 | AY16: 11.977832 | AZ16: 0.36926884 | BB16: 8.990743 | BC16: 0.31544159 | BE16: 73.720989 | BF16: 0.51067101 | BH16: 17.147965 | BI16: 0.42851912 | BK16: 5.9339726 | BL16: 0.25078982 | BN16: 3.1970738 | BO16: 0.16778242 | BQ16: 78.643565 | BR16: 0.50138142 | BT16: 14.18199 | BU16: 0.44752047 | BW16: 4.5675604 | BX16: 0.22220479 | BZ16: 2.6068843 | CA16: 0.15252934 | CC16: 76.368539 | CD16: 0.46632352 | CF16: 14.459168 | CG16: 0.41796792 | CI16: 5.765514 | CJ16: 0.22208591 | CL16: 3.4067792 | CM16: 0.18782783 | CO16: 67.924886 | CP16: 0.54760806 | CR16: 19.547491 | CS16: 0.39644188 | CU16: 8.0791896 | CV16: 0.29278497 | CX16: 4.4484332 | CY16: 0.20249801
A17: Austria | B17: -0.023609453 | C17: 0.018621401 | E17: 0.97403083 | F17: 0.018196857 | H17: 0.90926886 | I17: 0.037815243 | K17: 0.033820168 | L17: 0.0069429406 | N17: 0.8754487 | O17: 0.030872302 | Q17: 3.7194903 | R17: 6.8246801 | S17: 0.50283809 | U17: 46.906132 | V17: 0.86827782 | X17: 29.923764 | Y17: 0.68155146 | AA17: 13.380811 | AB17: 0.56791304 | AD17: 9.7892924 | AE17: 0.53147186 | AG17: 80.135393 | AH17: 0.679282 | AJ17: 12.774113 | AK17: 0.50542918 | AM17: 4.3464772 | AN17: 0.29816346 | AP17: 2.7440163 | AQ17: 0.29947825 | AS17: 58.164071 | AT17: 0.90029797 | AV17: 27.400889 | AW17: 0.81317947 | AY17: 9.0312994 | AZ17: 0.43646102 | BB17: 5.4037411 | BC17: 0.4384542 | BE17: 86.228359 | BF17: 0.71018749 | BH17: 8.0581735 | BI17: 0.47956575 | BK17: 4.1283516 | BL17: 0.37915344 | BN17: 1.5851162 | BO17: 0.22687446 | BQ17: 77.620487 | BR17: 0.88042763 | BT17: 14.521967 | BU17: 0.64029476 | BW17: 5.4152191 | BX17: 0.42099838 | BZ17: 2.4423272 | CA17: 0.25951129 | CC17: 84.083836 | CD17: 0.7142759 | CF17: 8.6781768 | CG17: 0.46847457 | CI17: 4.5713511 | CJ17: 0.35629717 | CL17: 2.6666357 | CM17: 0.26699149 | CO17: 71.819228 | CP17: 0.74913998 | CR17: 17.288142 | CS17: 0.59080305 | CU17: 6.9985583 | CV17: 0.3634622 | CX17: 3.8940718 | CY17: 0.35775468
A18: Belgium | B18: -0.11024264 | C18: 0.011777944 | E18: 0.88851901 | F18: 0.0097276346 | H18: 0.77958614 | I18: 0.025400624 | K18: 0.018110971 | L18: 0.0039105938 | N18: 0.76147519 | O18: 0.021490031 | Q18: 2.3231521 | R18: 5.2543409 | S18: 0.24390081 | U18: 45.716535 | V18: 0.6467168 | X18: 35.65125 | Y18: 0.63435901 | AA18: 11.604962 | AB18: 0.36889346 | AD18: 7.0272531 | AE18: 0.32082269 | AG18: 81.358712 | AH18: 0.52278623 | AJ18: 13.072746 | AK18: 0.48988757 | AM18: 3.3468457 | AN18: 0.23947497 | AP18: 2.2216968 | AQ18: 0.16270035 | AS18: 62.382997 | AT18: 0.64643894 | AV18: 26.54715 | AW18: 0.53172302 | AY18: 6.9815971 | AZ18: 0.28878673 | BB18: 4.0882562 | BC18: 0.27677301 | BE18: 87.988538 | BF18: 0.42326303 | BH18: 8.784775 | BI18: 0.33498555 | BK18: 2.3307812 | BL18: 0.19463623 | BN18: 0.89590574 | BO18: 0.11710189 | BQ18: 86.634353 | BR18: 0.42305593 | BT18: 10.111806 | BU18: 0.35506226 | BW18: 2.4354448 | BX18: 0.19718305 | BZ18: 0.81839602 | CA18: 0.12749526 | CC18: 86.514429 | CD18: 0.47433566 | CF18: 9.2979889 | CG18: 0.36226911 | CI18: 2.7622084 | CJ18: 0.22238487 | CL18: 1.4253738 | CM18: 0.14590619 | CO18: 69.35591 | CP18: 0.659797 | CR18: 22.123257 | CS18: 0.56408216 | CU18: 5.94885 | CV18: 0.30718991 | CX18: 2.5719833 | CY18: 0.18346596
A19: Canada | B19: 0.13718011 | C19: 0.012549152 | E19: 1.0442537 | F19: 0.0086388408 | H19: 1.0822023 | I19: 0.025136875 | K19: 0.045348328 | L19: 0.0061943311 | N19: 1.036854 | O19: 0.018942544 | Q19: 4.1903744 | R19: 9.2792586 | S19: 0.33570717 | U19: 43.432962 | V19: 0.57220956 | X19: 31.360924 | Y19: 0.48832606 | AA19: 15.192076 | AB19: 0.39666453 | AD19: 10.014039 | AE19: 0.30730252 | AG19: 64.58874 | AH19: 0.56620958 | AJ19: 24.407901 | AK19: 0.42512351 | AM19: 7.5487203 | AN19: 0.26562788 | AP19: 3.4546379 | AQ19: 0.17238623 | AS19: 57.680994 | AT19: 0.526755 | AV19: 25.657224 | AW19: 0.47245424 | AY19: 10.135312 | AZ19: 0.33807478 | BB19: 6.52647 | BC19: 0.27324866 | BE19: 81.1941 | BF19: 0.52604985 | BH19: 12.60953 | BI19: 0.4415963 | BK19: 3.9726063 | BL19: 0.20399197 | BN19: 2.2237638 | BO19: 0.16592003 | BQ19: 84.256497 | BR19: 0.43636562 | BT19: 10.703503 | BU19: 0.33892789 | BW19: 3.4130118 | BX19: 0.1856084 | BZ19: 1.6269879 | CA19: 0.13975869 | CC19: 80.837758 | CD19: 0.46441017 | CF19: 11.956163 | CG19: 0.36755332 | CI19: 4.4786078 | CJ19: 0.20090633 | CL19: 2.7274717 | CM19: 0.17683345 | CO19: 73.527477 | CP19: 0.45412646 | CR19: 16.834106 | CS19: 0.38766763 | CU19: 6.2898188 | CV19: 0.26776832 | CX19: 3.3485981 | CY19: 0.2001896
A20: Chile | B20: 0.0034995231 | C20: 0.0158877 | D20: † | E20: 1.0017883 | F20: 0.017107387 | G20: † | H20: 0.96933973 | I20: 0.035064373 | J20: † | K20: 0.010413814 | L20: 0.0052874926 | M20: † | N20: 0.95892592 | O20: 0.029776882 | P20: † | Q20: 1.0743203 | R20: 7.8194261 | S20: 0.42522712 | T20: † | U20: 46.159643 | V20: 0.7132302 | W20: † | X20: 29.988965 | Y20: 0.64291498 | Z20: † | AA20: 15.52856 | AB20: 0.56223556 | AC20: † | AD20: 8.3228326 | AE20: 0.43546035 | AF20: † | AG20: 69.163231 | AH20: 0.68887072 | AI20: † | AJ20: 20.645937 | AK20: 0.66245243 | AL20: † | AM20: 7.7277779 | AN20: 0.44286289 | AO20: † | AP20: 2.4630544 | AQ20: 0.24242061 | AR20: † | AS20: 63.965971 | AT20: 0.73436907 | AU20: † | AV20: 22.612512 | AW20: 0.61340117 | AX20: † | AY20: 9.4066076 | AZ20: 0.44191835 | BA20: † | BB20: 4.0149095 | BC20: 0.35706138 | BD20: † | BE20: 84.081347 | BF20: 0.74229261 | BG20: † | BH20: 9.4913777 | BI20: 0.58789148 | BJ20: † | BK20: 4.5062807 | BL20: 0.33478986 | BM20: † | BN20: 1.9209944 | BO20: 0.28199564 | BP20: † | BQ20: 78.320801 | BR20: 0.64482615 | BS20: † | BT20: 13.36006 | BU20: 0.50914548 | BV20: † | BW20: 6.0704665 | BX20: 0.40683168 | BY20: † | BZ20: 2.2486726 | CA20: 0.25303493 | CB20: † | CC20: 83.180106 | CD20: 0.67974311 | CE20: † | CF20: 10.273546 | CG20: 0.45772349 | CH20: † | CI20: 4.7485194 | CJ20: 0.37894066 | CK20: † | CL20: 1.7978289 | CM20: 0.25658981 | CN20: † | CO20: 68.471046 | CP20: 0.84876504 | CQ20: † | CR20: 18.91437 | CS20: 0.64966424 | CT20: † | CU20: 8.3501297 | CV20: 0.42616275 | CW20: † | CX20: 4.2644546 | CY20: 0.34389895 | CZ20: †
A21: Colombia | B21: 0.1819149 | C21: 0.022002047 | D21: † | E21: 1.0874944 | F21: 0.014489453 | G21: † | H21: 1.1693001 | I21: 0.043497425 | J21: † | K21: 0.034595148 | L21: 0.011520438 | M21: † | N21: 1.1347049 | O21: 0.031976986 | P21: † | Q21: 2.9586201 | R21: 11.676818 | S21: 0.53561621 | T21: † | U21: 41.256476 | V21: 0.79002302 | W21: † | X21: 26.4347 | Y21: 0.75881112 | Z21: † | AA21: 20.135173 | AB21: 0.80696523 | AC21: † | AD21: 12.17365 | AE21: 0.55520733 | AF21: † | AG21: 63.884676 | AH21: 0.70624346 | AI21: † | AJ21: 20.229552 | AK21: 0.57471241 | AL21: † | AM21: 11.753094 | AN21: 0.58098099 | AO21: † | AP21: 4.1326777 | AQ21: 0.31295783 | AR21: † | AS21: 57.189398 | AT21: 1.0406265 | AU21: † | AV21: 24.718876 | AW21: 0.73206784 | AX21: † | AY21: 12.966982 | AZ21: 0.63963078 | BA21: † | BB21: 5.1247444 | BC21: 0.38026961 | BD21: † | BE21: 78.690757 | BF21: 0.85159642 | BG21: † | BH21: 10.728832 | BI21: 0.46654021 | BJ21: † | BK21: 8.0753433 | BL21: 0.55986896 | BM21: † | BN21: 2.5050669 | BO21: 0.25429993 | BP21: † | BQ21: 74.592079 | BR21: 0.86393507 | BS21: † | BT21: 13.158189 | BU21: 0.52095672 | BV21: † | BW21: 9.0313731 | BX21: 0.50648778 | BY21: † | BZ21: 3.2183591 | CA21: 0.30590829 | CB21: † | CC21: 77.310582 | CD21: 0.90795037 | CE21: † | CF21: 11.502293 | CG21: 0.55558195 | CH21: † | CI21: 7.9223488 | CJ21: 0.50292246 | CK21: † | CL21: 3.2647755 | CM21: 0.27604246 | CN21: † | CO21: 62.174849 | CP21: 0.82190685 | CQ21: † | CR21: 19.851229 | CS21: 0.65381362 | CT21: † | CU21: 11.705439 | CV21: 0.52011439 | CW21: † | CX21: 6.2684826 | CY21: 0.39811455 | CZ21: †
A22: Czech Republic | B22: 0.01948318 | C22: 0.020388047 | E22: 1.0251911 | F22: 0.016062416 | H22: 1.0152161 | I22: 0.03791824 | K22: 0.047257342 | L22: 0.009572599 | N22: 0.96795878 | O22: 0.028345642 | Q22: 4.6549048 | R22: 8.2388914 | S22: 0.42623339 | U22: 42.134378 | V22: 0.85253227 | X22: 28.166146 | Y22: 0.64649664 | AA22: 15.931689 | AB22: 0.57572965 | AD22: 13.767786 | AE22: 0.58854137 | AG22: 69.604434 | AH22: 0.78130343 | AJ22: 18.242857 | AK22: 0.60040718 | AM22: 7.5480357 | AN22: 0.36311832 | AP22: 4.6046726 | AQ22: 0.35227584 | AS22: 64.810702 | AT22: 0.92249708 | AV22: 21.504665 | AW22: 0.73497768 | AY22: 8.6126061 | AZ22: 0.48222815 | BB22: 5.072027 | BC22: 0.37044985 | BE22: 84.787484 | BF22: 0.68620034 | BH22: 8.192253 | BI22: 0.43717927 | BK22: 4.5806352 | BL22: 0.35943389 | BN22: 2.4396275 | BO22: 0.26276786 | BQ22: 73.845258 | BR22: 0.88700994 | BT22: 16.052434 | BU22: 0.60134137 | BW22: 5.9670074 | BX22: 0.37623962 | BZ22: 4.1353007 | CA22: 0.341791 | CC22: 75.723474 | CD22: 0.82164209 | CF22: 14.342832 | CG22: 0.512905 | CI22: 5.9255713 | CJ22: 0.38567565 | CL22: 4.0081228 | CM22: 0.30031131 | CO22: 64.092572 | CP22: 0.8885226 | CR22: 21.349441 | CS22: 0.61750118 | CU22: 8.5383807 | CV22: 0.50453622 | CX22: 6.0196063 | CY22: 0.45948292
A23: Denmark | B23: 0.02760859 | C23: 0.016926461 | E23: 0.8919608 | F23: 0.012278154 | H23: 0.79033583 | I23: 0.025885073 | K23: 0.02365825 | L23: 0.0058135684 | N23: 0.76667756 | O23: 0.020071506 | Q23: 2.9934428 | R23: 5.007056 | S23: 0.38102859 | U23: 38.706726 | V23: 0.95777892 | X23: 39.896762 | Y23: 0.76340489 | AA23: 13.813943 | AB23: 0.50107036 | AD23: 7.5825693 | AE23: 0.40639218 | AG23: 72.47841 | AH23: 0.73723861 | AJ23: 21.325317 | AK23: 0.66215943 | AM23: 4.487529 | AN23: 0.33973103 | AP23: 1.7087449 | AQ23: 0.19528528 | AS23: 55.415428 | AT23: 0.92039305 | AV23: 31.104674 | AW23: 0.77683174 | AY23: 9.221807 | AZ23: 0.42170958 | BB23: 4.2580907 | BC23: 0.30126535 | BE23: 88.867673 | BF23: 0.5938701 | BH23: 8.2483902 | BI23: 0.45215351 | BK23: 1.8848932 | BL23: 0.21559436 | BN23: 0.99904371 | BO23: 0.14240627 | BQ23: 77.51955 | BR23: 0.76344628 | BT23: 17.913854 | BU23: 0.62142547 | BW23: 3.283371 | BX23: 0.29413329 | BZ23: 1.283225 | CA23: 0.18436906 | CC23: 81.30843 | CD23: 0.74463814 | CF23: 12.671995 | CG23: 0.54462231 | CI23: 3.4352519 | CJ23: 0.31107107 | CL23: 2.5843231 | CM23: 0.26243583 | CO23: 70.970906 | CP23: 0.67173298 | CR23: 21.917745 | CS23: 0.49324969 | CU23: 5.4051122 | CV23: 0.41659132 | CX23: 1.7062363 | CY23: 0.20496326
A24: Estonia | B24: 0.077707735 | C24: 0.016121734 | E24: 0.98656959 | F24: 0.010233877 | H24: 0.96856081 | I24: 0.02977314 | K24: 0.022259855 | L24: 0.0068601724 | N24: 0.94630098 | O24: 0.022912968 | Q24: 2.2982404 | R24: 8.2603413 | S24: 0.40122335 | U24: 44.768888 | V24: 0.87905051 | X24: 29.79405 | Y24: 0.79421752 | AA24: 15.820365 | AB24: 0.65083909 | AD24: 9.6166971 | AE24: 0.49077611 | AG24: 72.279187 | AH24: 0.68724923 | AJ24: 19.365043 | AK24: 0.64237531 | AM24: 5.6401552 | AN24: 0.31328943 | AP24: 2.715615 | AQ24: 0.24612226 | AS24: 55.396377 | AT24: 0.91459809 | AV24: 27.120969 | AW24: 0.83601155 | AY24: 11.717846 | AZ24: 0.53548275 | BB24: 5.7648082 | BC24: 0.34740143 | BE24: 84.38303 | BF24: 0.60186265 | BH24: 9.8658487 | BI24: 0.52242465 | BK24: 4.0760588 | BL24: 0.3389395 | BN24: 1.6750623 | BO24: 0.21802696 | BQ24: 81.790122 | BR24: 0.74566606 | BT24: 11.839597 | BU24: 0.64848811 | BW24: 4.6316569 | BX24: 0.31858283 | BZ24: 1.7386242 | CA24: 0.18469741 | CC24: 81.668834 | CD24: 0.7016453 | CF24: 11.553747 | CG24: 0.54545463 | CI24: 4.6342962 | CJ24: 0.33389454 | CL24: 2.1431226 | CM24: 0.25406207 | CO24: 74.502506 | CP24: 0.7439104 | CR24: 16.61474 | CS24: 0.59305215 | CU24: 6.1805174 | CV24: 0.37805763 | CX24: 2.7022373 | CY24: 0.24856226
A25: Finland | B25: -0.030802344 | C25: 0.015794613 | E25: 0.96165464 | F25: 0.014678994 | H25: 0.92575514 | I25: 0.034459226 | K25: 0.019463643 | L25: 0.0052692754 | N25: 0.90629148 | O25: 0.02918995 | Q25: 2.1024613 | R25: 6.2019961 | S25: 0.37024829 | U25: 49.341088 | V25: 0.71213282 | X25: 32.934288 | Y25: 0.65743293 | AA25: 10.606248 | AB25: 0.40523219 | AD25: 7.1183756 | AE25: 0.4129579 | AG25: 74.073302 | AH25: 0.66374933 | AJ25: 18.97954 | AK25: 0.58539092 | AM25: 4.1795695 | AN25: 0.30489573 | AP25: 2.7675891 | AQ25: 0.25830255 | AS25: 61.808192 | AT25: 0.79347735 | AV25: 26.379604 | AW25: 0.6464923 | AY25: 7.563258 | AZ25: 0.37517234 | BB25: 4.2489462 | BC25: 0.30062076 | BE25: 84.947172 | BF25: 0.60786048 | BH25: 10.881544 | BI25: 0.50638045 | BK25: 2.5727375 | BL25: 0.23290586 | BN25: 1.5985461 | BO25: 0.21626046 | BQ25: 87.513371 | BR25: 0.45123145 | BT25: 9.2620215 | BU25: 0.39146757 | BW25: 2.0942956 | BX25: 0.21185481 | BZ25: 1.1303115 | CA25: 0.18592166 | CC25: 84.088566 | CD25: 0.63028286 | CF25: 10.77897 | CG25: 0.46556419 | CI25: 2.803402 | CJ25: 0.24636525 | CL25: 2.3290614 | CM25: 0.2507398 | CO25: 74.883118 | CP25: 0.65242819 | CR25: 17.792198 | CS25: 0.54919758 | CU25: 4.8987091 | CV25: 0.34942024 | CX25: 2.425975 | CY25: 0.24086261
A26: France | B26: -0.077417456 | C26: 0.015470527 | E26: 0.98194018 | F26: 0.013516596 | H26: w | I26: w | K26: w | L26: w | N26: w | O26: w | Q26: w | R26: 6.7896117 | S26: 0.32568104 | U26: 51.283856 | V26: 0.76548565 | X26: 28.926445 | Y26: 0.70478155 | AA26: 11.892486 | AB26: 0.50437195 | AD26: 7.8972118 | AE26: 0.4005188 | AG26: 78.452917 | AH26: 0.67472795 | AJ26: 13.868326 | AK26: 0.5404663 | AM26: 4.6420223 | AN26: 0.34592051 | AP26: 3.0367355 | AQ26: 0.26731247 | AS26: 64.113754 | AT26: 0.79955076 | AV26: 23.657433 | AW26: 0.68738039 | AY26: 7.5595608 | AZ26: 0.39234933 | BB26: 4.6692521 | BC26: 0.31890445 | BE26: 85.801823 | BF26: 0.57929185 | BH26: 8.5982535 | BI26: 0.39389955 | BK26: 3.6403208 | BL26: 0.32528325 | BN26: 1.9596032 | BO26: 0.19700868 | BQ26: 85.179541 | BR26: 0.61789455 | BT26: 9.2260441 | BU26: 0.44466341 | BW26: 3.7141477 | BX26: 0.29240422 | BZ26: 1.8802675 | CA26: 0.20630728 | CC26: 86.106679 | CD26: 0.58959528 | CF26: 8.447441 | CG26: 0.41658198 | CI26: 3.5570383 | CJ26: 0.29136542 | CL26: 1.8888416 | CM26: 0.22564705 | CO26: 74.072094 | CP26: 0.76389426 | CR26: 16.864977 | CS26: 0.5722705 | CU26: 5.9528479 | CV26: 0.37111191 | CX26: 3.1100809 | CY26: 0.29669777
A27: Germany | B27: -0.010656097 | C27: 0.021992191 | D27: ‡ | E27: 0.92660591 | F27: 0.015598932 | G27: ‡ | H27: 0.85065955 | I27: 0.040612832 | J27: ‡ | K27: 0.015590077 | L27: 0.0092485558 | M27: ‡ | N27: 0.83506945 | O27: 0.031364277 | P27: ‡ | Q27: 1.8327047 | R27: 6.2415389 | S27: 0.48647164 | T27: ‡ | U27: 42.705189 | V27: 1.14291 | W27: ‡ | X27: 34.617312 | Y27: 0.87590857 | Z27: ‡ | AA27: 14.431685 | AB27: 0.83069482 | AC27: ‡ | AD27: 8.2458137 | AE27: 0.56458011 | AF27: ‡ | AG27: 77.656951 | AH27: 1.1005666 | AI27: ‡ | AJ27: 15.658082 | AK27: 0.85883778 | AL27: ‡ | AM27: 4.378138 | AN27: 0.44028534 | AO27: ‡ | AP27: 2.3068297 | AQ27: 0.29941131 | AR27: ‡ | AS27: 56.745599 | AT27: 1.0832864 | AU27: ‡ | AV27: 29.982887 | AW27: 0.99440254 | AX27: ‡ | AY27: 8.1581357 | AZ27: 0.61053113 | BA27: ‡ | BB27: 5.1133785 | BC27: 0.46572891 | BD27: ‡ | BE27: 87.627456 | BF27: 0.73399624 | BG27: ‡ | BH27: 7.2287205 | BI27: 0.53117006 | BJ27: ‡ | BK27: 4.1785381 | BL27: 0.4419397 | BM27: ‡ | BN27: 0.96528523 | BO27: 0.17496599 | BP27: ‡ | BQ27: 78.138255 | BR27: 1.0017636 | BS27: ‡ | BT27: 14.835087 | BU27: 0.87260663 | BV27: ‡ | BW27: 5.2480907 | BX27: 0.57319453 | BY27: ‡ | BZ27: 1.778567 | CA27: 0.25538583 | CB27: ‡ | CC27: 87.006045 | CD27: 0.8056364 | CE27: ‡ | CF27: 8.0412883 | CG27: 0.61518281 | CH27: ‡ | CI27: 3.5408338 | CJ27: 0.38656566 | CK27: ‡ | CL27: 1.4118327 | CM27: 0.24812654 | CN27: ‡ | CO27: 70.444401 | CP27: 1.0196741 | CQ27: ‡ | CR27: 19.310264 | CS27: 0.85741085 | CT27: ‡ | CU27: 7.8090709 | CV27: 0.55032532 | CW27: ‡ | CX27: 2.4362637 | CY27: 0.32123209 | CZ27: ‡
A28: Greece | B28: 0.0059771257 | C28: 0.018447183 | E28: 1.0009066 | F28: 0.015073115 | H28: 0.9868719 | I28: 0.036153071 | K28: 0.02859852 | L28: 0.006692619 | N28: 0.95827338 | O28: 0.029460453 | Q28: 2.8978958 | R28: 7.614476 | S28: 0.43945951 | U28: 47.935342 | V28: 0.79857609 | X28: 25.126161 | Y28: 0.56899655 | AA28: 14.866233 | AB28: 0.54664812 | AD28: 12.072264 | AE28: 0.48168934 | AG28: 80.496979 | AH28: 0.66189915 | AJ28: 11.936193 | AK28: 0.48657066 | AM28: 4.4375562 | AN28: 0.33953778 | AP28: 3.129272 | AQ28: 0.24706081 | AS28: 57.81192 | AT28: 0.80196679 | AV28: 25.236803 | AW28: 0.59019316 | AY28: 10.660535 | AZ28: 0.46665207 | BB28: 6.2907414 | BC28: 0.3187574 | BE28: 84.665262 | BF28: 0.77114219 | BH28: 7.824505 | BI28: 0.42175038 | BK28: 5.3333246 | BL28: 0.45344935 | BN28: 2.1769085 | BO28: 0.23352912 | BQ28: 79.125429 | BR28: 0.74158762 | BT28: 11.637764 | BU28: 0.43603168 | BW28: 5.908532 | BX28: 0.37482637 | BZ28: 3.328275 | CA28: 0.31108257 | CC28: 81.812717 | CD28: 0.77956795 | CF28: 9.1004107 | CG28: 0.44541466 | CI28: 6.1216268 | CJ28: 0.44711865 | CL28: 2.9652456 | CM28: 0.2207856 | CO28: 73.876151 | CP28: 0.93467595 | CR28: 14.883808 | CS28: 0.61526813 | CU28: 7.1626114 | CV28: 0.4492533 | CX28: 4.0774294 | CY28: 0.29704507
A29: Hungary | B29: -0.10867046 | C29: 0.020324703 | E29: 0.99347065 | F29: 0.017822354 | H29: 0.93743521 | I29: 0.0475532 | K29: 0.055822743 | L29: 0.011343577 | N29: 0.88161244 | O29: 0.036209625 | Q29: 5.9548373 | R29: 7.4226411 | S29: 0.42352167 | U29: 52.552053 | V29: 0.98265167 | X29: 24.872841 | Y29: 0.80801801 | AA29: 12.762574 | AB29: 0.54609941 | AD29: 9.8125318 | AE29: 0.56992314 | AG29: 71.663977 | AH29: 0.77147164 | AJ29: 17.684919 | AK29: 0.60022763 | AM29: 6.8456682 | AN29: 0.39699628 | AP29: 3.8054355 | AQ29: 0.26573344 | AS29: 72.227984 | AT29: 0.8742856 | AV29: 16.628714 | AW29: 0.68262179 | AY29: 7.3089775 | AZ29: 0.45811312 | BB29: 3.8343252 | BC29: 0.31882636 | BE29: 85.19597 | BF29: 0.84608853 | BH29: 8.2435244 | BI29: 0.52453068 | BK29: 4.7161417 | BL29: 0.40418366 | BN29: 1.8443636 | BO29: 0.22259102 | BQ29: 82.792004 | BR29: 0.86593472 | BT29: 9.9188911 | BU29: 0.60222755 | BW29: 5.1184981 | BX29: 0.38530199 | BZ29: 2.1706067 | CA29: 0.25442292 | CC29: 84.920982 | CD29: 0.864946 | CF29: 7.8799798 | CG29: 0.47560833 | CI29: 4.6072584 | CJ29: 0.36939579 | CL29: 2.59178 | CM29: 0.3077342 | CO29: 69.131051 | CP29: 0.91381367 | CR29: 17.43079 | CS29: 0.636026 | CU29: 8.3456379 | CV29: 0.48506529 | CX29: 5.0925206 | CY29: 0.45106657
A30: Iceland | B30: -0.18852264 | C30: 0.018246701 | D30: † | E30: 0.92442515 | F30: 0.019958522 | G30: † | H30: 0.88365835 | I30: 0.057375036 | J30: † | K30: 0.011227844 | L30: 0.0053192776 | M30: † | N30: 0.87243053 | O30: 0.052055757 | P30: † | Q30: 1.2706093 | R30: 4.9387446 | S30: 0.43525492 | T30: † | U30: 62.582171 | V30: 0.93777432 | W30: † | X30: 20.20762 | Y30: 0.79720181 | Z30: † | AA30: 10.324717 | AB30: 0.6378755 | AC30: † | AD30: 6.8854921 | AE30: 0.44811323 | AF30: † | AG30: 84.376132 | AH30: 0.77856225 | AI30: † | AJ30: 10.003368 | AK30: 0.65397985 | AL30: † | AM30: 3.4675375 | AN30: 0.36548963 | AO30: † | AP30: 2.1529629 | AQ30: 0.31487508 | AR30: † | AS30: 70.541001 | AT30: 0.92170153 | AU30: † | AV30: 17.905452 | AW30: 0.79975969 | AX30: † | AY30: 7.288756 | AZ30: 0.52474495 | BA30: † | BB30: 4.2647914 | BC30: 0.39448574 | BD30: † | BE30: 86.229141 | BF30: 0.70023752 | BG30: † | BH30: 9.1409993 | BI30: 0.55142333 | BJ30: † | BK30: 3.3644773 | BL30: 0.39294459 | BM30: † | BN30: 1.2653825 | BO30: 0.25191714 | BP30: † | BQ30: 89.997965 | BR30: 0.55921732 | BS30: † | BT30: 6.8865351 | BU30: 0.47053408 | BV30: † | BW30: 1.9629943 | BX30: 0.28596788 | BY30: † | BZ30: 1.1525056 | CA30: 0.19663059 | CB30: † | CC30: 89.286155 | CD30: 0.64138595 | CE30: † | CF30: 6.9516694 | CG30: 0.52817654 | CH30: † | CI30: 2.7360167 | CJ30: 0.35053927 | CK30: † | CL30: 1.0261594 | CM30: 0.17809495 | CN30: † | CO30: 83.598618 | CP30: 0.70923066 | CQ30: † | CR30: 10.843283 | CS30: 0.64473975 | CT30: † | CU30: 3.8355552 | CV30: 0.42010956 | CW30: † | CX30: 1.722544 | CY30: 0.23814125 | CZ30: †
A31: Ireland | B31: 0.13336397 | C31: 0.015024697 | E31: 1.0133383 | F31: 0.012063864 | H31: 1.0260116 | I31: 0.033604175 | K31: 0.012691776 | L31: 0.0049288747 | N31: 1.0133198 | O31: 0.028675301 | Q31: 1.2370012 | R31: 8.7499547 | S31: 0.4141836 | U31: 41.124686 | V31: 0.81747584 | X31: 36.202085 | Y31: 0.76611844 | AA31: 12.795537 | AB31: 0.51926909 | AD31: 9.8776912 | AE31: 0.42297483 | AG31: 65.300564 | AH31: 0.7427811 | AJ31: 26.13801 | AK31: 0.7071947 | AM31: 5.5568987 | AN31: 0.35253129 | AP31: 3.0045272 | AQ31: 0.24077771 | AS31: 55.445101 | AT31: 0.72481066 | AV31: 28.715794 | AW31: 0.63959531 | AY31: 8.8975391 | AZ31: 0.46345667 | BB31: 6.9415658 | BC31: 0.35654311 | BE31: 81.352596 | BF31: 0.60211577 | BH31: 12.991964 | BI31: 0.52224221 | BK31: 3.7048466 | BL31: 0.3280844 | BN31: 1.9505934 | BO31: 0.20789802 | BQ31: 79.235036 | BR31: 0.59762249 | BT31: 15.343444 | BU31: 0.50860504 | BW31: 3.7989067 | BX31: 0.25535702 | BZ31: 1.6226131 | CA31: 0.19613824 | CC31: 81.785803 | CD31: 0.52978473 | CF31: 12.248775 | CG31: 0.4286432 | CI31: 3.608711 | CJ31: 0.28102925 | CL31: 2.3567104 | CM31: 0.18993995 | CO31: 73.907892 | CP31: 0.73133646 | CR31: 18.128202 | CS31: 0.57082594 | CU31: 5.0769276 | CV31: 0.40011737 | CX31: 2.8869783 | CY31: 0.26756335
A32: Israel | B32: m | C32: m | E32: m | F32: m | H32: m | I32: m | K32: m | L32: m | N32: m | O32: m | Q32: m | R32: m | S32: m | U32: m | V32: m | X32: m | Y32: m | AA32: m | AB32: m | AD32: m | AE32: m | AG32: m | AH32: m | AJ32: m | AK32: m | AM32: m | AN32: m | AP32: m | AQ32: m | AS32: m | AT32: m | AV32: m | AW32: m | AY32: m | AZ32: m | BB32: m | BC32: m | BE32: m | BF32: m | BH32: m | BI32: m | BK32: m | BL32: m | BN32: m | BO32: m | BQ32: m | BR32: m | BT32: m | BU32: m | BW32: m | BX32: m | BZ32: m | CA32: m | CC32: m | CD32: m | CF32: m | CG32: m | CI32: m | CJ32: m | CL32: m | CM32: m | CO32: m | CP32: m | CR32: m | CS32: m | CU32: m | CV32: m | CX32: m | CY32: m
A33: Italy | B33: -0.069152665 | C33: 0.017349977 | E33: 1.0168723 | F33: 0.016252183 | H33: 0.99171418 | I33: 0.042218778 | K33: 0.048563487 | L33: 0.01043258 | N33: 0.9431507 | O33: 0.031786199 | Q33: 4.8969235 | R33: 7.8779032 | S33: 0.42713115 | U33: 53.390741 | V33: 0.72487801 | X33: 22.906444 | Y33: 0.69380006 | AA33: 12.926454 | AB33: 0.55148512 | AD33: 10.776361 | AE33: 0.51021526 | AG33: 72.131775 | AH33: 0.64268184 | AJ33: 17.858068 | AK33: 0.57903022 | AM33: 6.5614869 | AN33: 0.41655147 | AP33: 3.4486703 | AQ33: 0.34847173 | AS33: 70.065886 | AT33: 0.77749918 | AV33: 18.453462 | AW33: 0.56563782 | AY33: 7.9041111 | AZ33: 0.41908065 | BB33: 3.5765407 | BC33: 0.29841898 | BE33: 81.85068 | BF33: 0.8041094 | BH33: 9.3999541 | BI33: 0.5517849 | BK33: 6.7044906 | BL33: 0.47189014 | BN33: 2.0448749 | BO33: 0.22140606 | BQ33: 76.297013 | BR33: 0.81495373 | BT33: 12.67592 | BU33: 0.54867733 | BW33: 7.2363203 | BX33: 0.44359588 | BZ33: 3.7907463 | CA33: 0.33243377 | CC33: 83.550205 | CD33: 0.85658093 | CF33: 7.7511434 | CG33: 0.5492389 | CI33: 6.200887 | CJ33: 0.45737346 | CL33: 2.4977642 | CM33: 0.28176519 | CO33: 73.000349 | CP33: 0.82082739 | CR33: 15.197168 | CS33: 0.57049512 | CU33: 7.3305406 | CV33: 0.41406012 | CX33: 4.4719422 | CY33: 0.39610921
A34: Japan | B34: -0.28281949 | C34: 0.014508945 | E34: 0.86591074 | F34: 0.013867817 | H34: 0.7484951 | I34: 0.031146953 | K34: 0.023264106 | L34: 0.0068564897 | N34: 0.72523101 | O34: 0.024290463 | Q34: 3.1081173 | R34: 4.3187924 | S34: 0.31577132 | U34: 65.342508 | V34: 0.88328705 | X34: 17.389914 | Y34: 0.58895521 | AA34: 8.6284446 | AB34: 0.40841848 | AD34: 8.6391339 | AE34: 0.46770783 | AG34: 89.036388 | AH34: 0.39581724 | AJ34: 7.4033119 | AK34: 0.35356955 | AM34: 1.9373393 | AN34: 0.16956864 | AP34: 1.6229605 | AQ34: 0.1741153 | AS34: 73.209483 | AT34: 0.75400821 | AV34: 12.974931 | AW34: 0.43505836 | AY34: 6.8593762 | AZ34: 0.3607211 | BB34: 6.9562093 | BC34: 0.40290152 | BE34: 94.658973 | BF34: 0.35346306 | BH34: 3.0036361 | BI34: 0.23785614 | BK34: 1.3353409 | BL34: 0.15445507 | BN34: 1.0020501 | BO34: 0.13830155 | BQ34: 91.127336 | BR34: 0.49231706 | BT34: 6.0871045 | BU34: 0.36539749 | BW34: 1.7468497 | BX34: 0.21101373 | BZ34: 1.0387098 | CA34: 0.13869932 | CC34: 86.679821 | CD34: 0.61219703 | CF34: 7.3750835 | CG34: 0.34449689 | CI34: 3.0638514 | CJ34: 0.26919291 | CL34: 2.881244 | CM34: 0.24836328 | CO34: 83.370418 | CP34: 0.66125825 | CR34: 11.374881 | CS34: 0.50748624 | CU34: 3.0130839 | CV34: 0.25374251 | CX34: 2.2416169 | CY34: 0.20765569
A35: Korea | B35: m | C35: m | E35: m | F35: m | H35: m | I35: m | K35: m | L35: m | N35: m | O35: m | Q35: m | R35: m | S35: m | U35: 80.13635 | V35: 0.67845586 | X35: 10.472438 | Y35: 0.4394105 | AA35: 4.1895251 | AB35: 0.26677063 | AD35: 5.201687 | AE35: 0.31179553 | AG35: 96.455562 | AH35: 0.29384244 | AJ35: 2.3305724 | AK35: 0.22795745 | AM35: 0.68428799 | AN35: 0.10703803 | AP35: 0.5295775 | AQ35: 0.091122007 | AS35: 85.204441 | AT35: 0.51925124 | AV35: 6.8149506 | AW35: 0.31683168 | AY35: 3.4091241 | AZ35: 0.25483098 | BB35: 4.5714842 | BC35: 0.29443513 | BE35: 97.407101 | BF35: 0.21645147 | BH35: 1.4504002 | BI35: 0.18907959 | BK35: 0.72043492 | BL35: 0.091090587 | BN35: 0.42206395 | BO35: 0.081736306 | BQ35: 95.638105 | BR35: 0.28307566 | BT35: 3.1580246 | BU35: 0.22220065 | BW35: 0.70334149 | BX35: 0.11614708 | BZ35: 0.50052937 | CA35: 0.099971131 | CC35: 98.033554 | CD35: 0.20620876 | CF35: 0.9847201 | CG35: 0.13182796 | CI35: 0.55151982 | CJ35: 0.11408125 | CL35: 0.43020575 | CM35: 0.10678068 | CO35: 91.39063 | CP35: 0.48107077 | CR35: 6.2981285 | CS35: 0.3493242 | CU35: 1.410912 | CV35: 0.15068522 | CX35: 0.90032915 | CY35: 0.16349841
A36: Latvia | B36: 0.37125195 | C36: 0.017759906 | E36: 1.0310338 | F36: 0.012615502 | H36: 1.056604 | I36: 0.034636054 | K36: 0.025484679 | L36: 0.007738201 | N36: 1.0311193 | O36: 0.026897853 | Q36: 2.4119422 | R36: 11.317449 | S36: 0.58735608 | U36: 28.807686 | V36: 0.62404374 | X36: 35.694837 | Y36: 0.65983443 | AA36: 21.685118 | AB36: 0.62960978 | AD36: 13.812359 | AE36: 0.59497727 | AG36: 53.828893 | AH36: 0.73977221 | AJ36: 30.032916 | AK36: 0.74645924 | AM36: 11.661946 | AN36: 0.50049831 | AP36: 4.4762449 | AQ36: 0.34231847 | AS36: 49.328818 | AT36: 0.77471475 | AV36: 32.939186 | AW36: 0.69348897 | AY36: 11.842766 | AZ36: 0.46796477 | BB36: 5.88923 | BC36: 0.39768638 | BE36: 72.626157 | BF36: 0.81513233 | BH36: 16.90084 | BI36: 0.63940767 | BK36: 7.7214317 | BL36: 0.45556818 | BN36: 2.751572 | BO36: 0.26588585 | BQ36: 70.320666 | BR36: 0.84175736 | BT36: 19.427381 | BU36: 0.6079926 | BW36: 7.283854 | BX36: 0.44364864 | BZ36: 2.9680998 | CA36: 0.28525907 | CC36: 66.757146 | CD36: 0.80583911 | CF36: 20.996767 | CG36: 0.64243079 | CI36: 8.6821267 | CJ36: 0.4355264 | CL36: 3.5639598 | CM36: 0.35181984 | CO36: 56.726866 | CP36: 0.82351233 | CR36: 27.173578 | CS36: 0.67634779 | CU36: 10.995166 | CV36: 0.47227621 | CX36: 5.1043896 | CY36: 0.38141288
A37: Lithuania | B37: 0.019515131 | C37: 0.01602953 | E37: 1.0686959 | F37: 0.012217794 | H37: 1.0922761 | I37: 0.042892549 | K37: 0.052502056 | L37: 0.0094540857 | N37: 1.039774 | O37: 0.033438464 | Q37: 4.8066654 | R37: 9.7060096 | S37: 0.41180819 | U37: 52.330084 | V37: 0.69424219 | X37: 25.03478 | Y37: 0.57503227 | AA37: 13.678042 | AB37: 0.52542822 | AD37: 8.9570939 | AE37: 0.46837832 | AG37: 72.426419 | AH37: 0.67436423 | AJ37: 17.544021 | AK37: 0.52414311 | AM37: 7.2614307 | AN37: 0.35044143 | AP37: 2.7681284 | AQ37: 0.21522542 | AS37: 63.364631 | AT37: 0.69405471 | AV37: 23.343083 | AW37: 0.58899441 | AY37: 9.1981148 | AZ37: 0.39525493 | BB37: 4.0941707 | BC37: 0.27038283 | BE37: 76.497688 | BF37: 0.56030792 | BH37: 13.4194 | BI37: 0.47456229 | BK37: 7.8188695 | BL37: 0.37829112 | BN37: 2.264042 | BO37: 0.18462306 | BQ37: 79.676428 | BR37: 0.59861209 | BT37: 10.807838 | BU37: 0.39797291 | BW37: 6.5251283 | BX37: 0.34324946 | BZ37: 2.9906061 | CA37: 0.24826557 | CC37: 77.607632 | CD37: 0.557159 | CF37: 11.428503 | CG37: 0.43129784 | CI37: 7.9544769 | CJ37: 0.37139527 | CL37: 3.0093876 | CM37: 0.22498352 | CO37: 71.126874 | CP37: 0.62684685 | CR37: 16.349622 | CS37: 0.49221773 | CU37: 8.3236905 | CV37: 0.38483836 | CX37: 4.1998136 | CY37: 0.29956868
A38: Luxembourg | B38: -0.04421341 | C38: 0.013412081 | E38: 0.97388491 | F38: 0.013699884 | H38: 0.95835549 | I38: 0.046682823 | K38: 0.01163238 | L38: 0.0039945607 | N38: 0.94672312 | O38: 0.042688262 | Q38: 1.2137854 | R38: 6.933977 | S38: 0.38412694 | U38: 47.628696 | V38: 0.74822378 | X38: 31.734535 | Y38: 0.73827553 | AA38: 12.740313 | AB38: 0.50230584 | AD38: 7.8964553 | AE38: 0.42366938 | AG38: 76.653633 | AH38: 0.57843525 | AJ38: 15.684777 | AK38: 0.54866047 | AM38: 4.9419143 | AN38: 0.38866976 | AP38: 2.719676 | AQ38: 0.22283565 | AS38: 61.370082 | AT38: 0.69865078 | AV38: 26.531737 | AW38: 0.73884452 | AY38: 8.0369011 | AZ38: 0.3506839 | BB38: 4.06128 | BC38: 0.30009059 | BE38: 84.886627 | BF38: 0.54908813 | BH38: 9.0801227 | BI38: 0.48718215 | BK38: 4.3393324 | BL38: 0.32962513 | BN38: 1.6939184 | BO38: 0.18931677 | BQ38: 81.647263 | BR38: 0.54843221 | BT38: 11.85822 | BU38: 0.47349944 | BW38: 4.6563307 | BX38: 0.25450815 | BZ38: 1.8381865 | CA38: 0.20480666 | CC38: 85.839472 | CD38: 0.5749885 | CF38: 7.8442013 | CG38: 0.39407317 | CI38: 4.418674 | CJ38: 0.32664606 | CL38: 1.8976527 | CM38: 0.22958495 | CO38: 70.510383 | CP38: 0.71196019 | CR38: 18.652202 | CS38: 0.5984296 | CU38: 7.0732498 | CV38: 0.37975663 | CX38: 3.7641657 | CY38: 0.29591242
A39: Mexico | B39: -0.0017078854 | C39: 0.020333237 | D39: ‡ | E39: 1.0113061 | F39: 0.015230966 | G39: ‡ | H39: 1.0029235 | I39: 0.035615988 | J39: ‡ | K39: 0.014914322 | L39: 0.0068121153 | M39: ‡ | N39: 0.98800921 | O39: 0.028803873 | P39: ‡ | Q39: 1.4870847 | R39: 8.8048093 | S39: 0.52645666 | T39: ‡ | U39: 49.217153 | V39: 0.91845373 | W39: † | X39: 27.785393 | Y39: 0.6930807 | Z39: † | AA39: 14.178224 | AB39: 0.58558888 | AC39: † | AD39: 8.8192305 | AE39: 0.58649913 | AF39: † | AG39: 71.479292 | AH39: 0.87420798 | AI39: † | AJ39: 17.077133 | AK39: 0.68107378 | AL39: † | AM39: 8.389105 | AN39: 0.44473729 | AO39: † | AP39: 3.0544699 | AQ39: 0.30109436 | AR39: † | AS39: 62.655717 | AT39: 0.8997145 | AU39: † | AV39: 23.279631 | AW39: 0.69360319 | AX39: † | AY39: 9.8639414 | AZ39: 0.55728381 | BA39: † | BB39: 4.2007102 | BC39: 0.43166994 | BD39: † | BE39: 84.067531 | BF39: 0.78544786 | BG39: † | BH39: 9.0958683 | BI39: 0.53523523 | BJ39: † | BK39: 5.1973223 | BL39: 0.40228113 | BM39: † | BN39: 1.6392785 | BO39: 0.298691 | BP39: † | BQ39: 82.55891 | BR39: 0.78256212 | BS39: † | BT39: 9.9649588 | BU39: 0.54454834 | BV39: † | BW39: 5.5310026 | BX39: 0.3956605 | BY39: † | BZ39: 1.9451288 | CA39: 0.2592785 | CB39: † | CC39: 80.8999 | CD39: 0.84763197 | CE39: ‡ | CF39: 10.836147 | CG39: 0.56023992 | CH39: ‡ | CI39: 6.3310857 | CJ39: 0.47190697 | CK39: ‡ | CL39: 1.9328669 | CM39: 0.24386033 | CN39: ‡ | CO39: 70.494667 | CP39: 0.93826646 | CQ39: ‡ | CR39: 16.263101 | CS39: 0.65142885 | CT39: ‡ | CU39: 9.4205962 | CV39: 0.54847057 | CW39: ‡ | CX39: 3.8216359 | CY39: 0.45151531 | CZ39: ‡
A40: Netherlands* | B40: -0.29753219 | C40: 0.01435891 | E40: 0.74353212 | F40: 0.015557166 | H40: 0.55501902 | I40: 0.025999483 | K40: 0.004155167 | L40: 0.0037367807 | N40: 0.55086388 | O40: 0.022262703 | Q40: 0.74865305 | R40: 2.2844642 | S40: 0.27628491 | U40: 53.756467 | V40: 1.0258697 | X40: 34.052269 | Y40: 1.0124025 | AA40: 8.2085611 | AB40: 0.46111595 | AD40: 3.9827027 | AE40: 0.3101607 | AG40: 88.506782 | AH40: 0.58725409 | AJ40: 9.0664085 | AK40: 0.51940613 | AM40: 1.4835215 | AN40: 0.22458841 | AP40: 0.94328795 | AQ40: 0.17492692 | AS40: 69.682179 | AT40: 0.84764706 | AV40: 23.787983 | AW40: 0.78949109 | AY40: 4.8976698 | AZ40: 0.33181929 | BB40: 1.6321677 | BC40: 0.21512007 | BE40: 93.071365 | BF40: 0.52956687 | BH40: 5.4267812 | BI40: 0.4574336 | BK40: 0.9433798 | BL40: 0.17509922 | BN40: 0.55847361 | BO40: 0.13226877 | BQ40: 84.433667 | BR40: 0.64852939 | BT40: 12.768081 | BU40: 0.56042138 | BW40: 1.9278399 | BX40: 0.25436388 | BZ40: 0.87041217 | CA40: 0.17756392 | CC40: 91.596606 | CD40: 0.4837119 | CF40: 5.899726 | CG40: 0.37788088 | CI40: 1.4764278 | CJ40: 0.24506507 | CL40: 1.0272401 | CM40: 0.1346493 | CO40: 75.991817 | CP40: 0.88487207 | CR40: 17.748797 | CS40: 0.83436737 | CU40: 4.4372072 | CV40: 0.34949157 | CX40: 1.8221797 | CY40: 0.22394041
A41: New Zealand | B41: 0.40193278 | C41: 0.017192171 | E41: 1.1202772 | F41: 0.011214818 | H41: 1.2427545 | I41: 0.034317043 | K41: 0.027858086 | L41: 0.007636771 | N41: 1.2148964 | O41: 0.026680273 | Q41: 2.2416403 | R41: 14.958814 | S41: 0.58965094 | U41: 32.964503 | V41: 0.67047309 | X41: 35.458034 | Y41: 0.68083268 | AA41: 17.497837 | AB41: 0.60428267 | AD41: 14.079626 | AE41: 0.51881063 | AG41: 56.398637 | AH41: 0.75519669 | AJ41: 29.722054 | AK41: 0.70638197 | AM41: 9.1532598 | AN41: 0.40386012 | AP41: 4.7260487 | AQ41: 0.30319743 | AS41: 46.434866 | AT41: 0.81152167 | AV41: 30.21548 | AW41: 0.69623666 | AY41: 13.314667 | AZ41: 0.60238194 | BB41: 10.034988 | BC41: 0.4527491 | BE41: 71.674338 | BF41: 0.7829124 | BH41: 18.428821 | BI41: 0.63532118 | BK41: 6.5020877 | BL41: 0.35671611 | BN41: 3.3947528 | BO41: 0.25776588 | BQ41: 77.73585 | BR41: 0.6870554 | BT41: 15.048242 | BU41: 0.61063096 | BW41: 4.8880463 | BX41: 0.32887405 | BZ41: 2.3278616 | CA41: 0.20314869 | CC41: 75.548228 | CD41: 0.69882258 | CF41: 15.500372 | CG41: 0.58514802 | CI41: 6.0701015 | CJ41: 0.32609665 | CL41: 2.8812991 | CM41: 0.25107171 | CO41: 65.688159 | CP41: 0.75278435 | CR41: 21.085487 | CS41: 0.67729385 | CU41: 8.2461197 | CV41: 0.34160958 | CX41: 4.9802342 | CY41: 0.30812668
A42: Norway | B42: -0.12977306 | C42: 0.015606827 | E42: 0.92615469 | F42: 0.014628723 | H42: 0.86284471 | I42: 0.032631945 | K42: 0.012700395 | L42: 0.0056841139 | N42: 0.85014428 | O42: 0.026947832 | Q42: 1.4719213 | R42: 5.0352136 | S42: 0.32884275 | U42: 50.999918 | V42: 0.83457513 | X42: 30.181671 | Y42: 0.69443545 | AA42: 11.531297 | AB42: 0.46373252 | AD42: 7.2871135 | AE42: 0.39529068 | AG42: 81.782176 | AH42: 0.53071976 | AJ42: 13.018687 | AK42: 0.41433553 | AM42: 2.9718125 | AN42: 0.25324881 | AP42: 2.2273252 | AQ42: 0.21859163 | AS42: 65.46853 | AT42: 0.79369095 | AV42: 22.627376 | AW42: 0.60575917 | AY42: 7.6740194 | AZ42: 0.40883346 | BB42: 4.230074 | BC42: 0.24988014 | BE42: 87.66666 | BF42: 0.58300625 | BH42: 8.5604655 | BI42: 0.47618548 | BK42: 2.2705156 | BL42: 0.23043949 | BN42: 1.5023587 | BO42: 0.18412217 | BQ42: 80.028974 | BR42: 0.7091599 | BT42: 15.180476 | BU42: 0.61083385 | BW42: 3.2627412 | BX42: 0.28152511 | BZ42: 1.5278088 | CA42: 0.18287172 | CC42: 84.538623 | CD42: 0.62289177 | CF42: 10.101478 | CG42: 0.43900771 | CI42: 2.7571553 | CJ42: 0.22148751 | CL42: 2.602744 | CM42: 0.23745462 | CO42: 76.512385 | CP42: 0.66153929 | CR42: 16.226683 | CS42: 0.55727955 | CU42: 4.7369801 | CV42: 0.31901776 | CX42: 2.523952 | CY42: 0.25480268
A43: Poland | B43: 0.07050888 | C43: 0.01910182 | E43: 1.0272611 | F43: 0.013189677 | H43: 1.062629 | I43: 0.037912969 | K43: 0.031130293 | L43: 0.0092619319 | N43: 1.0314987 | O43: 0.028651038 | Q43: 2.9295542 | R43: 8.2838284 | S43: 0.43370809 | U43: 42.641604 | V43: 0.85552086 | X43: 30.9988 | Y43: 0.73469038 | AA43: 15.540843 | AB43: 0.61139255 | AD43: 10.818753 | AE43: 0.49827516 | AG43: 69.203734 | AH43: 0.69419132 | AJ43: 22.189708 | AK43: 0.58055897 | AM43: 5.6208574 | AN43: 0.36873642 | AP43: 2.9857002 | AQ43: 0.24219476 | AS43: 59.287383 | AT43: 0.92036813 | AV43: 26.482714 | AW43: 0.71948021 | AY43: 8.9026911 | AZ43: 0.47866378 | BB43: 5.3272122 | BC43: 0.32974132 | BE43: 80.705751 | BF43: 0.74769435 | BH43: 11.806893 | BI43: 0.48775184 | BK43: 5.4008142 | BL43: 0.37125475 | BN43: 2.086542 | BO43: 0.21768259 | BQ43: 77.795702 | BR43: 0.84209359 | BT43: 13.399248 | BU43: 0.59857797 | BW43: 6.2033406 | BX43: 0.3920002 | BZ43: 2.6017096 | CA43: 0.25383308 | CC43: 79.535488 | CD43: 0.73477649 | CF43: 12.28373 | CG43: 0.46905534 | CI43: 5.771533 | CJ43: 0.37053042 | CL43: 2.4092489 | CM43: 0.2242778 | CO43: 59.027434 | CP43: 0.93973799 | CR43: 25.437576 | CS43: 0.73553716 | CU43: 10.356912 | CV43: 0.49653636 | CX43: 5.1780779 | CY43: 0.33585961
...

Sheet Table III.B1.2.2
A1: PISA 2018 Results (Volume III) - © OECD 2019
A2: Annex B1 | B2: Annex B1.2 Results (tables): Bullying
A3: Version 2 - Last updated: 02-Dec-2019
A4: Disclaimer: http://oe.cd/disclaimer
A6: Table III.B1.2.2
A7: Change between 2015 and 2018 in students' exposure to bullying
A8: Based on students' reports
B11: Change between 2015 and 2018 (PISA 2018 - PISA 2015)1
B12: Percentage of students who reported being bullied at school at least a few times a month:
B13: Any type of bullying act | E13: Other students left me out of things on purpose | H13: Other students made fun of me | K13: I was threatened by other students | N13: Other students took away or destroyed things that belong to me | Q13: I got hit or pushed around by other students | T13: Other students spread nasty rumours about me
B14: % dif. | C14: S.E. | E14: % dif. | F14: S.E. | H14: % dif. | I14: S.E. | K14: % dif. | L14: S.E. | N14: % dif. | O14: S.E. | Q14: % dif. | R14: S.E. | T14: % dif. | U14: S.E.
A15: OECD
A16: Australia | B16: 5.3372092 | C16: 0.72934735 | E16: 0.70971817 | F16: 0.56797367 | H16: 5.8534026 | I16: 0.60706609 | K16: 1.9595313 | L16: 0.41819313 | N16: 1.4565136 | O16: 0.3582544 | Q16: 3.4344449 | R16: 0.38502371 | T16: 1.294687 | U16: 0.51236397
A17: Austria | B17: 4.022182 | C17: 0.93947011 | E17: 1.4120175 | F17: 0.53784651 | H17: 2.5164342 | I17: 0.75483358 | K17: 2.7888803 | L17: 0.54530346 | N17: 2.5132194 | O17: 0.59959376 | Q17: 3.0114095 | R17: 0.5758087 | T17: 3.1586766 | U17: 0.6471349
A18: Belgium | B18: 0.12188468 | C18: 0.68039596 | E18: -0.3780995 | F18: 0.39559159 | H18: 0.0036473533 | I18: 0.55129749 | K18: 0.53198093 | L18: 0.31200659 | N18: 0.29707038 | O18: 0.32056478 | Q18: 1.1360584 | R18: 0.34024605 | T18: -0.23903291 | U18: 0.49555814
A19: Canada | B19: 4.8682547 | C19: 0.65262043 | E19: 1.4635959 | F19: 0.44993579 | H19: 3.2612197 | I19: 0.57479531 | K19: 1.5425203 | L19: 0.37450951 | N19: 1.0613514 | O19: 0.3256653 | Q19: 2.1747332 | R19: 0.39204499 | T19: 1.8210399 | U19: 0.46456671
A20: Chile | B20: 5.8302393 | C20: 0.8427459 | D20: † | E20: 2.7760382 | F20: 0.65702808 | G20: † | H20: 3.846127 | I20: 0.68524873 | J20: † | K20: 3.5198333 | L20: 0.55421817 | M20: † | N20: 3.7681148 | O20: 0.57531816 | P20: † | Q20: 3.3484359 | R20: 0.55128092 | S20: † | T20: 2.9768817 | U20: 0.68350053 | V20: †
A21: Colombia | B21: 10.203026 | C21: 1.1020476 | D21: † | E21: 7.5850577 | F21: 0.72583163 | G21: † | H21: 6.5920439 | I21: 0.84075701 | J21: † | K21: 7.2416 | L21: 0.69402468 | M21: † | N21: 7.7523484 | O21: 0.67742169 | P21: † | Q21: 7.1438222 | R21: 0.70077962 | S21: † | T21: 7.0912671 | U21: 0.69738275 | V21: †
A22: Czech Republic | B22: 4.2694349 | C22: 1.0510136 | E22: 2.3257096 | F22: 0.6866551 | H22: 2.5888212 | I22: 0.79289466 | K22: 2.55212 | L22: 0.51970404 | N22: 2.7936814 | O22: 0.65535003 | Q22: 2.4780607 | R22: 0.64545888 | T22: 1.2165825 | U22: 0.84075445
A23: Denmark | B23: 1.2535348 | C23: 0.87944138 | E23: 0.22985639 | F23: 0.51573253 | H23: 2.2302766 | I23: 0.70495665 | K23: 1.020054 | L23: 0.35047066 | N23: 0.35683453 | O23: 0.48382252 | Q23: 2.537972 | R23: 0.51311803 | T23: -0.59965795 | U23: 0.59673786
A24: Estonia | B24: 5.259129 | C24: 0.94592148 | E24: 1.7376869 | F24: 0.51220208 | H24: 3.8032613 | I24: 0.79478633 | K24: 2.7606936 | L24: 0.47252926 | N24: 2.500088 | O24: 0.4928028 | Q24: 2.0828815 | R24: 0.54524165 | T24: 2.0100582 | U24: 0.54910707
A25: Finland | B25: 0.82367802 | C25: 0.73818725 | E25: -0.20560774 | F25: 0.54050779 | H25: 1.3007021 | I25: 0.66819048 | K25: 1.0936445 | L25: 0.44338828 | N25: 0.49028975 | O25: 0.37369344 | Q25: 0.5055238 | R25: 0.48639774 | T25: 0.52833265 | U25: 0.53683043
A26: France | B26: 1.8581591 | C26: 0.85991472 | E26: 0.9521389 | F26: 0.53156728 | H26: 0.54245025 | I26: 0.66364574 | K26: 2.5594442 | L26: 0.44781172 | N26: 2.6181943 | O26: 0.44965455 | Q26: 2.3893983 | R26: 0.45431447 | T26: 1.3469913 | U26: 0.60184884
A27: Germany | B27: 6.986701 | C27: 1.0787807 | D27: ‡ | E27: 1.2554835 | F27: 0.66170365 | G27: ‡ | H27: 4.0448828 | I27: 0.89327717 | J27: ‡ | K27: 3.4055295 | L27: 0.5264886 | M27: ‡ | N27: 3.2385881 | O27: 0.68308014 | P27: ‡ | Q27: 2.6890981 | R27: 0.53874248 | S27: ‡ | T27: 2.9597235 | U27: 0.68452746 | V27: ‡
A28: Greece | B28: 10.203736 | C28: 1.0530361 | E28: 2.6925046 | F28: 0.54332161 | H28: 6.9103146 | I28: 0.7386868 | K28: 4.2643471 | L28: 0.64025015 | N28: 4.6624265 | O28: 0.64005917 | Q28: 4.7770162 | R28: 0.64872128 | T28: 3.899617 | U28: 0.68376899
A29: Hungary | B29: 2.2310855 | C29: 0.98627567 | E29: 1.2829207 | F29: 0.63460815 | H29: 1.5211184 | I29: 0.72091037 | K29: 2.7090061 | L29: 0.61062342 | N29: 2.3327372 | O29: 0.63317537 | Q29: 3.2650774 | R29: 0.63420331 | T29: 1.6089762 | U29: 0.86365807
A30: Iceland | B30: 5.2749143 | C30: 0.97049069 | D30: † | E30: 1.0272655 | F30: 0.56572068 | G30: † | H30: 4.8373499 | I30: 0.74378508 | J30: † | K30: 1.6933031 | L30: 0.52392471 | M30: † | N30: 1.2891654 | O30: 0.4094401 | P30: † | Q30: 1.3184394 | R30: 0.47373432 | S30: † | T30: 0.66345412 | U30: 0.57443446 | V30: †
A31: Ireland | B31: 7.9691024 | C31: 0.89931905 | E31: 2.685853 | F31: 0.49752915 | H31: 7.3275557 | I31: 0.69758749 | K31: 2.7447739 | L31: 0.4934276 | N31: 2.037704 | O31: 0.43688205 | Q31: 2.8723102 | R31: 0.41918752 | T31: 1.97864 | U31: 0.58576792
A32: Israel | B32: m | C32: m | E32: m | F32: m | H32: m | I32: m | K32: m | L32: m | N32: m | O32: m | Q32: m | R32: m | T32: m | U32: m
A33: Italy | B33: m | C33: m | E33: m | F33: m | H33: m | I33: m | K33: m | L33: m | N33: m | O33: m | Q33: m | R33: m | T33: m | U33: m
A34: Japan | B34: -4.6556029 | C34: 0.89308995 | E34: -1.1649525 | F34: 0.40953156 | H34: -3.1634092 | I34: 0.78489429 | K34: -0.20966716 | L34: 0.31499791 | N34: -0.034032758 | O34: 0.32393414 | Q34: -2.9685767 | R34: 0.55159235 | T34: -0.86914927 | U34: 0.48842627
A35: Korea | B35: -2.539144 | C35: 0.70385772 | E35: -0.23035415 | F35: 0.20617822 | H35: -2.2056453 | I35: 0.67330664 | K35: 0.24073601 | L35: 0.17656401 | N35: -0.42834753 | O35: 0.23397313 | Q35: 0.12916183 | R35: 0.20714989 | T35: -0.48886767 | U35: 0.34382594
A36: Latvia | B36: 4.9125986 | C36: 1.1339084 | E36: 3.4084904 | F36: 0.81672633 | H36: 2.7605369 | I36: 0.85748208 | K36: 3.9744604 | L36: 0.71874893 | N36: 3.0495548 | O36: 0.76141047 | Q36: 3.8856947 | R36: 0.76913577 | T36: 2.8740931 | U36: 0.84484768
A37: Lithuania | B37: 6.210897 | C37: 0.9484157 | E37: 3.2260735 | F37: 0.62079501 | H37: 4.0975156 | I37: 0.68981534 | K37: 5.2869816 | L37: 0.55206102 | N37: 5.309289 | O37: 0.50077528 | Q37: 6.5226297 | R37: 0.55862975 | T37: 4.622663 | U37: 0.65945345
A38: Luxembourg | B38: 4.9684982 | C38: 0.77283579 | E38: 2.0057302 | F38: 0.54436302 | H38: 3.5338709 | I38: 0.5607807 | K38: 2.6681981 | L38: 0.44482148 | N38: 2.2718027 | O38: 0.41567007 | Q38: 2.7744439 | R38: 0.45078743 | T38: 2.8907528 | U38: 0.62112594
A39: Mexico | B39: 2.847167 | C39: 0.9523353 | D39: † | E39: 2.4788234 | F39: 0.64434254 | G39: † | H39: 1.1126059 | I39: 0.79081815 | J39: † | K39: 2.7297544 | L39: 0.56925255 | M39: † | N39: 2.9161851 | O39: 0.57383543 | P39: † | Q39: 2.9332824 | R39: 0.63419211 | S39: ‡ | T39: 3.9536448 | U39: 0.73956829 | V39: ‡
A40: Netherlands* | B40: 2.9339533 | C40: 0.7531597 | E40: -0.050911374 | F40: 0.40437675 | H40: 2.181057 | I40: 0.52996349 | K40: 0.24296206 | L40: 0.32235008 | N40: 0.56724256 | O40: 0.36760402 | Q40: 0.71445715 | R40: 0.37693155 | T40: 1.3886248 | U40: 0.54916096
A41: New Zealand | B41: 5.5009975 | C41: 0.94447368 | E41: 1.0611433 | F41: 0.74897349 | H41: 5.9611917 | I41: 0.90819561 | K41: 1.6225655 | L41: 0.64006376 | N41: 0.92921609 | O41: 0.52202898 | Q41: 2.284193 | R41: 0.59773237 | T41: 0.44510764 | U41: 0.70924389
A42: Norway | B42: 1.1208971 | C42: 0.91067809 | E42: -1.8292648 | F42: 0.54315114 | H42: 2.501054 | I42: 0.70215875 | K42: -0.070802681 | L42: 0.42898476 | N42: -0.22165297 | O42: 0.46621823 | Q42: 0.7758736 | R42: 0.46256262 | T42: -1.1784772 | U42: 0.63318276
A43: Poland | B43: 5.2748914 | C43: 1.0467124 | E43: 0.31488758 | F43: 0.6375947 | H43: 2.5430341 | I43: 0.73688018 | K43: 3.63642 | L43: 0.56667978 | N43: 4.6073179 | O43: 0.5905984 | Q43: 4.0803475 | R43: 0.57044554 | T43: 2.5710678 | U43: 0.86865175
...

Sheet Table III.B1.2.3
A1: PISA 2018 Results (Volume III) - © OECD 2019
A2: Annex B1 | B2: Annex B1.2 Results (tables): Bullying
A3: Version 2 - Last updated: 02-Dec-2019
A4: Disclaimer: http://oe.cd/disclaimer
A6: Table III.B1.2.3
A7: Prevalence of exposure to bullying in schools
A8: Based on students' reports
B11: Any type of bullying act | E11: Percentage of students who are in schools where…
E12: Over 50% of students reported being bullied at least a few times a month | H12: Between 25% and 50% of students reported being bullied at least a few times a month | K12: Between 10% and 25% of students reported being bullied at least a few times a month | N12: 10% of students or less reported students reported being bullied at least a few times a month
B14: % | C14: S.E. | E14: % | F14: S.E. | H14: % | I14: S.E. | K14: % | L14: S.E. | N14: % | O14: S.E.
A15: OECD
A16: Australia | B16: 29.548591 | C16: 0.52510725 | E16: 8.8812066 | F16: 1.0218073 | H16: 52.979648 | I16: 2.0127443 | K16: 29.721205 | L16: 1.7684631 | N16: 8.4179405 | O16: 1.0040468
A17: Austria | B17: 23.170104 | C17: 0.79568241 | E17: 2.9709946 | F17: 0.98760583 | H17: 33.581893 | I17: 3.2212496 | K17: 52.721022 | L17: 3.5874127 | N17: 10.726091 | O17: 2.2269002
A18: Belgium | B18: 18.632215 | C18: 0.50730102 | E18: 0.49560871 | F18: 0.30475056 | H18: 25.032686 | I18: 2.5552278 | K18: 54.070157 | L18: 3.1873562 | N18: 20.401548 | O18: 2.2047475
A19: Canada | B19: 25.206115 | C19: 0.45287583 | E19: 2.4602381 | F19: 0.72612287 | H19: 47.387325 | I19: 2.442979 | K19: 42.095113 | L19: 2.2692726 | N19: 8.0573242 | O19: 1.1767481
A20: Chile | B20: 23.851393 | C20: 0.64535224 | D20: † | E20: 3.0955662 | F20: 1.1216545 | H20: 34.724258 | I20: 3.4016013 | K20: 55.524157 | L20: 3.566148 | N20: 6.656019 | O20: 1.62843
A21: Colombia | B21: 32.308823 | C21: 0.91172448 | D21: † | E21: 11.645386 | F21: 2.336007 | H21: 61.060648 | I21: 3.7453119 | K21: 22.865452 | L21: 3.2011786 | N21: 4.4285131 | O21: 1.5153458
A22: Czech Republic | B22: 29.699476 | C22: 0.82013199 | E22: 10.939749 | F22: 1.8975298 | H22: 47.701886 | I22: 2.4969264 | K22: 35.962833 | L22: 2.9594854 | N22: 5.3955323 | O22: 1.0547198
A23: Denmark | B23: 21.396512 | C23: 0.71144018 | E23: 2.6510576 | F23: 0.99032713 | H23: 31.957033 | I23: 3.0427114 | K23: 49.379484 | L23: 2.9811282 | N23: 16.012425 | O23: 2.2406202
A24: Estonia | B24: 25.437062 | C24: 0.73290297 | E24: 2.6614373 | F24: 0.87379093 | H24: 47.710887 | I24: 1.8516597 | K24: 42.699769 | L24: 1.7369545 | N24: 6.9279071 | O24: 1.0821226
A25: Finland | B25: 17.724624 | C25: 0.50421462 | E25: 0.063395051 | F25: 0.063692865 | H25: 16.025109 | I25: 2.6783527 | K25: 68.955701 | L25: 3.3150029 | N25: 14.955796 | O25: 2.1578457
A26: France | B26: 19.789698 | C26: 0.65102365 | E26: 2.6950408 | F26: 0.70108722 | H26: 26.581967 | I26: 2.8174336 | K26: 53.342924 | L26: 3.366701 | N26: 17.380069 | O26: 2.4253364
A27: Germany | B27: 22.677499 | C27: 0.92986504 | D27: ‡ | E27: 5.3115057 | F27: 1.6803576 | H27: 38.144092 | I27: 3.5275931 | K27: 37.6121 | L27: 3.539928 | N27: 18.932303 | O27: 2.6514883
A28: Greece | B28: 26.938497 | C28: 0.82740518 | E28: 3.8254931 | F28: 1.2969727 | H28: 45.197853 | I28: 4.0545225 | K28: 45.84218 | L28: 4.0636665 | N28: 5.1344744 | O28: 1.4588023
A29: Hungary | B29: 22.575106 | C29: 0.7668999 | E29: 4.856065 | F29: 1.1255159 | H29: 32.368103 | I29: 3.0639977 | K29: 43.960318 | L29: 3.7220624 | N29: 18.815514 | O29: 2.7546831
A30: Iceland | B30: 17.210209 | C30: 0.7980373 | D30: † | E30: 1.3023035 | F30: 0.092947252 | H30: 10.581793 | I30: 0.17113939 | K30: 69.498216 | L30: 0.22890396 | N30: 18.617687 | O30: 0.23261003
A31: Ireland | B31: 22.673229 | C31: 0.67729562 | E31: 0 | F31: c | H31: 36.281853 | I31: 3.7677292 | K31: 54.227251 | L31: 4.0316299 | N31: 9.4908953 | O31: 2.1222656
A32: Israel | B32: m | C32: m | E32: m | F32: m | H32: m | I32: m | K32: m | L32: m | N32: m | O32: m
A33: Italy | B33: 23.702815 | C33: 0.68751382 | E33: 5.8199019 | F33: 1.3597527 | H33: 37.651218 | I33: 2.9796187 | K33: 40.651989 | L33: 2.8766907 | N33: 15.876891 | O33: 2.3614073
A34: Japan | B34: 17.267579 | C34: 0.62579235 | E34: 1.2708051 | F34: 0.79194173 | H34: 11.972997 | I34: 2.2852776 | K34: 65.399567 | L34: 3.7181705 | N34: 21.356631 | O34: 3.0460801
A35: Korea | B35: 9.3912121 | C35: 0.46076143 | E35: 0.068857524 | F35: 0.063209481 | H35: 2.1663714 | I35: 1.0869317 | K35: 44.132119 | L35: 3.7204758 | N35: 53.632652 | O35: 3.763676
A36: Latvia | B36: 35.497477 | C36: 0.82084956 | E36: 15.335536 | F36: 1.5773856 | H36: 59.708069 | I36: 1.9730231 | K36: 20.886097 | L36: 1.5491525 | N36: 4.0702973 | O36: 0.79203891
A37: Lithuania | B37: 22.635136 | C37: 0.68228929 | E37: 5.4455662 | F37: 0.84724321 | H37: 31.426101 | I37: 1.627707 | K37: 46.731337 | L37: 1.5611008 | N37: 16.396996 | O37: 1.1933772
A38: Luxembourg | B38: 20.636768 | C38: 0.57094785 | E38: 0 | F38: c | H38: 19.484336 | I38: 0.08933761 | K38: 79.920962 | L38: 0.098992173 | N38: 0.59470279 | O38: 0.040703411
