Workbook

Sheet TOC
A1: PISA 2018 Results (Volume III) - © OECD 2019
A2: Annex B1 | B2: Annex B1.8 Results (tables): Student co-operation and competition
A3: Version 2 - Last updated: 02-Dec-2019
A4: Disclaimer: http://oe.cd/disclaimer
A6: TOC | B6: PISA 2018 Results - Volume III
A8: Chapter 8 | B8: Student co-operation and competition
A9: Tables
A11: ='Table III.B1.8.1'!A6 -> Table III.B1.8.1 | B11: ='Table III.B1.8.1'!$A$7 -> Student co-operation
A12: ='Table III.B1.8.2'!A6 -> Table III.B1.8.2 | B12: ='Table III.B1.8.2'!$A$7 -> Student competition
A13: ='Table III.B1.8.3'!A6 -> Table III.B1.8.3 | B13: ='Table III.B1.8.3'!$A$7 -> Difference between student co-operation and competition
A14: ='Table III.B1.8.4'!A6 -> Table III.B1.8.4 | B14: ='Table III.B1.8.4'!$A$7 -> Prevalence of student co-operation in schools
A15: ='Table III.B1.8.5'!A6 -> Table III.B1.8.5 | B15: ='Table III.B1.8.5'!$A$7 -> Prevalence of student competition in schools
A16: ='Table III.B1.8.6'!A6 -> Table III.B1.8.6 | B16: ='Table III.B1.8.6'!$A$7 -> Student co-operation, by student characteristics
A17: ='Table III.B1.8.7'!A6 -> Table III.B1.8.7 | B17: ='Table III.B1.8.7'!$A$7 -> Student competition, by student characteristics
A18: ='Table III.B1.8.8'!A6 -> Table III.B1.8.8 | B18: ='Table III.B1.8.8'!$A$7 -> Student co-operation, by school characteristics
A19: ='Table III.B1.8.9'!A6 -> Table III.B1.8.9 | B19: ='Table III.B1.8.9'!$A$7 -> Student competition, by school characteristics
A20: ='Table III.B1.8.10'!A6 -> Table III.B1.8.10 | B20: ='Table III.B1.8.10'!$A$7 -> Student co-operation and reading performance
A21: ='Table III.B1.8.11'!A6 -> Table III.B1.8.11 | B21: ='Table III.B1.8.11'!$A$7 -> Student competition and reading performance
A22: ='Table III.B1.8.12'!A6 -> Table III.B1.8.12 | B22: ='Table III.B1.8.12'!$A$7 -> School-level co-operation and reading performance
A23: ='Table III.B1.8.13'!A6 -> Table III.B1.8.13 | B23: ='Table III.B1.8.13'!$A$7 -> School-level competition and reading performance
A24: ='Table III.B1.8.14'!A6 -> Table III.B1.8.14 | B24: ='Table III.B1.8.14'!$A$7 -> Students' attitudes towards competition and reading performance
A25: ='Table III.B1.8.15'!A6 -> Table III.B1.8.15 | B25: ='Table III.B1.8.15'!$A$7 -> Association between student competition and student outcomes, by students' attitudes towards competition
A26: ='Table III.B1.8.16'!A6 -> Table III.B1.8.16 | B26: ='Table III.B1.8.16'!$A$7 -> Association between student competition and student outcomes, by gender
A29: Symbols for missing data
A30: c: There were too few observations to provide reliable estimates (i.e. there were fewer than 30 students or fewer than 5 schools with valid data).
A31: m: Data are not available. There are no observations in the sample; these data were not collected by the country; or these data were collected but subsequently removed from the publication for technical reasons.
A32: w: Results were withdrawn at the request of the country concerned.

Sheet INFORMATION ON SCALED INDICES
A1: PISA 2018 Results (Volume III) - © OECD 2019
A2: Annex B1 | B2: Annex B1.8 Results (tables): Student co-operation and competition
A3: Version 2 - Last updated: 02-Dec-2019
A4: Disclaimer: http://oe.cd/disclaimer
A6: Information on scaled indices used in PISA 2015 Results (Volume III): What School Life Means for Students’ Lives
A11: Full name of the index | B11: Name in dataset | C11: Questionnaire | D11: Item 1 | E11: Item 2 | F11: Item 3 | G11: Item 4 | H11: Item 5 | I11: Item 6 | J11: Item 7
A12: Adaptive instruction | B12: adaptivity | C12: Student | D12: ST212Q01HA | E12: ST212Q02HA | F12: ST212Q03HA
A13: Attitudes towards competition | B13: compete | C13: Student | D13: ST181Q02HA | E13: ST181Q03HA | F13: ST181Q04HA
A14: Enjoyment of reading | B14: joyread | C14: Student | D14: ST160Q01IR | E14: ST160Q02IA | F14: ST160Q03IA | G14: ST160Q04IR | H14: ST160Q05IR
A15: Exposure to bullying | B15: beingbullied | C15: Student | D15: ST038Q03NA | E15: ST038Q04NA | F15: ST038Q05NA
A16: Fear of failure | B16: gfofail | C16: Student | D16: ST183Q01HA | E16: ST183Q02HA | F16: ST183Q03HA
A17: Disciplinary climate | B17: disclima | C17: Student | D17: ST097Q01TA | E17: ST097Q02TA | F17: ST097Q03TA | G17: ST097Q04TA | H17: ST097Q05TA
A18: Learning goals | B18: mastgoal | C18: Student | D18: ST208Q01HA | E18: ST208Q02HA | F18: ST208Q04HA
A19: Meaning in life | B19: eudmo | C19: Student | D19: ST185Q01HA | E19: ST185Q02HA | F19: ST185Q03HA
A20: Motivation to master tasks | B20: workmast | C20: Student | D20: ST182Q03HA | E20: ST182Q04HA | F20: ST182Q05HA
A21: Parents’ emotional support | B21: emosups | C21: Student | D21: ST123Q02NA | E21: ST123Q03NA | F21: ST123Q04NA
A22: Parents’ perceived school quality | B22: pqschool | C22: Parent | D22: PA007Q01TR | E22: PA007Q02TR | F22: PA007Q03TR | G22: PA007Q04TR | H22: PA007Q05TR | I22: PA007Q06TR | J22: PA007Q07TR
A23: Positive feelings | B23: swbp | C23: Student | D23: ST186Q01HA | E23: ST186Q03HA | F23: ST186Q05HA
A24: School policies for parental involvement | B24: paschpol | C24: Parent | D24: PA007Q09NR | E24: PA007Q11NR | F24: PA007Q12NR | G24: PA007Q13NR | H24: PA007Q14NR | I24: PA007Q15NR
A25: Self-efficacy | B25: resilience | C25: Student | D25: ST188Q01HA | E25: ST188Q02HA | F25: ST188Q03HA | G25: ST188Q06HA | H25: ST188Q07HA
A26: Sense of belonging | B26: belong | C26: Student | D26: ST034Q01TA | E26: ST034Q02TR | F26: ST034Q03TR | G26: ST034Q04TA | H26: ST034Q05TR | I26: ST034Q06TA
A27: Shortage of educational staff | B27: staffshort | C27: School | D27: SC017Q01NA | E27: SC017Q02NA | F27: SC017Q03NA | G27: SC017Q04NA
A28: Student competition | B28: percomp | C28: Student | D28: ST205Q01HA | E28: ST205Q02HA | F28: ST205Q03HA
A29: Student co-operation | B29: percoop | C29: Student | D29: ST206Q01HA | E29: ST206Q02HA | F29: ST206Q03HA
A30: Teacher behaviour hindering learning | B30: teachbeha | C30: School | D30: SC061Q06TA | E30: SC061Q07TA | F30: SC061Q08TA | G30: SC061Q09TA | H30: SC061Q10TA
A31: Teacher enthusiasm | B31: teachint | C31: Student | D31: ST213Q01HA | E31: ST213Q02HA | F31: ST213Q03HA | G31: ST213Q04HA
A32: Teacher feedback | B32: perfeed | C32: Student | D32: ST104Q02NA | E32: ST104Q03NA | F32: ST104Q04NA
A33: Teacher support | B33: teachsup | C33: Student | D33: ST100Q01TR | E33: ST100Q02TR | F33: ST100Q03TR | G33: ST100Q04TR
A34: Teacher-directed instruction | B34: dirins | C34: Student | D34: ST102Q01TR | E34: ST102Q02TR | F34: ST102Q03TR | G34: ST102Q04TR
A35: Teachers' stimulation of reading engagement | B35: stimread | C35: Student | D35: ST152Q05IA | E35: ST152Q06IA | F35: ST152Q07IA | G35: ST152Q08IA
A36: Value of school | B36: attlnact | C36: Student | D36: ST036Q05TR | E36: ST036Q06TR | F36: ST036Q08TR

Sheet Table III.B1.8.1
A1: PISA 2018 Results (Volume III) - © OECD 2019
A2: Annex B1 | B2: Annex B1.8 Results (tables): Student co-operation and competition
A3: Version 2 - Last updated: 02-Dec-2019
A4: Disclaimer: http://oe.cd/disclaimer
A6: Table III.B1.8.1
A7: Student co-operation
A8: Based on students' reports
B11: Index of student co-operation1 | H11: Percentage of students who reported the following:
H12: Students seem to value co-operation | T12: It seems that students are co-operating with each other | AF12: Students seem to share the feeling that co-operating with each other is important | AR12: Students feel that they are encouraged to co-operate with others
B13: Average | E13: Variability | H13: Not at all true | K13: Slightly true | N13: Very true | Q13: Extremely true | T13: Not at all true | W13: Slightly true | Z13: Very true | AC13: Extremely true | AF13: Not at all true | AI13: Slightly true | AL13: Very true | AO13: Extremely true | AR13: Not at all true | AU13: Slightly true | AX13: Very true | BA13: Extremely true
B14: Mean index | C14: S.E. | E14: S.D. | F14: S.E. | H14: % | I14: S.E. | K14: % | L14: S.E. | N14: % | O14: S.E. | Q14: % | R14: S.E. | T14: % | U14: S.E. | W14: % | X14: S.E. | Z14: % | AA14: S.E. | AC14: % | AD14: S.E. | AF14: % | AG14: S.E. | AI14: % | AJ14: S.E. | AL14: % | AM14: S.E. | AO14: % | AP14: S.E. | AR14: % | AS14: S.E. | AU14: % | AV14: S.E. | AX14: % | AY14: S.E. | BA14: % | BB14: S.E.
A15: OECD
A16: Australia | B16: 0.024334781 | C16: 0.012851336 | D16: † | E16: 0.94354398 | F16: 0.0059477807 | G16: † | H16: 5.1438435 | I16: 0.21406948 | K16: 36.206514 | L16: 0.53443984 | N16: 46.724224 | O16: 0.5200378 | Q16: 11.925419 | R16: 0.4404389 | T16: 3.973716 | U16: 0.19682017 | V16: † | W16: 32.312733 | X16: 0.50354509 | Y16: † | Z16: 52.161413 | AA16: 0.46636096 | AB16: † | AC16: 11.552139 | AD16: 0.39676348 | AE16: † | AF16: 5.4908274 | AG16: 0.25082156 | AI16: 34.170075 | AJ16: 0.56414013 | AL16: 49.071183 | AM16: 0.59350749 | AO16: 11.267914 | AP16: 0.4248756 | AR16: 4.6273939 | AS16: 0.22906644 | AT16: † | AU16: 28.846279 | AV16: 0.52458495 | AW16: † | AX16: 52.102581 | AY16: 0.5057941 | AZ16: † | BA16: 14.423746 | BB16: 0.47334286 | BC16: †
A17: Austria | B17: 0.35646852 | C17: 0.020974523 | E17: 1.0108333 | F17: 0.010663883 | H17: 7.4246847 | I17: 0.49358359 | K17: 19.873032 | L17: 0.8175458 | N17: 48.406834 | O17: 0.72217695 | Q17: 24.295449 | R17: 0.7781154 | T17: 5.2051098 | U17: 0.38342807 | W17: 19.120409 | X17: 0.71132134 | Z17: 51.867266 | AA17: 0.68318898 | AC17: 23.807215 | AD17: 0.74660202 | AF17: 5.7757347 | AG17: 0.37245743 | AI17: 19.640114 | AJ17: 0.72614771 | AL17: 50.484092 | AM17: 0.77695326 | AO17: 24.100059 | AP17: 0.73200286 | AR17: 6.1610005 | AS17: 0.44261207 | AU17: 22.06786 | AV17: 0.75199958 | AX17: 48.025799 | AY17: 0.78460725 | BA17: 23.74534 | BB17: 0.64596359
A18: Belgium | B18: -0.057201043 | C18: 0.015633574 | E18: 0.97918268 | F18: 0.0076967707 | H18: 7.6893882 | I18: 0.38219388 | K18: 35.151213 | L18: 0.69312396 | N18: 48.211671 | O18: 0.70054236 | Q18: 8.947728 | R18: 0.35054233 | T18: 7.6414809 | U18: 0.36719522 | W18: 28.997262 | X18: 0.68653699 | Z18: 52.529966 | AA18: 0.68000131 | AC18: 10.831291 | AD18: 0.42036037 | AF18: 9.7690197 | AG18: 0.44353871 | AI18: 31.324975 | AJ18: 0.6010247 | AL18: 49.298594 | AM18: 0.67876405 | AO18: 9.6074117 | AP18: 0.4144099 | AR18: 12.124584 | AS18: 0.46324175 | AU18: 33.797268 | AV18: 0.6794993 | AX18: 45.244464 | AY18: 0.66716991 | BA18: 8.8336838 | BB18: 0.36680618
A19: Canada | B19: m | C19: m | E19: m | F19: m | H19: m | I19: m | K19: m | L19: m | N19: m | O19: m | Q19: m | R19: m | T19: m | U19: m | W19: m | X19: m | Z19: m | AA19: m | AC19: m | AD19: m | AF19: m | AG19: m | AI19: m | AJ19: m | AL19: m | AM19: m | AO19: m | AP19: m | AR19: m | AS19: m | AU19: m | AV19: m | AX19: m | AY19: m | BA19: m | BB19: m
A20: Chile | B20: -0.17271714 | C20: 0.024625825 | D20: † | E20: 1.027201 | F20: 0.0086919554 | G20: † | H20: 9.1963984 | I20: 0.50858798 | J20: † | K20: 42.382794 | L20: 0.89952798 | M20: † | N20: 35.695327 | O20: 0.81185378 | P20: † | Q20: 12.725481 | R20: 0.67211836 | S20: † | T20: 6.5622947 | U20: 0.44393706 | V20: † | W20: 41.865654 | X20: 0.91196325 | Y20: † | Z20: 38.738008 | AA20: 0.83653989 | AB20: † | AC20: 12.834044 | AD20: 0.64956333 | AE20: † | AF20: 8.3988658 | AG20: 0.45750039 | AH20: † | AI20: 41.550058 | AJ20: 0.959036 | AK20: † | AL20: 37.376851 | AM20: 0.81863624 | AN20: † | AO20: 12.674225 | AP20: 0.68857745 | AQ20: † | AR20: 8.43327 | AS20: 0.48864776 | AT20: † | AU20: 39.37941 | AV20: 0.75088246 | AW20: † | AX20: 37.666478 | AY20: 0.78734425 | AZ20: † | BA20: 14.520843 | BB20: 0.64225885 | BC20: †
A21: Colombia | B21: -0.13124253 | C21: 0.020576081 | D21: † | E21: 1.001002 | F21: 0.0098051861 | G21: † | H21: 13.234363 | I21: 0.72904834 | J21: † | K21: 33.374862 | L21: 0.87302047 | M21: † | N21: 45.136831 | O21: 0.88706347 | P21: † | Q21: 8.253944 | R21: 0.44492789 | S21: † | T21: 9.1305085 | U21: 0.5232419 | V21: † | W21: 32.70847 | X21: 0.67655858 | Y21: † | Z21: 48.931159 | AA21: 0.79853969 | AB21: † | AC21: 9.2298621 | AD21: 0.50227627 | AE21: † | AF21: 8.8857629 | AG21: 0.56379936 | AH21: † | AI21: 31.891988 | AJ21: 0.72199148 | AK21: † | AL21: 49.011327 | AM21: 0.74369156 | AN21: † | AO21: 10.210921 | AP21: 0.53281399 | AQ21: † | AR21: 9.0695428 | AS21: 0.55850438 | AT21: † | AU21: 31.220645 | AV21: 0.81115065 | AW21: † | AX21: 48.025454 | AY21: 0.90559253 | AZ21: † | BA21: 11.684358 | BB21: 0.58566745 | BC21: †
A22: Czech Republic | B22: -0.22183528 | C22: 0.018754458 | E22: 0.97169271 | F22: 0.0087720734 | H22: 10.165089 | I22: 0.50732885 | K22: 46.812715 | L22: 0.93904206 | N22: 33.984326 | O22: 0.75706839 | Q22: 9.0378706 | R22: 0.48924299 | T22: 7.1029948 | U22: 0.41801737 | W22: 40.68587 | X22: 0.89365191 | Z22: 41.849486 | AA22: 0.88997189 | AC22: 10.361648 | AD22: 0.52033334 | AF22: 7.9954981 | AG22: 0.45675585 | AI22: 39.440893 | AJ22: 0.75870348 | AL22: 41.691376 | AM22: 0.67790749 | AO22: 10.872233 | AP22: 0.4694727 | AR22: 9.3580646 | AS22: 0.49587136 | AU22: 43.657032 | AV22: 0.96762124 | AX22: 36.733591 | AY22: 0.81700169 | BA22: 10.251312 | BB22: 0.45134013
A23: Denmark | B23: 0.3427123 | C23: 0.01486662 | E23: 0.85552103 | F23: 0.011499217 | H23: 2.6525721 | I23: 0.27549354 | K23: 21.217964 | L23: 0.76844112 | N23: 59.227212 | O23: 0.93981811 | Q23: 16.902252 | R23: 0.59029264 | T23: 1.6155543 | U23: 0.20293061 | W23: 17.680221 | X23: 0.6025108 | Z23: 61.567897 | AA23: 0.85357198 | AC23: 19.136328 | AD23: 0.679717 | AF23: 3.4045685 | AG23: 0.31524442 | AI23: 25.931884 | AJ23: 0.740908 | AL23: 55.541258 | AM23: 0.84219464 | AO23: 15.122289 | AP23: 0.58952047 | AR23: 3.0877576 | AS23: 0.31794452 | AU23: 22.945276 | AV23: 0.62384373 | AX23: 57.538522 | AY23: 0.86510806 | BA23: 16.428444 | BB23: 0.64028901
A24: Estonia | B24: -0.11676621 | C24: 0.015580692 | E24: 0.94434615 | F24: 0.00915389 | H24: 7.4359715 | I24: 0.4923282 | K24: 46.032802 | L24: 0.82506965 | N24: 36.957664 | O24: 0.81303465 | Q24: 9.5735629 | R24: 0.41366676 | T24: 4.6708084 | U24: 0.39539089 | W24: 36.788471 | X24: 0.73585516 | Z24: 46.550339 | AA24: 0.81955399 | AC24: 11.990381 | AD24: 0.47492041 | AF24: 5.9758854 | AG24: 0.39330583 | AI24: 38.57816 | AJ24: 0.75256749 | AL24: 44.312986 | AM24: 0.76746172 | AO24: 11.132969 | AP24: 0.45293804 | AR24: 7.1315746 | AS24: 0.41231664 | AU24: 39.604787 | AV24: 0.78581145 | AX24: 41.957728 | AY24: 0.85067743 | BA24: 11.305911 | BB24: 0.48288833
A25: Finland | B25: 0.08341595 | C25: 0.016507131 | E25: 0.90031768 | F25: 0.0082499725 | H25: 4.7872725 | I25: 0.26294979 | K25: 31.530728 | L25: 0.79878432 | N25: 55.202645 | O25: 0.77040526 | Q25: 8.4793554 | R25: 0.43650281 | T25: 3.9125251 | U25: 0.25633296 | W25: 25.95878 | X25: 0.7572321 | Z25: 59.678799 | AA25: 0.8227114 | AC25: 10.449896 | AD25: 0.52628537 | AF25: 5.2065588 | AG25: 0.29467129 | AI25: 30.746146 | AJ25: 0.70143883 | AL25: 55.112665 | AM25: 0.69414316 | AO25: 8.9346299 | AP25: 0.47650636 | AR25: 4.9182025 | AS25: 0.28817645 | AU25: 27.376693 | AV25: 0.71280459 | AX25: 57.127734 | AY25: 0.68891626 | BA25: 10.57737 | BB25: 0.52158203
A26: France | B26: -0.37953541 | C26: 0.016247046 | D26: † | E26: 1.0023309 | F26: 0.008799815 | G26: † | H26: 12.430692 | I26: 0.58336641 | J26: † | K26: 47.012127 | L26: 0.67132736 | M26: † | N26: 31.940552 | O26: 0.71739602 | P26: † | Q26: 8.6166289 | R26: 0.42595885 | S26: † | T26: 11.100204 | U26: 0.46241836 | V26: † | W26: 43.715225 | X26: 0.62119265 | Y26: † | Z26: 36.137096 | AA26: 0.80283783 | AB26: † | AC26: 9.0474756 | AD26: 0.39326158 | AE26: † | AF26: 13.480896 | AG26: 0.52724332 | AH26: † | AI26: 42.934705 | AJ26: 0.69203599 | AK26: † | AL26: 34.243091 | AM26: 0.77030747 | AN26: † | AO26: 9.3413084 | AP26: 0.44685471 | AQ26: † | AR26: 13.554234 | AS26: 0.50251509 | AT26: † | AU26: 40.845355 | AV26: 0.66744662 | AW26: † | AX26: 35.076659 | AY26: 0.76128001 | AZ26: † | BA26: 10.523752 | BB26: 0.49130215 | BC26: †
A27: Germany | B27: 0.067556501 | C27: 0.025913674 | D27: ‡ | E27: 1.0321921 | F27: 0.014157809 | G27: ‡ | H27: 9.9305894 | I27: 0.79411303 | J27: ‡ | K27: 28.074113 | L27: 1.1794048 | M27: ‡ | N27: 46.395388 | O27: 1.1427726 | P27: ‡ | Q27: 15.599909 | R27: 0.83047929 | S27: ‡ | T27: 7.6008553 | U27: 0.64427361 | V27: ‡ | W27: 26.685263 | X27: 0.98401133 | Y27: ‡ | Z27: 50.798303 | AA27: 1.0415613 | AB27: ‡ | AC27: 14.915578 | AD27: 0.78665815 | AE27: ‡ | AF27: 7.9090005 | AG27: 0.6104113 | AH27: ‡ | AI27: 28.479816 | AJ27: 1.1468768 | AK27: ‡ | AL27: 48.313536 | AM27: 1.1580626 | AN27: ‡ | AO27: 15.297648 | AP27: 0.78245209 | AQ27: ‡ | AR27: 8.942535 | AS27: 0.7069158 | AT27: ‡ | AU27: 31.364989 | AV27: 1.0937299 | AW27: ‡ | AX27: 45.510674 | AY27: 1.1334489 | AZ27: ‡ | BA27: 14.181802 | BB27: 0.84629419 | BC27: ‡
A28: Greece | B28: -0.016153399 | C28: 0.017312529 | E28: 1.0124433 | F28: 0.0082553997 | H28: 9.5414116 | I28: 0.49321401 | K28: 33.530188 | L28: 0.69225261 | N28: 39.971193 | O28: 0.68659776 | Q28: 16.957207 | R28: 0.49840577 | T28: 6.4644742 | U28: 0.36820251 | W28: 36.416533 | X28: 0.6780392 | Z28: 41.386515 | AA28: 0.70680744 | AC28: 15.732478 | AD28: 0.50582656 | AF28: 6.7848281 | AG28: 0.38229647 | AI28: 34.246795 | AJ28: 0.72698413 | AL28: 42.605553 | AM28: 0.65655399 | AO28: 16.362824 | AP28: 0.61092316 | AR28: 8.2167693 | AS28: 0.32680238 | AU28: 33.8999 | AV28: 0.62850064 | AX28: 39.379142 | AY28: 0.7187801 | BA28: 18.504189 | BB28: 0.59642243
A29: Hungary | B29: -0.13145841 | C29: 0.023976022 | E29: 1.0072497 | F29: 0.010806743 | H29: 9.0053079 | I29: 0.56886496 | K29: 40.029018 | L29: 0.92766796 | N29: 40.004815 | O29: 0.97955608 | Q29: 10.960859 | R29: 0.57995965 | T29: 7.1786228 | U29: 0.49954912 | W29: 37.953986 | X29: 0.96633333 | Z29: 43.477475 | AA29: 1.0591623 | AC29: 11.389916 | AD29: 0.58586264 | AF29: 8.2124094 | AG29: 0.5732113 | AI29: 37.216624 | AJ29: 0.92947575 | AL29: 43.519516 | AM29: 0.93717034 | AO29: 11.051451 | AP29: 0.52979481 | AR29: 9.0575615 | AS29: 0.57543639 | AU29: 38.566264 | AV29: 0.83811267 | AX29: 40.225105 | AY29: 0.95146433 | BA29: 12.151069 | BB29: 0.59234357
A30: Iceland | B30: 0.31193357 | C30: 0.022423244 | D30: † | E30: 0.97582412 | F30: 0.014250764 | G30: † | H30: 7.5899908 | I30: 0.56149531 | J30: † | K30: 19.123912 | L30: 0.87187061 | M30: † | N30: 56.762325 | O30: 1.0010431 | P30: † | Q30: 16.523772 | R30: 0.85140358 | S30: † | T30: 6.1070075 | U30: 0.52026517 | V30: † | W30: 16.152121 | X30: 0.7302826 | Y30: † | Z30: 59.325897 | AA30: 0.94461455 | AB30: † | AC30: 18.414975 | AD30: 0.91450816 | AE30: † | AF30: 6.2102539 | AG30: 0.51112004 | AH30: † | AI30: 17.519141 | AJ30: 0.8518524 | AK30: † | AL30: 58.287352 | AM30: 0.97647097 | AN30: † | AO30: 17.983253 | AP30: 0.89007513 | AQ30: † | AR30: 6.4831911 | AS30: 0.5108698 | AT30: † | AU30: 16.34445 | AV30: 0.81814989 | AW30: † | AX30: 58.021671 | AY30: 1.0374168 | AZ30: † | BA30: 19.150687 | BB30: 0.84348878 | BC30: †
A31: Ireland | B31: -0.17227425 | C31: 0.016413571 | E31: 0.92356824 | F31: 0.0087366155 | H31: 6.6663919 | I31: 0.38344491 | K31: 43.165268 | L31: 0.82637225 | N31: 42.586057 | O31: 0.86758504 | Q31: 7.5822831 | R31: 0.45662528 | T31: 5.6180326 | U31: 0.32542118 | W31: 37.463811 | X31: 0.8248368 | Z31: 48.99054 | AA31: 0.86705764 | AC31: 7.9276158 | AD31: 0.48541976 | AF31: 8.2275916 | AG31: 0.44169715 | AI31: 39.780888 | AJ31: 0.79068422 | AL31: 44.298547 | AM31: 0.75865875 | AO31: 7.6929729 | AP31: 0.41813663 | AR31: 7.0955974 | AS31: 0.47532115 | AU31: 34.968408 | AV31: 0.78470789 | AX31: 47.135379 | AY31: 0.91881519 | BA31: 10.800616 | BB31: 0.55975071
A32: Israel | B32: 0.06969555 | C32: 0.022042352 | E32: 1.0454105 | F32: 0.0093494775 | H32: 9.439716 | I32: 0.44375677 | K32: 31.407376 | L32: 0.81653257 | N32: 39.955012 | O32: 0.71260821 | Q32: 19.197896 | R32: 0.88202701 | T32: 6.3102055 | U32: 0.31365544 | W32: 31.079242 | X32: 0.82938159 | Z32: 44.717017 | AA32: 0.73377274 | AC32: 17.893535 | AD32: 0.811244 | AF32: 7.3299303 | AG32: 0.37566649 | AI32: 29.899366 | AJ32: 0.76786856 | AL32: 44.467022 | AM32: 0.70436366 | AO32: 18.303682 | AP32: 0.83005806 | AR32: 8.4032529 | AS32: 0.39163589 | AU32: 26.523549 | AV32: 0.70143747 | AX32: 43.307644 | AY32: 0.73676368 | BA32: 21.765554 | BB32: 0.86260573
A33: Italy | B33: -0.31281902 | C33: 0.015790849 | E33: 0.94378749 | F33: 0.0093170872 | H33: 11.776048 | I33: 0.42379064 | K33: 47.283465 | L33: 0.8909856 | N33: 33.424958 | O33: 0.83414736 | Q33: 7.5155281 | R33: 0.41398338 | T33: 8.2689131 | U33: 0.43390665 | W33: 44.129823 | X33: 0.93173455 | Z33: 39.945591 | AA33: 0.84352149 | AC33: 7.6556725 | AD33: 0.42346921 | AF33: 8.634707 | AG33: 0.498374 | AI33: 42.193724 | AJ33: 0.91553786 | AL33: 40.087525 | AM33: 0.91847962 | AO33: 9.084044 | AP33: 0.43175785 | AR33: 10.790168 | AS33: 0.51701755 | AU33: 40.531336 | AV33: 0.98140408 | AX33: 37.174017 | AY33: 0.9279076 | BA33: 11.504479 | BB33: 0.4510574
A34: Japan | B34: 0.11152416 | C34: 0.022927011 | E34: 1.0505165 | F34: 0.0085032038 | H34: 5.7622948 | I34: 0.44498459 | K34: 36.379832 | L34: 0.79821917 | N34: 40.192063 | O34: 0.73222732 | Q34: 17.66581 | R34: 0.7067666 | T34: 5.2084709 | U34: 0.33781211 | W34: 31.148723 | X34: 0.72345723 | Z34: 44.794865 | AA34: 0.70009046 | AC34: 18.847942 | AD34: 0.73485679 | AF34: 5.8353402 | AG34: 0.3975714 | AI34: 31.347719 | AJ34: 0.79744958 | AL34: 44.14671 | AM34: 0.71832911 | AO34: 18.670231 | AP34: 0.72051952 | AR34: 7.1167374 | AS34: 0.40867033 | AU34: 33.21795 | AV34: 0.66069185 | AX34: 41.786327 | AY34: 0.65168064 | BA34: 17.878985 | BB34: 0.67648265
A35: Korea | B35: 0.16054748 | C35: 0.018163673 | E35: 1.0421392 | F35: 0.0095665926 | H35: 7.8533114 | I35: 0.40789421 | K35: 27.043503 | L35: 0.68988566 | N35: 49.34078 | O35: 0.84726574 | Q35: 15.762406 | R35: 0.53941237 | T35: 7.1467798 | U35: 0.33778894 | W35: 24.546046 | X35: 0.65423736 | Z35: 51.711885 | AA35: 0.78341557 | AC35: 16.595289 | AD35: 0.54683197 | AF35: 7.6488919 | AG35: 0.37476133 | AI35: 23.262931 | AJ35: 0.6389115 | AL35: 51.09851 | AM35: 0.71368306 | AO35: 17.989667 | AP35: 0.55910805 | AR35: 7.7462751 | AS35: 0.40707164 | AU35: 23.226409 | AV35: 0.6786274 | AX35: 49.284511 | AY35: 0.77697039 | BA35: 19.742805 | BB35: 0.75822954
A36: Latvia | B36: -0.22367704 | C36: 0.014618357 | E36: 0.9073238 | F36: 0.0095303765 | H36: 8.6592708 | I36: 0.41256641 | K36: 47.852119 | L36: 0.87565097 | N36: 35.394861 | O36: 0.7950619 | Q36: 8.0937493 | R36: 0.38262453 | T36: 5.4201619 | U36: 0.37947038 | W36: 41.10711 | X36: 0.80426792 | Z36: 44.713754 | AA36: 0.84839328 | AC36: 8.7589735 | AD36: 0.40033368 | AF36: 7.0770418 | AG36: 0.41273551 | AI36: 41.296705 | AJ36: 0.88100467 | AL36: 42.599286 | AM36: 0.83330313 | AO36: 9.0269672 | AP36: 0.41214847 | AR36: 7.4037815 | AS36: 0.43117722 | AU36: 40.193082 | AV36: 0.89788406 | AX36: 42.022248 | AY36: 0.79889294 | BA36: 10.380888 | BB36: 0.46094726
A37: Lithuania | B37: 0.2192498 | C37: 0.016446788 | E37: 1.0529974 | F37: 0.008534322 | H37: 8.15368 | I37: 0.40883198 | K37: 26.456451 | L37: 0.68842207 | N37: 43.941132 | O37: 0.61326082 | Q37: 21.448738 | R37: 0.53709115 | T37: 5.7581244 | U37: 0.36853767 | W37: 25.753881 | X37: 0.61102381 | Z37: 46.86646 | AA37: 0.70596835 | AC37: 21.621534 | AD37: 0.55141558 | AF37: 6.3141621 | AG37: 0.38191327 | AI37: 25.727741 | AJ37: 0.64388051 | AL37: 46.469632 | AM37: 0.61736405 | AO37: 21.488464 | AP37: 0.55880744 | AR37: 7.1630497 | AS37: 0.40323049 | AU37: 25.105136 | AV37: 0.70933317 | AX37: 44.771953 | AY37: 0.66553195 | BA37: 22.959861 | BB37: 0.56458766
A38: Luxembourg | B38: -0.047948997 | C38: 0.014476545 | E38: 1.029997 | F38: 0.0086154789 | H38: 10.268074 | I38: 0.43625268 | K38: 32.599249 | L38: 0.70989024 | N38: 44.060981 | O38: 0.78305234 | Q38: 13.071696 | R38: 0.51226345 | T38: 8.2714675 | U38: 0.37932953 | W38: 30.937645 | X38: 0.64211493 | Z38: 47.542719 | AA38: 0.6780978 | AC38: 13.248168 | AD38: 0.48126006 | AF38: 9.1102189 | AG38: 0.42550483 | AI38: 31.596951 | AJ38: 0.62344406 | AL38: 47.070471 | AM38: 0.73658187 | AO38: 12.222359 | AP38: 0.47873337 | AR38: 10.264172 | AS38: 0.41294621 | AU38: 32.081646 | AV38: 0.56175247 | AX38: 44.432768 | AY38: 0.72274284 | BA38: 13.221415 | BB38: 0.50513239
A39: Mexico | B39: -0.054562778 | C39: 0.02225411 | D39: ‡ | E39: 0.98676394 | F39: 0.010577798 | G39: ‡ | H39: 7.979486 | I39: 0.51644882 | J39: ‡ | K39: 37.912657 | L39: 1.0830478 | M39: ‡ | N39: 42.672062 | O39: 1.0010192 | P39: ‡ | Q39: 11.435795 | R39: 0.63977799 | S39: ‡ | T39: 6.0358474 | U39: 0.46846048 | V39: ‡ | W39: 34.890215 | X39: 0.93175957 | Y39: ‡ | Z39: 47.282812 | AA39: 0.8761524 | AB39: ‡ | AC39: 11.791126 | AD39: 0.57698413 | AE39: ‡ | AF39: 6.5671697 | AG39: 0.47991143 | AH39: ‡ | AI39: 35.04089 | AJ39: 0.88988479 | AK39: ‡ | AL39: 46.441404 | AM39: 0.96322282 | AN39: ‡ | AO39: 11.950536 | AP39: 0.59521959 | AQ39: ‡ | AR39: 6.3256001 | AS39: 0.44145423 | AT39: ‡ | AU39: 33.121576 | AV39: 0.85058454 | AW39: ‡ | AX39: 46.929137 | AY39: 0.91061109 | AZ39: ‡ | BA39: 13.623687 | BB39: 0.62977704 | BC39: ‡
A40: Netherlands* | B40: 0.18482566 | C40: 0.019130224 | E40: 0.87768591 | F40: 0.010781393 | H40: 2.746872 | I40: 0.33318848 | K40: 30.073274 | L40: 0.81803693 | N40: 53.579552 | O40: 0.84928339 | Q40: 13.600302 | R40: 0.68121303 | T40: 1.741977 | U40: 0.26526714 | W40: 23.985941 | X40: 0.8215836 | Z40: 59.87361 | AA40: 0.91874575 | AC40: 14.398472 | AD40: 0.71380848 | AF40: 4.0363323 | AG40: 0.38488046 | AI40: 31.685067 | AJ40: 0.93927481 | AL40: 52.321832 | AM40: 0.91907716 | AO40: 11.956769 | AP40: 0.6412325 | AR40: 5.702336 | AS40: 0.48581497 | AU40: 34.758055 | AV40: 1.0154377 | AX40: 48.901263 | AY40: 1.0145433 | BA40: 10.638346 | BB40: 0.65234393
A41: New Zealand | B41: -0.014140229 | C41: 0.016133166 | E41: 0.92039077 | F41: 0.0086720804 | H41: 4.2296553 | I41: 0.38143279 | K41: 39.632468 | L41: 0.8909709 | N41: 45.770906 | O41: 0.80997119 | Q41: 10.366971 | R41: 0.49577773 | T41: 3.582532 | U41: 0.28859199 | W41: 33.935255 | X41: 0.87570823 | Z41: 52.327658 | AA41: 0.85247385 | AC41: 10.154555 | AD41: 0.48167797 | AF41: 5.3379262 | AG41: 0.3217535 | AI41: 36.933263 | AJ41: 0.84465172 | AL41: 47.992941 | AM41: 0.83712275 | AO41: 9.7358695 | AP41: 0.47566462 | AR41: 4.4028633 | AS41: 0.36359341 | AU41: 31.857229 | AV41: 0.85905635 | AX41: 51.430149 | AY41: 0.93606408 | BA41: 12.309759 | BB41: 0.52880403
A42: Norway | B42: 0.62197245 | C42: 0.015508513 | E42: 0.84839747 | F42: 0.012668599 | H42: 3.122048 | I42: 0.26206737 | K42: 10.382785 | L42: 0.53566293 | N42: 57.448558 | O42: 0.91814239 | Q42: 29.046609 | R42: 0.83255119 | T42: 2.5424623 | U42: 0.23775939 | W42: 10.413049 | X42: 0.5795058 | Z42: 60.628682 | AA42: 0.81574654 | AC42: 26.415807 | AD42: 0.76957282 | AF42: 2.9701569 | AG42: 0.22686583 | AI42: 12.447019 | AJ42: 0.55974535 | AL42: 58.976839 | AM42: 0.79190405 | AO42: 25.605985 | AP42: 0.71781268 | AR42: 3.5991958 | AS42: 0.27260592 | AU42: 17.215347 | AV42: 0.6541909 | AX42: 57.422802 | AY42: 0.77257778 | BA42: 21.762655 | BB42: 0.69772522
A43: Poland | B43: 0.0024117054 | C43: 0.017195597 | E43: 0.97238609 | F43: 0.0097319189 | H43: 10.205987 | I43: 0.5211775 | K43: 29.246434 | L43: 0.78638755 | N43: 49.630798 | O43: 0.84298342 | Q43: 10.916781 | R43: 0.49592057 | T43: 7.107858 | U43: 0.4224671 | W43: 27.644056 | X43: 0.69095791 | Z43: 54.144332 | AA43: 0.809188 | AC43: 11.103754 | AD43: 0.52178048 | AF43: 7.7125663 | AG43: 0.38127144 | AI43: 29.638136 | AJ43: 0.68374245 | AL43: 52.161124 | AM43: 0.76399892 | AO43: 10.488175 | AP43: 0.47723081 | AR43: 8.9249761 | AS43: 0.46753588 | AU43: 28.792804 | AV43: 0.73330487 | AX43: 49.590594 | AY43: 0.74692547 | BA43: 12.691625 | BB43: 0.51546262
...

Sheet Table III.B1.8.2
A1: PISA 2018 Results (Volume III) - © OECD 2019
A2: Annex B1 | B2: Annex B1.8 Results (tables): Student co-operation and competition
A3: Version 2 - Last updated: 02-Dec-2019
A4: Disclaimer: http://oe.cd/disclaimer
A6: Table III.B1.8.2
A7: Student competition
A8: Based on students' reports
B11: Index of student competition1 | H11: Percentage of students who reported the following:
H12: Students seem to value competition | T12: It seems that students are competing with each other | AF12: Students seem to share the feeling that competing with each other is important | AR12: Students feel that they are being compared with others
B13: Average | E13: Variability | H13: Not at all true | K13: Slightly true | N13: Very true | Q13: Extremely true | T13: Not at all true | W13: Slightly true | Z13: Very true | AC13: Extremely true | AF13: Not at all true | AI13: Slightly true | AL13: Very true | AO13: Extremely true | AR13: Not at all true | AU13: Slightly true | AX13: Very true | BA13: Extremely true
B14: Mean index | C14: S.E. | E14: S.D. | F14: S.E. | H14: % | I14: S.E. | K14: % | L14: S.E. | N14: % | O14: S.E. | Q14: % | R14: S.E. | T14: % | U14: S.E. | W14: % | X14: S.E. | Z14: % | AA14: S.E. | AC14: % | AD14: S.E. | AF14: % | AG14: S.E. | AI14: % | AJ14: S.E. | AL14: % | AM14: S.E. | AO14: % | AP14: S.E. | AR14: % | AS14: S.E. | AU14: % | AV14: S.E. | AX14: % | AY14: S.E. | BA14: % | BB14: S.E.
A15: OECD
A16: Australia | B16: 0.34728761 | C16: 0.011595543 | E16: 0.95086095 | F16: 0.0062264301 | H16: 3.4707911 | I16: 0.18282206 | K16: 29.684591 | L16: 0.50642413 | N16: 48.041919 | O16: 0.51563543 | Q16: 18.8027 | R16: 0.45916765 | T16: 5.1887283 | U16: 0.22156248 | W16: 30.628474 | X16: 0.50657931 | Z16: 44.216505 | AA16: 0.53076362 | AC16: 19.966293 | AD16: 0.46321132 | AF16: 8.8305779 | AG16: 0.2999715 | AI16: 35.571402 | AJ16: 0.59480272 | AL16: 40.840306 | AM16: 0.49384414 | AO16: 14.757714 | AP16: 0.44879073 | AR16: 5.9845774 | AS16: 0.25015842 | AU16: 25.660209 | AV16: 0.44946273 | AX16: 39.342869 | AY16: 0.48755505 | BA16: 29.012345 | BB16: 0.53287803
A17: Austria | B17: -0.029612781 | C17: 0.015955432 | E17: 0.93714883 | F17: 0.011014452 | H17: 11.987101 | I17: 0.53073157 | K17: 43.854741 | L17: 0.78512839 | N17: 35.364407 | O17: 0.70229741 | Q17: 8.7937509 | R17: 0.45211462 | T17: 11.5848 | U17: 0.50721988 | W17: 35.861667 | X17: 0.7863658 | Z17: 41.343543 | AA17: 0.77538622 | AC17: 11.20999 | AD17: 0.52008135 | AF17: 13.587159 | AG17: 0.54714049 | AI17: 40.744615 | AJ17: 0.78317133 | AL17: 36.959825 | AM17: 0.7380825 | AO17: 8.7084017 | AP17: 0.44147767 | AR17: 11.513666 | AS17: 0.46309801 | AU17: 34.955904 | AV17: 0.72865305 | AX17: 37.91901 | AY17: 0.79782291 | BA17: 15.611421 | BB17: 0.54219132
A18: Belgium | B18: -0.30551273 | C18: 0.015314899 | E18: 0.99223792 | F18: 0.0080828831 | H18: 12.730237 | I18: 0.38559782 | K18: 49.81432 | L18: 0.73899124 | N18: 31.58238 | O18: 0.65455009 | Q18: 5.8730623 | R18: 0.35256919 | T18: 19.462033 | U18: 0.547162 | W18: 39.872439 | X18: 0.65910332 | Z18: 33.440931 | AA18: 0.65019839 | AC18: 7.2245969 | AD18: 0.34069206 | AF18: 25.920501 | AG18: 0.61559545 | AI18: 38.847651 | AJ18: 0.73082385 | AL18: 29.203411 | AM18: 0.58351279 | AO18: 6.0284382 | AP18: 0.35364774 | AR18: 12.664159 | AS18: 0.42743364 | AU18: 31.181913 | AV18: 0.64248933 | AX18: 38.886488 | AY18: 0.68540617 | BA18: 17.267441 | BB18: 0.4571596
A19: Canada | B19: m | C19: m | E19: m | F19: m | H19: m | I19: m | K19: m | L19: m | N19: m | O19: m | Q19: m | R19: m | T19: m | U19: m | W19: m | X19: m | Z19: m | AA19: m | AC19: m | AD19: m | AF19: m | AG19: m | AI19: m | AJ19: m | AL19: m | AM19: m | AO19: m | AP19: m | AR19: m | AS19: m | AU19: m | AV19: m | AX19: m | AY19: m | BA19: m | BB19: m
A20: Chile | B20: -0.023663565 | C20: 0.0216088 | D20: † | E20: 1.0019232 | F20: 0.0097777151 | G20: † | H20: 10.226522 | I20: 0.51958964 | J20: † | K20: 47.108596 | L20: 0.81594511 | M20: † | N20: 31.089807 | O20: 0.69438828 | P20: † | Q20: 11.575075 | R20: 0.54672048 | S20: † | T20: 10.909309 | U20: 0.49669191 | V20: † | W20: 41.513217 | X20: 0.85139077 | Y20: † | Z20: 32.806141 | AA20: 0.7153951 | AB20: † | AC20: 14.771333 | AD20: 0.6340567 | AE20: † | AF20: 14.550108 | AG20: 0.68668888 | AH20: † | AI20: 42.546139 | AJ20: 0.81767083 | AK20: † | AL20: 30.531078 | AM20: 0.65425574 | AN20: † | AO20: 12.372674 | AP20: 0.60050058 | AQ20: † | AR20: 13.852288 | AS20: 0.48808821 | AT20: † | AU20: 39.799717 | AV20: 0.9452313 | AW20: † | AX20: 29.021184 | AY20: 0.72618866 | AZ20: † | BA20: 17.326811 | BB20: 0.66494784 | BC20: †
A21: Colombia | B21: 0.11927402 | C21: 0.017431963 | D21: † | E21: 0.86841013 | F21: 0.012054001 | G21: † | H21: 11.758897 | I21: 0.54743761 | J21: † | K21: 34.742789 | L21: 0.84238107 | M21: † | N21: 45.707686 | O21: 0.92429523 | P21: † | Q21: 7.7906281 | R21: 0.44849269 | S21: † | T21: 9.4129069 | U21: 0.58668952 | V21: † | W21: 30.561668 | X21: 0.74144591 | Y21: † | Z21: 48.990239 | AA21: 0.96040632 | AB21: † | AC21: 11.035186 | AD21: 0.5615336 | AE21: † | AF21: 10.73859 | AG21: 0.55043042 | AH21: † | AI21: 31.886801 | AJ21: 0.81570211 | AK21: † | AL21: 47.325254 | AM21: 0.89962335 | AN21: † | AO21: 10.049355 | AP21: 0.53713929 | AQ21: † | AR21: 17.111885 | AS21: 0.74730122 | AT21: † | AU21: 30.93387 | AV21: 0.78919683 | AW21: † | AX21: 38.958238 | AY21: 0.76293816 | AZ21: † | BA21: 12.996006 | BB21: 0.68742034 | BC21: †
A22: Czech Republic | B22: -0.51453073 | C22: 0.013677075 | E22: 0.91799055 | F22: 0.010950509 | H22: 17.758251 | I22: 0.46730399 | K22: 55.980912 | L22: 0.67452491 | N22: 20.228227 | O22: 0.62318844 | Q22: 6.0326105 | R22: 0.37537576 | T22: 21.187477 | U22: 0.61810975 | W22: 51.208717 | X22: 0.7850479 | Z22: 21.63535 | AA22: 0.63549857 | AC22: 5.9684568 | AD22: 0.37628794 | AF22: 27.590556 | AG22: 0.66280582 | AI22: 49.033386 | AJ22: 0.72643557 | AL22: 19.077228 | AM22: 0.53488054 | AO22: 4.2988303 | AP22: 0.35887279 | AR22: 13.254961 | AS22: 0.43343016 | AU22: 43.452811 | AV22: 0.6408765 | AX22: 30.118622 | AY22: 0.70372023 | BA22: 13.173606 | BB22: 0.51105098
A23: Denmark | B23: -0.1975122 | C23: 0.015383513 | E23: 0.90283824 | F23: 0.0094063845 | H23: 5.9172873 | I23: 0.34501819 | K23: 45.334504 | L23: 1.0389163 | N23: 40.014014 | O23: 0.87948915 | Q23: 8.7341941 | R23: 0.49716783 | T23: 12.174161 | U23: 0.42408201 | W23: 45.174962 | X23: 0.72575934 | Z23: 34.259767 | AA23: 0.77044366 | AC23: 8.3911094 | AD23: 0.44860075 | AF23: 24.631853 | AG23: 0.71530701 | AI23: 45.846158 | AJ23: 0.75015696 | AL23: 24.167864 | AM23: 0.7300318 | AO23: 5.3541253 | AP23: 0.32340894 | AR23: 13.550775 | AS23: 0.5384118 | AU23: 39.10925 | AV23: 0.71326225 | AX23: 33.310804 | AY23: 0.63288723 | BA23: 14.029171 | BB23: 0.57995772
A24: Estonia | B24: -0.30999629 | C24: 0.014126335 | E24: 0.86146616 | F24: 0.0093451826 | H24: 8.889782 | I24: 0.4942608 | K24: 57.437243 | L24: 0.70542946 | N24: 27.403264 | O24: 0.69347293 | Q24: 6.2697114 | R24: 0.40990986 | T24: 14.437959 | U24: 0.51727158 | W24: 52.120088 | X24: 0.76146665 | Z24: 26.644411 | AA24: 0.76703989 | AC24: 6.7975422 | AD24: 0.41239399 | AF24: 18.669153 | AG24: 0.57893709 | AI24: 51.211677 | AJ24: 0.79276801 | AL24: 24.666668 | AM24: 0.6454661 | AO24: 5.4525014 | AP24: 0.38453354 | AR24: 10.172743 | AS24: 0.47962223 | AU24: 41.500503 | AV24: 0.65618104 | AX24: 32.836392 | AY24: 0.71629813 | BA24: 15.490362 | BB24: 0.55749067
A25: Finland | B25: 0.10211281 | C25: 0.015232926 | E25: 0.85870418 | F25: 0.0094917176 | H25: 4.8464762 | I25: 0.2895046 | K25: 40.831027 | L25: 0.85000125 | N25: 46.964691 | O25: 0.87283363 | Q25: 7.3578068 | R25: 0.37429743 | T25: 6.2215071 | U25: 0.38021389 | W25: 35.214449 | X25: 0.80013448 | Z25: 47.945622 | AA25: 0.80519909 | AC25: 10.618421 | AD25: 0.52702983 | AF25: 9.347526 | AG25: 0.38705947 | AI25: 42.781345 | AJ25: 0.82177856 | AL25: 41.58062 | AM25: 0.78965831 | AO25: 6.2905083 | AP25: 0.3351449 | AR25: 9.6332915 | AS25: 0.44556169 | AU25: 37.913316 | AV25: 0.8748005 | AX25: 38.596111 | AY25: 0.70589644 | BA25: 13.857281 | BB25: 0.49082007
A26: France | B26: -0.18156863 | C26: 0.018713247 | E26: 1.105335 | F26: 0.0099350793 | H26: 11.848693 | I26: 0.44987864 | K26: 44.868156 | L26: 0.83418685 | N26: 29.590453 | O26: 0.7197658 | Q26: 13.692698 | R26: 0.53264832 | T26: 18.619574 | U26: 0.58131724 | W26: 40.407528 | X26: 0.75986558 | Z26: 27.211563 | AA26: 0.71329287 | AC26: 13.761335 | AD26: 0.58149724 | AF26: 25.059434 | AG26: 0.66141217 | AI26: 38.589602 | AJ26: 0.68996508 | AL26: 24.95693 | AM26: 0.60209106 | AO26: 11.394034 | AP26: 0.43293127 | AR26: 13.245833 | AS26: 0.53566962 | AU26: 32.217825 | AV26: 0.59369445 | AX26: 32.48557 | AY26: 0.58127061 | BA26: 22.050773 | BB26: 0.57651944
A27: Germany | B27: -0.4019879 | C27: 0.020920155 | D27: ‡ | E27: 0.9374771 | F27: 0.014384221 | G27: ‡ | H27: 16.368216 | I27: 0.78559403 | J27: ‡ | K27: 50.432353 | L27: 1.0195627 | M27: ‡ | N27: 28.308402 | O27: 0.97719388 | P27: ‡ | Q27: 4.8910291 | R27: 0.48382615 | S27: ‡ | T27: 21.522465 | U27: 0.87676602 | V27: ‡ | W27: 45.189492 | X27: 1.1137127 | Y27: ‡ | Z27: 27.37278 | AA27: 0.86570717 | AB27: ‡ | AC27: 5.9152635 | AD27: 0.54829558 | AE27: ‡ | AF27: 23.997354 | AG27: 0.88167259 | AH27: ‡ | AI27: 44.113648 | AJ27: 1.0679092 | AK27: ‡ | AL27: 26.235139 | AM27: 0.82738905 | AN27: ‡ | AO27: 5.6538597 | AP27: 0.52551266 | AQ27: ‡ | AR27: 12.793655 | AS27: 0.75460632 | AT27: ‡ | AU27: 34.493302 | AV27: 0.9068827 | AW27: ‡ | AX27: 36.979927 | AY27: 0.82821716 | AZ27: ‡ | BA27: 15.733116 | BB27: 0.86055412 | BC27: ‡
A28: Greece | B28: -0.058905157 | C28: 0.014218939 | E28: 0.94952659 | F28: 0.0082831818 | H28: 13.599342 | I28: 0.56214003 | K28: 50.528393 | L28: 0.7312407 | N28: 26.79736 | O28: 0.62271479 | Q28: 9.0749048 | R28: 0.38526616 | T28: 8.9943713 | U28: 0.38315998 | W28: 40.255492 | X28: 0.68300494 | Z28: 35.419987 | AA28: 0.63612776 | AC28: 15.33015 | AD28: 0.55089698 | AF28: 15.08735 | AG28: 0.54199767 | AI28: 44.512116 | AJ28: 0.67634605 | AL28: 31.246876 | AM28: 0.60748969 | AO28: 9.153658 | AP28: 0.33473601 | AR28: 8.8610277 | AS28: 0.43195549 | AU28: 31.330714 | AV28: 0.61840763 | AX28: 34.665895 | AY28: 0.68854244 | BA28: 25.142363 | BB28: 0.71529962
A29: Hungary | B29: -0.20072875 | C29: 0.018474254 | E29: 0.99287398 | F29: 0.010954624 | H29: 11.26451 | I29: 0.57821178 | K29: 48.196829 | L29: 0.83262592 | N29: 30.76858 | O29: 0.89786748 | Q29: 9.770081 | R29: 0.51800127 | T29: 13.457003 | U29: 0.60159689 | W29: 47.065914 | X29: 0.69609765 | Z29: 30.448564 | AA29: 0.76009891 | AC29: 9.0285181 | AD29: 0.52585148 | AF29: 18.986912 | AG29: 0.63520736 | AI29: 46.182768 | AJ29: 0.78704954 | AL29: 26.522761 | AM29: 0.65022071 | AO29: 8.3075592 | AP29: 0.42825599 | AR29: 15.191713 | AS29: 0.61978077 | AU29: 39.427342 | AV29: 0.8139732 | AX29: 30.543974 | AY29: 0.7118928 | BA29: 14.836971 | BB29: 0.68404121
A30: Iceland | B30: 0.087208729 | C30: 0.018279813 | D30: † | E30: 0.98736671 | F30: 0.012767192 | G30: † | H30: 8.4788548 | I30: 0.46189801 | K30: 29.962137 | L30: 0.9166201 | N30: 48.380993 | O30: 1.0003366 | Q30: 13.178015 | R30: 0.62622814 | T30: 10.003476 | U30: 0.58035308 | W30: 37.024599 | X30: 0.82042557 | Z30: 40.89166 | AA30: 0.82859855 | AC30: 12.080266 | AD30: 0.69252338 | AF30: 12.256924 | AG30: 0.59117051 | AI30: 40.460764 | AJ30: 0.899291 | AL30: 38.01053 | AM30: 0.84226232 | AO30: 9.2717816 | AP30: 0.54284245 | AR30: 10.252369 | AS30: 0.59695392 | AU30: 32.394725 | AV30: 0.87239236 | AX30: 42.808489 | AY30: 0.89932805 | BA30: 14.544417 | BB30: 0.72287508
A31: Ireland | B31: 0.20302336 | C31: 0.017762515 | E31: 0.97316974 | F31: 0.0094251077 | H31: 4.4613381 | I31: 0.27520302 | K31: 34.498869 | L31: 0.82870704 | N31: 44.596229 | O31: 0.83783785 | Q31: 16.443564 | R31: 0.54530095 | T31: 8.0406505 | U31: 0.4519248 | W31: 34.793734 | X31: 0.82324627 | Z31: 40.036881 | AA31: 0.89529938 | AC31: 17.128735 | AD31: 0.5730204 | AF31: 12.088563 | AG31: 0.52701789 | AI31: 37.467794 | AJ31: 0.75832431 | AL31: 37.50667 | AM31: 0.84241449 | AO31: 12.936973 | AP31: 0.56383535 | AR31: 8.6058906 | AS31: 0.42260309 | AU31: 26.296513 | AV31: 0.77907019 | AX31: 35.873379 | AY31: 0.87094696 | BA31: 29.224218 | BB31: 0.82067773
A32: Israel | B32: -0.079310129 | C32: 0.022402562 | E32: 1.0669491 | F32: 0.0099164828 | H32: 16.558673 | I32: 0.62309642 | K32: 40.638659 | L32: 0.66390336 | N32: 30.910193 | O32: 0.69414156 | Q32: 11.892475 | R32: 0.56921315 | T32: 13.517573 | U32: 0.60569473 | W32: 37.609096 | X32: 0.7045979 | Z32: 33.520755 | AA32: 0.62812044 | AC32: 15.352576 | AD32: 0.61331231 | AF32: 20.468406 | AG32: 0.75303714 | AI32: 37.886164 | AJ32: 0.67075857 | AL32: 29.921212 | AM32: 0.69954995 | AO32: 11.724217 | AP32: 0.55927414 | AR32: 16.739623 | AS32: 0.65948571 | AU32: 34.546987 | AV32: 0.66988212 | AX32: 28.130461 | AY32: 0.69091134 | BA32: 20.582928 | BB32: 0.67274356
A33: Italy | B33: -0.21240223 | C33: 0.014203001 | E33: 0.95065129 | F33: 0.010997629 | H33: 12.640677 | I33: 0.51364892 | K33: 45.987656 | L33: 0.80646798 | N33: 31.009079 | O33: 0.86672027 | Q33: 10.362588 | R33: 0.46790484 | T33: 15.68163 | U33: 0.52373698 | W33: 46.527776 | X33: 0.70055775 | Z33: 28.990473 | AA33: 0.70833175 | AC33: 8.8001213 | AD33: 0.50414168 | AF33: 18.722046 | AG33: 0.59420689 | AI33: 43.458852 | AJ33: 0.76585512 | AL33: 29.603253 | AM33: 0.80967081 | AO33: 8.2158488 | AP33: 0.46797966 | AR33: 13.185292 | AS33: 0.54705612 | AU33: 39.201851 | AV33: 0.69322946 | AX33: 32.409105 | AY33: 0.72297533 | BA33: 15.203752 | BB33: 0.5745547
A34: Japan | B34: -0.36880228 | C34: 0.023778984 | E34: 1.0035787 | F34: 0.013298667 | H34: 21.103615 | I34: 0.72818932 | K34: 54.430797 | L34: 0.66578764 | N34: 17.56023 | O34: 0.63109076 | Q34: 6.9053571 | R34: 0.44788856 | T34: 16.743015 | U34: 0.6640764 | W34: 49.087321 | X34: 0.76336247 | Z34: 26.000377 | AA34: 0.75423847 | AC34: 8.1692873 | AD34: 0.51930088 | AF34: 18.997225 | AG34: 0.6941253 | AI34: 49.039299 | AJ34: 0.71751912 | AL34: 24.876781 | AM34: 0.7327042 | AO34: 7.0866949 | AP34: 0.50555908 | AR34: 19.16426 | AS34: 0.61409748 | AU34: 44.912963 | AV34: 0.75788065 | AX34: 24.282213 | AY34: 0.67628954 | BA34: 11.640564 | BB34: 0.49730229
A35: Korea | B35: 0.52219738 | C35: 0.022348097 | E35: 1.1111927 | F35: 0.0097259781 | H35: 8.8590381 | I35: 0.4780489 | K35: 25.198025 | L35: 0.63420614 | N35: 41.621765 | O35: 0.62702583 | Q35: 24.321171 | R35: 0.74627701 | T35: 7.0179485 | U35: 0.41442115 | W35: 20.251234 | X35: 0.58904184 | Z35: 40.69892 | AA35: 0.7366128 | AC35: 32.031898 | AD35: 0.87259759 | AF35: 10.834636 | AG35: 0.54485858 | AI35: 23.828068 | AJ35: 0.5491199 | AL35: 40.563619 | AM35: 0.67741546 | AO35: 24.773676 | AP35: 0.75839164 | AR35: 12.29002 | AS35: 0.4600873 | AU35: 23.988523 | AV35: 0.62955019 | AX35: 38.251056 | AY35: 0.63508335 | BA35: 25.470401 | BB35: 0.77617551
A36: Latvia | B36: -0.073920631 | C36: 0.014195437 | E36: 0.88871475 | F36: 0.0093497235 | H36: 8.3065734 | I36: 0.38496947 | K36: 53.377323 | L36: 0.78923177 | N36: 30.752765 | O36: 0.71968988 | Q36: 7.5633391 | R36: 0.4354681 | T36: 8.1644277 | U36: 0.41923473 | W36: 45.581566 | X36: 0.74485901 | Z36: 35.672859 | AA36: 0.68601588 | AC36: 10.581147 | AD36: 0.50846556 | AF36: 12.474794 | AG36: 0.53682535 | AI36: 46.657108 | AJ36: 0.81866974 | AL36: 32.042309 | AM36: 0.76657036 | AO36: 8.8257886 | AP36: 0.47458691 | AR36: 8.6085818 | AS36: 0.44697101 | AU36: 37.804631 | AV36: 0.76426897 | AX36: 35.256683 | AY36: 0.8229953 | BA36: 18.330105 | BB36: 0.64652022
A37: Lithuania | B37: 0.097558124 | C37: 0.014319959 | E37: 1.0060772 | F37: 0.0089101119 | H37: 9.1563674 | I37: 0.42848432 | K37: 41.045075 | L37: 0.65479447 | N37: 36.549714 | O37: 0.64918655 | Q37: 13.248844 | R37: 0.43399395 | T37: 8.2012408 | U37: 0.40053806 | W37: 40.340927 | X37: 0.64908843 | Z37: 36.692436 | AA37: 0.6665271 | AC37: 14.765396 | AD37: 0.55000542 | AF37: 11.281794 | AG37: 0.5012212 | AI37: 39.656147 | AJ37: 0.69304652 | AL37: 35.030772 | AM37: 0.61047202 | AO37: 14.031286 | AP37: 0.45445016 | AR37: 9.6795244 | AS37: 0.36186656 | AU37: 34.759681 | AV37: 0.63113792 | AX37: 34.146182 | AY37: 0.68711425 | BA37: 21.414613 | BB37: 0.63628298
A38: Luxembourg | B38: -0.14937022 | C38: 0.01645398 | E38: 0.95440459 | F38: 0.01065448 | H38: 12.131349 | I38: 0.5100206 | K38: 48.184724 | L38: 0.67493516 | N38: 31.345471 | O38: 0.62716579 | Q38: 8.3384564 | R38: 0.45773107 | T38: 13.457267 | U38: 0.59048707 | W38: 41.654745 | X38: 0.69871252 | Z38: 35.330086 | AA38: 0.69616098 | AC38: 9.5579031 | AD38: 0.48501454 | AF38: 18.005628 | AG38: 0.59836247 | AI38: 41.921952 | AJ38: 0.69770793 | AL38: 31.656539 | AM38: 0.67641345 | AO38: 8.4158819 | AP38: 0.40620303 | AR38: 11.396418 | AS38: 0.50075554 | AU38: 34.68303 | AV38: 0.6303613 | AX38: 36.755133 | AY38: 0.61072434 | BA38: 17.165419 | BB38: 0.51910487
A39: Mexico | B39: 0.0073958545 | C39: 0.016081318 | D39: † | E39: 0.87450723 | F39: 0.011774475 | G39: † | H39: 6.0645931 | I39: 0.46425628 | J39: † | K39: 40.989813 | L39: 0.87547525 | M39: † | N39: 43.994822 | O39: 0.82693208 | P39: † | Q39: 8.9507718 | R39: 0.55629739 | S39: † | T39: 9.7937261 | U39: 0.52839668 | V39: † | W39: 42.011485 | X39: 0.93043908 | Y39: † | Z39: 39.683759 | AA39: 0.8558756 | AB39: † | AC39: 8.5110305 | AD39: 0.46229417 | AE39: † | AF39: 11.710713 | AG39: 0.57867689 | AH39: † | AI39: 40.960725 | AJ39: 0.734381 | AK39: † | AL39: 38.485819 | AM39: 0.75579064 | AN39: † | AO39: 8.8427429 | AP39: 0.43438032 | AQ39: † | AR39: 14.61813 | AS39: 0.57151018 | AT39: † | AU39: 37.367735 | AV39: 0.88451045 | AW39: † | AX39: 37.077938 | AY39: 0.87921283 | AZ39: † | BA39: 10.936197 | BB39: 0.60965779 | BC39: †
A40: Netherlands* | B40: -0.44702738 | C40: 0.01598364 | E40: 0.82960063 | F40: 0.013377978 | H40: 12.305994 | I40: 0.5751473 | K40: 64.801994 | L40: 0.76953572 | N40: 20.41514 | O40: 0.63030737 | Q40: 2.4768717 | R40: 0.28478228 | T40: 16.437849 | U40: 0.72305302 | W40: 49.875337 | X40: 0.85554379 | Z40: 28.322949 | AA40: 0.69147955 | AC40: 5.3638645 | AD40: 0.42222263 | AF40: 25.820469 | AG40: 0.84044746 | AI40: 48.444914 | AJ40: 1.0285256 | AL40: 22.205934 | AM40: 0.77256259 | AO40: 3.5286827 | AP40: 0.39918738 | AR40: 13.913312 | AS40: 0.64954682 | AU40: 42.26001 | AV40: 0.89371776 | AX40: 33.2148 | AY40: 0.75432789 | BA40: 10.611878 | BB40: 0.55743268
A41: New Zealand | B41: 0.33776632 | C41: 0.013173983 | E41: 0.9286158 | F41: 0.0088870065 | H41: 3.0686302 | I41: 0.26653905 | K41: 30.024594 | L41: 0.71323411 | N41: 48.422782 | O41: 0.85441405 | Q41: 18.483993 | R41: 0.5158666 | T41: 4.510786 | U41: 0.30969469 | W41: 31.087299 | X41: 0.6538301 | Z41: 45.75945 | AA41: 0.81074984 | AC41: 18.642465 | AD41: 0.55864612 | AF41: 8.3384197 | AG41: 0.44648537 | AI41: 36.183893 | AJ41: 0.65040562 | AL41: 42.149136 | AM41: 0.73862893 | AO41: 13.328551 | AP41: 0.45559849 | AR41: 6.1381137 | AS41: 0.35929366 | AU41: 26.26133 | AV41: 0.66113395 | AX41: 38.281144 | AY41: 0.7329415 | BA41: 29.319412 | BB41: 0.68216361
A42: Norway | B42: 0.42504748 | C42: 0.015863717 | E42: 0.87665997 | F42: 0.01123708 | H42: 3.3019607 | I42: 0.30176338 | K42: 15.459252 | L42: 0.51181388 | N42: 57.149472 | O42: 0.68805252 | Q42: 24.089315 | R42: 0.67098951 | T42: 4.3346413 | U42: 0.29790775 | W42: 26.445076 | X42: 0.61451833 | Z42: 51.160031 | AA42: 0.75175153 | AC42: 18.060252 | AD42: 0.62559891 | AF42: 7.0353008 | AG42: 0.37740921 | AI42: 35.863692 | AJ42: 0.78138416 | AL42: 45.3044 | AM42: 0.77372037 | AO42: 11.796607 | AP42: 0.50847621 | AR42: 6.8255189 | AS42: 0.33281554 | AU42: 27.233746 | AV42: 0.7170385 | AX42: 44.656052 | AY42: 0.63899993 | BA42: 21.284683 | BB42: 0.57261848
A43: Poland | B43: 0.17748956 | C43: 0.013581223 | E43: 0.89392712 | F43: 0.011206312 | H43: 10.271616 | I43: 0.58409491 | K43: 34.782501 | L43: 0.70696348 | N43: 45.184953 | O43: 0.75500203 | Q43: 9.7609302 | R43: 0.42270005 | T43: 7.2532944 | U43: 0.40433941 | W43: 30.983642 | X43: 0.66882383 | Z43: 48.297963 | AA43: 0.87151398 | AC43: 13.4651 | AD43: 0.5105403 | AF43: 8.2651432 | AG43: 0.4796339 | AI43: 34.985406 | AJ43: 0.71792088 | AL43: 47.331942 | AM43: 0.77001431 | AO43: 9.4175089 | AP43: 0.43318715 | AR43: 7.6269595 | AS43: 0.51694811 | AU43: 24.018908 | AV43: 0.63168784 | AX43: 44.833385 | AY43: 0.81932033 | BA43: 23.520747 | BB43: 0.72620542
...

Sheet Table III.B1.8.3
A1: PISA 2018 Results (Volume III) - © OECD 2019
A2: Annex B1 | B2: Annex B1.8 Results (tables): Student co-operation and competition
A3: Version 2 - Last updated: 02-Dec-2019
A4: Disclaimer: http://oe.cd/disclaimer
A6: Table III.B1.8.3
A7: Difference between student co-operation and competition
A8: Based on students' reports
B11: Index of student co-operation | E11: Index of student competition | H11: Difference between the indices of co-operation and competition
B14: Mean index | C14: S.E. | E14: Mean index | F14: S.E. | H14: Dif. | I14: S.E.
A15: OECD
A16: Australia | B16: 0.024334781 | C16: 0.012851336 | D16: † | E16: 0.34728761 | F16: 0.011595543 | H16: -0.32616715 | I16: 0.014789694 | J16: †
A17: Austria | B17: 0.35646852 | C17: 0.020974523 | E17: -0.029612781 | F17: 0.015955432 | H17: 0.39018965 | I17: 0.024776821 | J17: †
A18: Belgium | B18: -0.057201043 | C18: 0.015633574 | E18: -0.30551273 | F18: 0.015314899 | H18: 0.25063981 | I18: 0.022065456
A19: Canada | B19: m | C19: m | E19: m | F19: m | H19: m | I19: m
A20: Chile | B20: -0.17271714 | C20: 0.024625825 | D20: † | E20: -0.023663565 | F20: 0.0216088 | G20: † | H20: -0.1530393 | I20: 0.026188347 | J20: †
A21: Colombia | B21: -0.13124253 | C21: 0.020576081 | D21: † | E21: 0.11927402 | F21: 0.017431963 | G21: † | H21: -0.25117257 | I21: 0.02161892 | J21: †
A22: Czech Republic | B22: -0.22183528 | C22: 0.018754458 | E22: -0.51453073 | F22: 0.013677075 | H22: 0.29487144 | I22: 0.025519209
A23: Denmark | B23: 0.3427123 | C23: 0.01486662 | E23: -0.1975122 | F23: 0.015383513 | H23: 0.5411954 | I23: 0.020382914
A24: Estonia | B24: -0.11676621 | C24: 0.015580692 | E24: -0.30999629 | F24: 0.014126335 | H24: 0.19370461 | I24: 0.018489276
A25: Finland | B25: 0.08341595 | C25: 0.016507131 | E25: 0.10211281 | F25: 0.015232926 | H25: -0.016523763 | I25: 0.021607561
A26: France | B26: -0.37953541 | C26: 0.016247046 | D26: † | E26: -0.18156863 | F26: 0.018713247 | H26: -0.20169793 | I26: 0.024767889 | J26: †
A27: Germany | B27: 0.067556501 | C27: 0.025913674 | D27: ‡ | E27: -0.4019879 | F27: 0.020920155 | G27: ‡ | H27: 0.46854956 | I27: 0.031944928 | J27: ‡
A28: Greece | B28: -0.016153399 | C28: 0.017312529 | E28: -0.058905157 | F28: 0.014218939 | H28: 0.042908858 | I28: 0.02076768
A29: Hungary | B29: -0.13145841 | C29: 0.023976022 | E29: -0.20072875 | F29: 0.018474254 | H29: 0.072038933 | I29: 0.029021462
A30: Iceland | B30: 0.31193357 | C30: 0.022423244 | D30: † | E30: 0.087208729 | F30: 0.018279813 | G30: † | H30: 0.22332286 | I30: 0.02447909 | J30: †
A31: Ireland | B31: -0.17227425 | C31: 0.016413571 | E31: 0.20302336 | F31: 0.017762515 | H31: -0.39404917 | I31: 0.02359223
A32: Israel | B32: 0.06969555 | C32: 0.022042352 | E32: -0.079310129 | F32: 0.022402562 | H32: 0.14586157 | I32: 0.02928459
A33: Italy | B33: -0.31281902 | C33: 0.015790849 | E33: -0.21240223 | F33: 0.014203001 | H33: -0.10237826 | I33: 0.021025819 | J33: †
A34: Japan | B34: 0.11152416 | C34: 0.022927011 | E34: -0.36880228 | F34: 0.023778984 | H34: 0.47885155 | I34: 0.024463903
A35: Korea | B35: 0.16054748 | C35: 0.018163673 | E35: 0.52219738 | F35: 0.022348097 | H35: -0.36042532 | I35: 0.030500902
A36: Latvia | B36: -0.22367704 | C36: 0.014618357 | E36: -0.073920631 | F36: 0.014195437 | H36: -0.14446355 | I36: 0.020086737
A37: Lithuania | B37: 0.2192498 | C37: 0.016446788 | E37: 0.097558124 | F37: 0.014319959 | H37: 0.12444925 | I37: 0.024522814
A38: Luxembourg | B38: -0.047948997 | C38: 0.014476545 | E38: -0.14937022 | F38: 0.01645398 | H38: 0.10159377 | I38: 0.019974116
A39: Mexico | B39: -0.054562778 | C39: 0.02225411 | D39: ‡ | E39: 0.0073958545 | F39: 0.016081318 | G39: † | H39: -0.068744301 | I39: 0.022386012 | J39: ‡
A40: Netherlands* | B40: 0.18482566 | C40: 0.019130224 | E40: -0.44702738 | F40: 0.01598364 | H40: 0.63017364 | I40: 0.021396937
A41: New Zealand | B41: -0.014140229 | C41: 0.016133166 | E41: 0.33776632 | F41: 0.013173983 | H41: -0.35916212 | I41: 0.016177573
A42: Norway | B42: 0.62197245 | C42: 0.015508513 | E42: 0.42504748 | F42: 0.015863717 | H42: 0.19742865 | I42: 0.019002318
A43: Poland | B43: 0.0024117054 | C43: 0.017195597 | E43: 0.17748956 | F43: 0.013581223 | H43: -0.18257158 | I43: 0.022351822
A44: Portugal* | B44: -0.06073211 | C44: 0.019206288 | E44: 0.19267493 | F44: 0.014207891 | H44: -0.25944236 | I44: 0.023978189
A45: Slovak Republic | B45: -0.22832337 | C45: 0.01514256 | E45: -0.094587172 | F45: 0.015041573 | H45: -0.1309945 | I45: 0.021041563
...

Sheet Table III.B1.8.4
A1: PISA 2018 Results (Volume III) - © OECD 2019
A2: Annex B1 | B2: Annex B1.8 Results (tables): Student co-operation and competition
A3: Version 2 - Last updated: 02-Dec-2019
A4: Disclaimer: http://oe.cd/disclaimer
A6: Table III.B1.8.4
A7: Prevalence of student co-operation in schools
A8: Based on students' reports
B11: Percentage of students who reported that it is very or extremely true that students co-operate with each other | E11: Percentage of students who are in schools where…
E12: Over 90% of students reported that it is very or extremely true that students co-operate with each other | H12: Between 75% and 90% of students reported that it is very or extremely true that students co-operate with each other | K12: Between 25% and 75% of students reported that it is very or extremely true that students co-operate with each other | N12: Between 10% and 25% of students reported that it is very or extremely true that students co-operate with each other | Q12: 10% of students or less reported that it is very or extremely true that students co-operate with each other
B14: % | C14: S.E. | E14: % | F14: S.E. | H14: % | I14: S.E. | K14: % | L14: S.E. | N14: % | O14: S.E. | Q14: % | R14: S.E.
A15: OECD
A16: Australia | B16: 63.713551 | C16: 0.5359896 | D16: † | E16: 6.1653547 | F16: 0.97646011 | H16: 18.672762 | I16: 1.6227901 | K16: 73.333862 | L16: 1.5226763 | N16: 1.4197333 | O16: 0.49244582 | Q16: 0.40828825 | R16: 0.18255718
A17: Austria | B17: 75.674481 | C17: 0.78395293 | E17: 11.885562 | F17: 2.1416015 | H17: 44.678842 | I17: 3.1917702 | K17: 42.675013 | L17: 2.8688431 | N17: 0.16052262 | O17: 0.13973752 | Q17: 0.60006073 | R17: 0.29346812
A18: Belgium | B18: 63.361257 | C18: 0.75543225 | E18: 7.4099259 | F18: 1.5627626 | H18: 31.026084 | I18: 2.4815439 | K18: 58.171556 | L18: 2.6692393 | N18: 3.3062255 | O18: 1.1398783 | Q18: 0.086208701 | R18: 0.083891419
A19: Canada | B19: m | C19: m | E19: m | F19: m | H19: m | I19: m | K19: m | L19: m | N19: m | O19: m | Q19: m | R19: m
A20: Chile | B20: 51.572052 | C20: 1.03914 | D20: † | E20: 2.8123677 | F20: 1.0139726 | H20: 4.6371 | I20: 1.4517094 | K20: 87.604709 | L20: 2.2250217 | N20: 2.9947707 | O20: 1.2853024 | Q20: 1.9510528 | R20: 0.81465265
A21: Colombia | B21: 58.161021 | C21: 0.8524818 | D21: † | E21: 3.0298042 | F21: 1.1381776 | H21: 5.481036 | I21: 1.5571594 | K21: 88.486938 | L21: 2.0962301 | N21: 1.8850475 | O21: 0.8572367 | Q21: 1.1171747 | R21: 0.80967919
A22: Czech Republic | B22: 52.211135 | C22: 0.97074909 | E22: 2.2164512 | F22: 0.75300094 | H22: 7.900326 | I22: 1.6469695 | K22: 82.462618 | L22: 2.282045 | N22: 5.3148267 | O22: 1.2426797 | Q22: 2.1057784 | R22: 0.68577474
A23: Denmark | B23: 80.704225 | C23: 0.66666374 | E23: 25.711391 | F23: 2.7263275 | H23: 42.225532 | I23: 3.1599423 | K23: 31.979685 | L23: 2.633712 | N23: 0.083392092 | O23: 0.060174497 | Q23: 0 | R23: c
A24: Estonia | B24: 58.54072 | C24: 0.78856501 | E24: 1.6056952 | F24: 0.45684277 | H24: 9.9564205 | I24: 1.1378935 | K24: 86.933308 | L24: 1.2069258 | N24: 1.192077 | O24: 0.56208249 | Q24: 0.31249973 | R24: 0.23532422
A25: Finland | B25: 70.128695 | C25: 0.85397156 | E25: 4.6516234 | F25: 1.4324778 | H25: 30.20014 | I25: 3.5282769 | K25: 65.010717 | L25: 3.7263917 | N25: 0 | O25: c | Q25: 0.13752008 | R25: 0.096447004
A26: France | B26: 45.184571 | C26: 0.78596804 | D26: † | E26: 0.089169055 | F26: 0.085512127 | H26: 0.13760342 | I26: 0.11678182 | K26: 94.137811 | L26: 1.2587717 | N26: 5.3391808 | O26: 1.2461472 | Q26: 0.29623602 | R26: 0.15415097
A27: Germany | B27: 65.713881 | C27: 1.0813932 | D27: ‡ | E27: 8.3986429 | F27: 2.0630334 | H27: 21.983991 | I27: 3.0308407 | K27: 65.979693 | L27: 3.6631503 | N27: 1.1931355 | O27: 0.67702247 | Q27: 2.4445372 | R27: 1.0406159
A28: Greece | B28: 57.118993 | C28: 0.78074097 | E28: 2.1844538 | F28: 0.93945646 | H28: 5.26267 | I28: 1.5752423 | K28: 89.460652 | L28: 2.0716746 | N28: 2.5985307 | O28: 1.0038365 | Q28: 0.49369379 | R28: 0.2168022
A29: Hungary | B29: 54.867391 | C29: 1.1167959 | E29: 3.0859927 | F29: 0.97100759 | H29: 11.299838 | I29: 2.2131888 | K29: 78.088346 | L29: 2.6999915 | N29: 5.9850931 | O29: 1.6415278 | Q29: 1.5407308 | R29: 0.3552134
A30: Iceland | B30: 77.740872 | C30: 0.80783464 | D30: † | E30: 12.337977 | F30: 0.17966201 | H30: 53.196652 | I30: 0.23256082 | K30: 33.5757 | L30: 0.25741002 | N30: 0 | O30: c | Q30: 0.88967127 | R30: 0.074229128
A31: Ireland | B31: 56.918156 | C31: 0.88081963 | E31: 0 | F31: c | H31: 3.7397648 | I31: 1.6652463 | K31: 96.260235 | L31: 1.6652463 | N31: 0 | O31: c | Q31: 0 | R31: c
A32: Israel | B32: 62.610552 | C32: 0.89731206 | E32: 4.8248156 | F32: 1.3594731 | H32: 13.537704 | I32: 2.3396831 | K32: 80.556199 | L32: 2.3198747 | N32: 1.0812819 | O32: 0.74540765 | Q32: 0 | R32: c
A33: Italy | B33: 47.601263 | C33: 0.85513456 | E33: 1.5550011 | F33: 0.71823685 | H33: 4.350781 | I33: 1.4329271 | K33: 86.016589 | L33: 2.4719612 | N33: 5.8286719 | O33: 1.3864534 | Q33: 2.2489573 | R33: 1.0618744
A34: Japan | B34: 63.642806 | C34: 0.87618439 | E34: 2.5257342 | F34: 1.1406978 | H34: 14.4712 | I34: 2.6499358 | K34: 82.521662 | L34: 2.7474155 | N34: 0.48140349 | O34: 0.49379958 | Q34: 0 | R34: c
A35: Korea | B35: 68.307175 | C35: 0.79498841 | E35: 2.1398442 | F35: 1.1391526 | H35: 25.698966 | I35: 3.6345321 | K35: 72.16119 | L35: 3.7771718 | N35: 0 | O35: c | Q35: 0 | R35: c
A36: Latvia | B36: 53.472728 | C36: 0.81752128 | E36: 1.0906582 | F36: 0.42414819 | H36: 5.6942133 | I36: 0.92269342 | K36: 89.650883 | L36: 1.3713162 | N36: 2.3234102 | O36: 0.74329024 | Q36: 1.2408353 | R36: 0.43524129
A37: Lithuania | B37: 68.487994 | C37: 0.71838444 | E37: 7.5303012 | F37: 0.56265037 | H37: 24.820932 | I37: 1.2144001 | K37: 66.340483 | L37: 1.3600809 | N37: 0.80422373 | O37: 0.34438307 | Q37: 0.5040603 | R37: 0.15462407
A38: Luxembourg | B38: 60.790888 | C38: 0.67022613 | E38: 0 | F38: c | H38: 5.9778311 | I38: 0.044838274 | K38: 93.850052 | L38: 0.056166784 | N38: 0 | O38: c | Q38: 0.17211664 | R38: 0.032970372
A39: Mexico | B39: 59.073938 | C39: 1.0660855 | D39: ‡ | E39: 6.7207101 | F39: 1.7033178 | H39: 13.399152 | I39: 1.9781228 | K39: 75.84133 | L39: 2.5901985 | N39: 1.8840153 | O39: 0.77417989 | Q39: 2.1547927 | R39: 0.84293566
A40: Netherlands* | B40: 74.272082 | C40: 0.91718361 | E40: 7.2005109 | F40: 2.1658653 | H40: 42.123589 | I40: 4.2737534 | K40: 50.391484 | L40: 4.1653453 | N40: 0.28441601 | O40: 0.28925223 | Q40: 0 | R40: c
A41: New Zealand | B41: 62.482213 | C41: 0.88329949 | E41: 0.29800523 | F41: 0.25162766 | H41: 16.244606 | I41: 2.3170049 | K41: 82.962004 | L41: 2.3598199 | N41: 0.49538521 | O41: 0.37557697 | Q41: 0 | R41: c
A42: Norway | B42: 87.044488 | C42: 0.62930255 | E42: 44.64925 | F42: 3.3579363 | H42: 45.869007 | I42: 3.3522343 | K42: 9.2613473 | L42: 1.7911569 | N42: 0.22039545 | O42: 0.21833541 | Q42: 0 | R42: c
A43: Poland | B43: 65.248086 | C43: 0.80392983 | E43: 2.7295943 | F43: 0.85283533 | H43: 21.593609 | I43: 2.6456546 | K43: 75.574009 | L43: 2.7541403 | N43: 0 | O43: c | Q43: 0.10278816 | R43: 0.11136841
A44: Portugal* | B44: 58.398976 | C44: 1.049718 | E44: 2.1254903 | F44: 0.91563153 | H44: 11.427917 | I44: 2.1503706 | K44: 84.360906 | L44: 2.5541749 | N44: 1.9967667 | O44: 0.9963347 | Q44: 0.088919439 | R44: 0.074288655
...

Sheet Table III.B1.8.5
A1: PISA 2018 Results (Volume III) - © OECD 2019
