Workbook

Sheet TOC
A1: PISA 2018 Results (Volume II) - © OECD 2019
A2: Annex B1 | B2: Annex B1.8 Results (tables): Do boys and girls differ in their attitudes towards school and learning?
A3: Version 2 - Last updated: 02-Dec-2019
A4: Disclaimer: http://oe.cd/disclaimer
A6: TOC | B6: PISA 2018 Results - Volume II
A8: Chapter 8 | B8: Do boys and girls differ in their attitudes towards school and learning?
A9: Tables
A11: ='Table II.B1.8.1'!A6 -> Table II.B1.8.1 | B11: ='Table II.B1.8.1'!$A$7 -> Index of enjoyment of reading, by gender (PISA 2018)
A12: ='Table II.B1.8.2'!A6 -> Table II.B1.8.2 | B12: ='Table II.B1.8.2'!$A$7 -> Time spent reading for enjoyment, by gender
A13: ='Table II.B1.8.3'!A6 -> Table II.B1.8.3 | B13: ='Table II.B1.8.3'!$A$7 -> Index of enjoyment of reading, by gender (PISA 2009)
A14: ='Table II.B1.8.4'!A6 -> Table II.B1.8.4 | B14: ='Table II.B1.8.4'!$A$7 -> Index of enjoyment of reading, by gender (PISA 2000)
A15: ='Table II.B1.8.5'!A6 -> Table II.B1.8.5 | B15: ='Table II.B1.8.5'!$A$7 -> Change between 2000, 2009 and 2018 in the percentage of students who read for enjoyment, by gender
A16: ='Table II.B1.8.6'!A6 -> Table II.B1.8.6 | B16: ='Table II.B1.8.6'!$A$7 -> ICT use outside of school for leisure, by gender
A17: ='Table II.B1.8.7'!A6 -> Table II.B1.8.7 | B17: ='Table II.B1.8.7'!$A$7 -> Percentage of students reading e-mails, by gender
A18: ='Table II.B1.8.8'!A6 -> Table II.B1.8.8 | B18: ='Table II.B1.8.8'!$A$7 -> Percentage of students chatting on line (e.g. <WhatsApp>, <Messenger>), by gender
A19: ='Table II.B1.8.9'!A6 -> Table II.B1.8.9 | B19: ='Table II.B1.8.9'!$A$7 -> Percentage of students reading news on line, by gender
A20: ='Table II.B1.8.10'!A6 -> Table II.B1.8.10 | B20: ='Table II.B1.8.10'!$A$7 -> Percentage of students searching information on line to learn about a particular topic, by gender
A21: ='Table II.B1.8.11'!A6 -> Table II.B1.8.11 | B21: ='Table II.B1.8.11'!$A$7 -> Percentage of students taking part in online group discussions or forums, by gender
A22: ='Table II.B1.8.12'!A6 -> Table II.B1.8.12 | B22: ='Table II.B1.8.12'!$A$7 -> Percentage of students searching the Internet for practical information, by gender
A23: ='Table II.B1.8.13'!A6 -> Table II.B1.8.13 | B23: ='Table II.B1.8.13'!$A$7 -> How much time students spend studying before and after school, by gender
A24: ='Table II.B1.8.14'!A6 -> Table II.B1.8.14 | B24: ='Table II.B1.8.14'!$A$7 -> Index of attitudes towards competition, by gender
A25: ='Table II.B1.8.15'!A6 -> Table II.B1.8.15 | B25: ='Table II.B1.8.15'!$A$7 -> Index of motivation to master tasks, by gender
A26: ='Table II.B1.8.16'!A6 -> Table II.B1.8.16 | B26: ='Table II.B1.8.16'!$A$7 -> Index of perceived competence in reading, by gender
A27: ='Table II.B1.8.17'!A6 -> Table II.B1.8.17 | B27: ='Table II.B1.8.17'!$A$7 -> Index of perceived difficulty in reading, by gender
A28: ='Table II.B1.8.18'!A6 -> Table II.B1.8.18 | B28: ='Table II.B1.8.18'!$A$7 -> Index of fear of failure, by gender
A29: ='Table II.B1.8.19'!A6 -> Table II.B1.8.19 | B29: ='Table II.B1.8.19'!$A$7 -> Expectation to work in science-related occupations, by gender
A30: ='Table II.B1.8.20'!A6 -> Table II.B1.8.20 | B30: ='Table II.B1.8.20'!$A$7 -> Expectation to work in science-related occupations, by gender (PISA 2015)
A31: ='Table II.B1.8.21'!A6 -> Table II.B1.8.21 | B31: ='Table II.B1.8.21'!$A$7 -> Change between 2015 and 2018 in the expectation to work in science-related occupations, by gender
A32: ='Table II.B1.8.22'!A6 -> Table II.B1.8.22 | B32: ='Table II.B1.8.22'!$A$7 -> Expectation to work as science and engineering professionals amongst top performers in science or mathematics, by gender
A33: ='Table II.B1.8.23'!A6 -> Table II.B1.8.23 | B33: ='Table II.B1.8.23'!$A$7 -> Expectation to work as health professionals amongst top performers in science or mathematics, by gender
A37: Symbols for missing data
A38: c: There were too few observations to provide reliable estimates (i.e. there were fewer than 30 students or fewer than 5 schools with valid data).
A39: m: Data are not available. There was no observation in the sample; these data were not collected by the country; or these data were collected but subsequently removed from the publication for technical reasons.
A41: OECD averages
A42: OECD average, OECD average-37 | B42: Arithmetic mean across all OECD Member countries (and Colombia).
A43: OECD average-36b | B43: Arithmetic mean across all OECD Member countries (and Colombia), excluding Austria.
A44: OECD average-24 | B44: Arithmetic mean across all OECD Member countries, excluding Austria, Chile, Colombia, Estonia, Israel, Lithuania, Luxembourg, the Netherlands, the Slovak Republic, Slovenia, Turkey, the United Kingdom and the United States.
A46: Note
A47: Information on data for Cyprus: https://oe.cd/cyprus-disclaimer

Sheet Table II.B1.8.1
A1: PISA 2018 Results (Volume II) - © OECD 2019
A2: Annex B1 | B2: Annex B1.8 Results (tables): Do boys and girls differ in their attitudes towards school and learning?
A3: Version 2 - Last updated: 02-Dec-2019
A4: Disclaimer: http://oe.cd/disclaimer
A6: Table II.B1.8.1
A7: Index of enjoyment of reading, by gender (PISA 2018)
B11: Boys | T11: Girls | AL11: Gender differences (girls-boys)
B12: Percentage of students who agreed or strongly agreed with the following statements: | Q12: Index of enjoyment of reading | T12: Percentage of students who agreed or strongly agreed with the following statements: | AI12: Index of enjoyment of reading | AL12: Percentage of students who agreed or strongly agreed with the following statements: | BA12: Index of enjoyment of reading, before accounting for reading performance | BD12: Index of enjoyment of reading, after accounting for reading performance | BG12: Index of enjoyment of reading, after accounting for Index of ICT use outside of school for leisure
B13: I read only if I have to | E13: Reading is one of my favourite hobbies | H13: I like talking about books with other people | K13: For me, reading is a waste of time | N13: I read only to get information that I need | T13: I read only if I have to | W13: Reading is one of my favourite hobbies | Z13: I like talking about books with other people | AC13: For me, reading is a waste of time | AF13: I read only to get information that I need | AL13: I read only if I have to | AO13: Reading is one of my favourite hobbies | AR13: I like talking about books with other people | AU13: For me, reading is a waste of time | AX13: I read only to get information that I need
B14: % | C14: S.E. | D14: s | E14: % | F14: S.E. | G14: s | H14: % | I14: S.E. | J14: s | K14: % | L14: S.E. | M14: s | N14: % | O14: S.E. | P14: s | Q14: Mean Index | R14: S.E. | S14: s | T14: % | U14: S.E. | V14: s | W14: % | X14: S.E. | Y14: s | Z14: % | AA14: S.E. | AB14: s | AC14: % | AD14: S.E. | AE14: s | AF14: % | AG14: S.E. | AH14: s | AI14: Mean Index | AJ14: S.E. | AK14: s | AL14: % dif. | AM14: S.E. | AN14: s | AO14: % dif. | AP14: S.E. | AQ14: s | AR14: % dif. | AS14: S.E. | AT14: s | AU14: % dif. | AV14: S.E. | AW14: s | AX14: % dif. | AY14: S.E. | AZ14: s | BA14: Dif. | BB14: S.E. | BC14: s | BD14: Dif. | BE14: S.E. | BF14: s | BG14: Dif. | BH14: S.E. | BI14: s
A15: OECD
A16: Australia | B16: 61.451878 | C16: 0.6926375 | E16: 24.43996 | F16: 0.56178657 | H16: 25.778597 | I16: 0.64799855 | K16: 38.127032 | L16: 0.73489135 | N16: 62.376302 | O16: 0.71749538 | Q16: -0.39265692 | R16: 0.01574869 | T16: 45.915599 | U16: 0.73517902 | W16: 42.278656 | X16: 0.73748682 | Z16: 42.800753 | AA16: 0.69868618 | AC16: 24.666911 | AD16: 0.6747948 | AF16: 43.60376 | AG16: 0.67634687 | AI16: 0.14161444 | AJ16: 0.017807947 | AL16: -15.536279 | AM16: 1.0054904 | AO16: 17.838696 | AP16: 0.93082306 | AR16: 17.022156 | AS16: 0.90468082 | AU16: -13.460121 | AV16: 1.0208609 | AX16: -18.772542 | AY16: 0.97960098 | BA16: 0.53427136 | BB16: 0.023785812 | BD16: 0.42919532 | BE16: 0.022828377 | BG16: 0.5206229 | BH16: 0.024953183
A17: Austria | B17: 63.204522 | C17: 0.96341605 | E17: 17.014309 | F17: 0.63759708 | H17: 16.867401 | I17: 0.79689687 | K17: 44.205515 | L17: 0.95655008 | N17: 66.620114 | O17: 0.91234126 | Q17: -0.65481701 | R17: 0.019854659 | T17: 41.852607 | U17: 1.0794134 | W17: 39.77525 | X17: 1.0406479 | Z17: 35.809216 | AA17: 1.1777004 | AC17: 26.02149 | AD17: 0.96857513 | AF17: 40.253218 | AG17: 1.1479022 | AI17: 0.10034966 | AJ17: 0.029071876 | AL17: -21.351915 | AM17: 1.4475017 | AO17: 22.760941 | AP17: 1.1818291 | AR17: 18.941815 | AS17: 1.4236856 | AU17: -18.184025 | AV17: 1.3374467 | AX17: -26.366896 | AY17: 1.5142673 | BA17: 0.75516668 | BB17: 0.036624229 | BD17: 0.6513466 | BE17: 0.030384233 | BG17: 0.74648742 | BH17: 0.038682622
A18: Belgium | B18: 67.114893 | C18: 0.80493918 | E18: 13.857709 | F18: 0.62929209 | H18: 18.332218 | I18: 0.76627514 | K18: 51.450475 | L18: 0.99220698 | N18: 64.590603 | O18: 0.95856208 | Q18: -0.72756434 | R18: 0.022737393 | T18: 48.633355 | U18: 1.0127751 | W18: 29.060362 | X18: 0.89991886 | Z18: 32.612413 | AA18: 0.91669173 | AC18: 33.089775 | AD18: 1.0634706 | AF18: 45.340635 | AG18: 0.92937723 | AI18: -0.15661379 | AJ18: 0.025346002 | AL18: -18.481537 | AM18: 1.3012036 | AO18: 15.202653 | AP18: 1.0559419 | AR18: 14.280195 | AS18: 1.2142019 | AU18: -18.3607 | AV18: 1.4618014 | AX18: -19.249968 | AY18: 1.3739783 | BA18: 0.57095056 | BB18: 0.03334684 | BD18: 0.51701064 | BE18: 0.030472027 | BG18: 0.54852284 | BH18: 0.035987496
A19: Canada | B19: 56.892825 | C19: 0.7901328 | E19: 25.003471 | F19: 0.72402117 | H19: 28.758488 | I19: 0.6503501 | K19: 34.216242 | L19: 0.77887203 | N19: 57.745624 | O19: 0.73246769 | Q19: -0.3111287 | R19: 0.016861196 | T19: 39.06822 | U19: 0.69675752 | W19: 47.97698 | X19: 0.65621963 | Z19: 49.68362 | AA19: 0.76637817 | AC19: 18.731606 | AD19: 0.59211572 | AF19: 36.303732 | AG19: 0.69195024 | AI19: 0.32028286 | AJ19: 0.016749213 | AL19: -17.824606 | AM19: 0.97673226 | AO19: 22.973509 | AP19: 0.86278038 | AR19: 20.925131 | AS19: 0.79852924 | AU19: -15.484635 | AV19: 0.89560069 | AX19: -21.441891 | AY19: 0.84329106 | BA19: 0.63141156 | BB19: 0.01982592 | BD19: 0.53056459 | BE19: 0.018717961 | BG19: m | BH19: m
A20: Chile | B20: 70.196458 | C20: 0.91374651 | E20: 27.760331 | F20: 0.81833934 | H20: 31.532968 | I20: 1.0348597 | K20: 26.659511 | L20: 0.90942367 | N20: 68.416371 | O20: 0.89552226 | Q20: -0.26113996 | R20: 0.017493085 | T20: 51.945862 | U20: 1.0850775 | W20: 48.574891 | X20: 0.98658335 | Z20: 53.447821 | AA20: 1.0113885 | AC20: 12.747986 | AD20: 0.66785612 | AF20: 48.149457 | AG20: 1.0090028 | AI20: 0.35031197 | AJ20: 0.022492171 | AL20: -18.250596 | AM20: 1.3354362 | AO20: 20.81456 | AP20: 1.3543599 | AR20: 21.914853 | AS20: 1.3573019 | AU20: -13.911525 | AV20: 1.0872651 | AX20: -20.266913 | AY20: 1.2419623 | BA20: 0.61145193 | BB20: 0.026870904 | BD20: 0.56207889 | BE20: 0.024986088 | BG20: 0.6172931 | BH20: 0.03084057
A21: Colombia | B21: 49.363922 | C21: 1.0756973 | E21: 47.977441 | F21: 1.0731517 | H21: 45.150081 | I21: 1.183809 | K21: 17.203007 | L21: 0.82465946 | N21: 55.636549 | O21: 1.0791229 | Q21: 0.17831687 | R21: 0.015480757 | T21: 34.622332 | U21: 1.1962387 | W21: 63.193475 | X21: 0.97395439 | Z21: 59.64748 | AA21: 1.1501274 | AC21: 7.9015178 | AD21: 0.65456416 | AF21: 36.947052 | AG21: 0.97054264 | AI21: 0.57100807 | AJ21: 0.01942711 | AL21: -14.741591 | AM21: 1.5370049 | AO21: 15.216034 | AP21: 1.4124801 | AR21: 14.497399 | AS21: 1.5675477 | AU21: -9.3014891 | AV21: 1.0334428 | AX21: -18.689497 | AY21: 1.2913208 | BA21: 0.3926912 | BB21: 0.023070491 | BD21: 0.36946558 | BE21: 0.023669372 | BG21: m | BH21: m
A22: Czech Republic | B22: 61.877136 | C22: 0.92527856 | E22: 23.060019 | F22: 0.8090437 | H22: 25.16468 | I22: 0.88915419 | K22: 50.874604 | L22: 1.0990804 | N22: 57.152763 | O22: 1.0472691 | Q22: -0.43107953 | R22: 0.020707781 | T22: 36.362768 | U22: 1.0247963 | W22: 50.963698 | X22: 1.1700016 | Z22: 52.992603 | AA22: 1.1972974 | AC22: 25.343124 | AD22: 0.97337463 | AF22: 34.561137 | AG22: 1.0332351 | AI22: 0.35585585 | AJ22: 0.025042354 | AL22: -25.514368 | AM22: 1.2401992 | AO22: 27.903679 | AP22: 1.3747625 | AR22: 27.827923 | AS22: 1.4944083 | AU22: -25.53148 | AV22: 1.5437348 | AX22: -22.591625 | AY22: 1.4816148 | BA22: 0.78693538 | BB22: 0.030906776 | BD22: 0.66845914 | BE22: 0.029464821 | BG22: 0.78883631 | BH22: 0.033217811
A23: Denmark | B23: 65.594675 | C23: 1.0178978 | E23: 11.818747 | F23: 0.67716631 | H23: 20.584319 | I23: 0.81805486 | K23: 37.935214 | L23: 1.1471574 | N23: 66.463297 | O23: 1.1031581 | Q23: -0.61318923 | R23: 0.020682471 | T23: 48.670137 | U23: 1.1182012 | W23: 21.553173 | X23: 0.86680539 | Z23: 37.472971 | AA23: 1.3377488 | AC23: 24.271006 | AD23: 0.92767682 | AF23: 42.31326 | AG23: 1.2185968 | AI23: -0.13588437 | AJ23: 0.025833657 | AL23: -16.924538 | AM23: 1.4840702 | AO23: 9.7344257 | AP23: 1.0290714 | AR23: 16.888652 | AS23: 1.5541117 | AU23: -13.664209 | AV23: 1.5175374 | AX23: -24.150037 | AY23: 1.4622025 | BA23: 0.47730486 | BB23: 0.031942384 | BD23: 0.39571401 | BE23: 0.030739944 | BG23: 0.46460969 | BH23: 0.035769923
A24: Estonia | B24: 56.754397 | C24: 1.1722485 | E24: 17.785341 | F24: 0.8440497 | H24: 27.278629 | I24: 0.96352015 | K24: 37.213935 | L24: 1.0541745 | N24: 58.948159 | O24: 1.1341174 | Q24: -0.34474521 | R24: 0.017062743 | T24: 30.263373 | U24: 1.1208813 | W24: 44.793515 | X24: 1.0288834 | Z24: 51.592262 | AA24: 1.0632821 | AC24: 17.00839 | AD24: 0.77757668 | AF24: 34.108416 | AG24: 0.95739031 | AI24: 0.34668131 | AJ24: 0.021512398 | AL24: -26.491024 | AM24: 1.653247 | AO24: 27.008174 | AP24: 1.4088639 | AR24: 24.313633 | AS24: 1.3426238 | AU24: -20.205546 | AV24: 1.3257736 | AX24: -24.839743 | AY24: 1.5009974 | BA24: 0.69142652 | BB24: 0.028928188 | BD24: 0.60581913 | BE24: 0.027787536 | BG24: 0.69931265 | BH24: 0.0291073
A25: Finland | B25: 62.550321 | C25: 0.96976942 | E25: 15.276593 | F25: 0.81290723 | H25: 20.060105 | I25: 0.8954096 | K25: 49.415907 | L25: 1.0467632 | N25: 64.585104 | O25: 1.0772001 | Q25: -0.59765173 | R25: 0.02070035 | T25: 38.660492 | U25: 0.98511879 | W25: 35.475679 | X25: 0.94313403 | Z25: 41.38196 | AA25: 1.1216495 | AC25: 25.76968 | AD25: 0.92777336 | AF25: 39.153157 | AG25: 0.99233212 | AI25: 0.10026758 | AJ25: 0.026055735 | AL25: -23.889829 | AM25: 1.0664621 | AO25: 20.199086 | AP25: 1.2555834 | AR25: 21.321855 | AS25: 1.3265071 | AU25: -23.646228 | AV25: 1.0249734 | AX25: -25.431946 | AY25: 1.2818718 | BA25: 0.69791931 | BB25: 0.027518606 | BD25: 0.49892204 | BE25: 0.026846788 | BG25: 0.69711423 | BH25: 0.030722586
A26: France | B26: 51.159746 | C26: 0.98252865 | E26: 21.856463 | F26: 0.79850964 | H26: 27.184227 | I26: 1.1620601 | K26: 39.837076 | L26: 0.92176459 | N26: 57.320037 | O26: 1.093234 | Q26: -0.40092091 | R26: 0.021836328 | T26: 34.842171 | U26: 1.0969778 | W26: 39.253288 | X26: 1.0319619 | Z26: 43.644843 | AA26: 1.2377968 | AC26: 23.339363 | AD26: 0.84665669 | AF26: 38.689101 | AG26: 1.1361734 | AI26: 0.15812841 | AJ26: 0.027718704 | AL26: -16.317575 | AM26: 1.4564295 | AO26: 17.396825 | AP26: 1.2185937 | AR26: 16.460616 | AS26: 1.3114251 | AU26: -16.497713 | AV26: 1.1260859 | AX26: -18.630936 | AY26: 1.4147937 | BA26: 0.55904932 | BB26: 0.028926823 | BD26: 0.47397852 | BE26: 0.026764272 | BG26: 0.54862692 | BH26: 0.029173989
A27: Germany | B27: 61.473138 | C27: 1.1875118 | E27: 15.732889 | F27: 0.8237558 | H27: 13.710464 | I27: 0.86407588 | K27: 43.321526 | L27: 1.0890786 | N27: 65.584968 | O27: 1.1001826 | Q27: -0.67645252 | R27: 0.02821196 | T27: 37.816284 | U27: 0.90444375 | W27: 38.540407 | X27: 1.1015348 | Z27: 35.36818 | AA27: 1.1442596 | AC27: 24.057821 | AD27: 0.99517879 | AF27: 42.007471 | AG27: 1.1751891 | AI27: 0.14852597 | AJ27: 0.029038525 | AL27: -23.656854 | AM27: 1.3896413 | AO27: 22.807517 | AP27: 1.3204507 | AR27: 21.657716 | AS27: 1.3482349 | AU27: -19.263705 | AV27: 1.4442044 | AX27: -23.577497 | AY27: 1.4184813 | BA27: 0.8249785 | BB27: 0.036041084 | BD27: 0.73864902 | BE27: 0.033621831 | BG27: 0.77453507 | BH27: 0.037474623
A28: Greece | B28: 58.643361 | C28: 0.94642786 | E28: 26.383322 | F28: 0.99371175 | H28: 24.172178 | I28: 0.91392724 | K28: 22.666427 | L28: 1.1065996 | N28: 48.555409 | O28: 0.94741863 | Q28: -0.17287828 | R28: 0.015440184 | T28: 36.891197 | U28: 1.000969 | W28: 44.893491 | X28: 1.0045609 | Z28: 52.026535 | AA28: 1.0426963 | AC28: 9.5307013 | AD28: 0.61317523 | AF28: 25.816585 | AG28: 1.0260798 | AI28: 0.39543357 | AJ28: 0.020061423 | AL28: -21.752163 | AM28: 1.2377112 | AO28: 18.51017 | AP28: 1.2787296 | AR28: 27.854357 | AS28: 1.4038576 | AU28: -13.135726 | AV28: 1.1671653 | AX28: -22.738824 | AY28: 1.2008757 | BA28: 0.56831186 | BB28: 0.02310081 | BD28: 0.48049402 | BE28: 0.021650124 | BG28: 0.58043033 | BH28: 0.024607877
A29: Hungary | B29: 53.13597 | C29: 1.0872158 | E29: 20.404496 | F29: 1.0297681 | H29: 20.655598 | I29: 1.0588269 | K29: 40.677478 | L29: 1.1966894 | N29: 63.229536 | O29: 0.95010441 | Q29: -0.37884079 | R29: 0.017929431 | T29: 28.167047 | U29: 1.1377359 | W29: 48.877979 | X29: 1.2553617 | Z29: 49.114759 | AA29: 1.1834293 | AC29: 19.514521 | AD29: 0.98736969 | AF29: 34.453499 | AG29: 1.1601029 | AI29: 0.43592519 | AJ29: 0.030549451 | AL29: -24.968924 | AM29: 1.4070208 | AO29: 28.473483 | AP29: 1.6899147 | AR29: 28.459161 | AS29: 1.5099716 | AU29: -21.162956 | AV29: 1.3188277 | AX29: -28.776037 | AY29: 1.4604683 | BA29: 0.81476598 | BB29: 0.033039859 | BD29: 0.71395084 | BE29: 0.029818855 | BG29: 0.80443868 | BH29: 0.0326828
A30: Iceland | B30: 64.126231 | C30: 1.1867815 | E30: 18.11741 | F30: 0.90513149 | H30: 26.783434 | I30: 0.85806553 | K30: 36.507565 | L30: 1.288309 | N30: 60.485561 | O30: 1.1697212 | Q30: -0.44384989 | R30: 0.021656147 | T30: 49.299557 | U30: 1.1126806 | W30: 29.051856 | X30: 1.1263791 | Z30: 43.284479 | AA30: 1.0211389 | AC30: 25.061699 | AD30: 0.93800641 | AF30: 41.858904 | AG30: 1.0190616 | AI30: -0.013609239 | AJ30: 0.025795462 | AL30: -14.826673 | AM30: 1.571307 | AO30: 10.934445 | AP30: 1.4933445 | AR30: 16.501044 | AS30: 1.315519 | AU30: -11.445865 | AV30: 1.6973867 | AX30: -18.626656 | AY30: 1.6240696 | BA30: 0.43024065 | BB30: 0.034700636 | BD30: 0.30911029 | BE30: 0.031427246 | BG30: 0.41002842 | BH30: 0.041464147
A31: Ireland | B31: 59.00211 | C31: 1.2346281 | E31: 22.066567 | F31: 0.80021494 | H31: 22.959582 | I31: 0.83070174 | K31: 32.39527 | L31: 1.1164424 | N31: 60.842534 | O31: 1.22978 | Q31: -0.33667372 | R31: 0.02188314 | T31: 44.148716 | U31: 1.0609117 | W31: 39.317845 | X31: 0.88960768 | Z31: 43.803008 | AA31: 1.0467281 | AC31: 21.307 | AD31: 0.9727284 | AF31: 43.224076 | AG31: 1.2025255 | AI31: 0.18929079 | AJ31: 0.024322032 | AL31: -14.853394 | AM31: 1.3700134 | AO31: 17.251278 | AP31: 1.1675179 | AR31: 20.843426 | AS31: 1.272707 | AU31: -11.08827 | AV31: 1.3769524 | AX31: -17.618458 | AY31: 1.5924324 | BA31: 0.52596451 | BB31: 0.028913975 | BD31: 0.40912455 | BE31: 0.028796445 | BG31: 0.52912029 | BH31: 0.029300248
A32: Israel | B32: 51.627716 | C32: 1.4018206 | E32: 32.701248 | F32: 1.3644945 | H32: 32.325397 | I32: 1.2972456 | K32: 34.654308 | L32: 1.0932062 | N32: 58.693021 | O32: 1.2075248 | Q32: -0.16117645 | R32: 0.030727068 | T32: 38.240128 | U32: 1.1038776 | W32: 49.257774 | X32: 1.2097251 | Z32: 45.997264 | AA32: 1.0585086 | AC32: 20.731301 | AD32: 0.73807242 | AF32: 40.928199 | AG32: 1.1703416 | AI32: 0.30479534 | AJ32: 0.025778116 | AL32: -13.387588 | AM32: 1.716034 | AO32: 16.556526 | AP32: 1.7984299 | AR32: 13.671867 | AS32: 1.5919922 | AU32: -13.923007 | AV32: 1.3138897 | AX32: -17.764822 | AY32: 1.6167922 | BA32: 0.4659718 | BB32: 0.038587569 | BD32: 0.41228128 | BE32: 0.035621104 | BG32: 0.45766971 | BH32: 0.040273796 | BI32: †
A33: Italy | B33: 50.417542 | C33: 1.0925679 | E33: 23.692713 | F33: 0.72490744 | H33: 27.400927 | I33: 0.94773211 | K33: 37.099021 | L33: 1.0367386 | N33: 63.203171 | O33: 0.89045123 | Q33: -0.32111056 | R33: 0.017473666 | T33: 25.757001 | U33: 0.88271038 | W33: 55.563454 | X33: 1.0015618 | Z33: 54.68849 | AA33: 1.0376989 | AC33: 14.496293 | AD33: 0.76694122 | AF33: 31.210509 | AG33: 0.98698507 | AI33: 0.51963314 | AJ33: 0.021238042 | AL33: -24.660541 | AM33: 1.2604986 | AO33: 31.870741 | AP33: 1.201613 | AR33: 27.287562 | AS33: 1.3893643 | AU33: -22.602728 | AV33: 1.1726258 | AX33: -31.992662 | AY33: 1.2955764 | BA33: 0.8407437 | BB33: 0.02662722 | BD33: 0.78464374 | BE33: 0.027011052 | BG33: 0.85630239 | BH33: 0.026012232
A34: Japan | B34: 43.428526 | C34: 0.98354793 | E34: 42.036714 | F34: 0.9537654 | H34: 41.534253 | I34: 0.92542341 | K34: 18.346091 | L34: 0.69527408 | N34: 33.569325 | O34: 0.83315356 | Q34: 0.18778996 | R34: 0.020049825 | T34: 35.377755 | U34: 0.90181521 | W34: 48.224604 | X34: 0.91243059 | Z34: 44.816446 | AA34: 1.0995703 | AC34: 13.001336 | AD34: 0.59798636 | AF34: 22.635681 | AG34: 0.92267111 | AI34: 0.39737533 | AJ34: 0.026218292 | AL34: -8.0507711 | AM34: 1.2322617 | AO34: 6.1878898 | AP34: 1.3599095 | AR34: 3.2821937 | AS34: 1.4074439 | AU34: -5.344755 | AV34: 0.89029004 | AX34: -10.933644 | AY34: 1.3961029 | BA34: 0.20958538 | BB34: 0.032414844 | BD34: 0.13334056 | BE34: 0.033699434 | BG34: 0.208753 | BH34: 0.03269301
A35: Korea | B35: 57.526207 | C35: 1.145455 | E35: 40.208694 | F35: 1.0230904 | H35: 41.712495 | I35: 0.94329831 | K35: 19.722738 | L35: 0.73357669 | N35: 40.390085 | O35: 1.0348694 | Q35: 0.15962872 | R35: 0.018969972 | T35: 50.046074 | U35: 0.94599055 | W35: 44.316639 | X35: 1.1222694 | Z35: 49.140942 | AA35: 1.194662 | AC35: 10.928428 | AD35: 0.6440094 | AF35: 28.250222 | AG35: 0.88471155 | AI35: 0.3155108 | AJ35: 0.020012103 | AL35: -7.4801329 | AM35: 1.3453273 | AO35: 4.1079455 | AP35: 1.5463169 | AR35: 7.428447 | AS35: 1.448103 | AU35: -8.7943101 | AV35: 0.96674067 | AX35: -12.139863 | AY35: 1.3253766 | BA35: 0.15588208 | BB35: 0.026477489 | BD35: 0.095030512 | BE35: 0.023431092 | BG35: 0.15674729 | BH35: 0.026744642
A36: Latvia | B36: 56.865688 | C36: 0.97546455 | E36: 21.541548 | F36: 0.79093299 | H36: 27.444618 | I36: 0.88510706 | K36: 37.559601 | L36: 1.0031538 | N36: 64.726977 | O36: 1.1526579 | Q36: -0.29782589 | R36: 0.017138959 | T36: 32.921661 | U36: 0.87431252 | W36: 44.439892 | X36: 0.96118027 | Z36: 51.879748 | AA36: 0.90321546 | AC36: 17.21819 | AD36: 0.66467255 | AF36: 38.884318 | AG36: 0.91726547 | AI36: 0.31248059 | AJ36: 0.015789744 | AL36: -23.944027 | AM36: 1.4116224 | AO36: 22.898344 | AP36: 1.2619043 | AR36: 24.43513 | AS36: 1.2706852 | AU36: -20.341411 | AV36: 1.1721917 | AX36: -25.842658 | AY36: 1.4204505 | BA36: 0.61030648 | BB36: 0.025405813 | BD36: 0.51003559 | BE36: 0.024359986 | BG36: 0.63068182 | BH36: 0.0253166
A37: Lithuania | B37: 67.768783 | C37: 0.91060883 | E37: 23.404595 | F37: 0.87926877 | H37: 30.320538 | I37: 0.90162915 | K37: 45.359142 | L37: 0.74512035 | N37: 68.130774 | O37: 0.96670254 | Q37: -0.42625542 | R37: 0.017891582 | T37: 51.129654 | U37: 1.0321953 | W37: 45.321991 | X37: 1.0476 | Z37: 51.273425 | AA37: 0.96471471 | AC37: 23.232321 | AD37: 0.99283027 | AF37: 49.162881 | AG37: 1.1239949 | AI37: 0.217404 | AJ37: 0.024010972 | AL37: -16.639129 | AM37: 1.2849985 | AO37: 21.917396 | AP37: 1.2465618 | AR37: 20.952888 | AS37: 1.2116457 | AU37: -22.126821 | AV37: 1.1707727 | AX37: -18.967893 | AY37: 1.4720287 | BA37: 0.64365942 | BB37: 0.026631657 | BD37: 0.56821213 | BE37: 0.026955085 | BG37: 0.67584777 | BH37: 0.02833549
A38: Luxembourg | B38: 63.0461 | C38: 0.89669115 | E38: 19.192517 | F38: 0.766483 | H38: 20.251271 | I38: 0.88754881 | K38: 42.539691 | L38: 0.99315854 | N38: 59.601573 | O38: 0.89955008 | Q38: -0.54492948 | R38: 0.020302576 | T38: 43.635099 | U38: 0.93682922 | W38: 35.841826 | X38: 0.95410644 | Z38: 36.726042 | AA38: 0.91617155 | AC38: 24.636577 | AD38: 0.90915814 | AF38: 39.24947 | AG38: 0.8915437 | AI38: 0.074759172 | AJ38: 0.021816147 | AL38: -19.411001 | AM38: 1.316753 | AO38: 16.649309 | AP38: 1.1986964 | AR38: 16.47477 | AS38: 1.2692833 | AU38: -17.903114 | AV38: 1.2980159 | AX38: -20.352103 | AY38: 1.3344331 | BA38: 0.61968865 | BB38: 0.030100829 | BD38: 0.53205962 | BE38: 0.029081469 | BG38: 0.60496884 | BH38: 0.032553915
A39: Mexico | B39: 56.255631 | C39: 0.97468006 | E39: 47.269182 | F39: 1.0561844 | H39: 41.756061 | I39: 1.0962391 | K39: 18.251151 | L39: 0.87619561 | N39: 64.057502 | O39: 1.1263048 | Q39: 0.10389657 | R39: 0.01422581 | T39: 38.175478 | U39: 1.1896615 | W39: 65.027119 | X39: 1.1781742 | Z39: 60.437132 | AA39: 1.1581201 | AC39: 8.0956452 | AD39: 0.53705926 | AF39: 44.17206 | AG39: 1.3088667 | AI39: 0.58098356 | AJ39: 0.023627248 | AL39: -18.080153 | AM39: 1.3312089 | AO39: 17.757937 | AP39: 1.5348479 | AR39: 18.681071 | AS39: 1.4795496 | AU39: -10.155505 | AV39: 0.98768608 | AX39: -19.885442 | AY39: 1.5417856 | BA39: 0.47708699 | BB39: 0.025926631 | BD39: 0.4526349 | BE39: 0.025222764 | BG39: 0.50202654 | BH39: 0.026878102
A40: Netherlands* | B40: 74.311101 | C40: 0.97991649 | E40: 10.125825 | F40: 0.65201711 | H40: 10.837855 | I40: 0.66490188 | K40: 54.987476 | L40: 1.0648999 | N40: 71.632578 | O40: 1.1055639 | Q40: -0.89683382 | R40: 0.021445492 | T40: 51.529543 | U40: 1.1470214 | W40: 26.292515 | X40: 1.0839968 | Z40: 26.953858 | AA40: 1.0666131 | AC40: 30.134463 | AD40: 1.0459709 | AF40: 46.983017 | AG40: 1.1310301 | AI40: -0.23761901 | AJ40: 0.027883587 | AL40: -22.781557 | AM40: 1.421918 | AO40: 16.166689 | AP40: 1.162416 | AR40: 16.116003 | AS40: 1.1525446 | AU40: -24.853012 | AV40: 1.3367296 | AX40: -24.649561 | AY40: 1.4221294 | BA40: 0.6592148 | BB40: 0.030694253 | BD40: 0.57291831 | BE40: 0.028082846 | BG40: m | BH40: m
A41: New Zealand | B41: 59.602251 | C41: 1.0079579 | E41: 24.861461 | F41: 0.89070062 | H41: 24.250488 | I41: 0.87180566 | K41: 33.823239 | L41: 1.0339921 | N41: 59.73741 | O41: 0.90893016 | Q41: -0.33083602 | R41: 0.022821465 | T41: 44.755761 | U41: 1.11492 | W41: 42.639077 | X41: 0.94220823 | Z41: 42.945244 | AA41: 1.0843576 | AC41: 21.890466 | AD41: 0.98962403 | AF41: 43.992687 | AG41: 0.9724416 | AI41: 0.16152377 | AJ41: 0.026169339 | AL41: -14.846491 | AM41: 1.5746746 | AO41: 17.777616 | AP41: 1.2009817 | AR41: 18.694756 | AS41: 1.4473681 | AU41: -11.932773 | AV41: 1.483343 | AX41: -15.744723 | AY41: 1.282241 | BA41: 0.49235979 | BB41: 0.034422433 | BD41: 0.39024032 | BE41: 0.029729578 | BG41: 0.48576412 | BH41: 0.03680173
A42: Norway | B42: 68.038509 | C42: 0.85561653 | E42: 13.87076 | F42: 0.72007811 | H42: 16.023459 | I42: 0.84443866 | K42: 50.242796 | L42: 0.97246109 | N42: 72.3513 | O42: 0.84877455 | Q42: -0.80145451 | R42: 0.023684055 | T42: 47.953009 | U42: 1.0101361 | W42: 26.656061 | X42: 0.79169986 | Z42: 31.026911 | AA42: 0.97284977 | AC42: 30.819212 | AD42: 0.97362736 | AF42: 51.177857 | AG42: 1.0372627 | AI42: -0.21963039 | AJ42: 0.022796168 | AL42: -20.085499 | AM42: 1.3050737 | AO42: 12.785301 | AP42: 1.0198146 | AR42: 15.003452 | AS42: 1.2522599 | AU42: -19.423584 | AV42: 1.2129271 | AX42: -21.173443 | AY42: 1.3292446 | BA42: 0.58182413 | BB42: 0.032906729 | BD42: 0.46098825 | BE42: 0.03071867 | BG42: m | BH42: m
A43: Poland | B43: 51.305824 | C43: 1.0246182 | E43: 26.669675 | F43: 0.99739641 | H43: 31.069749 | I43: 1.1391036 | K43: 35.63502 | L43: 0.99995947 | N43: 58.908677 | O43: 0.98934581 | Q43: -0.17113143 | R43: 0.021422357 | T43: 27.90936 | U43: 0.98938605 | W43: 54.139004 | X43: 1.14556 | Z43: 58.001201 | AA43: 1.0563569 | AC43: 14.582128 | AD43: 0.78324244 | AF43: 31.940859 | AG43: 0.95861193 | AI43: 0.52761844 | AJ43: 0.023368408 | AL43: -23.396464 | AM43: 1.4162135 | AO43: 27.469329 | AP43: 1.5382766 | AR43: 26.931452 | AS43: 1.4406112 | AU43: -21.052891 | AV43: 1.2413076 | AX43: -26.967818 | AY43: 1.2913343 | BA43: 0.69874987 | BB43: 0.02764019 | BD43: 0.58377807 | BE43: 0.026683144 | BG43: 0.69410365 | BH43: 0.027387104
A44: Portugal* | B44: 41.031244 | C44: 1.0073262 | E44: 18.785661 | F44: 0.8078527 | H44: 22.923252 | I44: 1.0854992 | K44: 31.18843 | L44: 1.1315581 | N44: 60.291786 | O44: 1.0824363 | Q44: -0.2947035 | R44: 0.023219803 | T44: 19.923334 | U44: 0.806081 | W44: 45.464519 | X44: 0.97969726 | Z44: 53.304135 | AA44: 1.1527141 | AC44: 12.056819 | AD44: 0.66612039 | AF44: 32.491568 | AG44: 1.1165178 | AI44: 0.44968919 | AJ44: 0.020543424 | AL44: -21.10791 | AM44: 1.2780928 | AO44: 26.678858 | AP44: 1.257439 | AR44: 30.380884 | AS44: 1.5064076 | AU44: -19.131611 | AV44: 1.3731241 | AX44: -27.800218 | AY44: 1.5858477 | BA44: 0.74439269 | BB44: 0.029297926 | BD44: 0.67700192 | BE44: 0.028770158 | BG44: m | BH44: m
...

Sheet Table II.B1.8.2
A1: PISA 2018 Results (Volume II) - © OECD 2019
A2: Annex B1 | B2: Annex B1.8 Results (tables): Do boys and girls differ in their attitudes towards school and learning?
A3: Version 2 - Last updated: 02-Dec-2019
A4: Disclaimer: http://oe.cd/disclaimer
A6: Table II.B1.8.2
A7: Time spent reading for enjoyment, by gender
B12: Boys | K12: Girls | T12: Gender differences (girls-boys)
B13: I don't read or I read less than 30 minutes a day | E13: I read between 30 minutes to 2 hours a day | H13: I read more than 2 hours a day | K13: I don't read or I read less than 30 minutes a day | N13: I read between 30 minutes to 2 hours a day | Q13: I read more than 2 hours a day | T13: I don't read or I read less than 30 minutes a day | W13: I read between 30 minutes to 2 hours a day | Z13: I read more than 2 hours a day
B14: % | C14: S.E. | D14: s | E14: % | F14: S.E. | G14: s | H14: % | I14: S.E. | J14: s | K14: % | L14: S.E. | M14: s | N14: % | O14: S.E. | P14: s | Q14: % | R14: S.E. | S14: s | T14: % dif. | U14: S.E. | V14: s | W14: % dif. | X14: S.E. | Y14: s | Z14: % dif. | AA14: S.E. | AB14: s
A15: OECD
A16: Australia | B16: 76.170619 | C16: 0.59888397 | E16: 20.116015 | F16: 0.53741955 | H16: 3.7133666 | I16: 0.25553962 | K16: 63.260979 | L16: 0.69753181 | N16: 28.767897 | O16: 0.61751641 | Q16: 7.9711248 | R16: 0.40182789 | T16: -12.90964 | U16: 0.85605451 | W16: 8.6518819 | X16: 0.80855988 | Z16: 4.2577582 | AA16: 0.4752568
A17: Austria | B17: 81.581399 | C17: 0.71338992 | E17: 16.25661 | F17: 0.68764556 | H17: 2.1619911 | I17: 0.25013744 | K17: 60.877388 | L17: 1.1626429 | N17: 32.034404 | O17: 1.0599593 | Q17: 7.0882082 | R17: 0.604104 | T17: -20.704012 | U17: 1.3878677 | W17: 15.777794 | X17: 1.2004493 | Z17: 4.9262171 | AA17: 0.61472909
A18: Belgium | B18: 82.603063 | C18: 0.54373069 | E18: 14.985114 | F18: 0.56587897 | H18: 2.4118235 | I18: 0.27830224 | K18: 64.907529 | L18: 1.0381109 | N18: 29.427149 | O18: 0.89441981 | Q18: 5.6653212 | R18: 0.44591014 | T18: -17.695533 | U18: 0.96214429 | W18: 14.442036 | X18: 0.83340551 | Z18: 3.2534977 | AA18: 0.50968249
A19: Canada | B19: 75.506778 | C19: 0.72395331 | E19: 21.338294 | F19: 0.63103342 | H19: 3.1549284 | I19: 0.24785934 | K19: 59.603962 | L19: 0.66853697 | N19: 31.855462 | O19: 0.70630971 | Q19: 8.5405761 | R19: 0.33816172 | T19: -15.902816 | U19: 0.7924331 | W19: 10.517169 | X19: 0.86487901 | Z19: 5.3856477 | AA19: 0.42270417
A20: Chile | B20: 71.998027 | C20: 0.91775339 | E20: 23.243286 | F20: 0.78205017 | H20: 4.7586871 | I20: 0.46842174 | K20: 52.307872 | L20: 1.1438183 | N20: 33.713334 | O20: 1.020124 | Q20: 13.978794 | R20: 0.5517007 | T20: -19.690155 | U20: 1.3485016 | W20: 10.470048 | X20: 1.18639 | Z20: 9.2201069 | AA20: 0.75494813
A21: Colombia | B21: 67.472005 | C21: 1.1394145 | E21: 29.362845 | F21: 1.0799088 | H21: 3.1651504 | I21: 0.35296545 | K21: 51.624069 | L21: 1.1618094 | N21: 38.355288 | O21: 1.1074421 | Q21: 10.020643 | R21: 0.58997105 | T21: -15.847935 | U21: 1.4920625 | W21: 8.992443 | X21: 1.4901045 | Z21: 6.8554925 | AA21: 0.69701517
A22: Czech Republic | B22: 79.228871 | C22: 0.81483545 | E22: 17.726545 | F22: 0.70668107 | H22: 3.0445844 | I22: 0.3159331 | K22: 52.324362 | L22: 1.0020142 | N22: 37.991131 | O22: 1.0157101 | Q22: 9.6845065 | R22: 0.52199517 | T22: -26.904508 | U22: 1.0747152 | W22: 20.264586 | X22: 1.0249714 | Z22: 6.6399221 | AA22: 0.60298861
A23: Denmark | B23: 84.634266 | C23: 0.70013334 | E23: 13.985206 | F23: 0.62189912 | H23: 1.3805282 | I23: 0.22419538 | K23: 74.887907 | L23: 1.0039283 | N23: 22.017788 | O23: 0.91606304 | Q23: 3.0943043 | R23: 0.37516455 | T23: -9.7463585 | U23: 1.1398449 | W23: 8.0325824 | X23: 1.0250581 | Z23: 1.7137761 | AA23: 0.45068111
A24: Estonia | B24: 72.2213 | C24: 0.79454436 | E24: 24.866631 | F24: 0.78439879 | H24: 2.912069 | I24: 0.30529178 | K24: 46.073937 | L24: 1.0320398 | N24: 43.746423 | O24: 0.8929809 | Q24: 10.17964 | R24: 0.66692555 | T24: -26.147364 | U24: 1.2442119 | W24: 18.879792 | X24: 1.0281039 | Z24: 7.2675712 | AA24: 0.76443076
A25: Finland | B25: 78.140612 | C25: 0.76022661 | E25: 19.241185 | F25: 0.6885087 | H25: 2.6182029 | I25: 0.30757851 | K25: 57.715828 | L25: 0.87879969 | N25: 35.764144 | O25: 0.87456881 | Q25: 6.5200274 | R25: 0.45098284 | T25: -20.424783 | U25: 1.0419936 | W25: 16.522959 | X25: 0.94603706 | Z25: 3.9018245 | AA25: 0.51429715
A26: France | B26: 77.306439 | C26: 0.83529232 | E26: 19.531684 | F26: 0.75506027 | H26: 3.1618779 | I26: 0.33228222 | K26: 60.270386 | L26: 1.0692024 | N26: 31.989995 | O26: 1.0426622 | Q26: 7.7396186 | R26: 0.51574822 | T26: -17.036052 | U26: 1.2813953 | W26: 12.458312 | X26: 1.2406968 | Z26: 4.5777407 | AA26: 0.59741753
A27: Germany | B27: 81.118612 | C27: 0.90890515 | E27: 16.127094 | F27: 0.91875922 | H27: 2.754294 | I27: 0.31039509 | K27: 62.07859 | L27: 1.0935543 | N27: 30.361829 | O27: 1.0394725 | Q27: 7.5595813 | R27: 0.56881853 | T27: -19.040023 | U27: 1.2117916 | W27: 14.234735 | X27: 1.1696232 | Z27: 4.8052873 | AA27: 0.66391219
... A53: OECD average-37 | B53: 75.492415 | C53: 0.14287756 | E53: 21.13796 | F53: 0.13325358 | H53: 3.369625 | I53: 0.059501429 | K53: 57.203178 | L53: 0.16623533 | N53: 34.384072 | O53: 0.15522676 | Q53: 8.4127495 | R53: 0.087633876 | T53: -18.289236 | U53: 0.20865936 | W53: 13.246112 | X53: 0.19546833 | Z53: 5.0431245 | AA53: 0.10453819
A54: Partners
A55: Albania | B55: 43.217996 | C55: 1.1878285 | E55: 49.184256 | F55: 1.1612388 | H55: 7.5977483 | I55: 0.56782579 | K55: 17.777637 | L55: 0.6911254 | N55: 63.180923 | O55: 0.98649648 | Q55: 19.04144 | R55: 0.83235435 | T55: -25.44036 | U55: 1.3691206 | W55: 13.996668 | X55: 1.6058905 | Z55: 11.443692 | AA55: 0.97631165
A56: Argentina | B56: 74.815057 | C56: 0.93654868 | E56: 20.179316 | F56: 0.86097911 | H56: 5.0056266 | I56: 0.41842385 | K56: 56.97451 | L56: 0.94826125 | N56: 29.951633 | O56: 0.84545103 | Q56: 13.073857 | R56: 0.59577945 | T56: -17.840548 | U56: 1.267327 | W56: 9.7723171 | X56: 1.1041958 | Z56: 8.0682307 | AA56: 0.71153261
A57: Baku (Azerbaijan) | B57: 50.243488 | C57: 0.93039879 | E57: 33.163794 | F57: 0.91367065 | H57: 16.592719 | I57: 0.67317623 | K57: 47.103352 | L57: 1.0601757 | N57: 36.615306 | O57: 1.0520898 | Q57: 16.281342 | R57: 0.67295731 | T57: -3.1401357 | U57: 1.324728 | W57: 3.451512 | X57: 1.3601814 | Z57: -0.3113763 | AA57: 0.92000835
A58: Belarus | B58: 50.230353 | C58: 1.0931861 | E58: 41.938019 | F58: 1.0714311 | H58: 7.831628 | I58: 0.55553426 | K58: 26.774625 | L58: 0.97555894 | N58: 51.355201 | O58: 1.1203526 | Q58: 21.870174 | R58: 0.91335308 | T58: -23.455728 | U58: 1.2864504 | W58: 9.4171818 | X58: 1.4967133 | Z58: 14.038546 | AA58: 0.93179956
A59: Bosnia and Herzegovina | B59: 67.527094 | C59: 0.94637061 | E59: 28.810426 | F59: 0.90224293 | H59: 3.6624798 | I59: 0.3601021 | K59: 43.285945 | L59: 1.2155735 | N59: 45.486104 | O59: 0.99556269 | Q59: 11.227951 | R59: 0.60926365 | T59: -24.241149 | U59: 1.6492707 | W59: 16.675678 | X59: 1.375431 | Z59: 7.5654714 | AA59: 0.68596095
A60: Brazil | B60: 68.598971 | C60: 0.7849329 | E60: 25.800001 | F60: 0.68165223 | H60: 5.6010276 | I60: 0.34968195 | K60: 46.262046 | L60: 0.73723609 | N60: 38.909061 | O60: 0.78716688 | Q60: 14.828893 | R60: 0.62461169 | T60: -22.336926 | U60: 1.1056608 | W60: 13.10906 | X60: 1.1065959 | Z60: 9.2278658 | AA60: 0.64008183
A61: Brunei Darussalam | B61: 64.765805 | C61: 0.72055861 | E61: 27.458752 | F61: 0.71307939 | H61: 7.7754428 | I61: 0.44718718 | K61: 36.646594 | L61: 0.78486689 | N61: 37.730597 | O61: 0.72400914 | Q61: 25.622809 | R61: 0.68774731 | T61: -28.119211 | U61: 1.1316435 | W61: 10.271845 | X61: 1.0370907 | Z61: 17.847366 | AA61: 0.7620817
A62: B-S-J-Z (China) | B62: 30.706508 | C62: 0.92723081 | E62: 55.314544 | F62: 0.85228927 | H62: 13.978948 | I62: 0.69731369 | K62: 29.344142 | L62: 0.79386048 | N62: 57.934911 | O62: 0.79081808 | Q62: 12.720947 | R62: 0.5741445 | T62: -1.3623656 | U62: 1.0721576 | W62: 2.6203673 | X62: 1.1732383 | Z62: -1.2580017 | AA62: 0.81617672
A63: Bulgaria | B63: 60.66681 | C63: 1.1259296 | E63: 33.118739 | F63: 1.0491944 | H63: 6.2144509 | I63: 0.50600748 | K63: 38.218821 | L63: 1.564489 | N63: 46.062002 | O63: 1.1731738 | Q63: 15.719177 | R63: 0.8618253 | T63: -22.447989 | U63: 1.6291879 | W63: 12.943263 | X63: 1.3955921 | Z63: 9.5047256 | AA63: 0.95628761
A64: Costa Rica | B64: 79.324737 | C64: 0.84320037 | E64: 17.265738 | F64: 0.7286049 | H64: 3.4095251 | I64: 0.30627422 | K64: 56.517857 | L64: 1.0582527 | N64: 30.500084 | O64: 0.94409947 | Q64: 12.982058 | R64: 0.55412949 | T64: -22.80688 | U64: 1.1538305 | W64: 13.234347 | X64: 1.0617922 | Z64: 9.5725332 | AA64: 0.60500426
A65: Croatia | B65: 76.019923 | C65: 0.81102022 | E65: 21.658711 | F65: 0.80829861 | H65: 2.3213655 | I65: 0.28024052 | K65: 55.684627 | L65: 1.0868186 | N65: 35.770102 | O65: 0.98328466 | Q65: 8.5452713 | R65: 0.53264583 | T65: -20.335297 | U65: 1.3763195 | W65: 14.111391 | X65: 1.2607408 | Z65: 6.2239058 | AA65: 0.60087916
A66: Cyprus | B66: 67.815392 | C66: 0.97240744 | E66: 26.575821 | F66: 0.95836626 | H66: 5.6087866 | I66: 0.46015126 | K66: 51.923644 | L66: 0.93977952 | N66: 38.735014 | O66: 1.0094739 | Q66: 9.3413422 | R66: 0.63761124 | T66: -15.891748 | U66: 1.4615174 | W66: 12.159193 | X66: 1.5493669 | Z66: 3.7325555 | AA66: 0.81398188
... A73: Kosovo | B73: 39.843087 | C73: 1.0306401 | E73: 50.350019 | F73: 1.0402075 | H73: 9.8068938 | I73: 0.63422377 | K73: 18.933397 | L73: 0.7814167 | N73: 61.244896 | O73: 1.0352531 | Q73: 19.821707 | R73: 0.99542592 | T73: -20.90969 | U73: 1.1834583 | W73: 10.894877 | X73: 1.3921267 | Z73: 10.014813 | AA73: 1.0949051
A74: Lebanon | B74: m | C74: m | E74: m | F74: m | H74: m | I74: m | K74: m | L74: m | N74: m | O74: m | Q74: m | R74: m | T74: m | U74: m | W74: m | X74: m | Z74: m | AA74: m
A75: Macao (China) | B75: 48.95286 | C75: 1.1106333 | E75: 37.37015 | F75: 1.0237446 | H75: 13.67699 | I75: 0.7440743 | K75: 37.317613 | L75: 1.0631761 | N75: 45.019025 | O75: 0.98371574 | Q75: 17.663362 | R75: 0.83372014 | T75: -11.635247 | U75: 1.5462901 | W75: 7.6488746 | X75: 1.4233277 | Z75: 3.986372 | AA75: 1.0626386
A76: Malaysia | B76: 54.291465 | C76: 0.96504201 | E76: 37.003585 | F76: 0.88842861 | H76: 8.70495 | I76: 0.47605846 | K76: 34.081373 | L76: 0.98501629 | N76: 46.407053 | O76: 0.95862121 | Q76: 19.511575 | R76: 0.83753899 | T76: -20.210092 | U76: 1.2512603 | W76: 9.4034675 | X76: 1.1256627 | Z76: 10.806625 | AA76: 0.97745968
...

Sheet Table II.B1.8.3
A1: PISA 2018 Results (Volume II) - © OECD 2019
A2: Annex B1 | B2: Annex B1.8 Results (tables): Do boys and girls differ in their attitudes towards school and learning?
A3: Version 2 - Last updated: 02-Dec-2019
A4: Disclaimer: http://oe.cd/disclaimer
A6: Table II.B1.8.3
A7: Index of enjoyment of reading, by gender (PISA 2009)
B11: Boys | T11: Girls | AL11: Gender differences (girls-boys)
B12: Percentage of students who agreed or strongly agreed with the following statements: | Q12: Index of enjoyment of reading | T12: Percentage of students who agreed or strongly agreed with the following statements: | AI12: Index of enjoyment of reading | AL12: Percentage of students who agreed or strongly agreed with the following statements: | BA12: Index of enjoyment of reading, before accounting for reading performance | BD12: Index of enjoyment of reading, after accounting for reading performance
B13: I read only if I have to | E13: Reading is one of my favourite hobbies | H13: I like talking about books with other people | K13: For me, reading is a waste of time | N13: I read only to get information that I need | T13: I read only if I have to | W13: Reading is one of my favourite hobbies | Z13: I like talking about books with other people | AC13: For me, reading is a waste of time | AF13: I read only to get information that I need | AL13: I read only if I have to | AO13: Reading is one of my favourite hobbies | AR13: I like talking about books with other people | AU13: For me, reading is a waste of time | AX13: I read only to get information that I need
B14: % | C14: S.E. | D14: s | E14: % | F14: S.E. | G14: s | H14: % | I14: S.E. | J14: s | K14: % | L14: S.E. | M14: s | N14: % | O14: S.E. | P14: s | Q14: Mean Index | R14: S.E. | S14: s | T14: % | U14: S.E. | V14: s | W14: % | X14: S.E. | Y14: s | Z14: % | AA14: S.E. | AB14: s | AC14: % | AD14: S.E. | AE14: s | AF14: % | AG14: S.E. | AH14: s | AI14: Mean Index | AJ14: S.E. | AK14: s | AL14: % dif. | AM14: S.E. | AN14: s | AO14: % dif. | AP14: S.E. | AQ14: s | AR14: % dif. | AS14: S.E. | AT14: s | AU14: % dif. | AV14: S.E. | AW14: s | AX14: % dif. | AY14: S.E. | AZ14: s | BA14: Dif. | BB14: S.E. | BC14: s | BD14: Dif. | BE14: S.E. | BF14: s
A15: OECD
A16: Australia | B16: 51.775033 | C16: 0.73080104 | E16: 23.082819 | F16: 0.71177321 | H16: 25.065086 | I16: 0.64589174 | K16: 33.602755 | L16: 0.78909591 | N16: 54.570237 | O16: 0.86000133 | Q16: -0.33094313 | R16: 0.017162319 | T16: 30.547182 | U16: 0.81749002 | W16: 47.254377 | X16: 0.92506458 | Z16: 51.961262 | AA16: 0.84103006 | AC16: 18.538614 | AD16: 0.65783876 | AF16: 30.623468 | AG16: 0.91143214 | AI16: 0.30772457 | AJ16: 0.022594204 | AL16: -21.227851 | AM16: 0.96670621 | AO16: 24.171558 | AP16: 0.9408963 | AR16: 26.896176 | AS16: 0.94986963 | AU16: -15.064141 | AV16: 0.96492926 | AX16: -23.946769 | AY16: 1.1348211 | BA16: 0.6386677 | BB16: 0.02602735 | BD16: 0.44193553 | BE16: 0.021660677
A17: Austria | B17: m | C17: m | E17: m | F17: m | H17: m | I17: m | K17: m | L17: m | N17: m | O17: m | Q17: m | R17: m | T17: m | U17: m | W17: m | X17: m | Z17: m | AA17: m | AC17: m | AD17: m | AF17: m | AG17: m | AI17: m | AJ17: m | AL17: m | AM17: m | AO17: m | AP17: m | AR17: m | AS17: m | AU17: m | AV17: m | AX17: m | AY17: m | BA17: m | BB17: m | BD17: m | BE17: m
A18: Belgium | B18: 53.660871 | C18: 0.94299077 | E18: 16.962831 | F18: 0.70433663 | H18: 21.625906 | I18: 0.87307252 | K18: 42.888205 | L18: 1.0939676 | N18: 58.445968 | O18: 0.88295807 | Q18: -0.45217251 | R18: 0.022548548 | T18: 34.891801 | U18: 0.92841724 | W18: 31.548947 | X18: 0.81768399 | Z18: 36.508142 | AA18: 0.85093381 | AC18: 26.064467 | AD18: 0.87375401 | AF18: 35.683393 | AG18: 0.92886721 | AI18: 0.071195407 | AJ18: 0.020898206 | AL18: -18.76907 | AM18: 1.2928062 | AO18: 14.586116 | AP18: 1.0956616 | AR18: 14.882236 | AS18: 1.1479276 | AU18: -16.823739 | AV18: 1.3568528 | AX18: -22.762574 | AY18: 1.2659322 | BA18: 0.52336791 | BB18: 0.030118236 | BD18: 0.42403216 | BE18: 0.02586694
A19: Canada | B19: 50.650775 | C19: 0.73132985 | E19: 23.851538 | F19: 0.64071655 | H19: 29.050576 | I19: 0.70226937 | K19: 31.949096 | L19: 0.77669972 | N19: 53.744186 | O19: 0.7963093 | Q19: -0.28394709 | R19: 0.016464614 | T19: 23.902558 | U19: 0.57225693 | W19: 53.373522 | X19: 0.76927711 | Z19: 57.352496 | AA19: 0.7440796 | AC19: 12.181604 | AD19: 0.45405267 | AF19: 23.592235 | AG19: 0.66896551 | AI19: 0.54521333 | AJ19: 0.016185503 | AL19: -26.748217 | AM19: 0.87348031 | AO19: 29.521983 | AP19: 1.0566363 | AR19: 28.30192 | AS19: 1.0405555 | AU19: -19.767492 | AV19: 0.85890315 | AX19: -30.151951 | AY19: 0.99946534 | BA19: 0.82916042 | BB19: 0.022189345 | BD19: 0.66297949 | BE19: 0.0210458
A20: Chile | B20: 41.167249 | C20: 1.1379641 | E20: 23.718565 | F20: 0.80722439 | H20: 37.885662 | I20: 0.9771021 | K20: 24.050862 | L20: 0.93090637 | N20: 73.988755 | O20: 0.90819736 | Q20: -0.28141798 | R20: 0.017015387 | T20: 28.13065 | U20: 0.95413846 | W20: 40.790007 | X20: 1.031813 | Z20: 57.261652 | AA20: 1.0792795 | AC20: 11.388597 | AD20: 0.6563424 | AF20: 55.315122 | AG20: 1.0809107 | AI20: 0.16005472 | AJ20: 0.019977616 | AL20: -13.036598 | AM20: 1.4282606 | AO20: 17.071442 | AP20: 1.3527217 | AR20: 19.375989 | AS20: 1.3439646 | AU20: -12.662266 | AV20: 1.0610257 | AX20: -18.673632 | AY20: 1.3590384 | BA20: 0.4414727 | BB20: 0.023090589 | BD20: 0.38601197 | BE20: 0.020093536
A21: Colombia | B21: 43.362874 | C21: 1.2441298 | E21: 38.187499 | F21: 1.4610294 | H21: 39.084734 | I21: 1.4769502 | K21: 11.188149 | L21: 0.93680299 | N21: 57.424193 | O21: 1.3324969 | Q21: -0.015072168 | R21: 0.022677452 | T21: 29.4864 | U21: 1.2192123 | W21: 51.619788 | X21: 1.3602107 | Z21: 48.679744 | AA21: 1.261637 | AC21: 6.5204357 | AD21: 0.5481016 | AF21: 40.843068 | AG21: 1.4415476 | AI21: 0.27931391 | AJ21: 0.022251006 | AL21: -13.876474 | AM21: 1.6882655 | AO21: 13.432289 | AP21: 1.7184827 | AR21: 9.5950095 | AS21: 1.6519072 | AU21: -4.6677132 | AV21: 1.1608833 | AX21: -16.581125 | AY21: 1.9508231 | BA21: 0.29438608 | BB21: 0.025612893 | BD21: 0.28595153 | BE21: 0.025938748
A22: Czech Republic | B22: 51.242998 | C22: 0.96276307 | E22: 21.566597 | F22: 0.89539678 | H22: 22.918959 | I22: 0.89681229 | K22: 43.06855 | L22: 1.1235064 | N22: 64.153519 | O22: 0.97763513 | Q22: -0.43992147 | R22: 0.01821551 | T22: 28.977458 | U22: 1.0828261 | W22: 46.694301 | X22: 1.147796 | Z22: 48.499521 | AA22: 1.1850154 | AC22: 20.597736 | AD22: 0.89928942 | AF22: 37.782656 | AG22: 1.27077 | AI22: 0.21788793 | AJ22: 0.024653657 | AL22: -22.265541 | AM22: 1.381641 | AO22: 25.127704 | AP22: 1.4902444 | AR22: 25.580563 | AS22: 1.2861522 | AU22: -22.470814 | AV22: 1.4650054 | AX22: -26.370864 | AY22: 1.5252774 | BA22: 0.6578094 | BB22: 0.030433231 | BD22: 0.47724302 | BE22: 0.026597755
A23: Denmark | B23: 56.671229 | C23: 1.3430928 | E23: 16.109925 | F23: 0.89683397 | H23: 27.853907 | I23: 1.2006202 | K23: 35.22263 | L23: 1.1728279 | N23: 60.973135 | O23: 1.2580709 | Q23: -0.34784198 | R23: 0.022291729 | T23: 34.433054 | U23: 1.2045978 | W23: 32.052058 | X23: 0.9977161 | Z23: 45.282382 | AA23: 1.3587021 | AC23: 16.868051 | AD23: 1.0065779 | AF23: 34.252822 | AG23: 1.1403984 | AI23: 0.16927996 | AJ23: 0.022992079 | AL23: -22.238175 | AM23: 1.5573859 | AO23: 15.942133 | AP23: 1.1861802 | AR23: 17.428475 | AS23: 1.7294401 | AU23: -18.354579 | AV23: 1.3188896 | AX23: -26.720313 | AY23: 1.5784511 | BA23: 0.51712194 | BB23: 0.027247771 | BD23: 0.3857141 | BE23: 0.026539809
A24: Estonia | B24: 58.79204 | C24: 1.2131711 | E24: 14.94926 | F24: 0.8793161 | H24: 21.794319 | I24: 0.95442283 | K24: 32.87271 | L24: 1.1239394 | N24: 66.559324 | O24: 1.2035165 | Q24: -0.37905502 | R24: 0.019715096 | T24: 28.709684 | U24: 1.131846 | W24: 43.503537 | X24: 1.282261 | Z24: 49.558807 | AA24: 1.4675794 | AC24: 11.901642 | AD24: 0.84058028 | AF24: 36.401317 | AG24: 1.2881343 | AI24: 0.33483493 | AJ24: 0.024970323 | AL24: -30.082356 | AM24: 1.5389028 | AO24: 28.554278 | AP24: 1.5332169 | AR24: 27.764488 | AS24: 1.7001688 | AU24: -20.971069 | AV24: 1.3075205 | AX24: -30.158007 | AY24: 1.6431813 | BA24: 0.71388996 | BB24: 0.028238189 | BD24: 0.54238211 | BE24: 0.02589983
A25: Finland | B25: 49.896179 | C25: 1.1442624 | E25: 17.478482 | F25: 0.70937493 | H25: 20.148981 | I25: 0.806387 | K25: 41.635683 | L25: 1.1738737 | N25: 52.737522 | O25: 0.97035613 | Q25: -0.41293713 | R25: 0.020430268 | T25: 19.573918 | U25: 0.94411093 | W25: 50.357028 | X25: 1.2898076 | Z25: 47.883628 | AA25: 1.3671473 | AC25: 13.024214 | AD25: 0.80924336 | AF25: 20.03925 | AG25: 1.0157769 | AI25: 0.4953857 | AJ25: 0.0245943 | AL25: -30.322261 | AM25: 1.3904431 | AO25: 32.878546 | AP25: 1.327718 | AR25: 27.734647 | AS25: 1.3268358 | AU25: -28.611469 | AV25: 1.3282639 | AX25: -32.698273 | AY25: 1.2707965 | BA25: 0.90832283 | BB25: 0.025718001 | BD25: 0.62522594 | BE25: 0.023643707
A26: France | B26: 42.058812 | C26: 1.3623262 | E26: 23.240464 | F26: 1.1287995 | H26: 34.168747 | I26: 1.4684752 | K26: 33.755714 | L26: 1.5286224 | N26: 52.965278 | O26: 1.4413673 | Q26: -0.22850804 | R26: 0.031947761 | T26: 26.175433 | U26: 1.1361447 | W26: 38.70867 | X26: 1.3049886 | Z26: 50.506185 | AA26: 1.4553904 | AC26: 18.222839 | AD26: 0.97845049 | AF26: 34.6385 | AG26: 1.3659031 | AI26: 0.24314815 | AJ26: 0.030246735 | AL26: -15.88338 | AM26: 1.589137 | AO26: 15.468206 | AP26: 1.5653829 | AR26: 16.337438 | AS26: 1.6611638 | AU26: -15.532874 | AV26: 1.5226859 | AX26: -18.326779 | AY26: 1.4945774 | BA26: 0.47165618 | BB26: 0.038255332 | BD26: 0.31019366 | BE26: 0.034976976
A27: Germany | B27: 53.440315 | C27: 1.0980913 | E27: 19.209693 | F27: 0.87350835 | H27: 18.73996 | I27: 0.86748171 | K27: 40.551727 | L27: 1.1108022 | N27: 58.149942 | O27: 1.134325 | Q27: -0.37624372 | R27: 0.02268185 | T27: 24.633407 | U27: 0.99515965 | W27: 46.007011 | X27: 1.0068629 | Z27: 45.727002 | AA27: 1.2879986 | AC27: 18.478941 | AD27: 0.77539182 | AF27: 30.918765 | AG27: 1.0199904 | AI27: 0.51778752 | AJ27: 0.027475672 | AL27: -28.806908 | AM27: 1.4119297 | AO27: 26.797318 | AP27: 1.1608536 | AR27: 26.987042 | AS27: 1.4907392 | AU27: -22.072786 | AV27: 1.2699199 | AX27: -27.231176 | AY27: 1.4391195 | BA27: 0.89403124 | BB27: 0.03427188 | BD27: 0.69859573 | BE27: 0.030688587
A28: Greece | B28: 54.36864 | C28: 1.4865795 | E28: 20.469094 | F28: 0.99954671 | H28: 25.323962 | I28: 0.97193275 | K28: 19.010755 | L28: 0.92979208 | N28: 53.466581 | O28: 1.3649646 | Q28: -0.24297196 | R28: 0.022430231 | T28: 31.690509 | U28: 1.506786 | W28: 37.373371 | X28: 1.1516892 | Z28: 49.744214 | AA28: 1.3006649 | AC28: 7.275457 | AD28: 0.77520121 | AF28: 25.333539 | AG28: 1.329898 | AI28: 0.36025445 | AJ28: 0.023456771 | AL28: -22.678131 | AM28: 2.1958861 | AO28: 16.904277 | AP28: 1.5571925 | AR28: 24.420253 | AS28: 1.3899896 | AU28: -11.735298 | AV28: 1.2865692 | AX28: -28.133042 | AY28: 1.7973102 | BA28: 0.60322641 | BB28: 0.03016319 | BD28: 0.45825551 | BE28: 0.027568388
A29: Hungary | B29: 41.889613 | C29: 1.4745574 | E29: 25.151852 | F29: 1.3854526 | H29: 28.256986 | I29: 1.570727 | K29: 30.448482 | L29: 1.2146075 | N29: 59.753266 | O29: 1.3420692 | Q29: -0.1521145 | R29: 0.028022847 | T29: 22.881077 | U29: 1.1910545 | W29: 44.701953 | X29: 1.3502961 | Z29: 49.404451 | AA29: 1.3132055 | AC29: 13.916681 | AD29: 0.89212774 | AF29: 34.924971 | AG29: 1.2413156 | AI29: 0.42690531 | AJ29: 0.024743687 | AL29: -19.008536 | AM29: 1.6782316 | AO29: 19.5501 | AP29: 1.8078509 | AR29: 21.147465 | AS29: 2.0246204 | AU29: -16.531801 | AV29: 1.5370338 | AX29: -24.828295 | AY29: 1.8977501 | BA29: 0.57901981 | BB29: 0.036784218 | BD29: 0.42825743 | BE29: 0.030423858
... A46: Slovenia | B46: 65.277733 | C46: 1.1044885 | E46: 12.887793 | F46: 0.73719333 | H46: 22.236776 | I46: 0.97568931 | K46: 44.379487 | L46: 0.94470716 | N46: 65.484391 | O46: 0.98259311 | Q46: -0.53333527 | R46: 0.017886216 | T46: 39.818353 | U46: 1.1945693 | W46: 33.741869 | X46: 1.0311411 | Z46: 47.20323 | AA46: 1.1133324 | AC46: 22.140956 | AD46: 1.0567909 | AF46: 40.306778 | AG46: 1.2483719 | AI46: 0.1390173 | AJ46: 0.02253133 | AL46: -25.45938 | AM46: 1.7895159 | AO46: 20.854077 | AP46: 1.3211776 | AR46: 24.966454 | AS46: 1.4351175 | AU46: -22.238532 | AV46: 1.4597524 | AX46: -25.177613 | AY46: 1.6456073 | BA46: 0.67235257 | BB46: 0.030249578 | BD46: 0.47446253 | BE46: 0.027992902
A47: Spain | B47: 53.892344 | C47: 0.66224662 | E47: 24.62781 | F47: 0.70821626 | H47: 32.443236 | I47: 0.94223131 | K47: 24.248117 | L47: 0.77087073 | N47: 56.932269 | O47: 0.83537016 | Q47: -0.28145508 | R47: 0.016033168 | T47: 33.140565 | U47: 0.98247378 | W47: 43.06068 | X47: 0.67847568 | Z47: 52.58119 | AA47: 0.78138576 | AC47: 10.901509 | AD47: 0.50146918 | AF47: 35.124431 | AG47: 0.9685635 | AI47: 0.26361336 | AJ47: 0.014999203 | AL47: -20.751779 | AM47: 1.078276 | AO47: 18.43287 | AP47: 0.96853284 | AR47: 20.137954 | AS47: 1.0253326 | AU47: -13.346608 | AV47: 0.69779706 | AX47: -21.807838 | AY47: 1.1115986 | BA47: 0.54506844 | BB47: 0.019234252 | BD47: m | BE47: m
A48: Sweden | B48: 52.600073 | C48: 0.98488363 | E48: 16.059133 | F48: 0.82390557 | H48: 21.713634 | I48: 1.0026077 | K48: 38.12584 | L48: 0.93952071 | N48: 56.132711 | O48: 1.2453314 | Q48: -0.46639883 | R48: 0.019217139 | T48: 25.839965 | U48: 1.0539136 | W48: 38.575209 | X48: 1.1929575 | Z48: 45.718842 | AA48: 1.3361205 | AC48: 16.98328 | AD48: 0.89209047 | AF48: 26.734885 | AG48: 1.0138869 | AI48: 0.25757414 | AJ48: 0.026454094 | AL48: -26.760108 | AM48: 1.4585495 | AO48: 22.516076 | AP48: 1.4638991 | AR48: 24.005208 | AS48: 1.4946235 | AU48: -21.14256 | AV48: 1.2070633 | AX48: -29.397827 | AY48: 1.4141891 | BA48: 0.72397297 | BB48: 0.029110118 | BD48: 0.53894175 | BE48: 0.027236531
A49: Switzerland | B49: 55.799484 | C49: 1.1301474 | E49: 18.893835 | F49: 0.77406854 | H49: 20.71645 | I49: 0.88929008 | K49: 42.421848 | L49: 1.0098651 | N49: 59.101786 | O49: 1.0601151 | Q49: -0.43885339 | R49: 0.020274177 | T49: 30.672757 | U49: 1.1909628 | W49: 40.345925 | X49: 0.97301186 | Z49: 41.85918 | AA49: 1.089538 | AC49: 19.970655 | AD49: 0.84265241 | AF49: 32.167984 | AG49: 0.9104173 | AI49: 0.36598397 | AJ49: 0.028397321 | AL49: -25.126727 | AM49: 1.5202259 | AO49: 21.452089 | AP49: 1.299534 | AR49: 21.14273 | AS49: 1.4364099 | AU49: -22.451193 | AV49: 1.2042563 | AX49: -26.933802 | AY49: 1.2771353 | BA49: 0.80483735 | BB49: 0.032973956 | BD49: 0.60262874 | BE49: 0.03021531
A50: Turkey | B50: 27.41168 | C50: 1.0193903 | E50: 55.619283 | F50: 1.2913703 | H50: 55.711975 | I50: 1.1996366 | K50: 10.709036 | L50: 0.62013676 | N50: 43.653646 | O50: 1.0077581 | Q50: 0.3425855 | R50: 0.018242181 | T50: 14.374799 | U50: 0.84732018 | W50: 75.830406 | X50: 0.79637672 | Z50: 79.779783 | AA50: 0.94883256 | AC50: 4.6428427 | AD50: 0.68423988 | AF50: 18.636085 | AG50: 1.0470728 | AI50: 0.95207228 | AJ50: 0.023048196 | AL50: -13.036881 | AM50: 1.2453087 | AO50: 20.211123 | AP50: 1.5104616 | AR50: 24.067808 | AS50: 1.3657897 | AU50: -6.0661933 | AV50: 0.93509913 | AX50: -25.017561 | AY50: 1.3439476 | BA50: 0.60948678 | BB50: 0.027256695 | BD50: 0.53429367 | BE50: 0.027126803
A51: United Kingdom | B51: 50.215716 | C51: 1.0028531 | E51: 18.55491 | F51: 0.81864493 | H51: 24.361554 | I51: 0.98368523 | K51: 29.461582 | L51: 1.0231355 | N51: 58.565966 | O51: 1.0380234 | Q51: -0.37323069 | R51: 0.021399024 | T51: 33.749757 | U51: 1.0653624 | W51: 35.365242 | X51: 0.83492781 | Z51: 45.316899 | AA51: 1.3026726 | AC51: 17.537964 | AD51: 0.68137977 | AF51: 38.260766 | AG51: 1.0470206 | AI51: 0.12763274 | AJ51: 0.019466778 | AL51: -16.465959 | AM51: 1.3875976 | AO51: 16.810331 | AP51: 1.3120877 | AR51: 20.955345 | AS51: 1.6102924 | AU51: -11.923619 | AV51: 1.1599747 | AX51: -20.305199 | AY51: 1.3440402 | BA51: 0.50086343 | BB51: 0.027887933 | BD51: 0.38853202 | BE51: 0.024221044
A52: United States | B52: 60.472402 | C52: 1.07706 | E52: 20.388076 | F52: 1.1315197 | H52: 30.245129 | I52: 1.0658628 | K52: 34.283755 | L52: 1.3107424 | N52: 58.94382 | O52: 1.2785812 | Q52: -0.34557727 | R52: 0.027151478 | T52: 38.445547 | U52: 1.3522966 | W52: 41.118734 | X52: 1.3577043 | Z52: 52.136098 | AA52: 1.4233368 | AC52: 16.834939 | AD52: 1.0616532 | AF52: 34.616587 | AG52: 1.309408 | AI52: 0.28357895 | AJ52: 0.03211723 | AL52: -22.026855 | AM52: 1.3400711 | AO52: 20.730659 | AP52: 1.0148171 | AR52: 21.890969 | AS52: 1.6270576 | AU52: -17.448816 | AV52: 1.5089914 | AX52: -24.327233 | AY52: 1.343191 | BA52: 0.62915622 | BB52: 0.02836789 | BD52: 0.52273535 | BE52: 0.027326463
A53: OECD average-24 | B53: 50.855287 | C53: 0.22860644 | E53: 22.990907 | F53: 0.18278385 | H53: 27.363238 | I53: 0.20704041 | K53: 31.829798 | L53: 0.21364946 | N53: 56.333981 | O53: 0.22718194 | Q53: -0.29131288 | R53: 0.0043929837 | T53: 29.783345 | U53: 0.21552106 | W53: 43.354793 | X53: 0.22773924 | Z53: 48.910456 | AA53: 0.23572258 | AC53: 15.038217 | AD53: 0.16000932 | AF53: 31.730607 | AG53: 0.21394643 | AI53: 0.32580522 | AJ53: 0.0048235009 | AL53: -21.071942 | AM53: 0.29907528 | AO53: 20.363886 | AP53: 0.27827847 | AR53: 21.547218 | AS53: 0.29082203 | AU53: -16.791581 | AV53: 0.25303368 | AX53: -24.603373 | AY53: 0.29009473 | BA53: 0.61711811 | BB53: 0.0060706341 | BD53: 0.4511417 | BE53: 0.0054928198
A54: OECD average-36b | B54: 51.612956 | C54: 0.18922568 | E54: 23.26429 | F54: 0.15771532 | H54: 27.533127 | I54: 0.17091179 | K54: 31.846187 | L54: 0.17912298 | N54: 58.299651 | O54: 0.18702324 | Q54: -0.30014661 | R54: 0.0036597769 | T54: 30.506498 | U54: 0.18414262 | W54: 43.801013 | X54: 0.19000706 | Z54: 49.040913 | AA54: 0.19910493 | AC54: 15.126915 | AD54: 0.13661006 | AF54: 33.855393 | AG54: 0.18553047 | AI54: 0.31592107 | AJ54: 0.0040413654 | AL54: -21.106458 | AM54: 0.24800518 | AO54: 20.536723 | AP54: 0.23403001 | AR54: 21.507786 | AS54: 0.245278 | AU54: -16.719272 | AV54: 0.21186973 | AX54: -24.444258 | AY54: 0.24320905 | BA54: 0.61606767 | BB54: 0.0049893231 | BD54: 0.46569872 | BE54: 0.0045944487
A55: OECD average-37 | B55: m | C55: m | E55: m | F55: m | H55: m | I55: m | K55: m | L55: m | N55: m | O55: m | Q55: m | R55: m | T55: m | U55: m | W55: m | X55: m | Z55: m | AA55: m | AC55: m | AD55: m | AF55: m | AG55: m | AI55: m | AJ55: m | AL55: m | AM55: m | AO55: m | AP55: m | AR55: m | AS55: m | AU55: m | AV55: m | AX55: m | AY55: m | BA55: m | BB55: m | BD55: m | BE55: m
A56: Partners
A57: Albania | B57: 49.880007 | C57: 1.4311371 | E57: 52.426593 | F57: 1.4187856 | H57: 59.912092 | I57: 1.3372852 | K57: 9.0666863 | L57: 0.85320137 | N57: 52.074469 | O57: 1.4511147 | Q57: 0.36159053 | R57: 0.018786151 | T57: 22.583293 | U57: 1.1366692 | W57: 83.498848 | X57: 0.88204131 | Z57: 85.640555 | AA57: 0.93351938 | AC57: 3.515498 | AD57: 0.66955011 | AF57: 22.443086 | AG57: 1.1374015 | AI57: 0.98769918 | AJ57: 0.017391598 | AL57: -27.296713 | AM57: 1.5959717 | AO57: 31.072254 | AP57: 1.6197923 | AR57: 25.728464 | AS57: 1.7572327 | AU57: -5.5511883 | AV57: 1.143646 | AX57: -29.631383 | AY57: 1.5233811 | BA57: 0.62610865 | BB57: 0.022899456 | BD57: 0.52433927 | BE57: 0.023957171
A58: Argentina | B58: 65.271233 | C58: 1.1873405 | E58: 24.749689 | F58: 1.141647 | H58: 30.874868 | I58: 1.1417576 | K58: 24.586347 | L58: 1.1974533 | N58: 74.466186 | O58: 1.116377 | Q58: -0.34355633 | R58: 0.022073702 | T58: 51.173504 | U58: 1.4501913 | W58: 38.430953 | X58: 1.2016897 | Z58: 45.450849 | AA58: 1.3157915 | AC58: 15.302119 | AD58: 0.94938401 | AF58: 59.650117 | AG58: 1.4578372 | AI58: -0.005310118 | AJ58: 0.024938294 | AL58: -14.09773 | AM58: 1.7984263 | AO58: 13.681264 | AP58: 1.6600498 | AR58: 14.57598 | AS58: 1.4891755 | AU58: -9.2842278 | AV58: 1.4948276 | AX58: -14.816069 | AY58: 1.7295493 | BA58: 0.33824621 | BB58: 0.028518969 | BD58: 0.30159317 | BE58: 0.027444807
A59: Baku (Azerbaijan) | B59: m | C59: m | E59: m | F59: m | H59: m | I59: m | K59: m | L59: m | N59: m | O59: m | Q59: m | R59: m | T59: m | U59: m | W59: m | X59: m | Z59: m | AA59: m | AC59: m | AD59: m | AF59: m | AG59: m | AI59: m | AJ59: m | AL59: m | AM59: m | AO59: m | AP59: m | AR59: m | AS59: m | AU59: m | AV59: m | AX59: m | AY59: m | BA59: m | BB59: m | BD59: m | BE59: m
A60: Belarus | B60: m | C60: m | E60: m | F60: m | H60: m | I60: m | K60: m | L60: m | N60: m | O60: m | Q60: m | R60: m | T60: m | U60: m | W60: m | X60: m | Z60: m | AA60: m | AC60: m | AD60: m | AF60: m | AG60: m | AI60: m | AJ60: m | AL60: m | AM60: m | AO60: m | AP60: m | AR60: m | AS60: m | AU60: m | AV60: m | AX60: m | AY60: m | BA60: m | BB60: m | BD60: m | BE60: m
...

Sheet Table II.B1.8.4
A1: PISA 2018 Results (Volume II) - © OECD 2019
A2: Annex B1 | B2: Annex B1.8 Results (tables): Do boys and girls differ in their attitudes towards school and learning?
A3: Version 2 - Last updated: 02-Dec-2019
A4: Disclaimer: http://oe.cd/disclaimer
A6: Table II.B1.8.4
A7: Index of enjoyment of reading, by gender (PISA 2000)
