Workbook

Sheet TOC
A1: PISA 2018 Results (Volume III) - © OECD 2019
A2: Annex B1 | B2: Annex B1.13 Results (tables): Students' self-efficacy and fear of failure
A3: Version 2 - Last updated: 24-Jul-2020
A4: Disclaimer: http://oe.cd/disclaimer
A6: Annex B1 | B6: Annex B1.13 Results (tables): Students' self-efficacy and fear of failure
A7: Version 2 - Last updated: 02-Dec-2019
A8: Disclaimer: http://oe.cd/disclaimer
A10: TOC | B10: PISA 2018 Results - Volume III
A12: Chapter 13 | B12: Self-efficacy and fear of failure
A13: Tables
A15: ='Table III.B1.13.1'!A10 -> Table III.B1.13.1 | B15: ='Table III.B1.13.1'!A11 -> Students' self-efficacy | G15: Note:
A16: ='Table III.B1.13.2'!A10 -> Table III.B1.13.2 | B16: ='Table III.B1.13.2'!A11 -> Students' fear of failure | G16: In 2018, some regions in Spain conducted their high-stakes exams for tenth-grade students earlier in the year than in the past, which resulted in the testing period for these exams coinciding with the end of the PISA testing window. Because of this overlap, a number of students were negatively disposed towards the PISA test and did not try their best to demonstrate their proficiency. Although the data of only a minority of students show clear signs of lack of engagement (see PISA 2018 Results Volume I, Annex A9), the comparability of PISA 2018 data for Spain with those from earlier PISA assessments cannot be fully ensured.
A17: ='Table III.B1.13.3'!A10 -> Table III.B1.13.3 | B17: ='Table III.B1.13.3'!A11 -> Prevalence of self-efficacy in schools
A18: ='Table III.B1.13.4'!A10 -> Table III.B1.13.4 | B18: ='Table III.B1.13.4'!A11 -> Prevalence of fear of failure in schools
A19: ='Table III.B1.13.5'!A10 -> Table III.B1.13.5 | B19: ='Table III.B1.13.5'!A11 -> Index of self-efficacy, by student characteristics
A20: ='Table III.B1.13.6'!A10 -> Table III.B1.13.6 | B20: ='Table III.B1.13.6'!A11 -> Index of fear of failure, by student characteristics
A21: ='Table III.B1.13.7'!A10 -> Table III.B1.13.7 | B21: ='Table III.B1.13.7'!A11 -> Index of self-efficacy, by school characteristics
A22: ='Table III.B1.13.8'!A10 -> Table III.B1.13.8 | B22: ='Table III.B1.13.8'!A11 -> Index of fear of failure, by school characteristics
A23: ='Table III.B1.13.9'!A10 -> Table III.B1.13.9 | B23: ='Table III.B1.13.9'!A11 -> Self-efficacy and reading performance
A24: ='Table III.B1.13.10'!A10 -> Table III.B1.13.10 | B24: ='Table III.B1.13.10'!A11 -> Fear of failure and reading performance
A25: ='Table III.B1.13.11'!A10 -> Table III.B1.13.11 | B25: ='Table III.B1.13.11'!A11 -> School-level self-efficacy and reading performance
A26: ='Table III.B1.13.12'!A10 -> Table III.B1.13.12 | B26: ='Table III.B1.13.12'!A11 -> School-level fear of failure and reading performance
A27: ='Table III.B1.13.13'!A10 -> Table III.B1.13.13 | B27: ='Table III.B1.13.13'!A11 -> Self-efficacy, fear of failure and test performance, by gender
A28: ='Table III.B1.13.14'!A10 -> Table III.B1.13.14 | B28: ='Table III.B1.13.14'!A11 -> Fear of failure, by proficiency levels in reading and gender
A29: ='Table III.B1.13.15'!A10 -> Table III.B1.13.15 | B29: ='Table III.B1.13.15'!A11 -> Fear of failure and life satisfaction
A32: Symbols for missing data
A33: c: There were too few observations to provide reliable estimates (i.e. there were fewer than 30 students or fewer than 5 schools with valid data).
A34: m: Data are not available. There are no observations in the sample; these data were not collected by the country; or these data were collected but subsequently removed from the publication for technical reasons.
A35: w: Results were withdrawn at the request of the country concerned.

Sheet INFORMATION ON SCALED INDICES
A1: PISA 2018 Results (Volume III) - © OECD 2019
A2: Annex B1 | B2: Annex B1.13 Results (tables): Students' self-efficacy and fear of failure
A3: Version 2 - Last updated: 24-Jul-2020
A4: Disclaimer: http://oe.cd/disclaimer
A6: Annex B1 | B6: Annex B1.13 Results (tables): Students' self-efficacy and fear of failure
A7: Version 2 - Last updated: 02-Dec-2019
A8: Disclaimer: http://oe.cd/disclaimer
A10: Information on scaled indices used in PISA 2015 Results (Volume III): What School Life Means for Students’ Lives
A15: Full name of the index | B15: Name in dataset | C15: Questionnaire | D15: Item 1 | E15: Item 2 | F15: Item 3 | G15: Item 4 | H15: Item 5 | I15: Item 6 | J15: Item 7
A16: Adaptive instruction | B16: adaptivity | C16: Student | D16: ST212Q01HA | E16: ST212Q02HA | F16: ST212Q03HA
A17: Attitudes towards competition | B17: compete | C17: Student | D17: ST181Q02HA | E17: ST181Q03HA | F17: ST181Q04HA
A18: Enjoyment of reading | B18: joyread | C18: Student | D18: ST160Q01IR | E18: ST160Q02IA | F18: ST160Q03IA | G18: ST160Q04IR | H18: ST160Q05IR
A19: Exposure to bullying | B19: beingbullied | C19: Student | D19: ST038Q03NA | E19: ST038Q04NA | F19: ST038Q05NA
A20: Fear of failure | B20: gfofail | C20: Student | D20: ST183Q01HA | E20: ST183Q02HA | F20: ST183Q03HA
A21: Disciplinary climate | B21: disclima | C21: Student | D21: ST097Q01TA | E21: ST097Q02TA | F21: ST097Q03TA | G21: ST097Q04TA | H21: ST097Q05TA
A22: Learning goals | B22: mastgoal | C22: Student | D22: ST208Q01HA | E22: ST208Q02HA | F22: ST208Q04HA
A23: Meaning in life | B23: eudmo | C23: Student | D23: ST185Q01HA | E23: ST185Q02HA | F23: ST185Q03HA
A24: Motivation to master tasks | B24: workmast | C24: Student | D24: ST182Q03HA | E24: ST182Q04HA | F24: ST182Q05HA
A25: Parents’ emotional support | B25: emosups | C25: Student | D25: ST123Q02NA | E25: ST123Q03NA | F25: ST123Q04NA
A26: Parents’ perceived school quality | B26: pqschool | C26: Parent | D26: PA007Q01TR | E26: PA007Q02TR | F26: PA007Q03TR | G26: PA007Q04TR | H26: PA007Q05TR | I26: PA007Q06TR | J26: PA007Q07TR
A27: Positive feelings | B27: swbp | C27: Student | D27: ST186Q01HA | E27: ST186Q03HA | F27: ST186Q05HA
A28: School policies for parental involvement | B28: paschpol | C28: Parent | D28: PA007Q09NR | E28: PA007Q11NR | F28: PA007Q12NR | G28: PA007Q13NR | H28: PA007Q14NR | I28: PA007Q15NR
A29: Self-efficacy | B29: resilience | C29: Student | D29: ST188Q01HA | E29: ST188Q02HA | F29: ST188Q03HA | G29: ST188Q06HA | H29: ST188Q07HA
A30: Sense of belonging | B30: belong | C30: Student | D30: ST034Q01TA | E30: ST034Q02TR | F30: ST034Q03TR | G30: ST034Q04TA | H30: ST034Q05TR | I30: ST034Q06TA
A31: Shortage of educational staff | B31: staffshort | C31: School | D31: SC017Q01NA | E31: SC017Q02NA | F31: SC017Q03NA | G31: SC017Q04NA
A32: Student competition | B32: percomp | C32: Student | D32: ST205Q01HA | E32: ST205Q02HA | F32: ST205Q03HA
A33: Student co-operation | B33: percoop | C33: Student | D33: ST206Q01HA | E33: ST206Q02HA | F33: ST206Q03HA
A34: Teacher behaviour hindering learning | B34: teachbeha | C34: School | D34: SC061Q06TA | E34: SC061Q07TA | F34: SC061Q08TA | G34: SC061Q09TA | H34: SC061Q10TA
A35: Teacher enthusiasm | B35: teachint | C35: Student | D35: ST213Q01HA | E35: ST213Q02HA | F35: ST213Q03HA | G35: ST213Q04HA
A36: Teacher feedback | B36: perfeed | C36: Student | D36: ST104Q02NA | E36: ST104Q03NA | F36: ST104Q04NA
A37: Teacher support | B37: teachsup | C37: Student | D37: ST100Q01TR | E37: ST100Q02TR | F37: ST100Q03TR | G37: ST100Q04TR
A38: Teacher-directed instruction | B38: dirins | C38: Student | D38: ST102Q01TR | E38: ST102Q02TR | F38: ST102Q03TR | G38: ST102Q04TR
A39: Teachers' stimulation of reading engagement | B39: stimread | C39: Student | D39: ST152Q05IA | E39: ST152Q06IA | F39: ST152Q07IA | G39: ST152Q08IA
A40: Value of school | B40: attlnact | C40: Student | D40: ST036Q05TR | E40: ST036Q06TR | F40: ST036Q08TR

Sheet Table III.B1.13.1
A1: PISA 2018 Results (Volume III) - © OECD 2019
A2: Annex B1 | B2: Annex B1.13 Results (tables): Students' self-efficacy and fear of failure
A3: Version 2 - Last updated: 24-Jul-2020
A4: Disclaimer: http://oe.cd/disclaimer
A6: Annex B1 | B6: Annex B1.13 Results (tables): Students' self-efficacy and fear of failure
A7: Version 2 - Last updated: 02-Dec-2019
A8: Disclaimer: http://oe.cd/disclaimer
A10: Table III.B1.13.1
A11: Students' self-efficacy
A12: Based on students' reports
B15: Index of self-efficacy | H15: Percentage of students who reported the following:
H16: I usually manage one way or another | T16: I feel proud that I have accomplished things | AF16: I feel that I can handle many things at a time | AR16: My belief in myself gets me through hard times | BD16: When I’m in a difficult situation, I can usually find my way out of it
B17: Average | E17: Variability | H17: Strongly disagree | K17: Disagree | N17: Agree | Q17: Strongly agree | T17: Strongly disagree | W17: Disagree | Z17: Agree | AC17: Strongly agree | AF17: Strongly disagree | AI17: Disagree | AL17: Agree | AO17: Strongly agree | AR17: Strongly disagree | AU17: Disagree | AX17: Agree | BA17: Strongly agree | BD17: Strongly disagree | BG17: Disagree | BJ17: Agree | BM17: Strongly agree
B18: Mean index | C18: S.E. | E18: S.D. | F18: S.E. | H18: % | I18: S.E. | K18: % | L18: S.E. | N18: % | O18: S.E. | Q18: % | R18: S.E. | T18: % | U18: S.E. | W18: % | X18: S.E. | Z18: % | AA18: S.E. | AC18: % | AD18: S.E. | AF18: % | AG18: S.E. | AI18: % | AJ18: S.E. | AL18: % | AM18: S.E. | AO18: % | AP18: S.E. | AR18: % | AS18: S.E. | AU18: % | AV18: S.E. | AX18: % | AY18: S.E. | BA18: % | BB18: S.E. | BD18: % | BE18: S.E. | BG18: % | BH18: S.E. | BJ18: % | BK18: S.E. | BM18: % | BN18: S.E.
A19: OECD
A20: Australia | B20: 0.025454753 | C20: 0.011074198 | E20: 0.96396868 | F20: 0.0074270658 | H20: 1.3114081 | I20: 0.10836053 | K20: 5.4329621 | L20: 0.25060364 | N20: 72.388897 | O20: 0.46620165 | Q20: 20.866733 | R20: 0.41435161 | T20: 1.4385259 | U20: 0.10943328 | W20: 6.6908825 | X20: 0.26204659 | Z20: 59.24037 | AA20: 0.5143654 | AC20: 32.630222 | AD20: 0.48428705 | AF20: 3.9053294 | AG20: 0.21248115 | AI20: 23.537721 | AJ20: 0.39793276 | AL20: 56.748512 | AM20: 0.48367188 | AO20: 15.808438 | AP20: 0.36385299 | AR20: 6.9823906 | AS20: 0.27422856 | AU20: 26.147341 | AV20: 0.40807636 | AX20: 50.070708 | AY20: 0.47804626 | BA20: 16.79956 | BB20: 0.42230805 | BD20: 2.5940682 | BE20: 0.1633024 | BG20: 11.582586 | BH20: 0.40096442 | BJ20: 64.664542 | BK20: 0.51826837 | BM20: 21.158803 | BN20: 0.46767474
A21: Austria | B21: 0.081056302 | C21: 0.019159826 | E21: 1.0352059 | F21: 0.012227692 | H21: 3.4165014 | I21: 0.27220461 | K21: 12.060781 | L21: 0.53224198 | N21: 64.192939 | O21: 0.66528582 | Q21: 20.329778 | R21: 0.62134942 | T21: 2.6027281 | U21: 0.24669008 | W21: 12.501031 | X21: 0.50093289 | Z21: 47.183795 | AA21: 0.71675726 | AC21: 37.712446 | AD21: 0.80010563 | AF21: 4.0306302 | AG21: 0.24507164 | AI21: 25.101438 | AJ21: 0.6296848 | AL21: 52.359556 | AM21: 0.71060476 | AO21: 18.508376 | AP21: 0.53624424 | AR21: 6.4810813 | AS21: 0.30123323 | AU21: 20.877628 | AV21: 0.61452482 | AX21: 44.669962 | AY21: 0.68399142 | BA21: 27.971329 | BB21: 0.7520461 | BD21: 3.0602049 | BE21: 0.28280722 | BG21: 13.321744 | BH21: 0.51342105 | BJ21: 55.943834 | BK21: 0.74724587 | BM21: 27.674218 | BN21: 0.79639637
A22: Belgium (Flemish) | B22: -0.20960614 | C22: 0.016417729 | E22: 0.81999745 | F22: 0.013130932 | H22: 1.8118609 | I22: 0.20546118 | K22: 9.3084136 | L22: 0.40638595 | N22: 70.826908 | O22: 0.55561219 | Q22: 18.052818 | R22: 0.57985791 | T22: 1.045412 | U22: 0.27419639 | W22: 7.8534516 | X22: 0.38140221 | Z22: 64.432908 | AA22: 0.76781352 | AC22: 26.668228 | AD22: 0.84163771 | AF22: 2.7571259 | AG22: 0.26602345 | AI22: 33.599429 | AJ22: 0.7819275 | AL22: 54.224424 | AM22: 0.71289467 | AO22: 9.4190215 | AP22: 0.51749957 | AR22: 9.9410057 | AS22: 0.51435775 | AU22: 32.729608 | AV22: 0.78813462 | AX22: 46.028887 | AY22: 0.87451632 | BA22: 11.300499 | BB22: 0.42651019 | BD22: 2.5123041 | BE22: 0.36800964 | BG22: 14.634247 | BH22: 0.52186633 | BJ22: 68.828629 | BK22: 0.69626535 | BM22: 14.02482 | BN22: 0.51410305
A23: Canada | B23: 0.1310839 | C23: 0.009257815 | E23: 1.0089946 | F23: 0.0070374299 | H23: 1.4750641 | I23: 0.11868756 | K23: 5.4623717 | L23: 0.22999744 | N23: 66.782338 | O23: 0.46607484 | Q23: 26.280227 | R23: 0.41855183 | T23: 1.3930927 | U23: 0.12091025 | W23: 7.3093525 | X23: 0.28713147 | Z23: 56.428026 | AA23: 0.45702361 | AC23: 34.869529 | AD23: 0.45178523 | AF23: 4.0023347 | AG23: 0.19177686 | AI23: 23.397901 | AJ23: 0.40673431 | AL23: 52.497873 | AM23: 0.46602717 | AO23: 20.101892 | AP23: 0.37263103 | AR23: 6.0687222 | AS23: 0.22019877 | AU23: 23.34896 | AV23: 0.42776323 | AX23: 50.257568 | AY23: 0.45463631 | BA23: 20.32475 | BB23: 0.35104382 | BD23: 2.033931 | BE23: 0.11048526 | BG23: 10.577852 | BH23: 0.34657335 | BJ23: 61.852648 | BK23: 0.469268 | BM23: 25.535569 | BN23: 0.36833226
A24: Chile | B24: 0.2908346 | C24: 0.016741893 | E24: 1.1276964 | F24: 0.012727525 | H24: 2.1912686 | I24: 0.25432808 | K24: 5.5936711 | L24: 0.32392629 | N24: 61.188596 | O24: 0.71039016 | Q24: 31.026464 | R24: 0.70061188 | T24: 2.054412 | U24: 0.20911182 | W24: 6.9600796 | X24: 0.32838211 | Z24: 50.379253 | AA24: 0.80804346 | AC24: 40.606255 | AD24: 0.82134069 | AF24: 2.6721283 | AG24: 0.25028178 | AI24: 18.947168 | AJ24: 0.67971282 | AL24: 55.053184 | AM24: 0.78349396 | AO24: 23.32752 | AP24: 0.58697827 | AR24: 6.3241938 | AS24: 0.42869547 | AU24: 18.436436 | AV24: 0.48267572 | AX24: 44.575791 | AY24: 0.64400025 | BA24: 30.663579 | BB24: 0.59648318 | BD24: 3.3956318 | BE24: 0.26320971 | BG24: 12.223894 | BH24: 0.49068516 | BJ24: 54.10166 | BK24: 0.72826183 | BM24: 30.278814 | BN24: 0.60821095
A25: Colombia | B25: 0.29779172 | C25: 0.01765865 | E25: 0.98767509 | F25: 0.013871157 | H25: 2.5048176 | I25: 0.27022169 | K25: 8.1854416 | L25: 0.40086279 | N25: 70.325015 | O25: 0.81030738 | Q25: 18.984726 | R25: 0.66397186 | T25: 1.5563283 | U25: 0.21356963 | W25: 5.0545993 | X25: 0.3386767 | Z25: 56.42234 | AA25: 0.78789435 | AC25: 36.966733 | AD25: 0.81923763 | AF25: 1.951953 | AG25: 0.23180615 | AI25: 23.400633 | AJ25: 0.79266358 | AL25: 56.178765 | AM25: 0.85550782 | AO25: 18.468649 | AP25: 0.60537313 | AR25: 2.2218159 | AS25: 0.22104039 | AU25: 6.9510214 | AV25: 0.38994296 | AX25: 55.400256 | AY25: 0.85742342 | BA25: 35.426907 | BB25: 0.83267392 | BD25: 1.8030114 | BE25: 0.19800411 | BG25: 8.0630787 | BH25: 0.45026762 | BJ25: 60.73404 | BK25: 0.73873804 | BM25: 29.39987 | BN25: 0.73584232
A26: Czech Republic | B26: -0.27959011 | C26: 0.01265873 | E26: 0.8824418 | F26: 0.012237406 | H26: 2.141574 | I26: 0.27265731 | K26: 6.6169843 | L26: 0.4250862 | N26: 75.000142 | O26: 0.71085122 | Q26: 16.2413 | R26: 0.57180223 | T26: 4.1467873 | U26: 0.30137143 | W26: 25.523847 | X26: 0.57054598 | Z26: 56.304115 | AA26: 0.64297105 | AC26: 14.025251 | AD26: 0.41455629 | AF26: 3.6940265 | AG26: 0.30004433 | AI26: 28.137797 | AJ26: 0.69392582 | AL26: 57.601645 | AM26: 0.76051366 | AO26: 10.566531 | AP26: 0.4240845 | AR26: 8.0483725 | AS26: 0.33243295 | AU26: 29.378858 | AV26: 0.65964615 | AX26: 48.684408 | AY26: 0.72235967 | BA26: 13.888362 | BB26: 0.48597722 | BD26: 2.87984 | BE26: 0.24016774 | BG26: 15.618483 | BH26: 0.49506 | BJ26: 66.843566 | BK26: 0.72123993 | BM26: 14.658111 | BN26: 0.55255807
A27: Denmark | B27: 0.050364812 | C27: 0.015434761 | E27: 0.92254834 | F27: 0.013052558 | H27: 1.6282564 | I27: 0.1962395 | K27: 7.5122246 | L27: 0.43469868 | N27: 69.156185 | O27: 0.71582331 | Q27: 21.703334 | R27: 0.69953613 | T27: 1.3436796 | U27: 0.18733607 | W27: 11.3618 | X27: 0.52737888 | Z27: 65.246948 | AA27: 0.8429147 | AC27: 22.047572 | AD27: 0.72941665 | AF27: 2.3710225 | AG27: 0.26151071 | AI27: 19.942631 | AJ27: 0.5308533 | AL27: 60.028947 | AM27: 0.70576766 | AO27: 17.6574 | AP27: 0.61120593 | AR27: 4.875242 | AS27: 0.32917146 | AU27: 23.798372 | AV27: 0.57727258 | AX27: 52.735447 | AY27: 0.72422455 | BA27: 18.590939 | BB27: 0.60257509 | BD27: 1.2851337 | BE27: 0.16305063 | BG27: 8.7403644 | BH27: 0.45178886 | BJ27: 65.735494 | BK27: 0.7422745 | BM27: 24.239008 | BN27: 0.71656953
A28: Estonia | B28: -0.028236006 | C28: 0.015075036 | E28: 0.94413614 | F28: 0.012214669 | H28: 2.3836489 | I28: 0.22522681 | K28: 5.7229001 | L28: 0.33617965 | N28: 70.152462 | O28: 0.65148985 | Q28: 21.740989 | R28: 0.60611477 | T28: 1.9323474 | U28: 0.19757194 | W28: 13.166339 | X28: 0.51221938 | Z28: 61.564801 | AA28: 0.71123176 | AC28: 23.336512 | AD28: 0.66634122 | AF28: 2.3324627 | AG28: 0.25044619 | AI28: 26.230649 | AJ28: 0.77207181 | AL28: 58.220961 | AM28: 0.81730472 | AO28: 13.215927 | AP28: 0.55276917 | AR28: 5.8142941 | AS28: 0.3892194 | AU28: 22.735819 | AV28: 0.7089475 | AX28: 53.484801 | AY28: 0.79209647 | BA28: 17.965086 | BB28: 0.579236 | BD28: 2.1376048 | BE28: 0.22798512 | BG28: 11.310478 | BH28: 0.45918405 | BJ28: 66.631283 | BK28: 0.73368156 | BM28: 19.920634 | BN28: 0.62376709
A29: Finland | B29: -0.033589725 | C29: 0.015050031 | E29: 0.94733985 | F29: 0.01168246 | H29: 1.5837205 | I29: 0.16562185 | K29: 4.9037379 | L29: 0.28103129 | N29: 68.327861 | O29: 0.74747324 | Q29: 25.18468 | R29: 0.69647748 | T29: 1.879759 | U29: 0.18535392 | W29: 9.2373658 | X29: 0.40742325 | Z29: 61.554169 | AA29: 0.71850071 | AC29: 27.328706 | AD29: 0.68070372 | AF29: 3.8084575 | AG29: 0.24554754 | AI29: 27.882965 | AJ29: 0.73492781 | AL29: 55.895226 | AM29: 0.7379619 | AO29: 12.413351 | AP29: 0.50982604 | AR29: 5.3449852 | AS29: 0.3133208 | AU29: 24.112196 | AV29: 0.61259881 | AX29: 56.351975 | AY29: 0.6884458 | BA29: 14.190843 | BB29: 0.54908945 | BD29: 2.4961591 | BE29: 0.24214459 | BG29: 13.432396 | BH29: 0.5367671 | BJ29: 66.363552 | BK29: 0.66787042 | BM29: 17.707893 | BN29: 0.50488999
A30: France | B30: -0.10217827 | C30: 0.01438554 | E30: 0.99589463 | F30: 0.012076276 | H30: 1.9678354 | I30: 0.22017692 | K30: 5.6004215 | L30: 0.35694696 | N30: 63.299759 | O30: 0.72463263 | Q30: 29.131984 | R30: 0.70699374 | T30: 2.2158074 | U30: 0.19194975 | W30: 11.149439 | X30: 0.43254723 | Z30: 57.946033 | AA30: 0.68792372 | AC30: 28.688721 | AD30: 0.71292949 | AF30: 4.0033233 | AG30: 0.28659852 | AI30: 28.976805 | AJ30: 0.65737112 | AL30: 49.75207 | AM30: 0.72062686 | AO30: 17.267802 | AP30: 0.44489901 | AR30: 13.818555 | AS30: 0.54013276 | AU30: 27.653888 | AV30: 0.61314 | AX30: 39.994325 | AY30: 0.78133111 | BA30: 18.533232 | BB30: 0.51803101 | BD30: 4.0158974 | BE30: 0.28142366 | BG30: 20.496688 | BH30: 0.56650857 | BJ30: 55.413174 | BK30: 0.67336555 | BM30: 20.07424 | BN30: 0.53747709
A31: Germany | B31: -0.02022071 | C31: 0.015029133 | D31: † | E31: 0.95367033 | F31: 0.01637254 | G31: † | H31: 2.9641187 | I31: 0.32029183 | J31: † | K31: 12.24113 | L31: 0.59769902 | M31: † | N31: 66.344174 | O31: 0.89725737 | P31: † | Q31: 18.450576 | R31: 0.59736383 | S31: † | T31: 2.4782516 | U31: 0.28991644 | V31: † | W31: 15.246331 | X31: 0.54119448 | Y31: † | Z31: 51.467535 | AA31: 0.9689193 | AB31: † | AC31: 30.807883 | AD31: 0.82190795 | AE31: † | AF31: 3.3023149 | AG31: 0.28073701 | AH31: † | AI31: 27.443515 | AJ31: 0.6880958 | AK31: † | AL31: 53.700672 | AM31: 0.85021882 | AN31: † | AO31: 15.553498 | AP31: 0.55893772 | AQ31: † | AR31: 6.6862614 | AS31: 0.39006337 | AT31: † | AU31: 24.987678 | AV31: 0.72809824 | AW31: † | AX31: 44.923929 | AY31: 0.93239336 | AZ31: † | BA31: 23.402131 | BB31: 0.74842653 | BC31: † | BD31: 2.4815713 | BE31: 0.25865196 | BF31: † | BG31: 13.022251 | BH31: 0.59769162 | BI31: † | BJ31: 58.398693 | BK31: 0.86837326 | BL31: † | BM31: 26.097485 | BN31: 0.79813431 | BO31: †
A32: Greece | B32: 0.046908181 | C32: 0.016475358 | E32: 0.95335113 | F32: 0.011591818 | H32: 3.4304068 | I32: 0.36612265 | K32: 8.1008561 | L32: 0.39153021 | N32: 70.919041 | O32: 0.73774912 | Q32: 17.549697 | R32: 0.62513001 | T32: 2.5042908 | U32: 0.21088178 | W32: 13.280443 | X32: 0.52293895 | Z32: 57.947424 | AA32: 0.69687531 | AC32: 26.267842 | AD32: 0.63243966 | AF32: 2.3884792 | AG32: 0.26115089 | AI32: 22.726965 | AJ32: 0.65684574 | AL32: 55.834214 | AM32: 0.81553182 | AO32: 19.050342 | AP32: 0.62712744 | AR32: 3.7438489 | AS32: 0.24278462 | AU32: 17.84078 | AV32: 0.48618621 | AX32: 53.650056 | AY32: 0.63076598 | BA32: 24.765315 | BB32: 0.6353778 | BD32: 2.3197092 | BE32: 0.20536855 | BG32: 11.788027 | BH32: 0.53615729 | BJ32: 64.366703 | BK32: 0.7084927 | BM32: 21.525561 | BN32: 0.65264486
A33: Hungary | B33: 0.17362568 | C33: 0.013354649 | E33: 0.94555971 | F33: 0.012327475 | H33: 2.0627099 | I33: 0.27649984 | K33: 6.7284262 | L33: 0.33172397 | N33: 71.40126 | O33: 0.75082365 | Q33: 19.807604 | R33: 0.57366709 | T33: 1.5623362 | U33: 0.20320432 | W33: 7.5944288 | X33: 0.41223013 | Z33: 56.473915 | AA33: 0.64823937 | AC33: 34.36932 | AD33: 0.62927158 | AF33: 2.7503524 | AG33: 0.22528121 | AI33: 23.309078 | AJ33: 0.64627938 | AL33: 55.618636 | AM33: 0.81092904 | AO33: 18.321933 | AP33: 0.59932818 | AR33: 3.569778 | AS33: 0.25088453 | AU33: 16.059513 | AV33: 0.59006896 | AX33: 55.001067 | AY33: 0.6615102 | BA33: 25.369641 | BB33: 0.59135764 | BD33: 2.0913014 | BE33: 0.19805058 | BG33: 8.186547 | BH33: 0.34537622 | BJ33: 62.458105 | BK33: 0.81717233 | BM33: 27.264047 | BN33: 0.72306141
A34: Iceland | B34: 0.10457168 | C34: 0.020267438 | E34: 1.1681931 | F34: 0.017200678 | H34: 2.484458 | I34: 0.28425976 | K34: 6.2977829 | L34: 0.39211966 | N34: 60.201935 | O34: 0.69265516 | Q34: 31.015824 | R34: 0.72975111 | T34: 2.7266997 | U34: 0.27147745 | W34: 14.041027 | X34: 0.58417703 | Z34: 55.439257 | AA34: 0.91386998 | AC34: 27.793016 | AD34: 0.85134258 | AF34: 3.663174 | AG34: 0.3371057 | AI34: 20.756528 | AJ34: 0.65365324 | AL34: 54.460636 | AM34: 0.88723701 | AO34: 21.119662 | AP34: 0.67296463 | AR34: 6.4597743 | AS34: 0.41952545 | AU34: 24.191531 | AV34: 0.80476536 | AX34: 47.808986 | AY34: 1.0023856 | BA34: 21.539709 | BB34: 0.80379331 | BD34: 2.6570976 | BE34: 0.34055504 | BG34: 13.394536 | BH34: 0.57356988 | BJ34: 60.012053 | BK34: 0.81763592 | BM34: 23.936313 | BN34: 0.7106104
A35: Ireland | B35: -0.044074469 | C35: 0.012108059 | E35: 0.87585914 | F35: 0.011966808 | H35: 0.87445259 | I35: 0.11478544 | K35: 5.4326954 | L35: 0.24663032 | N35: 76.807688 | O35: 0.55203728 | Q35: 16.885164 | R35: 0.52607166 | T35: 0.95000286 | U35: 0.1390177 | W35: 8.9628724 | X35: 0.44380162 | Z35: 62.373553 | AA35: 0.73065776 | AC35: 27.713572 | AD35: 0.66269736 | AF35: 3.0204384 | AG35: 0.26960239 | AI35: 24.739375 | AJ35: 0.55132287 | AL35: 58.662411 | AM35: 0.69663619 | AO35: 13.577776 | AP35: 0.44905619 | AR35: 6.0139528 | AS35: 0.36742155 | AU35: 27.854684 | AV35: 0.61941336 | AX35: 50.580998 | AY35: 0.65987687 | BA35: 15.550364 | BB35: 0.57806646 | BD35: 1.9755895 | BE35: 0.19053798 | BG35: 12.551371 | BH35: 0.39904456 | BJ35: 66.584224 | BK35: 0.69411418 | BM35: 18.888815 | BN35: 0.55112281
A36: Israel | B36: 0.16964463 | C36: 0.019791403 | E36: 1.1421438 | F36: 0.012880829 | H36: 6.3648119 | I36: 0.4346486 | K36: 9.4514183 | L36: 0.45760064 | N36: 58.795164 | O36: 0.82252854 | Q36: 25.388606 | R36: 0.70059927 | T36: 3.9082055 | U36: 0.30278521 | W36: 13.880036 | X36: 0.62374013 | Z36: 43.08944 | AA36: 0.70265018 | AC36: 39.122319 | AD36: 0.79093369 | AF36: 6.0078547 | AG36: 0.38113269 | AI36: 25.213236 | AJ36: 0.63578828 | AL36: 46.479766 | AM36: 0.76462194 | AO36: 22.299143 | AP36: 0.56301799 | AR36: 5.0507038 | AS36: 0.29733341 | AU36: 15.390997 | AV36: 0.55430821 | AX36: 45.0737 | AY36: 0.70176467 | BA36: 34.4846 | BB36: 0.69733206 | BD36: 3.942447 | BE36: 0.28173012 | BG36: 11.491281 | BH36: 0.41226365 | BJ36: 54.805605 | BK36: 0.66086351 | BM36: 29.760667 | BN36: 0.67236821
A37: Italy | B37: -0.030853486 | C37: 0.012599343 | E37: 0.94445088 | F37: 0.011848825 | H37: 4.1892303 | I37: 0.29222447 | K37: 11.218604 | L37: 0.46875903 | N37: 66.849081 | O37: 0.71535245 | Q37: 17.743084 | R37: 0.59312267 | T37: 2.5144588 | U37: 0.19700266 | W37: 11.321541 | X37: 0.4239446 | Z37: 58.136554 | AA37: 0.68549894 | AC37: 28.027447 | AD37: 0.65032597 | AF37: 3.4807622 | AG37: 0.24785246 | AI37: 28.720556 | AJ37: 0.62753931 | AL37: 53.801528 | AM37: 0.71098379 | AO37: 13.997154 | AP37: 0.49466804 | AR37: 7.8830378 | AS37: 0.40601968 | AU37: 20.090612 | AV37: 0.52961475 | AX37: 48.64921 | AY37: 0.83303486 | BA37: 23.37714 | BB37: 0.68469831 | BD37: 3.1720143 | BE37: 0.24651111 | BG37: 11.256241 | BH37: 0.43680519 | BJ37: 59.588972 | BK37: 0.65757664 | BM37: 25.982772 | BN37: 0.66247591
A38: Japan | B38: -0.61381946 | C38: 0.014328841 | E38: 0.95278627 | F38: 0.014206953 | H38: 5.0960215 | I38: 0.29953238 | K38: 30.055372 | L38: 0.61620843 | N38: 51.979593 | O38: 0.75829874 | Q38: 12.869013 | R38: 0.45316283 | T38: 5.303839 | U38: 0.32539483 | W38: 25.919057 | X38: 0.55407661 | Z38: 51.482743 | AA38: 0.66171184 | AC38: 17.294362 | AD38: 0.60840107 | AF38: 12.510799 | AG38: 0.43095083 | AI38: 46.064387 | AJ38: 0.66203141 | AL38: 34.718908 | AM38: 0.6390201 | AO38: 6.7059071 | AP38: 0.33537761 | AR38: 9.0638009 | AS38: 0.40953558 | AU38: 34.681009 | AV38: 0.63642775 | AX38: 43.983831 | AY38: 0.74059757 | BA38: 12.271359 | BB38: 0.49495322 | BD38: 6.391026 | BE38: 0.31663675 | BG38: 35.053772 | BH38: 0.64806333 | BJ38: 48.642811 | BK38: 0.73767541 | BM38: 9.9123914 | BN38: 0.4407101
A39: Korea | B39: -0.036204302 | C39: 0.015000535 | E39: 1.0022312 | F39: 0.011941905 | H39: 1.4427787 | I39: 0.17231899 | K39: 12.953045 | L39: 0.4795788 | N39: 69.734604 | O39: 0.56987418 | Q39: 15.869572 | R39: 0.50081328 | T39: 0.9320801 | U39: 0.13096272 | W39: 7.6664388 | X39: 0.39492819 | Z39: 55.442896 | AA39: 0.63579707 | AC39: 35.958585 | AD39: 0.67976399 | AF39: 5.2512463 | AG39: 0.26720609 | AI39: 39.817105 | AJ39: 0.72788164 | AL39: 42.736942 | AM39: 0.78252178 | AO39: 12.194707 | AP39: 0.47557494 | AR39: 3.282234 | AS39: 0.24724807 | AU39: 19.653068 | AV39: 0.5829055 | AX39: 56.58644 | AY39: 0.69004049 | BA39: 20.478259 | BB39: 0.5607854 | BD39: 2.2008992 | BE39: 0.21306039 | BG39: 17.147703 | BH39: 0.55075976 | BJ39: 61.997226 | BK39: 0.68949563 | BM39: 18.654172 | BN39: 0.51825985
A40: Latvia | B40: -0.19181672 | C40: 0.011866624 | E40: 0.86767368 | F40: 0.013360506 | H40: 3.3516267 | I40: 0.26690194 | K40: 14.022177 | L40: 0.47167079 | N40: 70.550224 | O40: 0.67018225 | Q40: 12.075972 | R40: 0.39392607 | T40: 3.1448109 | U40: 0.26849205 | W40: 17.638237 | X40: 0.55330663 | Z40: 59.60946 | AA40: 0.79538935 | AC40: 19.607492 | AD40: 0.59919695 | AF40: 3.2133719 | AG40: 0.2795015 | AI40: 27.279351 | AJ40: 0.6438399 | AL40: 59.044346 | AM40: 0.76614997 | AO40: 10.462931 | AP40: 0.41261526 | AR40: 4.8450299 | AS40: 0.29858974 | AU40: 23.156117 | AV40: 0.6788562 | AX40: 56.62155 | AY40: 0.72402318 | BA40: 15.377304 | BB40: 0.54177975 | BD40: 2.4404975 | BE40: 0.22655507 | BG40: 13.631175 | BH40: 0.54667947 | BJ40: 66.707027 | BK40: 0.75007662 | BM40: 17.2213 | BN40: 0.4973108
A41: Lithuania | B41: 0.23197156 | C41: 0.013951089 | E41: 1.0469495 | F41: 0.012274423 | H41: 3.1777004 | I41: 0.27182162 | K41: 7.2198175 | L41: 0.38987975 | N41: 64.497554 | O41: 0.66895844 | Q41: 25.104928 | R41: 0.60846474 | T41: 2.0471064 | U41: 0.19296697 | W41: 9.4076026 | X41: 0.39489467 | Z41: 44.953027 | AA41: 0.60706097 | AC41: 43.592264 | AD41: 0.61225967 | AF41: 4.3413705 | AG41: 0.26232943 | AI41: 23.675085 | AJ41: 0.60160287 | AL41: 51.11151 | AM41: 0.64875824 | AO41: 20.872035 | AP41: 0.55498279 | AR41: 4.4801734 | AS41: 0.31749724 | AU41: 14.461602 | AV41: 0.54191217 | AX41: 48.957099 | AY41: 0.65274113 | BA41: 32.101126 | BB41: 0.57008556 | BD41: 2.5329293 | BE41: 0.20402131 | BG41: 12.28032 | BH41: 0.48382018 | BJ41: 57.716514 | BK41: 0.72547862 | BM41: 27.470237 | BN41: 0.60598872
A42: Luxembourg | B42: -0.0051981077 | C42: 0.015987346 | E42: 1.0605552 | F42: 0.013007622 | H42: 3.9634659 | I42: 0.2582365 | K42: 9.441434 | L42: 0.4089479 | N42: 62.538136 | O42: 0.75198206 | Q42: 24.056964 | R42: 0.61859508 | T42: 3.2119214 | U42: 0.26014668 | W42: 13.795446 | X42: 0.50581037 | Z42: 53.503191 | AA42: 0.74339254 | AC42: 29.489442 | AD42: 0.63942458 | AF42: 3.6882068 | AG42: 0.26425412 | AI42: 23.530016 | AJ42: 0.60138455 | AL42: 54.36172 | AM42: 0.71442924 | AO42: 18.420058 | AP42: 0.60192341 | AR42: 7.6128588 | AS42: 0.39927944 | AU42: 23.904374 | AV42: 0.65457316 | AX42: 47.099684 | AY42: 0.75042793 | BA42: 21.383083 | BB42: 0.55559459 | BD42: 3.9230418 | BE42: 0.28290363 | BG42: 15.417697 | BH42: 0.47707137 | BJ42: 56.182097 | BK42: 0.82251166 | BM42: 24.477164 | BN42: 0.67649049
A43: Mexico | B43: 0.36081506 | C43: 0.0146747 | D43: † | E43: 1.0162176 | F43: 0.011086358 | G43: † | H43: 1.9157447 | I43: 0.31079629 | J43: † | K43: 6.930539 | L43: 0.38875466 | M43: † | N43: 65.366144 | O43: 0.76787062 | P43: † | Q43: 25.787572 | R43: 0.6767053 | S43: † | T43: 1.1916155 | U43: 0.1605542 | V43: † | W43: 4.1097927 | X43: 0.30631021 | Y43: † | Z43: 52.456627 | AA43: 0.7607872 | AB43: † | AC43: 42.241965 | AD43: 0.77078916 | AE43: † | AF43: 1.8303819 | AG43: 0.19123684 | AH43: † | AI43: 20.488677 | AJ43: 0.62566077 | AK43: † | AL43: 56.843252 | AM43: 0.7895916 | AN43: † | AO43: 20.837689 | AP43: 0.63718682 | AQ43: † | AR43: 2.6515846 | AS43: 0.22477646 | AT43: † | AU43: 11.582573 | AV43: 0.4452879 | AW43: † | AX43: 52.976559 | AY43: 0.6989653 | AZ43: † | BA43: 32.789284 | BB43: 0.68378213 | BC43: † | BD43: 1.8855951 | BE43: 0.18401324 | BF43: † | BG43: 9.0441475 | BH43: 0.46125156 | BI43: † | BJ43: 56.864091 | BK43: 0.72380979 | BL43: † | BM43: 32.206166 | BN43: 0.66909847 | BO43: †
A44: Netherlands* | B44: -0.11302529 | C44: 0.016987893 | E44: 0.84274423 | F44: 0.01627351 | H44: 1.2481415 | I44: 0.21527239 | K44: 8.7305407 | L44: 0.46511388 | N44: 73.558887 | O44: 0.79115705 | Q44: 16.462431 | R44: 0.63011925 | T44: 1.1958234 | U44: 0.18344852 | W44: 10.060388 | X44: 0.51599844 | Z44: 66.597603 | AA44: 0.9611741 | AC44: 22.146185 | AD44: 0.87115852 | AF44: 3.0283551 | AG44: 0.3005636 | AI44: 31.277378 | AJ44: 0.79090203 | AL44: 54.965249 | AM44: 1.0096148 | AO44: 10.729018 | AP44: 0.68503989 | AR44: 5.1165303 | AS44: 0.34688931 | AU44: 25.801032 | AV44: 0.80237482 | AX44: 55.381955 | AY44: 0.91912989 | BA44: 13.700483 | BB44: 0.70538167 | BD44: 1.7677058 | BE44: 0.22851797 | BG44: 10.619655 | BH44: 0.61766229 | BJ44: 70.024927 | BK44: 0.86099969 | BM44: 17.587712 | BN44: 0.64332996
...

Sheet Table III.B1.13.2
A1: PISA 2018 Results (Volume III) - © OECD 2019
A2: Annex B1 | B2: Annex B1.13 Results (tables): Students' self-efficacy and fear of failure
A3: Version 2 - Last updated: 24-Jul-2020
A4: Disclaimer: http://oe.cd/disclaimer
A6: Annex B1 | B6: Annex B1.13 Results (tables): Students' self-efficacy and fear of failure
A7: Version 2 - Last updated: 02-Dec-2019
A8: Disclaimer: http://oe.cd/disclaimer
A10: Table III.B1.13.2
A11: Students' fear of failure
A12: Based on students' reports
B15: Index of fear of failure1 | H15: Percentage of students who reported the following:
H16: When I am failing, I worry about what others think of me | T16: When I am failing, I am afraid that I might not have enough talent | AF16: When I am failing, this makes me doubt my plans for the future
B17: Average | E17: Variability | H17: Strongly disagree | K17: Disagree | N17: Agree | Q17: Strongly agree | T17: Strongly disagree | W17: Disagree | Z17: Agree | AC17: Strongly agree | AF17: Strongly disagree | AI17: Disagree | AL17: Agree | AO17: Strongly agree
B18: Mean index | C18: S.E. | E18: S.D. | F18: S.E. | H18: % | I18: S.E. | K18: % | L18: S.E. | N18: % | O18: S.E. | Q18: % | R18: S.E. | T18: % | U18: S.E. | W18: % | X18: S.E. | Z18: % | AA18: S.E. | AC18: % | AD18: S.E. | AF18: % | AG18: S.E. | AI18: % | AJ18: S.E. | AL18: % | AM18: S.E. | AO18: % | AP18: S.E.
A19: OECD
A20: Australia | B20: 0.23229905 | C20: 0.0096878794 | E20: 1.0038961 | F20: 0.0067099588 | H20: 11.803457 | I20: 0.31793968 | K20: 26.550725 | L20: 0.47840175 | N20: 41.434108 | O20: 0.48399444 | Q20: 20.211709 | R20: 0.37287852 | T20: 9.6466772 | U20: 0.2977983 | W20: 26.609396 | X20: 0.46522257 | Z20: 42.43288 | AA20: 0.49097593 | AC20: 21.311047 | AD20: 0.36258759 | AF20: 9.4654778 | AG20: 0.30767512 | AI20: 22.595597 | AJ20: 0.47690674 | AL20: 40.701463 | AM20: 0.44428687 | AO20: 27.237462 | AP20: 0.40372735
A21: Austria | B21: -0.25980957 | C21: 0.014803103 | E21: 1.050622 | F21: 0.008889925 | H21: 18.943757 | I21: 0.61773919 | K21: 29.637735 | L21: 0.64709837 | N21: 33.62136 | O21: 0.64561746 | Q21: 17.797147 | R21: 0.52090018 | T21: 23.083427 | U21: 0.61135987 | W21: 33.468062 | X21: 0.65097872 | Z21: 29.355324 | AA21: 0.6771301 | AC21: 14.093187 | AD21: 0.43441002 | AF21: 28.926273 | AG21: 0.64298218 | AI21: 30.342577 | AJ21: 0.641702 | AL21: 26.771119 | AM21: 0.67103794 | AO21: 13.96003 | AP21: 0.44760578
A22: Belgium (Flemish) | B22: -0.19157854 | C22: 0.016591179 | E22: 0.89387001 | F22: 0.011080352 | H22: 15.919749 | I22: 0.62989416 | K22: 36.971318 | L22: 0.74569327 | N22: 36.889361 | O22: 0.76615212 | Q22: 10.219572 | R22: 0.45865123 | T22: 15.412319 | U22: 0.62896023 | W22: 40.324498 | X22: 0.85571505 | Z22: 34.744355 | AA22: 0.82177932 | AC22: 9.5188287 | AD22: 0.55175796 | AF22: 13.181548 | AG22: 0.55773045 | AI22: 34.162552 | AJ22: 0.67485293 | AL22: 39.286781 | AM22: 0.77000174 | AO22: 13.369118 | AP22: 0.57073129
A23: Canada | B23: 0.27240935 | C23: 0.010925187 | E23: 1.0408883 | F23: 0.0065744893 | H23: 13.454367 | I23: 0.3879788 | K23: 24.737197 | L23: 0.42414884 | N23: 39.605385 | O23: 0.55083436 | Q23: 22.20305 | R23: 0.44260901 | T23: 10.795772 | U23: 0.30719863 | W23: 23.780644 | X23: 0.4848829 | Z23: 40.909922 | AA23: 0.54313379 | AC23: 24.513662 | AD23: 0.42662876 | AF23: 10.85889 | AG23: 0.31870047 | AI23: 20.687435 | AJ23: 0.52095999 | AL23: 37.272934 | AM23: 0.44001596 | AO23: 31.18074 | AP23: 0.46283059
A24: Chile | B24: 0.084430888 | C24: 0.014684018 | E24: 0.99884825 | F24: 0.0099608423 | H24: 20.322911 | I24: 0.61702767 | K24: 28.393103 | L24: 0.56365439 | N24: 35.256181 | O24: 0.68449682 | Q24: 16.027806 | R24: 0.55798432 | T24: 12.072966 | U24: 0.46633205 | W24: 24.336289 | X24: 0.51173378 | Z24: 43.066 | AA24: 0.71323847 | AC24: 20.524745 | AD24: 0.61713749 | AF24: 17.214537 | AG24: 0.53985558 | AI24: 23.614192 | AJ24: 0.57766763 | AL24: 35.316174 | AM24: 0.57903303 | AO24: 23.855097 | AP24: 0.70561968
A25: Colombia | B25: -0.19415028 | C25: 0.013330394 | E25: 0.94044848 | F25: 0.0084640358 | H25: 17.096868 | I25: 0.5388127 | K25: 34.542785 | L25: 0.71451999 | N25: 38.249359 | O25: 0.7182557 | Q25: 10.110988 | R25: 0.36676027 | T25: 15.199443 | U25: 0.49051644 | W25: 33.953197 | X25: 0.75547916 | Z25: 39.540179 | AA25: 0.74746657 | AC25: 11.307182 | AD25: 0.42271747 | AF25: 20.487604 | AG25: 0.66191281 | AI25: 36.004412 | AJ25: 0.85319102 | AL25: 31.844014 | AM25: 0.81998794 | AO25: 11.663969 | AP25: 0.44318624
A26: Czech Republic | B26: -0.045775045 | C26: 0.014980797 | E26: 0.9092499 | F26: 0.0095703152 | H26: 12.166626 | I26: 0.52563952 | K26: 29.18431 | L26: 0.72709027 | N26: 44.415852 | O26: 0.84160733 | Q26: 14.233212 | R26: 0.55229673 | T26: 11.72501 | U26: 0.43254684 | W26: 36.772307 | X26: 0.70418975 | Z26: 39.758571 | AA26: 0.70422595 | AC26: 11.744111 | AD26: 0.44948572 | AF26: 13.455808 | AG26: 0.5245059 | AI26: 32.019483 | AJ26: 0.69137113 | AL26: 38.926691 | AM26: 0.73917789 | AO26: 15.598018 | AP26: 0.59149757
A27: Denmark | B27: -0.016519313 | C27: 0.01166113 | E27: 0.91101216 | F27: 0.010389548 | H27: 10.73302 | I27: 0.42200936 | K27: 31.014883 | L27: 0.72346292 | N27: 44.19766 | O27: 0.81619646 | Q27: 14.054437 | R27: 0.51561115 | T27: 9.688828 | U27: 0.40657133 | W27: 32.517586 | X27: 0.71978163 | Z27: 43.963529 | AA27: 0.88670629 | AC27: 13.830057 | AD27: 0.47068271 | AF27: 15.86483 | AG27: 0.58405284 | AI27: 37.147298 | AJ27: 0.75167319 | AL27: 32.872674 | AM27: 0.70985684 | AO27: 14.115199 | AP27: 0.5066289
A28: Estonia | B28: -0.17345962 | C28: 0.014530711 | E28: 0.91434187 | F28: 0.010287953 | H28: 14.717519 | I28: 0.57984225 | K28: 38.893368 | L28: 0.7595652 | N28: 36.571607 | O28: 0.69628017 | Q28: 9.8175052 | R28: 0.46967806 | T28: 12.988536 | U28: 0.49702867 | W28: 38.537059 | X28: 0.84435861 | Z28: 37.251101 | AA28: 0.75432027 | AC28: 11.223304 | AD28: 0.48703298 | AF28: 16.100521 | AG28: 0.60242404 | AI28: 38.722278 | AJ28: 0.76067036 | AL28: 33.146856 | AM28: 0.81060926 | AO28: 12.030345 | AP28: 0.53741847
A29: Finland | B29: -0.19242 | C29: 0.011428239 | E29: 0.9556142 | F29: 0.0086248965 | H29: 13.213189 | I29: 0.48612681 | K29: 36.429218 | L29: 0.69767145 | N29: 38.32274 | O29: 0.65461961 | Q29: 12.034852 | R29: 0.47109991 | T29: 14.667636 | U29: 0.45014215 | W29: 40.373949 | X29: 0.65726809 | Z29: 33.221298 | AA29: 0.64112022 | AC29: 11.737117 | AD29: 0.42825062 | AF29: 17.479274 | AG29: 0.46018181 | AI29: 41.117309 | AJ29: 0.72892834 | AL29: 29.508177 | AM29: 0.5457323 | AO29: 11.895239 | AP29: 0.42010107
A30: France | B30: 0.059087179 | C30: 0.01468641 | E30: 1.0569129 | F30: 0.0099957113 | H30: 25.857809 | I30: 0.72793814 | K30: 26.651749 | L30: 0.5588779 | N30: 31.188766 | O30: 0.72563799 | Q30: 16.301676 | R30: 0.51661944 | T30: 15.353742 | U30: 0.50031339 | W30: 22.814903 | X30: 0.55620503 | Z30: 40.517002 | AA30: 0.63309152 | AC30: 21.314353 | AD30: 0.59141781 | AF30: 15.546267 | AG30: 0.50754364 | AI30: 22.251413 | AJ30: 0.62842189 | AL30: 36.483559 | AM30: 0.61462305 | AO30: 25.718761 | AP30: 0.63502775
A31: Germany | B31: -0.37427442 | C31: 0.0180551 | E31: 1.0183801 | F31: 0.011451342 | H31: 20.053878 | I31: 0.8431494 | K31: 32.348282 | L31: 0.68756343 | N31: 33.009841 | O31: 0.71736649 | Q31: 14.587999 | R31: 0.55420455 | T31: 26.967061 | U31: 0.71958733 | W31: 35.270181 | X31: 0.79961119 | Z31: 26.73849 | AA31: 0.60919188 | AC31: 11.024268 | AD31: 0.52694696 | AF31: 29.145877 | AG31: 0.741584 | AI31: 33.415358 | AJ31: 0.86154025 | AL31: 24.858745 | AM31: 0.65351813 | AO31: 12.58002 | AP31: 0.57107347
... A35: Ireland | B35: 0.20648534 | C35: 0.012770212 | E35: 0.98480207 | F35: 0.0078243814 | H35: 9.9065245 | I35: 0.35528986 | K35: 26.435265 | L35: 0.6105998 | N35: 43.483329 | O35: 0.74981311 | Q35: 20.174881 | R35: 0.57007462 | T35: 9.3168838 | U35: 0.3796065 | W35: 28.039598 | X35: 0.69948348 | Z35: 43.001926 | AA35: 0.62747865 | AC35: 19.641593 | AD35: 0.5205573 | AF35: 9.8007084 | AG35: 0.38184025 | AI35: 25.288565 | AJ35: 0.58185342 | AL35: 40.173667 | AM35: 0.60456506 | AO35: 24.73706 | AP35: 0.55007287
A36: Israel | B36: m | C36: m | E36: m | F36: m | H36: m | I36: m | K36: m | L36: m | N36: m | O36: m | Q36: m | R36: m | T36: m | U36: m | W36: m | X36: m | Z36: m | AA36: m | AC36: m | AD36: m | AF36: m | AG36: m | AI36: m | AJ36: m | AL36: m | AM36: m | AO36: m | AP36: m
A37: Italy | B37: 0.038334486 | C37: 0.015846573 | E37: 0.96696901 | F37: 0.009279689 | H37: 16.301488 | I37: 0.50397937 | K37: 26.762261 | L37: 0.70816034 | N37: 40.765176 | O37: 0.67892114 | Q37: 16.171075 | R37: 0.51063972 | T37: 12.631151 | U37: 0.44314993 | W37: 28.744887 | X37: 0.72920562 | Z37: 41.568066 | AA37: 0.69583425 | AC37: 17.055896 | AD37: 0.56734849 | AF37: 14.341252 | AG37: 0.53718711 | AI37: 28.247356 | AJ37: 0.55085608 | AL37: 37.903316 | AM37: 0.71525643 | AO37: 19.508077 | AP37: 0.62996324
A38: Japan | B38: 0.37930291 | C38: 0.014998334 | E38: 0.95613776 | F38: 0.0084388135 | H38: 6.9637091 | I38: 0.38843786 | K38: 16.417074 | L38: 0.54305806 | N38: 47.554638 | O38: 0.68373445 | Q38: 29.064579 | R38: 0.6165603 | T38: 7.1508244 | U38: 0.38958113 | W38: 18.816035 | X38: 0.60539225 | Z38: 46.513112 | AA38: 0.65804557 | AC38: 27.520029 | AD38: 0.64317674 | AF38: 10.989597 | AG38: 0.44312465 | AI38: 28.133202 | AJ38: 0.68474578 | AL38: 39.218493 | AM38: 0.72104578 | AO38: 21.658709 | AP38: 0.58823212
A39: Korea | B39: 0.18566831 | C39: 0.014495243 | E39: 0.96348033 | F39: 0.0084372758 | H39: 7.0200652 | I39: 0.29470544 | K39: 18.005832 | L39: 0.52435554 | N39: 52.079964 | O39: 0.73822867 | Q39: 22.894138 | R39: 0.6727556 | T39: 9.7753236 | U39: 0.42485781 | W39: 23.815263 | X39: 0.54542118 | Z39: 47.076374 | AA39: 0.6914581 | AC39: 19.33304 | AD39: 0.61971751 | AF39: 14.143471 | AG39: 0.45223013 | AI39: 32.327406 | AJ39: 0.62999673 | AL39: 37.520458 | AM39: 0.65952666 | AO39: 16.008665 | AP39: 0.50233017
A40: Latvia | B40: -0.10366924 | C40: 0.012693906 | E40: 0.88686744 | F40: 0.009284561 | H40: 11.942754 | I40: 0.48197618 | K40: 33.315966 | L40: 0.64683561 | N40: 42.657226 | O40: 0.73671558 | Q40: 12.084054 | R40: 0.50580504 | T40: 12.08492 | U40: 0.49798371 | W40: 38.151916 | X40: 0.75590203 | Z40: 38.216744 | AA40: 0.72938575 | AC40: 11.546421 | AD40: 0.51509507 | AF40: 14.33131 | AG40: 0.46664214 | AI40: 36.534136 | AJ40: 0.75197675 | AL40: 35.937896 | AM40: 0.64416014 | AO40: 13.196659 | AP40: 0.49278635
A41: Lithuania | B41: -0.071558232 | C41: 0.013997853 | E41: 1.0295511 | F41: 0.0080414114 | H41: 16.947469 | I41: 0.52859747 | K41: 21.404597 | L41: 0.57447103 | N41: 40.13685 | O41: 0.64100998 | Q41: 21.511084 | R41: 0.56560924 | T41: 17.95689 | U41: 0.50325088 | W41: 29.312392 | X41: 0.68926423 | Z41: 37.360676 | AA41: 0.65697925 | AC41: 15.370042 | AD41: 0.4860898 | AF41: 23.341016 | AG41: 0.61014291 | AI41: 26.790044 | AJ41: 0.61031635 | AL41: 32.452886 | AM41: 0.73993198 | AO41: 17.416054 | AP41: 0.50001698
A42: Luxembourg | B42: -0.14100757 | C42: 0.015880179 | E42: 1.0570931 | F42: 0.010059249 | H42: 23.035988 | I42: 0.60821324 | K42: 27.307972 | L42: 0.62479796 | N42: 33.413806 | O42: 0.63786747 | Q42: 16.242234 | R42: 0.55048679 | T42: 20.956046 | U42: 0.60020024 | W42: 29.978975 | X42: 0.69314705 | Z42: 33.03467 | AA42: 0.63548301 | AC42: 16.03031 | AD42: 0.57069038 | AF42: 20.430229 | AG42: 0.55195512 | AI42: 25.937455 | AJ42: 0.61178175 | AL42: 34.659392 | AM42: 0.74332387 | AO42: 18.972924 | AP42: 0.64021378
A43: Mexico | B43: 0.062019913 | C43: 0.016003699 | E43: 0.94820353 | F43: 0.0081433061 | H43: 16.030936 | I43: 0.61615452 | K43: 30.156055 | L43: 0.77986236 | N43: 39.420311 | O43: 0.719808 | Q43: 14.392697 | R43: 0.48987446 | T43: 10.309088 | U43: 0.50242935 | W43: 26.876592 | X43: 0.71220656 | Z43: 45.326556 | AA43: 0.68653042 | AC43: 17.487764 | AD43: 0.53384154 | AF43: 15.490595 | AG43: 0.58695121 | AI43: 27.326782 | AJ43: 0.61044226 | AL43: 38.547554 | AM43: 0.61922558 | AO43: 18.63507 | AP43: 0.61268531
A44: Netherlands* | B44: -0.39469159 | C44: 0.015530625 | E44: 0.91241908 | F44: 0.012949683 | H44: 18.784404 | I44: 0.70861507 | K44: 36.279991 | L44: 0.84617003 | N44: 34.434278 | O44: 0.80571522 | Q44: 10.501327 | R44: 0.45971296 | T44: 21.415015 | U44: 0.82574219 | W44: 43.159428 | X44: 0.91247921 | Z44: 27.43868 | AA44: 0.71380874 | AC44: 7.9868775 | AD44: 0.39775503 | AF44: 22.443754 | AG44: 0.71623639 | AI44: 41.893278 | AJ44: 1.0253188 | AL44: 27.09772 | AM44: 0.71759802 | AO44: 8.5652482 | AP44: 0.50564501
A45: New Zealand | B45: 0.24532442 | C45: 0.014285319 | E45: 1.0140315 | F45: 0.0081445068 | H45: 11.01365 | I45: 0.39464942 | K45: 24.380925 | L45: 0.6381211 | N45: 42.137063 | O45: 0.64727115 | Q45: 22.468361 | R45: 0.51429178 | T45: 10.271918 | U45: 0.47079228 | W45: 27.189041 | X45: 0.59169631 | Z45: 41.237041 | AA45: 0.6586614 | AC45: 21.302 | AD45: 0.49889089 | AF45: 9.5745059 | AG45: 0.38796492 | AI45: 22.880475 | AJ45: 0.66568964 | AL45: 38.482514 | AM45: 0.71858503 | AO45: 29.062505 | AP45: 0.67613848
A46: Norway | B46: m | C46: m | E46: m | F46: m | H46: m | I46: m | K46: m | L46: m | N46: m | O46: m | Q46: m | R46: m | T46: m | U46: m | W46: m | X46: m | Z46: m | AA46: m | AC46: m | AD46: m | AF46: m | AG46: m | AI46: m | AJ46: m | AL46: m | AM46: m | AO46: m | AP46: m
A47: Poland | B47: 0.01326819 | C47: 0.015209123 | E47: 0.90759421 | F47: 0.0093948243 | H47: 13.756837 | I47: 0.50649915 | K47: 32.731618 | L47: 0.69383047 | N47: 40.254212 | O47: 0.69621545 | Q47: 13.257333 | R47: 0.49083495 | T47: 10.219884 | U47: 0.42259707 | W47: 32.672157 | X47: 0.69544621 | Z47: 43.524619 | AA47: 0.74185543 | AC47: 13.58334 | AD47: 0.56415891 | AF47: 11.226686 | AG47: 0.42669346 | AI47: 30.827536 | AJ47: 0.7425101 | AL47: 40.670168 | AM47: 0.72808231 | AO47: 17.275609 | AP47: 0.61576354
...

Sheet Table III.B1.13.3
A1: PISA 2018 Results (Volume III) - © OECD 2019
A2: Annex B1 | B2: Annex B1.13 Results (tables): Students' self-efficacy and fear of failure
A3: Version 2 - Last updated: 24-Jul-2020
A4: Disclaimer: http://oe.cd/disclaimer
A6: Annex B1 | B6: Annex B1.13 Results (tables): Students' self-efficacy and fear of failure
A7: Version 2 - Last updated: 02-Dec-2019
A8: Disclaimer: http://oe.cd/disclaimer
A10: Table III.B1.13.3
A11: Prevalence of self-efficacy in schools
A12: Based on students' reports
B15: Percentage of students who agreed or strongly agreed that they usually manage one way or another | E15: Percentage of students who are in schools where…
E16: Over 90% of students agreed or strongly agreed that they usually manage one way or another | H16: Between 75% and 90% of students agreed or strongly agreed that they usually manage one way or another | K16: Between 25% and 75% of students agreed or strongly agreed that they usually manage one way or another | N16: Between 10% and 25% of students agreed or strongly agreed that they usually manage one way or another | Q16: 10% of students or less agreed or strongly agreed that they usually manage one way or another
B18: % | C18: S.E. | E18: % | F18: S.E. | H18: % | I18: S.E. | K18: % | L18: S.E. | N18: % | O18: S.E. | Q18: % | R18: S.E.
A19: OECD
A20: Australia | B20: 93.25563 | C20: 0.27678397 | E20: 73.650399 | F20: 1.7991016 | H20: 24.092609 | I20: 1.644526 | K20: 2.2301144 | L20: 0.57313745 | N20: 0 | O20: c | Q20: 0.026877324 | R20: 0.028104593
A21: Austria | B21: 84.522717 | C21: 0.59887273 | E21: 37.277897 | F21: 3.1917009 | H21: 45.175556 | I21: 3.2293271 | K21: 17.323552 | L21: 2.2191731 | N21: 0 | O21: c | Q21: 0.2229953 | R21: 0.23695255
A22: Belgium (Flemish) | B22: 88.879725 | C22: 0.48927732 | E22: 46.36222 | F22: 4.1971154 | H22: 50.347669 | I22: 4.068609 | K22: 3.2901107 | L22: 1.3334179 | N22: 0 | O22: c | Q22: 0 | R22: c
A23: Canada | B23: 93.062564 | C23: 0.26805973 | E23: 77.075249 | F23: 2.2028703 | H23: 22.085242 | I23: 2.2019128 | K23: 0.80895059 | L23: 0.36545542 | N23: 0 | O23: c | Q23: 0.030557841 | R23: 0.01686549
A24: Chile | B24: 92.21506 | C24: 0.42552889 | E24: 71.544346 | F24: 3.3742746 | H24: 25.505779 | I24: 3.1830829 | K24: 2.8147816 | L24: 0.98876797 | N24: 0 | O24: c | Q24: 0.13509348 | R24: 0.081451331
A25: Colombia | B25: 89.309741 | C25: 0.52570287 | E25: 49.630572 | F25: 3.868346 | H25: 46.152618 | I25: 3.7472841 | K25: 4.2168097 | L25: 1.3200051 | N25: 0 | O25: c | Q25: 0 | R25: c
A26: Czech Republic | B26: 91.241442 | C26: 0.53542652 | E26: 67.040902 | F26: 3.1522228 | H26: 26.828191 | I26: 3.0366624 | K26: 6.1309077 | L26: 1.3111121 | N26: 0 | O26: c | Q26: 0 | R26: c
A27: Denmark | B27: 90.859519 | C27: 0.45911757 | E27: 58.619949 | F27: 3.1814424 | H27: 38.947935 | I27: 3.1405598 | K27: 2.4321155 | L27: 0.81475938 | N27: 0 | O27: c | Q27: 0 | R27: c
A28: Estonia | B28: 91.893451 | C28: 0.40181841 | E28: 70.739692 | F28: 1.8169594 | H28: 23.206409 | I28: 1.7174074 | K28: 6.0538994 | L28: 0.8965578 | N28: 0 | O28: c | Q28: 0 | R28: c
A29: Finland | B29: 93.512542 | C29: 0.32709544 | E29: 74.426993 | F29: 2.875703 | H29: 25.573007 | I29: 2.875703 | K29: 0 | L29: c | N29: 0 | O29: c | Q29: 0 | R29: c
A30: France | B30: 92.431743 | C30: 0.45681833 | E30: 72.328115 | F30: 2.866885 | H30: 24.147971 | I30: 2.8221232 | K30: 3.5239135 | L30: 1.179837 | N30: 0 | O30: c | Q30: 0 | R30: c
A31: Germany | B31: 84.794751 | C31: 0.7244875 | D31: † | E31: 32.444623 | F31: 3.3565074 | H31: 45.32036 | I31: 4.1006836 | K31: 22.235017 | L31: 3.2758742 | N31: 0 | O31: c | Q31: 0 | R31: c
A32: Greece | B32: 88.468737 | C32: 0.58990527 | E32: 50.958984 | F32: 3.7263199 | H32: 40.291004 | I32: 3.7491722 | K32: 8.5213634 | L32: 1.9382856 | N32: 0 | O32: c | Q32: 0.2286479 | R32: 0.12777679
A33: Hungary | B33: 91.208864 | C33: 0.44166686 | E33: 65.160405 | F33: 3.2770085 | H33: 31.196195 | I33: 3.4671122 | K33: 3.4733928 | L33: 1.0074962 | N33: 0 | O33: c | Q33: 0.17000715 | R33: 0.12801805
A34: Iceland | B34: 91.217759 | C34: 0.48106881 | E34: 61.791775 | F34: 0.20161752 | H34: 34.770536 | I34: 0.18071845 | K34: 3.4376891 | L34: 0.10201251 | N34: 0 | O34: c | Q34: 0 | R34: c
A35: Ireland | B35: 93.692852 | C35: 0.28079391 | E35: 81.430483 | F35: 2.9043898 | H35: 18.569517 | I35: 2.9043898 | K35: 0 | L35: c | N35: 0 | O35: c | Q35: 0 | R35: c
A36: Israel | B36: 84.18377 | C36: 0.71502871 | E36: 33.978007 | F36: 3.6562162 | H36: 41.68934 | I36: 3.8761731 | K36: 23.494559 | L36: 2.5365612 | N36: 0.45870439 | O36: 0.44796989 | Q36: 0.37939005 | R36: 0.39096584
A37: Italy | B37: 84.592166 | C37: 0.5290972 | E37: 33.409027 | F37: 2.891555 | H37: 50.271755 | I37: 2.9486819 | K37: 16.297168 | L37: 1.9447089 | N37: 0.014932502 | O37: 0.019734111 | Q37: 0.007117466 | R37: 0.0071088369
A38: Japan | B38: 64.848607 | C38: 0.68532147 | E38: 0 | F38: c | H38: 11.694324 | I38: 2.2062635 | K38: 88.238374 | L38: 2.225486 | N38: 0.0673018 | O38: 0.067058458 | Q38: 0 | R38: c
A39: Korea | B39: 85.604176 | C39: 0.52970587 | E39: 21.283964 | F39: 3.2271647 | H39: 72.18224 | I39: 3.3310194 | K39: 6.5337953 | L39: 1.9268038 | N39: 0 | O39: c | Q39: 0 | R39: c
A40: Latvia | B40: 82.626196 | C40: 0.58377805 | E40: 21.435404 | F40: 1.6380724 | H40: 59.704656 | I40: 1.8503208 | K40: 18.378713 | L40: 1.6711717 | N40: 0.12901826 | O40: 0.1313157 | Q40: 0.35220911 | R40: 0.13432117
A41: Lithuania | B41: 89.602482 | C41: 0.43312557 | E41: 55.572026 | F41: 1.9622495 | H41: 37.467838 | I41: 1.9265611 | K41: 6.7508938 | L41: 1.0281112 | N41: 0 | O41: c | Q41: 0.20924215 | R41: 0.12724714
A42: Luxembourg | B42: 86.5951 | C42: 0.48071655 | E42: 31.750726 | F42: 0.065855562 | H42: 66.629808 | I42: 0.065113578 | K42: 1.6194656 | L42: 0.02720491 | N42: 0 | O42: c | Q42: 0 | R42: c
A43: Mexico | B43: 91.153716 | C43: 0.50307108 | D43: † | E43: 64.18476 | F43: 3.0454977 | H43: 31.831565 | I43: 3.0799012 | K43: 3.2529299 | L43: 0.89727131 | N43: 0 | O43: c | Q43: 0.73074492 | R43: 0.66824998
A44: Netherlands* | B44: 90.021318 | C44: 0.51412132 | E44: 55.838864 | F44: 3.9489908 | H44: 39.526554 | I44: 4.0407134 | K44: 4.6345815 | L44: 1.3507401 | N44: 0 | O44: c | Q44: 0 | R44: c
A45: New Zealand | B45: 93.543426 | C45: 0.34997887 | E45: 78.264069 | F45: 2.7660623 | H45: 20.524032 | I45: 2.6962997 | K45: 1.2118988 | L45: 0.69378224 | N45: 0 | O45: c | Q45: 0 | R45: c
...

Sheet Table III.B1.13.4
A1: PISA 2018 Results (Volume III) - © OECD 2019
A2: Annex B1 | B2: Annex B1.13 Results (tables): Students' self-efficacy and fear of failure
A3: Version 2 - Last updated: 24-Jul-2020
A4: Disclaimer: http://oe.cd/disclaimer
A6: Annex B1 | B6: Annex B1.13 Results (tables): Students' self-efficacy and fear of failure
A7: Version 2 - Last updated: 02-Dec-2019
A8: Disclaimer: http://oe.cd/disclaimer
A10: Table III.B1.13.4
A11: Prevalence of fear of failure in schools
A12: Based on students' reports
B15: Percentage of students who agreed or strongly agreed that they worry about what others think of them when they fail | E15: Percentage of students who are in schools where…
E16: Over 90% of students agreed or strongly agreed that they worry about what others think of them when they fail | H16: Between 75% and 90% of students agreed or strongly agreed that they worry about what others think of them when they fail | K16: Between 25% and 75% of students agreed or strongly agreed that they worry about what others think of them when they fail | N16: Between 10% and 25% of students agreed or strongly agreed that they worry about what others think of them when they fail | Q16: 10% of students or less agreed or strongly agreed that they worry about what others think of them when they fail
B18: % | C18: S.E. | E18: % | F18: S.E. | H18: % | I18: S.E. | K18: % | L18: S.E. | N18: % | O18: S.E. | Q18: % | R18: S.E.
A19: OECD
A20: Australia | B20: 61.645817 | C20: 0.51581294 | E20: 2.8930126 | F20: 0.6853011 | H20: 12.65259 | I20: 1.2835698 | K20: 83.227524 | L20: 1.4824402 | N20: 0.67356271 | O20: 0.34338995 | Q20: 0.55331095 | R20: 0.20732757
A21: Austria | B21: 51.418507 | C21: 0.75826939 | E21: 0.54489925 | F21: 0.20681062 | H21: 1.1634212 | I21: 0.65287292 | K21: 96.788808 | L21: 0.77333282 | N21: 0.84435654 | O21: 0.37894654 | Q21: 0.65851527 | R21: 0.33068987
A22: Belgium (Flemish) | B22: 47.108934 | C22: 0.86420462 | E22: 0.0075962734 | F22: 0.0055535155 | H22: 1.5892441 | I22: 1.2043247 | K22: 98.088351 | L22: 1.2204154 | N22: 0.13345154 | O22: 0.13371385 | Q22: 0.18135707 | R22: 0.10202358
A23: Canada | B23: 61.808435 | C23: 0.54292931 | E23: 0.95179119 | F23: 0.54924845 | H23: 11.70995 | I23: 1.6340155 | K23: 86.712527 | L23: 1.8009656 | N23: 0.5397455 | O23: 0.44316137 | Q23: 0.085986539 | R23: 0.036177733
A24: Chile | B24: 51.283987 | C24: 0.78480889 | E24: 0.98944696 | F24: 0.40419617 | H24: 0.039335309 | I24: 0.055786523 | K24: 97.282648 | L24: 0.84545962 | N24: 0.53951305 | O24: 0.4069998 | Q24: 1.1490566 | R24: 0.6085279
A25: Colombia | B25: 48.360348 | C25: 0.72104071 | E25: 0.59910429 | F25: 0.47308321 | H25: 1.3421681 | I25: 0.82477281 | K25: 96.054685 | L25: 1.1958248 | N25: 1.8800997 | O25: 0.70623715 | Q25: 0.1239432 | R25: 0.1313651
A26: Czech Republic | B26: 58.649064 | C26: 0.88393857 | E26: 1.7407336 | F26: 0.68816917 | H26: 6.234192 | I26: 1.2685811 | K26: 90.480895 | L26: 1.2471546 | N26: 1.2016687 | O26: 0.6378277 | Q26: 0.34251035 | R26: 0.3626834
A27: Denmark | B27: 58.252096 | C27: 0.76279709 | E27: 0.47539506 | F27: 0.31905151 | H27: 8.7153199 | I27: 1.6877895 | K27: 90.006092 | L27: 1.7556484 | N27: 0.64572742 | O27: 0.3784877 | Q27: 0.15746579 | R27: 0.10850891
A28: Estonia | B28: 46.389112 | C28: 0.75549846 | E28: 0.31077219 | F28: 0.14667171 | H28: 1.6158532 | I28: 0.65153107 | K28: 91.13164 | L28: 1.3710601 | N28: 5.3676205 | O28: 1.1693404 | Q28: 1.5741137 | R28: 0.53366746
A29: Finland | B29: 50.357592 | C29: 0.63736827 | E29: 0.20734652 | F29: 0.12043935 | H29: 0.81169475 | I29: 0.58123157 | K29: 98.271531 | L29: 0.80455076 | N29: 0.52459948 | O29: 0.52505065 | Q29: 0.18482854 | R29: 0.13587142
A30: France | B30: 47.490442 | C30: 0.73647643 | E30: 0.1028841 | F30: 0.10501462 | H30: 0.49761337 | I30: 0.28295696 | K30: 95.761782 | L30: 1.3120083 | N30: 3.5938775 | O30: 1.3457946 | Q30: 0.043843365 | R30: 0.043803143
A31: Germany | B31: 47.59784 | C31: 0.89572545 | E31: 0 | F31: c | H31: 0.62525344 | I31: 0.51288545 | K31: 95.150413 | L31: 1.540876 | N31: 3.7771953 | O31: 1.389169 | Q31: 0.44713873 | R31: 0.41297158
A32: Greece | B32: 54.704264 | C32: 0.66606073 | E32: 0.37050518 | F32: 0.18378649 | H32: 1.8940189 | I32: 0.78560403 | K32: 96.734861 | L32: 0.82547776 | N32: 0 | O32: c | Q32: 1.0006149 | R32: 0.28839117
A33: Hungary | B33: 55.480007 | C33: 0.89990078 | E33: 2.0486011 | F33: 0.4694174 | H33: 2.1354041 | I33: 0.90565287 | K33: 93.550644 | L33: 0.80007535 | N33: 1.2607342 | O33: 0.72109167 | Q33: 1.0046164 | R33: 0.33292307
A34: Iceland | B34: 63.88738 | C34: 0.87378786 | E34: 0.87906637 | F34: 0.11251505 | H34: 7.9192441 | I34: 0.15698525 | K34: 90.518862 | L34: 0.17146015 | N34: 0.44587606 | O34: 0.036154126 | Q34: 0.2369516 | R34: 0.10710187
A35: Ireland | B35: 63.658211 | C35: 0.71239191 | E35: 0 | F35: c | H35: 10.298042 | I35: 2.527057 | K35: 89.701958 | L35: 2.527057 | N35: 0 | O35: c | Q35: 0 | R35: c
A36: Israel | B36: m | C36: m | E36: m | F36: m | H36: m | I36: m | K36: m | L36: m | N36: m | O36: m | Q36: m | R36: m
A37: Italy | B37: 56.936251 | C37: 0.74205899 | E37: 0.24135546 | F37: 0.12685529 | H37: 5.2424265 | I37: 1.4487998 | K37: 93.469427 | L37: 1.5025668 | N37: 0.51370589 | O37: 0.37024851 | Q37: 0.53308486 | R37: 0.27639462
A38: Japan | B38: 76.619217 | C38: 0.63755553 | E38: 6.282747 | F38: 1.8380133 | H38: 50.881321 | I38: 3.7535438 | K38: 42.835932 | L38: 3.6588616 | N38: 0 | O38: c | Q38: 0 | R38: c
A39: Korea | B39: 74.974103 | C39: 0.55560077 | E39: 1.2111782 | F39: 0.8212117 | H39: 51.493581 | I39: 3.4968223 | K39: 47.161591 | L39: 3.5170761 | N39: 0 | O39: c | Q39: 0.13364917 | R39: 0.091258975
A40: Latvia | B40: 54.74128 | C40: 0.69294773 | E40: 0.67794645 | F40: 0.30013083 | H40: 4.2946669 | I40: 0.93359262 | K40: 93.096335 | L40: 1.0731186 | N40: 1.5900853 | O40: 0.59063927 | Q40: 0.3409661 | R40: 0.2189542
A41: Lithuania | B41: 61.647935 | C41: 0.70799982 | E41: 2.3863843 | F41: 0.44463925 | H41: 12.914253 | I41: 1.1154532 | K41: 82.627737 | L41: 1.2967548 | N41: 1.6217256 | O41: 0.54651683 | Q41: 0.44990002 | R41: 0.16971783
A42: Luembourg | B42: 49.65604 | C42: 0.71412306 | E42: 0 | F42: c | H42: 0 | I42: c | K42: 100 | L42: c | N42: 0 | O42: c | Q42: 0 | R42: c
A43: Meico | B43: 53.813008 | C43: 0.80962309 | E43: 2.4503683 | F43: 0.92619974 | H43: 4.2562435 | I43: 1.2513604 | K43: 91.264502 | L43: 1.7494806 | N43: 0.70535022 | O43: 0.70768099 | Q43: 1.3235359 | R43: 0.68889246
A44: Netherlands* | B44: 44.935605 | C44: 0.86112485 | E44: 0 | F44: c | H44: 0 | I44: c | K44: 92.887767 | L44: 1.8593292 | N44: 7.1122326 | O44: 1.8593292 | Q44: 0 | R44: c
A45: New Zealand | B45: 64.605424 | C45: 0.71664846 | E45: 1.0336363 | F45: 0.5719085 | H45: 15.391828 | I45: 2.2993959 | K45: 83.574535 | L45: 2.3268517 | N45: 0 | O45: c | Q45: 0 | R45: c
...

Sheet Table III.B1.13.5
A1: PISA 2018 Results (Volume III) - © OECD 2019
A2: Annex B1 | B2: Annex B1.13 Results (tables): Students' self-efficacy and fear of failure
A3: Version 2 - Last updated: 24-Jul-2020
A4: Disclaimer: http://oe.cd/disclaimer
A6: Annex B1 | B6: Annex B1.13 Results (tables): Students' self-efficacy and fear of failure
A7: Version 2 - Last updated: 02-Dec-2019
A8: Disclaimer: http://oe.cd/disclaimer
A10: Table III.B1.13.5
A11: Index of self-efficacy, by student characteristics
A12: Based on students' reports
B15: Index of self-efficacy, by the following student characteristics:
B16: Gender | K16: Socio-economic status1 | T16: Education level | AC16: Immigrant background
B17: Boys | E17: Girls | H17: Girls - boys | K17: Disadvantaged students | N17: Advantaged students | Q17: Advantaged -disadvantaged | T17: Lower secondary (ISCED 2) | W17: Upper secondary (ISCED 3) | Z17: ISCED 3 - ISCED 2 | AC17: Non-immigrant students | AF17: Immigrant students | AI17: Immigrant - non-immigrant
B18: Mean index | C18: S.E. | E18: Mean index | F18: S.E. | H18: Dif. | I18: S.E. | K18: Mean index | L18: S.E. | N18: Mean index | O18: S.E. | Q18: Dif. | R18: S.E. | T18: Mean index | U18: S.E. | W18: Mean index | X18: S.E. | Z18: Dif. | AA18: S.E. | AC18: Mean index | AD18: S.E. | AF18: Mean index | AG18: S.E. | AI18: Dif. | AJ18: S.E.
A19: OECD
A20: Australia | B20: 0.057559124 | C20: 0.013276081 | E20: -0.007818656 | F20: 0.016239128 | H20: -0.06537778 | I20: 0.019795727 | K20: -0.16540709 | L20: 0.018909871 | N20: 0.22819697 | O20: 0.018499153 | Q20: 0.39360406 | R20: 0.024426885 | T20: 0.023973789 | U20: 0.01180378 | W20: 0.038702887 | X20: 0.029570272 | Z20: 0.014729097 | AA20: 0.031777025 | AC20: -0.0060111835 | AD20: 0.013242531 | AF20: 0.10237686 | AG20: 0.020445248 | AI20: 0.10838804 | AJ20: 0.024398825
A21: Austria | B21: 0.080521599 | C21: 0.023744597 | E21: 0.081579455 | F21: 0.025666576 | H21: 0.0010578561 | I21: 0.031255344 | K21: -0.029155521 | L21: 0.030559787 | N21: 0.19475021 | O21: 0.031696344 | Q21: 0.22390573 | R21: 0.041282582 | T21: m | U21: m | W21: m | X21: m | Z21: m | AA21: m | AC21: 0.081868717 | AD21: 0.018948267 | AF21: 0.099410056 | AG21: 0.04050907 | AI21: 0.01754134 | AJ21: 0.03903633
