Workbook
Name _: [1]EAT12_1!#REF!,[1]EAT12_1!#REF!,[1]EAT12_1!#REF!,[1]EAT12_1!#REF!,[1]EAT12_1!#REF!,[1]EAT12_1!#REF!,[1]EAT12_1!#REF!,[1]EAT12_1!#REF!,[1]EAT12_1!#REF!,[1]EAT12_1!#REF!
Name _: [1]EAT12_1!#REF!,[1]EAT12_1!#REF!,[1]EAT12_1!#REF!,[1]EAT12_1!#REF!,[1]EAT12_1!#REF!,[1]EAT12_1!#REF!,[1]EAT12_1!#REF!,[1]EAT12_1!#REF!,[1]EAT12_1!#REF!,[1]EAT12_1!#REF!
Name _______ISC3: [2]ISC01!$B:$B+[3]Q_ISC3!$1:$23
Name ______ISC3: [2]ISC01!$B:$B+[3]Q_ISC3!$1:$23
Name _____ISC3: [2]ISC01!$B:$B+[3]Q_ISC3!$1:$23
Name ____ISC3: [2]ISC01!$B:$B+[3]Q_ISC3!$1:$23
Name ___ISC3: [2]ISC01!$B:$B+[3]Q_ISC3!$1:$23
Name __ISC3: [2]ISC01!$B:$B+[3]Q_ISC3!$1:$23
Name _6Y: [1]EAT12_1!#REF!,[1]EAT12_1!#REF!,[1]EAT12_1!#REF!,[1]EAT12_1!#REF!,[1]EAT12_1!#REF!,[1]EAT12_1!#REF!,[1]EAT12_1!#REF!,[1]EAT12_1!#REF!,[1]EAT12_1!#REF!,[1]EAT12_1!#REF!
Name _6Y: [1]EAT12_1!#REF!,[1]EAT12_1!#REF!,[1]EAT12_1!#REF!,[1]EAT12_1!#REF!,[1]EAT12_1!#REF!,[1]EAT12_1!#REF!,[1]EAT12_1!#REF!,[1]EAT12_1!#REF!,[1]EAT12_1!#REF!,[1]EAT12_1!#REF!
Name _ISC3: [2]ISC01!$B:$B+[3]Q_ISC3!$1:$23
Name calcul: '[6]Calcul_B1.1'!$A$1:$L$37
Name POpula: [8]POpula!$A$1:$I$1559
Name SPSS: [9]Figure5.6!$B$2:$X$30
Name toto: [10]Data5.11a!$B$3:$C$34

Sheet TOC
A1: PISA 2018 Results (Volume II) - © OECD 2019
A2: Annex B1 | B2: Annex B1.9 Results (tables): Immigrant background and students’ performance
A3: Version 2 - Last updated: 02-Dec-2019
A4: Disclaimer: http://oe.cd/disclaimer
A6: TOC | B6: PISA 2018 Results - Volume II
A8: Chapter 9 | B8: Immigrant background and students’ performance
A9: Tables
A11: ='Table II.B1.9.1'!A6 -> Table II.B1.9.1 | B11: ='Table II.B1.9.1'!$A$7 -> Socio-economic status, by immigrant background
A12: ='Table II.B1.9.2'!A6 -> Table II.B1.9.2 | B12: ='Table II.B1.9.2'!$A$7 -> Language spoken at home, by immigrant background
A13: ='Table II.B1.9.3'!A6 -> Table II.B1.9.3 | B13: ='Table II.B1.9.3'!$A$7 -> Mean reading performance and academic resilience, by immigrant background
A14: ='Table II.B1.9.4'!A6 -> Table II.B1.9.4 | B14: ='Table II.B1.9.4'!$A$7 -> Low performance in reading, by immigrant background
A15: ='Table II.B1.9.5'!A6 -> Table II.B1.9.5 | B15: ='Table II.B1.9.5'!$A$7 -> Students who expect to complete tertiary education, by immigrant background
A16: ='Table II.B1.9.6'!A6 -> Table II.B1.9.6 | B16: ='Table II.B1.9.6'!$A$7 -> Percentage of academically resilient immigrant students, by quarter of key indices
A17: ='Table II.B1.9.7'!A6 -> Table II.B1.9.7 | B17: ='Table II.B1.9.7'!$A$7 -> Average of key student attitudes, by academic resilience
A18: ='Table II.B1.9.8'!A6 -> Table II.B1.9.8 | B18: ='Table II.B1.9.8'!$A$7 -> Students' well-being, by immigrant background
A19: ='Table II.B1.9.9'!A6 -> Table II.B1.9.9 | B19: ='Table II.B1.9.9'!$A$7 -> Change between 2009 and 2018 in the percentage of students with an immigrant background
A20: ='Table II.B1.9.10'!A6 -> Table II.B1.9.10 | B20: ='Table II.B1.9.10'!$A$7 -> Change between 2009 and 2018 in the reading performance of students with an immigrant background
A21: ='Table II.B1.9.11'!A6 -> Table II.B1.9.11 | B21: ='Table II.B1.9.11'!$A$7 -> Concentration of immigrant students in schools
A25: Symbols for missing data
A26: c: There were too few observations to provide reliable estimates (i.e. there were fewer than 30 students or fewer than 5 schools with valid data).
A27: m: Data are not available. There was no observation in the sample; these data were not collected by the country; or these data were collected but subsequently removed from the publication for technical reasons.
A28: w: Results were withdrawn at the request of the country concerned.
A30: OECD averages
A31: OECD average, OECD average-37 | B31: Arithmetic mean across all OECD Member countries (and Colombia).
A32: OECD average-36a | B32: Arithmetic mean across all OECD Member countries (and Colombia), excluding Spain.
A33: OECD average-36b | B33: Arithmetic mean across all OECD Member countries (and Colombia), excluding Austria.
A34: OECD average-35a | B34: Arithmetic mean across all OECD Member countries (and Colombia), excluding Austria and Spain.
A36: Note
A37: Information on data for Cyprus: https://oe.cd/cyprus-disclaimer

Sheet Table II.B1.9.1
A1: PISA 2018 Results (Volume II) - © OECD 2019
A2: Annex B1 | B2: Annex B1.9 Results (tables): Immigrant background and students’ performance
A3: Version 2 - Last updated: 02-Dec-2019
A4: Disclaimer: http://oe.cd/disclaimer
A6: Table II.B1.9.1
A7: Socio-economic status, by immigrant background
A8: Based on students' reports
B12: Percentage of immigrant students | E12: Students' socio-economic status (ESCS) | Q12: Percentage of disadvantaged students1 | AC12: Percentage of advantaged students2
E13: Non-immigrant students | H13: Immigrant students | K13: Second-generation immigrant students | N13: First-generation immigrant students | Q13: Non-immigrant | T13: Immigrant | W13: Second-generation immigrant | Z13: First-generation immigrant | AC13: Non-immigrant | AF13: Immigrant | AI13: Second-generation immigrant | AL13: First-generation immigrant
B14: % | C14: S.E. | D14: s | E14: Mean index | F14: S.E. | G14: s | H14: Mean index | I14: S.E. | J14: s | K14: Mean index | L14: S.E. | M14: s | N14: Mean index | O14: S.E. | P14: s | Q14: % | R14: S.E. | S14: s | T14: % | U14: S.E. | V14: s | W14: % | X14: S.E. | Y14: s | Z14: % | AA14: S.E. | AB14: s | AC14: % | AD14: S.E. | AE14: s | AF14: % | AG14: S.E. | AH14: s | AI14: % | AJ14: S.E. | AK14: s | AL14: % | AM14: S.E. | AN14: s
A15: OECD
A16: Australia | B16: 27.708763 | C16: 0.84465676 | E16: 0.32305747 | F16: 0.014593513 | H16: 0.30979036 | I16: 0.031466425 | K16: 0.30290287 | L16: 0.034974924 | N16: 0.31634007 | O16: 0.039017975 | Q16: 24.655072 | R16: 0.65623097 | T16: 25.357487 | U16: 1.3676533 | W16: 26.844219 | X16: 1.7040073 | Z16: 23.943668 | AA16: 1.5230141 | AC16: 25.142158 | AD16: 0.60488735 | AF16: 25.147367 | AG16: 0.95613847 | AI16: 23.374674 | AJ16: 1.1160294 | AL16: 26.833123 | AM16: 1.3861304
A17: Austria | B17: 22.686235 | C17: 1.1527353 | E17: 0.16765104 | F17: 0.016702574 | H17: -0.50710657 | I17: 0.028544783 | K17: -0.53410089 | L17: 0.030701666 | N17: -0.45519889 | O17: 0.056809488 | Q17: 17.883371 | R17: 0.71961571 | T17: 49.029747 | U17: 1.556668 | W17: 48.688817 | X17: 1.8527656 | Z17: 49.685324 | AA17: 2.6902116 | AC17: 28.83031 | AD17: 0.88622769 | AF17: 11.710718 | AG17: 0.86812378 | AI17: 9.0780124 | AJ17: 0.91000044 | AL17: 16.773178 | AM17: 1.6790542
A18: Belgium | B18: 18.059455 | C18: 0.8584751 | E18: 0.1932849 | F18: 0.01742347 | H18: -0.45160943 | I18: 0.037686551 | K18: -0.42801682 | L18: 0.032413064 | N18: -0.48241614 | O18: 0.069575587 | Q18: 20.482619 | R18: 0.68197042 | T18: 43.933765 | U18: 1.7468384 | W18: 42.73928 | X18: 1.8778163 | Z18: 45.493497 | AA18: 2.7941706 | AC18: 28.199495 | AD18: 0.74988366 | AF18: 11.580407 | AG18: 1.0472458 | AI18: 10.81519 | AJ18: 1.0382242 | AL18: 12.57961 | AM18: 1.6698537
A19: Canada | B19: 34.969966 | C19: 1.4227691 | E19: 0.45103423 | F19: 0.014122474 | H19: 0.36883745 | I19: 0.02816572 | K19: 0.35929271 | L19: 0.033258818 | N19: 0.37884379 | O19: 0.033311323 | Q19: 23.398017 | R19: 0.59086282 | T19: 27.3124 | U19: 1.3005911 | W19: 28.277233 | X19: 1.678225 | Z19: 26.300907 | AA19: 1.4297833 | AC19: 25.789762 | AD19: 0.75471729 | AF19: 23.597649 | AG19: 1.0451171 | AI19: 23.655935 | AJ19: 1.3959772 | AL19: 23.536545 | AM19: 1.2496227
A20: Chile | B20: 3.3908615 | C20: 0.38959487 | E20: -0.56648428 | F20: 0.027851757 | H20: -0.77108255 | I20: 0.089456021 | K20: -0.24022539 | L20: 0.18771126 | N20: -0.90727907 | O20: 0.10591562 | Q20: 24.243654 | R20: 1.0042866 | T20: 37.749999 | U20: 3.8186489 | W20: 21.506954 | X20: 8.1504853 | Z20: 41.917308 | AA20: 5.2318527 | AC20: 25.540923 | AD20: 1.0155964 | AF20: 21.475547 | AG20: 3.2364166 | AI20: 35.77406 | AJ20: 7.3700242 | AL20: 17.807125 | AM20: 3.4562252
A21: Colombia | B21: 0.55659208 | C21: 0.12058001 | E21: -1.1808829 | F21: 0.044758798 | H21: -1.6247984 | I21: 0.32376165 | K21: c | L21: c | N21: c | O21: c | Q21: 24.682446 | R21: 1.3083263 | T21: 53.771044 | U21: 7.8978314 | W21: m | X21: m | Z21: m | AA21: m | AC21: 25.079745 | AD21: 1.2171089 | AF21: 24.081953 | AG21: 7.2688286 | AI21: m | AJ21: m | AL21: m | AM21: m
A22: Czech Republic | B22: 4.1464036 | C22: 0.38608927 | E22: -0.1957662 | F22: 0.01727141 | H22: -0.4832509 | I22: 0.099164074 | K22: -0.5470877 | L22: 0.11841798 | N22: -0.42262146 | O22: 0.16399796 | Q22: 24.168284 | R22: 0.81695473 | T22: 41.584724 | U22: 3.9161963 | W22: 44.455096 | X22: 5.6402945 | Z22: 38.85857 | AA22: 4.6172263 | AC22: 25.222868 | AD22: 0.76171316 | AF22: 19.477544 | AG22: 2.9163574 | AI22: 17.757815 | AJ22: 3.9752479 | AL22: 21.11087 | AM22: 3.6254361
A23: Denmark | B23: 10.653251 | C23: 0.43829698 | E23: 0.59646765 | F23: 0.015168411 | H23: -0.13642186 | I23: 0.039013428 | K23: -0.14915405 | L23: 0.038307064 | N23: -0.089004775 | O23: 0.090551901 | Q23: 21.176325 | R23: 0.81528609 | T23: 56.514699 | U23: 1.9185515 | W23: 57.002783 | X23: 1.9926461 | Z23: 54.696982 | AA23: 4.3578405 | AC23: 26.869177 | AD23: 0.84362099 | AF23: 10.124243 | AG23: 1.2232184 | AI23: 9.7531975 | AJ23: 1.3734875 | AL23: 11.506089 | AM23: 2.640677
A24: Estonia | B24: 10.392583 | C24: 0.46505303 | E24: 0.078719499 | F24: 0.016363207 | H24: 0.092634669 | I24: 0.040518434 | K24: 0.075662068 | L24: 0.037559692 | N24: 0.31508268 | O24: 0.19726478 | Q24: 25.177321 | R24: 0.76977604 | T24: 23.978915 | U24: 2.1484897 | W24: 24.53868 | X24: 2.1540913 | Z24: 16.642469 | AA24: 6.3342119 | AC24: 25.301572 | AD24: 0.80265976 | AF24: 23.055251 | AG24: 1.9663178 | AI24: 21.952655 | AJ24: 1.972935 | AL24: 37.50621 | AM24: 9.3652988
A25: Finland | B25: 5.7757806 | C25: 0.47656616 | E25: 0.33048823 | F25: 0.018389489 | H25: -0.23527832 | I25: 0.073514966 | K25: -0.13689668 | L25: 0.081338249 | N25: -0.30850926 | O25: 0.10165931 | Q25: 23.749811 | R25: 0.80537355 | T25: 45.332059 | U25: 3.2175172 | W25: 42.428378 | X25: 4.043797 | Z25: 47.493431 | AA25: 4.268274 | AC25: 25.817664 | AD25: 1.0404929 | AF25: 13.054513 | AG25: 2.2104778 | AI25: 13.874951 | AJ25: 3.3220125 | AL25: 12.443815 | AM25: 2.8288438
A26: France | B26: 14.292398 | C26: 0.93597143 | E26: 0.061388335 | F26: 0.018687842 | H26: -0.58143621 | I26: 0.045863494 | K26: -0.57380791 | L26: 0.054998587 | N26: -0.59721215 | O26: 0.074029399 | Q26: 21.227013 | R26: 0.86154386 | T26: 46.981045 | U26: 2.2374591 | W26: 46.31376 | X26: 3.1142931 | Z26: 48.361045 | AA26: 3.1262587 | AC26: 27.192319 | AD26: 0.98353031 | AF26: 12.532257 | AG26: 1.396706 | AI26: 12.539299 | AJ26: 1.650694 | AL26: 12.517692 | AM26: 2.1930121
A27: Germany | B27: 22.168808 | C27: 1.1487898 | E27: 0.096672321 | F27: 0.027617645 | H27: -0.77034438 | I27: 0.039479541 | K27: -0.76375741 | L27: 0.046209988 | N27: -0.78695543 | O27: 0.070290491 | Q27: 18.670006 | R27: 0.93573647 | T27: 47.289096 | U27: 1.6458899 | W27: 48.061027 | X27: 2.0675156 | Z27: 45.342438 | AA27: 2.9505509 | AC27: 29.226831 | AD27: 1.2006145 | AF27: 9.9928889 | AG27: 1.1184688 | AI27: 9.6881312 | AJ27: 1.3641604 | AL27: 10.761427 | AM27: 1.7980385
A28: Greece | B28: 11.696103 | C28: 0.66265155 | E28: -0.019375595 | F28: 0.025962439 | H28: -0.76784831 | I28: 0.033997119 | K28: -0.75820329 | L28: 0.032975735 | N28: -0.79398739 | O28: 0.088564139 | Q28: 21.00651 | R28: 1.0036725 | T28: 54.193293 | U28: 1.9499868 | W28: 53.297248 | X28: 1.9663906 | Z28: 56.621676 | AA28: 4.3588763 | AC28: 27.173592 | AD28: 1.1444733 | AF28: 7.9232478 | AG28: 1.1222141 | AI28: 6.7304116 | AJ28: 1.2320847 | AL28: 11.155967 | AM28: 2.5481815
A29: Hungary | B29: 2.5521961 | C29: 0.30831545 | E29: -0.12211944 | F29: 0.020243656 | H29: 0.051227631 | I29: 0.087140992 | K29: 0.25208512 | L29: 0.094687415 | N29: -0.16038313 | O29: 0.12222575 | Q29: 25.116797 | R29: 0.76398438 | T29: 19.355296 | U29: 3.7852998 | W29: 13.268581 | X29: 4.0976101 | Z29: 25.767874 | AA29: 5.8616218 | AC29: 24.918006 | AD29: 0.90272418 | AF29: 30.699906 | AG29: 4.7718863 | AI29: 38.886472 | AJ29: 5.9639865 | AL29: 22.075059 | AM29: 7.0330044
A30: Iceland | B30: 5.5922791 | C30: 0.40139674 | E30: 0.59175627 | F30: 0.013391246 | H30: -0.18158209 | I30: 0.078233589 | K30: -0.13077366 | L30: 0.091132711 | N30: -0.22213245 | O30: 0.11938551 | Q30: 23.170367 | R30: 0.74891367 | T30: 55.219266 | U30: 3.8981221 | W30: 57.69004 | X30: 5.0810861 | Z30: 53.247334 | AA30: 5.2483675 | AC30: 26.393145 | AD30: 0.84356308 | AF30: 2.8932693 | AG30: 0.99531237 | AI30: 5.0869281 | AJ30: 1.7706954 | AL30: 1.1425035 | AM30: 1.1417614
A31: Ireland | B31: 17.860839 | C31: 0.91486177 | E31: 0.13175115 | F31: 0.025185791 | H31: 0.097630372 | I31: 0.042386904 | K31: 0.12223518 | L31: 0.053760449 | N31: 0.077505089 | O31: 0.056273168 | Q31: 24.952311 | R31: 1.0231832 | T31: 25.781785 | U31: 1.7741388 | W31: 22.26868 | X31: 2.1322933 | Z31: 28.655298 | AA31: 2.5862673 | AC31: 25.194708 | AD31: 1.0896374 | AF31: 25.036217 | AG31: 1.9346302 | AI31: 22.274962 | AJ31: 2.2660463 | AL31: 27.29476 | AM31: 2.8296139
A32: Israel | B32: 16.416253 | C32: 1.0738364 | E32: 0.39927053 | F32: 0.026080324 | H32: 0.16857023 | I32: 0.052672798 | K32: 0.23041096 | L32: 0.057873735 | N32: -0.031844709 | O32: 0.094418429 | Q32: 23.202622 | R32: 0.95520564 | T32: 30.482304 | U32: 2.0181814 | W32: 28.464834 | X32: 2.4150951 | Z32: 37.020571 | AA32: 3.179625 | AC32: 26.256319 | AD32: 1.1059293 | AF32: 21.241163 | AG32: 1.7464055 | AI32: 22.098846 | AJ32: 1.9572492 | AL32: 18.461563 | AM32: 2.6742075
A33: Italy | B33: 10.025087 | C33: 0.49170849 | E33: -0.15839003 | F33: 0.021438386 | H33: -0.74113834 | I33: 0.044243623 | K33: -0.67981713 | L33: 0.056212532 | N33: -0.81549732 | O33: 0.060441052 | Q33: 22.86804 | R33: 0.77650428 | T33: 42.959307 | U33: 2.678333 | W33: 40.833265 | X33: 3.3982522 | Z33: 45.537375 | AA33: 3.5519075 | AC33: 26.922778 | AD33: 1.0006507 | AF33: 7.8068416 | AG33: 1.3166898 | AI33: 9.8125838 | AJ33: 2.0705684 | AL33: 5.3746499 | AM33: 1.5747608
A34: Japan | B34: 0.62269076 | C34: 0.13447374 | E34: w | F34: w | H34: w | I34: w | K34: w | L34: w | N34: w | O34: w | Q34: w | R34: w | T34: w | U34: w | W34: w | X34: w | Z34: w | AA34: w | AC34: w | AD34: w | AF34: w | AG34: w | AI34: w | AJ34: w | AL34: w | AM34: w
A35: Korea | B35: 0.16599464 | C35: 0.08987183 | E35: 0.076241976 | F35: 0.020022799 | H35: c | I35: c | K35: c | L35: c | N35: c | O35: c | Q35: 24.729442 | R35: 0.88304807 | T35: m | U35: m | W35: m | X35: m | Z35: m | AA35: m | AC35: 25.146158 | AD35: 1.0094778 | AF35: m | AG35: m | AI35: m | AJ35: m | AL35: m | AM35: m
A36: Latvia | B36: 4.4397198 | C36: 0.3368561 | E36: -0.0050949683 | F36: 0.014312397 | H36: 0.065933779 | I36: 0.05486545 | K36: 0.011878326 | L36: 0.05842792 | N36: 0.29694796 | O36: 0.1700938 | Q36: 25.221396 | R36: 0.69806338 | T36: 21.792553 | U36: 2.608769 | W36: 24.413195 | X36: 3.1354622 | Z36: 10.592839 | AA36: 4.0221864 | AC36: 24.833535 | AD36: 0.60126345 | AF36: 27.349311 | AG36: 2.790138 | AI36: 22.988165 | AJ36: 2.7850965 | AL36: 45.987329 | AM36: 8.2846169
A37: Lithuania | B37: 1.559925 | C37: 0.1305157 | E37: 0.0291297 | F37: 0.013576415 | H37: 0.11642104 | I37: 0.11899444 | K37: 0.19240008 | L37: 0.083318399 | N37: -0.15603523 | O37: 0.37428465 | Q37: 25.051914 | R37: 0.62253485 | T37: 16.945706 | U37: 3.9796455 | W37: 16.759377 | X37: 3.8663836 | Z37: 17.613869 | AA37: 12.762927 | AC37: 25.114519 | AD37: 0.69820994 | AF37: 28.122751 | AG37: 4.1721622 | AI37: 26.490512 | AJ37: 4.516712 | AL37: 33.975864 | AM37: 9.0002776
A38: Luxembourg | B38: 54.871809 | C38: 0.64370888 | E38: 0.41439208 | F38: 0.01741086 | H38: -0.31101135 | I38: 0.020021113 | K38: -0.3795853 | L38: 0.030013722 | N38: -0.22619843 | O38: 0.030453893 | Q38: 9.6611953 | R38: 0.59137366 | T38: 37.25501 | U38: 0.93898913 | W38: 38.154017 | X38: 1.3881068 | Z38: 36.14311 | AA38: 1.4691141 | AC38: 31.446854 | AD38: 1.0385215 | AF38: 19.828106 | AG38: 0.70538311 | AI38: 16.653772 | AJ38: 0.99219948 | AL38: 23.754151 | AM38: 1.0216551
A39: Mexico | B39: 1.5614212 | C39: 0.26845506 | E39: -1.1750488 | F39: 0.039048539 | H39: -1.5283515 | I39: 0.15223524 | K39: -1.81773 | L39: 0.18361519 | N39: -1.1711495 | O39: 0.23911872 | Q39: 24.592503 | R39: 1.1172698 | T39: 36.512785 | U39: 6.1991778 | W39: 46.879687 | X39: 8.0855046 | Z39: 23.716127 | AA39: 6.9625294 | AC39: 25.303898 | AD39: 1.1294979 | AF39: 18.441507 | AG39: 5.9947739 | AI39: 8.7975585 | AJ39: 5.8817431 | AL39: 30.345771 | AM39: 10.089873
A40: Netherlands* | B40: 13.767366 | C40: 1.1613432 | E40: 0.3812005 | F40: 0.020448416 | H40: -0.3350508 | I40: 0.0505363 | K40: -0.32832972 | L40: 0.05620947 | N40: -0.36264607 | O40: 0.10606085 | Q40: 21.184737 | R40: 0.81478494 | T40: 47.565946 | U40: 2.2762373 | W40: 46.606025 | X40: 2.5087749 | Z40: 51.507165 | AA40: 4.5727421 | AC40: 27.527297 | AD40: 1.1832416 | AF40: 10.057071 | AG40: 1.0448631 | AI40: 9.7085297 | AJ40: 1.1723521 | AL40: 11.488105 | AM40: 2.8318763
A41: New Zealand | B41: 26.459841 | C41: 1.3482097 | E41: 0.1479623 | F41: 0.020239355 | H41: 0.22109409 | I41: 0.035602577 | K41: 0.083281698 | L41: 0.046200756 | N41: 0.32966129 | O41: 0.039176727 | Q41: 25.483246 | R41: 0.89596307 | T41: 23.05472 | U41: 1.5910334 | W41: 30.260647 | X41: 2.2257767 | Z41: 17.377964 | AA41: 1.6618916 | AC41: 24.727972 | AD41: 0.82581727 | AF41: 27.054961 | AG41: 1.1680278 | AI41: 25.063476 | AJ41: 1.6193083 | AL41: 28.623833 | AM41: 1.5093643
A42: Norway | B42: 12.399896 | C42: 0.77280409 | E42: 0.61557497 | F42: 0.018201652 | H42: 0.022176608 | I42: 0.045118402 | K42: 0.14161689 | L42: 0.050352137 | N42: -0.099116994 | O42: 0.072171139 | Q42: 21.921268 | R42: 0.76176319 | T42: 46.947435 | U42: 1.8939483 | W42: 40.926009 | X42: 2.5307004 | Z42: 53.062294 | AA42: 3.2150361 | AC42: 26.442042 | AD42: 1.084395 | AF42: 14.166923 | AG42: 1.2781093 | AI42: 15.290973 | AJ42: 1.7188842 | AL42: 13.025432 | AM42: 1.8439778
A43: Poland | B43: 0.64312079 | C43: 0.190311 | E43: -0.14265449 | F43: 0.023659598 | H43: c | I43: c | K43: c | L43: c | N43: c | O43: c | Q43: 24.84103 | R43: 0.89468432 | T43: m | U43: m | W43: m | X43: m | Z43: m | AA43: m | AC43: 25.03431 | AD43: 1.0642874 | AF43: m | AG43: m | AI43: m | AJ43: m | AL43: m | AM43: m
A44: Portugal* | B44: 6.9632336 | C44: 0.57149007 | E44: -0.37297475 | F44: 0.034704884 | H44: -0.56613711 | I44: 0.090928648 | K44: -0.45387288 | L44: 0.1010174 | N44: -0.71955728 | O44: 0.13822711 | Q44: 24.806995 | R44: 1.0246635 | T44: 26.154811 | U44: 3.0679988 | W44: 24.18171 | X44: 3.7659305 | Z44: 28.851247 | AA44: 4.9989636 | AC44: 25.666307 | AD44: 1.289451 | AF44: 17.807965 | AG44: 2.4723271 | AI44: 22.272155 | AJ44: 3.3979395 | AL44: 11.707207 | AM44: 3.1143235
...

Sheet Table II.B1.9.2
A1: PISA 2018 Results (Volume II) - © OECD 2019
A2: Annex B1 | B2: Annex B1.9 Results (tables): Immigrant background and students’ performance
A3: Version 2 - Last updated: 02-Dec-2019
A4: Disclaimer: http://oe.cd/disclaimer
A6: Table II.B1.9.2
A7: Language spoken at home, by immigrant background
A8: Based on students' reports
B12: Percentage of immigrant students | E12: Percentage of students who speak mainly another language at home | T12: Average performance in reading
E13: All students | H13: Non-immigrant | K13: Immigrant | N13: Second-generation immigrant | Q13: First-generation immigrant | T13: Immigrant students who speak mainly another language at home | W13: Immigrant students who speak the language of assessment at home | Z13: Difference in reading performance between immigrant students who speak the language of assessment at home and those who do not
B14: % | C14: S.E. | D14: s | E14: % | F14: S.E. | G14: s | H14: % | I14: S.E. | J14: s | K14: % | L14: S.E. | M14: s | N14: % | O14: S.E. | P14: s | Q14: % | R14: S.E. | S14: s | T14: Mean score | U14: S.E. | V14: s | W14: Mean score | X14: S.E. | Y14: s | Z14: Score dif. | AA14: S.E. | AB14: s
A15: OECD
A16: Australia | B16: 27.708763 | C16: 0.84465676 | E16: 13.276377 | F16: 0.55957714 | H16: 2.6875176 | I16: 0.19530622 | K16: 40.072203 | L16: 1.1336135 | N16: 32.797866 | O16: 1.3830896 | Q16: 47.012589 | R16: 1.7024636 | T16: 491.63955 | U16: 4.446552 | W16: 524.67641 | X16: 3.6081609 | Z16: 33.036861 | AA16: 4.4811497
A17: Austria | B17: 22.686235 | C17: 1.1527353 | E17: 20.496457 | F17: 0.90151551 | H17: 4.6612943 | I17: 0.34233551 | K17: 73.759018 | L17: 1.4086764 | N17: 72.439363 | O17: 1.7951061 | Q17: 76.276963 | R17: 1.9380138 | T17: 425.06291 | U17: 3.8596257 | W17: 471.30849 | X17: 8.4050868 | Z17: 46.245582 | AA17: 7.7444158
A18: Belgium | B18: 18.059455 | C18: 0.8584751 | E18: 17.536608 | F18: 0.84811966 | H18: 7.8777547 | I18: 0.51592839 | K18: 59.317426 | L18: 1.6864713 | N18: 55.715897 | O18: 2.3306208 | Q18: 64.023923 | R18: 3.27716 | T18: 429.36521 | U18: 4.584528 | W18: 468.01934 | X18: 5.1655628 | Z18: 38.654131 | AA18: 6.2110038
A19: Canada | B19: 34.969966 | C19: 1.4227691 | E19: 21.016716 | F19: 0.84408642 | H19: 4.3083376 | I19: 0.19531992 | K19: 51.706789 | L19: 1.1000887 | N19: 37.196486 | O19: 1.2293627 | Q19: 66.907881 | R19: 1.3535904 | T19: 507.9707 | U19: 3.393022 | W19: 536.65252 | X19: 3.9991512 | Z19: 28.681822 | AA19: 4.2876732
A20: Chile | B20: 3.3908615 | C20: 0.38959487 | E20: 1.8475888 | F20: 0.175707 | H20: 1.7039417 | I20: 0.16729104 | K20: 6.4631559 | L20: 2.3965378 | N20: 11.570103 | O20: 7.2271303 | Q20: 5.1529194 | R20: 2.225352 | T20: c | U20: c | W20: 439.51485 | X20: 7.9867542 | Z20: c | AA20: c
A21: Colombia | B21: 0.55659208 | C21: 0.12058001 | E21: 1.6506953 | F21: 0.17440621 | H21: 1.5130825 | I21: 0.16281086 | K21: 13.973481 | L21: 6.4293773 | N21: c | O21: c | Q21: c | R21: c | T21: c | U21: c | W21: 354.79125 | X21: 14.689332 | Z21: c | AA21: c
A22: Czech Republic | B22: 4.1464036 | C22: 0.38608927 | E22: 5.751648 | F22: 0.50522542 | H22: 2.7679404 | I22: 0.31228374 | K22: 71.181172 | L22: 3.5088641 | N22: 54.432578 | O22: 5.1551818 | Q22: 87.062021 | R22: 3.5427724 | T22: 437.39502 | U22: 11.48601 | W22: 443.39241 | X22: 15.039417 | Z22: 5.9973935 | AA22: 17.915812
A23: Denmark | B23: 10.653251 | C23: 0.43829698 | E23: 8.0689624 | F23: 0.39362101 | H23: 2.8702732 | I23: 0.26861299 | K23: 50.897215 | L23: 1.8385675 | N23: 44.277997 | O23: 2.2523433 | Q23: 75.564449 | R23: 3.6273681 | T23: 430.28771 | U23: 4.996098 | W23: 459.16828 | X23: 4.6016264 | Z23: 28.880569 | AA23: 6.3058126
A24: Estonia | B24: 10.392583 | C24: 0.46505303 | E24: 5.3852968 | F24: 0.39654398 | H24: 4.5174124 | I24: 0.35306226 | K24: 12.651133 | L24: 1.7066836 | N24: 10.464952 | O24: 1.5738927 | Q24: 40.915448 | R24: 7.8849202 | T24: 460.10222 | U24: 10.08737 | W24: 493.58089 | X24: 4.9044652 | Z24: 33.478669 | AA24: 10.858399
A25: Finland | B25: 5.7757806 | C25: 0.47656616 | E25: 7.5785608 | F25: 0.49436505 | H25: 3.3146349 | I25: 0.39888443 | K25: 73.859011 | L25: 2.3182347 | N25: 62.849667 | O25: 4.8812485 | Q25: 82.04672 | R25: 2.4515011 | T25: 425.17148 | U25: 8.4533262 | W25: 466.04648 | X25: 15.154602 | Z25: 40.875002 | AA25: 17.528553
A26: France | B26: 14.292398 | C26: 0.93597143 | E26: 11.543447 | F26: 0.66106081 | H26: 5.7899376 | I26: 0.46340046 | K26: 45.530349 | L26: 2.3052974 | N26: 35.6092 | O26: 2.2505111 | Q26: 65.944772 | R26: 3.1030498 | T26: 434.947 | U26: 6.7647098 | W26: 461.81689 | X26: 6.7266162 | Z26: 26.869885 | AA26: 8.3832534
A27: Germany | B27: 22.168808 | C27: 1.1487898 | E27: 17.822175 | F27: 0.95152182 | H27: 4.4530643 | I27: 0.40075058 | K27: 62.48237 | L27: 1.5319132 | N27: 52.910849 | O27: 1.9527305 | Q27: 85.974114 | R27: 2.4942943 | T27: 430.07769 | U27: 6.9167391 | W27: 499.66797 | X27: 7.1071168 | Z27: 69.590277 | AA27: 7.1968763
A28: Greece | B28: 11.696103 | C28: 0.66265155 | E28: 6.2419355 | F28: 0.46735183 | H28: 1.5125143 | I28: 0.2641178 | K28: 40.933171 | L28: 2.4535546 | N28: 33.041713 | O28: 2.5887419 | Q28: 62.405866 | R28: 4.0673354 | T28: 389.91473 | U28: 8.4119626 | W28: 430.86752 | X28: 5.9134151 | Z28: 40.952795 | AA28: 8.1993639
A29: Hungary | B29: 2.5521961 | C29: 0.30831545 | E29: 2.2015821 | F29: 0.23297578 | H29: 1.8643918 | I29: 0.23352283 | K29: 14.10221 | L29: 3.012348 | N29: 15.572294 | O29: 3.7356421 | Q29: 12.553423 | R29: 5.0092196 | T29: c | U29: c | W29: 489.39379 | X29: 10.780735 | Z29: c | AA29: c
A30: Iceland | B30: 5.5922791 | C30: 0.40139674 | E30: 7.1670161 | F30: 0.44511882 | H30: 2.6969908 | I30: 0.29616653 | K30: 81.478625 | L30: 2.8630685 | N30: 69.65143 | O30: 4.8536031 | Q30: 90.937932 | R30: 2.9499814 | T30: 406.02068 | U30: 7.8312173 | W30: 410.30905 | X30: 20.784048 | Z30: 4.2883639 | AA30: 21.656801
A31: Ireland | B31: 17.860839 | C31: 0.91486177 | E31: 9.0837827 | F31: 0.59268494 | H31: 0.36131498 | I31: 0.086811673 | K31: 49.447429 | L31: 1.8763177 | N31: 27.024615 | O31: 2.6130647 | Q31: 67.822715 | R31: 1.9580724 | T31: 498.4897 | U31: 5.3251096 | W31: 518.2334 | X31: 5.1686394 | Z31: 19.743705 | AA31: 7.220863
A32: Israel | B32: 16.416253 | C32: 1.0738364 | E32: 14.024953 | F32: 0.859249 | H32: 6.5283768 | I32: 0.69052684 | K32: 51.228787 | L32: 1.9877901 | N32: 44.01461 | O32: 2.2685563 | Q32: 74.36265 | R32: 2.8525618 | T32: 464.04426 | U32: 7.621583 | W32: 479.25167 | X32: 6.9369616 | Z32: 15.207418 | AA32: 7.0483249
A33: Italy | B33: 10.025087 | C33: 0.49170849 | E33: 18.464272 | F33: 0.6098366 | H33: 13.481258 | I33: 0.66291822 | K33: 62.239048 | L33: 1.9688944 | N33: 55.424856 | O33: 2.3807285 | Q33: 70.392224 | R33: 3.1384944 | T33: 423.00842 | U33: 6.0645142 | W33: 466.88104 | X33: 7.2902776 | Z33: 43.872615 | AA33: 9.3770847
A34: Japan | B34: 0.62269076 | C34: 0.13447374 | E34: 0.96766638 | F34: 0.17881164 | H34: w | I34: w | K34: w | L34: w | N34: w | O34: w | Q34: w | R34: w | T34: w | U34: w | W34: w | X34: w | Z34: w | AA34: w
A35: Korea | B35: 0.16599464 | C35: 0.08987183 | E35: 0.59048557 | F35: 0.080897464 | H35: 0.54000672 | I35: 0.082469349 | K35: c | L35: c | N35: c | O35: c | Q35: c | R35: c | T35: c | U35: c | W35: c | X35: c | Z35: c | AA35: c
A36: Latvia | B36: 4.4397198 | C36: 0.3368561 | E36: 10.532325 | F36: 0.69999372 | H36: 9.8857405 | I36: 0.6912659 | K36: 23.503665 | L36: 3.0602879 | N36: 23.066354 | O36: 3.297757 | Q36: 25.403327 | R36: 7.4271371 | T36: 422.14921 | U36: 16.408569 | W36: 491.41146 | X36: 10.008557 | Z36: 69.262249 | AA36: 19.390616
A37: Lithuania | B37: 1.559925 | C37: 0.1305157 | E37: 5.8565488 | F37: 0.40841141 | H37: 5.3551794 | I37: 0.42243152 | K37: 30.254404 | L37: 4.4679387 | N37: 28.312078 | O37: 4.7586009 | Q37: 37.338158 | R37: 11.667119 | T37: 408.04233 | U37: 26.606317 | W37: 478.27753 | X37: 12.207893 | Z37: 70.235202 | AA37: 31.116166
A38: Luxembourg | B38: 54.871809 | C38: 0.64370888 | E38: 82.883376 | F38: 0.41867302 | H38: 91.995827 | I38: 0.5368489 | K38: 75.585094 | L38: 0.72848826 | N38: 77.182532 | O38: 1.0343732 | Q38: 73.605345 | R38: 1.0234341 | T38: 431.93718 | U38: 2.0287159 | W38: 527.54779 | X38: 3.8835423 | Z38: 95.610614 | AA38: 4.7078294
A39: Mexico | B39: 1.5614212 | C39: 0.26845506 | E39: 2.8831952 | F39: 0.58353316 | H39: 2.6739052 | I39: 0.56910717 | K39: 16.351841 | L39: 5.1049338 | N39: 10.658287 | O39: 4.833108 | Q39: 23.379829 | R39: 8.741124 | T39: c | U39: c | W39: 331.75496 | X39: 16.75973 | Z39: c | AA39: c
A40: Netherlands* | B40: 13.767366 | C40: 1.1613432 | E40: 9.7827873 | F40: 0.76169075 | H40: 2.2171627 | I40: 0.30335633 | K40: 55.108604 | L40: 2.259351 | N40: 50.497458 | O40: 2.5189563 | Q40: 74.093526 | R40: 4.3851229 | T40: 415.47913 | U40: 6.7763238 | W40: 440.92456 | X40: 7.6286405 | Z40: 25.445431 | AA40: 7.4966319
A41: New Zealand | B41: 26.459841 | C41: 1.3482097 | E41: 14.299239 | F41: 0.78375162 | H41: 2.8179319 | I41: 0.29934067 | K41: 45.318833 | L41: 1.5925637 | N41: 37.278981 | O41: 2.1280539 | Q41: 51.667552 | R41: 1.9576934 | T41: 486.23604 | U41: 4.9401073 | W41: 526.11843 | X41: 4.2652618 | Z41: 39.88239 | AA41: 6.4575462
A42: Norway | B42: 12.399896 | C42: 0.77280409 | E42: 10.243323 | F42: 0.55301199 | H42: 2.6688419 | I42: 0.24253388 | K42: 62.908163 | L42: 2.0528251 | N42: 43.717142 | O42: 2.8563677 | Q42: 82.238448 | R42: 2.146147 | T42: 454.89316 | U42: 6.2132005 | W42: 459.86692 | X42: 6.41882 | Z42: 4.9737541 | AA42: 8.7555912
A43: Poland | B43: 0.64312079 | C43: 0.190311 | E43: 1.7211215 | F43: 0.28691901 | H43: 1.197866 | I43: 0.18502079 | K43: c | L43: c | N43: c | O43: c | Q43: c | R43: c | T43: c | U43: c | W43: c | X43: c | Z43: c | AA43: c
A44: Portugal* | B44: 6.9632336 | C44: 0.57149007 | E44: 3.060403 | F44: 0.34313067 | H44: 1.1763295 | I44: 0.15089817 | K44: 27.601835 | L44: 2.6980688 | N44: 23.492716 | O44: 3.4105114 | Q44: 33.169862 | R44: 3.4525292 | T44: 446.45752 | U44: 13.908733 | W44: 469.10213 | X44: 7.52879 | Z44: 22.644611 | AA44: 13.266423
...

Sheet Table II.B1.9.3
A1: PISA 2018 Results (Volume II) - © OECD 2019
A2: Annex B1 | B2: Annex B1.9 Results (tables): Immigrant background and students’ performance
A3: Version 2 - Last updated: 02-Dec-2019
A4: Disclaimer: http://oe.cd/disclaimer
A6: Table II.B1.9.3
A7: Mean reading performance and academic resilience, by immigrant background
A8: Based on students' reports
B12: Percentage of immigrant students | E12: Reading performance | T12: Score-point difference in reading performance associated with immigrant background | Z12: Academic resilience
E13: Average performance | H13: Non-immigrant students | K13: Immigrant students | N13: Second-generation immigrant students | Q13: First-generation immigrant students | T13: Before accounting for gender, and students' and schools' socio-economic profile1 | W13: After accounting for gender, and students' and schools' socio-economic profile | Z13: Academically resilient immigrant students2
B14: % | C14: S.E. | D14: s | E14: Mean score | F14: S.E. | G14: s | H14: Mean score | I14: S.E. | J14: s | K14: Mean score | L14: S.E. | M14: s | N14: Mean score | O14: S.E. | P14: s | Q14: Mean score | R14: S.E. | S14: s | T14: Score dif. | U14: S.E. | V14: s | W14: Score dif. | X14: S.E. | Y14: s | Z14: % | AA14: S.E. | AB14: s
A15: OECD
A16: Australia | B16: 27.708763 | C16: 0.84465676 | E16: 502.63172 | F16: 1.6343431 | H16: 503.91231 | I16: 1.951208 | K16: 511.46358 | L16: 3.3466747 | N16: 522.69432 | O16: 4.4797664 | Q16: 500.74704 | R16: 3.855339 | T16: 7.5512713 | U16: 3.5409789 | W16: 7.3628035 | X16: 2.9551638 | Z16: 29.111354 | AA16: 1.3494019
A17: Austria | B17: 22.686235 | C17: 1.1527353 | E17: 484.39257 | F17: 2.6974721 | H17: 499.74546 | I17: 2.5553271 | K17: 437.19821 | L17: 4.2295542 | N17: 445.84614 | O17: 4.3424548 | Q17: 420.69767 | R17: 5.5425713 | T17: -62.547252 | U17: 4.5392983 | W17: -33.266328 | X17: 3.6020549 | Z17: 11.249149 | AA17: 1.177217
A18: Belgium | B18: 18.059455 | C18: 0.8584751 | E18: 492.86444 | F18: 2.3219733 | H18: 506.33144 | I18: 2.3968596 | K18: 444.84524 | L18: 3.820851 | N18: 458.64087 | O18: 4.6961356 | Q18: 426.80515 | R18: 5.2161717 | T18: -61.486194 | U18: 4.1101038 | W18: -20.583226 | X18: 4.0001766 | Z18: 11.958291 | AA18: 1.1733206
A19: Canada | B19: 34.969966 | C19: 1.4227691 | E19: 520.08552 | F19: 1.7997162 | H19: 524.68102 | I19: 1.633461 | K19: 521.71187 | L19: 3.0378807 | N19: 535.21126 | O19: 3.8710754 | Q19: 507.56569 | R19: 3.6246895 | T19: -2.969153 | U19: 2.9340387 | W19: -0.55934083 | X19: 2.5675253 | Z19: 26.171212 | AA19: 1.163767
A20: Chile | B20: 3.3908615 | C20: 0.38959487 | E20: 452.27255 | F20: 2.6437662 | H20: 456.19479 | I20: 2.7163774 | K20: 437.76713 | L20: 7.4834392 | N20: 447.05769 | O20: 18.30035 | Q20: 435.38355 | R20: 8.4970364 | T20: -18.427664 | U20: 7.0907932 | W20: -13.944888 | X20: 6.9350897 | Z20: 18.620008 | AA20: 2.9226844
A21: Colombia | B21: 0.55659208 | C21: 0.12058001 | E21: 412.29509 | F21: 3.2513437 | H21: 414.21725 | I21: 3.3107893 | K21: 355.44416 | L21: 13.867266 | N21: c | O21: c | Q21: c | R21: c | T21: -58.77309 | U21: 13.58002 | W21: -45.935667 | X21: 11.235457 | Z21: 13.48085 | AA21: 5.3270447
A22: Czech Republic | B22: 4.1464036 | C22: 0.38608927 | E22: 490.21882 | F22: 2.5478509 | H22: 493.06561 | I22: 2.4655619 | K22: 439.84246 | L22: 9.7407124 | N22: 459.45838 | O22: 10.489841 | Q22: 421.01253 | R22: 14.445681 | T22: -53.223146 | U22: 9.3556898 | W22: -34.182201 | X22: 7.3245325 | Z22: 12.328681 | AA22: 2.5039197
A23: Denmark | B23: 10.653251 | C23: 0.43829698 | E23: 501.12993 | F23: 1.7954575 | H23: 509.43313 | I23: 1.8802014 | K23: 444.01161 | L23: 3.51761 | N23: 446.53503 | O23: 3.7389257 | Q23: 434.57382 | R23: 7.4277439 | T23: -65.421517 | U23: 3.8397758 | W23: -34.382163 | X23: 3.7292618 | Z23: 9.3137141 | AA23: 1.2089118
A24: Estonia | B24: 10.392583 | C24: 0.46505303 | E24: 523.01702 | F24: 1.8422422 | H24: 528.28938 | I24: 1.8949545 | K24: 489.34546 | L24: 4.5428461 | N24: 492.16591 | O24: 4.8818743 | Q24: 452.88086 | R24: 16.831925 | T24: -38.943925 | U24: 4.6335749 | W24: -34.784561 | X24: 4.4626503 | Z24: 13.645164 | AA24: 1.5280881
A25: Finland | B25: 5.7757806 | C25: 0.47656616 | E25: 520.07875 | F25: 2.307102 | H25: 527.46534 | I25: 2.0653459 | K25: 435.26771 | L25: 7.4636437 | N25: 455.64754 | O25: 10.280568 | Q25: 420.21567 | R25: 8.9588837 | T25: -92.197637 | U25: 7.2739799 | W25: -74.453261 | X25: 6.7469277 | Z25: 7.925234 | AA25: 1.8380393
A26: France | B26: 14.292398 | C26: 0.93597143 | E26: 492.60648 | F26: 2.3209786 | H26: 501.62109 | I26: 2.7047716 | K26: 449.4669 | L26: 5.2803394 | N26: 461.32402 | O26: 5.725192 | Q26: 425.15799 | R26: 7.4824822 | T26: -52.154184 | U26: 6.1854978 | W26: -12.513224 | X26: 5.0499827 | Z26: 13.387354 | AA26: 1.7492732
A27: Germany | B27: 22.168808 | C27: 1.1487898 | E27: 498.27926 | F27: 3.0254079 | H27: 518.89768 | I27: 3.3154584 | K27: 456.09491 | L27: 6.4947134 | N27: 477.30587 | O27: 6.6207429 | Q27: 404.54593 | R27: 11.754542 | T27: -62.802761 | U27: 6.788329 | W27: -17.307426 | X27: 5.614662 | Z27: 15.951269 | AA27: 1.713528
A28: Greece | B28: 11.696103 | C28: 0.66265155 | E28: 457.41439 | F28: 3.6209997 | H28: 465.21237 | I28: 3.4340115 | K28: 413.88989 | L28: 6.1000894 | N28: 420.11794 | O28: 6.9111881 | Q28: 397.01116 | R28: 9.1962335 | T28: -51.322484 | U28: 5.3218911 | W28: -22.057417 | X28: 5.0848347 | Z28: 12.114292 | AA28: 1.7343942
A29: Hungary | B29: 2.5521961 | C29: 0.30831545 | E29: 475.98667 | F29: 2.2509621 | H29: 476.65005 | I29: 2.2839301 | K29: 489.69457 | L29: 9.7957599 | N29: 509.92332 | O29: 11.126283 | Q29: 468.38285 | R29: 16.473515 | T29: 13.044523 | U29: 9.6969175 | W29: -6.8907017 | X29: 9.3982188 | Z29: 30.955939 | AA29: 5.3374465
A30: Iceland | B30: 5.5922791 | C30: 0.40139674 | E30: 473.97432 | F30: 1.7415106 | H30: 480.61498 | I30: 1.8486401 | K30: 406.81495 | L30: 7.6485079 | N30: 412.43603 | O30: 10.851301 | Q30: 402.31925 | R30: 9.516608 | T30: -73.800037 | U30: 8.0182293 | W30: -54.554196 | X30: 7.9106982 | Z30: 7.0376725 | AA30: 2.5554542
A31: Ireland | B31: 17.860839 | C31: 0.91486177 | E31: 518.07846 | F31: 2.2444778 | H31: 522.14707 | I31: 2.2619281 | K31: 508.47065 | L31: 3.8318043 | N31: 508.81138 | O31: 5.2604256 | Q31: 508.19142 | R31: 5.2883873 | T31: -13.676427 | U31: 3.7656264 | W31: -9.1506771 | X31: 3.2321568 | Z31: 21.577211 | AA31: 1.5370106
A32: Israel | B32: 16.416253 | C32: 1.0738364 | E32: 470.41518 | F32: 3.6709853 | H32: 480.54756 | I32: 3.501449 | K32: 469.79154 | L32: 6.6289829 | N32: 492.67148 | O32: 6.1346967 | Q32: 398.46818 | R32: 10.44041 | T32: -10.756017 | U32: 6.3544 | W32: 6.160572 | X32: 5.2910024 | Z32: 24.347764 | AA32: 1.835965
A33: Italy | B33: 10.025087 | C33: 0.49170849 | E33: 476.28468 | F33: 2.4389103 | H33: 482.401 | I33: 2.6006131 | K33: 439.57329 | L33: 4.8650843 | N33: 444.9724 | O33: 5.8631757 | Q33: 433.11367 | R33: 7.1448041 | T33: -42.827717 | U33: 5.1257183 | W33: -22.200454 | X33: 3.9876932 | Z33: 14.070313 | AA33: 1.5942714
A34: Japan | B34: 0.62269076 | C34: 0.13447374 | E34: 503.85604 | F34: 2.6709735 | H34: w | I34: w | K34: w | L34: w | N34: w | O34: w | Q34: w | R34: w | T34: w | U34: w | W34: w | X34: w | Z34: w | AA34: w
A35: Korea | B35: 0.16599464 | C35: 0.08987183 | E35: 514.05229 | F35: 2.940543 | H35: 515.12675 | I35: 2.9209104 | K35: c | L35: c | N35: c | O35: c | Q35: c | R35: c | T35: c | U35: c | W35: c | X35: c | Z35: m | AA35: m
A36: Latvia | B36: 4.4397198 | C36: 0.3368561 | E36: 478.69867 | F36: 1.6168558 | H36: 479.93389 | I36: 1.6005103 | K36: 475.8642 | L36: 8.7498953 | N36: 466.55716 | O36: 9.1518703 | Q36: 514.95121 | R36: 19.900105 | T36: -4.0696853 | U36: 8.7876719 | W36: -6.6806076 | X36: 8.138578 | Z36: 27.523448 | AA36: 3.8096114
A37: Lithuania | B37: 1.559925 | C37: 0.1305157 | E37: 475.87348 | F37: 1.5182764 | H37: 477.58021 | I37: 1.5352143 | K37: 457.02829 | L37: 11.073045 | N37: 453.72573 | O37: 11.498882 | Q37: 469.07288 | R37: 27.309359 | T37: -20.551922 | U37: 11.170091 | W37: -27.357543 | X37: 8.9973149 | Z37: 20.283333 | AA37: 4.2146134
A38: Luxembourg | B38: 54.871809 | C38: 0.64370888 | E38: 469.98539 | F38: 1.1258908 | H38: 490.54639 | I38: 1.9132343 | K38: 455.116 | L38: 1.6703589 | N38: 450.11428 | O38: 2.8600937 | Q38: 461.30841 | R38: 2.8734824 | T38: -35.430397 | U38: 2.8026168 | W38: -16.913718 | X38: 2.7535218 | Z38: 21.831594 | AA38: 0.74302601
A39: Mexico | B39: 1.5614212 | C39: 0.26845506 | E39: 420.46889 | F39: 2.7462789 | H39: 424.06068 | I39: 2.7798477 | K39: 328.34087 | L39: 14.4745 | N39: 331.75902 | O39: 13.436897 | Q39: 324.12159 | R39: 22.429701 | T39: -95.719809 | U39: 14.899681 | W39: -79.663081 | X39: 11.640307 | Z39: 7.2854592 | AA39: 3.4004797
A40: Netherlands* | B40: 13.767366 | C40: 1.1613432 | E40: 484.78373 | F40: 2.6508645 | H40: 497.77469 | I40: 2.9218823 | K40: 425.88382 | L40: 6.1727654 | N40: 432.66632 | O40: 6.6635329 | Q40: 398.65322 | R40: 13.027171 | T40: -71.890869 | U40: 7.1491177 | W40: -22.933468 | X40: 6.4901763 | Z40: 8.8990482 | AA40: 1.679251
A41: New Zealand | B41: 26.459841 | C41: 1.3482097 | E41: 505.72728 | F41: 2.0431431 | H41: 510.32752 | I41: 2.2911237 | K41: 508.0442 | L41: 3.4912752 | N41: 517.88793 | O41: 5.2859079 | Q41: 500.27103 | R41: 3.9806804 | T41: -2.283322 | U41: 4.0326144 | W41: -7.603639 | X41: 3.342158 | Z41: 26.497087 | AA41: 1.318802
A42: Norway | B42: 12.399896 | C42: 0.77280409 | E42: 499.45096 | F42: 2.1718488 | H42: 508.80829 | I42: 2.1337358 | K42: 456.68009 | L42: 4.6570035 | N42: 462.68581 | O42: 6.9735206 | Q42: 450.6463 | R42: 5.5088345 | T42: -52.128202 | U42: 4.4367654 | W42: -32.528382 | X42: 4.4566742 | Z42: 13.905681 | AA42: 1.4699074
A43: Poland | B43: 0.64312079 | C43: 0.190311 | E43: 511.8557 | F43: 2.702458 | H43: 513.57453 | I43: 2.6893653 | K43: c | L43: c | N43: c | O43: c | Q43: c | R43: c | T43: c | U43: c | W43: c | X43: c | Z43: m | AA43: m
A44: Portugal* | B44: 6.9632336 | C44: 0.57149007 | E44: 491.80079 | F44: 2.4289308 | H44: 495.22658 | I44: 2.5983994 | K44: 462.8518 | L44: 7.844581 | N44: 482.88275 | O44: 10.131723 | Q44: 435.70903 | R44: 9.0738008 | T44: -32.374778 | U44: 8.1806951 | W44: -26.342864 | X44: 6.2079931 | Z44: 17.119861 | AA44: 2.7920622
...

Sheet Table II.B1.9.4
A1: PISA 2018 Results (Volume II) - © OECD 2019
A2: Annex B1 | B2: Annex B1.9 Results (tables): Immigrant background and students’ performance
A3: Version 2 - Last updated: 02-Dec-2019
A4: Disclaimer: http://oe.cd/disclaimer
A6: Table II.B1.9.4
A7: Low performance in reading, by immigrant background
A8: Based on students' reports
B12: Percentage of immigrant students | E12: Percentage of low performers in reading (below Level 2) | T12: Likelihood of an immigrant student scoring below Level 2 in reading, compared to a non-immigrant student
E13: All students | H13: Non-immigrant students | K13: Immigrant students | N13: Second-generation immigrant students | Q13: First-generation immigrant students | T13: Before accounting for gender, and students' and schools' socio-economic profile1 | W13: After accounting for gender, and students' and schools' socio-economic profile
B14: % | C14: S.E. | D14: s | E14: % | F14: S.E. | G14: s | H14: % | I14: S.E. | J14: s | K14: % | L14: S.E. | M14: s | N14: % | O14: S.E. | P14: s | Q14: % | R14: S.E. | S14: s | T14: Odds ratio | U14: S.E. | V14: s | W14: Odds ratio | X14: S.E. | Y14: s
A15: OECD
A16: Australia | B16: 27.708763 | C16: 0.84465676 | E16: 19.627389 | F16: 0.49689006 | H16: 19.05872 | I16: 0.64898386 | K16: 18.376228 | L16: 0.94588801 | N16: 15.016953 | O16: 1.3397405 | Q16: 21.581698 | R16: 1.2749244 | T16: 0.95633854 | U16: 0.074674582 | W16: 0.94145003 | X16: 0.0732238
A17: Austria | B17: 22.686235 | C17: 1.1527353 | E17: 23.623262 | F17: 1.0177296 | H17: 18.275692 | I17: 0.92577673 | K17: 39.900604 | L17: 2.2125511 | N17: 35.994021 | O17: 2.3464851 | Q17: 47.354489 | R17: 2.9515814 | T17: 2.9693805 | U17: 0.31889027 | W17: 1.9740209 | X17: 0.23619908
A18: Belgium | B18: 18.059455 | C18: 0.8584751 | E18: 21.253462 | F18: 0.88050965 | H18: 16.629454 | I18: 0.86116092 | K18: 37.590828 | L18: 1.9041932 | N18: 32.532243 | O18: 2.1165319 | Q18: 44.205775 | R18: 2.8444487 | T18: 3.0208257 | U18: 0.2717492 | W18: 1.5968658 | X18: 0.19877522
A19: Canada | B19: 34.969966 | C19: 1.4227691 | E19: 13.750312 | F19: 0.49377054 | H19: 12.171901 | I19: 0.45534069 | K19: 13.983638 | L19: 0.90315204 | N19: 10.114305 | O19: 0.92000543 | Q19: 18.038362 | R19: 1.2887077 | T19: 1.1733176 | U19: 0.094246065 | W19: 1.1049763 | X19: 0.092266589
A20: Chile | B20: 3.3908615 | C20: 0.38959487 | E20: 31.720952 | F20: 1.1970505 | H20: 30.145426 | I20: 1.2158612 | K20: 38.564993 | L20: 4.5416233 | N20: 38.09135 | O20: 8.846299 | Q20: 38.686511 | R20: 4.9364579 | T20: 1.4603875 | U20: 0.27450599 | W20: 1.4261407 | X20: 0.31722987
A21: Colombia | B21: 0.55659208 | C21: 0.12058001 | E21: 49.903149 | F21: 1.7115931 | H21: 49.075613 | I21: 1.753948 | K21: 77.11628 | L21: 7.0242449 | N21: m | O21: m | Q21: m | R21: m | T21: 3.6145969 | U21: 1.8577844 | W21: 3.4521373 | X21: 1.8618269
A22: Czech Republic | B22: 4.1464036 | C22: 0.38608927 | E22: 20.740483 | F22: 1.1172124 | H22: 19.769722 | I22: 1.0783185 | K22: 37.689499 | L22: 4.8292608 | N22: 30.722856 | O22: 5.5628177 | Q22: 44.376995 | R22: 7.4911289 | T22: 2.4602468 | U22: 0.50462218 | W22: 1.9538343 | X22: 0.47262165
A23: Denmark | B23: 10.653251 | C23: 0.43829698 | E23: 15.999534 | F23: 0.68408443 | H23: 13.262135 | I23: 0.66268466 | K23: 35.348587 | L23: 1.7865264 | N23: 34.559289 | O23: 1.9768785 | Q23: 38.300631 | R23: 4.3082242 | T23: 3.5770921 | U23: 0.32586765 | W23: 2.0730059 | X23: 0.22733597
A24: Estonia | B24: 10.392583 | C24: 0.46505303 | E24: 11.054281 | F24: 0.59368212 | H24: 9.9138736 | I24: 0.60853261 | K24: 18.531069 | L24: 2.1485122 | N24: 17.496249 | O24: 2.2688755 | Q24: 31.909876 | R24: 7.6420314 | T24: 2.0697569 | U24: 0.33179882 | W24: 2.0170151 | X24: 0.33808753
A25: Finland | B25: 5.7757806 | C25: 0.47656616 | E25: 13.544526 | F25: 0.71193746 | H25: 11.204787 | I25: 0.603694 | K25: 39.871783 | L25: 3.9035262 | N25: 32.838802 | O25: 5.125141 | Q25: 45.066167 | R25: 4.5035027 | T25: 5.2645113 | U25: 0.87322863 | W25: 4.6357462 | X25: 0.86384965
A26: France | B26: 14.292398 | C26: 0.93597143 | E26: 20.93725 | F26: 0.74442562 | H26: 17.968072 | I26: 0.92780096 | K26: 34.95557 | L26: 2.3757278 | N26: 30.279551 | O26: 2.5183857 | Q26: 44.542127 | R26: 3.5812523 | T26: 2.4545149 | U26: 0.33569347 | W26: 1.2732359 | X26: 0.19992216
A27: Germany | B27: 22.168808 | C27: 1.1487898 | E27: 20.685095 | F27: 1.0533617 | H27: 14.327246 | I27: 1.0390999 | K27: 35.534285 | L27: 2.5318603 | N27: 27.651565 | O27: 2.513748 | Q27: 54.691663 | R27: 4.8192937 | T27: 3.2988764 | U27: 0.41550299 | W27: 1.7306615 | X27: 0.26396558
A28: Greece | B28: 11.696103 | C28: 0.66265155 | E28: 30.515796 | F28: 1.5099751 | H28: 27.40197 | I28: 1.4104558 | K28: 48.338951 | L28: 2.9963014 | N28: 44.799569 | O28: 3.5649693 | Q28: 57.931074 | R28: 4.9735337 | T28: 2.4804378 | U28: 0.26971728 | W28: 1.5900794 | X28: 0.20880261
A29: Hungary | B29: 2.5521961 | C29: 0.30831545 | E29: 25.273944 | F29: 0.90917236 | H29: 25.025533 | I29: 0.91136969 | K29: 19.330846 | L29: 4.6617288 | N29: 13.20601 | O29: 4.5186078 | Q29: 25.783585 | R29: 8.6157827 | T29: 0.71982385 | U29: 0.21145772 | W29: 1.2156398 | X29: 0.46600957
A30: Iceland | B30: 5.5922791 | C30: 0.40139674 | E30: 26.355899 | F30: 0.86142488 | H30: 23.913967 | I30: 0.86748807 | K30: 51.186767 | L30: 4.0712518 | N30: 51.410543 | O30: 6.3506123 | Q30: 51.007792 | R30: 4.9779404 | T30: 3.3421701 | U30: 0.56937302 | W30: 2.7088106 | X30: 0.52133534
A31: Ireland | B31: 17.860839 | C31: 0.91486177 | E31: 11.799349 | F31: 0.66913411 | H31: 10.85152 | I31: 0.6533151 | K31: 13.778555 | L31: 1.3382664 | N31: 15.208494 | O31: 2.0859865 | Q31: 12.606733 | R31: 1.7427275 | T31: 1.3128376 | U31: 0.15397205 | W31: 1.2118163 | X31: 0.1519677
A32: Israel | B32: 16.416253 | C32: 1.0738364 | E32: 31.062114 | F32: 1.3024957 | H32: 28.203038 | I32: 1.3181491 | K32: 29.544976 | L32: 2.1951571 | N32: 21.962096 | O32: 2.014555 | Q32: 53.183004 | R32: 3.955603 | T32: 1.0678268 | U32: 0.11406046 | W32: 0.79055121 | X32: 0.097584303
A33: Italy | B33: 10.025087 | C33: 0.49170849 | E33: 23.267173 | F33: 0.96900308 | H33: 21.006761 | I33: 1.0012391 | K33: 36.609243 | L33: 2.7269351 | N33: 33.944195 | O33: 3.3493517 | Q33: 39.797767 | R33: 4.0774505 | T33: 2.1752784 | U33: 0.28214019 | W33: 1.6893256 | X33: 0.24233349
A34: Japan | B34: 0.62269076 | C34: 0.13447374 | E34: 16.779171 | F34: 0.96372667 | H34: w | I34: w | K34: w | L34: w | N34: w | O34: w | Q34: w | R34: w | T34: w | U34: w | W34: w | X34: w
A35: Korea | B35: 0.16599464 | C35: 0.08987183 | E35: 15.108271 | F35: 0.90521412 | H35: 14.782884 | I35: 0.89507705 | K35: m | L35: m | N35: m | O35: m | Q35: m | R35: m | T35: c | U35: c | W35: c | X35: c
A36: Latvia | B36: 4.4397198 | C36: 0.3368561 | E36: 22.442881 | F36: 0.74903948 | H36: 21.764437 | I36: 0.74520733 | K36: 27.338382 | L36: 3.6194268 | N36: 28.686752 | O36: 4.3078541 | Q36: 21.675599 | R36: 6.4115182 | T36: 1.3539284 | U36: 0.24776693 | W36: 1.436491 | X36: 0.27893128
A37: Lithuania | B37: 1.559925 | C37: 0.1305157 | E37: 24.363296 | F37: 0.75310711 | H37: 23.730157 | I37: 0.75109947 | K37: 31.782731 | L37: 5.3078637 | N37: 31.977712 | O37: 5.5879207 | Q37: 31.071625 | R37: 12.017528 | T37: 1.5010323 | U37: 0.37360013 | W37: 2.0344823 | X37: 0.51626452
A38: Luxembourg | B38: 54.871809 | C38: 0.64370888 | E38: 29.291415 | F38: 0.57021144 | H38: 20.299658 | I38: 0.98617486 | K38: 35.872895 | L38: 0.82870351 | N38: 36.184404 | O38: 1.3579188 | Q38: 35.487228 | R38: 1.3752142 | T38: 2.1990514 | U38: 0.17032247 | W38: 1.6405512 | X38: 0.15646221
A39: Mexico | B39: 1.5614212 | C39: 0.26845506 | E39: 44.694002 | F39: 1.3290781 | H39: 43.233436 | I39: 1.3409184 | K39: 84.48917 | L39: 5.1776248 | N39: 85.716085 | O39: 5.4488416 | Q39: 82.974695 | R39: 8.7090179 | T39: 7.2560334 | U39: 3.0834639 | W39: 6.5605703 | X39: 2.638157
A40: Netherlands* | B40: 13.767366 | C40: 1.1613432 | E40: 24.086606 | F40: 1.0277694 | H40: 19.606146 | I40: 1.0935784 | K40: 43.540427 | L40: 3.1049196 | N40: 40.391646 | O40: 3.4558043 | Q40: 56.182254 | R40: 5.8236744 | T40: 3.1681963 | U40: 0.47596131 | W40: 1.5016786 | X40: 0.28064004
A41: New Zealand | B41: 26.459841 | C41: 1.3482097 | E41: 18.96356 | F41: 0.79043097 | H41: 17.125094 | I41: 0.85435668 | K41: 18.98572 | L41: 1.3218681 | N41: 16.171329 | O41: 1.7145607 | Q41: 21.208122 | R41: 1.6573724 | T41: 1.1348576 | U41: 0.11102972 | W41: 1.2719747 | X41: 0.12595754
A42: Norway | B42: 12.399896 | C42: 0.77280409 | E42: 19.292981 | F42: 0.76939762 | H42: 16.444308 | I42: 0.71513073 | K42: 32.162107 | L42: 2.1076935 | N42: 29.104464 | O42: 2.8828679 | Q42: 35.234038 | R42: 2.6487154 | T42: 2.4101654 | U42: 0.2466798 | W42: 1.8737689 | X42: 0.20868744
A43: Poland | B43: 0.64312079 | C43: 0.190311 | E43: 14.675607 | F43: 0.75161379 | H43: 14.176869 | I43: 0.73833438 | K43: m | L43: m | N43: m | O43: m | Q43: m | R43: m | T43: c | U43: c | W43: c | X43: c
A44: Portugal* | B44: 6.9632336 | C44: 0.57149007 | E44: 20.221871 | F44: 0.91671452 | H44: 19.161594 | I44: 0.97582166 | K44: 29.576863 | L44: 3.5330476 | N44: 24.431433 | O44: 4.7150258 | Q44: 36.549134 | R44: 4.4967842 | T44: 1.7731845 | U44: 0.32208255 | W44: 1.7504579 | X44: 0.27797431
...

Sheet Table II.B1.9.5
A1: PISA 2018 Results (Volume II) - © OECD 2019
A2: Annex B1 | B2: Annex B1.9 Results (tables): Immigrant background and students’ performance
A3: Version 2 - Last updated: 02-Dec-2019
A4: Disclaimer: http://oe.cd/disclaimer
A6: Table II.B1.9.5
A7: Students who expect to complete tertiary education, by immigrant background
A8: Based on students' reports
B12: Percentage of immigrant students | E12: Percentage of students who expect to complete tertiary education (ISCED 5B, ISCED 5A or 6) | T12: Likelihood of an immigrant student expecting to complete tertiary education, compared to a non-immigrant student
E13: All students | H13: Non-immigrant students | K13: Immigrant students | N13: Second-generation immigrant students | Q13: First-generation immigrant students | T13: Before accounting for gender, students' and schools' socio-economic profile,1 and performance in reading | W13: After accounting for gender, students' and schools' socio-economic profile, and performance in reading
B14: % | C14: S.E. | D14: s | E14: % | F14: S.E. | G14: s | H14: % | I14: S.E. | J14: s | K14: % | L14: S.E. | M14: s | N14: % | O14: S.E. | P14: s | Q14: % | R14: S.E. | S14: s | T14: Odds ratio | U14: S.E. | V14: s | W14: Odds ratio | X14: S.E. | Y14: s
A15: OECD
A16: Australia | B16: 27.708763 | C16: 0.84465676 | E16: 68.221511 | F16: 0.64789184 | H16: 64.190527 | I16: 0.68199189 | K16: 80.338087 | L16: 0.83878959 | N16: 80.744083 | O16: 1.1214215 | Q16: 79.94741 | R16: 1.188453 | T16: 2.2794113 | U16: 0.12219176 | W16: 2.7750833 | X16: 0.20329526
A17: Austria | B17: 22.686235 | C17: 1.1527353 | E17: 47.995764 | F17: 0.8744499 | H17: 49.240754 | I17: 0.97519151 | K17: 44.330981 | L17: 1.9975281 | N17: 43.367865 | O17: 2.2596832 | Q17: 46.222426 | R17: 2.9433085 | T17: 0.82088868 | U17: 0.074567433 | W17: 1.6958534 | X17: 0.14820156
A18: Belgium | B18: 18.059455 | C18: 0.8584751 | E18: 68.847502 | F18: 0.81681154 | H18: 70.128293 | I18: 0.90650609 | K18: 64.973042 | L18: 1.8300823 | N18: 67.462837 | O18: 2.064159 | Q18: 61.561919 | R18: 3.1212322 | T18: 0.79012817 | U18: 0.071593586 | W18: 2.4005653 | X18: 0.22922975
A19: Canada | B19: 34.969966 | C19: 1.4227691 | E19: 87.031687 | F19: 0.43385762 | H19: 85.33088 | I19: 0.50581011 | K19: 91.571449 | L19: 0.56822582 | N19: 91.44343 | O19: 0.83249105 | Q19: 91.708309 | R19: 0.67256867 | T19: 1.8676912 | U19: 0.14270387 | W19: 2.3877922 | X19: 0.20560329
A20: Chile | B20: 3.3908615 | C20: 0.38959487 | E20: 84.79319 | F20: 0.78573155 | H20: 85.582587 | I20: 0.76981118 | K20: 78.311119 | L20: 3.0064516 | N20: 77.267718 | O20: 7.6770836 | Q20: 78.586871 | R20: 3.2442575 | T20: 0.60825792 | U20: 0.10007202 | W20: 0.62354371 | X20: 0.10881797
A21: Colombia | B21: 0.55659208 | C21: 0.12058001 | E21: 75.638973 | F21: 1.1610288 | H21: 76.360445 | I21: 1.1169011 | K21: 52.109904 | L21: 7.3939241 | N21: m | O21: m | Q21: m | R21: m | T21: 0.33685687 | U21: 0.10278807 | W21: 0.57692474 | X21: 0.22505222
A22: Czech Republic | B22: 4.1464036 | C22: 0.38608927 | E22: 64.470246 | F22: 1.0921513 | H22: 64.729943 | I22: 1.1112181 | K22: 61.670971 | L22: 3.7686917 | N22: 57.993124 | O22: 5.9525537 | Q22: 65.226812 | R22: 4.808493 | T22: 0.87670535 | U22: 0.14368706 | W22: 2.1084285 | X22: 0.6346149
A23: Denmark | B23: 10.653251 | C23: 0.43829698 | E23: 64.046861 | F23: 0.8723983 | H23: 64.833007 | I23: 0.9540549 | K23: 59.278342 | L23: 1.9653641 | N23: 62.138367 | O23: 2.1612314 | Q23: 47.322311 | R23: 4.7246941 | T23: 0.78960461 | U23: 0.071487927 | W23: 2.3069043 | X23: 0.26039411
A24: Estonia | B24: 10.392583 | C24: 0.46505303 | E24: 69.994719 | F24: 0.87139162 | H24: 70.807517 | I24: 0.89998457 | K24: 63.151193 | L24: 2.2292445 | N24: 62.799699 | O24: 2.1970215 | Q24: 67.776032 | R24: 8.7757275 | T24: 0.70656124 | U24: 0.067805564 | W24: 0.93792282 | X24: 0.099788019
A25: Finland | B25: 5.7757806 | C25: 0.47656616 | E25: 63.581351 | F25: 0.92649226 | H25: 63.512535 | I25: 0.9470632 | K25: 68.027606 | L25: 2.8012323 | N25: 69.328861 | O25: 4.1308496 | Q25: 67.059691 | R25: 3.9013893 | T25: 1.2223463 | U25: 0.15747674 | W25: 3.0032599 | X25: 0.49952176
A26: France | B26: 14.292398 | C26: 0.93597143 | E26: 78.338752 | F26: 0.65863516 | H26: 78.935194 | I26: 0.75197754 | K26: 76.055548 | L26: 1.8700014 | N26: 76.624451 | O26: 2.226091 | Q26: 74.8723 | R26: 3.0046894 | T26: 0.84764263 | U26: 0.10080446 | W26: 1.2968393 | X26: 0.15686466
A27: Germany | B27: 22.168808 | C27: 1.1487898 | E27: 33.867804 | F27: 1.0822312 | H27: 35.072044 | I27: 1.2522886 | K27: 29.195027 | L27: 1.9355305 | N27: 28.810965 | O27: 2.3235475 | Q27: 30.255068 | R27: 3.1268406 | T27: 0.76333605 | U27: 0.076074581 | W27: 2.2081997 | X27: 0.27157509
A28: Greece | B28: 11.696103 | C28: 0.66265155 | E28: 74.359132 | F28: 1.1717291 | H28: 77.097512 | I28: 1.1421831 | K28: 58.804914 | L28: 2.2333888 | N28: 60.076185 | O28: 2.6835904 | Q28: 55.262518 | R28: 3.8681868 | T28: 0.42404355 | U28: 0.043223228 | W28: 0.91934722 | X28: 0.096728056
A29: Hungary | B29: 2.5521961 | C29: 0.30831545 | E29: 51.487974 | F29: 0.97522539 | H29: 51.358003 | I29: 0.97611134 | K29: 61.021221 | L29: 4.6173923 | N29: 69.700998 | O29: 5.8984113 | Q29: 51.061248 | R29: 7.254997 | T29: 1.482709 | U29: 0.28174459 | W29: 1.0734101 | X29: 0.23922198
A30: Iceland | B30: 5.5922791 | C30: 0.40139674 | E30: 61.921049 | F30: 0.79523593 | H30: 62.516042 | I30: 0.81507106 | K30: 55.258144 | L30: 3.8007394 | N30: 59.899983 | O30: 5.9183613 | Q30: 51.544382 | R30: 4.92374 | T30: 0.74051911 | U30: 0.11820082 | W30: 1.4239196 | X30: 0.276291
A31: Ireland | B31: 17.860839 | C31: 0.91486177 | E31: 79.665788 | F31: 0.81443542 | H31: 79.530176 | I31: 0.89082861 | K31: 81.506858 | L31: 1.2866674 | N31: 82.904266 | O31: 2.0922746 | Q31: 80.365835 | R31: 1.9724976 | T31: 1.1343984 | U31: 0.10259043 | W31: 1.4674023 | X31: 0.15321261
A32: Israel | B32: 16.416253 | C32: 1.0738364 | E32: 73.045336 | F32: 1.0014097 | H32: 74.815623 | I32: 0.9493842 | K32: 75.336486 | L32: 1.9193543 | N32: 79.461505 | O32: 1.8534103 | Q32: 62.521932 | R32: 3.224379 | T32: 1.0282277 | U32: 0.10719074 | W32: 1.1991443 | X32: 0.12995515
A33: Italy | B33: 10.025087 | C33: 0.49170849 | E33: 60.521423 | F33: 0.76911641 | H33: 61.927552 | I33: 0.82172834 | K33: 49.913046 | L33: 2.4779536 | N33: 49.76758 | O33: 3.2305066 | Q33: 50.087539 | R33: 3.3088738 | T33: 0.6126555 | U33: 0.062395522 | W33: 1.0736051 | X33: 0.11543577
A34: Japan | B34: 0.62269076 | C34: 0.13447374 | E34: 74.129605 | F34: 0.78129151 | H34: w | I34: w | K34: w | L34: w | N34: w | O34: w | Q34: w | R34: w | T34: w | U34: w | W34: w | X34: w
A35: Korea | B35: 0.16599464 | C35: 0.08987183 | E35: 89.418545 | F35: 0.71013239 | H35: 89.795852 | I35: 0.68950655 | K35: m | L35: m | N35: m | O35: m | Q35: m | R35: m | T35: c | U35: c | W35: c | X35: c
A36: Latvia | B36: 4.4397198 | C36: 0.3368561 | E36: 64.591091 | F36: 0.79228904 | H36: 64.92474 | I36: 0.80154885 | K36: 59.849599 | L36: 3.3540954 | N36: 56.154185 | O36: 3.8128809 | Q36: 75.002589 | R36: 5.2086408 | T36: 0.80530805 | U36: 0.117671 | W36: 0.74020203 | X36: 0.11520957
A37: Lithuania | B37: 1.559925 | C37: 0.1305157 | E37: 71.662926 | F37: 0.62848954 | H37: 71.956011 | I37: 0.64232665 | K37: 75.88011 | L37: 4.0599349 | N37: 78.629872 | O37: 3.6982146 | Q37: 65.811664 | R37: 11.613133 | T37: 1.2260984 | U37: 0.2911998 | W37: 1.5208338 | X37: 0.39315943
A38: Luxembourg | B38: 54.871809 | C38: 0.64370888 | E38: 61.531793 | F38: 0.59916659 | H38: 64.683529 | I38: 1.0441016 | K38: 59.499127 | L38: 0.8330544 | N38: 56.017162 | O38: 1.1668764 | Q38: 63.893912 | R38: 1.324219 | T38: 0.80210239 | U38: 0.048869437 | W38: 1.4123638 | X38: 0.095618842
A39: Mexico | B39: 1.5614212 | C39: 0.26845506 | E39: 83.319381 | F39: 0.75392855 | H39: 83.632022 | I39: 0.7585209 | K39: 77.439513 | L39: 7.200345 | N39: 68.213288 | O39: 10.975166 | P39: † | Q39: 86.392272 | R39: 7.1145698 | T39: 0.67179461 | U39: 0.31017901 | W39: 1.6941102 | X39: 0.8721825
A40: Netherlands* | B40: 13.767366 | C40: 1.1613432 | E40: 68.905295 | F40: 0.93849529 | H40: 68.247374 | I40: 0.9975936 | K40: 74.216941 | L40: 2.8633159 | M40: † | N40: 73.814198 | O40: 3.1932626 | Q40: 76.365751 | R40: 5.4710083 | S40: † | T40: 1.339252 | U40: 0.2178938 | W40: 5.21647 | X40: 1.1785099
A41: New Zealand | B41: 26.459841 | C41: 1.3482097 | E41: 61.084563 | F41: 0.87133945 | H41: 57.436913 | I41: 0.92240742 | K41: 72.434293 | L41: 1.2870549 | N41: 73.132248 | O41: 1.7312712 | Q41: 71.876329 | R41: 1.5656844 | T41: 1.9472293 | U41: 0.14504201 | W41: 2.205462 | X41: 0.18555081
A42: Norway | B42: 12.399896 | C42: 0.77280409 | E42: 67.507633 | F42: 0.96547131 | H42: 66.525062 | I42: 1.0031022 | K42: 77.508844 | L42: 1.9519031 | N42: 79.363594 | O42: 2.5779669 | Q42: 75.639545 | R42: 2.3443096 | T42: 1.7340993 | U42: 0.19602843 | W42: 4.5608479 | X42: 0.62394291
A43: Poland | B43: 0.64312079 | C43: 0.190311 | E43: 56.994551 | F43: 1.0911237 | H43: 57.025646 | I43: 1.0979292 | K43: m | L43: m | N43: m | O43: m | Q43: m | R43: m | T43: c | U43: c | W43: c | X43: c
A44: Portugal* | B44: 6.9632336 | C44: 0.57149007 | E44: 73.625121 | F44: 0.79783622 | H44: 74.419148 | I44: 0.85084601 | K44: 66.442321 | L44: 3.4976013 | N44: 72.64048 | O44: 3.9128575 | Q44: 57.664923 | R44: 5.8734807 | T44: 0.6805863 | U44: 0.11494183 | W44: 0.88846746 | X44: 0.14676039
...

Sheet Table II.B1.9.6
A1: PISA 2018 Results (Volume II) - © OECD 2019
A2: Annex B1 | B2: Annex B1.9 Results (tables): Immigrant background and students’ performance
A3: Version 2 - Last updated: 02-Dec-2019
A4: Disclaimer: http://oe.cd/disclaimer
A6: Table II.B1.9.6
A7: Percentage of academically resilient immigrant students, by quarter of key indices
A8: Based on students' reports
B11: Percentage of academically resilient immigrant students,1 by national quarter of the following indices | DC11: Percentage of academically resilient immigrant students, amongst students who exhibited or did not exhibit a growth mindset4
B12: Index of parents' emotional support | Q12: Index of teacher support | AF12: Index of teacher enthusiasm2 | AU12: Index of self-efficacy3 | BJ12: Index of disciplinary climate | BY12: Index of student co-operation | CN12: Index of student competition
B13: Bottom quarter | E13: Second quarter | H13: Third quarter | K13: Top quarter | N13: Difference Top - Bottom | Q13: Bottom quarter | T13: Second quarter | W13: Third quarter | Z13: Top quarter | AC13: Difference Top - Bottom | AF13: Bottom quarter | AI13: Second quarter | AL13: Third quarter | AO13: Top quarter | AR13: Difference Top - Bottom | AU13: Bottom quarter | AX13: Second quarter | BA13: Third quarter | BD13: Top quarter | BG13: Difference Top - Bottom | BJ13: Bottom quarter | BM13: Second quarter | BP13: Third quarter | BS13: Top quarter | BV13: Difference Top - Bottom | BY13: Bottom quarter | CB13: Second quarter | CE13: Third quarter | CH13: Top quarter | CK13: Difference Top - Bottom | CN13: Bottom quarter | CQ13: Second quarter | CT13: Third quarter | CW13: Top quarter | CZ13: Difference Top - Bottom | DC13: Students did not exhibit a growth mindset | DF13: Students exhibited a growth mindset | DI13: Difference between students who exhibited a growth mindset and those who did not
