Workbook

Sheet TOC
A1: PISA 2018 Results (Volume III) - © OECD 2019
A2: Annex B1 | B2: Annex B1.11 Results (tables): Students' life satisfaction and meaning in life
A3: Version 2 - Last updated: 02-Dec-2019
A4: Disclaimer: http://oe.cd/disclaimer
A6: TOC | B6: PISA 2018 Results - Volume III
A8: Chapter 11 | B8: Students' life satisfaction and sense of meaning in life
A9: Tables
A11: ='Table III.B1.11.1'!A6 -> Table III.B1.11.1 | B11: ='Table III.B1.11.1'!$A$7 -> Students' life satisfaction
A12: ='Table III.B1.11.2'!A6 -> Table III.B1.11.2 | B12: ='Table III.B1.11.2'!$A$7 -> Change between 2015 and 2018 in students' levels of life satisfaction
A13: ='Table III.B1.11.3'!A6 -> Table III.B1.11.3 | B13: ='Table III.B1.11.3'!$A$7 -> Prevalence of students who are not satisfied with life
A14: ='Table III.B1.11.4'!A6 -> Table III.B1.11.4 | B14: ='Table III.B1.11.4'!$A$7 -> Satisfied students, by student characteristics
A15: ='Table III.B1.11.5'!A6 -> Table III.B1.11.5 | B15: ='Table III.B1.11.5'!$A$7 -> Students who are not satisfied with life, by student characteristics
A16: ='Table III.B1.11.6'!A6 -> Table III.B1.11.6 | B16: ='Table III.B1.11.6'!$A$7 -> Students who are satisfied with life, by school characteristics
A17: ='Table III.B1.11.7'!A6 -> Table III.B1.11.7 | B17: ='Table III.B1.11.7'!$A$7 -> Students' life satisfaction and reading performance
A18: ='Table III.B1.11.8'!A6 -> Table III.B1.11.8 | B18: ='Table III.B1.11.8'!$A$7 -> School-level life satisfaction and reading performance
A19: ='Table III.B1.11.9'!A6 -> Table III.B1.11.9 | B19: ='Table III.B1.11.9'!$A$7 -> Change between 2015 and 2018 in students' average life satisfaction, by student characteristics
A20: ='Table III.B1.11.10'!A6 -> Table III.B1.11.10 | B20: ='Table III.B1.11.10'!$A$7 -> Students' satisfaction with life and school climate
A21: ='Table III.B1.11.11'!A6 -> Table III.B1.11.11 | B21: ='Table III.B1.11.11'!$A$7 -> Time spent on the Internet outside of school in 2012, 2015, 2018
A22: ='Table III.B1.11.12'!A6 -> Table III.B1.11.12 | B22: ='Table III.B1.11.12'!$A$7 -> Change between 2015 and 2018 in the relationship between Internet time and life satisfaction
A23: ='Table III.B1.11.13'!A6 -> Table III.B1.11.13 | B23: ='Table III.B1.11.13'!$A$7 -> Students' life satisfaction, by attitudes towards using the Internet
A24: ='Table III.B1.11.14'!A6 -> Table III.B1.11.14 | B24: ='Table III.B1.11.14'!$A$7 -> Students' sense of meaning in life
A25: ='Table III.B1.11.15'!A6 -> Table III.B1.11.15 | B25: ='Table III.B1.11.15'!$A$7 -> Index of meaning in life, by student characteristics
A26: ='Table III.B1.11.16'!A6 -> Table III.B1.11.16 | B26: ='Table III.B1.11.16'!$A$7 -> Index of meaning in life, by school characteristics
A27: ='Table III.B1.11.17'!A6 -> Table III.B1.11.17 | B27: ='Table III.B1.11.17'!$A$7 -> Students' sense of meaning in life and school climate
A28: ='Table III.B1.11.18'!A6 -> Table III.B1.11.18 | B28: ='Table III.B1.11.18'!$A$7 -> Students' sense of meaning in life and reading performance
A29: ='Table III.B1.11.19'!A6 -> Table III.B1.11.19 | B29: ='Table III.B1.11.19'!$A$7 -> Individual components of students' sense of meaning in life and reading performance
A30: ='Table III.B1.11.20'!A6 -> Table III.B1.11.20 | B30: ='Table III.B1.11.20'!$A$7 -> Students' sense of meaning in life, by student truancy and lateness
A31: ='Table III.B1.11.21'!A6 -> Table III.B1.11.21 | B31: ='Table III.B1.11.21'!$A$7 -> Students' satisfaction with life and sense of meaning in life
A34: Symbols for missing data
A35: c: There were too few observations to provide reliable estimates (i.e. there were fewer than 30 students or fewer than 5 schools with valid data).
A36: m: Data are not available. There are no observations in the sample; these data were not collected by the country; or these data were collected but subsequently removed from the publication for technical reasons.
A37: w: Results were withdrawn at the request of the country concerned.

Sheet INFORMATION ON SCALED INDICES
A1: PISA 2018 Results (Volume III) - © OECD 2019
A2: Annex B1 | B2: Annex B1.11 Results (tables): Students' life satisfaction and meaning in life
A3: Version 2 - Last updated: 02-Dec-2019
A4: Disclaimer: http://oe.cd/disclaimer
A6: Information on scaled indices used in PISA 2015 Results (Volume III): What School Life Means for Students’ Lives
A11: Full name of the index | B11: Name in dataset | C11: Questionnaire | D11: Item 1 | E11: Item 2 | F11: Item 3 | G11: Item 4 | H11: Item 5 | I11: Item 6 | J11: Item 7
A12: Adaptive instruction | B12: adaptivity | C12: Student | D12: ST212Q01HA | E12: ST212Q02HA | F12: ST212Q03HA
A13: Attitudes towards competition | B13: compete | C13: Student | D13: ST181Q02HA | E13: ST181Q03HA | F13: ST181Q04HA
A14: Enjoyment of reading | B14: joyread | C14: Student | D14: ST160Q01IR | E14: ST160Q02IA | F14: ST160Q03IA | G14: ST160Q04IR | H14: ST160Q05IR
A15: Exposure to bullying | B15: beingbullied | C15: Student | D15: ST038Q03NA | E15: ST038Q04NA | F15: ST038Q05NA
A16: Fear of failure | B16: gfofail | C16: Student | D16: ST183Q01HA | E16: ST183Q02HA | F16: ST183Q03HA
A17: Disciplinary climate | B17: disclima | C17: Student | D17: ST097Q01TA | E17: ST097Q02TA | F17: ST097Q03TA | G17: ST097Q04TA | H17: ST097Q05TA
A18: Learning goals | B18: mastgoal | C18: Student | D18: ST208Q01HA | E18: ST208Q02HA | F18: ST208Q04HA
A19: Meaning in life | B19: eudmo | C19: Student | D19: ST185Q01HA | E19: ST185Q02HA | F19: ST185Q03HA
A20: Motivation to master tasks | B20: workmast | C20: Student | D20: ST182Q03HA | E20: ST182Q04HA | F20: ST182Q05HA
A21: Parents’ emotional support | B21: emosups | C21: Student | D21: ST123Q02NA | E21: ST123Q03NA | F21: ST123Q04NA
A22: Parents’ perceived school quality | B22: pqschool | C22: Parent | D22: PA007Q01TR | E22: PA007Q02TR | F22: PA007Q03TR | G22: PA007Q04TR | H22: PA007Q05TR | I22: PA007Q06TR | J22: PA007Q07TR
A23: Positive feelings | B23: swbp | C23: Student | D23: ST186Q01HA | E23: ST186Q03HA | F23: ST186Q05HA
A24: School policies for parental involvement | B24: paschpol | C24: Parent | D24: PA007Q09NR | E24: PA007Q11NR | F24: PA007Q12NR | G24: PA007Q13NR | H24: PA007Q14NR | I24: PA007Q15NR
A25: Self-efficacy | B25: resilience | C25: Student | D25: ST188Q01HA | E25: ST188Q02HA | F25: ST188Q03HA | G25: ST188Q06HA | H25: ST188Q07HA
A26: Sense of belonging | B26: belong | C26: Student | D26: ST034Q01TA | E26: ST034Q02TR | F26: ST034Q03TR | G26: ST034Q04TA | H26: ST034Q05TR | I26: ST034Q06TA
A27: Shortage of educational staff | B27: staffshort | C27: School | D27: SC017Q01NA | E27: SC017Q02NA | F27: SC017Q03NA | G27: SC017Q04NA
A28: Student competition | B28: percomp | C28: Student | D28: ST205Q01HA | E28: ST205Q02HA | F28: ST205Q03HA
A29: Student co-operation | B29: percoop | C29: Student | D29: ST206Q01HA | E29: ST206Q02HA | F29: ST206Q03HA
A30: Teacher behaviour hindering learning | B30: teachbeha | C30: School | D30: SC061Q06TA | E30: SC061Q07TA | F30: SC061Q08TA | G30: SC061Q09TA | H30: SC061Q10TA
A31: Teacher enthusiasm | B31: teachint | C31: Student | D31: ST213Q01HA | E31: ST213Q02HA | F31: ST213Q03HA | G31: ST213Q04HA
A32: Teacher feedback | B32: perfeed | C32: Student | D32: ST104Q02NA | E32: ST104Q03NA | F32: ST104Q04NA
A33: Teacher support | B33: teachsup | C33: Student | D33: ST100Q01TR | E33: ST100Q02TR | F33: ST100Q03TR | G33: ST100Q04TR
A34: Teacher-directed instruction | B34: dirins | C34: Student | D34: ST102Q01TR | E34: ST102Q02TR | F34: ST102Q03TR | G34: ST102Q04TR
A35: Teachers' stimulation of reading engagement | B35: stimread | C35: Student | D35: ST152Q05IA | E35: ST152Q06IA | F35: ST152Q07IA | G35: ST152Q08IA
A36: Value of school | B36: attlnact | C36: Student | D36: ST036Q05TR | E36: ST036Q06TR | F36: ST036Q08TR

Sheet Table III.B1.11.1
A1: PISA 2018 Results (Volume III) - © OECD 2019
A2: Annex B1 | B2: Annex B1.11 Results (tables): Students' life satisfaction and meaning in life
A3: Version 2 - Last updated: 02-Dec-2019
A4: Disclaimer: http://oe.cd/disclaimer
A6: Table III.B1.11.1
A7: Students' life satisfaction
A8: Based on students' reports
B12: Average life satisfaction | H12: Percentage of students who reported the following levels of life satisfaction:
B13: All students | E13: Variability | H13: 0-Not at all satisfied | K13: 1 | N13: 2 | Q13: 3 | T13: 4 | W13: 5 | Z13: 6 | AC13: 7 | AF13: 8 | AI13: 9 | AL13: 10-Completely satisfied
B14: Mean index | C14: S.E. | E14: S.D. | F14: S.E. | H14: % | I14: S.E. | K14: % | L14: S.E. | N14: % | O14: S.E. | Q14: % | R14: S.E. | T14: % | U14: S.E. | W14: % | X14: S.E. | Z14: % | AA14: S.E. | AC14: % | AD14: S.E. | AF14: % | AG14: S.E. | AI14: % | AJ14: S.E. | AL14: % | AM14: S.E.
A15: OECD
A16: Australia | B16: m | C16: m | E16: m | F16: m | H16: m | I16: m | K16: m | L16: m | N16: m | O16: m | Q16: m | R16: m | T16: m | U16: m | W16: m | X16: m | Z16: m | AA16: m | AC16: m | AD16: m | AF16: m | AG16: m | AI16: m | AJ16: m | AL16: m | AM16: m
A17: Austria | B17: 7.1367697 | C17: 0.043433545 | E17: 2.6001484 | F17: 0.029851469 | H17: 2.3222444 | I17: 0.21904687 | K17: 2.4018177 | L17: 0.19496222 | N17: 3.229879 | O17: 0.30059134 | Q17: 3.8945763 | R17: 0.23296555 | T17: 5.0903936 | U17: 0.30249276 | W17: 6.3810745 | X17: 0.39977783 | Z17: 7.08231 | AA17: 0.32612268 | AC17: 13.269853 | AD17: 0.50687436 | AF17: 19.122226 | AG17: 0.53739491 | AI17: 19.552173 | AJ17: 0.53560526 | AL17: 17.653453 | AM17: 0.62096252
A18: Belgium | B18: m | C18: m | E18: m | F18: m | H18: m | I18: m | K18: m | L18: m | N18: m | O18: m | Q18: m | R18: m | T18: m | U18: m | W18: m | X18: m | Z18: m | AA18: m | AC18: m | AD18: m | AF18: m | AG18: m | AI18: m | AJ18: m | AL18: m | AM18: m
A19: Canada | B19: m | C19: m | E19: m | F19: m | H19: m | I19: m | K19: m | L19: m | N19: m | O19: m | Q19: m | R19: m | T19: m | U19: m | W19: m | X19: m | Z19: m | AA19: m | AC19: m | AD19: m | AF19: m | AG19: m | AI19: m | AJ19: m | AL19: m | AM19: m
A20: Chile | B20: 7.0306785 | C20: 0.045276354 | E20: 2.7188046 | F20: 0.032903685 | H20: 2.9613225 | I20: 0.31042634 | K20: 2.3709231 | L20: 0.17772528 | N20: 2.8506362 | O20: 0.20022922 | Q20: 3.7104982 | R20: 0.20492891 | T20: 5.6921895 | U20: 0.33248975 | W20: 10.327127 | X20: 0.36974355 | Z20: 7.8367694 | AA20: 0.3157548 | AC20: 11.487251 | AD20: 0.46151723 | AF20: 15.484837 | AG20: 0.52581701 | AI20: 14.63476 | AJ20: 0.45215114 | AL20: 22.643685 | AM20: 0.65622805
A21: Colombia | B21: 7.6188194 | C21: 0.045362852 | E21: 2.6594104 | F21: 0.033568395 | H21: 2.4567092 | I21: 0.24276229 | K21: 1.8735089 | L21: 0.22347694 | N21: 2.3262101 | O21: 0.18678926 | Q21: 2.7936158 | R21: 0.23065904 | T21: 4.050952 | U21: 0.28736618 | W21: 7.8267317 | X21: 0.35707105 | Z21: 5.6912459 | AA21: 0.29835106 | AC21: 9.2199656 | AD21: 0.40073687 | AF21: 15.428183 | AG21: 0.53124575 | AI21: 13.803782 | AJ21: 0.48307542 | AL21: 34.529097 | AM21: 0.87713018
A22: Czech Republic | B22: 6.9143272 | C22: 0.04744092 | E22: 2.6583533 | F22: 0.028331959 | H22: 2.700043 | I22: 0.21692674 | K22: 2.9546437 | L22: 0.23905447 | N22: 3.1295418 | O22: 0.2481607 | Q22: 4.0895764 | R22: 0.27952108 | T22: 5.1605796 | U22: 0.30553031 | W22: 8.6501886 | X22: 0.41215576 | Z22: 8.562081 | AA22: 0.3897686 | AC22: 13.303188 | AD22: 0.49946975 | AF22: 18.557275 | AG22: 0.5318771 | AI22: 15.824825 | AJ22: 0.54437422 | AL22: 17.068058 | AM22: 0.72759029
A23: Denmark | B23: m | C23: m | E23: m | F23: m | H23: m | I23: m | K23: m | L23: m | N23: m | O23: m | Q23: m | R23: m | T23: m | U23: m | W23: m | X23: m | Z23: m | AA23: m | AC23: m | AD23: m | AF23: m | AG23: m | AI23: m | AJ23: m | AL23: m | AM23: m
A24: Estonia | B24: 7.1902235 | C24: 0.036984322 | E24: 2.4065945 | F24: 0.031064241 | H24: 1.7064287 | I24: 0.19034747 | K24: 1.7256654 | L24: 0.18750025 | N24: 2.461099 | O24: 0.26680426 | Q24: 3.1998702 | R24: 0.26289603 | T24: 5.3839636 | U24: 0.355113 | W24: 7.1182783 | X24: 0.34523778 | Z24: 8.5916179 | AA24: 0.43107874 | AC24: 15.049063 | AD24: 0.53847199 | AF24: 20.1778 | AG24: 0.55476549 | AI24: 18.530054 | AJ24: 0.64371159 | AL24: 16.05616 | AM24: 0.63285434
A25: Finland | B25: 7.6149144 | C25: 0.032945979 | E25: 2.1802721 | F25: 0.030614104 | H25: 1.0511253 | I25: 0.13278733 | K25: 1.3328563 | L25: 0.15103232 | N25: 1.4985791 | O25: 0.18858362 | Q25: 2.7932284 | R25: 0.19689432 | T25: 3.7176224 | U25: 0.2419033 | W25: 5.4314063 | X25: 0.27820326 | Z25: 6.5449441 | AA25: 0.28881974 | AC25: 11.394656 | AD25: 0.45085413 | AF25: 23.4232 | AG25: 0.54878234 | AI25: 27.787455 | AJ25: 0.6422346 | AL25: 15.024926 | AM25: 0.49728519
A26: France | B26: 7.1863724 | C26: 0.0341046 | E26: 2.2317956 | F26: 0.026660701 | H26: 1.2129879 | I26: 0.12677127 | K26: 1.4623561 | L26: 0.19063052 | N26: 1.7851585 | O26: 0.198899 | Q26: 2.7394005 | R26: 0.22090847 | T26: 4.5798899 | U26: 0.28982087 | W26: 8.675007 | X26: 0.43269446 | Z26: 9.9064664 | AA26: 0.40404078 | AC26: 17.728946 | AD26: 0.47222791 | AF26: 21.374025 | AG26: 0.56290012 | AI26: 16.199473 | AJ26: 0.54586214 | AL26: 14.336289 | AM26: 0.44377411
A27: Germany | B27: 7.0184656 | C27: 0.037607241 | E27: 2.5600242 | F27: 0.032710375 | H27: 2.1189007 | I27: 0.22883587 | K27: 2.2947911 | L27: 0.23028825 | N27: 2.6824431 | O27: 0.24642591 | Q27: 4.9191737 | R27: 0.34028252 | T27: 4.7306285 | U27: 0.34914532 | W27: 8.6597727 | X27: 0.42135817 | Z27: 8.0528081 | AA27: 0.51067421 | AC27: 14.004613 | AD27: 0.5258711 | AF27: 18.824946 | AG27: 0.70715459 | AI27: 16.859952 | AJ27: 0.60813271 | AL27: 16.85197 | AM27: 0.68636298
A28: Greece | B28: 6.9890418 | C28: 0.035741304 | E28: 2.4779131 | F28: 0.027684744 | H28: 2.2141515 | I28: 0.19998916 | K28: 1.9576419 | L28: 0.17974915 | N28: 2.4455394 | O28: 0.17800354 | Q28: 3.7393881 | R28: 0.21800909 | T28: 5.0467068 | U28: 0.29519233 | W28: 8.8508784 | X28: 0.37517265 | Z28: 10.2664 | AA28: 0.4167607 | AC28: 15.951347 | AD28: 0.40735582 | AF28: 18.972226 | AG28: 0.475084 | AI28: 14.196773 | AJ28: 0.42618451 | AL28: 16.358948 | AM28: 0.6837156
A29: Hungary | B29: 7.1161344 | C29: 0.048167882 | E29: 2.5107183 | F29: 0.033872866 | H29: 2.300056 | I29: 0.25342256 | K29: 1.6646106 | L29: 0.17019981 | N29: 2.4637819 | O29: 0.25778831 | Q29: 3.9074013 | R29: 0.28679899 | T29: 5.3428791 | U29: 0.33437982 | W29: 7.8123028 | X29: 0.40974011 | Z29: 8.5942606 | AA29: 0.46964362 | AC29: 14.28805 | AD29: 0.53041725 | AF29: 19.660346 | AG29: 0.52409451 | AI29: 15.661769 | AJ29: 0.63466296 | AL29: 18.304542 | AM29: 0.60959002
A30: Iceland | B30: 7.3387283 | C30: 0.038213343 | E30: 2.3663543 | F30: 0.035143371 | H30: 1.595475 | I30: 0.22757595 | K30: 1.465298 | L30: 0.24137017 | N30: 2.4800648 | O30: 0.25015645 | Q30: 3.2099876 | R30: 0.32322589 | T30: 4.4025711 | U30: 0.34589984 | W30: 5.5770793 | X30: 0.4472272 | Z30: 8.8546392 | AA30: 0.49638439 | AC30: 14.401644 | AD30: 0.68413481 | AF30: 21.495621 | AG30: 0.80558346 | AI30: 18.758754 | AJ30: 0.73297579 | AL30: 17.758866 | AM30: 0.66335172
A31: Ireland | B31: 6.7350315 | C31: 0.045669803 | E31: 2.465357 | F31: 0.026894832 | H31: 2.1523313 | I31: 0.21907147 | K31: 2.0081431 | L31: 0.19149832 | N31: 2.941431 | O31: 0.2068306 | Q31: 4.3738979 | R31: 0.24819073 | T31: 6.960793 | U31: 0.33590489 | W31: 9.402753 | X31: 0.44235799 | Z31: 10.781029 | AA31: 0.44825162 | AC31: 16.046621 | AD31: 0.44401963 | AF31: 19.026341 | AG31: 0.5997702 | AI31: 14.656328 | AJ31: 0.48720182 | AL31: 11.650332 | AM31: 0.46038816
A32: Israel | B32: m | C32: m | E32: m | F32: m | H32: m | I32: m | K32: m | L32: m | N32: m | O32: m | Q32: m | R32: m | T32: m | U32: m | W32: m | X32: m | Z32: m | AA32: m | AC32: m | AD32: m | AF32: m | AG32: m | AI32: m | AJ32: m | AL32: m | AM32: m
A33: Italy | B33: 6.9125324 | C33: 0.037755477 | E33: 2.4279716 | F33: 0.032840996 | H33: 2.4375162 | I33: 0.25231572 | K33: 2.3551181 | L33: 0.20667958 | N33: 2.2265818 | O33: 0.19724521 | Q33: 3.2186985 | R33: 0.21142052 | T33: 5.2416011 | U33: 0.31595392 | W33: 8.5220894 | X33: 0.42955179 | Z33: 8.984655 | AA33: 0.39517965 | AC33: 17.167073 | AD33: 0.55592782 | AF33: 23.338237 | AG33: 0.59529805 | AI33: 14.655625 | AJ33: 0.4042197 | AL33: 11.852805 | AM33: 0.49273798
A34: Japan | B34: 6.178495 | C34: 0.040129555 | E34: 2.5950715 | F34: 0.023205136 | H34: 2.6920245 | I34: 0.22754035 | K34: 3.1050749 | L34: 0.2201449 | N34: 4.1549706 | O34: 0.23508246 | Q34: 6.7828388 | R34: 0.39755562 | T34: 7.9872259 | U34: 0.37096422 | W34: 13.032092 | X34: 0.4861252 | Z34: 11.998572 | AA34: 0.45076022 | AC34: 15.796619 | AD34: 0.53523416 | AF34: 14.626389 | AG34: 0.46184218 | AI34: 8.8442058 | AJ34: 0.4146158 | AL34: 10.979987 | AM34: 0.48763026
A35: Korea | B35: 6.5153678 | C35: 0.042920914 | E35: 2.6146721 | F35: 0.021292677 | H35: 2.0962852 | I35: 0.21089151 | K35: 2.5113183 | L35: 0.1896601 | N35: 4.0622708 | O35: 0.27261461 | Q35: 6.8167983 | R35: 0.30965058 | T35: 7.2973377 | U35: 0.33030171 | W35: 10.154579 | X35: 0.37057477 | Z35: 10.318182 | AA35: 0.38946018 | AC35: 14.761157 | AD35: 0.49116937 | AF35: 15.891903 | AG35: 0.43946461 | AI35: 12.78582 | AJ35: 0.4252321 | AL35: 13.304349 | AM35: 0.57841912
A36: Latvia | B36: 7.162515 | C36: 0.038912507 | E36: 2.377328 | F36: 0.030994494 | H36: 1.6915383 | I36: 0.20793472 | K36: 1.8273345 | L36: 0.2196398 | N36: 2.0637118 | O36: 0.20931968 | Q36: 3.3130515 | R36: 0.28111597 | T36: 4.3153804 | U36: 0.29502203 | W36: 8.8023682 | X36: 0.43830879 | Z36: 9.1734545 | AA36: 0.42331338 | AC36: 15.3641 | AD36: 0.52092387 | AF36: 20.127544 | AG36: 0.64200642 | AI36: 17.740724 | AJ36: 0.61788056 | AL36: 15.580793 | AM36: 0.6205104
A37: Lithuania | B37: 7.6079704 | C37: 0.035318851 | E37: 2.4198969 | F37: 0.029347267 | H37: 1.5747766 | I37: 0.15531479 | K37: 1.839666 | L37: 0.19837629 | N37: 1.9317549 | O37: 0.16181155 | Q37: 2.4611937 | R37: 0.17423066 | T37: 3.8568046 | U37: 0.2743591 | W37: 6.7877886 | X37: 0.30305524 | Z37: 6.1033259 | AA37: 0.37384823 | AC37: 12.131003 | AD37: 0.48705749 | AF37: 17.673798 | AG37: 0.48088063 | AI37: 20.982123 | AJ37: 0.57289924 | AL37: 24.657765 | AM37: 0.59165757
A38: Luxembourg | B38: 7.0387882 | C38: 0.036972096 | E38: 2.4854725 | F38: 0.0272073 | H38: 2.1814429 | I38: 0.22788658 | K38: 2.0434002 | L38: 0.19962824 | N38: 2.419233 | O38: 0.20201933 | Q38: 3.9741677 | R38: 0.28885419 | T38: 5.3261657 | U38: 0.33313399 | W38: 8.457347 | X38: 0.38694627 | Z38: 7.4032723 | AA38: 0.35673087 | AC38: 15.864682 | AD38: 0.53540621 | AF38: 19.853842 | AG38: 0.47830482 | AI38: 17.584565 | AJ38: 0.46302834 | AL38: 14.891882 | AM38: 0.51137699
A39: Mexico | B39: 8.1103486 | C39: 0.035204994 | E39: 2.2068606 | F39: 0.037805061 | H39: 0.99511937 | I39: 0.16918294 | K39: 1.1934866 | L39: 0.15574111 | N39: 1.4678479 | O39: 0.18525133 | Q39: 1.7642148 | R39: 0.24191156 | T39: 2.8264334 | U39: 0.25634548 | W39: 5.6439695 | X39: 0.3396051 | Z39: 3.4945501 | AA39: 0.22158152 | AC39: 7.5744472 | AD39: 0.38382391 | AF39: 19.14725 | AG39: 0.52579937 | AI39: 24.005792 | AJ39: 0.71612452 | AL39: 31.886888 | AM39: 0.7965109
A40: Netherlands* | B40: 7.5015809 | C40: 0.032570798 | E40: 1.7008165 | F40: 0.032234731 | H40: 0.2788229 | I40: 0.095612478 | K40: 0.44272723 | L40: 0.11270334 | N40: 1.0232255 | O40: 0.15165816 | Q40: 1.6581209 | R40: 0.20248622 | T40: 2.2795536 | U40: 0.23987705 | W40: 4.5012058 | X40: 0.35194639 | Z40: 10.358304 | AA40: 0.55337465 | AC40: 22.905621 | AD40: 0.76929128 | AF40: 29.794661 | AG40: 0.72085287 | AI40: 17.353729 | AJ40: 0.64787905 | AL40: 9.4040288 | AM40: 0.54009412
A41: New Zealand | B41: m | C41: m | E41: m | F41: m | H41: m | I41: m | K41: m | L41: m | N41: m | O41: m | Q41: m | R41: m | T41: m | U41: m | W41: m | X41: m | Z41: m | AA41: m | AC41: m | AD41: m | AF41: m | AG41: m | AI41: m | AJ41: m | AL41: m | AM41: m
A42: Norway | B42: m | C42: m | E42: m | F42: m | H42: m | I42: m | K42: m | L42: m | N42: m | O42: m | Q42: m | R42: m | T42: m | U42: m | W42: m | X42: m | Z42: m | AA42: m | AC42: m | AD42: m | AF42: m | AG42: m | AI42: m | AJ42: m | AL42: m | AM42: m
A43: Poland | B43: 6.7419757 | C43: 0.046462114 | E43: 2.6494714 | F43: 0.033028978 | H43: 3.1185217 | I43: 0.26267345 | K43: 2.5419746 | L43: 0.24026283 | N43: 3.389621 | O43: 0.28836227 | Q43: 4.5111634 | R43: 0.28794921 | T43: 5.8055098 | U43: 0.40076295 | W43: 8.8091129 | X43: 0.38848556 | Z43: 9.9458245 | AA43: 0.38469108 | AC43: 15.010562 | AD43: 0.64253927 | AF43: 17.451046 | AG43: 0.5359658 | AI43: 14.448633 | AJ43: 0.54009591 | AL43: 14.968031 | AM43: 0.62474033
A44: Portugal* | B44: 7.1275473 | C44: 0.037443767 | E44: 2.2120668 | F44: 0.027394154 | H44: 1.1395997 | I44: 0.15590768 | K44: 1.5546358 | L44: 0.20226931 | N44: 1.4789247 | O44: 0.17283485 | Q44: 3.1863385 | R44: 0.24806588 | T44: 4.7665493 | U44: 0.35797058 | W44: 9.5467464 | X44: 0.49896657 | Z44: 9.4429573 | AA44: 0.42761485 | AC44: 17.12234 | AD44: 0.52134061 | AF44: 23.026231 | AG44: 0.56673964 | AI44: 16.197449 | AJ44: 0.54361924 | AL44: 12.538229 | AM44: 0.50454964
...

Sheet Table III.B1.11.2
A1: PISA 2018 Results (Volume III) - © OECD 2019
A2: Annex B1 | B2: Annex B1.11 Results (tables): Students' life satisfaction and meaning in life
A3: Version 2 - Last updated: 02-Dec-2019
A4: Disclaimer: http://oe.cd/disclaimer
A6: Table III.B1.11.2
A7: Change between 2015 and 2018 in students' levels of life satisfaction
A8: Based on students' reports
B11: Change between 2015 and 2018 (PISA 2018 - PISA 2015)
B12: Average life satisfaction | E12: Percentage of students who reported the following feelings about life:
E13: Not satisfied (Students who reported 0 to 4 on the life-satisfaction scale) | H13: Somewhat satisfied (Students who reported 5 or 6 on the life-satisfaction scale) | K13: Moderately satisfied (Students who reported 7 or 8 on the life-satisfaction scale) | N13: Very satisfied (Students who reported 9 or 10 on the life-satisfaction scale) | Q13: Satisfied (Students who reported 7 or 10 on the life-satisfaction scale)
B14: Dif. | C14: S.E. | E14: % dif. | F14: S.E. | H14: % dif. | I14: S.E. | K14: % dif. | L14: S.E. | N14: % dif. | O14: S.E. | Q14: % dif. | R14: S.E.
A15: OECD
A16: Australia | B16: m | C16: m | E16: m | F16: m | H16: m | I16: m | K16: m | L16: m | N16: m | O16: m | Q16: m | R16: m
A17: Austria | B17: -0.38582715 | C17: 0.055994861 | E17: 5.8560729 | F17: 0.75459969 | H17: 0.041373741 | I17: 0.71884406 | K17: -3.4103806 | L17: 0.91102636 | N17: -2.487066 | O17: 1.0567671 | Q17: -5.8974466 | R17: 1.0261858
A18: Belgium | B18: m | C18: m | E18: m | F18: m | H18: m | I18: m | K18: m | L18: m | N18: m | O18: m | Q18: m | R18: m
A19: Canada | B19: m | C19: m | E19: m | F19: m | H19: m | I19: m | K19: m | L19: m | N19: m | O19: m | Q19: m | R19: m
A20: Chile | B20: -0.33667254 | C20: 0.060333487 | E20: 5.5367336 | F20: 0.78233194 | H20: 0.24617754 | I20: 0.79993427 | K20: -4.9821172 | L20: 0.98868144 | N20: -0.80079406 | O20: 1.0945184 | Q20: -5.7829113 | R20: 1.0641609
A21: Colombia | B21: -0.26573223 | C21: 0.05892561 | E21: 3.3715091 | F21: 0.69496882 | H21: 0.53807646 | I21: 0.6307357 | K21: -1.3953973 | L21: 0.91760105 | N21: -2.5141883 | O21: 1.2391459 | Q21: -3.9095857 | R21: 0.90594989
A22: Czech Republic | B22: -0.14001252 | C22: 0.059658423 | E22: 4.275001 | F22: 0.85022104 | H22: -3.0705667 | I22: 0.70149058 | K22: -3.4498932 | L22: 0.93257892 | N22: 2.2454591 | O22: 1.0400865 | Q22: -1.2044343 | R22: 1.0204724
A23: Denmark | B23: m | C23: m | E23: m | F23: m | H23: m | I23: m | K23: m | L23: m | N23: m | O23: m | Q23: m | R23: m
A24: Estonia | B24: -0.3145842 | C24: 0.050407123 | E24: 5.1919322 | F24: 0.74427116 | H24: -0.45255885 | I24: 0.76281548 | K24: -2.3769004 | L24: 1.0902735 | N24: -2.362473 | O24: 1.1906081 | Q24: -4.7393732 | R24: 0.99219984
A25: Finland | B25: -0.27526662 | C25: 0.042465702 | E25: 3.7465992 | F25: 0.56394911 | H25: 1.7564795 | I25: 0.5553239 | K25: -3.9282439 | L25: 0.92249048 | N25: -1.5748348 | O25: 1.0559965 | Q25: -5.5030785 | R25: 0.7654196
A26: France | B26: -0.44277066 | C26: 0.043236766 | E26: 4.4035044 | F26: 0.6481089 | H26: 3.6522007 | I26: 0.78428042 | K26: -1.9993817 | L26: 1.0391604 | N26: -6.0563235 | O26: 0.89879256 | Q26: -8.0557051 | R26: 0.92408943
A27: Germany | B27: -0.33389565 | C27: 0.051506393 | E27: 5.6775904 | F27: 0.73791182 | H27: 0.6042006 | I27: 0.77982748 | K27: -6.0389023 | L27: 1.064572 | N27: -0.24288876 | O27: 1.0050578 | Q27: -6.2817912 | R27: 0.96773261
A28: Greece | B28: 0.074481532 | C28: 0.048729029 | E28: 0.71000189 | F28: 0.6954686 | H28: -1.8784544 | I28: 0.77225804 | K28: -3.1638951 | L28: 0.90408736 | N28: 4.3323479 | O28: 0.94603825 | Q28: 1.1684525 | R28: 0.91532147
A29: Hungary | B29: -0.056098431 | C29: 0.0606151 | E29: 2.5404506 | F29: 0.8272956 | H29: -1.0303859 | I29: 0.80857527 | K29: -3.7916179 | L29: 1.0728456 | N29: 2.2815533 | O29: 1.1265405 | Q29: -1.5100647 | R29: 1.1740702
A30: Iceland | B30: -0.45673555 | C30: 0.054911736 | E30: 3.6649098 | F30: 0.7796973 | H30: 2.8376086 | I30: 0.8729645 | K30: 3.6438529 | L30: 1.2121204 | N30: -10.146372 | O30: 1.189923 | Q30: -6.5025187 | R30: 1.0474074
A31: Ireland | B31: -0.56917304 | C31: 0.054935683 | E31: 6.5551238 | F31: 0.77070868 | H31: 4.4579296 | I31: 0.82870841 | K31: -4.888535 | L31: 1.0214138 | N31: -6.1245179 | O31: 1.0231297 | Q31: -11.013053 | R31: 1.1383286
A32: Israel | B32: m | C32: m | E32: m | F32: m | H32: m | I32: m | K32: m | L32: m | N32: m | O32: m | Q32: m | R32: m
A33: Italy | B33: 0.021165399 | C33: 0.053961717 | E33: 0.81683743 | F33: 0.76589715 | H33: -2.8539603 | I33: 0.83632404 | K33: -0.23727608 | L33: 0.94243383 | N33: 2.2743988 | O33: 0.9080171 | Q33: 2.0371227 | R33: 1.0688938
A34: Japan | B34: -0.61834079 | C34: 0.053024072 | E34: 8.6547079 | F34: 0.78843462 | H34: 2.1730568 | I34: 0.68580955 | K34: -6.8848662 | L34: 0.92501289 | N34: -3.9428988 | O34: 0.8988831 | Q34: -10.827765 | R34: 1.0142305
A35: Korea | B35: 0.15348426 | C35: 0.057264421 | E35: 1.1499517 | F35: 0.89218247 | H35: -5.0723968 | I35: 0.82522988 | K35: -3.5568531 | L35: 0.93922096 | N35: 7.4792981 | O35: 0.83261871 | Q35: 3.9224451 | R35: 1.1112885
A36: Latvia | B36: -0.21082002 | C36: 0.052385636 | E36: 4.3120966 | F36: 0.71085161 | H36: -0.18585648 | I36: 0.87589777 | K36: -5.9972038 | L36: 1.0006896 | N36: 1.8709639 | O36: 1.1603873 | Q36: -4.1262398 | R36: 0.98549336
A37: Lithuania | B37: -0.25634369 | C37: 0.047573373 | E37: 3.5502555 | F37: 0.61903965 | H37: 0.090854086 | I37: 0.6776737 | K37: -1.6834518 | L37: 0.92447144 | N37: -1.9576579 | O37: 1.0577615 | Q37: -3.6411097 | R37: 0.85659385
A38: Luxembourg | B38: -0.34328294 | C38: 0.0489593 | E38: 4.8297181 | F38: 0.72933924 | H38: -0.72324568 | I38: 0.7412653 | K38: -0.44072181 | L38: 0.90128034 | N38: -3.6657505 | O38: 0.89130175 | Q38: -4.1064725 | R38: 0.95482057
A39: Mexico | B39: -0.15901278 | C39: 0.046377108 | E39: 1.8648885 | F39: 0.52323943 | H39: -0.34445068 | I39: 0.54061127 | K39: 1.0572561 | L39: 0.85082132 | N39: -2.5776939 | O39: 0.97547591 | Q39: -1.5204378 | R39: 0.78257108
A40: Netherlands* | B40: -0.32584777 | C40: 0.040576998 | E40: 2.0106416 | F40: 0.51032537 | H40: 4.2430882 | I40: 0.84961832 | K40: -0.56077927 | L40: 1.0951245 | N40: -5.6929507 | O40: 1.0198804 | Q40: -6.2537298 | R40: 0.93911266
A41: New Zealand | B41: m | C41: m | E41: m | F41: m | H41: m | I41: m | K41: m | L41: m | N41: m | O41: m | Q41: m | R41: m
A42: Norway | B42: m | C42: m | E42: m | F42: m | H42: m | I42: m | K42: m | L42: m | N42: m | O42: m | Q42: m | R42: m
A43: Poland | B43: -0.44265425 | C43: 0.061171096 | E43: 6.7653751 | F43: 0.84948474 | H43: 0.024087993 | I43: 0.82404482 | K43: -3.851083 | L43: 1.101351 | N43: -2.9383802 | O43: 1.1042 | Q43: -6.789463 | R43: 1.1312102
...

Sheet Table III.B1.11.3
A1: PISA 2018 Results (Volume III) - © OECD 2019
A2: Annex B1 | B2: Annex B1.11 Results (tables): Students' life satisfaction and meaning in life
A3: Version 2 - Last updated: 02-Dec-2019
A4: Disclaimer: http://oe.cd/disclaimer
A6: Table III.B1.11.3
A7: Prevalence of students who are not satisfied with life
A8: Based on students' reports
B11: Percentage of not satisfied1 students | E11: Percentage of students who are in schools where…
E12: Over 50% of students reported being not satisfied with life | H12: Between 25% and 50% of students reported being not satisfied with life | K12: Between 10% and 25% of students reported being not satisfied with life | N12: 10% of students or less reported being not satisfied with life
B14: % | C14: S.E. | E14: % | F14: S.E. | H14: % | I14: S.E. | K14: % | L14: S.E. | N14: % | O14: S.E.
A15: OECD
A16: Australia | B16: m | C16: m | E16: m | F16: m | H16: m | I16: m | K16: m | L16: m | N16: m | O16: m
A17: Austria | B17: 16.938911 | C17: 0.5788859 | E17: 1.2347727 | F17: 0.65259039 | H17: 15.899623 | I17: 2.6175723 | K17: 55.890261 | L17: 3.3337808 | N17: 26.975344 | O17: 2.6196209
A18: Belgium | B18: m | C18: m | E18: m | F18: m | H18: m | I18: m | K18: m | L18: m | N18: m | O18: m
A19: Canada | B19: m | C19: m | E19: m | F19: m | H19: m | I19: m | K19: m | L19: m | N19: m | O19: m
A20: Chile | B20: 17.58557 | C20: 0.59741551 | E20: 0.58872729 | F20: 0.29458658 | H20: 13.707976 | I20: 2.7988929 | K20: 68.325898 | L20: 3.382209 | N20: 17.377399 | O20: 2.4992974
A21: Colombia | B21: 13.500996 | C21: 0.54395365 | E21: 0.061933223 | F21: 0.06207027 | H21: 9.4011473 | I21: 1.7500587 | K21: 54.604251 | L21: 3.8481014 | N21: 35.932669 | O21: 3.7121771
A22: Czech Republic | B22: 18.034385 | C22: 0.64399126 | E22: 0.54293677 | F22: 0.41379701 | H22: 21.690487 | I22: 2.4100165 | K22: 53.725922 | L22: 3.1610307 | N22: 24.040654 | O22: 2.8326879
A23: Denmark | B23: m | C23: m | E23: m | F23: m | H23: m | I23: m | K23: m | L23: m | N23: m | O23: m
A24: Estonia | B24: 14.477027 | C24: 0.59272192 | E24: 1.0776442 | F24: 0.48603341 | H24: 7.326393 | I24: 1.1502587 | K24: 56.916762 | L24: 2.0911452 | N24: 34.679201 | O24: 2.1886101
A25: Finland | B25: 10.393411 | C25: 0.45917192 | E25: 0.067967289 | F25: 0.067211315 | H25: 3.6787265 | I25: 1.2495672 | K25: 44.251987 | L25: 3.3799541 | N25: 52.001319 | O25: 3.387146
A26: France | B26: 11.779793 | C26: 0.51232034 | E26: 0.095990844 | F26: 0.10480881 | H26: 6.6337431 | I26: 1.5470981 | K26: 44.319633 | L26: 3.235472 | N26: 48.950633 | O26: 3.374983
A27: Germany | B27: 16.745937 | C27: 0.60605534 | E27: 0.18757977 | F27: 0.18445366 | H27: 16.901077 | I27: 2.8239909 | K27: 61.377988 | L27: 3.619439 | N27: 21.533355 | O27: 3.0933607
A28: Greece | B28: 15.403428 | C28: 0.50468145 | E28: 0.23502499 | F28: 0.14776118 | H28: 10.5465 | I28: 2.1144077 | K28: 64.100232 | L28: 3.1375538 | N28: 25.118243 | O28: 2.8032491
A29: Hungary | B29: 15.678729 | C29: 0.62431353 | E29: 0.67499594 | F29: 0.30339567 | H29: 13.043814 | I29: 2.510927 | K29: 55.034754 | L29: 3.799161 | N29: 31.246436 | O29: 3.5818523
A30: Iceland | B30: 13.153397 | C30: 0.57404005 | E30: 0.11823633 | F30: 0.057767804 | H30: 4.9481541 | I30: 0.15222857 | K30: 56.491118 | L30: 0.25132476 | N30: 38.442492 | O30: 0.24569462
A31: Ireland | B31: 18.436596 | C31: 0.63802222 | E31: 0.28799299 | F31: 0.28960235 | H31: 19.363207 | I31: 2.9934699 | K31: 67.767259 | L31: 3.693952 | N31: 12.581541 | O31: 2.9447301
A32: Israel | B32: m | C32: m | E32: m | F32: m | H32: m | I32: m | K32: m | L32: m | N32: m | O32: m
A33: Italy | B33: 15.479516 | C33: 0.51988443 | E33: 0.38184262 | F33: 0.34669734 | H33: 14.97007 | I33: 2.2266815 | K33: 55.082524 | L33: 3.402233 | N33: 29.565564 | O33: 2.7535156
A34: Japan | B34: 24.722135 | C34: 0.60645113 | E34: 0.0673018 | F34: 0.067058458 | H34: 45.802262 | I34: 3.4615863 | K34: 52.070148 | L34: 3.5371052 | N34: 2.0602886 | O34: 1.0362762
A35: Korea | B35: 22.78401 | C35: 0.62813001 | E35: 0.51565335 | F35: 0.51580364 | H35: 38.81611 | I35: 3.6008735 | K35: 54.019529 | L35: 3.4919179 | N35: 6.6487076 | O35: 1.694783
A36: Latvia | B36: 13.211016 | C36: 0.53704557 | E36: 0.44673877 | F36: 0.24887371 | H36: 10.070584 | I36: 1.2341627 | K36: 49.150274 | L36: 1.8893332 | N36: 40.332404 | O36: 1.762248
A37: Lithuania | B37: 11.664196 | C37: 0.47195128 | E37: 0.13099426 | F37: 0.045579368 | H37: 6.5972369 | I37: 1.0960296 | K37: 47.406414 | L37: 1.9837591 | N37: 45.865355 | O37: 2.0264688
A38: Luxembourg | B38: 15.94441 | C38: 0.53679278 | E38: 0 | F38: c | H38: 2.4619526 | I38: 0.031053725 | K38: 92.938335 | L38: 0.040534272 | N38: 4.5997125 | O38: 0.025508261
A39: Mexico | B39: 8.2471021 | C39: 0.43527301 | E39: 0.71281945 | F39: 0.65302023 | H39: 3.9327201 | I39: 1.0683655 | K39: 29.137115 | L39: 3.2596855 | N39: 66.217346 | O39: 3.2795194
A40: Netherlands* | B40: 5.6824501 | C40: 0.43130208 | E40: 0 | F40: c | H40: 0.041937733 | I40: 0.041751329 | K40: 15.701104 | L40: 3.1120716 | N40: 84.256959 | O40: 3.1126236
A41: New Zealand | B41: m | C41: m | E41: m | F41: m | H41: m | I41: m | K41: m | L41: m | N41: m | O41: m
A42: Norway | B42: m | C42: m | E42: m | F42: m | H42: m | I42: m | K42: m | L42: m | N42: m | O42: m
A43: Poland | B43: 19.36679 | C43: 0.69136816 | E43: 0.35848949 | F43: 0.19277148 | H43: 22.123509 | I43: 2.7470427 | K43: 59.135475 | L43: 3.2567506 | N43: 18.382526 | O43: 2.6309647
A44: Portugal* | B44: 12.126048 | C44: 0.55221341 | E44: 0.16026531 | F44: 0.13421248 | H44: 8.1978341 | I44: 2.2298863 | K44: 43.939918 | L44: 3.4429673 | N44: 47.701983 | O44: 3.2780131
...

Sheet Table III.B1.11.4
A1: PISA 2018 Results (Volume III) - © OECD 2019
A2: Annex B1 | B2: Annex B1.11 Results (tables): Students' life satisfaction and meaning in life
A3: Version 2 - Last updated: 02-Dec-2019
A4: Disclaimer: http://oe.cd/disclaimer
A6: Table III.B1.11.4
A7: Satisfied students, by student characteristics
A8: Based on students' reports
B11: Percentage of students who are satisfied1 with life, by the following student characteristics:
B12: Gender | K12: Socio-economic status2 | T12: Education level | AC12: Immigrant background
B13: Boys | E13: Girls | H13: Girls - boys | K13: Disadvantaged students | N13: Advantaged students | Q13: Advantaged -disadvantaged | T13: Lower secondary (ISCED 2) | W13: Upper secondary (ISCED 3) | Z13: ISCED 3 - ISCED 2 | AC13: Non-immigrant students | AF13: Immigrant students | AI13: Immigrant - non-immigrant
B14: % | C14: S.E. | E14: % | F14: S.E. | H14: % dif. | I14: S.E. | K14: % | L14: S.E. | N14: % | O14: S.E. | Q14: % dif. | R14: S.E. | T14: % | U14: S.E. | W14: % | X14: S.E. | Z14: % dif. | AA14: S.E. | AC14: % | AD14: S.E. | AF14: % | AG14: S.E. | AI14: % dif. | AJ14: S.E.
A15: OECD
A16: Australia | B16: m | C16: m | E16: m | F16: m | H16: m | I16: m | K16: m | L16: m | N16: m | O16: m | Q16: m | R16: m | T16: m | U16: m | W16: m | X16: m | Z16: m | AA16: m | AC16: m | AD16: m | AF16: m | AG16: m | AI16: m | AJ16: m
A17: Austria | B17: 75.391675 | C17: 0.91888286 | E17: 63.781521 | F17: 0.98139103 | H17: -11.610154 | I17: 1.3099417 | K17: 66.307584 | L17: 1.4056386 | N17: 72.803872 | O17: 1.2886284 | Q17: 6.4962875 | R17: 1.9569898 | T17: m | U17: m | W17: m | X17: m | Z17: m | AA17: m | AC17: 70.959755 | AD17: 0.82134759 | AF17: 64.764531 | AG17: 1.5348254 | AI17: -6.1952241 | AJ17: 1.655622
A18: Belgium | B18: m | C18: m | E18: m | F18: m | H18: m | I18: m | K18: m | L18: m | N18: m | O18: m | Q18: m | R18: m | T18: m | U18: m | W18: m | X18: m | Z18: m | AA18: m | AC18: m | AD18: m | AF18: m | AG18: m | AI18: m | AJ18: m
A19: Canada | B19: m | C19: m | E19: m | F19: m | H19: m | I19: m | K19: m | L19: m | N19: m | O19: m | Q19: m | R19: m | T19: m | U19: m | W19: m | X19: m | Z19: m | AA19: m | AC19: m | AD19: m | AF19: m | AG19: m | AI19: m | AJ19: m
A20: Chile | B20: 69.455682 | C20: 0.98016788 | E20: 58.846264 | F20: 1.0429888 | H20: -10.609418 | I20: 1.3654848 | K20: 57.554618 | L20: 1.3950193 | N20: 68.795794 | O20: 1.256074 | Q20: 11.241176 | R20: 1.9006625 | T20: 58.12388 | U20: 4.5736698 | W20: 64.567954 | X20: 0.71645374 | Z20: 6.4440735 | AA20: 4.5246953 | AC20: 64.455259 | AD20: 0.75440532 | AF20: 56.398138 | AG20: 3.9767821 | AI20: -8.0571209 | AJ20: 3.9861607
A21: Colombia | B21: 76.151624 | C21: 0.9170332 | E21: 69.951083 | F21: 0.87262331 | H21: -6.2005411 | I21: 1.1359658 | K21: 75.6213 | L21: 1.3641309 | N21: 72.426245 | O21: 1.2187123 | Q21: -3.195055 | R21: 1.9509877 | T21: 70.893554 | U21: 1.1449646 | W21: 74.158828 | X21: 0.86088184 | Z21: 3.2652736 | AA21: 1.4459696 | AC21: 72.948053 | AD21: 0.71173984 | AF21: 81.349812 | AG21: 7.990987 | AI21: 8.401759 | AJ21: 8.1133165
A22: Czech Republic | B22: 70.839258 | C22: 0.93922023 | E22: 58.454192 | F22: 1.0557785 | H22: -12.385065 | I22: 1.3960436 | K22: 59.638493 | L22: 1.9962028 | N22: 69.567655 | O22: 1.2511563 | Q22: 9.9291622 | R22: 2.3336239 | T22: 64.797121 | U22: 1.0400141 | W22: 64.705666 | X22: 1.1035624 | Z22: -0.091455661 | AA22: 1.5337566 | AC22: 65.002729 | AD22: 0.73618912 | AF22: 56.658694 | AG22: 3.7680724 | AI22: -8.3440348 | AJ22: 3.7200394
A23: Denmark | B23: m | C23: m | E23: m | F23: m | H23: m | I23: m | K23: m | L23: m | N23: m | O23: m | Q23: m | R23: m | T23: m | U23: m | W23: m | X23: m | Z23: m | AA23: m | AC23: m | AD23: m | AF23: m | AG23: m | AI23: m | AJ23: m
A24: Estonia | B24: 75.588106 | C24: 0.83511601 | E24: 64.136014 | F24: 0.97512269 | H24: -11.452092 | I24: 1.1001618 | K24: 65.063801 | L24: 1.3542683 | N24: 77.180899 | O24: 1.3466947 | Q24: 12.117098 | R24: 1.8831597 | T24: 69.883597 | U24: 0.73913041 | W24: 64.856006 | X24: 5.5070033 | Z24: -5.0275907 | AA24: 5.5641825 | AC24: 69.949075 | AD24: 0.81625073 | AF24: 68.590125 | AG24: 2.1494515 | AI24: -1.3589501 | AJ24: 2.4028577
A25: Finland | B25: 83.853847 | C25: 0.75479751 | E25: 71.368461 | F25: 0.9103289 | H25: -12.485386 | I25: 1.2289815 | K25: 71.943704 | L25: 1.2925536 | N25: 82.815313 | O25: 0.95832723 | Q25: 10.871609 | R25: 1.6491445 | T25: 77.722341 | U25: 0.56393568 | W25: c | X25: c | Z25: c | AA25: c | AC25: 77.913371 | AD25: 0.60566404 | AF25: 73.197948 | AG25: 2.7867337 | AI25: -4.7154224 | AJ25: 2.8718038
A26: France | B26: 74.231814 | C26: 0.73010562 | E26: 65.00457 | F26: 1.002185 | H26: -9.2272445 | I26: 1.0027349 | K26: 62.871316 | L26: 1.5367566 | N26: 75.597917 | O26: 1.3148955 | Q26: 12.726601 | R26: 2.1494175 | T26: 62.356438 | U26: 1.7667706 | W26: 71.042541 | X26: 0.79204608 | Z26: 8.6861026 | AA26: 1.935435 | AC26: 70.570346 | AD26: 0.77720429 | AF26: 64.476425 | AG26: 1.8136649 | AI26: -6.0939217 | AJ26: 1.9361711
A27: Germany | B27: 72.284016 | C27: 0.99749331 | E27: 60.075446 | F27: 1.0270252 | H27: -12.20857 | I27: 1.4855609 | K27: 62.849133 | L27: 1.4197353 | N27: 69.896674 | O27: 1.5400076 | Q27: 7.0475407 | R27: 2.2544648 | T27: 66.519836 | U27: 0.74173313 | W27: 67.165215 | X27: 2.5120357 | Z27: 0.64537903 | AA27: 2.6065825 | AC27: 67.501729 | AD27: 0.9134498 | AF27: 63.040481 | AG27: 1.5882033 | AI27: -4.4612482 | AJ27: 1.9796956
A28: Greece | B28: 70.274242 | C28: 0.99908856 | E28: 60.695738 | F28: 1.013585 | H28: -9.5785042 | I28: 1.5662594 | K28: 63.851269 | L28: 1.5346227 | N28: 65.895113 | O28: 1.3598617 | Q28: 2.0438442 | R28: 2.0409439 | T28: 62.977909 | U28: 5.5427679 | W28: 65.587971 | X28: 0.62953858 | Z28: 2.6100623 | AA28: 5.5923088 | AC28: 65.704037 | AD28: 0.62561327 | AF28: 62.201432 | AG28: 2.0243347 | AI28: -3.5026055 | AJ28: 1.9755392
A29: Hungary | B29: 74.065599 | C29: 1.0327646 | E29: 61.905208 | F29: 1.1541672 | H29: -12.160391 | I29: 1.3955104 | K29: 64.130813 | L29: 1.5481234 | N29: 71.744495 | O29: 1.5273279 | Q29: 7.6136814 | R29: 2.1488846 | T29: 68.774928 | U29: 2.7692546 | W29: 67.823954 | X29: 0.96179228 | Z29: -0.95097341 | AA29: 3.045401 | AC29: 67.822493 | AD29: 0.88522201 | AF29: 72.507136 | AG29: 4.4509615 | AI29: 4.6846428 | AJ29: 4.3484582
A30: Iceland | B30: 79.373219 | C30: 0.99266485 | E30: 65.789382 | F30: 1.1562821 | H30: -13.583837 | I30: 1.4964688 | K30: 67.762512 | L30: 1.8976574 | N30: 77.14514 | O30: 1.4193375 | Q30: 9.382628 | R30: 2.4447359 | T30: 72.372861 | U30: 0.78272205 | W30: c | X30: c | Z30: c | AA30: c | AC30: 72.833985 | AD30: 0.79550813 | AF30: 66.734126 | AG30: 3.7391858 | AI30: -6.0998589 | AJ30: 3.8112737
A31: Ireland | B31: 67.275231 | C31: 1.1007149 | E31: 55.542107 | F31: 1.1779815 | H31: -11.733123 | I31: 1.3777319 | K31: 57.760634 | L31: 1.393931 | N31: 63.537125 | O31: 1.5117654 | Q31: 5.7764912 | R31: 1.9543763 | T31: 61.191859 | U31: 1.0317675 | W31: 61.706797 | X31: 1.1869726 | Z31: 0.51493771 | AA31: 1.275113 | AC31: 61.808549 | AD31: 1.0078006 | AF31: 59.472158 | AG31: 1.683295 | AI31: -2.3363915 | AJ31: 1.8775866
A32: Israel | B32: m | C32: m | E32: m | F32: m | H32: m | I32: m | K32: m | L32: m | N32: m | O32: m | Q32: m | R32: m | T32: m | U32: m | W32: m | X32: m | Z32: m | AA32: m | AC32: m | AD32: m | AF32: m | AG32: m | AI32: m | AJ32: m
A33: Italy | B33: 73.864924 | C33: 0.88913898 | E33: 59.813439 | F33: 1.0001166 | H33: -14.051484 | I33: 1.323904 | K33: 61.707757 | L33: 1.4593481 | N33: 72.453427 | O33: 0.96288541 | Q33: 10.745669 | R33: 1.6130864 | T33: 54.919349 | U33: 4.657327 | W33: 67.127857 | X33: 0.70695675 | Z33: 12.208508 | AA33: 4.6411996 | AC33: 68.538732 | AD33: 0.70854672 | AF33: 54.258516 | AG33: 2.4090032 | AI33: -14.280215 | AJ33: 2.4121519
A34: Japan | B34: 50.884068 | C34: 0.90174463 | E34: 49.642856 | F34: 1.2606842 | H34: -1.2412121 | I34: 1.5654466 | K34: 48.681463 | L34: 1.4583658 | N34: 52.944491 | O34: 1.6257461 | Q34: 4.2630286 | R34: 2.1725398 | T34: m | U34: m | W34: 50.247201 | X34: 0.77627934 | Z34: m | AA34: m | AC34: w | AD34: w | AF34: w | AG34: w | AI34: w | AJ34: w
A35: Korea | B35: 65.295491 | C35: 0.95618521 | E35: 47.378862 | F35: 0.95801689 | H35: -17.916629 | I35: 1.3619649 | K35: 53.734021 | L35: 1.3351337 | N35: 58.619691 | O35: 1.164023 | Q35: 4.8856705 | R35: 1.6900907 | T35: 58.355849 | U35: 2.1252408 | W35: 56.436072 | X35: 0.82860827 | Z35: -1.9197775 | AA35: 2.3160697 | AC35: 56.732378 | AD35: 0.76115356 | AF35: c | AG35: c | AI35: c | AJ35: c
A36: Latvia | B36: 72.543233 | C36: 0.91563582 | E36: 65.24502 | F36: 1.1481134 | H36: -7.2982136 | I36: 1.5309513 | K36: 60.535189 | L36: 1.5771105 | N36: 75.771152 | O36: 1.4492431 | Q36: 15.235963 | R36: 2.3201879 | T36: 68.818501 | U36: 0.70897519 | W36: 68.670539 | X36: 3.8261576 | Z36: -0.14796159 | AA36: 3.8572534 | AC36: 68.769286 | AD36: 0.75732558 | AF36: 69.438123 | AG36: 3.1613963 | AI36: 0.66883725 | AJ36: 3.3844723
A37: Lithuania | B37: 79.5504 | C37: 0.8924961 | E37: 71.272219 | F37: 0.88561208 | H37: -8.2781816 | I37: 1.2716534 | K37: 73.191147 | L37: 1.1159381 | N37: 76.972215 | O37: 1.2270826 | Q37: 3.7810681 | R37: 1.68084 | T37: 75.44469 | U37: 0.62039838 | W37: m | X37: m | Z37: m | AA37: m | AC37: 75.494764 | AD37: 0.64062706 | AF37: 70.946828 | AG37: 4.8905376 | AI37: -4.5479359 | AJ37: 5.0247461
A38: Luxembourg | B38: 73.273428 | C38: 0.86002567 | E38: 63.00784 | F38: 1.0174179 | H38: -10.265588 | I38: 1.300754 | K38: 61.709124 | L38: 1.5999577 | N38: 76.415921 | O38: 1.2880745 | Q38: 14.706796 | R38: 1.8978717 | T38: 66.168287 | U38: 0.85294506 | W38: 70.646951 | X38: 0.98413633 | Z38: 4.4786639 | AA38: 1.2188723 | AC38: 72.009519 | AD38: 1.0259205 | AF38: 65.344378 | AG38: 0.98543035 | AI38: -6.6651409 | AJ38: 1.4534119
A39: Mexico | B39: 84.842335 | C39: 0.73069199 | E39: 80.594709 | F39: 0.89969546 | H39: -4.2476257 | I39: 1.1562069 | K39: 79.259281 | L39: 1.4207754 | N39: 84.814865 | O39: 0.9774016 | Q39: 5.5555831 | R39: 1.7200986 | T39: 81.538292 | U39: 1.4687033 | V39: † | W39: 82.834485 | X39: 0.67158092 | Z39: 1.2961929 | AA39: 1.6859646 | AB39: † | AC39: 82.982835 | AD39: 0.56483505 | AF39: 69.963595 | AG39: 7.741823 | AH39: † | AI39: -13.01924 | AJ39: 7.7024677 | AK39: †
A40: Netherlands* | B40: 85.374412 | C40: 0.86337395 | E40: 73.726562 | F40: 1.2017623 | H40: -11.647849 | I40: 1.3847023 | K40: 79.454654 | L40: 1.6956574 | N40: 82.460088 | O40: 1.625193 | Q40: 3.0054343 | R40: 2.4646931 | T40: 78.649108 | U40: 0.95637961 | W40: 80.695239 | X40: 1.3071696 | Z40: 2.0461302 | AA40: 1.6041841 | AC40: 79.445259 | AD40: 0.84061804 | AF40: 79.85457 | AG40: 2.2628763 | AH40: † | AI40: 0.40931117 | AJ40: 2.4459998 | AK40: †
A41: New Zealand | B41: m | C41: m | E41: m | F41: m | H41: m | I41: m | K41: m | L41: m | N41: m | O41: m | Q41: m | R41: m | T41: m | U41: m | W41: m | X41: m | Z41: m | AA41: m | AC41: m | AD41: m | AF41: m | AG41: m | AI41: m | AJ41: m
A42: Norway | B42: m | C42: m | E42: m | F42: m | H42: m | I42: m | K42: m | L42: m | N42: m | O42: m | Q42: m | R42: m | T42: m | U42: m | W42: m | X42: m | Z42: m | AA42: m | AC42: m | AD42: m | AF42: m | AG42: m | AI42: m | AJ42: m
A43: Poland | B43: 69.907948 | C43: 0.94175808 | E43: 54.010589 | F43: 1.0515346 | H43: -15.897359 | I43: 1.2940547 | K43: 58.120742 | L43: 1.5082134 | N43: 63.516133 | O43: 1.4790851 | Q43: 5.3953908 | R43: 2.1036373 | T43: 62.194385 | U43: 0.78013945 | W43: c | X43: c | Z43: c | AA43: c | AC43: 61.937456 | AD43: 0.78086274 | AF43: c | AG43: c | AI43: c | AJ43: c
...

Sheet Table III.B1.11.5
A1: PISA 2018 Results (Volume III) - © OECD 2019
A2: Annex B1 | B2: Annex B1.11 Results (tables): Students' life satisfaction and meaning in life
A3: Version 2 - Last updated: 02-Dec-2019
A4: Disclaimer: http://oe.cd/disclaimer
A6: Table III.B1.11.5
A7: Students who are not satisfied with life, by student characteristics
A8: Based on students' reports
B11: Percentage of students who are not satisfied1 with life, by the following student characteristics:
B12: Gender | K12: Socio-economic status2 | T12: Education level | AC12: Immigrant background
B13: Boys | E13: Girls | H13: Girls - boys | K13: Disadvantaged students | N13: Advantaged students | Q13: Advantaged -disadvantaged | T13: Lower secondary (ISCED 2) | W13: Upper secondary (ISCED 3) | Z13: ISCED 3 - ISCED 2 | AC13: Non-immigrant students | AF13: Immigrant students | AI13: Immigrant - non-immigrant
B14: % | C14: S.E. | E14: % | F14: S.E. | H14: % dif. | I14: S.E. | K14: % | L14: S.E. | N14: % | O14: S.E. | Q14: % dif. | R14: S.E. | T14: % | U14: S.E. | W14: % | X14: S.E. | Z14: % dif. | AA14: S.E. | AC14: % | AD14: S.E. | AF14: % | AG14: S.E. | AI14: % dif. | AJ14: S.E.
A15: OECD
A16: Australia | B16: m | C16: m | E16: m | F16: m | H16: m | I16: m | K16: m | L16: m | N16: m | O16: m | Q16: m | R16: m | T16: m | U16: m | W16: m | X16: m | Z16: m | AA16: m | AC16: m | AD16: m | AF16: m | AG16: m | AI16: m | AJ16: m
A17: Austria | B17: 14.374085 | C17: 0.72445868 | E17: 19.51357 | F17: 0.69376014 | H17: 5.1394854 | I17: 0.8992915 | K17: 19.026134 | L17: 1.3142094 | N17: 15.38705 | O17: 1.0561628 | Q17: -3.6390844 | R17: 1.6789922 | T17: m | U17: m | W17: m | X17: m | Z17: m | AA17: m | AC17: 15.732528 | AD17: 0.6521201 | AF17: 20.953386 | AG17: 1.5978918 | AI17: 5.2208587 | AJ17: 1.8006802
A18: Belgium | B18: m | C18: m | E18: m | F18: m | H18: m | I18: m | K18: m | L18: m | N18: m | O18: m | Q18: m | R18: m | T18: m | U18: m | W18: m | X18: m | Z18: m | AA18: m | AC18: m | AD18: m | AF18: m | AG18: m | AI18: m | AJ18: m
A19: Canada | B19: m | C19: m | E19: m | F19: m | H19: m | I19: m | K19: m | L19: m | N19: m | O19: m | Q19: m | R19: m | T19: m | U19: m | W19: m | X19: m | Z19: m | AA19: m | AC19: m | AD19: m | AF19: m | AG19: m | AI19: m | AJ19: m
A20: Chile | B20: 15.261614 | C20: 0.68966541 | E20: 19.998428 | F20: 0.8467566 | H20: 4.7368141 | I20: 0.99318087 | K20: 21.334463 | L20: 1.2545985 | N20: 14.957925 | O20: 0.89418391 | Q20: -6.3765382 | R20: 1.6255992 | T20: 26.126611 | U20: 4.1008389 | W20: 17.143061 | X20: 0.56674084 | Z20: -8.9835493 | AA20: 4.1023029 | AC20: 17.454146 | AD20: 0.62641917 | AF20: 23.167669 | AG20: 3.2579943 | AI20: 5.7135224 | AJ20: 3.3931054
A21: Colombia | B21: 12.268255 | C21: 0.6920866 | E21: 14.67905 | F21: 0.68213033 | H21: 2.4107946 | I21: 0.83934907 | K21: 12.535456 | L21: 1.0653907 | N21: 13.299913 | O21: 0.8940958 | Q21: 0.76445651 | R21: 1.4030548 | T21: 15.708154 | U21: 1.0076854 | W21: 12.255665 | X21: 0.5821018 | Z21: -3.4524894 | AA21: 1.1330979 | AC21: 13.507281 | AD21: 0.55473541 | AF21: 4.2719337 | AG21: 2.7307557 | AI21: -9.2353475 | AJ21: 2.8416906
A22: Czech Republic | B22: 16.115967 | C22: 0.81877269 | E22: 20.02002 | F22: 0.98050982 | H22: 3.904053 | I22: 1.2790776 | K22: 21.33551 | L22: 1.4085438 | N22: 15.994026 | O22: 0.9308679 | Q22: -5.3414842 | R22: 1.6233442 | T22: 17.918843 | U22: 0.93397953 | W22: 18.160232 | X22: 0.9501532 | Z22: 0.24138886 | AA22: 1.374326 | AC22: 17.89163 | AD22: 0.65643684 | AF22: 20.833213 | AG22: 3.3162705 | AI22: 2.9415832 | AJ22: 3.391577
A23: Denmark | B23: m | C23: m | E23: m | F23: m | H23: m | I23: m | K23: m | L23: m | N23: m | O23: m | Q23: m | R23: m | T23: m | U23: m | W23: m | X23: m | Z23: m | AA23: m | AC23: m | AD23: m | AF23: m | AG23: m | AI23: m | AJ23: m
A24: Estonia | B24: 11.70672 | C24: 0.66916055 | E24: 17.200339 | F24: 0.84507587 | H24: 5.4936193 | I24: 0.970856 | K24: 17.546404 | L24: 1.1492743 | N24: 9.5593635 | O24: 0.88790354 | Q24: -7.987041 | R24: 1.3608814 | T24: 14.513018 | U24: 0.59120082 | W24: 11.947061 | X24: 5.4564156 | Z24: -2.5659569 | AA24: 5.4387844 | AC24: 14.323626 | AD24: 0.63356038 | AF24: 15.256605 | AG24: 1.5750072 | AI24: 0.93297865 | AJ24: 1.7109607
A25: Finland | B25: 7.3989135 | C25: 0.58135513 | E25: 13.406274 | F25: 0.6931289 | H25: 6.0073607 | I25: 0.9057548 | K25: 14.110372 | L25: 1.1169209 | N25: 8.361861 | O25: 0.72378114 | Q25: -5.7485108 | R25: 1.3337778 | T25: 10.34634 | U25: 0.4543501 | W25: c | X25: c | Z25: c | AA25: c | AC25: 10.14023 | AD25: 0.45220009 | AF25: 13.669499 | AG25: 2.2890983 | AI25: 3.5292686 | AJ25: 2.2702882
A26: France | B26: 9.8976416 | C26: 0.54765862 | E26: 13.678779 | F26: 0.6958986 | H26: 3.7811377 | I26: 0.73382133 | K26: 16.478151 | L26: 0.97025634 | N26: 8.8006526 | O26: 0.85552494 | Q26: -7.6774986 | R26: 1.2599087 | T26: 17.256244 | U26: 1.1661745 | W26: 10.724098 | X26: 0.56140701 | Z26: -6.5321458 | AA26: 1.2926099 | AC26: 11.263862 | AD26: 0.53245402 | AF26: 14.676491 | AG26: 1.4820063 | AI26: 3.4126282 | AJ26: 1.5314824
A27: Germany | B27: 12.907386 | C27: 0.76057865 | E27: 21.068107 | F27: 0.91829783 | H27: 8.1607206 | I27: 1.1803161 | K27: 20.254899 | L27: 1.1887888 | N27: 12.930742 | O27: 1.0788001 | Q27: -7.324157 | R27: 1.7290922 | T27: 16.748831 | U27: 0.61912118 | W27: 16.662561 | X27: 3.2455883 | Z27: -0.086269566 | AA27: 3.309612 | AC27: 16.515858 | AD27: 0.69345102 | AF27: 17.579809 | AG27: 1.387883 | AI27: 1.0639515 | AJ27: 1.5447978
A28: Greece | B28: 14.084884 | C28: 0.70730399 | E28: 16.718838 | F28: 0.69352514 | H28: 2.6339537 | I28: 0.97670259 | K28: 16.448451 | L28: 0.90651914 | N28: 15.262557 | O28: 1.1207949 | Q28: -1.1858941 | R28: 1.3884485 | T28: 19.171266 | U28: 4.6769998 | W28: 15.239728 | X28: 0.48684734 | Z28: -3.931538 | AA28: 4.7012941 | AC28: 15.27905 | AD28: 0.50072511 | AF28: 17.030526 | AG28: 1.6555758 | AI28: 1.7514766 | AJ28: 1.6561208
A29: Hungary | B29: 12.177522 | C29: 0.79291705 | E29: 19.099453 | F29: 0.86910055 | H29: 6.9219305 | I29: 1.1375274 | K29: 19.029611 | L29: 1.2835878 | N29: 13.706061 | O29: 0.98423682 | Q29: -5.3235501 | R29: 1.5881911 | T29: 16.584926 | U29: 1.6687634 | W29: 15.583125 | X29: 0.70909006 | Z29: -1.001801 | AA29: 1.9609565 | AC29: 15.661181 | AD29: 0.63515849 | AF29: 14.3817 | AG29: 3.317779 | AI29: -1.279481 | AJ29: 3.3332365
A30: Iceland | B30: 10.228065 | C30: 0.79866827 | E30: 15.938803 | F30: 0.86316689 | H30: 5.7107377 | I30: 1.2026304 | K30: 17.200943 | L30: 1.2996423 | N30: 11.395282 | O30: 1.063308 | Q30: -5.805661 | R30: 1.7657315 | T30: 13.228972 | U30: 0.57415403 | W30: c | X30: c | Z30: c | AA30: c | AC30: 12.83001 | AD30: 0.58152757 | AF30: 17.820844 | AG30: 3.1977725 | AI30: 4.9908336 | AJ30: 3.2879312
A31: Ireland | B31: 15.48107 | C31: 0.79349597 | E31: 21.362999 | F31: 0.87408492 | H31: 5.8819287 | I31: 1.0770926 | K31: 20.567372 | L31: 1.1349949 | N31: 17.086589 | O31: 1.0079743 | Q31: -3.4807828 | R31: 1.4526814 | T31: 18.797207 | U31: 0.80436489 | W31: 17.808232 | X31: 0.90767009 | Z31: -0.98897485 | AA31: 1.1482281 | AC31: 17.843453 | AD31: 0.64709284 | AF31: 20.305221 | AG31: 1.4698911 | AI31: 2.4617686 | AJ31: 1.4930551
A32: Israel | B32: m | C32: m | E32: m | F32: m | H32: m | I32: m | K32: m | L32: m | N32: m | O32: m | Q32: m | R32: m | T32: m | U32: m | W32: m | X32: m | Z32: m | AA32: m | AC32: m | AD32: m | AF32: m | AG32: m | AI32: m | AJ32: m
A33: Italy | B33: 12.320809 | C33: 0.62148323 | E33: 18.799182 | F33: 0.87641043 | H33: 6.478373 | I33: 1.1332674 | K33: 18.09211 | L33: 1.2290987 | N33: 12.051466 | O33: 0.84035258 | Q33: -6.0406448 | R33: 1.4697222 | T33: 26.226105 | U33: 3.949981 | W33: 15.378116 | X33: 0.52205802 | Z33: -10.847989 | AA33: 3.9797611 | AC33: 14.460344 | AD33: 0.51319455 | AF33: 23.311979 | AG33: 2.0314387 | AI33: 8.8516358 | AJ33: 2.0099384
A34: Japan | B34: 24.935274 | C34: 0.85162344 | E34: 24.519879 | F34: 0.826917 | H34: -0.41539496 | I34: 1.161493 | K34: 25.000095 | L34: 1.1800406 | N34: 23.581819 | O34: 1.2816816 | Q34: -1.4182767 | R34: 1.6980098 | T34: m | U34: m | W34: 24.722135 | X34: 0.60645113 | Z34: m | AA34: m | AC34: w | AD34: w | AF34: w | AG34: w | AI34: w | AJ34: w
A35: Korea | B35: 17.694629 | C35: 0.73600892 | E35: 28.356669 | F35: 0.80374397 | H35: 10.66204 | I35: 0.99073767 | K35: 23.375967 | L35: 1.0846621 | N35: 23.258227 | O35: 1.0738112 | Q35: -0.11774058 | R35: 1.4113441 | T35: 21.231174 | U35: 1.7525273 | W35: 23.07978 | X35: 0.69003407 | Z35: 1.8486063 | AA35: 1.9314987 | AC35: 22.809429 | AD35: 0.62660112 | AF35: c | AG35: c | AI35: c | AJ35: c
A36: Latvia | B36: 11.084753 | C36: 0.72511204 | E36: 15.244973 | F36: 0.87769127 | H36: 4.1602203 | I36: 1.2028276 | K36: 16.482103 | L36: 1.2507219 | N36: 9.9146915 | O36: 0.85162702 | Q36: -6.5674115 | R36: 1.6218179 | T36: 13.113122 | U36: 0.53813933 | W36: 15.825566 | X36: 2.682782 | Z36: 2.7124443 | AA36: 2.6804817 | AC36: 13.125475 | AD36: 0.5514941 | AF36: 14.646358 | AG36: 2.499998 | AI36: 1.5208828 | AJ36: 2.5736779
A37: Lithuania | B37: 9.9535608 | C37: 0.64897129 | E37: 13.402647 | F37: 0.63046195 | H37: 3.4490858 | I37: 0.86137162 | K37: 11.936713 | L37: 0.77747658 | N37: 11.426026 | O37: 0.94985077 | Q37: -0.51068713 | R37: 1.12376 | T37: 11.664196 | U37: 0.47195128 | W37: m | X37: m | Z37: m | AA37: m | AC37: 11.627492 | AD37: 0.47852492 | AF37: 10.917851 | AG37: 2.7138705 | AI37: -0.70964041 | AJ37: 2.8143803
A38: Luxembourg | B38: 13.666265 | C38: 0.75733949 | E38: 18.271304 | F38: 0.70665018 | H38: 4.6050385 | I38: 1.0003346 | K38: 19.838068 | L38: 1.2025732 | N38: 11.122829 | O38: 0.95953485 | Q38: -8.715239 | R38: 1.5143371 | T38: 17.320062 | U38: 0.78137753 | W38: 14.280079 | X38: 0.68286039 | Z38: -3.0399826 | AA38: 1.0192192 | AC38: 14.282689 | AD38: 0.66028544 | AF38: 17.035211 | AG38: 0.75636501 | AI38: 2.7525219 | AJ38: 0.91348562
A39: Mexico | B39: 7.4144432 | C39: 0.54116392 | E39: 9.0019176 | F39: 0.6962375 | H39: 1.5874744 | I39: 0.90201251 | K39: 10.599373 | L39: 0.96924557 | N39: 6.7129417 | O39: 0.72641437 | Q39: -3.8864315 | R39: 1.2488533 | T39: 11.87773 | U39: 1.2757978 | V39: † | W39: 7.5044791 | X39: 0.46660998 | Z39: -4.3732512 | AA39: 1.4026613 | AB39: † | AC39: 7.9499602 | AD39: 0.42318503 | AF39: 15.060016 | AG39: 5.3783391 | AH39: † | AI39: 7.1100558 | AJ39: 5.3441667 | AK39: †
A40: Netherlands* | B40: 3.6903051 | C40: 0.49130929 | E40: 7.6123382 | F40: 0.62279558 | H40: 3.9220331 | I40: 0.71921803 | K40: 7.0935542 | L40: 0.987655 | N40: 4.1702211 | O40: 0.60750407 | Q40: -2.923333 | R40: 1.1235745 | T40: 6.1054691 | U40: 0.57256608 | W40: 5.0354752 | X40: 0.61621202 | Z40: -1.0699939 | AA40: 0.82750103 | AC40: 5.6204632 | AD40: 0.45394802 | AF40: 5.7057583 | AG40: 1.0103274 | AH40: † | AI40: 0.085295106 | AJ40: 1.0288187 | AK40: †
A41: New Zealand | B41: m | C41: m | E41: m | F41: m | H41: m | I41: m | K41: m | L41: m | N41: m | O41: m | Q41: m | R41: m | T41: m | U41: m | W41: m | X41: m | Z41: m | AA41: m | AC41: m | AD41: m | AF41: m | AG41: m | AI41: m | AJ41: m
A42: Norway | B42: m | C42: m | E42: m | F42: m | H42: m | I42: m | K42: m | L42: m | N42: m | O42: m | Q42: m | R42: m | T42: m | U42: m | W42: m | X42: m | Z42: m | AA42: m | AC42: m | AD42: m | AF42: m | AG42: m | AI42: m | AJ42: m
A43: Poland | B43: 15.160984 | C43: 0.76794059 | E43: 23.487747 | F43: 1.0605626 | H43: 8.326763 | I43: 1.2529063 | K43: 20.586583 | L43: 1.2189071 | N43: 17.474484 | O43: 1.0043683 | Q43: -3.1120987 | R43: 1.6117602 | T43: 19.102557 | U43: 0.67079917 | W43: c | X43: c | Z43: c | AA43: c | AC43: 19.334463 | AD43: 0.68805244 | AF43: c | AG43: c | AI43: c | AJ43: c
...

Sheet Table III.B1.11.6
A1: PISA 2018 Results (Volume III) - © OECD 2019
A2: Annex B1 | B2: Annex B1.11 Results (tables): Students' life satisfaction and meaning in life
A3: Version 2 - Last updated: 02-Dec-2019
A4: Disclaimer: http://oe.cd/disclaimer
A6: Table III.B1.11.6
A7: Students who are satisfied with life, by school characteristics
A8: Based on students' reports
B11: Percentage of students who are satisfied or very satisfied1 with life, by the following school characteristics:
B12: School socio-economic profile2 | N12: School location | Z12: School type | AI12: Concentration of immigrant students3
B13: Disadvantaged schools | E13: Socio-economically average schools | H13: Advantaged schools | K13: Advantaged -disadvantaged schools | N13: Rural area or village (fewer than 3 000 people) | Q13: Town (3 000 to 100 000 people) | T13: City (over 100 000 people) | W13: City - rural area | Z13: Public | AC13: Private | AF13: Private - public | AI13: Low immigrant concentration | AL13: High immigrant concentration | AO13: High concentration - low concentration
B14: % | C14: S.E. | E14: % | F14: S.E. | H14: % | I14: S.E. | K14: % dif. | L14: S.E. | N14: % | O14: S.E. | Q14: % | R14: S.E. | T14: % | U14: S.E. | W14: % dif. | X14: S.E. | Z14: % | AA14: S.E. | AC14: % | AD14: S.E. | AF14: % dif. | AG14: S.E. | AI14: % | AJ14: S.E. | AL14: % | AM14: S.E. | AO14: % dif. | AP14: S.E.
A15: OECD
A16: Australia | B16: m | C16: m | E16: m | F16: m | H16: m | I16: m | K16: m | L16: m | N16: m | O16: m | Q16: m | R16: m | T16: m | U16: m | W16: m | X16: m | Z16: m | AA16: m | AC16: m | AD16: m | AF16: m | AG16: m | AI16: m | AJ16: m | AL16: m | AM16: m | AO16: m | AP16: m
A17: Austria | B17: 69.656022 | C17: 1.6183107 | E17: 69.679019 | F17: 1.1492028 | H17: 69.337076 | I17: 1.4511451 | K17: -0.31894579 | L17: 2.273215 | N17: 72.333193 | O17: 3.4013005 | Q17: 71.350589 | R17: 0.92844156 | T17: 65.295495 | U17: 1.5016603 | W17: -7.0376976 | X17: 3.7386005 | Z17: 70.416143 | AA17: 0.76059024 | AC17: 62.807699 | AD17: 3.2422216 | AF17: -7.6084442 | AG17: 3.3859022 | AI17: 72.300044 | AJ17: 1.2576164 | AL17: 68.010351 | AM17: 1.0186616 | AO17: -4.2896928 | AP17: 1.6685852
A18: Belgium | B18: m | C18: m | E18: m | F18: m | H18: m | I18: m | K18: m | L18: m | N18: m | O18: m | Q18: m | R18: m | T18: m | U18: m | W18: m | X18: m | Z18: m | AA18: m | AC18: m | AD18: m | AF18: m | AG18: m | AI18: m | AJ18: m | AL18: m | AM18: m | AO18: m | AP18: m
A19: Canada | B19: m | C19: m | E19: m | F19: m | H19: m | I19: m | K19: m | L19: m | N19: m | O19: m | Q19: m | R19: m | T19: m | U19: m | W19: m | X19: m | Z19: m | AA19: m | AC19: m | AD19: m | AF19: m | AG19: m | AI19: m | AJ19: m | AL19: m | AM19: m | AO19: m | AP19: m
A20: Chile | B20: 64.762873 | C20: 1.285776 | E20: 62.005044 | F20: 1.1398033 | H20: 68.127109 | I20: 1.3785383 | K20: 3.3642366 | L20: 1.8896311 | N20: 61.375508 | O20: 4.486968 | Q20: 64.851684 | R20: 1.2169702 | T20: 64.6724 | U20: 0.96409354 | W20: 3.2968924 | X20: 4.5425739 | Z20: 62.322909 | AA20: 1.2651155 | AC20: 65.273571 | AD20: 0.95407417 | AF20: 2.9506614 | AG20: 1.6078722 | AI20: 64.768782 | AJ20: 0.82134173 | AL20: 60.042646 | AM20: 2.3089817 | AO20: -4.726136 | AP20: 2.5058657
