Workbook
Name calcul: '[3]Calcul_B1.1'!$A$1:$L$37
Name calcul1: '[4]Calcul_B1.1'!$A$1:$L$37
Name p5_age: [6]p5_ageISC5a!$A$1:$D$55
Name p5nr: [7]P5nr_2!$A$1:$AC$43
Name POpula: [8]POpula!$A$1:$I$1559
Name popula1: [8]POpula!$A$1:$I$1559
Name SPSS: [9]Figure5.6!$B$2:$X$30
Name toto: '[10]Graph 3.7.a'!$B$125:$C$151
Name toto1: [11]Data5.11a!$B$3:$C$34
Name weight: [12]F5_W!$A$1:$C$33
Name x: [13]Settings!$B$14

Sheet TOC
A1: PISA 2018 Results (Volume I) - © OECD 2019
A2: Annex B1 | B2: Annex B1 Results for countries and economies
A3: Version 3+1 - Last updated: 24-Jul-2020
A4: Disclaimer: http://oe.cd/disclaimer
A6: Annex B1 | B6: Annex B1 Results for countries and economies
A7: Version 3 - Last updated: 02-Dec-2019
A8: Disclaimer: http://oe.cd/disclaimer
A10: TOC | B10: PISA 2018 Results - Volume I
A12: Annex B1 | B12: Results for countries and economies | N12: Symbols for missing data
A13: Tables | N13: c: There are too few observations or no observation to provide reliable estimates (i.e. there are fewer than 30 students or fewer than 5 schools with valid data).
N14: m: Data are not available. These data were not submitted by the country or were collected but subsequently removed from the publication for technical reasons.
A16: ='Table I.B1.1'!A10 -> Table I.B1.1 | B16: ='Table I.B1.1'!$A$11 -> Percentage of students at each proficiency level in reading | N16: Notes:
A17: ='Table I.B1.2'!A10 -> Table I.B1.2 | B17: ='Table I.B1.2'!$A$11 -> Percentage of students at each proficiency level in mathematics | N17: Information on data for Cyprus: https://oe.cd/cyprus-disclaimer
A18: ='Table I.B1.3'!A10 -> Table I.B1.3 | B18: ='Table I.B1.3'!$A$11 -> Percentage of students at each proficiency level in science | N18: In 2018, some regions in Spain conducted their high-stakes exams for tenth-grade students earlier in the year than in the past, which resulted in the testing period for these exams coinciding with the end of the PISA testing window. Because of this overlap, a number of students were negatively disposed towards the PISA test and did not try their best to demonstrate their proficiency. Although the data of only a minority of students show clear signs of lack of engagement (see PISA 2018 Results Volume I, Annex A9), the comparability of PISA 2018 data for Spain with those from earlier PISA assessments cannot be fully ensured.
A19: ='Table I.B1.4'!A10 -> Table I.B1.4 | B19: ='Table I.B1.4'!$A$11 -> Mean score and variation in reading performance
A20: ='Table I.B1.5'!A10 -> Table I.B1.5 | B20: ='Table I.B1.5'!$A$11 -> Mean score and variation in mathematics performance
A21: ='Table I.B1.6'!A10 -> Table I.B1.6 | B21: ='Table I.B1.6'!$A$11 -> Mean score and variation in science performance
A22: ='Table I.B1.7'!A10 -> Table I.B1.7 | B22: ='Table I.B1.7'!$A$11 -> Percentage of low achievers and top performers in reading, 2009 through 2018
A23: ='Table I.B1.8'!A10 -> Table I.B1.8 | B23: ='Table I.B1.8'!$A$11 -> Percentage of low achievers and top performers in mathematics, 2003 through 2018
A24: ='Table I.B1.9'!A10 -> Table I.B1.9 | B24: ='Table I.B1.9'!$A$11 -> Percentage of low achievers and top performers in science, 2006 through 2018
A25: ='Table I.B1.10'!A10 -> Table I.B1.10 | B25: ='Table I.B1.10'!$A$11 -> Mean reading performance, 2000 through 2018 | N25: OECD averages:
A26: ='Table I.B1.11'!A10 -> Table I.B1.11 | B26: ='Table I.B1.11'!$A$11 -> Mean mathematics performance, 2003 through 2018 | N26: OECD average | O26: Arithmetic mean across all OECD Member countries (and Colombia).
A27: ='Table I.B1.12'!A10 -> Table I.B1.12 | B27: ='Table I.B1.12'!$A$11 -> Mean science performance, 2006 through 2018 | N27: OECD average-37 | O27: Arithmetic mean across all OECD Member countries (and Colombia).
A28: ='Table I.B1.13'!A10 -> Table I.B1.13 | B28: ='Table I.B1.13'!$A$11 -> Distribution of reading scores, 2000 through 2018 | N28: OECD average-36a | O28: Arithmetic mean across all OECD Member countries (and Colombia), excluding Spain.
A29: ='Table I.B1.14'!A10 -> Table I.B1.14 | B29: ='Table I.B1.14'!$A$11 -> Distribution of mathematics scores, 2003 through 2018 | N29: OECD average-36b | O29: Arithmetic mean across all OECD Member countries (and Colombia), excluding Austria.
A30: ='Table I.B1.15'!A10 -> Table I.B1.15 | B30: ='Table I.B1.15'!$A$11 -> Distribution of science scores, 2006 through 2018 | N30: OECD average-35a | O30: Arithmetic mean across all OECD Member countries (and Colombia), excluding Austria and Spain.
A31: ='Table I.B1.16'!A10 -> Table I.B1.16 | B31: ='Table I.B1.16'!$A$11 -> Percentage of students at each level on the cognitive process subscale of reading "locate information" | N31: OECD average-35b | O31: Arithmetic mean across all OECD Member countries (and Colombia), excluding Spain and the United States.
A32: ='Table I.B1.17'!A10 -> Table I.B1.17 | B32: ='Table I.B1.17'!$A$11 -> Percentage of students at each level on the cognitive process subscale of reading "understand" | N32: OECD average-30 | O32: Arithmetic mean across all OECD Member countries, excluding Chile, Colombia, Estonia, Israel, Lithuania, Slovenia and the United Kingdom.
A33: ='Table I.B1.18'!A10 -> Table I.B1.18 | B33: ='Table I.B1.18'!$A$11 -> Percentage of students at each level on the cognitive process subscale of reading "evaluate and reflect" | N33: OECD average-29a | O33: Arithmetic mean across all OECD Member countries, excluding Austria, Chile, Colombia, Estonia, Israel, Lithuania, Slovenia and the United Kingdom.
A34: ='Table I.B1.19'!A10 -> Table I.B1.19 | B34: ='Table I.B1.19'!$A$11 -> Percentage of students at each level on the text structure subscale of reading "single" | N34: OECD average-29b | O34: Arithmetic mean across all OECD Member countries, excluding Chile, Colombia, Estonia, Israel, Lithuania, Slovenia, Spain and the United Kingdom.
A35: ='Table I.B1.20'!A10 -> Table I.B1.20 | B35: ='Table I.B1.20'!$A$11 -> Percentage of students at each level on the text structure subscale of reading "multiple" | N35: OECD average-27 | O35: Arithmetic mean across all OECD Member countries, excluding Colombia, Estonia, Lithuania, Luxembourg, the Netherlands, the Slovak Republic, Slovenia, Spain, Turkey and the United Kingdom.
A36: ='Table I.B1.21'!A10 -> Table I.B1.21 | B36: ='Table I.B1.21'!$A$11 -> Mean score and variation in the cognitive process subscale of reading "locate information" | N36: OECD average-23 | O36: Arithmetic mean across all OECD Member countries, excluding Austria, Chile, Colombia, Estonia, Israel, Lithuania, Luxembourg, the Netherlands, the Slovak Republic, Slovenia, Spain, Turkey, the United Kingdom and the United States.
A37: ='Table I.B1.22'!A10 -> Table I.B1.22 | B37: ='Table I.B1.22'!$A$11 -> Mean score and variation in the cognitive process subscale of reading "understand"
A38: ='Table I.B1.23'!A10 -> Table I.B1.23 | B38: ='Table I.B1.23'!$A$11 -> Mean score and variation in the cognitive process subscale of reading "evaluate and reflect"
A39: ='Table I.B1.24'!A10 -> Table I.B1.24 | B39: ='Table I.B1.24'!$A$11 -> Mean score and variation in the text structure subscale of reading "single"
A40: ='Table I.B1.25'!A10 -> Table I.B1.25 | B40: ='Table I.B1.25'!$A$11 -> Mean score and variation in the text structure subscale of reading "multiple"
A41: ='Table I.B1.26'!A10 -> Table I.B1.26 | B41: ='Table I.B1.26'!$A$11 -> Top performers in reading, mathematics and science
A42: ='Table I.B1.27'!A10 -> Table I.B1.27 | B42: ='Table I.B1.27'!$A$11 -> Low achievers in reading, mathematics and science
A43: ='Table I.B1.28'!A10 -> Table I.B1.28 | B43: ='Table I.B1.28'!$A$11 -> Variation in reading performance, 2000 through 2018
A44: ='Table I.B1.29'!A10 -> Table I.B1.29 | B44: ='Table I.B1.29'!$A$11 -> Variation in mathematics performance, 2003 through 2018
...

Sheet Table I.B1.1
A1: PISA 2018 Results (Volume I) - © OECD 2019
A2: Annex B1 | B2: Annex B1 Results for countries and economies
A3: Version 3+1 - Last updated: 24-Jul-2020
A4: Disclaimer: http://oe.cd/disclaimer
A6: Annex B1 | B6: Annex B1 Results for countries and economies
A7: Version 3 - Last updated: 02-Dec-2019
A8: Disclaimer: http://oe.cd/disclaimer
A10: Table I.B1.1
A11: Percentage of students at each proficiency level in reading
B16: All students
B17: Below Level 1c (less than 189.33 score points) | D17: Level 1c (from 189.33 to less than 262.04 score points) | F17: Level 1b (from 262.04 to less than 334.75 score points) | H17: Level 1a (from 334.75 to less than 407.47 score points) | J17: Level 2 (from 407.47 to less than 480.18 score points) | L17: Level 3 (from 480.18 to less than 552.89 score points) | N17: Level 4 (from 552.89 to less than 625.61 score points) | P17: Level 5 (from 625.61 to less than 698.32 score points) | R17: Level 6 (above 698.32 score points)
B18: % | C18: S.E. | D18: % | E18: S.E. | F18: % | G18: S.E. | H18: % | I18: S.E. | J18: % | K18: S.E. | L18: % | M18: S.E. | N18: % | O18: S.E. | P18: % | Q18: S.E. | R18: % | S18: S.E.
A19: OECD
A20: Australia | B20: 0.10395926 | C20: 0.056260686 | D20: 1.4214947 | E20: 0.15491292 | F20: 5.5717758 | G20: 0.29423619 | H20: 12.530159 | I20: 0.35504315 | J20: 21.1112 | K20: 0.4759832 | L20: 25.37531 | M20: 0.51454823 | N20: 20.868243 | O20: 0.48937582 | P20: 10.329688 | Q20: 0.36230161 | R20: 2.6881695 | S20: 0.21461339
A21: Austria | B21: 0.039336766 | C21: 0.032563692 | D21: 0.918584 | E21: 0.1940297 | F21: 6.4072487 | G21: 0.56754915 | H21: 16.258093 | I21: 0.83795492 | J21: 23.483885 | K21: 0.82643146 | L21: 26.211394 | M21: 0.87493812 | N21: 19.270051 | O21: 0.78144485 | P21: 6.6720101 | Q21: 0.46847157 | R21: 0.73939755 | S21: 0.13139879
A22: Belgium | B22: 0.0646797 | C22: 0.05285052 | D22: 1.1505115 | E22: 0.19348826 | F22: 5.9915311 | G22: 0.43096362 | H22: 14.04674 | I22: 0.61815945 | J22: 22.355538 | K22: 0.65657695 | L22: 26.482681 | M22: 0.68095324 | N22: 20.361348 | O22: 0.71221569 | P22: 8.2653141 | Q22: 0.49123013 | R22: 1.2816566 | S22: 0.20068295
A23: Canada | B23: 0.035805952 | C23: 0.02216128 | D23: 0.65943142 | E23: 0.1070178 | F23: 3.0996066 | G23: 0.20189962 | H23: 9.9554683 | I23: 0.38590888 | J23: 20.118562 | K23: 0.57076995 | L23: 27.164958 | M23: 0.46349838 | N23: 23.973146 | O23: 0.51324188 | P23: 12.154291 | Q23: 0.46271396 | R23: 2.83873 | S23: 0.22909433
A24: Chile | B24: 0.099852759 | C24: 0.087152802 | D24: 1.7179544 | E24: 0.23794606 | F24: 8.8680682 | G24: 0.61816419 | H24: 21.035076 | I24: 0.90086227 | J24: 29.487161 | K24: 0.85622539 | L24: 24.418887 | M24: 0.85653009 | N24: 11.778833 | O24: 0.59873503 | P24: 2.4104332 | Q24: 0.28258513 | R24: 0.18373441 | S24: 0.071122049
A25: Colombia | B25: 0.17194844 | C25: 0.079521444 | D25: 3.6270831 | E25: 0.44853714 | F25: 15.77913 | G25: 0.93144122 | H25: 30.324988 | I25: 1.0325813 | J25: 27.662931 | K25: 0.99468677 | L25: 15.811803 | M25: 0.85129016 | N25: 5.676212 | O25: 0.54939362 | P25: 0.91093191 | Q25: 0.17503737 | R25: 0.034972261 | S25: 0.028272856
A26: Czech Republic | B26: 0.061976885 | C26: 0.056551752 | D26: 0.73624257 | E26: 0.21041958 | F26: 4.9627911 | G26: 0.53902823 | H26: 14.979472 | I26: 0.78282252 | J26: 24.956897 | K26: 0.87449554 | L26: 26.936234 | M26: 0.89591329 | N26: 19.129919 | O26: 0.7789054 | P26: 7.1840825 | Q26: 0.48176773 | R26: 1.0523839 | S26: 0.19316367
A27: Denmark | B27: 0.030539835 | C27: 0.033699572 | D27: 0.5494429 | E27: 0.13711548 | F27: 3.5125758 | G27: 0.3117888 | H27: 11.906975 | I27: 0.54267977 | J27: 23.901207 | K27: 0.7977808 | L27: 30.107231 | M27: 0.89097258 | N27: 21.576709 | O27: 0.79568931 | P27: 7.312377 | Q27: 0.47973065 | R27: 1.1029415 | S27: 0.20473092
A28: Estonia | B28: 0 | C28: c | D28: 0.28517573 | E28: 0.10184409 | F28: 2.0593108 | G28: 0.22604757 | H28: 8.7097949 | I28: 0.50378644 | J28: 21.159821 | K28: 0.86175316 | L28: 29.896048 | M28: 0.86967371 | N28: 24.030531 | O28: 0.79892133 | P28: 11.053392 | Q28: 0.57143666 | R28: 2.8059261 | S28: 0.32120527
A29: Finland | B29: 0.048442318 | C29: 0.03514403 | D29: 0.79997961 | E29: 0.1632959 | F29: 3.3262646 | G29: 0.37516776 | H29: 9.3698398 | I29: 0.56591805 | J29: 19.24947 | K29: 0.7036438 | L29: 27.583047 | M29: 0.81367674 | N29: 25.389044 | O29: 0.78438035 | P29: 11.870714 | Q29: 0.67462714 | R29: 2.3631993 | S29: 0.33350159
A30: France | B30: 0.045047046 | C30: 0.037692657 | D30: 1.132848 | E30: 0.16912385 | F30: 5.7374064 | G30: 0.43439953 | H30: 14.021949 | I30: 0.65139532 | J30: 22.84602 | K30: 0.82065929 | L30: 26.566999 | M30: 0.84699786 | N30: 20.452641 | O30: 0.70525275 | P30: 8.0605466 | Q30: 0.6243713 | R30: 1.1365437 | S30: 0.19303611
A31: Germany | B31: 0.061441456 | C31: 0.051014153 | D31: 1.3033194 | E31: 0.25544398 | F31: 5.7471455 | G31: 0.5090169 | H31: 13.573189 | I31: 0.84267025 | J31: 21.130336 | K31: 0.80695854 | L31: 25.40579 | M31: 0.75164437 | N31: 21.472556 | O31: 0.86729593 | P31: 9.5100681 | Q31: 0.60287846 | R31: 1.796156 | S31: 0.22955944
A32: Greece | B32: 0.12113321 | C32: 0.066180557 | D32: 2.1185027 | E32: 0.3280473 | F32: 9.3227126 | G32: 0.74803855 | H32: 18.953448 | I32: 0.90298273 | J32: 27.347574 | K32: 0.79035207 | L32: 25.151832 | M32: 1.0364895 | N32: 13.334697 | O32: 0.80254351 | P32: 3.3114228 | Q32: 0.44455132 | R32: 0.33867732 | S32: 0.10849432
A33: Hungary | B33: 0.035972986 | C33: 0.054453302 | D33: 1.247905 | E33: 0.2308527 | F33: 6.9616581 | G33: 0.61562771 | H33: 17.028408 | I33: 0.77043271 | J33: 25.162039 | K33: 0.86505852 | L33: 26.323718 | M33: 0.92989136 | N33: 17.531982 | O33: 0.79484072 | P33: 5.1976851 | Q33: 0.48314599 | R33: 0.51063173 | S33: 0.14616255
A34: Iceland | B34: 0.1227935 | C34: 0.082641593 | D34: 2.312583 | E34: 0.34692133 | F34: 8.0387355 | G34: 0.72266077 | H34: 15.881787 | I34: 0.84997502 | J34: 24.60912 | K34: 0.94964512 | L34: 25.074249 | M34: 0.84509055 | N34: 16.854802 | O34: 0.72750663 | P34: 6.2447388 | Q34: 0.57877528 | R34: 0.8611915 | S34: 0.22967015
A35: Ireland | B35: 0.001470123 | C35: 0.0068348704 | D35: 0.21291446 | E35: 0.078927288 | F35: 2.1109862 | G35: 0.26633853 | H35: 9.4739786 | I35: 0.60023386 | J35: 21.742397 | K35: 0.81578015 | L35: 30.290825 | M35: 0.85958278 | N35: 24.07889 | O35: 0.79047041 | P35: 10.329447 | Q35: 0.57663923 | R35: 1.7590918 | S35: 0.27062138
A36: Israel | B36: 0.74781062 | C36: 0.18959369 | D36: 4.9662841 | E36: 0.51004779 | F36: 10.372669 | G36: 0.67442767 | H36: 14.97535 | I36: 0.8520132 | J36: 19.409056 | K36: 0.73797321 | L36: 21.579246 | M36: 0.79318763 | N36: 17.54329 | O36: 0.78575082 | P36: 8.3583209 | Q36: 0.55247666 | R36: 2.0479734 | S36: 0.27862991
A37: Italy | B37: 0.14768735 | C37: 0.065021753 | D37: 1.6540384 | E37: 0.27261858 | F37: 6.6923664 | G37: 0.58138961 | H37: 14.77308 | I37: 0.70865305 | J37: 26.286987 | K37: 0.88396476 | L37: 28.213774 | M37: 0.94071938 | N37: 16.887359 | O37: 0.71401557 | P37: 4.8787787 | Q37: 0.43362709 | R37: 0.46592877 | S37: 0.13210369
A38: Japan | B38: 0.056546188 | C38: 0.042262587 | D38: 0.65042201 | E38: 0.16431578 | F38: 4.0778467 | G38: 0.42644149 | H38: 11.994356 | I38: 0.65727965 | J38: 22.498558 | K38: 0.8538702 | L38: 28.609232 | M38: 0.95337149 | N38: 21.862572 | O38: 0.76213426 | P38: 8.5968764 | Q38: 0.62822933 | R38: 1.6535895 | S38: 0.26192863
A39: Korea | B39: 0.065184927 | C39: 0.058700352 | D39: 1.1077133 | E39: 0.19722989 | F39: 4.3120663 | G39: 0.37803498 | H39: 9.6233062 | I39: 0.65598767 | J39: 19.578623 | K39: 0.69390976 | L39: 27.634567 | M39: 0.80452897 | N39: 24.55522 | O39: 0.81617803 | P39: 10.805079 | Q39: 0.64930806 | R39: 2.31824 | S39: 0.35813533
A40: Latvia | B40: 0.02080514 | C40: 0.020396826 | D40: 0.59036084 | E40: 0.14365566 | F40: 5.2187602 | G40: 0.43599019 | H40: 16.612955 | I40: 0.6126251 | J40: 27.379078 | K40: 0.84924258 | L40: 28.793708 | M40: 0.84275158 | N40: 16.565046 | O40: 0.72741308 | P40: 4.422259 | Q40: 0.43187095 | R40: 0.39702825 | S40: 0.13620433
... A50: Slovenia | B50: 0.045331714 | C50: 0.050039414 | D50: 0.64440041 | E50: 0.16018227 | F50: 4.2503694 | G50: 0.38619084 | H50: 12.94089 | I50: 0.54194306 | J50: 24.524055 | K50: 0.75090254 | L50: 29.535149 | M50: 0.87598448 | N50: 20.306574 | O50: 0.68165363 | P50: 6.7777795 | Q50: 0.47347035 | R50: 0.97545134 | S50: 0.22028736
A51: Spain | B51: m | C51: m | D51: m | E51: m | F51: m | G51: m | H51: m | I51: m | J51: m | K51: m | L51: m | M51: m | N51: m | O51: m | P51: m | Q51: m | R51: m | S51: m
A52: Sweden | B52: 0.15330846 | C52: 0.066699009 | D52: 1.4621934 | E52: 0.19886999 | F52: 5.1405629 | G52: 0.49708407 | H52: 11.636979 | I52: 0.71672354 | J52: 20.605969 | K52: 0.75845667 | L52: 25.47285 | M52: 0.75230602 | N52: 22.254771 | O52: 0.8147501 | P52: 10.884074 | Q52: 0.67537402 | R52: 2.3892934 | S52: 0.26595261
A53: Switzerland | B53: 0.095534514 | C53: 0.058415964 | D53: 1.3122096 | E53: 0.25644631 | F53: 7.1230009 | G53: 0.58910273 | H53: 15.103314 | I53: 0.74306645 | J53: 23.420626 | K53: 0.94641741 | L53: 26.334764 | M53: 0.82555046 | N53: 18.510937 | O53: 0.75644645 | P53: 6.9457578 | Q53: 0.63731709 | R53: 1.153856 | S53: 0.23871713
A54: Turkey | B54: 0.013830822 | C54: 0.02050441 | D54: 0.68882872 | E54: 0.17478795 | F54: 6.3454731 | G54: 0.60620028 | H54: 19.08412 | I54: 0.72407859 | J54: 30.174289 | K54: 0.87638515 | L54: 26.877445 | M54: 0.97512504 | N54: 13.488857 | O54: 0.60249634 | P54: 3.1265762 | Q54: 0.45604051 | R54: 0.20058067 | S54: 0.093330248
A55: United Kingdom | B55: 0.027651002 | C55: 0.025975544 | D55: 0.81736856 | E55: 0.1592189 | F55: 4.1727486 | G55: 0.38924589 | H55: 12.285327 | I55: 0.67624008 | J55: 22.981228 | K55: 0.72059425 | L55: 27.219269 | M55: 0.67438343 | N55: 21.045052 | O55: 0.81825209 | P55: 9.4512829 | Q55: 0.62900158 | R55: 2.0000725 | S55: 0.24148409
...

Sheet Table I.B1.2
A1: PISA 2018 Results (Volume I) - © OECD 2019
A2: Annex B1 | B2: Annex B1 Results for countries and economies
A3: Version 3+1 - Last updated: 24-Jul-2020
A4: Disclaimer: http://oe.cd/disclaimer
A6: Annex B1 | B6: Annex B1 Results for countries and economies
A7: Version 3 - Last updated: 02-Dec-2019
A8: Disclaimer: http://oe.cd/disclaimer
A10: Table I.B1.2
A11: Percentage of students at each proficiency level in mathematics
B16: All students
B17: Below Level 1 (below 357.77 score points) | D17: Level 1 (from 357.77 to less than 420.07 score points) | F17: Level 2 (from 420.07 to less than 482.38 score points) | H17: Level 3 (from 482.38 to less than 544.68 score points) | J17: Level 4 (from 544.68 to less than 606.99 score points) | L17: Level 5 (from 606.99 to less than 669.30 score points) | N17: Level 6 (above 669.30 score points)
B18: % | C18: S.E. | D18: % | E18: S.E. | F18: % | G18: S.E. | H18: % | I18: S.E. | J18: % | K18: S.E. | L18: % | M18: S.E. | N18: % | O18: S.E.
A19: OECD
A20: Australia | B20: 7.6186715 | C20: 0.50295224 | D20: 14.814451 | E20: 0.53336438 | F20: 23.376645 | G20: 0.52198475 | H20: 25.550001 | I20: 0.50749756 | J20: 18.177123 | K20: 0.47110829 | L20: 8.0039973 | M20: 0.37565283 | N20: 2.45911 | O20: 0.27773573
A21: Austria | B21: 7.2719516 | C21: 0.66084931 | D21: 13.806926 | E21: 0.80228669 | F21: 20.827325 | G21: 0.95039305 | H21: 24.906693 | I21: 0.9466484 | J21: 20.628732 | K21: 0.82487784 | L21: 10.033267 | M21: 0.66959644 | N21: 2.5251056 | O21: 0.33463686
A22: Belgium | B22: 6.8631034 | C22: 0.65441611 | D22: 12.798822 | E22: 0.64258291 | F22: 18.616673 | G22: 0.65235476 | H22: 23.765891 | I22: 0.76008645 | J22: 22.223697 | K22: 0.74615889 | L22: 12.499155 | M22: 0.62509045 | N22: 3.232659 | O22: 0.40326491
A23: Canada | B23: 4.9857808 | C23: 0.40073775 | D23: 11.275408 | E23: 0.52152693 | F23: 20.811211 | G23: 0.61149403 | H23: 25.876744 | I23: 0.56778254 | J23: 21.721628 | K23: 0.74306967 | L23: 11.311396 | M23: 0.48976271 | N23: 4.0178317 | O23: 0.33355196
A24: Chile | B24: 24.677317 | C24: 1.110858 | D24: 27.231242 | E24: 0.94655572 | F24: 25.528044 | G24: 0.88814807 | H24: 15.62227 | I24: 0.75675079 | J24: 5.7148664 | K24: 0.47519723 | L24: 1.0979946 | M24: 0.17349399 | N24: 0.12826666 | O24: 0.04763931
A25: Colombia | B25: 35.500749 | C25: 1.6872141 | D25: 29.886046 | E25: 1.2173389 | F25: 21.088514 | G25: 0.91366253 | H25: 9.9501586 | I25: 0.68819162 | J25: 3.0586964 | K25: 0.38197488 | L25: 0.48672442 | M25: 0.13960151 | N25: 0.029111061 | O25: 0.026339222
A26: Czech Republic | B26: 6.6257874 | C26: 0.68925118 | D26: 13.759293 | E26: 0.7117445 | F26: 22.105959 | G26: 0.82102364 | H26: 25.194517 | I26: 0.93399558 | J26: 19.646933 | K26: 0.74023164 | L26: 9.5267067 | M26: 0.52897804 | N26: 3.1408045 | O26: 0.33319371
A27: Denmark | B27: 3.7152444 | C27: 0.35276393 | D27: 10.855949 | E27: 0.58487486 | F27: 21.970503 | G27: 0.87269942 | H27: 28.819543 | I27: 0.84459723 | J27: 23.010397 | K27: 0.79067255 | L27: 9.5073188 | M27: 0.60353773 | N27: 2.1210444 | O27: 0.31025093
A28: Estonia | B28: 2.0866728 | C28: 0.27320153 | D28: 8.1297435 | E28: 0.56935466 | F28: 20.790874 | G28: 0.80510158 | H28: 28.953315 | I28: 0.82316495 | J28: 24.553716 | K28: 0.76171597 | L28: 11.820761 | M28: 0.68002034 | N28: 3.6649176 | O28: 0.39867419
A29: Finland | B29: 3.8451535 | C29: 0.40267719 | D29: 11.130382 | E29: 0.55946901 | F29: 22.295645 | G29: 0.85486948 | H29: 28.936811 | I29: 0.99418042 | J29: 22.666551 | K29: 0.80544214 | L29: 9.3159481 | M29: 0.53643106 | N29: 1.8095094 | O29: 0.28509672
A30: France | B30: 8.0465285 | C30: 0.53105691 | D30: 13.209103 | E30: 0.62056711 | F30: 21.101688 | G30: 0.80338974 | H30: 25.57541 | I30: 0.78651548 | J30: 21.042753 | K30: 0.81573371 | L30: 9.2315067 | M30: 0.62666142 | N30: 1.7930096 | O30: 0.27414705
A31: Germany | B31: 7.5620818 | C31: 0.66598721 | D31: 13.534535 | E31: 0.82673483 | F31: 20.740656 | G31: 0.90362327 | H31: 24.026693 | I31: 0.759043 | J31: 20.816189 | K31: 0.81612896 | L31: 10.509824 | M31: 0.71680785 | N31: 2.8100206 | O31: 0.30445201
... A58: OECD total | B58: 11.530908 | C58: 0.28348323 | D58: 17.175892 | E58: 0.26128325 | F58: 22.925564 | G58: 0.31328328 | H58: 22.586246 | I58: 0.29153124 | J58: 16.314243 | K58: 0.28036419 | L58: 7.4233759 | M58: 0.22007222 | N58: 2.0437696 | O58: 0.095685817
A59: Partners
A60: Albania | B60: 16.914099 | C60: 0.8713184 | D60: 25.45875 | E60: 0.8766103 | F60: 28.562373 | G60: 0.98008897 | H60: 19.272073 | I60: 0.8470423 | J60: 7.4965418 | K60: 0.65650369 | L60: 1.9734969 | M60: 0.24028911 | N60: 0.32266487 | O60: 0.13481963
A61: Argentina | B61: 40.473342 | C61: 1.5766349 | D61: 28.493777 | E61: 1.0417193 | F61: 19.61868 | G61: 0.87595501 | H61: 8.8199877 | I61: 0.65225301 | J61: 2.2565642 | K61: 0.26429835 | L61: 0.32754306 | M61: 0.096433215 | N61: 0.010105846 | O61: 0.01578183
A62: Baku (Azerbaijan) | B62: 24.6611 | C62: 1.0048911 | D62: 26.073759 | E62: 0.82380182 | F62: 25.210254 | G62: 0.85221031 | H62: 15.662285 | I62: 0.70972092 | J62: 6.4221624 | K62: 0.58508764 | L62: 1.6815614 | M62: 0.26729485 | N62: 0.28887781 | O62: 0.10384555
A63: Belarus | B63: 11.373434 | C63: 0.73002108 | D63: 17.989151 | E63: 0.72112666 | F63: 24.707071 | G63: 0.85743138 | H63: 23.408531 | I63: 0.74893725 | J63: 15.224264 | K63: 0.74840803 | L63: 6.0567724 | M63: 0.5312722 | N63: 1.2407771 | O63: 0.2443804
A64: Bosnia and Herzegovina | B64: 28.708621 | C64: 1.3499743 | D64: 28.854789 | E64: 1.022434 | F64: 24.192821 | G64: 0.90254729 | H64: 13.137133 | I64: 0.79906056 | J64: 4.3143571 | K64: 0.47284469 | L64: 0.73806839 | M64: 0.18783418 | N64: 0.05420955 | O64: 0.042941402
A65: Brazil | B65: 41.025277 | C65: 0.99007956 | D65: 27.068589 | E65: 0.71058884 | F65: 18.236675 | G65: 0.66527974 | H65: 9.2843777 | I65: 0.46611065 | J65: 3.445818 | K65: 0.32297846 | L65: 0.80972719 | M65: 0.1676613 | N65: 0.12953555 | O65: 0.048787236
A66: Brunei Darussalam | B66: 22.148388 | C66: 0.80030061 | D66: 25.719864 | E66: 0.78443018 | F66: 24.03742 | G66: 0.60808833 | H66: 16.168699 | I66: 0.5297332 | J66: 8.8935798 | K66: 0.46154621 | L66: 2.6767153 | M66: 0.27813321 | N66: 0.35533408 | O66: 0.082794938
A67: B-S-J-Z (China) | B67: 0.4973956 | C67: 0.14515745 | D67: 1.9149555 | E67: 0.30470357 | F67: 6.8878683 | G67: 0.51526488 | H67: 17.500926 | I67: 0.78497818 | J67: 28.897452 | K67: 0.98008629 | L67: 27.842529 | M67: 0.96936462 | N67: 16.458874 | O67: 1.1481889
A68: Bulgaria | B68: 21.920588 | C68: 1.4027982 | D68: 22.492254 | E68: 0.83370869 | F68: 23.724763 | G68: 0.95336664 | H68: 18.203795 | I68: 0.97834564 | J68: 9.444932 | K68: 0.65384205 | L68: 3.3331489 | M68: 0.50208611 | N68: 0.88051905 | O68: 0.22027036
A69: Costa Rica | B69: 27.818007 | C69: 1.2757195 | D69: 32.180081 | E69: 1.221213 | F69: 25.645273 | G69: 1.2334513 | H69: 11.193971 | I69: 1.0254244 | J69: 2.8419212 | K69: 0.54856783 | L69: 0.31307643 | M69: 0.11649213 | N69: 0.0076710723 | O69: 0.022633695
A70: Croatia | B70: 10.980081 | C70: 0.82239225 | D70: 20.180659 | E70: 0.83095704 | F70: 27.379067 | G70: 0.8737235 | H70: 23.298992 | I70: 0.80322798 | J70: 13.02056 | K70: 0.75339405 | L70: 4.3151086 | M70: 0.48333195 | N70: 0.82553242 | O70: 0.20074788
A71: Cyprus | B71: 17.201899 | C71: 0.61700897 | D71: 19.653454 | E71: 0.65883785 | F71: 24.695005 | G71: 0.90079093 | H71: 21.975585 | I71: 0.84956584 | J71: 12.092378 | K71: 0.54642451 | L71: 3.7260509 | M71: 0.35262229 | N71: 0.65562697 | O71: 0.14535974
A72: Dominican Republic | B72: 69.280033 | C72: 1.4020058 | D72: 21.277874 | E72: 0.95108024 | F72: 7.2908842 | G72: 0.63404688 | H72: 1.8438838 | I72: 0.40904337 | J72: 0.27932497 | K72: 0.11172031 | L72: 0.02799979 | M72: 0.032297657 | N72: 0 | O72: c
...

Sheet Table I.B1.3
A1: PISA 2018 Results (Volume I) - © OECD 2019
A2: Annex B1 | B2: Annex B1 Results for countries and economies
A3: Version 3+1 - Last updated: 24-Jul-2020
A4: Disclaimer: http://oe.cd/disclaimer
A6: Annex B1 | B6: Annex B1 Results for countries and economies
A7: Version 3 - Last updated: 02-Dec-2019
A8: Disclaimer: http://oe.cd/disclaimer
A10: Table I.B1.3
A11: Percentage of students at each proficiency level in science
B16: All students
B17: Below Level 1b (below 260.54 score points) | D17: Level 1b (from 260.54 to less than 334.94 score points) | F17: Level 1a (from 334.94 to less than 409.54 score points) | H17: Level 2 (from 409.54 to less than 484.14 score points) | J17: Level 3 (from 484.14 to less than 558.73 score points) | L17: Level 4 (from 558.73 to less than 633.33 score points) | N17: Level 5 (from 633.33 to less than 707.93 score points) | P17: Level 6 (above 707.93 score points)
B18: % | C18: S.E. | D18: % | E18: S.E. | F18: % | G18: S.E. | H18: % | I18: S.E. | J18: % | K18: S.E. | L18: % | M18: S.E. | N18: % | O18: S.E. | P18: % | Q18: S.E.
A19: OECD
A20: Australia | B20: 0.64464273 | C20: 0.10097902 | D20: 4.4672317 | E20: 0.28038226 | F20: 13.748146 | G20: 0.48268401 | H20: 23.00219 | I20: 0.55715572 | J20: 27.493664 | K20: 0.59916791 | L20: 21.162923 | M20: 0.5678533 | N20: 7.9244559 | O20: 0.39677207 | P20: 1.5567465 | Q20: 0.22150996
A21: Austria | B21: 0.55763248 | C21: 0.15567513 | D21: 4.8414811 | E21: 0.46845038 | F21: 16.452096 | G21: 0.91132932 | H21: 24.975881 | I21: 0.84692352 | J21: 27.639829 | K21: 0.76841253 | L21: 19.237713 | M21: 0.81974323 | N21: 5.8407157 | O21: 0.55611965 | P21: 0.45465157 | Q21: 0.12064746
A22: Belgium | B22: 0.55065091 | C22: 0.14880841 | D22: 5.3058709 | E22: 0.4809719 | F22: 14.150575 | G22: 0.62631933 | H22: 22.224532 | I22: 0.74793053 | J22: 28.40278 | K22: 0.79846209 | L22: 21.332323 | M22: 0.69244025 | N22: 7.3175002 | O22: 0.40736299 | P22: 0.71576752 | Q22: 0.15274031
A23: Canada | B23: 0.39944823 | C23: 0.069598077 | D23: 2.5752999 | E23: 0.19639584 | F23: 10.461168 | G23: 0.4303007 | H23: 22.380403 | I23: 0.56994868 | J23: 29.349304 | K23: 0.6264621 | L23: 23.502881 | M23: 0.65541601 | N23: 9.5079726 | O23: 0.46344647 | P23: 1.8235234 | Q23: 0.2254422
A24: Chile | B24: 0.97172754 | C24: 0.20622094 | D24: 8.8273447 | E24: 0.66576655 | F24: 25.544428 | G24: 1.0017839 | H24: 33.124784 | I24: 0.98230605 | J24: 22.561535 | K24: 0.96289249 | L24: 7.9401196 | M24: 0.5558375 | N24: 0.99574149 | O24: 0.17653839 | P24: 0.034319116 | Q24: 0.023788557
A25: Colombia | B25: 2.0667215 | C25: 0.32749285 | D25: 15.310341 | E25: 1.1187009 | F25: 32.989774 | G25: 1.0718977 | H25: 29.641057 | I25: 1.2061427 | J25: 15.366948 | K25: 0.84401423 | L25: 4.1840678 | M25: 0.44188373 | N25: 0.42860848 | O25: 0.10923784 | P25: 0.012483044 | Q25: 0.016033248
A26: Czech Republic | B26: 0.38147813 | C26: 0.12538744 | D26: 3.8978667 | E26: 0.445075 | F26: 14.485357 | G26: 0.8244269 | H26: 25.925214 | I26: 0.9650935 | J26: 28.712048 | K26: 0.95870739 | L26: 19.063634 | M26: 0.84006737 | N26: 6.583992 | O26: 0.47907866 | P26: 0.95040943 | Q26: 0.18325763
A27: Denmark | B27: 0.65742071 | C27: 0.16945597 | D27: 4.1473808 | E27: 0.3384917 | F27: 13.850992 | G27: 0.60072868 | H27: 26.568379 | I27: 0.69815908 | J27: 30.114505 | K27: 0.91900555 | L27: 19.13384 | M27: 0.813075 | N27: 5.0002122 | O27: 0.47505813 | P27: 0.52726978 | Q27: 0.16054814
A28: Estonia | B28: 0.095427231 | C28: 0.057448489 | D28: 1.1294515 | E28: 0.2065183 | F28: 7.5327177 | G28: 0.54901395 | H28: 21.512143 | I28: 0.73920249 | J28: 32.106341 | K28: 0.90158629 | L28: 25.424817 | M28: 0.83015981 | N28: 10.246242 | O28: 0.53146786 | P28: 1.95286 | Q28: 0.24477132
A29: Finland | B29: 0.43770182 | C29: 0.12175268 | D29: 2.7973964 | E29: 0.33236324 | F29: 9.6518581 | G29: 0.5515055 | H29: 21.07524 | I29: 0.71287699 | J29: 28.886575 | K29: 0.83997994 | L29: 24.884845 | M29: 0.82967427 | N29: 10.477664 | O29: 0.62040155 | P29: 1.7887193 | Q29: 0.33807088
A30: France | B30: 0.60209327 | C30: 0.17352084 | D30: 5.0054357 | E30: 0.42356092 | F30: 14.892057 | G30: 0.75428193 | H30: 24.573937 | I30: 0.88638106 | J30: 28.345536 | K30: 0.74880023 | L30: 20.030017 | M30: 0.88464236 | N30: 5.9132752 | O30: 0.49780345 | P30: 0.63764959 | Q30: 0.13980198
A31: Germany | B31: 0.76243148 | C31: 0.21241604 | D31: 5.0309063 | E31: 0.51610605 | F31: 13.807421 | G31: 0.74248583 | H31: 22.031407 | I31: 0.94575686 | J31: 26.918714 | K31: 0.93262737 | L31: 21.455325 | M31: 0.99152071 | N31: 8.5121979 | O31: 0.58482732 | P31: 1.4815977 | Q31: 0.20969577
... A42: Luxembourg | B42: 0.81938599 | C42: 0.17449973 | D42: 6.7818434 | E42: 0.39915977 | F42: 19.164407 | G42: 0.63179992 | H42: 25.679592 | I42: 0.81289151 | J42: 25.554785 | K42: 0.75770292 | L42: 16.551041 | M42: 0.58035501 | N42: 4.9338787 | O42: 0.50696337 | P42: 0.51506725 | Q42: 0.15830616
A43: Mexico | B43: 1.021098 | C43: 0.25774252 | D43: 11.605914 | E43: 0.97204628 | F43: 34.180679 | G43: 1.2708951 | H43: 33.949592 | I43: 0.93032536 | J43: 15.453605 | K43: 0.86668871 | L43: 3.5363235 | M43: 0.46928572 | N43: 0.25278749 | O43: 0.097081139 | P43: 0 | Q43: c
A44: Netherlands* | B44: 0.89756768 | C44: 0.24649506 | D44: 4.764792 | E44: 0.51241995 | F44: 14.376085 | G44: 0.81921802 | H44: 22.437345 | I44: 0.83351047 | J44: 24.859775 | K44: 1.0862595 | L44: 22.054481 | M44: 1.0345304 | N44: 9.1004937 | O44: 0.67810602 | P44: 1.5094614 | Q44: 0.25416525
A45: New Zealand | B45: 0.61092095 | C45: 0.15256296 | D45: 4.312238 | E45: 0.43136334 | F45: 13.118638 | G45: 0.60483531 | H45: 21.968577 | I45: 0.64127276 | J45: 26.830016 | K45: 0.71623682 | L45: 21.848178 | M45: 0.66938555 | N45: 9.5393408 | O45: 0.58468091 | P45: 1.7720916 | Q45: 0.2692228
A46: Norway | B46: 1.0578908 | C46: 0.20684418 | D46: 5.6853314 | E46: 0.41231338 | F46: 14.102113 | G46: 0.78783066 | H46: 25.045246 | I46: 0.88827994 | J46: 28.581247 | K46: 0.74114092 | L46: 18.73914 | M46: 0.71868706 | N46: 6.0541913 | O46: 0.4744911 | P46: 0.7348411 | Q46: 0.13327345
A47: Poland | B47: 0.20872831 | C47: 0.11378204 | D47: 2.5042396 | E47: 0.34084486 | F47: 11.129304 | G47: 0.66738146 | H47: 24.915375 | I47: 0.84203736 | J47: 29.987283 | K47: 0.96518934 | L47: 21.975275 | M47: 0.807809 | N47: 8.1126074 | O47: 0.7130733 | P47: 1.1671868 | Q47: 0.24564788
A48: Portugal* | B48: 0.44833179 | C48: 0.13343487 | D48: 4.3698281 | E48: 0.61546454 | F48: 14.742638 | G48: 0.86898926 | H48: 26.242321 | I48: 0.93861656 | J48: 29.3876 | K48: 1.0067522 | L48: 19.184718 | M48: 0.861563 | N48: 5.142382 | O48: 0.52771417 | P48: 0.48218076 | Q48: 0.15284448
A49: Slovak Republic | B49: 1.4385954 | C49: 0.24612442 | D49: 7.9181404 | E49: 0.59418226 | F49: 19.944983 | G49: 0.74357616 | H49: 28.529841 | I49: 0.87626479 | J49: 25.262262 | K49: 0.76008389 | L49: 13.199096 | M49: 0.62814565 | N49: 3.3847799 | O49: 0.32705562 | P49: 0.32230289 | Q49: 0.11389306
A50: Slovenia | B50: 0.19613435 | C50: 0.095092461 | D50: 2.4722068 | E50: 0.29118176 | F50: 11.887167 | G50: 0.58029351 | H50: 24.594323 | I50: 0.78790276 | J50: 31.752645 | K50: 1.0046889 | L50: 21.758712 | M50: 0.87193476 | N50: 6.718449 | O50: 0.54902037 | P50: 0.62036312 | Q50: 0.17119085
A51: Spain** | B51: 0.55124755 | C51: 0.10092015 | D51: 4.5258787 | E51: 0.28250056 | F51: 16.197617 | G51: 0.54355108 | H51: 28.369466 | I51: 0.50172361 | J51: 29.401595 | K51: 0.50643333 | L51: 16.769963 | M51: 0.43707101 | N51: 3.8711552 | O51: 0.23888004 | P51: 0.31307852 | Q51: 0.068677789
A52: Sweden | B52: 0.62255343 | C52: 0.1590285 | D52: 4.5614879 | E52: 0.51905818 | F52: 13.823398 | G52: 0.74433927 | H52: 23.990791 | I52: 0.69188048 | J52: 27.950422 | K52: 0.84962809 | L52: 20.749086 | M52: 0.92716462 | N52: 7.3482291 | O52: 0.52274335 | P52: 0.95403207 | Q52: 0.18181223
A53: Switzerland | B53: 0.42267846 | C53: 0.13556214 | D53: 4.5838712 | E53: 0.48403317 | F53: 15.218466 | G53: 0.75248792 | H53: 24.923102 | I53: 0.86580722 | J53: 27.772965 | K53: 0.94171737 | L53: 19.273593 | M53: 1.0236558 | N53: 6.945514 | O53: 0.68807162 | P53: 0.85981048 | Q53: 0.16956651
A54: Turkey | B54: 0.33445934 | C54: 0.12100807 | D54: 4.694609 | E54: 0.44990197 | F54: 20.123016 | G54: 0.81411453 | H54: 32.772961 | I54: 0.9509112 | J54: 27.284809 | K54: 1.0150518 | L54: 12.329328 | M54: 0.66990713 | N54: 2.3378395 | O54: 0.438742 | P54: 0.12297808 | Q54: 0.07456824
A55: United Kingdom | B55: 0.6424793 | C55: 0.1524645 | D55: 3.8743231 | E55: 0.40578943 | F55: 12.918325 | G55: 0.64991392 | H55: 24.000195 | I55: 0.823793 | J55: 28.10075 | K55: 0.75864793 | L55: 20.784624 | M55: 0.74180031 | N55: 8.2271735 | O55: 0.55078632 | P55: 1.4521307 | Q55: 0.22273154
... A58: OECD total | B58: 0.68030637 | C58: 0.062879768 | D58: 5.5832245 | E58: 0.20895652 | F58: 17.151462 | G58: 0.29498612 | H58: 25.858296 | I58: 0.28874625 | J58: 26.045436 | K58: 0.32228472 | L58: 17.641582 | M58: 0.32324998 | N58: 6.1228454 | O58: 0.23016024 | P58: 0.91684864 | Q58: 0.068622646
...

Sheet Table I.B1.4
A1: PISA 2018 Results (Volume I) - © OECD 2019
A2: Annex B1 | B2: Annex B1 Results for countries and economies
A3: Version 3+1 - Last updated: 24-Jul-2020
A4: Disclaimer: http://oe.cd/disclaimer
A6: Annex B1 | B6: Annex B1 Results for countries and economies
A7: Version 3 - Last updated: 02-Dec-2019
A8: Disclaimer: http://oe.cd/disclaimer
A10: Table I.B1.4
A11: Mean score and variation in reading performance
B16: Mean score | D16: Standard deviation | F16: Percentiles
F17: 5th | H17: 10th | J17: 25th | L17: Median (50th) | N17: 75th | P17: 90th | R17: 95th
B18: Mean | C18: S.E. | D18: S.D. | E18: S.E. | F18: Score | G18: S.E. | H18: Score | I18: S.E. | J18: Score | K18: S.E. | L18: Score | M18: S.E. | N18: Score | O18: S.E. | P18: Score | Q18: S.E. | R18: Score | S18: S.E.
A19: OECD
A20: Australia | B20: 502.63172 | C20: 1.6343431 | D20: 108.65994 | E20: 0.89933053 | F20: 314.7591 | G20: 2.7327738 | H20: 356.6448 | I20: 2.7927941 | J20: 428.752 | K20: 2.1891699 | L20: 507.3367 | M20: 1.9474427 | N20: 580.0111 | O20: 1.9851908 | P20: 640.4898 | Q20: 2.1923577 | R20: 673.3754 | S20: 2.5517945
A21: Austria | B21: 484.39257 | C21: 2.6974721 | D21: 99.384331 | E21: 1.2177783 | F21: 317.9643 | G21: 3.9234701 | H21: 349.8399 | I21: 3.727402 | J21: 412.7271 | K21: 4.1275547 | L21: 488.1626 | M21: 3.8020673 | N21: 557.7239 | O21: 2.863928 | P21: 612.042 | Q21: 2.8922268 | R21: 640.9809 | S21: 2.9029435
A22: Belgium | B22: 492.86444 | C22: 2.3219733 | D22: 102.57505 | E22: 1.2795801 | F22: 317.2521 | G22: 4.0478171 | H22: 352.306 | I22: 3.8291169 | J22: 421.3862 | K22: 3.1963812 | L22: 497.6026 | M22: 2.6520396 | N22: 567.8217 | O22: 2.5541814 | P22: 623.4654 | Q22: 2.5945296 | R22: 653.065 | S22: 2.7871659
A23: Canada | B23: 520.08552 | C23: 1.7997162 | D23: 100.29705 | E23: 0.80684781 | F23: 349.2105 | G23: 2.815526 | H23: 387.5861 | I23: 2.416736 | J23: 452.4397 | K23: 2.2901815 | L23: 524.075 | M23: 2.1505581 | N23: 591.9612 | O23: 2.046846 | P23: 646.3823 | Q23: 2.3411677 | R23: 676.6561 | S23: 2.8169657
A24: Chile | B24: 452.27255 | C24: 2.6437662 | D24: 92.017742 | E24: 1.2071098 | F24: 298.4127 | G24: 3.7049178 | H24: 331.2514 | I24: 3.5816057 | J24: 388.6755 | K24: 3.1484821 | L24: 453.0922 | M24: 3.1966228 | N24: 517.2497 | O24: 3.3701314 | P24: 571.8504 | Q24: 3.3415645 | R24: 602.3834 | S24: 3.5459143
A25: Colombia | B25: 412.29509 | C25: 3.2513437 | D25: 88.66606 | E25: 1.5429224 | F25: 271.511 | G25: 4.0539176 | H25: 300.0133 | I25: 3.7256734 | J25: 349.8847 | K25: 3.54028 | L25: 407.6717 | M25: 3.8443663 | N25: 472.266 | O25: 4.1325786 | P25: 531.5032 | Q25: 4.688066 | R25: 565.8329 | S25: 4.8873291
A26: Czech Republic | B26: 490.21882 | C26: 2.5478509 | D26: 97.32986 | E26: 1.6211317 | F26: 328.1978 | G26: 5.2161094 | H26: 362.2878 | I26: 4.2699948 | J26: 422.064 | K26: 3.6580015 | L26: 491.6102 | M26: 3.0305394 | N26: 559.8998 | O26: 2.9175794 | P26: 616.4033 | Q26: 2.7782866 | R26: 647.0212 | S26: 3.0754396
A27: Denmark | B27: 501.12993 | C27: 1.7954575 | D27: 92.094606 | E27: 1.1557517 | F27: 343.9313 | G27: 4.0145596 | H27: 380.3746 | I27: 2.9974004 | J27: 438.5616 | K27: 2.6627042 | L27: 504.4086 | M27: 2.1948461 | N27: 566.115 | O27: 2.1174904 | P27: 618.1513 | Q27: 2.6388374 | R27: 646.9444 | S27: 3.2578171
A28: Estonia | B28: 523.01702 | C28: 1.8422422 | D28: 93.210811 | E28: 1.182771 | F28: 366.8048 | G28: 3.7864988 | H28: 401.8092 | I28: 3.4647827 | J28: 460.109 | K28: 2.6153158 | L28: 523.7264 | M28: 2.2786804 | N28: 587.2644 | O28: 2.2601535 | P28: 643.3116 | Q28: 3.1029105 | R28: 675.8149 | S28: 3.6908459
A29: Finland | B29: 520.07875 | C29: 2.307102 | D29: 99.552789 | E29: 1.2678883 | F29: 344.7441 | G29: 4.6607823 | H29: 386.7083 | I29: 4.2264551 | J29: 455.0898 | K29: 3.183237 | L29: 526.8987 | M29: 2.7612075 | N29: 591.1847 | O29: 2.5035212 | P29: 642.9918 | Q29: 3.0398801 | R29: 672.1733 | S29: 3.3258139
A30: France | B30: 492.60648 | C30: 2.3209786 | D30: 101.17499 | E30: 1.4659374 | F30: 319.3339 | G30: 4.2651722 | H30: 355.4004 | I30: 3.5362904 | J30: 422.8905 | K30: 3.020323 | L30: 496.9364 | M30: 3.0352783 | N30: 566.6214 | O30: 3.3283965 | P30: 621.8852 | Q30: 3.5843947 | R30: 650.5383 | S30: 3.9525848
A31: Germany | B31: 498.27926 | C31: 3.0254079 | D31: 105.74827 | E31: 1.5123986 | F31: 316.4907 | G31: 4.9806291 | H31: 353.9461 | I31: 4.5279182 | J31: 424.2065 | K31: 4.4147408 | L31: 503.8069 | M31: 4.1164522 | N31: 575.8749 | O31: 3.4566539 | P31: 632.2541 | Q31: 3.4502988 | R31: 662.5311 | S31: 3.6487067
... A50: Slovenia | B50: 495.34562 | C50: 1.2322992 | D50: 93.604491 | E50: 1.2138944 | F50: 335.3338 | G50: 3.9129279 | H50: 371.9137 | I50: 3.0480774 | J50: 431.373 | K50: 2.2473934 | L50: 498.8514 | M50: 1.9080498 | N50: 561.1432 | O50: 2.0633284 | P50: 613.5595 | Q50: 2.7765912 | R50: 644.4444 | S50: 3.398304
A51: Spain | B51: m | C51: m | D51: m | E51: m | F51: m | G51: m | H51: m | I51: m | J51: m | K51: m | L51: m | M51: m | N51: m | O51: m | P51: m | Q51: m | R51: m | S51: m
A52: Sweden | B52: 505.78522 | C52: 3.0247715 | D52: 107.53457 | E52: 1.4501586 | F52: 316.8167 | G52: 5.4523556 | H52: 360.0405 | I52: 5.7053793 | J52: 434.1655 | K52: 4.1301348 | L52: 511.5237 | M52: 3.398396 | N52: 583.4868 | O52: 3.2053913 | P52: 640.4641 | Q52: 3.4676902 | R52: 671.5611 | S52: 3.6715051
A53: Switzerland | B53: 483.92941 | C53: 3.1243224 | D53: 102.71246 | E53: 1.5136945 | F53: 307.5919 | G53: 5.0745449 | H53: 344.7044 | I53: 4.609661 | J53: 412.7578 | K53: 4.030999 | L53: 488.0777 | M53: 3.6309025 | N53: 557.74475 | O53: 3.786378 | P53: 615.1979 | Q53: 4.0388689 | R53: 647.0122 | S53: 4.3598306
A54: Turkey | B54: 465.63167 | C54: 2.1712145 | D54: 87.662532 | E54: 1.6494216 | F54: 321.0462 | G54: 4.6126357 | H54: 350.9296 | I54: 4.1449673 | J54: 404.3672 | K54: 2.9524136 | L54: 465.859 | M54: 2.5707495 | N54: 526.7196 | O54: 2.4134217 | P54: 581.0066 | Q54: 3.0643968 | R54: 610.0065 | S54: 4.5914934
A55: United Kingdom | B55: 503.92811 | C55: 2.5825912 | D55: 100.2099 | E55: 1.2728022 | F55: 334.4766 | G55: 4.4306397 | H55: 371.9345 | I55: 4.2717138 | J55: 435.3553 | K55: 3.2366734 | L55: 506.2974 | M55: 2.7144214 | N55: 574.8277 | O55: 3.0597299 | P55: 632.3994 | Q55: 3.4896972 | R55: 664.1193 | S55: 3.776042
A56: United States* | B56: 505.35277 | C56: 3.5686732 | D56: 107.89452 | E56: 1.572413 | F56: 321.3249 | G56: 5.7162762 | H56: 360.5795 | I56: 5.2950842 | J56: 429.81 | K56: 4.4069105 | L56: 509.7399 | M56: 4.0995931 | N56: 583.5722 | O56: 4.3054239 | P56: 642.5907 | Q56: 3.8592105 | R56: 675.6511 | S56: 4.5525583
A57: OECD average | B57: 487.12599 | C57: 0.41476905 | D57: 99.388301 | E57: 0.2316461 | F57: 317.75192 | G57: 0.74217722 | H57: 354.34721 | I57: 0.67178423 | J57: 418.66434 | K57: 0.56505699 | L57: 490.38789 | M57: 0.50887019 | N57: 558.27588 | O57: 0.49795437 | P57: 614.18766 | Q57: 0.5472187 | R57: 644.87857 | S57: 0.63179155
A58: OECD total | B58: 484.96188 | C58: 1.1997835 | D58: 104.6376 | E58: 0.56275447 | F58: 311.1993 | G58: 1.6407953 | H58: 346.7138 | I58: 1.5642552 | J58: 410.84085 | K58: 1.3612126 | L58: 485.8877 | M58: 1.3972127 | N58: 560.1983 | O58: 1.3591495 | P58: 620.8939 | Q58: 1.5876842 | R58: 654.22345 | S58: 1.7592502
A59: Partners
A60: Albania | B60: 405.42937 | C60: 1.9222908 | D60: 80.275347 | E60: 1.1705511 | F60: 276.8924 | G60: 2.9306068 | H60: 303.3187 | I60: 2.9016673 | J60: 349.1654 | K60: 2.1824669 | L60: 403.1043 | M60: 2.119177 | N60: 459.2703 | O60: 2.7510194 | P60: 510.3547 | Q60: 3.2931808 | R60: 542.26805 | S60: 4.1462121
A61: Argentina | B61: 401.50311 | C61: 2.9770427 | D61: 97.79452 | E61: 1.4616039 | F61: 239.7714 | G61: 4.4561977 | H61: 274.0897 | I61: 4.1922355 | J61: 333.4561 | K61: 3.4422352 | L61: 402.06915 | M61: 3.5725842 | N61: 470.8539 | O61: 3.6461792 | P61: 529.3057 | Q61: 3.4140048 | R61: 560.9736 | S61: 3.8823631
A62: Baku (Azerbaijan) | B62: 389.38833 | C62: 2.5058139 | D62: 74.052853 | E62: 1.7207894 | F62: 269.8906 | G62: 2.6236127 | H62: 294.499 | I62: 2.5018682 | J62: 338.4161 | K62: 2.4405431 | L62: 388.5405 | M62: 2.4010279 | N62: 437.7557 | O62: 2.9695174 | P62: 484.6994 | Q62: 4.5796305 | R62: 513.7821 | S62: 6.2617707
A63: Belarus | B63: 473.78845 | C63: 2.4350607 | D63: 89.405179 | E63: 1.2580814 | F63: 322.40055 | G63: 4.482276 | H63: 355.2106 | I63: 3.393894 | J63: 412.0225 | K63: 3.0996525 | L63: 475.4296 | M63: 2.9846183 | N63: 537.9347 | O63: 3.0136187 | P63: 588.7624 | Q63: 3.0705814 | R63: 617.103 | S63: 4.0044385
A64: Bosnia and Herzegovina | B64: 402.97782 | C64: 2.9250634 | D64: 79.32583 | E64: 1.2198052 | F64: 278.4494 | G64: 3.1230998 | H64: 302.8978 | I64: 2.7952961 | J64: 345.6262 | K64: 3.0404954 | L64: 399.5252 | M64: 3.5119984 | N64: 457.9971 | O64: 3.6643492 | P64: 508.7224 | Q64: 4.0625196 | R64: 537.1183 | S64: 3.9920818
...

Sheet Table I.B1.5
A1: PISA 2018 Results (Volume I) - © OECD 2019
A2: Annex B1 | B2: Annex B1 Results for countries and economies
A3: Version 3+1 - Last updated: 24-Jul-2020
A4: Disclaimer: http://oe.cd/disclaimer
A6: Annex B1 | B6: Annex B1 Results for countries and economies
A7: Version 3 - Last updated: 02-Dec-2019
A8: Disclaimer: http://oe.cd/disclaimer
A10: Table I.B1.5
A11: Mean score and variation in mathematics performance
B16: Mean score | D16: Standard deviation | F16: Percentiles
F17: 5th | H17: 10th | J17: 25th | L17: Median (50th) | N17: 75th | P17: 90th | R17: 95th
B18: Mean | C18: S.E. | D18: S.D. | E18: S.E. | F18: Score | G18: S.E. | H18: Score | I18: S.E. | J18: Score | K18: S.E. | L18: Score | M18: S.E. | N18: Score | O18: S.E. | P18: Score | Q18: S.E. | R18: Score | S18: S.E.
A19: OECD
A20: Australia | B20: 491.36003 | C20: 1.939833 | D20: 92.197271 | E20: 1.1735769 | F20: 338.9586 | G20: 3.811551 | H20: 371.4833 | I20: 2.9915913 | J20: 428.0615 | K20: 2.2095781 | L20: 492.4077 | M20: 2.0566171 | N20: 554.9627 | O20: 2.0267534 | P20: 609.2507 | Q20: 2.7035422 | R20: 640.9206 | S20: 3.5805498
A21: Austria | B21: 498.94231 | C21: 2.9709987 | D21: 93.497362 | E21: 1.4774924 | F21: 341.0703 | G21: 4.3752735 | H21: 373.6246 | I21: 4.3651203 | J21: 433.4107 | K21: 4.0242729 | L21: 503.2416 | M21: 3.6641301 | N21: 566.4084 | O21: 3.5104693 | P21: 617.6456 | Q21: 3.2807667 | R21: 646.4358 | S21: 3.6218072
A22: Belgium | B22: 508.07031 | C22: 2.262662 | D22: 95.36659 | E22: 1.6997146 | F22: 344.0781 | G22: 4.3160357 | H22: 376.5234 | I22: 4.0540004 | J22: 439.8344 | K22: 3.2198572 | L22: 514.2278 | M22: 2.5424998 | N22: 578.9802 | O22: 2.5701439 | P22: 628.353 | Q22: 3.4061093 | R22: 655.5793 | S22: 3.7389589
A23: Canada | B23: 512.01694 | C23: 2.3574757 | D23: 92.293431 | E23: 1.1120308 | F23: 357.8541 | G23: 3.1691271 | H23: 391.7904 | I23: 3.0378842 | J23: 449.4232 | K23: 2.8299652 | L23: 513.4756 | M23: 2.6194103 | N23: 575.9716 | O23: 2.6729041 | P23: 629.1471 | Q23: 2.6661519 | R23: 660.5418 | S23: 3.19419
A24: Chile | B24: 417.40656 | C24: 2.4158876 | D24: 84.62262 | E24: 1.4434928 | F24: 282.2449 | G24: 3.8826512 | H24: 310.7085 | I24: 3.5021034 | J24: 358.5657 | K24: 2.8953897 | L24: 415.8844 | M24: 2.8965919 | N24: 475.3166 | O24: 3.1790399 | P24: 528.2705 | Q24: 3.5382261 | R24: 558.5981 | S24: 4.0852603
A25: Colombia | B25: 390.93227 | C25: 2.9895591 | D25: 81.200399 | E25: 2.0241018 | F25: 262.3642 | G25: 5.351477 | H25: 290.0758 | I25: 3.8632261 | J25: 334.7394 | K25: 3.5254796 | L25: 387.4174 | M25: 3.5277094 | N25: 444.5176 | O25: 3.803469 | P25: 498.8089 | Q25: 4.4892759 | R25: 531.1092 | S25: 4.4496337
A26: Czech Republic | B26: 499.46765 | C26: 2.4606615 | D26: 93.165784 | E26: 1.6841752 | F26: 345.0422 | G26: 5.2104962 | H26: 377.5823 | I26: 4.5817812 | J26: 434.9874 | K26: 3.6049617 | L26: 501.0163 | M26: 2.7266399 | N26: 564.2881 | O26: 2.7706168 | P26: 619.007 | Q26: 3.138049 | R26: 650.3869 | S26: 3.894917
A27: Denmark | B27: 509.39837 | C27: 1.7350024 | D27: 82.444394 | E27: 1.0278377 | F27: 369.5553 | G27: 3.5790992 | H27: 400.774 | I27: 2.5894473 | J27: 453.6947 | K27: 2.2845493 | L27: 511.5051 | M27: 2.2915628 | N27: 567.446 | O27: 2.335859 | P27: 613.4288 | Q27: 2.7803507 | R27: 639.7761 | S27: 3.5293103
A28: Estonia | B28: 523.41458 | C28: 1.7436022 | D28: 81.636104 | E28: 1.1409034 | F28: 389.7926 | G28: 3.121176 | H28: 418.995 | I28: 2.882468 | J28: 468.0558 | K28: 2.4406836 | L28: 523.8797 | M28: 2.040712 | N28: 579.2761 | O28: 2.1669044 | P28: 627.6308 | Q28: 2.6782438 | R28: 656.6703 | S28: 3.6476818
A29: Finland | B29: 507.30136 | C29: 1.9679204 | D29: 82.412711 | E29: 1.2313582 | F29: 367.5716 | G29: 3.6321808 | H29: 398.9986 | I29: 3.4221421 | J29: 451.3343 | K29: 2.5463309 | L29: 510.4301 | M29: 2.4649486 | N29: 564.7403 | O29: 2.3609198 | P29: 611.8091 | Q29: 2.5076517 | R29: 638.6786 | S29: 3.3206926
A30: France | B30: 495.40758 | C30: 2.3202141 | D30: 92.567823 | E30: 1.5245068 | F30: 333.3131 | G30: 4.2841761 | H30: 370.1186 | I30: 3.4255786 | J30: 432.9333 | K30: 3.1957863 | L30: 501.7183 | M30: 3.0458647 | N30: 562.207 | O30: 3.2244879 | P30: 611.1397 | Q30: 3.2531018 | R30: 637.8275 | S30: 3.5532336
A31: Germany | B31: 500.04378 | C31: 2.6470829 | D31: 95.390362 | E31: 1.4508597 | F31: 337.4825 | G31: 4.6497821 | H31: 372.857 | I31: 4.1548777 | J31: 433.0465 | K31: 3.6341765 | L31: 504.0459 | M31: 3.5128214 | N31: 569.7079 | O31: 3.337308 | P31: 620.7117 | Q31: 3.2163371 | R31: 650.1695 | S31: 3.4496706
... A58: OECD total | B58: 477.61224 | C58: 1.0224777 | D58: 97.395876 | E58: 0.51211755 | F58: 317.73625 | G58: 1.7363044 | H58: 350.1577 | I58: 1.4779278 | J58: 408.7514 | K58: 1.3445713 | L58: 478.1079 | M58: 1.2172055 | N58: 547.1212 | O58: 1.2031996 | P58: 604.1945 | Q58: 1.3359243 | R58: 636.03275 | S58: 1.4935771
A59: Partners
A60: Albania | B60: 437.22199 | C60: 2.4209769 | D60: 83.111344 | E60: 1.2831418 | F60: 303.0776 | G60: 3.6280706 | H60: 332.4518 | I60: 3.0686379 | J60: 380.6041 | K60: 2.8745372 | L60: 436.1977 | M60: 3.0433118 | N60: 492.9771 | O60: 2.7536539 | P60: 543.6083 | Q60: 3.4795158 | R60: 575.2662 | S60: 3.7637896
A61: Argentina | B61: 379.45382 | C61: 2.7711142 | D61: 84.044622 | E61: 1.6955698 | F61: 243.3273 | G61: 4.5945173 | H61: 272.1274 | I61: 4.1017427 | J61: 321.547 | K61: 3.60335 | L61: 378.2738 | M61: 3.1090149 | N61: 436.2306 | O61: 3.4743527 | P61: 489.007 | Q61: 3.8219067 | R61: 520.488 | S61: 3.9903804
A62: Baku (Azerbaijan) | B62: 419.64311 | C62: 2.822266 | D62: 89.305934 | E62: 1.6714081 | F62: 276.2265 | G62: 3.7719577 | H62: 305.955 | I62: 3.3744208 | J62: 358.7279 | K62: 2.8550412 | L62: 418.3972 | M62: 3.0855888 | N62: 479.634 | O62: 3.7709772 | P62: 535.3821 | Q62: 4.9793194 | R62: 569.7866 | S62: 5.3894513
A63: Belarus | B63: 471.86514 | C63: 2.6740709 | D63: 92.957928 | E63: 1.4249254 | F63: 317.727 | G63: 5.0128885 | H63: 350.8859 | I63: 3.3828478 | J63: 407.3401 | K63: 3.0554956 | L63: 472.8089 | M63: 3.0110569 | N63: 537.1948 | O63: 3.2090408 | P63: 592.0274 | Q63: 3.450564 | R63: 623.2441 | S63: 4.079402
A64: Bosnia and Herzegovina | B64: 406.38441 | C64: 3.0558675 | D64: 81.969125 | E64: 1.3172614 | F64: 276.2936 | G64: 4.07906 | H64: 303.2999 | I64: 3.1743265 | J64: 348.9222 | K64: 3.1974867 | L64: 403.8649 | M64: 3.5039721 | N64: 462.1333 | O64: 3.6846297 | P64: 514.2019 | Q64: 4.4329139 | R64: 545.4455 | S64: 4.2648183
A65: Brazil | B65: 383.56912 | C65: 2.0323689 | D65: 87.535636 | E65: 1.5607627 | F65: 250.8056 | G65: 3.0579363 | H65: 276.5052 | I65: 2.5233435 | J65: 321.76 | K65: 2.3448881 | L65: 376.8624 | M65: 2.3550952 | N65: 439.981 | O65: 2.8237512 | P65: 500.6473 | Q65: 3.9064773 | R65: 538.2465 | S65: 4.9013472
A66: Brunei Darussalam | B66: 430.11296 | C66: 1.1589696 | D66: 91.387258 | E66: 1.0012813 | F66: 286.7062 | G66: 3.398065 | H66: 315.8377 | I66: 2.4437015 | J66: 365.4718 | K66: 2.0420446 | L66: 425.139 | M66: 1.5617057 | N66: 492.1842 | O66: 1.9756036 | P66: 555.1167 | Q66: 2.1587931 | R66: 587.8506 | S66: 3.391799
A67: B-S-J-Z (China) | B67: 591.3936 | C67: 2.5171672 | D67: 80.325357 | E67: 1.7997872 | F67: 451.8667 | G67: 5.2487207 | H67: 486.124 | I67: 4.2019876 | J67: 540.2099 | K67: 2.9837384 | L67: 595.9496 | M67: 2.6825095 | N67: 647.2004 | O67: 2.9623951 | P67: 690.7297 | Q67: 3.2113389 | R67: 715.6577 | S67: 3.5799364
A68: Bulgaria | B68: 436.04057 | C68: 3.8172445 | D68: 97.42871 | E68: 2.0877644 | F68: 280.1791 | G68: 6.1218985 | H68: 311.4493 | I68: 4.6360454 | J68: 367.5541 | K68: 4.6246313 | L68: 434.3799 | M68: 4.1813406 | N68: 502.6937 | O68: 4.130092 | P68: 562.8534 | Q68: 5.7163522 | R68: 599.0874 | S68: 6.8497303
A69: Costa Rica | B69: 402.33056 | C69: 3.2887994 | D69: 74.72099 | E69: 1.9620527 | F69: 281.7113 | G69: 4.1593473 | H69: 308.2839 | I69: 3.367786 | J69: 351.5568 | K69: 2.6522532 | L69: 400.8429 | M69: 3.2532475 | N69: 452.3085 | O69: 4.2170091 | P69: 498.8412 | Q69: 5.4820608 | R69: 528.024 | S69: 7.0038991
A70: Croatia | B70: 464.20427 | C70: 2.5485653 | D70: 86.535171 | E70: 1.6504247 | F70: 323.1404 | G70: 4.6194844 | H70: 353.5065 | I70: 3.9353932 | J70: 404.6481 | K70: 3.0474675 | L70: 463.106 | M70: 2.9330693 | N70: 523.0936 | O70: 3.1352743 | P70: 576.8805 | Q70: 3.8590585 | R70: 607.8796 | S70: 4.2199077
A71: Cyprus | B71: 450.68299 | C71: 1.4102091 | D71: 94.703746 | E71: 1.0960119 | F71: 292.1485 | G71: 3.5122548 | H71: 325.3082 | I71: 2.846945 | J71: 385.106 | K71: 2.4747495 | L71: 454.1925 | M71: 1.9499334 | N71: 517.25 | O71: 2.1430403 | P71: 571.2574 | Q71: 2.4434851 | R71: 601.2692 | S71: 3.4219854
... A102: Viet Nam*** | B102: 495.67543 | C102: 3.9967359 | D102: 74.795891 | E102: 1.9804308 | F102: 373.4084 | G102: 5.0438223 | H102: 400.1348 | I102: 5.0324808 | J102: 444.83 | K102: 4.3969728 | L102: 495.6885 | M102: 4.1454686 | N102: 546.1187 | O102: 4.5105783 | P102: 591.0327 | Q102: 5.118093 | R102: 619.2721 | S102: 5.778232
...

Sheet Table I.B1.6
A1: PISA 2018 Results (Volume I) - © OECD 2019
A2: Annex B1 | B2: Annex B1 Results for countries and economies
A3: Version 3+1 - Last updated: 24-Jul-2020
A4: Disclaimer: http://oe.cd/disclaimer
A6: Annex B1 | B6: Annex B1 Results for countries and economies
A7: Version 3 - Last updated: 02-Dec-2019
A8: Disclaimer: http://oe.cd/disclaimer
A10: Table I.B1.6
A11: Mean score and variation in science performance
B16: Mean score | D16: Standard deviation | F16: Percentiles
F17: 5th | H17: 10th | J17: 25th | L17: Median (50th) | N17: 75th | P17: 90th | R17: 95th
B18: Mean | C18: S.E. | D18: S.D. | E18: S.E. | F18: Score | G18: S.E. | H18: Score | I18: S.E. | J18: Score | K18: S.E. | L18: Score | M18: S.E. | N18: Score | O18: S.E. | P18: Score | Q18: S.E. | R18: Score | S18: S.E.
A19: OECD
A20: Australia | B20: 502.96456 | C20: 1.7953983 | D20: 100.6808 | E20: 1.0682424 | F20: 333.9954 | G20: 2.714006 | H20: 368.6599 | I20: 2.5990501 | J20: 432.4099 | K20: 2.19254 | L20: 506.2878 | M20: 2.2779165 | N20: 575.1824 | O20: 2.1750232 | P20: 630.6432 | Q20: 2.7340477 | R20: 663.5264 | S20: 3.7882651
A21: Austria | B21: 489.78044 | C21: 2.7773948 | D21: 95.588909 | E21: 1.2457433 | F21: 332.2313 | G21: 3.7882721 | H21: 361.2022 | I21: 3.1068134 | J21: 419.8993 | K21: 3.5598796 | L21: 492.6303 | M21: 3.5352434 | N21: 560.1892 | O21: 3.1174268 | P21: 613.5825 | Q21: 3.3207014 | R21: 642.1057 | S21: 3.6855766
A22: Belgium | B22: 498.77313 | C22: 2.2292398 | D22: 98.809722 | E22: 1.3344468 | F22: 328.2019 | G22: 4.1679504 | H22: 362.5334 | I22: 4.0237117 | J22: 428.3953 | K22: 3.3719955 | L22: 505.4762 | M22: 2.627983 | N22: 571.1352 | O22: 2.506177 | P22: 623.5968 | Q22: 2.3374132 | R22: 652.0906 | S22: 2.7729967
A23: Canada | B23: 517.99766 | C23: 2.1536512 | D23: 95.721036 | E23: 0.9634875 | F23: 357.1811 | G23: 2.5971751 | H23: 392.59 | I23: 2.3194149 | J23: 452.5943 | K23: 2.5183811 | L23: 520.3644 | M23: 2.6009758 | N23: 585.848 | O23: 2.5605927 | P23: 639.5609 | Q23: 2.5432058 | R23: 670.7862 | S23: 3.5744648
A24: Chile | B24: 443.58256 | C24: 2.4152801 | D24: 83.484076 | E24: 1.4087033 | F24: 308.8908 | G24: 3.5855099 | H24: 335.7529 | I24: 3.1304387 | J24: 384.5063 | K24: 2.9563965 | L24: 442.1338 | M24: 2.8721478 | N24: 501.6387 | O24: 3.3249934 | P24: 553.3757 | Q24: 3.3284867 | R24: 583.5255 | S24: 3.828156
A25: Colombia | B25: 413.32299 | C25: 3.0524015 | D25: 81.98976 | E25: 1.3983532 | F25: 286.5535 | G25: 3.8027166 | H25: 310.7065 | I25: 3.6877824 | J25: 354.5678 | K25: 3.6003552 | L25: 408.7806 | M25: 3.5591019 | N25: 468.9652 | O25: 3.984898 | P25: 523.9515 | Q25: 4.1282481 | R25: 555.4976 | S25: 4.1777044
A26: Czech Republic | B26: 496.79131 | C26: 2.5460694 | D26: 94.491506 | E26: 1.6461141 | F26: 340.8044 | G26: 4.8175249 | H26: 372.8419 | I26: 4.0373212 | J26: 430.2258 | K26: 3.7172794 | L26: 497.2566 | M26: 3.0603412 | N26: 563.9268 | O26: 3.1265454 | P26: 619.7912 | Q26: 2.9337701 | R26: 651.1667 | S26: 3.5773426
A27: Denmark | B27: 492.63703 | C27: 1.9376037 | D27: 91.460953 | E27: 1.2658268 | F27: 336.9679 | G27: 3.8035245 | H27: 371.9204 | I27: 3.4112917 | J27: 430.9579 | K27: 2.5600737 | L27: 495.5902 | M27: 2.5154454 | N27: 557.8824 | O27: 2.5885683 | P27: 608.6014 | Q27: 3.1368609 | R27: 636.9955 | S27: 3.6440294
A28: Estonia | B28: 530.108 | C28: 1.8845691 | D28: 87.849415 | E28: 1.1642196 | F28: 384.1542 | G28: 3.902504 | H28: 416.6326 | I28: 3.4820716 | J28: 469.4488 | K28: 2.8827827 | L28: 530.8352 | M28: 2.4499127 | N28: 590.7322 | O28: 2.3905056 | P28: 643.5582 | Q28: 2.7274807 | R28: 673.6104 | S28: 2.9618489
A29: Finland | B29: 521.88456 | C29: 2.5095152 | D29: 96.409638 | E29: 1.3122139 | F29: 355.6674 | G29: 4.3783471 | H29: 393.4122 | I29: 4.1157671 | J29: 457.5413 | K29: 3.2181915 | L29: 526.3528 | M29: 2.9193 | N29: 590.488 | O29: 2.7617545 | P29: 643.444 | Q29: 2.9439853 | R29: 672.7039 | S29: 3.8007363
A30: France | B30: 492.97708 | C30: 2.2236613 | D30: 96.004289 | E30: 1.4382879 | F30: 329.5076 | G30: 4.2351763 | H30: 364.0601 | I30: 3.5018795 | J30: 425.0323 | K30: 3.0552287 | L30: 497.0938 | M30: 3.0770031 | N30: 563.1235 | O30: 2.887883 | P30: 614.7786 | Q30: 3.1725652 | R30: 643.9383 | S30: 3.7966738
A31: Germany | B31: 502.9889 | C31: 2.9115006 | D31: 102.85678 | E31: 1.6022809 | F31: 328.0659 | G31: 5.203388 | H31: 363.4694 | I31: 4.0050217 | J31: 430.2418 | K31: 3.8781573 | L31: 508.482 | M31: 3.9482356 | N31: 577.2314 | O31: 3.5214893 | P31: 633.1365 | Q31: 3.2939975 | R31: 664.8541 | S31: 3.2857752
... A58: OECD total | B58: 486.40644 | C58: 1.0732231 | D58: 99.039122 | E58: 0.53794297 | F58: 325.4304 | G58: 1.4623075 | H58: 356.8863 | I58: 1.4801366 | J58: 414.648 | K58: 1.2672686 | L58: 486.07165 | M58: 1.2236986 | N58: 557.6612 | O58: 1.3286394 | P58: 616.10285 | Q58: 1.3975519 | R58: 648.4039 | S58: 1.6114426
A59: Partners
A60: Albania | B60: 416.72626 | C60: 1.9854047 | D60: 74.069122 | E60: 1.1250366 | F60: 297.7325 | G60: 3.185242 | H60: 323.0344 | I60: 3.0758859 | J60: 365.7923 | K60: 2.4462013 | L60: 415.5042 | M60: 2.5284786 | N60: 466.4568 | O60: 2.5937944 | P60: 513.5306 | Q60: 3.1827533 | R60: 540.9516 | S60: 3.6257214
A61: Argentina | B61: 404.07144 | C61: 2.870526 | D61: 89.589723 | E61: 1.5793729 | F61: 261.4257 | G61: 4.7199442 | H61: 291.0459 | I61: 3.9753936 | J61: 340.0319 | K61: 3.4192599 | L61: 401.1643 | M61: 3.3251255 | N61: 466.3725 | O61: 3.6596069 | P61: 523.0053 | Q61: 3.9648719 | R61: 554.989 | S61: 3.6520307
A62: Baku (Azerbaijan) | B62: 397.64958 | C62: 2.3565838 | D62: 73.691501 | E62: 1.6406094 | F62: 280.564 | G62: 2.9614307 | H62: 304.7386 | I62: 2.5365271 | J62: 346.6778 | K62: 2.3023449 | L62: 395.3979 | M62: 2.1962799 | N62: 445.71 | O62: 2.9967078 | P62: 493.6662 | Q62: 4.6137694 | R62: 523.6395 | S62: 6.1592883
A63: Belarus | B63: 471.26368 | C63: 2.4461952 | D63: 85.026144 | E63: 1.2906328 | F63: 331.1411 | G63: 3.7355655 | H63: 360.5506 | I63: 3.5069916 | J63: 411.8504 | K63: 3.4068472 | L63: 471.6963 | M63: 2.8952577 | N63: 531.2369 | O63: 2.6722082 | P63: 581.1933 | Q63: 2.7477448 | R63: 609.6225 | S63: 3.6837147
A64: Bosnia and Herzegovina | B64: 398.49766 | C64: 2.7372524 | D64: 76.596401 | E64: 1.279819 | F64: 277.6362 | G64: 3.636888 | H64: 302.0412 | I64: 3.0913997 | J64: 343.8374 | K64: 2.7042898 | L64: 395.8663 | M64: 3.2305826 | N64: 450.8633 | O64: 3.6079556 | P64: 499.4943 | Q64: 3.80335 | R64: 528.1912 | S64: 4.0548457
A65: Brazil | B65: 403.62094 | C65: 2.0577515 | D65: 90.311432 | E65: 1.4542098 | F65: 267.785 | G65: 2.9872328 | H65: 292.4679 | I65: 2.3371644 | J65: 337.6071 | K65: 2.1477082 | L65: 396.327 | M65: 2.3076977 | N65: 464.2448 | O65: 3.0995356 | P65: 526.6831 | Q65: 3.6133759 | R65: 562.7114 | S65: 4.8094738
A66: Brunei Darussalam | B66: 430.98438 | C66: 1.2100865 | D66: 95.8938 | E66: 1.0628532 | F66: 290.0612 | G66: 2.6252293 | H66: 314.7066 | I66: 2.0264425 | J66: 359.213 | K66: 1.917902 | L66: 420.715 | M66: 1.5260058 | N66: 496.9377 | O66: 1.7324176 | P66: 566.3629 | Q66: 2.7612423 | R66: 603.4964 | S66: 2.7751418
A67: B-S-J-Z (China) | B67: 590.45264 | C67: 2.6715704 | D67: 83.189546 | E67: 1.6703951 | F67: 447.8374 | G67: 5.0072532 | H67: 481.8106 | I67: 3.9892297 | J67: 536.4005 | K67: 3.4064625 | L67: 593.8092 | M67: 2.8468967 | N67: 648.7385 | O67: 3.0691257 | P67: 695.2492 | Q67: 3.7125746 | R67: 720.6374 | S67: 3.9058505
