Workbook

Sheet TOC
A1: PISA 2018 Results (Volume III) - © OECD 2019
A2: Annex B1 | B2: Annex B1.4 Results (tables): Student truancy and lateness
A3: Version 2 - Last updated: 02-Dec-2019
A4: Disclaimer: http://oe.cd/disclaimer
A6: TOC | B6: PISA 2018 Results - Volume III
A8: Chapter 4 | B8: Truancy and lateness
A9: Tables
A11: ='Table III.B1.4.1'!A6 -> Table III.B1.4.1 | B11: ='Table III.B1.4.1'!$A$7 -> Student truancy and lateness
A12: ='Table III.B1.4.2'!A6 -> Table III.B1.4.2 | B12: ='Table III.B1.4.2'!$A$7 -> Change between 2015 and 2018 in student truancy and lateness
A13: ='Table III.B1.4.3'!A6 -> Table III.B1.4.3 | B13: ='Table III.B1.4.3'!$A$7 -> Prevalence of student truancy in schools
A14: ='Table III.B1.4.4'!A6 -> Table III.B1.4.4 | B14: ='Table III.B1.4.4'!$A$7 -> Prevalence of student lateness in schools
A15: ='Table III.B1.4.5'!A6 -> Table III.B1.4.5 | B15: ='Table III.B1.4.5'!$A$7 -> Student truancy, by student characteristics
A16: ='Table III.B1.4.6'!A6 -> Table III.B1.4.6 | B16: ='Table III.B1.4.6'!$A$7 -> Student lateness, by student characteristics
A17: ='Table III.B1.4.7'!A6 -> Table III.B1.4.7 | B17: ='Table III.B1.4.7'!$A$7 -> Student truancy, by school characteristics
A18: ='Table III.B1.4.8'!A6 -> Table III.B1.4.8 | B18: ='Table III.B1.4.8'!$A$7 -> Student lateness, by school characteristics
A19: ='Table III.B1.4.9'!A6 -> Table III.B1.4.9 | B19: ='Table III.B1.4.9'!$A$7 -> Student truancy and lateness, and reading performance
A20: ='Table III.B1.4.10'!A6 -> Table III.B1.4.10 | B20: ='Table III.B1.4.10'!$A$7 -> School-level truancy and reading performance
A21: ='Table III.B1.4.11'!A6 -> Table III.B1.4.11 | B21: ='Table III.B1.4.11'!$A$7 -> School-level lateness and reading performance
A22: ='Table III.B1.4.12'!A6 -> Table III.B1.4.12 | B22: ='Table III.B1.4.12'!$A$7 -> Repeated student truancy and lateness, and reading performance
A23: ='Table III.B1.4.13'!A6 -> Table III.B1.4.13 | B23: ='Table III.B1.4.13'!$A$7 -> Predictors of student truancy
A26: Symbols for missing data
A27: c: There were too few observations to provide reliable estimates (i.e. there were fewer than 30 students or fewer than 5 schools with valid data).
A28: m: Data are not available. There are no observations in the sample; these data were not collected by the country; or these data were collected but subsequently removed from the publication for technical reasons.
A29: w: Results were withdrawn at the request of the country concerned.

Sheet INOFRMATION ON SCALED INDICES
A1: PISA 2018 Results (Volume III) - © OECD 2019
A2: Annex B1 | B2: Annex B1.4 Results (tables): Student truancy and lateness
A3: Version 2 - Last updated: 02-Dec-2019
A4: Disclaimer: http://oe.cd/disclaimer
A6: Information on scaled indices used in PISA 2015 Results (Volume III): What School Life Means for Students’ Lives
A11: Full name of the index | B11: Name in dataset | C11: Questionnaire | D11: Item 1 | E11: Item 2 | F11: Item 3 | G11: Item 4 | H11: Item 5 | I11: Item 6 | J11: Item 7
A12: Adaptive instruction | B12: adaptivity | C12: Student | D12: ST212Q01HA | E12: ST212Q02HA | F12: ST212Q03HA
A13: Attitudes towards competition | B13: compete | C13: Student | D13: ST181Q02HA | E13: ST181Q03HA | F13: ST181Q04HA
A14: Enjoyment of reading | B14: joyread | C14: Student | D14: ST160Q01IR | E14: ST160Q02IA | F14: ST160Q03IA | G14: ST160Q04IR | H14: ST160Q05IR
A15: Exposure to bullying | B15: beingbullied | C15: Student | D15: ST038Q03NA | E15: ST038Q04NA | F15: ST038Q05NA
A16: Fear of failure | B16: gfofail | C16: Student | D16: ST183Q01HA | E16: ST183Q02HA | F16: ST183Q03HA
A17: Disciplinary climate | B17: disclima | C17: Student | D17: ST097Q01TA | E17: ST097Q02TA | F17: ST097Q03TA | G17: ST097Q04TA | H17: ST097Q05TA
A18: Learning goals | B18: mastgoal | C18: Student | D18: ST208Q01HA | E18: ST208Q02HA | F18: ST208Q04HA
A19: Meaning in life | B19: eudmo | C19: Student | D19: ST185Q01HA | E19: ST185Q02HA | F19: ST185Q03HA
A20: Motivation to master tasks | B20: workmast | C20: Student | D20: ST182Q03HA | E20: ST182Q04HA | F20: ST182Q05HA
A21: Parents’ emotional support | B21: emosups | C21: Student | D21: ST123Q02NA | E21: ST123Q03NA | F21: ST123Q04NA
A22: Parents’ perceived school quality | B22: pqschool | C22: Parent | D22: PA007Q01TR | E22: PA007Q02TR | F22: PA007Q03TR | G22: PA007Q04TR | H22: PA007Q05TR | I22: PA007Q06TR | J22: PA007Q07TR
A23: Positive feelings | B23: swbp | C23: Student | D23: ST186Q01HA | E23: ST186Q03HA | F23: ST186Q05HA
A24: School policies for parental involvement | B24: paschpol | C24: Parent | D24: PA007Q09NR | E24: PA007Q11NR | F24: PA007Q12NR | G24: PA007Q13NR | H24: PA007Q14NR | I24: PA007Q15NR
A25: Self-efficacy | B25: resilience | C25: Student | D25: ST188Q01HA | E25: ST188Q02HA | F25: ST188Q03HA | G25: ST188Q06HA | H25: ST188Q07HA
A26: Sense of belonging | B26: belong | C26: Student | D26: ST034Q01TA | E26: ST034Q02TR | F26: ST034Q03TR | G26: ST034Q04TA | H26: ST034Q05TR | I26: ST034Q06TA
A27: Shortage of educational staff | B27: staffshort | C27: School | D27: SC017Q01NA | E27: SC017Q02NA | F27: SC017Q03NA | G27: SC017Q04NA
A28: Student competition | B28: percomp | C28: Student | D28: ST205Q01HA | E28: ST205Q02HA | F28: ST205Q03HA
A29: Student co-operation | B29: percoop | C29: Student | D29: ST206Q01HA | E29: ST206Q02HA | F29: ST206Q03HA
A30: Teacher behaviour hindering learning | B30: teachbeha | C30: School | D30: SC061Q06TA | E30: SC061Q07TA | F30: SC061Q08TA | G30: SC061Q09TA | H30: SC061Q10TA
A31: Teacher enthusiasm | B31: teachint | C31: Student | D31: ST213Q01HA | E31: ST213Q02HA | F31: ST213Q03HA | G31: ST213Q04HA
A32: Teacher feedback | B32: perfeed | C32: Student | D32: ST104Q02NA | E32: ST104Q03NA | F32: ST104Q04NA
A33: Teacher support | B33: teachsup | C33: Student | D33: ST100Q01TR | E33: ST100Q02TR | F33: ST100Q03TR | G33: ST100Q04TR
A34: Teacher-directed instruction | B34: dirins | C34: Student | D34: ST102Q01TR | E34: ST102Q02TR | F34: ST102Q03TR | G34: ST102Q04TR
A35: Teachers' stimulation of reading engagement | B35: stimread | C35: Student | D35: ST152Q05IA | E35: ST152Q06IA | F35: ST152Q07IA | G35: ST152Q08IA
A36: Value of school | B36: attlnact | C36: Student | D36: ST036Q05TR | E36: ST036Q06TR | F36: ST036Q08TR

Sheet Table III.B1.4.1
A1: PISA 2018 Results (Volume III) - © OECD 2019
A2: Annex B1 | B2: Annex B1.4 Results (tables): Student truancy and lateness
A3: Version 2 - Last updated: 02-Dec-2019
A4: Disclaimer: http://oe.cd/disclaimer
A6: Table III.B1.4.1
A7: Student truancy and lateness
A8: Based on students' reports
B11: Percentage of students who reported that the following happened in the two weeks prior to the PISA test:
B12: I skipped a whole day of school | N12: I skipped some classes | Z12: I arrived late for school
B13: Never | E13: Once or twice | H13: Three or four times | K13: Five or more times | N13: Never | Q13: Once or twice | T13: Three or four times | W13: Five or more times | Z13: Never | AC13: Once or twice | AF13: Three or four times | AI13: Five or more times
B14: % | C14: S.E. | E14: % | F14: S.E. | H14: % | I14: S.E. | K14: % | L14: S.E. | N14: % | O14: S.E. | Q14: % | R14: S.E. | T14: % | U14: S.E. | W14: % | X14: S.E. | Z14: % | AA14: S.E. | AC14: % | AD14: S.E. | AF14: % | AG14: S.E. | AI14: % | AJ14: S.E.
A15: OECD
A16: Australia | B16: 67.008128 | C16: 0.55475889 | E16: 25.463229 | F16: 0.50140665 | H16: 4.1097451 | I16: 0.19864923 | K16: 3.4188983 | L16: 0.2075722 | N16: 78.822646 | O16: 0.53002282 | Q16: 15.426319 | R16: 0.44636606 | T16: 3.5359232 | U16: 0.21240647 | W16: 2.2151115 | X16: 0.15935474 | Z16: 54.416661 | AA16: 0.62775413 | AC16: 29.734833 | AD16: 0.50782335 | AF16: 8.3916803 | AG16: 0.27757517 | AI16: 7.4568261 | AJ16: 0.30418569
A17: Austria | B17: 82.669892 | C17: 0.58488252 | E17: 11.825591 | F17: 0.49056563 | H17: 2.7822827 | I17: 0.20584263 | K17: 2.7222339 | L17: 0.23394768 | N17: 74.026393 | O17: 0.89768079 | Q17: 18.269955 | R17: 0.74822983 | T17: 4.3359786 | U17: 0.34789416 | W17: 3.3676737 | X17: 0.25392015 | Z17: 57.947425 | AA17: 0.79941477 | AC17: 26.479158 | AD17: 0.70812841 | AF17: 8.2917551 | AG17: 0.43365449 | AI17: 7.2816624 | AJ17: 0.45720077
A18: Belgium | B18: 91.313024 | C18: 0.35052522 | E18: 6.3616252 | F18: 0.34093639 | H18: 0.98988832 | I18: 0.11021268 | K18: 1.335463 | L18: 0.16088988 | N18: 85.795494 | O18: 0.52071746 | Q18: 10.582287 | R18: 0.40542409 | T18: 1.9905346 | U18: 0.20419967 | W18: 1.631684 | X18: 0.16822612 | Z18: 46.448203 | AA18: 0.71563676 | AC18: 31.472487 | AD18: 0.508289 | AF18: 9.7597838 | AG18: 0.35706336 | AI18: 12.319526 | AJ18: 0.50662122
A19: Canada | B19: 76.787108 | C19: 0.4968779 | E19: 17.885408 | F19: 0.44889322 | H19: 2.9001856 | I19: 0.17322539 | K19: 2.4272986 | L19: 0.14545793 | N19: 67.153658 | O19: 0.66585903 | Q19: 23.136976 | R19: 0.50568975 | T19: 5.9129109 | U19: 0.26587969 | W19: 3.7964546 | X19: 0.20622837 | Z19: 47.674573 | AA19: 0.64673781 | AC19: 30.810768 | AD19: 0.43980134 | AF19: 10.745641 | AG19: 0.36559004 | AI19: 10.769018 | AJ19: 0.35062557
A20: Chile | B20: 89.504309 | C20: 0.53206702 | D20: † | E20: 7.0264616 | F20: 0.44745596 | G20: † | H20: 1.7191757 | I20: 0.22564975 | J20: † | K20: 1.750054 | L20: 0.20872007 | M20: † | N20: 81.075097 | O20: 0.79111042 | P20: † | Q20: 13.350568 | R20: 0.60708643 | S20: † | T20: 3.3875384 | U20: 0.32140034 | V20: † | W20: 2.1867972 | X20: 0.22468878 | Y20: † | Z20: 31.559151 | AA20: 0.89145788 | AB20: † | AC20: 35.07575 | AD20: 0.67270744 | AE20: † | AF20: 14.770489 | AG20: 0.63136163 | AH20: † | AI20: 18.59461 | AJ20: 0.78853478 | AK20: †
A21: Colombia | B21: 56.405859 | C21: 0.79188107 | D21: † | E21: 36.545665 | F21: 0.78807763 | G21: † | H21: 4.640128 | I21: 0.40038582 | J21: † | K21: 2.4083474 | L21: 0.22744744 | M21: † | N21: 56.139232 | O21: 0.91746087 | P21: † | Q21: 35.404156 | R21: 0.90808681 | S21: † | T21: 6.0443667 | U21: 0.42212219 | V21: † | W21: 2.4122451 | X21: 0.24401128 | Y21: † | Z21: 54.867288 | AA21: 1.0295572 | AB21: † | AC21: 33.435789 | AD21: 0.89407123 | AE21: † | AF21: 8.0002782 | AG21: 0.42541359 | AH21: † | AI21: 3.6966447 | AJ21: 0.37845045 | AK21: †
A22: Czech Republic | B22: 89.545225 | C22: 0.50063053 | E22: 6.3619392 | F22: 0.38219501 | H22: 1.8738452 | I22: 0.1981992 | K22: 2.218991 | L22: 0.26485785 | N22: 88.09185 | O22: 0.54871607 | Q22: 7.9249506 | R22: 0.36741935 | T22: 2.2627358 | U22: 0.24070238 | W22: 1.7204634 | X22: 0.24833797 | Z22: 46.23363 | AA22: 0.99523641 | AC22: 32.796071 | AD22: 0.74901209 | AF22: 10.465749 | AG22: 0.45488494 | AI22: 10.50455 | AJ22: 0.59529849
A23: Denmark | B23: 80.334483 | C23: 0.7011951 | E23: 14.623549 | F23: 0.63824803 | H23: 2.6294281 | I23: 0.23133567 | K23: 2.4125403 | L23: 0.24506945 | N23: 75.57121 | O23: 0.89051485 | Q23: 17.871103 | R23: 0.70910554 | T23: 3.6675148 | U23: 0.37270599 | W23: 2.8901723 | X23: 0.26542223 | Z23: 52.097834 | AA23: 0.8934772 | AC23: 29.810026 | AD23: 0.66009444 | AF23: 9.6303342 | AG23: 0.46335639 | AI23: 8.4618058 | AJ23: 0.42868728
A24: Estonia | B24: 82.514613 | C24: 0.58456501 | E24: 13.312725 | F24: 0.50377148 | H24: 2.2353899 | I24: 0.18978937 | K24: 1.9372724 | L24: 0.24041163 | N24: 68.962967 | O24: 0.88170027 | Q24: 23.537845 | R24: 0.74987792 | T24: 4.6194591 | U24: 0.32007406 | W24: 2.8797292 | X24: 0.31918115 | Z24: 55.297345 | AA24: 0.7672725 | AC24: 29.016327 | AD24: 0.65267913 | AF24: 9.6002967 | AG24: 0.46492036 | AI24: 6.0860309 | AJ24: 0.37021778
A25: Finland | B25: 86.795176 | C25: 0.56717241 | E25: 10.657147 | F25: 0.45709561 | H25: 1.2613504 | I25: 0.1445516 | K25: 1.2863266 | L25: 0.18411599 | N25: 80.058273 | O25: 0.63612743 | Q25: 15.976535 | R25: 0.49487989 | T25: 2.299709 | U25: 0.22134558 | W25: 1.6654829 | X25: 0.20843557 | Z25: 55.393166 | AA25: 0.82763202 | AC25: 31.309885 | AD25: 0.69815761 | AF25: 8.3413838 | AG25: 0.39411383 | AI25: 4.9555653 | AJ25: 0.27575896
A26: France | B26: 83.888107 | C26: 0.66023669 | E26: 10.364092 | F26: 0.48160808 | H26: 2.4424775 | I26: 0.22164476 | K26: 3.3053237 | L26: 0.3274291 | N26: 70.459778 | O26: 0.87681751 | Q26: 19.747175 | R26: 0.54686923 | T26: 5.0930782 | U26: 0.3417248 | W26: 4.6999695 | X26: 0.38199323 | Z26: 43.028943 | AA26: 0.90326572 | AC26: 31.886085 | AD26: 0.74203892 | AF26: 12.126009 | AG26: 0.488087 | AI26: 12.958963 | AJ26: 0.61268031
A27: Germany | B27: 86.712984 | C27: 0.85752485 | D27: ‡ | E27: 9.1541793 | F27: 0.64803517 | G27: ‡ | H27: 2.0116383 | I27: 0.28546505 | J27: ‡ | K27: 2.1211984 | L27: 0.31633626 | M27: ‡ | N27: 78.992097 | O27: 1.060584 | P27: ‡ | Q27: 14.926314 | R27: 0.82914132 | S27: ‡ | T27: 3.5031307 | U27: 0.39055302 | V27: ‡ | W27: 2.5784586 | X27: 0.3843116 | Y27: ‡ | Z27: 54.113115 | AA27: 1.3656066 | AB27: ‡ | AC27: 29.118166 | AD27: 1.1375114 | AE27: ‡ | AF27: 8.79885 | AG27: 0.53342976 | AH27: ‡ | AI27: 7.9698693 | AJ27: 0.7161716 | AK27: ‡
A28: Greece | B28: 71.438045 | C28: 0.63731893 | E28: 20.716329 | F28: 0.60266765 | H28: 4.1722312 | I28: 0.27599766 | K28: 3.6733948 | L28: 0.28272829 | N28: 48.76752 | O28: 1.2805108 | Q28: 33.418672 | R28: 0.93192063 | T28: 10.514768 | U28: 0.45084145 | W28: 7.2990402 | X28: 0.40253422 | Z28: 44.170243 | AA28: 0.83529892 | AC28: 29.813566 | AD28: 0.71685242 | AF28: 13.261106 | AG28: 0.56800327 | AI28: 12.755085 | AJ28: 0.49784533
A29: Hungary | B29: 87.982737 | C29: 0.66946146 | E29: 8.7488184 | F29: 0.51378735 | H29: 2.2031907 | I29: 0.201366 | K29: 1.0652538 | L29: 0.17825414 | N29: 80.753393 | O29: 0.94922154 | Q29: 14.002792 | R29: 0.70959766 | T29: 3.5073814 | U29: 0.39689441 | W29: 1.7364333 | X29: 0.20324268 | Z29: 58.509289 | AA29: 1.1148966 | AC29: 28.263146 | AD29: 0.77562708 | AF29: 7.9442955 | AG29: 0.56581913 | AI29: 5.2832694 | AJ29: 0.44838356
A30: Iceland | B30: 92.649477 | C30: 0.52694601 | E30: 4.2259928 | F30: 0.39467059 | H30: 1.5701012 | I30: 0.24141358 | K30: 1.554429 | L30: 0.22326709 | N30: 75.583523 | O30: 0.93483858 | Q30: 16.4708 | R30: 0.75684504 | T30: 4.3258928 | U30: 0.40862842 | W30: 3.6197838 | X30: 0.38747929 | Z30: 50.486008 | AA30: 0.9442542 | AC30: 28.278717 | AD30: 0.91512202 | AF30: 11.174689 | AG30: 0.59920607 | AI30: 10.060586 | AJ30: 0.61922851
A31: Ireland | B31: 70.106498 | C31: 0.80737933 | E31: 24.17728 | F31: 0.72083757 | H31: 3.2494971 | I31: 0.27978067 | K31: 2.4667255 | L31: 0.22170757 | N31: 72.328753 | O31: 0.98154706 | Q31: 20.553985 | R31: 0.7598742 | T31: 4.8061347 | U31: 0.38927701 | W31: 2.3111274 | X31: 0.23663409 | Z31: 66.381408 | AA31: 0.98025577 | AC31: 24.460262 | AD31: 0.81557678 | AF31: 5.2585351 | AG31: 0.37371496 | AI31: 3.8997947 | AJ31: 0.26825499
A32: Israel | B32: 61.565408 | C32: 0.84529106 | E32: 25.994831 | F32: 0.70671115 | H32: 7.0950759 | I32: 0.33988859 | K32: 5.3446848 | L32: 0.36152301 | N32: 55.022164 | O32: 1.1229698 | Q32: 29.571338 | R32: 0.76459541 | T32: 9.0287666 | U32: 0.45460973 | W32: 6.3777314 | X32: 0.42822589 | Z32: 38.858194 | AA32: 0.9205957 | AC32: 32.51122 | AD32: 0.54540085 | AF32: 15.28491 | AG32: 0.46103484 | AI32: 13.345676 | AJ32: 0.63373146
A33: Italy | B33: 43.194593 | C33: 0.9853858 | E33: 39.839342 | F33: 0.8166281 | H33: 8.0350193 | I33: 0.41856539 | K33: 8.9310457 | L33: 0.50473466 | N33: 47.582426 | O33: 0.89466428 | Q33: 37.937685 | R33: 0.84115646 | T33: 8.8742072 | U33: 0.49229999 | W33: 5.6056826 | X33: 0.32354093 | Z33: 54.861592 | AA33: 0.95415894 | AC33: 27.321138 | AD33: 0.72209128 | AF33: 10.127962 | AG33: 0.55850673 | AI33: 7.6893079 | AJ33: 0.4704445
A34: Japan | B34: 97.89465 | C34: 0.35354781 | E34: 1.675253 | F34: 0.2666988 | H34: 0.13012471 | I34: 0.049128366 | K34: 0.29997255 | L34: 0.096442491 | N34: 96.452778 | O34: 0.38399645 | Q34: 2.7735814 | R34: 0.29447499 | T34: 0.41508054 | U34: 0.086081309 | W34: 0.35855993 | X34: 0.10446261 | Z34: 87.344383 | AA34: 0.70973831 | AC34: 10.312711 | AD34: 0.53319896 | AF34: 1.2977198 | AG34: 0.19414139 | AI34: 1.0451861 | AJ34: 0.16794378
A35: Korea | B35: 97.768412 | C35: 0.32630547 | E35: 1.5323109 | F35: 0.25609284 | H35: 0.3523081 | I35: 0.104502 | K35: 0.34696907 | L35: 0.07649142 | N35: 97.400912 | O35: 0.38195981 | Q35: 1.7801365 | R35: 0.24516309 | T35: 0.42667494 | U35: 0.099195936 | W35: 0.39227638 | X35: 0.13343085 | Z35: 80.849762 | AA35: 0.78273336 | AC35: 14.002087 | AD35: 0.50746968 | AF35: 2.8877626 | AG35: 0.28349153 | AI35: 2.2603879 | AJ35: 0.27759234
A36: Latvia | B36: 71.349985 | C36: 0.77686397 | E36: 21.65992 | F36: 0.60270833 | H36: 4.25619 | I36: 0.35990071 | K36: 2.7339053 | L36: 0.24683026 | N36: 59.260299 | O36: 0.81369384 | Q36: 30.08755 | R36: 0.76193737 | T36: 6.7538147 | U36: 0.33769557 | W36: 3.8983364 | X36: 0.32419312 | Z36: 45.061021 | AA36: 0.84911507 | AC36: 34.095028 | AD36: 0.77330901 | AF36: 12.596258 | AG36: 0.46127943 | AI36: 8.2476927 | AJ36: 0.49888809
A37: Lithuania | B37: 72.155569 | C37: 0.6832187 | E37: 19.168222 | F37: 0.61006313 | H37: 5.3727152 | I37: 0.3169785 | K37: 3.3034939 | L37: 0.24653499 | N37: 58.052788 | O37: 0.80577303 | Q37: 29.642636 | R37: 0.73409847 | T37: 8.3558728 | U37: 0.47555764 | W37: 3.9487032 | X37: 0.27320297 | Z37: 50.186381 | AA37: 0.80936837 | AC37: 30.63544 | AD37: 0.59168989 | AF37: 11.339071 | AG37: 0.41764196 | AI37: 7.839109 | AJ37: 0.37608465
A38: Luxembourg | B38: 84.801348 | C38: 0.5562809 | E38: 10.409176 | F38: 0.45778001 | H38: 2.5864177 | I38: 0.25139712 | K38: 2.2030587 | L38: 0.21116815 | N38: 80.669142 | O38: 0.59180128 | Q38: 12.925115 | R38: 0.48597283 | T38: 3.6991419 | U38: 0.28345201 | W38: 2.706601 | X38: 0.21322508 | Z38: 45.279416 | AA38: 0.75105601 | AC38: 31.509763 | AD38: 0.71686596 | AF38: 11.423558 | AG38: 0.39096566 | AI38: 11.787263 | AJ38: 0.41886817
A39: Mexico | B39: 71.266677 | C39: 1.034841 | D39: † | E39: 23.726817 | F39: 0.92583263 | G39: † | H39: 3.7856007 | I39: 0.32016994 | J39: † | K39: 1.2209048 | L39: 0.17115473 | M39: † | N39: 71.306953 | O39: 0.94607628 | P39: † | Q39: 23.185071 | R39: 0.77411848 | S39: † | T39: 4.4483623 | U39: 0.37893555 | V39: † | W39: 1.0596137 | X39: 0.16937048 | Y39: † | Z39: 53.006375 | AA39: 1.1584818 | AB39: † | AC39: 34.109926 | AD39: 0.92531619 | AE39: † | AF39: 9.3989411 | AG39: 0.5323828 | AH39: † | AI39: 3.4847579 | AJ39: 0.31774332 | AK39: †
A40: Netherlands* | B40: 92.761079 | C40: 0.54158444 | E40: 5.600142 | F40: 0.44358261 | H40: 0.86325427 | I40: 0.17757333 | K40: 0.77552472 | L40: 0.1592391 | N40: 77.556524 | O40: 1.0451145 | Q40: 16.608063 | R40: 0.80737581 | T40: 3.2237705 | U40: 0.26919996 | W40: 2.6116423 | X40: 0.33111863 | Z40: 51.207971 | AA40: 1.1130913 | AC40: 30.634833 | AD40: 0.82352998 | AF40: 8.4083853 | AG40: 0.57550993 | AI40: 9.7488111 | AJ40: 0.70461655
A41: New Zealand | B41: 71.015203 | C41: 0.81876377 | E41: 22.193835 | F41: 0.72749219 | H41: 3.6808446 | I41: 0.26026871 | K41: 3.110117 | L41: 0.26950581 | N41: 73.53145 | O41: 0.90347038 | Q41: 19.357329 | R41: 0.72350772 | T41: 4.2642356 | U41: 0.27725477 | W41: 2.8469857 | X41: 0.24093234 | Z41: 52.369996 | AA41: 0.94350084 | AC41: 28.768546 | AD41: 0.68267175 | AF41: 9.6866029 | AG41: 0.49974937 | AI41: 9.1748547 | AJ41: 0.47242703
A42: Norway | B42: 86.431888 | C42: 0.51978064 | E42: 9.1598414 | F42: 0.45379201 | H42: 2.1832319 | I42: 0.19603074 | K42: 2.2250385 | L42: 0.21851158 | N42: 79.057702 | O42: 0.65561965 | Q42: 14.535169 | R42: 0.52980252 | T42: 3.4488398 | U42: 0.2684247 | W42: 2.9582893 | X42: 0.21748743 | Z42: 50.720412 | AA42: 0.85659141 | AC42: 30.490421 | AD42: 0.6660505 | AF42: 9.0105843 | AG42: 0.39787916 | AI42: 9.7785834 | AJ42: 0.45582857
A43: Poland | B43: 76.05654 | C43: 0.9892452 | E43: 15.995319 | F43: 0.69098794 | H43: 3.5028941 | I43: 0.31566233 | K43: 4.445247 | L43: 0.35202474 | N43: 64.53469 | O43: 1.0001679 | Q43: 23.180121 | R43: 0.71689557 | T43: 6.2779853 | U43: 0.4326755 | W43: 6.0072034 | X43: 0.41583103 | Z43: 44.700018 | AA43: 1.0819382 | AC43: 29.863703 | AD43: 0.58883307 | AF43: 11.205031 | AG43: 0.51822031 | AI43: 14.231247 | AJ43: 0.72278452
...

Sheet Table III.B1.4.2
A1: PISA 2018 Results (Volume III) - © OECD 2019
A2: Annex B1 | B2: Annex B1.4 Results (tables): Student truancy and lateness
A3: Version 2 - Last updated: 02-Dec-2019
A4: Disclaimer: http://oe.cd/disclaimer
A6: Table III.B1.4.2
A7: Change between 2015 and 2018 in student truancy and lateness
A8: Based on students' reports
B11: Change between 2015 and 2018 (PISA 2018 - PISA 2015)
B12: Percentage of students who reported that the following happened at least once in the two weeks prior to the PISA test:
B13: I skipped a whole day of school | E13: I skipped some classes | H13: I arrived late for school
B14: % dif. | C14: S.E. | E14: % dif. | F14: S.E. | H14: % dif. | I14: S.E.
A15: OECD
A16: Australia | B16: 4.0223942 | C16: 0.79134071 | E16: 5.1380601 | F16: 0.68080509 | H16: 4.5364723 | I16: 0.84181792
A17: Austria | B17: 6.4430318 | C17: 0.76817429 | E17: 8.7549067 | F17: 1.1410588 | H17: 6.8777547 | I17: 1.2863401
A18: Belgium | B18: 1.6101153 | C18: 0.49076357 | E18: 2.4628086 | F18: 0.76036495 | H18: 2.0418568 | I18: 1.1530839
A19: Canada | B19: 5.3927531 | C19: 0.70061022 | E19: 6.3054271 | F19: 0.9596141 | H19: 4.5835638 | I19: 1.0110073
A20: Chile | B20: 1.1932843 | C20: 0.78396505 | D20: † | E20: 0.23011398 | F20: 1.1472036 | G20: † | H20: 1.6985165 | I20: 1.2715321 | J20: †
A21: Colombia | B21: -0.25337619 | C21: 1.1422533 | D21: † | E21: -1.6221843 | F21: 1.2287867 | G21: † | H21: 2.2452002 | I21: 1.3678944 | J21: †
A22: Czech Republic | B22: 2.3793046 | C22: 0.66903406 | E22: 2.3224413 | F22: 0.72561479 | H22: 1.7983707 | I22: 1.3263474
A23: Denmark | B23: 2.6734908 | C23: 0.89312029 | E23: 0.40139076 | F23: 1.1901776 | H23: 0.35203114 | I23: 1.2581104
A24: Estonia | B24: -5.4849172 | C24: 0.95334506 | E24: -3.8848865 | F24: 1.2094823 | H24: 1.8491549 | I24: 1.1816474
A25: Finland | B25: -23.408627 | C25: 1.0429373 | E25: -28.216005 | F25: 1.1114954 | H25: 8.4006262 | I25: 1.2125636
A26: France | B26: 5.2627587 | C26: 0.87197495 | E26: 4.7889543 | F26: 1.1681834 | H26: 4.3605008 | I26: 1.264142
A27: Germany | B27: 4.4068966 | C27: 0.96786761 | D27: ‡ | E27: 5.2589083 | F27: 1.2704161 | G27: ‡ | H27: 5.7605896 | I27: 1.7022336 | J27: ‡
A28: Greece | B28: 8.9158363 | C28: 1.0483662 | E28: 5.8992605 | F28: 1.9145797 | H28: 1.6002301 | I28: 1.1303055
A29: Hungary | B29: 3.6045973 | C29: 0.81177723 | E29: 1.5831043 | F29: 1.2194684 | H29: 5.7126474 | I29: 1.444032
A30: Iceland | B30: 2.865922 | C30: 0.63930655 | E30: 5.9647622 | F30: 1.1543746 | H30: -0.52410161 | I30: 1.3799751
A31: Ireland | B31: 5.5163517 | C31: 1.1079822 | E31: 4.6052761 | F31: 1.2404962 | H31: 2.5112479 | I31: 1.3446357
A32: Israel | B32: 5.7395682 | C32: 1.2508446 | E32: 6.9754505 | F32: 1.5848815 | H32: 3.2693121 | I32: 1.4563487
A33: Italy | B33: 1.595832 | C33: 1.269503 | E33: 11.554599 | F33: 1.1493545 | H33: 8.9194174 | I33: 1.2869827
A34: Japan | B34: 0.33948889 | C34: 0.41804135 | E34: 0.4907904 | F34: 0.50720757 | H34: 0.94011235 | I34: 0.95215356
A35: Korea | B35: 0.36703753 | C35: 0.39446828 | E35: -0.037128665 | F35: 0.48154318 | H35: -0.26488942 | I35: 1.2388675
A36: Latvia | B36: 3.9300411 | C36: 1.0780216 | E36: 1.6896124 | F36: 1.2366929 | H36: 1.8025315 | I36: 1.2869146
A37: Lithuania | B37: 5.5655756 | C37: 1.0027543 | E37: 1.5095868 | F37: 1.2181243 | H37: 2.0608284 | I37: 1.1561892
A38: Luxembourg | B38: 3.7505035 | C38: 0.67993057 | E38: 4.0589104 | F38: 0.78999758 | H38: 0.37851062 | I38: 1.0128109
A39: Mexico | B39: 2.962276 | C39: 1.3029869 | D39: † | E39: 3.8049617 | F39: 1.261474 | G39: † | H39: -1.8658981 | I39: 1.4772446 | J39: †
A40: Netherlands* | B40: 1.9092878 | C40: 0.64083457 | E40: 3.5806956 | F40: 1.2961301 | H40: -2.176842 | I40: 1.3911239
A41: New Zealand | B41: 4.0146685 | C41: 1.0529259 | E41: 3.8482556 | F41: 1.1251916 | H41: 2.3005755 | I41: 1.3403237
A42: Norway | B42: 0.095120385 | C42: 0.72003776 | E42: 1.214402 | F42: 0.9432202 | H42: 2.2937829 | I42: 1.2379527
A43: Poland | B43: 3.668103 | C43: 1.3298246 | E43: -1.9614007 | F43: 1.5272667 | H43: -1.166762 | I43: 1.6019603
...

Sheet Table III.B1.4.3
A1: PISA 2018 Results (Volume III) - © OECD 2019
A2: Annex B1 | B2: Annex B1.4 Results (tables): Student truancy and lateness
A3: Version 2 - Last updated: 02-Dec-2019
A4: Disclaimer: http://oe.cd/disclaimer
A6: Table III.B1.4.3
A7: Prevalence of student truancy in schools
A8: Based on students' reports
B11: Percentage of students who skipped a whole day of school at least once in the two weeks prior to the PISA test | E11: Percentage of students who are in schools where…
E12: Over 90% of students skipped school at least once in the two weeks prior to the PISA test | H12: Between 75% and 90% of students skipped school at least once in the two weeks prior to the PISA test | K12: Between 25% and 75% of students skipped school at least once in the two weeks prior to the PISA test | N12: Between 10% and 25% of students skipped school at least once in the two weeks prior to the PISA test | Q12: 10% of students or less skipped school at least once in the two weeks prior to the PISA test
B14: % | C14: S.E. | E14: % | F14: S.E. | H14: % | I14: S.E. | K14: % | L14: S.E. | N14: % | O14: S.E. | Q14: % | R14: S.E.
A15: OECD
A16: Australia | B16: 32.991872 | C16: 0.55475889 | E16: 0.50087711 | F16: 0.31674606 | H16: 0.25854994 | I16: 0.13933489 | K16: 68.910478 | L16: 1.926843 | N16: 24.919568 | O16: 1.8028784 | Q16: 5.4105272 | R16: 0.89707068
A17: Austria | B17: 17.330108 | C17: 0.58488252 | E17: 0.26156258 | F17: 0.24366521 | H17: 0 | I17: c | K17: 22.327168 | L17: 2.4254428 | N17: 47.696865 | O17: 3.393876 | Q17: 29.714405 | R17: 2.9710337
A18: Belgium | B18: 8.6869765 | C18: 0.35052522 | E18: 0.057242495 | F18: 0.056248757 | H18: 0 | I18: c | K18: 5.7024507 | L18: 1.1446589 | N18: 31.225348 | O18: 2.6724293 | Q18: 63.014959 | R18: 2.4446
A19: Canada | B19: 23.212892 | C19: 0.4968779 | E19: 0.072384429 | F19: 0.029468728 | H19: 0.054275151 | I19: 0.040136144 | K19: 42.111374 | L19: 2.3290603 | N19: 44.539645 | O19: 2.3899008 | Q19: 13.222322 | R19: 1.291186
A20: Chile | B20: 10.495691 | C20: 0.53206702 | D20: † | E20: 0.52379841 | F20: 0.26981119 | H20: 0 | I20: c | K20: 7.3201878 | L20: 1.6385689 | N20: 37.853069 | O20: 3.3985013 | Q20: 54.302945 | R20: 3.3571812
A21: Colombia | B21: 43.594141 | C21: 0.79188107 | D21: † | E21: 1.6372166 | F21: 0.84518402 | H21: 0.30433051 | I21: 0.19449179 | K21: 89.909514 | L21: 1.902692 | N21: 6.8722481 | O21: 1.5760116 | Q21: 1.2766907 | R21: 0.7148788
A22: Czech Republic | B22: 10.454775 | C22: 0.50063053 | E22: 0.32402617 | F22: 0.32285801 | H22: 0 | I22: c | K22: 9.1669047 | L22: 1.6020718 | N22: 34.315415 | O22: 3.0883411 | Q22: 56.193654 | R22: 2.9216721
A23: Denmark | B23: 19.665517 | C23: 0.7011951 | E23: 0.12587619 | F23: 0.10316477 | H23: 0 | I23: c | K23: 28.324489 | L23: 2.6088936 | N23: 54.013926 | O23: 3.3028999 | Q23: 17.535709 | R23: 2.5314462
A24: Estonia | B24: 17.485387 | C24: 0.58456501 | E24: 0.10107781 | F24: 0.06937347 | H24: 0 | I24: c | K24: 22.849036 | L24: 1.8663988 | N24: 47.446228 | O24: 1.9359859 | Q24: 29.603658 | R24: 1.6434741
A25: Finland | B25: 13.204824 | C25: 0.56717241 | E25: 0 | F25: c | H25: 0 | I25: c | K25: 9.7796781 | L25: 1.997302 | N25: 51.895301 | O25: 3.5947569 | Q25: 38.325021 | R25: 3.4057518
A26: France | B26: 16.111893 | C26: 0.66023669 | E26: 0.13305184 | F26: 0.096453154 | H26: 0 | I26: c | K26: 20.898549 | L26: 2.622155 | N26: 45.051287 | O26: 3.3768105 | Q26: 33.917112 | R26: 3.0543309
A27: Germany | B27: 13.287016 | C27: 0.85752485 | D27: ‡ | E27: 0 | F27: c | H27: 0.42703989 | I27: 0.4290057 | K27: 22.015401 | L27: 2.7587263 | N27: 33.532582 | O27: 3.0317899 | Q27: 44.024977 | R27: 3.3031088
A28: Greece | B28: 28.561955 | C28: 0.63731893 | E28: 0.25741159 | F28: 0.14844843 | H28: 0.48339152 | I28: 0.48468683 | K28: 53.977676 | L28: 2.8793532 | N28: 40.464872 | O28: 2.9591727 | Q28: 4.8166481 | R28: 1.4099632
A29: Hungary | B29: 12.017263 | C29: 0.66946146 | E29: 0.36129866 | F29: 0.16170523 | H29: 0.14584877 | I29: 0.14590665 | K29: 12.456724 | L29: 2.0557091 | N29: 29.680227 | O29: 3.320917 | Q29: 57.355901 | R29: 3.1814417
A30: Iceland | B30: 7.350523 | C30: 0.52694601 | E30: 0.11309257 | F30: 0.02973716 | H30: 0 | I30: c | K30: 0.82373035 | L30: 0.065221922 | N30: 22.535407 | O30: 0.18316156 | Q30: 76.52777 | R30: 0.19274975
A31: Ireland | B31: 29.893502 | C31: 0.80737933 | E31: 0 | F31: c | H31: 0 | I31: c | K31: 69.694127 | L31: 3.7386693 | N31: 27.706658 | O31: 3.85098 | Q31: 2.5992152 | R31: 1.3255717
A32: Israel | B32: 38.434592 | C32: 0.84529106 | E32: 0.98562957 | F32: 0.72570539 | H32: 0.31508206 | I32: 0.32583899 | K32: 84.537566 | L32: 2.0770547 | N32: 11.840835 | O32: 2.1326421 | Q32: 2.3208873 | R32: 1.1638703
A33: Italy | B33: 56.805407 | C33: 0.9853858 | E33: 2.147971 | F33: 0.79681696 | H33: 13.526417 | I33: 2.224219 | K33: 82.430261 | L33: 2.3838096 | N33: 1.6560104 | O33: 0.79953147 | Q33: 0.23934085 | R33: 0.11894009
A34: Japan | B34: 2.1053503 | C34: 0.35354781 | E34: 0 | F34: c | H34: 0 | I34: c | K34: 0.54870529 | L34: 0.49759421 | N34: 3.8081198 | O34: 1.1341575 | Q34: 95.643175 | R34: 1.2438309
A35: Korea | B35: 2.2315881 | C35: 0.32630547 | E35: 0 | F35: c | H35: 0 | I35: c | K35: 0.13771505 | L35: 0.1502511 | N35: 5.606351 | O35: 1.8820447 | Q35: 94.255934 | R35: 1.8867201
A36: Latvia | B36: 28.650015 | C36: 0.77686397 | E36: 0.67714593 | F36: 0.34483561 | H36: 0.92784404 | I36: 0.45922362 | K36: 54.064315 | L36: 1.7626893 | N36: 37.050775 | O36: 1.7579742 | Q36: 7.2799196 | R36: 1.0379263
A37: Lithuania | B37: 27.844431 | C37: 0.6832187 | E37: 0.41136381 | F37: 0.23522326 | H37: 1.6171574 | I37: 0.61911502 | K37: 49.993144 | L37: 1.7087679 | N37: 35.678783 | O37: 1.5978066 | Q37: 12.299551 | R37: 0.9415261
A38: Luxembourg | B38: 15.198652 | C38: 0.5562809 | E38: 0 | F38: c | H38: 0 | I38: c | K38: 14.26701 | L38: 0.072839115 | N38: 63.914714 | O38: 0.082865094 | Q38: 21.818275 | R38: 0.072602169
A39: Mexico | B39: 28.733323 | C39: 1.034841 | D39: † | E39: 2.3553803 | F39: 1.0597875 | H39: 0.1609234 | I39: 0.16497149 | K39: 52.90879 | L39: 3.1860732 | N39: 29.976606 | O39: 2.9775372 | Q39: 14.598299 | R39: 2.3554523
A40: Netherlands* | B40: 7.2389209 | C40: 0.54158444 | E40: 0 | F40: c | H40: 0 | I40: c | K40: 2.9627032 | L40: 1.442228 | N40: 29.612959 | O40: 3.3154375 | Q40: 67.424338 | R40: 3.4346544
A41: New Zealand | B41: 28.984797 | C41: 0.81876377 | E41: 0 | F41: c | H41: 0.93210377 | I41: 0.57603162 | K41: 62.048851 | L41: 2.9344321 | N41: 32.09638 | O41: 2.7396204 | Q41: 4.9226653 | R41: 1.2537813
A42: Norway | B42: 13.568112 | C42: 0.51978064 | E42: 0 | F42: c | H42: 0 | I42: c | K42: 7.9542023 | L42: 1.7502478 | N42: 55.941872 | O42: 3.2493915 | Q42: 36.103926 | R42: 3.2285855
A43: Poland | B43: 23.94346 | C43: 0.9892452 | E43: 0.15591857 | F43: 0.11836375 | H43: 0.29015928 | I43: 0.28324224 | K43: 39.702754 | L43: 3.5349339 | N43: 44.825839 | O43: 3.7191372 | Q43: 15.02533 | R43: 2.0770272
A44: Portugal* | B44: 28.089308 | C44: 0.66231314 | E44: 0.32626578 | F44: 0.21265732 | H44: 0.36352823 | I44: 0.34912891 | K44: 60.106399 | L44: 2.944846 | N44: 32.433632 | O44: 2.7709035 | Q44: 6.7701755 | R44: 1.3309816
...

Sheet Table III.B1.4.4
A1: PISA 2018 Results (Volume III) - © OECD 2019
A2: Annex B1 | B2: Annex B1.4 Results (tables): Student truancy and lateness
A3: Version 2 - Last updated: 02-Dec-2019
A4: Disclaimer: http://oe.cd/disclaimer
A6: Table III.B1.4.4
A7: Prevalence of student lateness in schools
A8: Based on students' reports
B11: Percentage of students who arrived late for school at least once in the two weeks prior to the PISA test | E11: Percentage of students who are in schools where…
E12: Over 90% of students arrived late for school at least once in the two weeks prior to the PISA test | H12: Between 75% and 90% of students arrived late for school at least once in the two weeks prior to the PISA test | K12: Between 25% and 75% of students arrived late for school at least once in the two weeks prior to the PISA test | N12: Between 10% and 25% of students arrived late for school at least once in the two weeks prior to the PISA test | Q12: 10% of students or fewer arrived late for school at least once in the two weeks prior to the PISA test
B14: % | C14: S.E. | E14: % | F14: S.E. | H14: % | I14: S.E. | K14: % | L14: S.E. | N14: % | O14: S.E. | Q14: % | R14: S.E.
A15: OECD
A16: Australia | B16: 45.583339 | C16: 0.62775413 | E16: 0.94901513 | F16: 0.29443125 | H16: 2.2266509 | I16: 0.60979387 | K16: 87.092286 | L16: 1.4029269 | N16: 6.8744581 | O16: 1.0992395 | Q16: 2.8575897 | R16: 0.79273464
A17: Austria | B17: 42.052575 | C17: 0.79941477 | E17: 0.67014279 | F17: 0.3319434 | H17: 1.8510044 | I17: 0.85414361 | K17: 84.974907 | L17: 2.3287273 | N17: 10.334273 | O17: 2.0713617 | Q17: 2.1696727 | R17: 0.63055651
A18: Belgium | B18: 53.551797 | C18: 0.71563676 | E18: 0.595881 | F18: 0.30613711 | H18: 7.8831629 | I18: 1.3011026 | K18: 89.662245 | L18: 1.3498612 | N18: 1.8587115 | O18: 0.58771666 | Q18: 0 | R18: c
A19: Canada | B19: 52.325427 | C19: 0.64673781 | E19: 0.85889789 | F19: 0.44018073 | H19: 5.503139 | I19: 1.1350783 | K19: 89.202705 | L19: 1.4881675 | N19: 3.5578471 | O19: 0.76123365 | Q19: 0.8774114 | R19: 0.49857312
A20: Chile | B20: 68.440849 | C20: 0.89145788 | D20: † | E20: 6.9257456 | F20: 1.7577855 | H20: 24.876212 | I20: 3.0276461 | K20: 67.88715 | L20: 3.3290473 | N20: 0.21465459 | O20: 0.18954681 | Q20: 0.096237058 | R20: 0.098513356
A21: Colombia | B21: 45.132712 | C21: 1.0295572 | D21: † | E21: 1.3842608 | F21: 0.83043003 | H21: 3.0104209 | I21: 1.2396625 | K21: 84.956991 | L21: 2.7283875 | N21: 9.3462837 | O21: 2.1445995 | Q21: 1.3020432 | R21: 0.71407116
A22: Czech Republic | B22: 53.76637 | C22: 0.99523641 | E22: 3.424183 | F22: 0.89490151 | H22: 10.505769 | I22: 1.9413148 | K22: 81.564473 | L22: 1.700891 | N22: 4.0004436 | O22: 1.0886997 | Q22: 0.50513056 | R22: 0.14891088
A23: Denmark | B23: 47.902166 | C23: 0.8934772 | E23: 0.72235467 | F23: 0.33490791 | H23: 3.7877443 | I23: 1.1831748 | K23: 87.940848 | L23: 1.8283365 | N23: 6.7424447 | O23: 1.3396199 | Q23: 0.80660815 | R23: 0.45141097
A24: Estonia | B24: 44.702655 | C24: 0.7672725 | E24: 0.35463998 | F24: 0.16916638 | H24: 3.9068222 | I24: 1.0996203 | K24: 85.981075 | L24: 1.5676327 | N24: 4.9351908 | O24: 1.0700883 | Q24: 4.8222724 | R24: 1.128241
A25: Finland | B25: 44.606834 | C25: 0.82763202 | E25: 0.069505234 | F25: 0.068762143 | H25: 1.3413852 | I25: 0.706185 | K25: 90.354578 | L25: 1.8779803 | N25: 6.7568878 | O25: 1.5752308 | Q25: 1.4776437 | R25: 0.76527201
A26: France | B26: 56.971057 | C26: 0.90326572 | E26: 1.3416812 | F26: 0.57900371 | H26: 13.867332 | I26: 1.928181 | K26: 84.169535 | L26: 2.0062812 | N26: 0.49867053 | O26: 0.50709935 | Q26: 0.12278089 | R26: 0.11014094
A27: Germany | B27: 45.886885 | C27: 1.3656066 | D27: ‡ | E27: 2.1086758 | F27: 0.79111185 | H27: 7.948992 | I27: 2.2799589 | K27: 74.60702 | L27: 3.1890345 | N27: 11.95869 | O27: 2.1935417 | Q27: 3.3766227 | R27: 1.3654622
A28: Greece | B28: 55.829757 | C28: 0.83529892 | E28: 1.5765766 | F28: 0.69276532 | H28: 7.7874152 | I28: 1.9415703 | K28: 87.443443 | L28: 2.2681727 | N28: 2.7363515 | O28: 1.0364812 | Q28: 0.45621341 | R28: 0.1894139
A29: Hungary | B29: 41.490711 | C29: 1.1148966 | E29: 1.9143899 | F29: 0.55873029 | H29: 3.1377368 | I29: 1.2424157 | K29: 73.97907 | L29: 3.1020881 | N29: 18.150393 | O29: 2.6949631 | Q29: 2.8184107 | R29: 0.76447958
A30: Iceland | B30: 49.513992 | C30: 0.9442542 | E30: 0.084582428 | F30: 0.028992805 | H30: 2.203508 | I30: 0.07710712 | K30: 91.643219 | L30: 0.1457948 | N30: 4.26666 | O30: 0.077516247 | Q30: 1.8020309 | R30: 0.098985075
A31: Ireland | B31: 33.618592 | C31: 0.98025577 | E31: 0 | F31: c | H31: 0.29076182 | I31: 0.35953449 | K31: 71.934387 | L31: 3.6112446 | N31: 26.335262 | O31: 3.7286568 | Q31: 1.4395896 | R31: 1.0182044
A32: Israel | B32: 61.141806 | C32: 0.9205957 | E32: 2.3285811 | F32: 0.99767408 | H32: 15.375679 | I32: 2.641961 | K32: 82.047951 | L32: 2.6563785 | N32: 0 | O32: c | Q32: 0.24778818 | R32: 0.16241625
A33: Italy | B33: 45.138408 | C33: 0.95415894 | E33: 2.5313124 | F33: 0.9698729 | H33: 4.9872128 | I33: 1.2007057 | K33: 80.321099 | L33: 2.6210323 | N33: 11.513374 | O33: 2.1652907 | Q33: 0.64700179 | R33: 0.41530364
A34: Japan | B34: 12.655617 | C34: 0.70973831 | E34: 0 | F34: c | H34: 0 | I34: c | K34: 9.1776902 | L34: 2.0638408 | N34: 41.492803 | O34: 3.6149321 | Q34: 49.329507 | R34: 3.9709177
A35: Korea | B35: 19.150238 | C35: 0.78273336 | E35: 0 | F35: c | H35: 0 | I35: c | K35: 30.485455 | L35: 2.8529791 | N35: 50.210654 | O35: 3.6735564 | Q35: 19.303891 | R35: 2.8256166
A36: Latvia | B36: 54.938979 | C36: 0.84911507 | E36: 1.2333839 | F36: 0.4920079 | H36: 8.0847082 | I36: 1.2300106 | K36: 85.562595 | L36: 1.4387237 | N36: 4.4353187 | O36: 0.83126599 | Q36: 0.68399432 | R36: 0.27772581
A37: Lithuania | B37: 49.813619 | C37: 0.80936837 | E37: 2.8018466 | F37: 0.56877989 | H37: 5.8104911 | I37: 1.0290465 | K37: 85.058658 | L37: 1.1668163 | N37: 5.621658 | O37: 0.53432082 | Q37: 0.70734607 | R37: 0.29451698
A38: Luxembourg | B38: 54.720584 | C38: 0.75105601 | E38: 0.2323576 | F38: 0.037203505 | H38: 0 | I38: c | K38: 99.594221 | L38: 0.038290601 | N38: 0.17342168 | O38: 0.0095844035 | Q38: 0 | R38: c
A39: Mexico | B39: 46.993625 | C39: 1.1584818 | D39: † | E39: 4.4845888 | F39: 1.3556877 | H39: 3.9186468 | I39: 1.3546293 | K39: 79.985441 | L39: 2.6096551 | N39: 6.0218136 | O39: 1.4141857 | Q39: 5.5895099 | R39: 1.4905636
A40: Netherlands* | B40: 48.792029 | C40: 1.1130913 | E40: 0.9072492 | F40: 0.73871049 | H40: 4.2702832 | I40: 1.3577585 | K40: 90.809233 | L40: 2.3381262 | N40: 3.396946 | O40: 1.5681409 | Q40: 0.61628903 | R40: 0.61899613
A41: New Zealand | B41: 47.630004 | C41: 0.94350084 | E41: 1.2369444 | F41: 0.77396548 | H41: 3.0157325 | I41: 1.1621982 | K41: 90.576365 | L41: 1.7429734 | N41: 4.4688573 | O41: 1.060934 | Q41: 0.70210055 | R41: 0.46048001
A42: Norway | B42: 49.279588 | C42: 0.85659141 | E42: 0 | F42: c | H42: 3.6216364 | I42: 1.2226216 | K42: 92.092528 | L42: 1.5399926 | N42: 4.1053977 | O42: 0.91052296 | Q42: 0.18043801 | R42: 0.12774523
A43: Poland | B43: 55.299982 | C43: 1.0819382 | E43: 0.74998226 | F43: 0.30186377 | H43: 11.152725 | I43: 2.4216607 | K43: 84.537715 | L43: 2.6880663 | N43: 3.1875341 | O43: 0.97724706 | Q43: 0.37204301 | R43: 0.19661597
A44: Portugal* | B44: 49.753277 | C44: 0.87869987 | E44: 0.50320426 | F44: 0.31246248 | H44: 2.2860061 | I44: 0.77376598 | K44: 90.667818 | L44: 1.7537035 | N44: 6.2180187 | O44: 1.5966884 | Q44: 0.32495265 | R44: 0.15961215
...

Sheet Table III.B1.4.5
A1: PISA 2018 Results (Volume III) - © OECD 2019
A2: Annex B1 | B2: Annex B1.4 Results (tables): Student truancy and lateness
A3: Version 2 - Last updated: 02-Dec-2019
A4: Disclaimer: http://oe.cd/disclaimer
A6: Table III.B1.4.5
A7: Student truancy, by student characteristics
A8: Based on students' reports
B11: Percentage of students who skipped a whole day of school at least once in the two weeks prior to the PISA test, by the following student characteristics:
B12: Gender | K12: Socio-economic status1 | T12: Education level | AC12: Immigrant background
B13: Boys | E13: Girls | H13: Girls - boys | K13: Disadvantaged students | N13: Advantaged students | Q13: Advantaged -disadvantaged | T13: Lower secondary (ISCED 2) | W13: Upper secondary (ISCED 3) | Z13: ISCED 3 - ISCED 2 | AC13: Non-immigrant students | AF13: Immigrant students | AI13: Immigrant - non-immigrant
B14: % | C14: S.E. | E14: % | F14: S.E. | H14: % dif. | I14: S.E. | K14: % | L14: S.E. | N14: % | O14: S.E. | Q14: % dif. | R14: S.E. | T14: % | U14: S.E. | W14: % | X14: S.E. | Z14: % dif. | AA14: S.E. | AC14: % | AD14: S.E. | AF14: % | AG14: S.E. | AI14: % dif. | AJ14: S.E.
A15: OECD
A16: Australia | B16: 32.123435 | C16: 0.71593694 | E16: 33.915296 | F16: 0.80406087 | H16: 1.7918614 | I16: 1.0394032 | K16: 39.319275 | L16: 1.0773007 | N16: 27.429631 | O16: 0.80446405 | Q16: -11.889645 | R16: 1.360752 | T16: 32.961198 | U16: 0.56731904 | W16: 33.69159 | X16: 2.1478608 | Z16: 0.73039192 | AA16: 2.1997467 | AC16: 33.709772 | AD16: 0.58612793 | AF16: 30.942543 | AG16: 1.0258403 | AI16: -2.7672296 | AJ16: 1.0956562
A17: Austria | B17: 18.579233 | C17: 0.90372762 | E17: 16.117033 | F17: 0.83986465 | H17: -2.4622006 | I17: 1.3018308 | K17: 21.543788 | L17: 1.1433572 | N17: 14.051537 | O17: 1.2056714 | Q17: -7.4922511 | R17: 1.6605812 | T17: m | U17: m | W17: m | X17: m | Z17: m | AA17: m | AC17: 15.824756 | AD17: 0.65980912 | AF17: 22.513942 | AG17: 1.6243247 | AI17: 6.6891859 | AJ17: 1.8220825
A18: Belgium | B18: 11.255614 | C18: 0.55223666 | E18: 6.1954614 | F18: 0.48993777 | H18: -5.0601522 | I18: 0.78580434 | K18: 11.464997 | L18: 0.7929242 | N18: 6.2218718 | O18: 0.62470434 | Q18: -5.2431248 | R18: 0.92199054 | T18: 14.232352 | U18: 2.119414 | V18: ‡ | W18: 8.402571 | X18: 0.365611 | Z18: -5.8297809 | AA18: 2.197155 | AB18: ‡ | AC18: 7.5709982 | AD18: 0.39564631 | AF18: 13.928178 | AG18: 1.0315267 | AI18: 6.3571803 | AJ18: 1.1293535
A19: Canada | B19: 22.715701 | C19: 0.65869036 | E19: 23.69455 | F19: 0.73844352 | H19: 0.97884926 | I19: 0.98677172 | K19: 28.299441 | L19: 0.94450954 | N19: 19.943018 | O19: 0.81953108 | Q19: -8.3564235 | R19: 1.1514728 | T19: 19.99417 | U19: 1.1602267 | W19: 23.564355 | X19: 0.54372907 | Z19: 3.5701846 | AA19: 1.3093425 | AC19: 23.808685 | AD19: 0.5679977 | AF19: 21.881797 | AG19: 0.88745647 | AI19: -1.9268878 | AJ19: 1.028835
A20: Chile | B20: 12.826663 | C20: 0.82177746 | D20: † | E20: 8.1211297 | F20: 0.58127163 | G20: † | H20: -4.7055332 | I20: 0.94649775 | J20: † | K20: 13.23231 | L20: 1.1773242 | M20: † | N20: 9.4275537 | O20: 0.93277117 | P20: † | Q20: -3.8047566 | R20: 1.5199321 | S20: † | T20: 27.815726 | U20: 4.8978589 | V20: † | W20: 9.7573835 | X20: 0.49199914 | Y20: † | Z20: -18.058343 | AA20: 4.8785323 | AB20: † | AC20: 10.141755 | AD20: 0.54190548 | AE20: † | AF20: 16.65314 | AG20: 3.6605035 | AH20: † | AI20: 6.5113858 | AJ20: 3.6892057 | AK20: †
A21: Colombia | B21: 42.598984 | C21: 1.0456576 | D21: † | E21: 44.577414 | F21: 1.2175664 | G21: † | H21: 1.97843 | I21: 1.6284238 | J21: † | K21: 44.286409 | L21: 1.8657764 | M21: † | N21: 39.899479 | O21: 1.2583748 | Q21: -4.3869299 | R21: 2.2156625 | S21: † | T21: 52.812692 | U21: 1.4736789 | V21: † | W21: 38.714436 | X21: 0.88706134 | Z21: -14.098256 | AA21: 1.6999481 | AB21: † | AC21: 43.499694 | AD21: 0.79712965 | AE21: † | AF21: c | AG21: c | AI21: c | AJ21: c
A22: Czech Republic | B22: 11.954046 | C22: 0.74600486 | E22: 8.8875348 | F22: 0.62018987 | H22: -3.0665117 | I22: 0.93060819 | K22: 14.690417 | L22: 1.0260814 | N22: 7.6157422 | O22: 0.7810985 | Q22: -7.0746751 | R22: 1.3489702 | T22: 10.51579 | U22: 0.76930996 | W22: 10.390401 | X22: 0.77356782 | Z22: -0.12538879 | AA22: 1.1742424 | AC22: 9.831569 | AD22: 0.45059641 | AF22: 22.509862 | AG22: 4.1672304 | AI22: 12.678293 | AJ22: 4.1957569
A23: Denmark | B23: 20.42254 | C23: 0.9002475 | E23: 18.918683 | F23: 1.0427748 | H23: -1.503857 | I23: 1.3528983 | K23: 26.773788 | L23: 1.3143275 | N23: 14.288998 | O23: 1.0287222 | Q23: -12.48479 | R23: 1.6164152 | T23: 19.762029 | U23: 0.67095454 | W23: c | X23: c | Z23: c | AA23: c | AC23: 18.996295 | AD23: 0.74076512 | AF23: 24.500013 | AG23: 1.6389668 | AI23: 5.5037184 | AJ23: 1.7725283
A24: Estonia | B24: 17.515429 | C24: 0.92883173 | E24: 17.455743 | F24: 0.6907316 | H24: -0.059686771 | I24: 1.1433301 | K24: 21.504505 | L24: 1.5714758 | N24: 12.879927 | O24: 1.0247985 | Q24: -8.6245781 | R24: 1.9419733 | T24: 17.359392 | U24: 0.57714047 | W24: 26.633485 | X24: 7.2875007 | Z24: 9.2740922 | AA24: 7.274599 | AC24: 15.934766 | AD24: 0.57014236 | AF24: 30.420747 | AG24: 2.1401961 | AI24: 14.48598 | AJ24: 2.1908185
A25: Finland | B25: 14.760324 | C25: 0.83608131 | E25: 11.63681 | F25: 0.70569842 | H25: -3.1235142 | I25: 1.0516447 | K25: 17.376496 | L25: 1.1689224 | N25: 10.144649 | O25: 0.79133748 | Q25: -7.231847 | R25: 1.3520402 | T25: 13.236468 | U25: 0.57027945 | W25: c | X25: c | Z25: c | AA25: c | AC25: 12.393688 | AD25: 0.54306413 | AF25: 26.576952 | AG25: 2.8841217 | AI25: 14.183264 | AJ25: 2.8221698
A26: France | B26: 19.083169 | C26: 0.98938526 | E26: 13.120731 | F26: 0.73970576 | H26: -5.9624377 | I26: 1.1602624 | K26: 21.946821 | L26: 1.1869677 | N26: 9.4079027 | O26: 0.91017801 | Q26: -12.538918 | R26: 1.4402635 | T26: 25.582444 | U26: 1.8764851 | V26: † | W26: 14.397729 | X26: 0.71049946 | Z26: -11.184715 | AA26: 1.9864967 | AB26: † | AC26: 15.086773 | AD26: 0.73588425 | AF26: 22.031122 | AG26: 1.6472491 | AI26: 6.9443487 | AJ26: 1.87408
A27: Germany | B27: 14.999394 | C27: 1.1335418 | D27: ‡ | E27: 11.310881 | F27: 1.0035153 | G27: ‡ | H27: -3.6885137 | I27: 1.3505114 | J27: ‡ | K27: 18.143813 | L27: 1.9324085 | M27: ‡ | N27: 9.9863592 | O27: 1.2342878 | P27: † | Q27: -8.1574535 | R27: 2.1426965 | S27: ‡ | T27: 13.088229 | U27: 0.88026306 | V27: ‡ | W27: 17.443617 | X27: 2.8856484 | Y27: † | Z27: 4.3553878 | AA27: 2.9670418 | AB27: ‡ | AC27: 11.473406 | AD27: 0.76101361 | AE27: † | AF27: 19.476369 | AG27: 1.9423003 | AH27: ‡ | AI27: 8.0029627 | AJ27: 1.8018634 | AK27: ‡
A28: Greece | B28: 33.902021 | C28: 0.98723297 | E28: 23.260144 | F28: 0.86837046 | H28: -10.641877 | I28: 1.380655 | K28: 29.618829 | L28: 1.3041269 | N28: 23.024929 | O28: 1.2285947 | Q28: -6.5939008 | R28: 1.9404008 | T28: 36.437581 | U28: 3.3267098 | W28: 28.251816 | X28: 0.64755561 | Z28: -8.1857647 | AA28: 3.3918957 | AC28: 28.421979 | AD28: 0.67255443 | AF28: 28.346363 | AG28: 1.802119 | AI28: -0.075616603 | AJ28: 1.8679708
A29: Hungary | B29: 14.046598 | C29: 0.9626682 | E29: 10.05804 | F29: 0.69125689 | H29: -3.9885582 | I29: 1.0254015 | K29: 18.803737 | L29: 1.7656627 | N29: 8.0428557 | O29: 0.90705958 | Q29: -10.760882 | R29: 1.8571655 | T29: 26.202525 | U29: 3.3109594 | V29: † | W29: 10.714266 | X29: 0.60930073 | Z29: -15.488259 | AA29: 3.2733533 | AB29: † | AC29: 11.995723 | AD29: 0.66562153 | AF29: 7.5075811 | AG29: 2.9329513 | AI29: -4.4881422 | AJ29: 2.8444458
A30: Iceland | B30: 8.9847438 | C30: 0.77249525 | E30: 5.75339 | F30: 0.70054027 | H30: -3.2313537 | I30: 1.0312065 | K30: 9.5611286 | L30: 1.4980604 | M30: † | N30: 4.7952825 | O30: 0.99235612 | Q30: -4.7658461 | R30: 1.7869472 | S30: † | T30: 7.2508075 | U30: 0.51727881 | W30: c | X30: c | Z30: c | AA30: c | AC30: 6.582327 | AD30: 0.49046335 | AF30: 18.599425 | AG30: 3.1348147 | AI30: 12.017098 | AJ30: 3.1233302
A31: Ireland | B31: 27.641284 | C31: 1.0480301 | E31: 32.095206 | F31: 1.2396492 | H31: 4.4539216 | I31: 1.6469107 | K31: 33.928513 | L31: 1.3314553 | N31: 25.689759 | O31: 1.4540688 | Q31: -8.2387533 | R31: 1.9763591 | T31: 25.609851 | U31: 0.92490879 | W31: 36.888845 | X31: 1.3313929 | Z31: 11.278994 | AA31: 1.5126411 | AC31: 29.250172 | AD31: 0.8902725 | AF31: 32.303049 | AG31: 1.6690201 | AI31: 3.0528765 | AJ31: 1.8146541
A32: Israel | B32: 40.072905 | C32: 1.0938837 | E32: 37.147091 | F32: 1.1551814 | H32: -2.9258144 | I32: 1.5023856 | K32: 42.916178 | L32: 1.5701447 | N32: 33.733715 | O32: 1.5345873 | Q32: -9.1824634 | R32: 2.0722376 | T32: 35.130565 | U32: 2.3899651 | W32: 38.890479 | X32: 0.92680488 | Z32: 3.7599139 | AA32: 2.636149 | AC32: 38.205461 | AD32: 0.96744709 | AF32: 38.29617 | AG32: 1.7031552 | AI32: 0.090709142 | AJ32: 1.8996213
A33: Italy | B33: 57.186027 | C33: 1.329461 | E33: 56.404409 | F33: 1.2323642 | H33: -0.78161776 | I33: 1.648159 | K33: 63.659667 | L33: 1.6772054 | N33: 51.501282 | O33: 1.6752438 | Q33: -12.158385 | R33: 2.2783055 | T33: 75.663431 | U33: 12.569716 | V33: † | W33: 56.64426 | X33: 0.98513824 | Z33: -19.019171 | AA33: 12.617248 | AB33: † | AC33: 56.623732 | AD33: 0.96973512 | AF33: 58.30566 | AG33: 2.7304964 | AI33: 1.6819276 | AJ33: 2.6129958
A34: Japan | B34: 2.3132098 | C34: 0.40630995 | E34: 1.9062246 | F34: 0.36988866 | H34: -0.4069852 | I34: 0.32474902 | K34: 2.6763696 | L34: 0.66014411 | N34: 2.0397661 | O34: 0.42629524 | Q34: -0.63660353 | R34: 0.65139685 | T34: m | U34: m | W34: 2.1053503 | X34: 0.35354781 | Z34: m | AA34: m | AC34: w | AD34: w | AF34: w | AG34: w | AI34: w | AJ34: w
A35: Korea | B35: 2.4231952 | C35: 0.35369533 | E35: 2.0219385 | F35: 0.47982297 | H35: -0.4012567 | I35: 0.52336475 | K35: 3.0904048 | L35: 0.50610193 | N35: 1.3501035 | O35: 0.41589862 | Q35: -1.7403013 | R35: 0.61502595 | T35: 3.0941876 | U35: 0.84215105 | W35: 2.0673043 | X35: 0.36210804 | Z35: -1.0268833 | AA35: 0.92880018 | AC35: 2.1613715 | AD35: 0.30007374 | AF35: c | AG35: c | AI35: c | AJ35: c
A36: Latvia | B36: 30.130496 | C36: 0.97514146 | E36: 27.255929 | F36: 1.143993 | H36: -2.8745669 | I36: 1.4583228 | K36: 34.560257 | L36: 1.3526322 | N36: 24.116699 | O36: 1.5903941 | Q36: -10.443558 | R36: 1.8953011 | T36: 28.591755 | U36: 0.79246865 | W36: 30.176153 | X36: 4.3283314 | Z36: 1.5843987 | AA36: 4.412726 | AC36: 28.624078 | AD36: 0.78691052 | AF36: 27.981519 | AG36: 3.4525675 | AI36: -0.64255917 | AJ36: 3.4526886
A37: Lithuania | B37: 31.863346 | C37: 0.96202192 | E37: 23.686371 | F37: 0.88051037 | H37: -8.1769749 | I37: 1.2753635 | K37: 34.729829 | L37: 1.4078362 | N37: 21.029471 | O37: 1.158516 | Q37: -13.700358 | R37: 1.8098849 | T37: 27.844431 | U37: 0.6832187 | W37: m | X37: m | Z37: m | AA37: m | AC37: 27.610531 | AD37: 0.69858901 | AF37: 30.515086 | AG37: 5.8257856 | AI37: 2.9045551 | AJ37: 5.8918773
A38: Luxembourg | B38: 17.724427 | C38: 0.83599765 | E38: 12.59378 | F38: 0.7144751 | H38: -5.1306477 | I38: 1.0895043 | K38: 21.628047 | L38: 1.3353177 | N38: 10.099423 | O38: 0.86894186 | Q38: -11.528624 | R38: 1.6075078 | T38: 20.117321 | U38: 0.79653458 | W38: 9.4171977 | X38: 0.61435478 | Z38: -10.700124 | AA38: 0.9163246 | AC38: 11.138801 | AD38: 0.72015605 | AF38: 18.236712 | AG38: 0.78948516 | AI38: 7.0979109 | AJ38: 1.0817505
A39: Mexico | B39: 31.857555 | C39: 1.3070668 | D39: † | E39: 25.705224 | F39: 1.2600197 | G39: † | H39: -6.152331 | I39: 1.5311291 | J39: † | K39: 32.686133 | L39: 2.3521266 | M39: ‡ | N39: 24.018545 | O39: 1.4991439 | P39: † | Q39: -8.6675877 | R39: 2.6914227 | S39: ‡ | T39: 42.32254 | U39: 2.9262288 | V39: ‡ | W39: 26.658385 | X39: 1.1015543 | Y39: † | Z39: -15.664154 | AA39: 3.1718373 | AB39: ‡ | AC39: 28.585015 | AD39: 1.0135043 | AE39: † | AF39: 30.477174 | AG39: 10.351989 | AH39: ‡ | AI39: 1.8921588 | AJ39: 10.384899 | AK39: ‡
A40: Netherlands* | B40: 8.5657133 | C40: 0.72553471 | E40: 5.9544256 | F40: 0.67660495 | H40: -2.6112877 | I40: 0.89300956 | K40: 8.4599889 | L40: 1.0183793 | M40: † | N40: 6.6505581 | O40: 0.91065963 | Q40: -1.8094308 | R40: 1.3457832 | S40: † | T40: 9.0900233 | U40: 0.72610105 | V40: † | W40: 4.4493485 | X40: 0.68084632 | Z40: -4.6406747 | AA40: 0.94627947 | AB40: † | AC40: 6.7145247 | AD40: 0.51102034 | AF40: 10.878829 | AG40: 1.9140132 | AH40: † | AI40: 4.1643042 | AJ40: 1.9252511 | AK40: †
A41: New Zealand | B41: 29.287636 | C41: 1.1084337 | E41: 28.693617 | F41: 1.132203 | H41: -0.59401923 | I41: 1.5339824 | K41: 35.05771 | L41: 1.3433203 | N41: 23.902538 | O41: 1.3441652 | Q41: -11.155172 | R41: 1.6840739 | T41: 29.538953 | U41: 2.8427041 | V41: † | W41: 28.949448 | X41: 0.85438214 | Z41: -0.58950474 | AA41: 2.9748649 | AB41: † | AC41: 29.823805 | AD41: 0.89733035 | AF41: 26.303645 | AG41: 1.3794751 | AI41: -3.5201604 | AJ41: 1.4276839
A42: Norway | B42: 15.896243 | C42: 0.73552679 | E42: 11.288293 | F42: 0.65787559 | H42: -4.6079502 | I42: 0.93499815 | K42: 18.542439 | L42: 1.1454158 | N42: 10.97049 | O42: 0.9428774 | Q42: -7.5719488 | R42: 1.386892 | T42: 13.620109 | U42: 0.52066524 | W42: c | X42: c | Z42: c | AA42: c | AC42: 12.702935 | AD42: 0.5469923 | AF42: 19.105297 | AG42: 1.455693 | AI42: 6.4023611 | AJ42: 1.5189899
A43: Poland | B43: 27.775929 | C43: 1.2596159 | E43: 20.177017 | F43: 1.035078 | H43: -7.5989125 | I43: 1.2211502 | K43: 27.384611 | L43: 1.7920589 | N43: 19.027807 | O43: 1.1291997 | Q43: -8.3568033 | R43: 2.0658211 | T43: 23.90061 | U43: 1.0017725 | W43: c | X43: c | Z43: c | AA43: c | AC43: 23.934527 | AD43: 0.99541631 | AF43: c | AG43: c | AI43: c | AJ43: c
...

Sheet Table III.B1.4.6
A1: PISA 2018 Results (Volume III) - © OECD 2019
A2: Annex B1 | B2: Annex B1.4 Results (tables): Student truancy and lateness
A3: Version 2 - Last updated: 02-Dec-2019
A4: Disclaimer: http://oe.cd/disclaimer
A6: Table III.B1.4.6
A7: Student lateness, by student characteristics
A8: Based on students' reports
B11: Percentage of students who arrived late for school at least once in the two weeks prior to the PISA test, by the following student characteristics:
B12: Gender | K12: Socio-economic status1 | T12: Education level | AC12: Immigrant background
B13: Boys | E13: Girls | H13: Girls - boys | K13: Disadvantaged students | N13: Advantaged students | Q13: Advantaged -disadvantaged | T13: Lower secondary (ISCED 2) | W13: Upper secondary (ISCED 3) | Z13: ISCED 3 - ISCED 2 | AC13: Non-immigrant students | AF13: Immigrant students | AI13: Immigrant - non-immigrant
B14: % | C14: S.E. | E14: % | F14: S.E. | H14: % dif. | I14: S.E. | K14: % | L14: S.E. | N14: % | O14: S.E. | Q14: % dif. | R14: S.E. | T14: % | U14: S.E. | W14: % | X14: S.E. | Z14: % dif. | AA14: S.E. | AC14: % | AD14: S.E. | AF14: % | AG14: S.E. | AI14: % dif. | AJ14: S.E.
A15: OECD
A16: Australia | B16: 45.891222 | C16: 0.85127032 | E16: 45.257197 | F16: 0.94181789 | H16: -0.6340246 | I16: 1.2763175 | K16: 52.116067 | L16: 1.197082 | N16: 41.220416 | O16: 0.94775738 | Q16: -10.895651 | R16: 1.519624 | T16: 46.000832 | U16: 0.6593303 | W16: 40.706179 | X16: 1.8517794 | Z16: -5.2946524 | AA16: 1.9698529 | AC16: 44.46346 | AD16: 0.67168656 | AF16: 47.197591 | AG16: 1.1583448 | AI16: 2.7341308 | AJ16: 1.2423263
A17: Austria | B17: 45.829454 | C17: 1.1731701 | E17: 38.389287 | F17: 1.0472791 | H17: -7.4401669 | I17: 1.5440072 | K17: 47.934721 | L17: 1.4828817 | N17: 40.707775 | O17: 1.5551086 | Q17: -7.2269454 | R17: 2.1779687 | T17: m | U17: m | W17: m | X17: m | Z17: m | AA17: m | AC17: 37.809071 | AD17: 0.88631553 | AF17: 57.212522 | AG17: 1.4676908 | AI17: 19.40345 | AJ17: 1.6706826
A18: Belgium | B18: 56.476886 | C18: 0.86063352 | E18: 50.715961 | F18: 0.9847892 | H18: -5.760925 | I18: 1.2003146 | K18: 60.580301 | L18: 1.3814994 | N18: 46.723293 | O18: 1.2219369 | Q18: -13.857008 | R18: 1.8635977 | T18: 69.979436 | U18: 3.0227938 | V18: ‡ | W18: 52.696592 | X18: 0.74822943 | Z18: -17.282845 | AA18: 3.1884036 | AB18: ‡ | AC18: 50.288319 | AD18: 0.77472663 | AF18: 68.620812 | AG18: 1.7331058 | AI18: 18.332493 | AJ18: 1.928331
A19: Canada | B19: 55.829055 | C19: 0.77662505 | E19: 48.936462 | F19: 0.72686522 | H19: -6.892593 | I19: 0.7999206 | K19: 57.239458 | L19: 1.0677342 | N19: 48.457236 | O19: 0.95973967 | Q19: -8.7822227 | R19: 1.2605243 | T19: 47.151543 | U19: 1.658664 | W19: 52.886025 | X19: 0.67055605 | Z19: 5.7344828 | AA19: 1.702282 | AC19: 51.037529 | AD19: 0.73949328 | AF19: 54.452159 | AG19: 1.0924029 | AI19: 3.4146299 | AJ19: 1.214927
A20: Chile | B20: 69.268635 | C20: 1.1066267 | D20: † | E20: 67.596143 | F20: 1.160151 | G20: † | H20: -1.6724913 | I20: 1.4135591 | J20: † | K20: 69.615253 | L20: 1.7642786 | M20: † | N20: 65.426281 | O20: 1.7322342 | P20: † | Q20: -4.1889715 | R20: 2.509027 | S20: † | T20: 81.075604 | U20: 3.4438887 | V20: † | W20: 67.907348 | X20: 0.89499715 | Y20: † | Z20: -13.168256 | AA20: 3.4675238 | AB20: † | AC20: 68.062537 | AD20: 0.91997828 | AE20: † | AF20: 77.908695 | AG20: 3.5396952 | AH20: † | AI20: 9.8461581 | AJ20: 3.6010358 | AK20: †
A21: Colombia | B21: 47.058374 | C21: 1.2869205 | D21: † | E21: 43.223612 | F21: 1.239731 | G21: † | H21: -3.8347616 | I21: 1.4747609 | J21: † | K21: 43.463557 | L21: 1.910372 | M21: † | N21: 41.621191 | O21: 1.3902874 | Q21: -1.8423654 | R21: 2.3342463 | S21: † | T21: 50.94116 | U21: 1.7074793 | V21: † | W21: 42.094712 | X21: 1.0816874 | Z21: -8.8464481 | AA21: 1.7589313 | AB21: † | AC21: 45.007531 | AD21: 1.0492444 | AE21: † | AF21: c | AG21: c | AI21: c | AJ21: c
A22: Czech Republic | B22: 57.412331 | C22: 1.0974928 | E22: 49.971784 | F22: 1.408936 | H22: -7.4405465 | I22: 1.5619997 | K22: 59.553522 | L22: 1.8766122 | N22: 49.760364 | O22: 1.4707241 | Q22: -9.7931577 | R22: 2.171636 | T22: 51.626729 | U22: 1.4812112 | W22: 56.032967 | X22: 1.3466505 | Z22: 4.4062386 | AA22: 1.9914882 | AC22: 53.282262 | AD22: 0.99280918 | AF22: 63.835373 | AG22: 4.1894191 | AI22: 10.553111 | AJ22: 4.1537064
A23: Denmark | B23: 52.858639 | C23: 1.1488664 | E23: 43.006938 | F23: 1.2235499 | H23: -9.8517006 | I23: 1.5640795 | K23: 51.512045 | L23: 1.5257443 | N23: 45.460053 | O23: 1.5202354 | Q23: -6.0519921 | R23: 2.136438 | T23: 48.165274 | U23: 0.88601022 | W23: c | X23: c | Z23: c | AA23: c | AC23: 46.458685 | AD23: 0.93716181 | AF23: 61.2239 | AG23: 1.7052531 | AI23: 14.765215 | AJ23: 1.8296003
A24: Estonia | B24: 48.817269 | C24: 1.0166495 | E24: 40.629254 | F24: 1.1218405 | H24: -8.1880158 | I24: 1.4804937 | K24: 40.738876 | L24: 1.6242972 | N24: 46.000264 | O24: 1.5270704 | Q24: 5.2613871 | R24: 1.8860119 | T24: 44.673079 | U24: 0.77568335 | W24: 46.855852 | X24: 7.8703545 | Z24: 2.1827732 | AA24: 7.9497259 | AC24: 43.394202 | AD24: 0.76303197 | AF24: 55.718833 | AG24: 2.3477145 | AI24: 12.32463 | AJ24: 2.3211268
A25: Finland | B25: 50.899346 | C25: 1.0567652 | E25: 38.252551 | F25: 1.0132094 | H25: -12.646795 | I25: 1.2394583 | K25: 45.156597 | L25: 1.5366745 | N25: 42.70007 | O25: 1.6188492 | Q25: -2.4565268 | R25: 1.9333292 | T25: 44.618338 | U25: 0.8196209 | W25: c | X25: c | Z25: c | AA25: c | AC25: 43.396348 | AD25: 0.83842152 | AF25: 64.200008 | AG25: 3.0656399 | AI25: 20.80366 | AJ25: 3.1189526
A26: France | B26: 60.467631 | C26: 1.1997687 | E26: 53.452045 | F26: 1.1296729 | H26: -7.0155861 | I26: 1.4723171 | K26: 61.681104 | L26: 1.6583553 | N26: 51.526368 | O26: 1.59815 | Q26: -10.154737 | R26: 2.1403158 | T26: 67.02645 | U26: 2.0110889 | V26: † | W26: 55.15606 | X26: 1.0202765 | Z26: -11.870389 | AA26: 2.2850527 | AB26: † | AC26: 55.480679 | AD26: 0.97523497 | AF26: 66.185485 | AG26: 1.9866861 | AI26: 10.704806 | AJ26: 2.2120106
A27: Germany | B27: 50.409239 | C27: 1.5166579 | D27: ‡ | E27: 40.678477 | F27: 1.6669935 | G27: ‡ | H27: -9.7307626 | I27: 1.7566515 | J27: ‡ | K27: 48.399337 | L27: 2.3702632 | M27: ‡ | N27: 44.527883 | O27: 2.3358072 | P27: † | Q27: -3.8714539 | R27: 3.2388775 | S27: ‡ | T27: 45.882741 | U27: 1.4126205 | V27: ‡ | W27: 45.973315 | X27: 4.6999266 | Y27: † | Z27: 0.090574835 | AA27: 4.9399093 | AB27: ‡ | AC27: 42.150567 | AD27: 1.4858321 | AE27: † | AF27: 59.727816 | AG27: 2.3822048 | AH27: ‡ | AI27: 17.577248 | AJ27: 2.7924088 | AK27: ‡
A28: Greece | B28: 58.951312 | C28: 1.1540309 | E28: 52.735003 | F28: 1.1602215 | H28: -6.2163096 | I28: 1.6155589 | K28: 55.069698 | L28: 1.5600619 | N28: 53.993209 | O28: 1.6730704 | Q28: -1.0764892 | R28: 2.4455869 | T28: 62.301986 | U28: 4.1818064 | V28: † | W28: 55.580911 | X28: 0.84604192 | Z28: -6.7210745 | AA28: 4.260091 | AB28: † | AC28: 55.070093 | AD28: 0.85135522 | AF28: 60.788323 | AG28: 2.1910673 | AI28: 5.7182302 | AJ28: 2.2663551
A29: Hungary | B29: 44.451931 | C29: 1.3910645 | E29: 38.650868 | F29: 1.3888987 | H29: -5.8010626 | I29: 1.6657059 | K29: 48.630102 | L29: 1.8956996 | N29: 38.410438 | O29: 1.7860741 | Q29: -10.219664 | R29: 2.4477147 | T29: 56.117392 | U29: 3.7061702 | V29: † | W29: 40.166866 | X29: 1.1076108 | Z29: -15.950526 | AA29: 3.7183855 | AB29: † | AC29: 41.199645 | AD29: 1.126646 | AF29: 47.608194 | AG29: 5.39791 | AI29: 6.4085491 | AJ29: 5.4118346
